Workbook

Sheet City characteristics
B2: City Basic Data
B4: Calibration methodology | C4: GHG Inventory
B6: A. City Characteristics
B7: Data Item | C7: Value | D7: Units
B8: City Name | C8: Chicago
B9: Latitude | C9: 42
B10: Longitude | C10: -88.5
B11: County | C11: Cook County
B12: State | C12: Illinois
B13: Census Division | C13: East North Central
B14: Climate Division | C14: Midwest
B15: Egrid Region | C15: RFC West
B16: Area of city (excluding water, natural and agricultural areas) | C16: 600 | D16: square kilometers
B18: B. Planning Base Year and Target Years
B19: Year | C19: Value | D19: Units
B20: Base Year | C20: 2019 | D20: Acceptable range [2018,2021]
B21: End Year | C21: 2100
B23: C. City Population and GDP
B24: Data Item | C24: Value | D24: Units
B25: Population in Base Year | C25: 2691 | D25: Thousand of people
B26: Annual population growth (Base Year - End Year) | C26: 0.5 | D26: % people
B27: GDP in Base Year | C27: =728720*50% -> 364360 | D27: Million US$
B28: Annual GDP growth rate | C28: 2 | D28: % US$
B29: Share of manufacturing GDP | C29: 5 | D29: % US$
B30: Share of State population | C30: 0.21244178
B31: Share of State GDP | C31: 0.40674258
B32: Adjustment from state manufacturing GDP | C32: 0.3968254
B34: D. Climate Data
B35: Data Item | C35: 2000 | D35: 2050 | E35: 2100 | F35: Units
B36: Heating degree days (HDD) | C36: 5644.5333 | D36: 5140.5862 | E36: 4850.2262 | F36: F
B37: Cooling degree days (CDD) | C37: 966.1125 | D37: 1218.0861 | E37: 1363.2661 | F37: F
B39: Data Item | C39: Value | D39: Units
B40: Correction from State HDD | C40: 0.87934777
B41: Correction from State CDD | C41: 1.0299707
B42: Annual precipitation | C42: 762 | D42: mm / year
B43: Climate change scenario | C43: RCP4.5
B44: Average temperature increase in 1980-2020 | C44: 1.2446429 | D44: F
B45: Forecasted average temperature increase in 2035-2065 | C45: 3.31 | D45: F
B46: Forecasted average temperature increase in 2070-2100 | C46: 4.5 | D46: F
B48: E. Energy scenario
...

Sheet Region
B3: ~BookRegions_Map
B4: BookName | C4: Region
B5: GC | C5: EGRID
C6: CITY

Sheet TimeSlices
B3: ~TimeSlices | G3: ~TFM_INS
B4: Season | C4: Weekly | D4: DayNite | G4: TimeSlice | H4: LimType | I4: Attribute | J4: Year | K4: Other_Indexes | L4: Tech_Comm_Info | M4: AllRegions
B5: I | D5: P | G5: IDAM | I5: YRFR | M5: 0.0822
B6: W | D6: N | G6: IDPM | I6: YRFR | M6: 0.0957
B7: S | D7: DAM | G7: IN | I7: YRFR | M7: 0.1532
D8: DPM | G8: IP | I8: YRFR | M8: 0.0032
G9: WDAM | I9: YRFR | M9: 0.0815
G10: WDPM | I10: YRFR | M10: 0.1087
G11: WN | I11: YRFR | M11: 0.1381
G12: WP | I12: YRFR | M12: 0.0032
G13: SDAM | I13: YRFR | M13: 0.0975
G14: SDPM | I14: YRFR | M14: 0.1087
G15: SN | I15: YRFR | M15: 0.1253
G16: SP | I16: YRFR | M16: 0.0027

Sheet TimePeriods
H2: Default
B3: ~StartYear | H3: Start | I3: Mid | J3: End | K3: Lnth | N3: Base year | O3: 2016 | P3: 2017 | Q3: 2018 | R3: 2019 | S3: 2020 | T3: 2021 | U3: 2022 | V3: 2023 | W3: 2024 | X3: 2025
B4: ='City characteristics'!C20 -> 2019 | H4: =B4 -> 2019 | I4: =IF(H4="","",H4+(K4-1)/2) -> 2019 | J4: =IF(H4="","",H4+K4-1) -> 2019 | K4: =IF(H4="","",_xlfn.XLOOKUP($B$4,$O$3:$X$3,$O4:$X4)) -> 1 | O4: 1 | P4: 1 | Q4: 1 | R4: 1 | S4: 1 | T4: 1 | U4: 1 | V4: 1 | W4: 1 | X4: 1
H5: =IFERROR(IF(J4+1>'City characteristics'!$C$21,"",J4+1),"") -> 2020 | I5: =IF(H5="","",H5+(K5-1)/2) -> 2020 | J5: =IF(H5="","",H5+K5-1) -> 2020 | K5: =IF(H5="","",_xlfn.XLOOKUP($B$4,$O$3:$X$3,$O5:$X5)) -> 1 | O5: 1 | P5: 1 | Q5: 1 | R5: 1 | S5: 1 | T5: 1 | U5: 1 | V5: 1 | W5: 1 | X5: 1
H6: =IFERROR(IF(J5+1>'City characteristics'!$C$21,"",J5+1),"") -> 2021 | I6: =IF(H6="","",H6+(K6-1)/2) -> 2021 | J6: =IF(H6="","",H6+K6-1) -> 2021 | K6: =IF(H6="","",_xlfn.XLOOKUP($B$4,$O$3:$X$3,$O6:$X6)) -> 1 | O6: 1 | P6: 1 | Q6: 1 | R6: 1 | S6: 1 | T6: 1 | U6: 1 | V6: 1 | W6: 3 | X6: 3
B7: ~ActivePDef | H7: =IFERROR(IF(J6+1>'City characteristics'!$C$21,"",J6+1),"") -> 2022 | I7: =IF(H7="","",H7+(K7-1)/2) -> 2022 | J7: =IF(H7="","",H7+K7-1) -> 2022 | K7: =IF(H7="","",_xlfn.XLOOKUP($B$4,$O$3:$X$3,$O7:$X7)) -> 1 | O7: 1 | P7: 1 | Q7: 1 | R7: 1 | S7: 1 | T7: 1 | U7: 1 | V7: 3 | W7: 3 | X7: 3
B8: Pdef-1 | H8: =IFERROR(IF(J7+1>'City characteristics'!$C$21,"",J7+1),"") -> 2023 | I8: =IF(H8="","",H8+(K8-1)/2) -> 2023 | J8: =IF(H8="","",H8+K8-1) -> 2023 | K8: =IF(H8="","",_xlfn.XLOOKUP($B$4,$O$3:$X$3,$O8:$X8)) -> 1 | O8: 1 | P8: 1 | Q8: 1 | R8: 1 | S8: 1 | T8: 1 | U8: 3 | V8: 3 | W8: 1 | X8: 1
H9: =IFERROR(IF(J8+1>'City characteristics'!$C$21,"",J8+1),"") -> 2024 | I9: =IF(H9="","",H9+(K9-1)/2) -> 2024 | J9: =IF(H9="","",H9+K9-1) -> 2024 | K9: =IF(H9="","",_xlfn.XLOOKUP($B$4,$O$3:$X$3,$O9:$X9)) -> 1 | O9: 1 | P9: 1 | Q9: 1 | R9: 1 | S9: 1 | T9: 3 | U9: 3 | V9: 1 | W9: 5 | X9: 5
H10: =IFERROR(IF(J9+1>'City characteristics'!$C$21,"",J9+1),"") -> 2025 | I10: =IF(H10="","",H10+(K10-1)/2) -> 2025 | J10: =IF(H10="","",H10+K10-1) -> 2025 | K10: =IF(H10="","",_xlfn.XLOOKUP($B$4,$O$3:$X$3,$O10:$X10)) -> 1 | O10: 1 | P10: 1 | Q10: 1 | R10: 1 | S10: 3 | T10: 3 | U10: 1 | V10: 5 | W10: 5 | X10: 5
B11: ~TimePeriods | H11: =IFERROR(IF(J10+1>'City characteristics'!$C$21,"",J10+1),"") -> 2026 | I11: =IF(H11="","",H11+(K11-1)/2) -> 2027 | J11: =IF(H11="","",H11+K11-1) -> 2028 | K11: =IF(H11="","",_xlfn.XLOOKUP($B$4,$O$3:$X$3,$O11:$X11)) -> 3 | O11: 1 | P11: 1 | Q11: 1 | R11: 3 | S11: 3 | T11: 1 | U11: 5 | V11: 5 | W11: 5 | X11: 5
B12: Default | C12: Calibration | H12: =IFERROR(IF(J11+1>'City characteristics'!$C$21,"",J11+1),"") -> 2029 | I12: =IF(H12="","",H12+(K12-1)/2) -> 2030 | J12: =IF(H12="","",H12+K12-1) -> 2031 | K12: =IF(H12="","",_xlfn.XLOOKUP($B$4,$O$3:$X$3,$O12:$X12)) -> 3 | O12: 1 | P12: 1 | Q12: 3 | R12: 3 | S12: 1 | T12: 5 | U12: 5 | V12: 5 | W12: 5 | X12: 5
B13: =K4 -> 1 | C13: 1 | H13: =IFERROR(IF(J12+1>'City characteristics'!$C$21,"",J12+1),"") -> 2032 | I13: =IF(H13="","",H13+(K13-1)/2) -> 2032 | J13: =IF(H13="","",H13+K13-1) -> 2032 | K13: =IF(H13="","",_xlfn.XLOOKUP($B$4,$O$3:$X$3,$O13:$X13)) -> 1 | O13: 1 | P13: 3 | Q13: 3 | R13: 1 | S13: 5 | T13: 5 | U13: 5 | V13: 5 | W13: 5 | X13: 5
B14: =K5 -> 1 | H14: =IFERROR(IF(J13+1>'City characteristics'!$C$21,"",J13+1),"") -> 2033 | I14: =IF(H14="","",H14+(K14-1)/2) -> 2035 | J14: =IF(H14="","",H14+K14-1) -> 2037 | K14: =IF(H14="","",_xlfn.XLOOKUP($B$4,$O$3:$X$3,$O14:$X14)) -> 5 | O14: 3 | P14: 3 | Q14: 1 | R14: 5 | S14: 5 | T14: 5 | U14: 5 | V14: 5 | W14: 5 | X14: 5
B15: =K6 -> 1 | H15: =IFERROR(IF(J14+1>'City characteristics'!$C$21,"",J14+1),"") -> 2038 | I15: =IF(H15="","",H15+(K15-1)/2) -> 2040 | J15: =IF(H15="","",H15+K15-1) -> 2042 | K15: =IF(H15="","",_xlfn.XLOOKUP($B$4,$O$3:$X$3,$O15:$X15)) -> 5 | O15: 3 | P15: 1 | Q15: 5 | R15: 5 | S15: 5 | T15: 5 | U15: 5 | V15: 5 | W15: 5 | X15: 5
B16: =K7 -> 1 | H16: =IFERROR(IF(J15+1>'City characteristics'!$C$21,"",J15+1),"") -> 2043 | I16: =IF(H16="","",H16+(K16-1)/2) -> 2045 | J16: =IF(H16="","",H16+K16-1) -> 2047 | K16: =IF(H16="","",_xlfn.XLOOKUP($B$4,$O$3:$X$3,$O16:$X16)) -> 5 | O16: 1 | P16: 5 | Q16: 5 | R16: 5 | S16: 5 | T16: 5 | U16: 5 | V16: 5 | W16: 5 | X16: 5
B17: =K8 -> 1 | H17: =IFERROR(IF(J16+1>'City characteristics'!$C$21,"",J16+1),"") -> 2048 | I17: =IF(H17="","",H17+(K17-1)/2) -> 2050 | J17: =IF(H17="","",H17+K17-1) -> 2052 | K17: =IF(H17="","",_xlfn.XLOOKUP($B$4,$O$3:$X$3,$O17:$X17)) -> 5 | O17: 5 | P17: 5 | Q17: 5 | R17: 5 | S17: 5 | T17: 5 | U17: 5 | V17: 5 | W17: 5 | X17: 5
B18: =K9 -> 1 | H18: =IFERROR(IF(J17+1>'City characteristics'!$C$21,"",J17+1),"") -> 2053 | I18: =IF(H18="","",H18+(K18-1)/2) -> 2055 | J18: =IF(H18="","",H18+K18-1) -> 2057 | K18: =IF(H18="","",_xlfn.XLOOKUP($B$4,$O$3:$X$3,$O18:$X18)) -> 5 | O18: 5 | P18: 5 | Q18: 5 | R18: 5 | S18: 5 | T18: 5 | U18: 5 | V18: 5 | W18: 5 | X18: 5
B19: =K10 -> 1 | H19: =IFERROR(IF(J18+1>'City characteristics'!$C$21,"",J18+1),"") -> 2058 | I19: =IF(H19="","",H19+(K19-1)/2) -> 2060 | J19: =IF(H19="","",H19+K19-1) -> 2062 | K19: =IF(H19="","",_xlfn.XLOOKUP($B$4,$O$3:$X$3,$O19:$X19)) -> 5 | O19: 5 | P19: 5 | Q19: 5 | R19: 5 | S19: 5 | T19: 5 | U19: 5 | V19: 5 | W19: 5 | X19: 5
B20: =K11 -> 3 | H20: =IFERROR(IF(J19+1>'City characteristics'!$C$21,"",J19+1),"") -> 2063 | I20: =IF(H20="","",H20+(K20-1)/2) -> 2065 | J20: =IF(H20="","",H20+K20-1) -> 2067 | K20: =IF(H20="","",_xlfn.XLOOKUP($B$4,$O$3:$X$3,$O20:$X20)) -> 5 | O20: 5 | P20: 5 | Q20: 5 | R20: 5 | S20: 5 | T20: 5 | U20: 5 | V20: 5 | W20: 5 | X20: 5
B21: =K12 -> 3 | H21: =IFERROR(IF(J20+1>'City characteristics'!$C$21,"",J20+1),"") -> 2068 | I21: =IF(H21="","",H21+(K21-1)/2) -> 2070 | J21: =IF(H21="","",H21+K21-1) -> 2072 | K21: =IF(H21="","",_xlfn.XLOOKUP($B$4,$O$3:$X$3,$O21:$X21)) -> 5 | O21: 5 | P21: 5 | Q21: 5 | R21: 5 | S21: 5 | T21: 5 | U21: 5 | V21: 5 | W21: 5 | X21: 5
B22: =K13 -> 1 | H22: =IFERROR(IF(J21+1>'City characteristics'!$C$21,"",J21+1),"") -> 2073 | I22: =IF(H22="","",H22+(K22-1)/2) -> 2075 | J22: =IF(H22="","",H22+K22-1) -> 2077 | K22: =IF(H22="","",_xlfn.XLOOKUP($B$4,$O$3:$X$3,$O22:$X22)) -> 5 | O22: 5 | P22: 5 | Q22: 5 | R22: 5 | S22: 5 | T22: 5 | U22: 5 | V22: 5 | W22: 5 | X22: 5
B23: =K14 -> 5 | H23: =IFERROR(IF(J22+1>'City characteristics'!$C$21,"",J22+1),"") -> 2078 | I23: =IF(H23="","",H23+(K23-1)/2) -> 2080 | J23: =IF(H23="","",H23+K23-1) -> 2082 | K23: =IF(H23="","",_xlfn.XLOOKUP($B$4,$O$3:$X$3,$O23:$X23)) -> 5 | O23: 5 | P23: 5 | Q23: 5 | R23: 5 | S23: 5 | T23: 5 | U23: 5 | V23: 5 | W23: 5 | X23: 5
B24: =K15 -> 5 | H24: =IFERROR(IF(J23+1>'City characteristics'!$C$21,"",J23+1),"") -> 2083 | I24: =IF(H24="","",H24+(K24-1)/2) -> 2085 | J24: =IF(H24="","",H24+K24-1) -> 2087 | K24: =IF(H24="","",_xlfn.XLOOKUP($B$4,$O$3:$X$3,$O24:$X24)) -> 5 | O24: 5 | P24: 5 | Q24: 5 | R24: 5 | S24: 5 | T24: 5 | U24: 5 | V24: 5 | W24: 5 | X24: 5
B25: =K16 -> 5 | H25: =IFERROR(IF(J24+1>'City characteristics'!$C$21,"",J24+1),"") -> 2088 | I25: =IF(H25="","",H25+(K25-1)/2) -> 2090 | J25: =IF(H25="","",H25+K25-1) -> 2092 | K25: =IF(H25="","",_xlfn.XLOOKUP($B$4,$O$3:$X$3,$O25:$X25)) -> 5 | O25: 5 | P25: 5 | Q25: 5 | R25: 5 | S25: 5 | T25: 5 | U25: 5 | V25: 5 | W25: 5 | X25: 5
... B28: =K19 -> 5 | H28: =IFERROR(IF(J27+1>'City characteristics'!$C$21,"",J27+1),"") | I28: =IF(H28="","",H28+(K28-1)/2) | J28: =IF(H28="","",H28+K28-1) | K28: =IF(H28="","",_xlfn.XLOOKUP($B$4,$O$3:$X$3,$O28:$X28)) | O28: 5 | P28: 5 | Q28: 5 | R28: 5 | S28: 5 | T28: 5 | U28: 5 | V28: 5 | W28: 5 | X28: 5
B29: =K20 -> 5 | H29: =IFERROR(IF(J28+1>'City characteristics'!$C$21,"",J28+1),"") | I29: =IF(H29="","",H29+(K29-1)/2) | J29: =IF(H29="","",H29+K29-1) | K29: =IF(H29="","",_xlfn.XLOOKUP($B$4,$O$3:$X$3,$O29:$X29)) | O29: 5 | P29: 5 | Q29: 5 | R29: 5 | S29: 5 | T29: 5 | U29: 5 | V29: 5 | W29: 5
B30: =K21 -> 5 | H30: =IFERROR(IF(J29+1>'City characteristics'!$C$21,"",J29+1),"") | I30: =IF(H30="","",H30+(K30-1)/2) | J30: =IF(H30="","",H30+K30-1) | K30: =IF(H30="","",_xlfn.XLOOKUP($B$4,$O$3:$X$3,$O30:$X30)) | O30: 5 | P30: 5 | Q30: 5 | R30: 5 | S30: 5 | T30: 5 | U30: 5 | V30: 5
B31: =K22 -> 5 | O31: 5 | P31: 5 | Q31: 5 | R31: 5 | S31: 5 | T31: 5 | U31: 5
B32: =K23 -> 5 | O32: 5 | P32: 5 | Q32: 5 | R32: 5 | S32: 5 | T32: 5
B33: =K24 -> 5 | O33: 5 | P33: 5 | Q33: 5 | R33: 5 | S33: 5
B34: =K25 -> 5 | O34: 5 | P34: 5 | Q34: 5 | R34: 5
B35: =K26 -> 5 | O35: 5 | P35: 5 | Q35: 5
B36: =K27 -> 5 | O36: 5 | P36: 5
B37: =K28 | O37: 5

Sheet Inter-Extra.polation
B1: ~TFM_MIG
B2: TimeSlice | C2: LimType | D2: Attribute | E2: Year2 | F2: Other_Indexes | G2: AllRegions | H2: Pset_Set | I2: Pset_PN | J2: Pset_PD | K2: Pset_CI | L2: Pset_CO | M2: Cset_Set | N2: Cset_CN | O2: Cset_CD
C3: FX | D3: Share | E3: 0 | G3: 1
C4: UP,LO | D4: Share | E4: 0 | G4: 3
C5: UP,LO | D5: CAP_BND | E5: 0 | G5: 3
C6: UP,LO | D6: ACT_BND | E6: 0 | G6: 1
D7: IRE_BND | E7: 0 | G7: 1
D8: UC_RHSRT | E8: 0 | G8: 1
C9: UP,LO | D9: NCAP_BND | E9: 0 | G9: 1
D11: FLO_EMIS | E11: 0 | G11: 1
B15: ~TFM_UPD
B16: TimeSlice | C16: LimType | D16: Attribute | E16: Year | F16: Other_Indexes | G16: EGRID | H16: CITY | I16: Pset_Set | J16: Pset_PN | K16: Pset_PD | L16: Pset_CI | M16: Pset_CO | N16: Cset_Set | O16: Cset_CN | P16: Cset_CD
D17: ACTCOST | G17: 10000 | H17: 10000 | I17: IRE | J17: IMPNRG*Z
D18: ACTCOST | G18: 100000 | H18: 100000 | I18: IRE | J18: IMPDEMZ
D19: ACTCOST | G19: 100000 | H19: 100000 | I19: IRE | J19: IMPMAT*Z
B22: ~TFM_INS-txt
B23: TimeSlice | C23: LimType | D23: Attribute | E23: Year | F23: Attrib_Cond | G23: AllRegions | H23: Pset_Set | I23: Pset_PN | J23: Pset_PD | K23: Pset_CI | L23: Pset_CO | M23: Cset_Set | N23: Cset_CN | O23: Cset_CD
D24: PRC_TSL | G24: DAYNITE | I24: IMPNRGZ

Sheet Defaults
B3: ~Currencies | D3: ~DefUnits
B4: Currency | D4: Option | E4: COM | F4: RSD | G4: IND | H4: TRA | I4: ELC | J4: SUP
B5: CUR | D5: Process_ActUnit
B6: CAD | D6: Process_CapUnit
B7: US | D7: Commodity_Unit
B8: MEX
