Workbook

Sheet ReadMe
A1: Generic Comet (GC) TIMES Supply
B3: Sheet color
C4: Raw Data and Parameters
C6: City Specific Data
C8: Post processing for TIMES
C10: Table formatted for TIMES

Sheet >> City Data

Sheet City characteristics
B2: City Basic Data
B4: Calibration methodology | C4: GHG Inventory
B6: A. City Characteristics
B7: Data Item | C7: Value | D7: Units
B8: City Name | C8: New York
B9: Latitude | C9: 40.5
B10: Longitude | C10: -75
B11: County | C11: New York County
B12: State | C12: New York
B13: Census Division | C13: Middle Atlantic
B14: Climate Division | C14: Northeast
B15: Egrid Region | C15: NPCC NYC/Westchester
B16: Area of city (excluding water, natural and agricultural areas) | C16: 778 | D16: square kilometers
B17: * Division and Region Map can be found in the Maps sheet.
B18: B. Planning Base Year and Target Years
B19: Year | C19: Value | D19: Units
B20: Base Year | C20: 2019 | D20: Acceptable range [2018,2021]
B21: End Year | C21: 2050
B23: C. City Population and GDP
B24: Data Item | C24: Value | D24: Units
B25: Population in Base Year | C25: 8337 | D25: Thousand of people
B26: Annual population growth (Base Year - End Year) | C26: 0.5 | D26: % people
B27: GDP in Base Year | C27: 1206000 | D27: Million US$
B28: Annual GDP growth rate | C28: 2 | D28: % US$
B29: Share of manufacturing GDP | C29: 5 | D29: % US$
B30: Share of State population | C30: 0.42835123
B31: Share of State GDP | C31: 0.67251772
B32: Adjustment from state manufacturing GDP | C32: 1.0638298
B34: D. Climate Data
B35: Data Item | C35: 2000 | D35: 2050 | E35: 2100 | F35: Units
B36: Heating degree days (HDD) | C36: 4473.4625 | D36: 4066.4182 | E36: 3763.8582 | F36: F
B37: Cooling degree days (CDD) | C37: 1020.7333 | D37: 1224.2555 | E37: 1375.5355 | F37: F
B39: Data Item | C39: Value | D39: Units
B40: Correction from State HDD | C40: 0.72727402
B41: Correction from State CDD | C41: 1.5583715
B42: Annual precipitation | C42: 762 | D42: mm / year
B43: Climate change scenario | C43: RCP4.5
B44: Average temperature increase in 1980-2020 | C44: 1.4617857 | D44: F
B45: Forecasted average temperature increase in 2035-2065 | C45: 3.13 | D45: F
B46: Forecasted average temperature increase in 2070-2100 | C46: 4.37 | D46: F
...

Sheet >> GC_Resid

Sheet IND RESID
A1: Sector | B1: Sub-sector | C1: Archetype | D1: Vintage | E1: End Use | F1: Technology | G1: Energy | H1: Input Label | I1: Output Label | J1: Technology Label | K1: DEMAND (TJ) | L1: SPLIT (%) | M1: DEMAND EUSE (TJ) | N1: RESID (MW) | O1: CFA | P1: C2A
A2: Industrial | B2: All Industries | E2: All end use | G2: Coal | H2: INDCOA | I2: INDAINDMD | J2: INDAINAEUCOA19 | K2: 66716.461 | L2: 0 | M2: 0 | N2: 0 | O2: 0.9 | P2: 31.536
A3: Industrial | B3: All Industries | E3: All end use | G3: Petcoke | H3: INDPCK | I3: INDAINDMD | J3: INDAINAEUPCK19 | K3: 66716.461 | L3: 0 | M3: 0 | N3: 0 | O3: 0.9 | P3: 31.536
A4: Industrial | B4: All Industries | E4: All end use | G4: LPG | H4: INDLPG | I4: INDAINDMD | J4: INDAINAEULPG19 | K4: 66716.461 | L4: 0 | M4: 0 | N4: 0 | O4: 0.9 | P4: 31.536
A5: Industrial | B5: All Industries | E5: All end use | G5: Fuel oil | H5: INDFOI | I5: INDAINDMD | J5: INDAINAEUFOI19 | K5: 66716.461 | L5: 0.044204541 | M5: 2949.1706 | N5: 103.90843 | O5: 0.9 | P5: 31.536
A6: Industrial | B6: All Industries | E6: All end use | G6: Natural gas | H6: INDNGA | I6: INDAINDMD | J6: INDAINAEUNGA19 | K6: 66716.461 | L6: 0.46029788 | M6: 30709.446 | N6: 1081.989 | O6: 0.9 | P6: 31.536
A7: Industrial | B7: All Industries | E7: All end use | G7: RNG | H7: INDRNG | I7: INDAINDMD | J7: INDAINAEURNG19 | K7: 66716.461 | L7: 0.001212344 | M7: 80.883298 | N7: 2.8497695 | O7: 0.9 | P7: 31.536
A8: Industrial | B8: All Industries | E8: All end use | G8: Kerosene | H8: INDKER | I8: INDAINDMD | J8: INDAINAEUKER19 | K8: 66716.461 | L8: 0 | M8: 0 | N8: 0 | O8: 0.9 | P8: 31.536
A9: Industrial | B9: All Industries | E9: All end use | G9: Waste | H9: INDWAS | I9: INDAINDMD | J9: INDAINAEUWAS19 | K9: 66716.461 | L9: 0 | M9: 0 | N9: 0 | O9: 0.9 | P9: 31.536
A10: Industrial | B10: All Industries | E10: All end use | G10: Wood biomass | H10: INDBIO | I10: INDAINDMD | J10: INDAINAEUBIO19 | K10: 66716.461 | L10: 0 | M10: 0 | N10: 0 | O10: 0.9 | P10: 31.536
A11: Industrial | B11: All Industries | E11: All end use | G11: Gasoline | H11: INDGSL | I11: INDAINDMD | J11: INDAINAEUGSL19 | K11: 66716.461 | L11: 0 | M11: 0 | N11: 0 | O11: 0.9 | P11: 31.536
A12: Industrial | B12: All Industries | E12: All end use | G12: Diesel | H12: INDDSL | I12: INDAINDMD | J12: INDAINAEUDSL19 | K12: 66716.461 | L12: 0 | M12: 0 | N12: 0 | O12: 0.9 | P12: 31.536
A13: Industrial | B13: All Industries | E13: All end use | G13: Steam | H13: INDSTM | I13: INDAINDMD | J13: INDAINAEUSTM19 | K13: 66716.461 | L13: 0.012291579 | M13: 820.05065 | N13: 28.892929 | O13: 0.9 | P13: 31.536
A14: Industrial | B14: All Industries | E14: All end use | G14: Electricity | H14: INDELC | I14: INDAINDMD | J14: INDAINAEUELC19 | K14: 66716.461 | L14: 0.48199365 | M14: 32156.911 | N14: 1132.9877 | O14: 0.9 | P14: 31.536

Sheet Demand
A1: Sector | B1: Sub-sector | C1: Archetype | D1: Vintage | E1: Demand Label | F1: Unit | G1: 2019 | H1: 2020 | I1: 2025 | J1: 2030 | K1: 2035 | L1: 2040 | M1: 2045 | N1: 2050 | O1: 2055 | P1: 2060 | Q1: 2065 | R1: 2070 | S1: 2075 | T1: 2080 | U1: 2085 | V1: 2090 | W1: 2095 | X1: 2100
A2: Commercial | B2: Hotel | D2: Old | E2: COMHOTOldDMD | F2: Mm2 | G2: 11.978701 | H2: 11.978701 | I2: 11.978701 | J2: 11.978701 | K2: 11.978701 | L2: 11.978701 | M2: 11.978701 | N2: 11.978701 | O2: 11.978701 | P2: 11.978701 | Q2: 11.978701 | R2: 11.978701 | S2: 11.978701 | T2: 11.978701 | U2: 11.978701 | V2: 11.978701 | W2: 11.978701 | X2: 11.978701
A3: Commercial | B3: Retail | D3: Old | E3: COMRETOldDMD | F3: Mm2 | G3: 23.081056 | H3: 23.081056 | I3: 23.081056 | J3: 23.081056 | K3: 23.081056 | L3: 23.081056 | M3: 23.081056 | N3: 23.081056 | O3: 23.081056 | P3: 23.081056 | Q3: 23.081056 | R3: 23.081056 | S3: 23.081056 | T3: 23.081056 | U3: 23.081056 | V3: 23.081056 | W3: 23.081056 | X3: 23.081056
A4: Commercial | B4: Office | D4: Old | E4: COMOFFOldDMD | F4: Mm2 | G4: 73.164819 | H4: 73.164819 | I4: 73.164819 | J4: 73.164819 | K4: 73.164819 | L4: 73.164819 | M4: 73.164819 | N4: 73.164819 | O4: 73.164819 | P4: 73.164819 | Q4: 73.164819 | R4: 73.164819 | S4: 73.164819 | T4: 73.164819 | U4: 73.164819 | V4: 73.164819 | W4: 73.164819 | X4: 73.164819
A5: Commercial | B5: Hospital | D5: Old | E5: COMHOPOldDMD | F5: Mm2 | G5: 44.382259 | H5: 44.382259 | I5: 44.382259 | J5: 44.382259 | K5: 44.382259 | L5: 44.382259 | M5: 44.382259 | N5: 44.382259 | O5: 44.382259 | P5: 44.382259 | Q5: 44.382259 | R5: 44.382259 | S5: 44.382259 | T5: 44.382259 | U5: 44.382259 | V5: 44.382259 | W5: 44.382259 | X5: 44.382259
A6: Commercial | B6: Educationnal | D6: Old | E6: COMEDUOldDMD | F6: Mm2 | G6: 48.565496 | H6: 48.565496 | I6: 48.565496 | J6: 48.565496 | K6: 48.565496 | L6: 48.565496 | M6: 48.565496 | N6: 48.565496 | O6: 48.565496 | P6: 48.565496 | Q6: 48.565496 | R6: 48.565496 | S6: 48.565496 | T6: 48.565496 | U6: 48.565496 | V6: 48.565496 | W6: 48.565496 | X6: 48.565496
A7: Commercial | B7: Warehouse | D7: Old | E7: COMWAROldDMD | F7: Mm2 | G7: 32.733587 | H7: 32.733587 | I7: 32.733587 | J7: 32.733587 | K7: 32.733587 | L7: 32.733587 | M7: 32.733587 | N7: 32.733587 | O7: 32.733587 | P7: 32.733587 | Q7: 32.733587 | R7: 32.733587 | S7: 32.733587 | T7: 32.733587 | U7: 32.733587 | V7: 32.733587 | W7: 32.733587 | X7: 32.733587
A8: Commercial | B8: Municipal | D8: Old | E8: COMMUNOldDMD | F8: Mm2 | G8: 16.841333 | H8: 16.841333 | I8: 16.841333 | J8: 16.841333 | K8: 16.841333 | L8: 16.841333 | M8: 16.841333 | N8: 16.841333 | O8: 16.841333 | P8: 16.841333 | Q8: 16.841333 | R8: 16.841333 | S8: 16.841333 | T8: 16.841333 | U8: 16.841333 | V8: 16.841333 | W8: 16.841333 | X8: 16.841333
A9: Commercial | B9: Other | D9: Old | E9: COMOTHOldDMD | F9: Mm2 | G9: 8.7602804 | H9: 8.7602804 | I9: 8.7602804 | J9: 8.7602804 | K9: 8.7602804 | L9: 8.7602804 | M9: 8.7602804 | N9: 8.7602804 | O9: 8.7602804 | P9: 8.7602804 | Q9: 8.7602804 | R9: 8.7602804 | S9: 8.7602804 | T9: 8.7602804 | U9: 8.7602804 | V9: 8.7602804 | W9: 8.7602804 | X9: 8.7602804
A10: Commercial | B10: Hotel | D10: New | E10: COMHOTNewDMD | F10: Mm2 | G10: 0 | H10: 0.23957402 | I10: 1.4374441 | J10: 2.6353143 | K10: 3.8331844 | L10: 5.0310545 | M10: 6.2289246 | N10: 7.4267947 | O10: 8.6246649 | P10: 9.822535 | Q10: 11.020405 | R10: 12.218275 | S10: 13.416145 | T10: 14.614015 | U10: 15.811886 | V10: 17.009756 | W10: 18.207626 | X10: 19.405496
A11: Commercial | B11: Retail | D11: New | E11: COMRETNewDMD | F11: Mm2 | G11: 0 | H11: 0.46162113 | I11: 2.7697268 | J11: 5.0778324 | K11: 7.3859381 | L11: 9.6940437 | M11: 12.002149 | N11: 14.310255 | O11: 16.618361 | P11: 18.926466 | Q11: 21.234572 | R11: 23.542678 | S11: 25.850783 | T11: 28.158889 | U11: 30.466995 | V11: 32.7751 | W11: 35.083206 | X11: 37.391311
A12: Commercial | B12: Office | D12: New | E12: COMOFFNewDMD | F12: Mm2 | G12: 0 | H12: 1.4632964 | I12: 8.7797783 | J12: 16.09626 | K12: 23.412742 | L12: 30.729224 | M12: 38.045706 | N12: 45.362188 | O12: 52.67867 | P12: 59.995152 | Q12: 67.311633 | R12: 74.628115 | S12: 81.944597 | T12: 89.261079 | U12: 96.577561 | V12: 103.89404 | W12: 111.21052 | X12: 118.52701
A13: Commercial | B13: Hospital | D13: New | E13: COMHOPNewDMD | F13: Mm2 | G13: 0 | H13: 0.88764519 | I13: 5.3258711 | J13: 9.764097 | K13: 14.202323 | L13: 18.640549 | M13: 23.078775 | N13: 27.517001 | O13: 31.955227 | P13: 36.393453 | Q13: 40.831679 | R13: 45.269904 | S13: 49.70813 | T13: 54.146356 | U13: 58.584582 | V13: 63.022808 | W13: 67.461034 | X13: 71.89926
... A17: Commercial | B17: Other | D17: New | E17: COMOTHNewDMD | F17: Mm2 | G17: 0 | H17: 0.17520561 | I17: 1.0512337 | J17: 1.9272617 | K17: 2.8032897 | L17: 3.6793178 | M17: 4.5553458 | N17: 5.4313739 | O17: 6.3074019 | P17: 7.18343 | Q17: 8.059458 | R17: 8.9354861 | S17: 9.8115141 | T17: 10.687542 | U17: 11.56357 | V17: 12.439598 | W17: 13.315626 | X17: 14.191654
A18: Residential | B18: Apartment | C18: Low Income | D18: Old | E18: RESAPALOOldDMD | F18: Mm2 | G18: 51.807877 | H18: 51.807877 | I18: 51.807877 | J18: 51.807877 | K18: 51.807877 | L18: 51.807877 | M18: 51.807877 | N18: 51.807877 | O18: 51.807877 | P18: 51.807877 | Q18: 51.807877 | R18: 51.807877 | S18: 51.807877 | T18: 51.807877 | U18: 51.807877 | V18: 51.807877 | W18: 51.807877 | X18: 51.807877
A19: Residential | B19: House | C19: Low Income | D19: Old | E19: RESHOULOOldDMD | F19: Mm2 | G19: 14.956798 | H19: 14.956798 | I19: 14.956798 | J19: 14.956798 | K19: 14.956798 | L19: 14.956798 | M19: 14.956798 | N19: 14.956798 | O19: 14.956798 | P19: 14.956798 | Q19: 14.956798 | R19: 14.956798 | S19: 14.956798 | T19: 14.956798 | U19: 14.956798 | V19: 14.956798 | W19: 14.956798 | X19: 14.956798
A20: Residential | B20: Apartment | C20: Lower-Middle Income | D20: Old | E20: RESAPALMOldDMD | F20: Mm2 | G20: 57.121976 | H20: 57.121976 | I20: 57.121976 | J20: 57.121976 | K20: 57.121976 | L20: 57.121976 | M20: 57.121976 | N20: 57.121976 | O20: 57.121976 | P20: 57.121976 | Q20: 57.121976 | R20: 57.121976 | S20: 57.121976 | T20: 57.121976 | U20: 57.121976 | V20: 57.121976 | W20: 57.121976 | X20: 57.121976
A21: Residential | B21: House | C21: Lower-Middle Income | D21: Old | E21: RESHOULMOldDMD | F21: Mm2 | G21: 38.299259 | H21: 38.299259 | I21: 38.299259 | J21: 38.299259 | K21: 38.299259 | L21: 38.299259 | M21: 38.299259 | N21: 38.299259 | O21: 38.299259 | P21: 38.299259 | Q21: 38.299259 | R21: 38.299259 | S21: 38.299259 | T21: 38.299259 | U21: 38.299259 | V21: 38.299259 | W21: 38.299259 | X21: 38.299259
A22: Residential | B22: Apartment | C22: Upper-Middle Income | D22: Old | E22: RESAPAUMOldDMD | F22: Mm2 | G22: 15.495888 | H22: 15.495888 | I22: 15.495888 | J22: 15.495888 | K22: 15.495888 | L22: 15.495888 | M22: 15.495888 | N22: 15.495888 | O22: 15.495888 | P22: 15.495888 | Q22: 15.495888 | R22: 15.495888 | S22: 15.495888 | T22: 15.495888 | U22: 15.495888 | V22: 15.495888 | W22: 15.495888 | X22: 15.495888
A23: Residential | B23: House | C23: Upper-Middle Income | D23: Old | E23: RESHOUUMOldDMD | F23: Mm2 | G23: 19.187214 | H23: 19.187214 | I23: 19.187214 | J23: 19.187214 | K23: 19.187214 | L23: 19.187214 | M23: 19.187214 | N23: 19.187214 | O23: 19.187214 | P23: 19.187214 | Q23: 19.187214 | R23: 19.187214 | S23: 19.187214 | T23: 19.187214 | U23: 19.187214 | V23: 19.187214 | W23: 19.187214 | X23: 19.187214
A24: Residential | B24: Apartment | C24: High Income | D24: Old | E24: RESAPAHIOldDMD | F24: Mm2 | G24: 66.398717 | H24: 66.398717 | I24: 66.398717 | J24: 66.398717 | K24: 66.398717 | L24: 66.398717 | M24: 66.398717 | N24: 66.398717 | O24: 66.398717 | P24: 66.398717 | Q24: 66.398717 | R24: 66.398717 | S24: 66.398717 | T24: 66.398717 | U24: 66.398717 | V24: 66.398717 | W24: 66.398717 | X24: 66.398717
A25: Residential | B25: House | C25: High Income | D25: Old | E25: RESHOUHIOldDMD | F25: Mm2 | G25: 96.552051 | H25: 96.552051 | I25: 96.552051 | J25: 96.552051 | K25: 96.552051 | L25: 96.552051 | M25: 96.552051 | N25: 96.552051 | O25: 96.552051 | P25: 96.552051 | Q25: 96.552051 | R25: 96.552051 | S25: 96.552051 | T25: 96.552051 | U25: 96.552051 | V25: 96.552051 | W25: 96.552051 | X25: 96.552051
A26: Residential | B26: Apartment | C26: Low Income | D26: New | E26: RESAPALONewDMD | F26: Mm2 | G26: 0 | H26: 0.25903939 | I26: 1.5542363 | J26: 2.8494333 | K26: 4.1446302 | L26: 5.4398271 | M26: 6.7350241 | N26: 8.030221 | O26: 9.3254179 | P26: 10.620615 | Q26: 11.915812 | R26: 13.211009 | S26: 14.506206 | T26: 15.801403 | U26: 17.0966 | V26: 18.391797 | W26: 19.686993 | X26: 20.98219
A27: Residential | B27: House | C27: Low Income | D27: New | E27: RESHOULONewDMD | F27: Mm2 | G27: 0 | H27: 0.07478399 | I27: 0.44870394 | J27: 0.82262389 | K27: 1.1965438 | L27: 1.5704638 | M27: 1.9443837 | N27: 2.3183037 | O27: 2.6922236 | P27: 3.0661436 | Q27: 3.4400635 | R27: 3.8139835 | S27: 4.1879034 | T27: 4.5618234 | U27: 4.9357433 | V27: 5.3096633 | W27: 5.6835832 | X27: 6.0575032
A28: Residential | B28: Apartment | C28: Lower-Middle Income | D28: New | E28: RESAPALMNewDMD | F28: Mm2 | G28: 0 | H28: 0.28560988 | I28: 1.7136593 | J28: 3.1417087 | K28: 4.5697581 | L28: 5.9978075 | M28: 7.4258569 | N28: 8.8539063 | O28: 10.281956 | P28: 11.710005 | Q28: 13.138055 | R28: 14.566104 | S28: 15.994153 | T28: 17.422203 | U28: 18.850252 | V28: 20.278302 | W28: 21.706351 | X28: 23.1344
A29: Residential | B29: House | C29: Lower-Middle Income | D29: New | E29: RESHOULMNewDMD | F29: Mm2 | G29: 0 | H29: 0.19149629 | I29: 1.1489778 | J29: 2.1064592 | K29: 3.0639407 | L29: 4.0214222 | M29: 4.9789036 | N29: 5.9363851 | O29: 6.8938665 | P29: 7.851348 | Q29: 8.8088295 | R29: 9.7663109 | S29: 10.723792 | T29: 11.681274 | U29: 12.638755 | V29: 13.596237 | W29: 14.553718 | X29: 15.5112
... A33: Residential | B33: House | C33: High Income | D33: New | E33: RESHOUHINewDMD | F33: Mm2 | G33: 0 | H33: 0.48276025 | I33: 2.8965615 | J33: 5.3103628 | K33: 7.7241641 | L33: 10.137965 | M33: 12.551767 | N33: 14.965568 | O33: 17.379369 | P33: 19.79317 | Q33: 22.206972 | R33: 24.620773 | S33: 27.034574 | T33: 29.448376 | U33: 31.862177 | V33: 34.275978 | W33: 36.689779 | X33: 39.103581
A34: Industrial | B34: All Industries | E34: INDAINDMD | F34: TJ | G34: 66716.461 | H34: 68050.79 | I34: 74855.869 | J34: 82341.456 | K34: 90575.602 | L34: 99633.162 | M34: 109596.48 | N34: 120556.13 | O34: 132611.74 | P34: 145872.91 | Q34: 160460.2 | R34: 176506.22 | S34: 194156.85 | T34: 213572.53 | U34: 234929.78 | V34: 258422.76 | W34: 284265.04 | X34: 312691.54
A35: Transportation | B35: Passenger | C35: Passenger Car | E35: TRAPASCARDMD | F35: M Vkm | G35: 68921.251 | H35: 69265.857 | I35: 70997.504 | J35: 72772.441 | K35: 74591.752 | L35: 76456.546 | M35: 78367.96 | N35: 80327.159 | O35: 82335.338 | P35: 84393.721 | Q35: 86503.564 | R35: 88666.153 | S35: 90882.807 | T35: 93154.877 | U35: 95483.749 | V35: 97870.843 | W35: 100317.61 | X35: 102825.55
A36: Transportation | B36: Passenger | C36: Passenger Truck | E36: TRAPASLDTDMD | F36: M Vkm | G36: 0 | H36: 0 | I36: 0 | J36: 0 | K36: 0 | L36: 0 | M36: 0 | N36: 0 | O36: 0 | P36: 0 | Q36: 0 | R36: 0 | S36: 0 | T36: 0 | U36: 0 | V36: 0 | W36: 0 | X36: 0
A37: Transportation | B37: Passenger | C37: Motorcycle | E37: TRAPASMOTDMD | F37: M Vkm | G37: 0 | H37: 0 | I37: 0 | J37: 0 | K37: 0 | L37: 0 | M37: 0 | N37: 0 | O37: 0 | P37: 0 | Q37: 0 | R37: 0 | S37: 0 | T37: 0 | U37: 0 | V37: 0 | W37: 0 | X37: 0
A38: Transportation | B38: Freight | C38: Light Commercial Truck | E38: TRAFRECLTDMD | F38: M Vkm | G38: 1578.5179 | H38: 1586.4105 | I38: 1626.0707 | J38: 1666.7225 | K38: 1708.3906 | L38: 1751.1003 | M38: 1794.8778 | N38: 1839.7498 | O38: 1885.7435 | P38: 1932.8871 | Q38: 1981.2093 | R38: 2030.7395 | S38: 2081.508 | T38: 2133.5457 | U38: 2186.8844 | V38: 2241.5565 | W38: 2297.5954 | X38: 2355.0353
A39: Transportation | B39: Freight | C39: Refuse Truck | E39: TRAFRERFTDMD | F39: M Vkm | G39: 70.026308 | H39: 70.37644 | I39: 72.135851 | J39: 73.939247 | K39: 75.787728 | L39: 77.682421 | M39: 79.624482 | N39: 81.615094 | O39: 83.655471 | P39: 85.746858 | Q39: 87.89053 | R39: 90.087793 | S39: 92.339988 | T39: 94.648487 | U39: 97.0147 | V39: 99.440067 | W39: 101.92607 | X39: 104.47422
A40: Transportation | B40: Freight | C40: Single Unit Long-haul Truck | E40: TRAFRESLHDMD | F40: M Vkm | G40: 0 | H40: 0 | I40: 0 | J40: 0 | K40: 0 | L40: 0 | M40: 0 | N40: 0 | O40: 0 | P40: 0 | Q40: 0 | R40: 0 | S40: 0 | T40: 0 | U40: 0 | V40: 0 | W40: 0 | X40: 0
A41: Transportation | B41: Freight | C41: Single Unit Short-haul Truck | E41: TRAFRESSHDMD | F41: M Vkm | G41: 0 | H41: 0 | I41: 0 | J41: 0 | K41: 0 | L41: 0 | M41: 0 | N41: 0 | O41: 0 | P41: 0 | Q41: 0 | R41: 0 | S41: 0 | T41: 0 | U41: 0 | V41: 0 | W41: 0 | X41: 0
A42: Transportation | B42: Freight | C42: Combination Long-haul Truck | E42: TRAFRECLHDMD | F42: M Vkm | G42: 1367.6202 | H42: 1374.4583 | I42: 1408.8197 | J42: 1444.0402 | K42: 1480.1412 | L42: 1517.1447 | M42: 1555.0734 | N42: 1593.9502 | O42: 1633.7989 | P42: 1674.6439 | Q42: 1716.51 | R42: 1759.4228 | S42: 1803.4083 | T42: 1848.4935 | U42: 1894.7059 | V42: 1942.0735 | W42: 1990.6254 | X42: 2040.391
A43: Transportation | B43: Freight | C43: Combination Short-haul Truck | E43: TRAFRECSHDMD | F43: M Vkm | G43: 0 | H43: 0 | I43: 0 | J43: 0 | K43: 0 | L43: 0 | M43: 0 | N43: 0 | O43: 0 | P43: 0 | Q43: 0 | R43: 0 | S43: 0 | T43: 0 | U43: 0 | V43: 0 | W43: 0 | X43: 0
A44: Transportation | B44: Passenger | C44: Transit Bus | E44: TRAPASTBUDMD | F44: M Vkm | G44: 498.20419 | H44: 500.69521 | I44: 513.21259 | J44: 526.0429 | K44: 539.19397 | L44: 552.67382 | M44: 566.49067 | N44: 580.65294 | O44: 595.16926 | P44: 610.04849 | Q44: 625.2997 | R44: 640.93219 | S44: 656.9555 | T44: 673.37939 | U44: 690.21387 | V44: 707.46922 | W44: 725.15595 | X44: 743.28485
A45: Transportation | B45: Passenger | C45: School Bus | E45: TRAPASSBUDMD | F45: M Vkm | G45: 86.053217 | H45: 86.483483 | I45: 88.645571 | J45: 90.86171 | K45: 93.133253 | L45: 95.461584 | M45: 97.848123 | N45: 100.29433 | O45: 102.80168 | P45: 105.37173 | Q45: 108.00602 | R45: 110.70617 | S45: 113.47382 | T45: 116.31067 | U45: 119.21844 | V45: 122.1989 | W45: 125.25387 | X45: 128.38522
A46: Transportation | B46: Passenger | C46: Other Buses | E46: TRAPASOBUDMD | F46: M Vkm | G46: 0 | H46: 0 | I46: 0 | J46: 0 | K46: 0 | L46: 0 | M46: 0 | N46: 0 | O46: 0 | P46: 0 | Q46: 0 | R46: 0 | S46: 0 | T46: 0 | U46: 0 | V46: 0 | W46: 0 | X46: 0
...

Sheet >> TIMES

Sheet Def_Tech
B2: ~FI_Process
B3: Sets | C3: Region | D3: TechName | E3: TechDesc | F3: Tact | G3: Tcap | H3: Tslvl | I3: PrimaryCG | J3: Vintage
B4: *Process Set Membership | C4: Region | D4: Technology Name | E4: Technology Description | F4: Activity Unit | G4: Capacity Unit | H4: TimeSlice level of Process Activity | I4: Primary Commodity Group | J4: Vintage Tracking
B5: =IF(_xlfn.XLOOKUP(D5,'IND RESID'!J:J,'IND RESID'!N:N)=0,"*","PRE") -> * | C5: CITY | D5: ='IND RESID'!J2 -> INDAINAEUCOA19 | E5: ='IND RESID'!A2&" "&'IND RESID'!B2&" "&'IND RESID'!E2&" "&'IND RESID'!G2&" "&'City characteristics'!$C$20 -> Industrial All Industries All end use Coal 2019 | F5: TJ | G5: MW
B6: =IF(_xlfn.XLOOKUP(D6,'IND RESID'!J:J,'IND RESID'!N:N)=0,"*","PRE") -> * | C6: CITY | D6: ='IND RESID'!J3 -> INDAINAEUPCK19 | E6: ='IND RESID'!A3&" "&'IND RESID'!B3&" "&'IND RESID'!E3&" "&'IND RESID'!G3&" "&'City characteristics'!$C$20 -> Industrial All Industries All end use Petcoke 2019 | F6: TJ | G6: MW
B7: =IF(_xlfn.XLOOKUP(D7,'IND RESID'!J:J,'IND RESID'!N:N)=0,"*","PRE") -> * | C7: CITY | D7: ='IND RESID'!J4 -> INDAINAEULPG19 | E7: ='IND RESID'!A4&" "&'IND RESID'!B4&" "&'IND RESID'!E4&" "&'IND RESID'!G4&" "&'City characteristics'!$C$20 -> Industrial All Industries All end use LPG 2019 | F7: TJ | G7: MW
B8: =IF(_xlfn.XLOOKUP(D8,'IND RESID'!J:J,'IND RESID'!N:N)=0,"*","PRE") -> PRE | C8: CITY | D8: ='IND RESID'!J5 -> INDAINAEUFOI19 | E8: ='IND RESID'!A5&" "&'IND RESID'!B5&" "&'IND RESID'!E5&" "&'IND RESID'!G5&" "&'City characteristics'!$C$20 -> Industrial All Industries All end use Fuel oil 2019 | F8: TJ | G8: MW
B9: =IF(_xlfn.XLOOKUP(D9,'IND RESID'!J:J,'IND RESID'!N:N)=0,"*","PRE") -> PRE | C9: CITY | D9: ='IND RESID'!J6 -> INDAINAEUNGA19 | E9: ='IND RESID'!A6&" "&'IND RESID'!B6&" "&'IND RESID'!E6&" "&'IND RESID'!G6&" "&'City characteristics'!$C$20 -> Industrial All Industries All end use Natural gas 2019 | F9: TJ | G9: MW
B10: =IF(_xlfn.XLOOKUP(D10,'IND RESID'!J:J,'IND RESID'!N:N)=0,"*","PRE") -> PRE | C10: CITY | D10: ='IND RESID'!J7 -> INDAINAEURNG19 | E10: ='IND RESID'!A7&" "&'IND RESID'!B7&" "&'IND RESID'!E7&" "&'IND RESID'!G7&" "&'City characteristics'!$C$20 -> Industrial All Industries All end use RNG 2019 | F10: TJ | G10: MW
B11: =IF(_xlfn.XLOOKUP(D11,'IND RESID'!J:J,'IND RESID'!N:N)=0,"*","PRE") -> * | C11: CITY | D11: ='IND RESID'!J8 -> INDAINAEUKER19 | E11: ='IND RESID'!A8&" "&'IND RESID'!B8&" "&'IND RESID'!E8&" "&'IND RESID'!G8&" "&'City characteristics'!$C$20 -> Industrial All Industries All end use Kerosene 2019 | F11: TJ | G11: MW
B12: =IF(_xlfn.XLOOKUP(D12,'IND RESID'!J:J,'IND RESID'!N:N)=0,"*","PRE") -> * | C12: CITY | D12: ='IND RESID'!J9 -> INDAINAEUWAS19 | E12: ='IND RESID'!A9&" "&'IND RESID'!B9&" "&'IND RESID'!E9&" "&'IND RESID'!G9&" "&'City characteristics'!$C$20 -> Industrial All Industries All end use Waste 2019 | F12: TJ | G12: MW
B13: =IF(_xlfn.XLOOKUP(D13,'IND RESID'!J:J,'IND RESID'!N:N)=0,"*","PRE") -> * | C13: CITY | D13: ='IND RESID'!J10 -> INDAINAEUBIO19 | E13: ='IND RESID'!A10&" "&'IND RESID'!B10&" "&'IND RESID'!E10&" "&'IND RESID'!G10&" "&'City characteristics'!$C$20 -> Industrial All Industries All end use Wood biomass 2019 | F13: TJ | G13: MW
B14: =IF(_xlfn.XLOOKUP(D14,'IND RESID'!J:J,'IND RESID'!N:N)=0,"*","PRE") -> * | C14: CITY | D14: ='IND RESID'!J11 -> INDAINAEUGSL19 | E14: ='IND RESID'!A11&" "&'IND RESID'!B11&" "&'IND RESID'!E11&" "&'IND RESID'!G11&" "&'City characteristics'!$C$20 -> Industrial All Industries All end use Gasoline 2019 | F14: TJ | G14: MW
B15: =IF(_xlfn.XLOOKUP(D15,'IND RESID'!J:J,'IND RESID'!N:N)=0,"*","PRE") -> * | C15: CITY | D15: ='IND RESID'!J12 -> INDAINAEUDSL19 | E15: ='IND RESID'!A12&" "&'IND RESID'!B12&" "&'IND RESID'!E12&" "&'IND RESID'!G12&" "&'City characteristics'!$C$20 -> Industrial All Industries All end use Diesel 2019 | F15: TJ | G15: MW
B16: =IF(_xlfn.XLOOKUP(D16,'IND RESID'!J:J,'IND RESID'!N:N)=0,"*","PRE") -> PRE | C16: CITY | D16: ='IND RESID'!J13 -> INDAINAEUSTM19 | E16: ='IND RESID'!A13&" "&'IND RESID'!B13&" "&'IND RESID'!E13&" "&'IND RESID'!G13&" "&'City characteristics'!$C$20 -> Industrial All Industries All end use Steam 2019 | F16: TJ | G16: MW
B17: =IF(_xlfn.XLOOKUP(D17,'IND RESID'!J:J,'IND RESID'!N:N)=0,"*","PRE") -> PRE | C17: CITY | D17: ='IND RESID'!J14 -> INDAINAEUELC19 | E17: ='IND RESID'!A14&" "&'IND RESID'!B14&" "&'IND RESID'!E14&" "&'IND RESID'!G14&" "&'City characteristics'!$C$20 -> Industrial All Industries All end use Electricity 2019 | F17: TJ | G17: MW

Sheet Def_Comm
B2: ~FI_Comm
B3: Csets | C3: CommName | D3: CommDesc | E3: Unit | F3: LimType | G3: CTSLvl | H3: PeakTS | I3: Ctype
B4: *Commodity Set Membership | C4: Commodity Name | D4: Commodity Description | E4: Unit | F4: Sense of the Balance EQN. | G4: Timeslice Level | H4: Peak Monitoring | I4: Electricity Indicator
B5: DEM | C5: =Demand!E34 -> INDAINDMD | D5: =Demand!A34&" "&Demand!B34&" "&Demand!C34&" "&Demand!D34&" "&"demand" -> Industrial All Industries demand | E5: TJ

Sheet ResidIND
L1: ='City characteristics'!C20 -> 2019
L2: PRC_RESID
E4: ~FI_T
B5: Region | C5: TechName | D5: Comm-IN | E5: Comm-OUT | F5: EFF | G5: PRC_CAPACT | H5: NCAP_AFA | I5: NCAP_AFA~LO | J5: NCAP_TLIFE | K5: NCAP_FOM | L5: =L2&"~"&L1 -> PRC_RESID~2019
B6: * | C6: * | F6: Out/In | G6: TJ/MW | H6: % | I6: % | J6: Yr | K6: $ /kW / Yr | L6: MW
B7: =IF(L7=0,"*",Def_Tech!C5) -> * | C7: =Def_Tech!D5 -> INDAINAEUCOA19 | D7: =_xlfn.XLOOKUP(C7,'IND RESID'!J:J,'IND RESID'!H:H) -> INDCOA | E7: =_xlfn.XLOOKUP(C7,'IND RESID'!J:J,'IND RESID'!I:I) -> INDAINDMD | F7: 1 | G7: =_xlfn.XLOOKUP(C7,'IND RESID'!J:J,'IND RESID'!P:P) -> 31.536 | H7: =_xlfn.XLOOKUP(C7,'IND RESID'!J:J,'IND RESID'!O:O) -> 0.9 | I7: =H7*0.9 -> 0.81 | J7: 25 | L7: =_xlfn.XLOOKUP(C7,'IND RESID'!J:J,'IND RESID'!N:N) -> 0
B8: =IF(L8=0,"*",Def_Tech!C6) -> * | C8: =Def_Tech!D6 -> INDAINAEUPCK19 | D8: =_xlfn.XLOOKUP(C8,'IND RESID'!J:J,'IND RESID'!H:H) -> INDPCK | E8: =_xlfn.XLOOKUP(C8,'IND RESID'!J:J,'IND RESID'!I:I) -> INDAINDMD | F8: 1 | G8: =_xlfn.XLOOKUP(C8,'IND RESID'!J:J,'IND RESID'!P:P) -> 31.536 | H8: =_xlfn.XLOOKUP(C8,'IND RESID'!J:J,'IND RESID'!O:O) -> 0.9 | I8: =H8*0.9 -> 0.81 | J8: 25 | L8: =_xlfn.XLOOKUP(C8,'IND RESID'!J:J,'IND RESID'!N:N) -> 0
B9: =IF(L9=0,"*",Def_Tech!C7) -> * | C9: =Def_Tech!D7 -> INDAINAEULPG19 | D9: =_xlfn.XLOOKUP(C9,'IND RESID'!J:J,'IND RESID'!H:H) -> INDLPG | E9: =_xlfn.XLOOKUP(C9,'IND RESID'!J:J,'IND RESID'!I:I) -> INDAINDMD | F9: 1 | G9: =_xlfn.XLOOKUP(C9,'IND RESID'!J:J,'IND RESID'!P:P) -> 31.536 | H9: =_xlfn.XLOOKUP(C9,'IND RESID'!J:J,'IND RESID'!O:O) -> 0.9 | I9: =H9*0.9 -> 0.81 | J9: 25 | L9: =_xlfn.XLOOKUP(C9,'IND RESID'!J:J,'IND RESID'!N:N) -> 0
B10: =IF(L10=0,"*",Def_Tech!C8) -> CITY | C10: =Def_Tech!D8 -> INDAINAEUFOI19 | D10: =_xlfn.XLOOKUP(C10,'IND RESID'!J:J,'IND RESID'!H:H) -> INDFOI | E10: =_xlfn.XLOOKUP(C10,'IND RESID'!J:J,'IND RESID'!I:I) -> INDAINDMD | F10: 1 | G10: =_xlfn.XLOOKUP(C10,'IND RESID'!J:J,'IND RESID'!P:P) -> 31.536 | H10: =_xlfn.XLOOKUP(C10,'IND RESID'!J:J,'IND RESID'!O:O) -> 0.9 | I10: =H10*0.9 -> 0.81 | J10: 25 | L10: =_xlfn.XLOOKUP(C10,'IND RESID'!J:J,'IND RESID'!N:N) -> 103.90843
B11: =IF(L11=0,"*",Def_Tech!C9) -> CITY | C11: =Def_Tech!D9 -> INDAINAEUNGA19 | D11: =_xlfn.XLOOKUP(C11,'IND RESID'!J:J,'IND RESID'!H:H) -> INDNGA | E11: =_xlfn.XLOOKUP(C11,'IND RESID'!J:J,'IND RESID'!I:I) -> INDAINDMD | F11: 1 | G11: =_xlfn.XLOOKUP(C11,'IND RESID'!J:J,'IND RESID'!P:P) -> 31.536 | H11: =_xlfn.XLOOKUP(C11,'IND RESID'!J:J,'IND RESID'!O:O) -> 0.9 | I11: =H11*0.9 -> 0.81 | J11: 25 | L11: =_xlfn.XLOOKUP(C11,'IND RESID'!J:J,'IND RESID'!N:N) -> 1081.989
B12: =IF(L12=0,"*",Def_Tech!C10) -> CITY | C12: =Def_Tech!D10 -> INDAINAEURNG19 | D12: =_xlfn.XLOOKUP(C12,'IND RESID'!J:J,'IND RESID'!H:H) -> INDRNG | E12: =_xlfn.XLOOKUP(C12,'IND RESID'!J:J,'IND RESID'!I:I) -> INDAINDMD | F12: 1 | G12: =_xlfn.XLOOKUP(C12,'IND RESID'!J:J,'IND RESID'!P:P) -> 31.536 | H12: =_xlfn.XLOOKUP(C12,'IND RESID'!J:J,'IND RESID'!O:O) -> 0.9 | I12: =H12*0.9 -> 0.81 | J12: 25 | L12: =_xlfn.XLOOKUP(C12,'IND RESID'!J:J,'IND RESID'!N:N) -> 2.8497695
B13: =IF(L13=0,"*",Def_Tech!C11) -> * | C13: =Def_Tech!D11 -> INDAINAEUKER19 | D13: =_xlfn.XLOOKUP(C13,'IND RESID'!J:J,'IND RESID'!H:H) -> INDKER | E13: =_xlfn.XLOOKUP(C13,'IND RESID'!J:J,'IND RESID'!I:I) -> INDAINDMD | F13: 1 | G13: =_xlfn.XLOOKUP(C13,'IND RESID'!J:J,'IND RESID'!P:P) -> 31.536 | H13: =_xlfn.XLOOKUP(C13,'IND RESID'!J:J,'IND RESID'!O:O) -> 0.9 | I13: =H13*0.9 -> 0.81 | J13: 25 | L13: =_xlfn.XLOOKUP(C13,'IND RESID'!J:J,'IND RESID'!N:N) -> 0
B14: =IF(L14=0,"*",Def_Tech!C12) -> * | C14: =Def_Tech!D12 -> INDAINAEUWAS19 | D14: =_xlfn.XLOOKUP(C14,'IND RESID'!J:J,'IND RESID'!H:H) -> INDWAS | E14: =_xlfn.XLOOKUP(C14,'IND RESID'!J:J,'IND RESID'!I:I) -> INDAINDMD | F14: 1 | G14: =_xlfn.XLOOKUP(C14,'IND RESID'!J:J,'IND RESID'!P:P) -> 31.536 | H14: =_xlfn.XLOOKUP(C14,'IND RESID'!J:J,'IND RESID'!O:O) -> 0.9 | I14: =H14*0.9 -> 0.81 | J14: 25 | L14: =_xlfn.XLOOKUP(C14,'IND RESID'!J:J,'IND RESID'!N:N) -> 0
B15: =IF(L15=0,"*",Def_Tech!C13) -> * | C15: =Def_Tech!D13 -> INDAINAEUBIO19 | D15: =_xlfn.XLOOKUP(C15,'IND RESID'!J:J,'IND RESID'!H:H) -> INDBIO | E15: =_xlfn.XLOOKUP(C15,'IND RESID'!J:J,'IND RESID'!I:I) -> INDAINDMD | F15: 1 | G15: =_xlfn.XLOOKUP(C15,'IND RESID'!J:J,'IND RESID'!P:P) -> 31.536 | H15: =_xlfn.XLOOKUP(C15,'IND RESID'!J:J,'IND RESID'!O:O) -> 0.9 | I15: =H15*0.9 -> 0.81 | J15: 25 | L15: =_xlfn.XLOOKUP(C15,'IND RESID'!J:J,'IND RESID'!N:N) -> 0
B16: =IF(L16=0,"*",Def_Tech!C14) -> * | C16: =Def_Tech!D14 -> INDAINAEUGSL19 | D16: =_xlfn.XLOOKUP(C16,'IND RESID'!J:J,'IND RESID'!H:H) -> INDGSL | E16: =_xlfn.XLOOKUP(C16,'IND RESID'!J:J,'IND RESID'!I:I) -> INDAINDMD | F16: 1 | G16: =_xlfn.XLOOKUP(C16,'IND RESID'!J:J,'IND RESID'!P:P) -> 31.536 | H16: =_xlfn.XLOOKUP(C16,'IND RESID'!J:J,'IND RESID'!O:O) -> 0.9 | I16: =H16*0.9 -> 0.81 | J16: 25 | L16: =_xlfn.XLOOKUP(C16,'IND RESID'!J:J,'IND RESID'!N:N) -> 0
B17: =IF(L17=0,"*",Def_Tech!C15) -> * | C17: =Def_Tech!D15 -> INDAINAEUDSL19 | D17: =_xlfn.XLOOKUP(C17,'IND RESID'!J:J,'IND RESID'!H:H) -> INDDSL | E17: =_xlfn.XLOOKUP(C17,'IND RESID'!J:J,'IND RESID'!I:I) -> INDAINDMD | F17: 1 | G17: =_xlfn.XLOOKUP(C17,'IND RESID'!J:J,'IND RESID'!P:P) -> 31.536 | H17: =_xlfn.XLOOKUP(C17,'IND RESID'!J:J,'IND RESID'!O:O) -> 0.9 | I17: =H17*0.9 -> 0.81 | J17: 25 | L17: =_xlfn.XLOOKUP(C17,'IND RESID'!J:J,'IND RESID'!N:N) -> 0
B18: =IF(L18=0,"*",Def_Tech!C16) -> CITY | C18: =Def_Tech!D16 -> INDAINAEUSTM19 | D18: =_xlfn.XLOOKUP(C18,'IND RESID'!J:J,'IND RESID'!H:H) -> INDSTM | E18: =_xlfn.XLOOKUP(C18,'IND RESID'!J:J,'IND RESID'!I:I) -> INDAINDMD | F18: 1 | G18: =_xlfn.XLOOKUP(C18,'IND RESID'!J:J,'IND RESID'!P:P) -> 31.536 | H18: =_xlfn.XLOOKUP(C18,'IND RESID'!J:J,'IND RESID'!O:O) -> 0.9 | I18: =H18*0.9 -> 0.81 | J18: 25 | L18: =_xlfn.XLOOKUP(C18,'IND RESID'!J:J,'IND RESID'!N:N) -> 28.892929
B19: =IF(L19=0,"*",Def_Tech!C17) -> CITY | C19: =Def_Tech!D17 -> INDAINAEUELC19 | D19: =_xlfn.XLOOKUP(C19,'IND RESID'!J:J,'IND RESID'!H:H) -> INDELC | E19: =_xlfn.XLOOKUP(C19,'IND RESID'!J:J,'IND RESID'!I:I) -> INDAINDMD | F19: 1 | G19: =_xlfn.XLOOKUP(C19,'IND RESID'!J:J,'IND RESID'!P:P) -> 31.536 | H19: =_xlfn.XLOOKUP(C19,'IND RESID'!J:J,'IND RESID'!O:O) -> 0.9 | I19: =H19*0.9 -> 0.81 | J19: 25 | L19: =_xlfn.XLOOKUP(C19,'IND RESID'!J:J,'IND RESID'!N:N) -> 1132.9877

Sheet >> Parameters
