Workbook

Sheet ReadMe
A1: Generic Comet (GC) TIMES Supply
B3: Sheet color
C4: Raw Data and Parameters
C6: City Specific Data
C8: Post processing for TIMES
C10: Table formatted for TIMES

Sheet >> City Data

Sheet City characteristics
B2: City Basic Data
B4: Calibration methodology | C4: GHG Inventory
B6: A. City Characteristics
B7: Data Item | C7: Value | D7: Units
B8: City Name | C8: New York
B9: Latitude | C9: 40.5
B10: Longitude | C10: -75
B11: County | C11: New York County
B12: State | C12: New York
B13: Census Division | C13: Middle Atlantic
B14: Climate Division | C14: Northeast
B15: Egrid Region | C15: NPCC NYC/Westchester
B16: Area of city (excluding water, natural and agricultural areas) | C16: 778 | D16: square kilometers
B17: * Division and Region Map can be found in the Maps sheet.
B18: B. Planning Base Year and Target Years
B19: Year | C19: Value | D19: Units
B20: Base Year | C20: 2019 | D20: Acceptable range [2018,2021]
B21: End Year | C21: 2050
B23: C. City Population and GDP
B24: Data Item | C24: Value | D24: Units
B25: Population in Base Year | C25: 8337 | D25: Thousand of people
B26: Annual population growth (Base Year - End Year) | C26: 0.5 | D26: % people
B27: GDP in Base Year | C27: 1206000 | D27: Million US$
B28: Annual GDP growth rate | C28: 2 | D28: % US$
B29: Share of manufacturing GDP | C29: 5 | D29: % US$
B30: Share of State population | C30: 0.42835123
B31: Share of State GDP | C31: 0.67251772
B32: Adjustment from state manufacturing GDP | C32: 1.0638298
B34: D. Climate Data
B35: Data Item | C35: 2000 | D35: 2050 | E35: 2100 | F35: Units
B36: Heating degree days (HDD) | C36: 4473.4625 | D36: 4066.4182 | E36: 3763.8582 | F36: F
B37: Cooling degree days (CDD) | C37: 1020.7333 | D37: 1224.2555 | E37: 1375.5355 | F37: F
B39: Data Item | C39: Value | D39: Units
B40: Correction from State HDD | C40: 0.72727402
B41: Correction from State CDD | C41: 1.5583715
B42: Annual precipitation | C42: 762 | D42: mm / year
B43: Climate change scenario | C43: RCP4.5
B44: Average temperature increase in 1980-2020 | C44: 1.4617857 | D44: F
B45: Forecasted average temperature increase in 2035-2065 | C45: 3.13 | D45: F
B46: Forecasted average temperature increase in 2070-2100 | C46: 4.37 | D46: F
...

Sheet >> GC_Resid

Sheet ELC RESID
O1: 2019 | P1: 2020 | Q1: 2025 | R1: 2030 | S1: 2035 | T1: 2040 | U1: 2045 | V1: 2050 | W1: 2055 | X1: 2060 | Y1: 2065 | Z1: 2070 | AA1: 2075 | AB1: 2080 | AC1: 2085 | AD1: 2090 | AE1: 2095 | AF1: 2100 | AG1: 2019 | AH1: 2030 | AI1: 2050 | AJ1: 2100 | AK1: 2019 | AL1: 2030 | AM1: 2050 | AN1: 2100 | AO1: 2019 | AP1: 2030 | AQ1: 2050 | AR1: 2100
A2: Sector | B2: Sub-sector | C2: Archetype | D2: Vintage | E2: End Use | F2: Technology | G2: Energy | H2: Technology Label | I2: Generation (TJ) | J2: Fuel Input (MWh) | K2: Capacity Factor (%) | L2: Efficiency (%) | M2: Fixed OM 2023 US$ / kW . Yr | N2: Variable OM 2023 US$ / GJ | O2: Capacity base year (MW) | P2: Capacity 2020 (MW) | Q2: Capacity 2025 (MW) | R2: Capacity 2030 (MW) | S2: Capacity 2035 (MW) | T2: Capacity 2040 (MW) | U2: Capacity 2045 (MW) | V2: Capacity 2050 (MW) | W2: Capacity 2055 (MW) | X2: Capacity 2060 (MW) | Y2: Capacity 2065 (MW) | Z2: Capacity 2070 (MW) | AA2: Capacity 2075 (MW) | AB2: Capacity 2080 (MW) | AC2: Capacity 2085 (MW) | AD2: Capacity 2090 (MW) | AE2: Capacity 2095 (MW) | AF2: Capacity 2100 (MW) | AG2: Average CO2 emission factor ( t CO2 / TJ) | AH2: Average CO2 emission factor ( t CO2 / TJ) | AI2: Average CO2 emission factor ( t CO2 / TJ) | AJ2: Average CO2 emission factor ( t CO2 / TJ) | AK2: Average CH4 emission factor ( t CH4 / TJ) | AL2: Average CH4 emission factor ( t CH4 / TJ) | AM2: Average CH4 emission factor ( t CH4 / TJ) | AN2: Average CH4 emission factor ( t CH4 / TJ) | AO2: Average N2O emission factor ( t N2O / TJ) | AP2: Average N2O emission factor ( t N2O / TJ) | AQ2: Average N2O emission factor ( t N2O / TJ) | AR2: Average N2O emission factor ( t N2O / TJ)
A3: Electricity | B3: Grid | D3: 2019 | E3: Dispatchable | F3: Combustion turbine | G3: Natural gas | H3: ELCNGAGRDCTU19 | I3: 12173.114 | J3: 34569.709 | K3: 0.13746195 | L3: 0.35213238 | M3: 27.138389 | N3: 2.0228151 | O3: 2808.1 | P3: 1517.2 | Q3: 1517.2 | R3: 1517.2 | S3: 1517.2 | T3: 681.9 | U3: 677.3 | V3: 139.5 | W3: 0 | X3: 0 | Y3: 0 | Z3: 0 | AA3: 0 | AB3: 0 | AC3: 0 | AD3: 0 | AE3: 0 | AF3: 0
A4: Electricity | B4: Grid | D4: 2019 | E4: Dispatchable | F4: Steam turbine | G4: Natural gas | H4: ELCNGAGRDSTU19 | I4: 10774.678 | J4: 29246.467 | K4: 0.084997091 | L4: 0.36840957 | M4: 27.138389 | N4: 2.0228151 | O4: 4019.7 | P4: 16 | Q4: 16 | R4: 16 | S4: 16 | T4: 16 | U4: 16 | V4: 0 | W4: 0 | X4: 0 | Y4: 0 | Z4: 0 | AA4: 0 | AB4: 0 | AC4: 0 | AD4: 0 | AE4: 0 | AF4: 0
A5: Electricity | B5: Grid | D5: 2019 | E5: Dispatchable | F5: Combined cycle combustion turbine | G5: Natural gas | H5: ELCNGAGRDCCC19 | I5: 46780.596 | J5: 91771.957 | K5: 0.64588452 | L5: 0.50974827 | M5: 35.166828 | N5: 0.61563937 | O5: 2296.7 | P5: 2296.7 | Q5: 2296.7 | R5: 1726.5 | S5: 1484.5 | T5: 751 | U5: 400 | V5: 0 | W5: 0 | X5: 0 | Y5: 0 | Z5: 0 | AA5: 0 | AB5: 0 | AC5: 0 | AD5: 0 | AE5: 0 | AF5: 0
A6: Electricity | B6: Grid | D6: 2019 | E6: Dispatchable | F6: Combined cycle steam turbine | G6: Natural gas | H6: ELCNGAGRDCCS19 | I6: 17753.904 | J6: 34991.141 | K6: 0.47892182 | L6: 0.50738283 | M6: 35.166828 | N6: 0.61563937 | O6: 1175.5 | P6: 1173.1 | Q6: 1173.1 | R6: 860.5 | S6: 780.5 | T6: 505 | U6: 250 | V6: 0 | W6: 0 | X6: 0 | Y6: 0 | Z6: 0 | AA6: 0 | AB6: 0 | AC6: 0 | AD6: 0 | AE6: 0 | AF6: 0
A7: Electricity | B7: Grid | D7: 2019 | E7: Dispatchable | F7: Combined cycle - single shaft | G7: Natural gas | H7: ELCNGAGRDACC19 | I7: 0 | J7: 0 | M7: 34.827599 | N7: 0.61563937 | O7: 0 | P7: 0 | Q7: 0 | R7: 0 | S7: 0 | T7: 0 | U7: 0 | V7: 0 | W7: 0 | X7: 0 | Y7: 0 | Z7: 0 | AA7: 0 | AB7: 0 | AC7: 0 | AD7: 0 | AE7: 0 | AF7: 0
A8: Electricity | B8: Grid | D8: 2019 | E8: Dispatchable | F8: Other turbine | G8: Natural gas | H8: ELCNGAGRDOTT19 | I8: 0 | J8: 0 | M8: 34.827599 | N8: 0.61563937 | O8: 0 | P8: 0 | Q8: 0 | R8: 0 | S8: 0 | T8: 0 | U8: 0 | V8: 0 | W8: 0 | X8: 0 | Y8: 0 | Z8: 0 | AA8: 0 | AB8: 0 | AC8: 0 | AD8: 0 | AE8: 0 | AF8: 0
A9: Electricity | B9: Grid | D9: 2019 | E9: Dispatchable | F9: Internal combustion engine | G9: Natural gas | H9: ELCNGAGRDICE19 | I9: 234.73082 | J9: 538.0716 | K9: 0.23406495 | L9: 0.43624458 | M9: 27.138389 | N9: 2.0228151 | O9: 31.8 | P9: 31.8 | Q9: 31.8 | R9: 23.4 | S9: 22.5 | T9: 22.3 | U9: 2.4 | V9: 0 | W9: 0 | X9: 0 | Y9: 0 | Z9: 0 | AA9: 0 | AB9: 0 | AC9: 0 | AD9: 0 | AE9: 0 | AF9: 0
A10: Electricity | B10: Grid | D10: 2019 | E10: Dispatchable | F10: Fuel cell | G10: Natural gas | H10: ELCNGAGRDFCE19 | I10: 192.024 | J10: 392.5061 | K10: 0.92258198 | L10: 0.48922552 | M10: 34.827599 | N10: 0.61563937 | O10: 6.6 | P10: 6.6 | Q10: 6.6 | R10: 6.6 | S10: 6.6 | T10: 6.6 | U10: 6.6 | V10: 6.6 | W10: 0 | X10: 0 | Y10: 0 | Z10: 0 | AA10: 0 | AB10: 0 | AC10: 0 | AD10: 0 | AE10: 0 | AF10: 0
A11: Electricity | B11: Grid | D11: 2019 | E11: Dispatchable | F11: Combustion turbine | G11: RNG | H11: ELCRNGGRDCTU19 | I11: 0 | J11: 0 | M11: 27.138389 | N11: 2.0228151 | O11: 0 | P11: 0 | Q11: 0 | R11: 0 | S11: 0 | T11: 0 | U11: 0 | V11: 0 | W11: 0 | X11: 0 | Y11: 0 | Z11: 0 | AA11: 0 | AB11: 0 | AC11: 0 | AD11: 0 | AE11: 0 | AF11: 0
A12: Electricity | B12: Grid | D12: 2019 | E12: Dispatchable | F12: Steam turbine | G12: RNG | H12: ELCRNGGRDSTU19 | I12: 0 | J12: 0 | M12: 27.138389 | N12: 2.0228151 | O12: 0 | P12: 0 | Q12: 0 | R12: 0 | S12: 0 | T12: 0 | U12: 0 | V12: 0 | W12: 0 | X12: 0 | Y12: 0 | Z12: 0 | AA12: 0 | AB12: 0 | AC12: 0 | AD12: 0 | AE12: 0 | AF12: 0
A13: Electricity | B13: Grid | D13: 2019 | E13: Dispatchable | F13: Combined cycle combustion turbine | G13: RNG | H13: ELCRNGGRDCCC19 | I13: 0 | J13: 0 | M13: 35.166828 | N13: 0.61563937 | O13: 0 | P13: 0 | Q13: 0 | R13: 0 | S13: 0 | T13: 0 | U13: 0 | V13: 0 | W13: 0 | X13: 0 | Y13: 0 | Z13: 0 | AA13: 0 | AB13: 0 | AC13: 0 | AD13: 0 | AE13: 0 | AF13: 0
A14: Electricity | B14: Grid | D14: 2019 | E14: Dispatchable | F14: Combined cycle steam turbine | G14: RNG | H14: ELCRNGGRDCCS19 | I14: 0 | J14: 0 | M14: 35.166828 | N14: 0.61563937 | O14: 0 | P14: 0 | Q14: 0 | R14: 0 | S14: 0 | T14: 0 | U14: 0 | V14: 0 | W14: 0 | X14: 0 | Y14: 0 | Z14: 0 | AA14: 0 | AB14: 0 | AC14: 0 | AD14: 0 | AE14: 0 | AF14: 0
A15: Electricity | B15: Grid | D15: 2019 | E15: Dispatchable | F15: Internal combustion engine | G15: RNG | H15: ELCRNGGRDICE19 | I15: 0 | J15: 0 | M15: 27.138389 | N15: 2.0228151 | O15: 0 | P15: 0 | Q15: 0 | R15: 0 | S15: 0 | T15: 0 | U15: 0 | V15: 0 | W15: 0 | X15: 0 | Y15: 0 | Z15: 0 | AA15: 0 | AB15: 0 | AC15: 0 | AD15: 0 | AE15: 0 | AF15: 0
A16: Electricity | B16: Grid | D16: 2019 | E16: Dispatchable | F16: Fuel cell | G16: RNG | H16: ELCRNGGRDFCE19 | I16: 0 | J16: 0 | M16: 34.827599 | N16: 0.61563937 | O16: 0 | P16: 0 | Q16: 0 | R16: 0 | S16: 0 | T16: 0 | U16: 0 | V16: 0 | W16: 0 | X16: 0 | Y16: 0 | Z16: 0 | AA16: 0 | AB16: 0 | AC16: 0 | AD16: 0 | AE16: 0 | AF16: 0
A17: Electricity | B17: Grid | D17: 2019 | E17: Dispatchable | F17: Combustion turbine | G17: Fuel oil | H17: ELCFOIGRDCTU19 | I17: 16.1352 | J17: 99.921256 | K17: 0.0013132542 | L17: 0.16147915 | M17: 27.138389 | N17: 2.0228151 | O17: 389.6 | P17: 0 | Q17: 0 | R17: 0 | S17: 0 | T17: 0 | U17: 0 | V17: 0 | W17: 0 | X17: 0 | Y17: 0 | Z17: 0 | AA17: 0 | AB17: 0 | AC17: 0 | AD17: 0 | AE17: 0 | AF17: 0
A18: Electricity | B18: Grid | D18: 2019 | E18: Dispatchable | F18: Steam turbine | G18: Fuel oil | H18: ELCFOIGRDSTU19 | I18: 0 | J18: 0 | M18: 27.138389 | N18: 2.0228151 | O18: 0 | P18: 0 | Q18: 0 | R18: 0 | S18: 0 | T18: 0 | U18: 0 | V18: 0 | W18: 0 | X18: 0 | Y18: 0 | Z18: 0 | AA18: 0 | AB18: 0 | AC18: 0 | AD18: 0 | AE18: 0 | AF18: 0
A19: Electricity | B19: Grid | D19: 2019 | E19: Dispatchable | F19: Combined cycle combustion turbine | G19: Fuel oil | H19: ELCFOIGRDCCC19 | I19: 0 | J19: 0 | M19: 35.166828 | N19: 0.61563937 | O19: 0 | P19: 0 | Q19: 0 | R19: 0 | S19: 0 | T19: 0 | U19: 0 | V19: 0 | W19: 0 | X19: 0 | Y19: 0 | Z19: 0 | AA19: 0 | AB19: 0 | AC19: 0 | AD19: 0 | AE19: 0 | AF19: 0
A20: Electricity | B20: Grid | D20: 2019 | E20: Dispatchable | F20: Combined cycle steam turbine | G20: Fuel oil | H20: ELCFOIGRDCCS19 | I20: 0 | J20: 0 | M20: 35.166828 | N20: 0.61563937 | O20: 0 | P20: 0 | Q20: 0 | R20: 0 | S20: 0 | T20: 0 | U20: 0 | V20: 0 | W20: 0 | X20: 0 | Y20: 0 | Z20: 0 | AA20: 0 | AB20: 0 | AC20: 0 | AD20: 0 | AE20: 0 | AF20: 0
A21: Electricity | B21: Grid | D21: 2019 | E21: Dispatchable | F21: Other turbine | G21: Fuel oil | H21: ELCFOIGRDOTT19 | I21: 0 | J21: 0 | M21: 35.166828 | N21: 0.61563937 | O21: 0 | P21: 0 | Q21: 0 | R21: 0 | S21: 0 | T21: 0 | U21: 0 | V21: 0 | W21: 0 | X21: 0 | Y21: 0 | Z21: 0 | AA21: 0 | AB21: 0 | AC21: 0 | AD21: 0 | AE21: 0 | AF21: 0
A22: Electricity | B22: Grid | D22: 2019 | E22: Dispatchable | F22: Internal combustion engine | G22: Fuel oil | H22: ELCFOIGRDICE19 | I22: 8.6313024 | J22: 31.086118 | K22: 0.0012700548 | L22: 0.27765778 | M22: 34.827599 | N22: 0.61563937 | O22: 215.5 | P22: 186.1 | Q22: 178.8 | R22: 172 | S22: 141.7 | T22: 105 | U22: 55.6 | V22: 13 | W22: 0 | X22: 0 | Y22: 0 | Z22: 0 | AA22: 0 | AB22: 0 | AC22: 0 | AD22: 0 | AE22: 0 | AF22: 0
A23: Electricity | B23: Grid | D23: 2019 | E23: Dispatchable | F23: Steam turbine | G23: Coal | H23: ELCCOAGRDSTU19 | I23: 0 | J23: 0 | M23: 87.747456 | N23: 2.6573005 | O23: 0 | P23: 0 | Q23: 0 | R23: 0 | S23: 0 | T23: 0 | U23: 0 | V23: 0 | W23: 0 | X23: 0 | Y23: 0 | Z23: 0 | AA23: 0 | AB23: 0 | AC23: 0 | AD23: 0 | AE23: 0 | AF23: 0
A24: Electricity | B24: Grid | D24: 2019 | E24: Dispatchable | F24: Other turbine | G24: Coal | H24: ELCCOAGRDOTT19 | I24: 0 | J24: 0 | M24: 169.72801 | N24: 4.6392824 | O24: 0 | P24: 0 | Q24: 0 | R24: 0 | S24: 0 | T24: 0 | U24: 0 | V24: 0 | W24: 0 | X24: 0 | Y24: 0 | Z24: 0 | AA24: 0 | AB24: 0 | AC24: 0 | AD24: 0 | AE24: 0 | AF24: 0
A25: Electricity | B25: Grid | D25: 2019 | E25: Dispatchable | F25: Steam turbine | G25: Biomass | H25: ELCBIOGRDSTU19 | I25: 0 | J25: 0 | M25: 177.77906 | N25: 1.5830727 | O25: 0 | P25: 0 | Q25: 0 | R25: 0 | S25: 0 | T25: 0 | U25: 0 | V25: 0 | W25: 0 | X25: 0 | Y25: 0 | Z25: 0 | AA25: 0 | AB25: 0 | AC25: 0 | AD25: 0 | AE25: 0 | AF25: 0
A26: Electricity | B26: Grid | D26: 2019 | E26: Dispatchable | F26: Other turbine | G26: Biomass | H26: ELCBIOGRDOTT19 | I26: 0 | J26: 0 | M26: 177.77906 | N26: 1.5830727 | O26: 0 | P26: 0 | Q26: 0 | R26: 0 | S26: 0 | T26: 0 | U26: 0 | V26: 0 | W26: 0 | X26: 0 | Y26: 0 | Z26: 0 | AA26: 0 | AB26: 0 | AC26: 0 | AD26: 0 | AE26: 0 | AF26: 0
A27: Electricity | B27: Grid | D27: 2019 | E27: Dispatchable | F27: Internal combustion engine | G27: Other bioenergy | H27: ELCOTBGRDICE19 | I27: 0 | J27: 0 | M27: 177.77906 | N27: 1.5830727 | O27: 0 | P27: 0 | Q27: 0 | R27: 0 | S27: 0 | T27: 0 | U27: 0 | V27: 0 | W27: 0 | X27: 0 | Y27: 0 | Z27: 0 | AA27: 0 | AB27: 0 | AC27: 0 | AD27: 0 | AE27: 0 | AF27: 0
A28: Electricity | B28: Grid | D28: 2019 | E28: Dispatchable | F28: Steam turbine | G28: Waste | H28: ELCWASGRDSTU19 | I28: 1357.2108 | J28: 7369.616 | K28: 0.72088563 | L28: 0.18416303 | M28: 177.77906 | N28: 1.5830727 | O28: 59.7 | P28: 59.7 | Q28: 59.7 | R28: 59.7 | S28: 0 | T28: 0 | U28: 0 | V28: 0 | W28: 0 | X28: 0 | Y28: 0 | Z28: 0 | AA28: 0 | AB28: 0 | AC28: 0 | AD28: 0 | AE28: 0 | AF28: 0
A29: Electricity | B29: Grid | D29: 2019 | E29: Dispatchable | F29: Steam turbine | G29: Waste heat | H29: ELCHETGRDSTU19 | I29: 0 | J29: 0 | M29: 177.77906 | N29: 1.5830727 | O29: 0 | P29: 0 | Q29: 0 | R29: 0 | S29: 0 | T29: 0 | U29: 0 | V29: 0 | W29: 0 | X29: 0 | Y29: 0 | Z29: 0 | AA29: 0 | AB29: 0 | AC29: 0 | AD29: 0 | AE29: 0 | AF29: 0
A30: Electricity | B30: Grid | D30: 2019 | E30: Dispatchable | F30: Other turbine | G30: Waste heat | H30: ELCHETGRDOTT19 | I30: 0 | J30: 0 | M30: 177.77906 | N30: 1.5830727 | O30: 0 | P30: 0 | Q30: 0 | R30: 0 | S30: 0 | T30: 0 | U30: 0 | V30: 0 | W30: 0 | X30: 0 | Y30: 0 | Z30: 0 | AA30: 0 | AB30: 0 | AC30: 0 | AD30: 0 | AE30: 0 | AF30: 0
A31: Electricity | B31: Grid | D31: 2019 | E31: Dispatchable | F31: Steam turbine | G31: Steam | H31: ELCSTMGRDSTU19 | I31: 0 | J31: 0 | M31: 177.77906 | N31: 1.5830727 | O31: 0 | P31: 0 | Q31: 0 | R31: 0 | S31: 0 | T31: 0 | U31: 0 | V31: 0 | W31: 0 | X31: 0 | Y31: 0 | Z31: 0 | AA31: 0 | AB31: 0 | AC31: 0 | AD31: 0 | AE31: 0 | AF31: 0
A32: Electricity | B32: Grid | D32: 2019 | E32: Dispatchable | F32: Steam turbine | G32: Uranium | H32: ELCURNGRDSTU19 | I32: 60101.435 | J32: 182125.56 | K32: 0.82466638 | L32: 0.33 | M32: 172.01215 | N32: 0.77583125 | O32: 2311 | P32: 2311 | Q32: 0 | R32: 0 | S32: 0 | T32: 0 | U32: 0 | V32: 0 | W32: 0 | X32: 0 | Y32: 0 | Z32: 0 | AA32: 0 | AB32: 0 | AC32: 0 | AD32: 0 | AE32: 0 | AF32: 0
A33: Electricity | B33: Grid | D33: 2019 | E33: Storage | F33: Compressed air energy storage | G33: Storage | H33: ELCSTGGRDCES19 | I33: 0 | J33: 0 | M33: 44.870272 | N33: 0 | O33: 0 | P33: 0 | Q33: 0 | R33: 0 | S33: 0 | T33: 0 | U33: 0 | V33: 0 | W33: 0 | X33: 0 | Y33: 0 | Z33: 0 | AA33: 0 | AB33: 0 | AC33: 0 | AD33: 0 | AE33: 0 | AF33: 0
A34: Electricity | B34: Grid | D34: 2019 | E34: Storage | F34: Flywheel energy storage | G34: Storage | H34: ELCSTGGRDFES19 | I34: 0 | J34: 0 | M34: 44.870272 | N34: 0 | O34: 0 | P34: 0 | Q34: 0 | R34: 0 | S34: 0 | T34: 0 | U34: 0 | V34: 0 | W34: 0 | X34: 0 | Y34: 0 | Z34: 0 | AA34: 0 | AB34: 0 | AC34: 0 | AD34: 0 | AE34: 0 | AF34: 0
A35: Electricity | B35: Grid | D35: 2019 | E35: Storage | F35: Battery energy storage | G35: Storage | H35: ELCSTGGRDBES19 | I35: 0 | J35: 0 | L35: 0.8 | M35: 44.870272 | N35: 0 | O35: 0 | P35: 0 | Q35: 0 | R35: 0 | S35: 0 | T35: 0 | U35: 0 | V35: 0 | W35: 0 | X35: 0 | Y35: 0 | Z35: 0 | AA35: 0 | AB35: 0 | AC35: 0 | AD35: 0 | AE35: 0 | AF35: 0
A36: Electricity | B36: Grid | D36: 2019 | E36: Baseload | F36: Steam turbine | G36: Geothermal | H36: ELCGEOGRDSTU19 | I36: 0 | J36: 0 | L36: 1 | M36: 170.80991 | N36: 0 | O36: 0 | P36: 0 | Q36: 0 | R36: 0 | S36: 0 | T36: 0 | U36: 0 | V36: 0 | W36: 0 | X36: 0 | Y36: 0 | Z36: 0 | AA36: 0 | AB36: 0 | AC36: 0 | AD36: 0 | AE36: 0 | AF36: 0
A37: Electricity | B37: Grid | D37: 2019 | E37: Baseload | F37: Binary cycle turbine | G37: Geothermal | H37: ELCGEOGRDBCT19 | I37: 0 | J37: 0 | L37: 1 | M37: 128.47969 | N37: 0 | O37: 0 | P37: 0 | Q37: 0 | R37: 0 | S37: 0 | T37: 0 | U37: 0 | V37: 0 | W37: 0 | X37: 0 | Y37: 0 | Z37: 0 | AA37: 0 | AB37: 0 | AC37: 0 | AD37: 0 | AE37: 0 | AF37: 0
A38: Electricity | B38: Grid | D38: 2019 | E38: Non Dispatchable | F38: Wind turbine - onshore | G38: Wind | H38: ELCWNDGRDWON19 | I38: 0 | J38: 0 | L38: 1 | M38: 34.974598 | N38: 0 | O38: 0 | P38: 0 | Q38: 0 | R38: 0 | S38: 0 | T38: 0 | U38: 0 | V38: 0 | W38: 0 | X38: 0 | Y38: 0 | Z38: 0 | AA38: 0 | AB38: 0 | AC38: 0 | AD38: 0 | AE38: 0 | AF38: 0
A39: Electricity | B39: Grid | D39: 2019 | E39: Non Dispatchable | F39: Wind turbine - offshore | G39: Wind | H39: ELCWNDGRDWOF19 | I39: 0 | J39: 0 | L39: 1 | M39: 112.55896 | N39: 0 | O39: 0 | P39: 0 | Q39: 0 | R39: 0 | S39: 0 | T39: 0 | U39: 0 | V39: 0 | W39: 0 | X39: 0 | Y39: 0 | Z39: 0 | AA39: 0 | AB39: 0 | AC39: 0 | AD39: 0 | AE39: 0 | AF39: 0
A40: Electricity | B40: Grid | D40: 2019 | E40: Storage | F40: Hydraulic turbine - reversible | G40: Storage | H40: ELCSTGGRDHES19 | I40: 0 | J40: 0 | L40: 0.7 | M40: 21.100097 | N40: 0.16961493 | O40: 0 | P40: 0 | Q40: 0 | R40: 0 | S40: 0 | T40: 0 | U40: 0 | V40: 0 | W40: 0 | X40: 0 | Y40: 0 | Z40: 0 | AA40: 0 | AB40: 0 | AC40: 0 | AD40: 0 | AE40: 0 | AF40: 0
...

Sheet Demand
A1: Sector | B1: Sub-sector | C1: Archetype | D1: Vintage | E1: Demand Label | F1: Unit | G1: 2019 | H1: 2020 | I1: 2025 | J1: 2030 | K1: 2035 | L1: 2040 | M1: 2045 | N1: 2050 | O1: 2055 | P1: 2060 | Q1: 2065 | R1: 2070 | S1: 2075 | T1: 2080 | U1: 2085 | V1: 2090 | W1: 2095 | X1: 2100
A2: Commercial | B2: Hotel | D2: Old | E2: COMHOTOldDMD | F2: Mm2 | G2: 11.978701 | H2: 11.978701 | I2: 11.978701 | J2: 11.978701 | K2: 11.978701 | L2: 11.978701 | M2: 11.978701 | N2: 11.978701 | O2: 11.978701 | P2: 11.978701 | Q2: 11.978701 | R2: 11.978701 | S2: 11.978701 | T2: 11.978701 | U2: 11.978701 | V2: 11.978701 | W2: 11.978701 | X2: 11.978701
A3: Commercial | B3: Retail | D3: Old | E3: COMRETOldDMD | F3: Mm2 | G3: 23.081056 | H3: 23.081056 | I3: 23.081056 | J3: 23.081056 | K3: 23.081056 | L3: 23.081056 | M3: 23.081056 | N3: 23.081056 | O3: 23.081056 | P3: 23.081056 | Q3: 23.081056 | R3: 23.081056 | S3: 23.081056 | T3: 23.081056 | U3: 23.081056 | V3: 23.081056 | W3: 23.081056 | X3: 23.081056
A4: Commercial | B4: Office | D4: Old | E4: COMOFFOldDMD | F4: Mm2 | G4: 73.164819 | H4: 73.164819 | I4: 73.164819 | J4: 73.164819 | K4: 73.164819 | L4: 73.164819 | M4: 73.164819 | N4: 73.164819 | O4: 73.164819 | P4: 73.164819 | Q4: 73.164819 | R4: 73.164819 | S4: 73.164819 | T4: 73.164819 | U4: 73.164819 | V4: 73.164819 | W4: 73.164819 | X4: 73.164819
A5: Commercial | B5: Hospital | D5: Old | E5: COMHOPOldDMD | F5: Mm2 | G5: 44.382259 | H5: 44.382259 | I5: 44.382259 | J5: 44.382259 | K5: 44.382259 | L5: 44.382259 | M5: 44.382259 | N5: 44.382259 | O5: 44.382259 | P5: 44.382259 | Q5: 44.382259 | R5: 44.382259 | S5: 44.382259 | T5: 44.382259 | U5: 44.382259 | V5: 44.382259 | W5: 44.382259 | X5: 44.382259
A6: Commercial | B6: Educationnal | D6: Old | E6: COMEDUOldDMD | F6: Mm2 | G6: 48.565496 | H6: 48.565496 | I6: 48.565496 | J6: 48.565496 | K6: 48.565496 | L6: 48.565496 | M6: 48.565496 | N6: 48.565496 | O6: 48.565496 | P6: 48.565496 | Q6: 48.565496 | R6: 48.565496 | S6: 48.565496 | T6: 48.565496 | U6: 48.565496 | V6: 48.565496 | W6: 48.565496 | X6: 48.565496
A7: Commercial | B7: Warehouse | D7: Old | E7: COMWAROldDMD | F7: Mm2 | G7: 32.733587 | H7: 32.733587 | I7: 32.733587 | J7: 32.733587 | K7: 32.733587 | L7: 32.733587 | M7: 32.733587 | N7: 32.733587 | O7: 32.733587 | P7: 32.733587 | Q7: 32.733587 | R7: 32.733587 | S7: 32.733587 | T7: 32.733587 | U7: 32.733587 | V7: 32.733587 | W7: 32.733587 | X7: 32.733587
A8: Commercial | B8: Municipal | D8: Old | E8: COMMUNOldDMD | F8: Mm2 | G8: 16.841333 | H8: 16.841333 | I8: 16.841333 | J8: 16.841333 | K8: 16.841333 | L8: 16.841333 | M8: 16.841333 | N8: 16.841333 | O8: 16.841333 | P8: 16.841333 | Q8: 16.841333 | R8: 16.841333 | S8: 16.841333 | T8: 16.841333 | U8: 16.841333 | V8: 16.841333 | W8: 16.841333 | X8: 16.841333
A9: Commercial | B9: Other | D9: Old | E9: COMOTHOldDMD | F9: Mm2 | G9: 8.7602804 | H9: 8.7602804 | I9: 8.7602804 | J9: 8.7602804 | K9: 8.7602804 | L9: 8.7602804 | M9: 8.7602804 | N9: 8.7602804 | O9: 8.7602804 | P9: 8.7602804 | Q9: 8.7602804 | R9: 8.7602804 | S9: 8.7602804 | T9: 8.7602804 | U9: 8.7602804 | V9: 8.7602804 | W9: 8.7602804 | X9: 8.7602804
A10: Commercial | B10: Hotel | D10: New | E10: COMHOTNewDMD | F10: Mm2 | G10: 0 | H10: 0.23957402 | I10: 1.4374441 | J10: 2.6353143 | K10: 3.8331844 | L10: 5.0310545 | M10: 6.2289246 | N10: 7.4267947 | O10: 8.6246649 | P10: 9.822535 | Q10: 11.020405 | R10: 12.218275 | S10: 13.416145 | T10: 14.614015 | U10: 15.811886 | V10: 17.009756 | W10: 18.207626 | X10: 19.405496
A11: Commercial | B11: Retail | D11: New | E11: COMRETNewDMD | F11: Mm2 | G11: 0 | H11: 0.46162113 | I11: 2.7697268 | J11: 5.0778324 | K11: 7.3859381 | L11: 9.6940437 | M11: 12.002149 | N11: 14.310255 | O11: 16.618361 | P11: 18.926466 | Q11: 21.234572 | R11: 23.542678 | S11: 25.850783 | T11: 28.158889 | U11: 30.466995 | V11: 32.7751 | W11: 35.083206 | X11: 37.391311
A12: Commercial | B12: Office | D12: New | E12: COMOFFNewDMD | F12: Mm2 | G12: 0 | H12: 1.4632964 | I12: 8.7797783 | J12: 16.09626 | K12: 23.412742 | L12: 30.729224 | M12: 38.045706 | N12: 45.362188 | O12: 52.67867 | P12: 59.995152 | Q12: 67.311633 | R12: 74.628115 | S12: 81.944597 | T12: 89.261079 | U12: 96.577561 | V12: 103.89404 | W12: 111.21052 | X12: 118.52701
A13: Commercial | B13: Hospital | D13: New | E13: COMHOPNewDMD | F13: Mm2 | G13: 0 | H13: 0.88764519 | I13: 5.3258711 | J13: 9.764097 | K13: 14.202323 | L13: 18.640549 | M13: 23.078775 | N13: 27.517001 | O13: 31.955227 | P13: 36.393453 | Q13: 40.831679 | R13: 45.269904 | S13: 49.70813 | T13: 54.146356 | U13: 58.584582 | V13: 63.022808 | W13: 67.461034 | X13: 71.89926
... A17: Commercial | B17: Other | D17: New | E17: COMOTHNewDMD | F17: Mm2 | G17: 0 | H17: 0.17520561 | I17: 1.0512337 | J17: 1.9272617 | K17: 2.8032897 | L17: 3.6793178 | M17: 4.5553458 | N17: 5.4313739 | O17: 6.3074019 | P17: 7.18343 | Q17: 8.059458 | R17: 8.9354861 | S17: 9.8115141 | T17: 10.687542 | U17: 11.56357 | V17: 12.439598 | W17: 13.315626 | X17: 14.191654
A18: Residential | B18: Apartment | C18: Low Income | D18: Old | E18: RESAPALOOldDMD | F18: Mm2 | G18: 51.807877 | H18: 51.807877 | I18: 51.807877 | J18: 51.807877 | K18: 51.807877 | L18: 51.807877 | M18: 51.807877 | N18: 51.807877 | O18: 51.807877 | P18: 51.807877 | Q18: 51.807877 | R18: 51.807877 | S18: 51.807877 | T18: 51.807877 | U18: 51.807877 | V18: 51.807877 | W18: 51.807877 | X18: 51.807877
A19: Residential | B19: House | C19: Low Income | D19: Old | E19: RESHOULOOldDMD | F19: Mm2 | G19: 14.956798 | H19: 14.956798 | I19: 14.956798 | J19: 14.956798 | K19: 14.956798 | L19: 14.956798 | M19: 14.956798 | N19: 14.956798 | O19: 14.956798 | P19: 14.956798 | Q19: 14.956798 | R19: 14.956798 | S19: 14.956798 | T19: 14.956798 | U19: 14.956798 | V19: 14.956798 | W19: 14.956798 | X19: 14.956798
A20: Residential | B20: Apartment | C20: Lower-Middle Income | D20: Old | E20: RESAPALMOldDMD | F20: Mm2 | G20: 57.121976 | H20: 57.121976 | I20: 57.121976 | J20: 57.121976 | K20: 57.121976 | L20: 57.121976 | M20: 57.121976 | N20: 57.121976 | O20: 57.121976 | P20: 57.121976 | Q20: 57.121976 | R20: 57.121976 | S20: 57.121976 | T20: 57.121976 | U20: 57.121976 | V20: 57.121976 | W20: 57.121976 | X20: 57.121976
A21: Residential | B21: House | C21: Lower-Middle Income | D21: Old | E21: RESHOULMOldDMD | F21: Mm2 | G21: 38.299259 | H21: 38.299259 | I21: 38.299259 | J21: 38.299259 | K21: 38.299259 | L21: 38.299259 | M21: 38.299259 | N21: 38.299259 | O21: 38.299259 | P21: 38.299259 | Q21: 38.299259 | R21: 38.299259 | S21: 38.299259 | T21: 38.299259 | U21: 38.299259 | V21: 38.299259 | W21: 38.299259 | X21: 38.299259
A22: Residential | B22: Apartment | C22: Upper-Middle Income | D22: Old | E22: RESAPAUMOldDMD | F22: Mm2 | G22: 15.495888 | H22: 15.495888 | I22: 15.495888 | J22: 15.495888 | K22: 15.495888 | L22: 15.495888 | M22: 15.495888 | N22: 15.495888 | O22: 15.495888 | P22: 15.495888 | Q22: 15.495888 | R22: 15.495888 | S22: 15.495888 | T22: 15.495888 | U22: 15.495888 | V22: 15.495888 | W22: 15.495888 | X22: 15.495888
A23: Residential | B23: House | C23: Upper-Middle Income | D23: Old | E23: RESHOUUMOldDMD | F23: Mm2 | G23: 19.187214 | H23: 19.187214 | I23: 19.187214 | J23: 19.187214 | K23: 19.187214 | L23: 19.187214 | M23: 19.187214 | N23: 19.187214 | O23: 19.187214 | P23: 19.187214 | Q23: 19.187214 | R23: 19.187214 | S23: 19.187214 | T23: 19.187214 | U23: 19.187214 | V23: 19.187214 | W23: 19.187214 | X23: 19.187214
A24: Residential | B24: Apartment | C24: High Income | D24: Old | E24: RESAPAHIOldDMD | F24: Mm2 | G24: 66.398717 | H24: 66.398717 | I24: 66.398717 | J24: 66.398717 | K24: 66.398717 | L24: 66.398717 | M24: 66.398717 | N24: 66.398717 | O24: 66.398717 | P24: 66.398717 | Q24: 66.398717 | R24: 66.398717 | S24: 66.398717 | T24: 66.398717 | U24: 66.398717 | V24: 66.398717 | W24: 66.398717 | X24: 66.398717
A25: Residential | B25: House | C25: High Income | D25: Old | E25: RESHOUHIOldDMD | F25: Mm2 | G25: 96.552051 | H25: 96.552051 | I25: 96.552051 | J25: 96.552051 | K25: 96.552051 | L25: 96.552051 | M25: 96.552051 | N25: 96.552051 | O25: 96.552051 | P25: 96.552051 | Q25: 96.552051 | R25: 96.552051 | S25: 96.552051 | T25: 96.552051 | U25: 96.552051 | V25: 96.552051 | W25: 96.552051 | X25: 96.552051
A26: Residential | B26: Apartment | C26: Low Income | D26: New | E26: RESAPALONewDMD | F26: Mm2 | G26: 0 | H26: 0.25903939 | I26: 1.5542363 | J26: 2.8494333 | K26: 4.1446302 | L26: 5.4398271 | M26: 6.7350241 | N26: 8.030221 | O26: 9.3254179 | P26: 10.620615 | Q26: 11.915812 | R26: 13.211009 | S26: 14.506206 | T26: 15.801403 | U26: 17.0966 | V26: 18.391797 | W26: 19.686993 | X26: 20.98219
A27: Residential | B27: House | C27: Low Income | D27: New | E27: RESHOULONewDMD | F27: Mm2 | G27: 0 | H27: 0.07478399 | I27: 0.44870394 | J27: 0.82262389 | K27: 1.1965438 | L27: 1.5704638 | M27: 1.9443837 | N27: 2.3183037 | O27: 2.6922236 | P27: 3.0661436 | Q27: 3.4400635 | R27: 3.8139835 | S27: 4.1879034 | T27: 4.5618234 | U27: 4.9357433 | V27: 5.3096633 | W27: 5.6835832 | X27: 6.0575032
A28: Residential | B28: Apartment | C28: Lower-Middle Income | D28: New | E28: RESAPALMNewDMD | F28: Mm2 | G28: 0 | H28: 0.28560988 | I28: 1.7136593 | J28: 3.1417087 | K28: 4.5697581 | L28: 5.9978075 | M28: 7.4258569 | N28: 8.8539063 | O28: 10.281956 | P28: 11.710005 | Q28: 13.138055 | R28: 14.566104 | S28: 15.994153 | T28: 17.422203 | U28: 18.850252 | V28: 20.278302 | W28: 21.706351 | X28: 23.1344
A29: Residential | B29: House | C29: Lower-Middle Income | D29: New | E29: RESHOULMNewDMD | F29: Mm2 | G29: 0 | H29: 0.19149629 | I29: 1.1489778 | J29: 2.1064592 | K29: 3.0639407 | L29: 4.0214222 | M29: 4.9789036 | N29: 5.9363851 | O29: 6.8938665 | P29: 7.851348 | Q29: 8.8088295 | R29: 9.7663109 | S29: 10.723792 | T29: 11.681274 | U29: 12.638755 | V29: 13.596237 | W29: 14.553718 | X29: 15.5112
... A33: Residential | B33: House | C33: High Income | D33: New | E33: RESHOUHINewDMD | F33: Mm2 | G33: 0 | H33: 0.48276025 | I33: 2.8965615 | J33: 5.3103628 | K33: 7.7241641 | L33: 10.137965 | M33: 12.551767 | N33: 14.965568 | O33: 17.379369 | P33: 19.79317 | Q33: 22.206972 | R33: 24.620773 | S33: 27.034574 | T33: 29.448376 | U33: 31.862177 | V33: 34.275978 | W33: 36.689779 | X33: 39.103581
A34: Industrial | B34: All Industries | E34: INDAINDMD | F34: TJ | G34: 66716.461 | H34: 68050.79 | I34: 74855.869 | J34: 82341.456 | K34: 90575.602 | L34: 99633.162 | M34: 109596.48 | N34: 120556.13 | O34: 132611.74 | P34: 145872.91 | Q34: 160460.2 | R34: 176506.22 | S34: 194156.85 | T34: 213572.53 | U34: 234929.78 | V34: 258422.76 | W34: 284265.04 | X34: 312691.54
A35: Transportation | B35: Passenger | C35: Passenger Car | E35: TRAPASCARDMD | F35: M Vkm | G35: 68921.251 | H35: 69265.857 | I35: 70997.504 | J35: 72772.441 | K35: 74591.752 | L35: 76456.546 | M35: 78367.96 | N35: 80327.159 | O35: 82335.338 | P35: 84393.721 | Q35: 86503.564 | R35: 88666.153 | S35: 90882.807 | T35: 93154.877 | U35: 95483.749 | V35: 97870.843 | W35: 100317.61 | X35: 102825.55
A36: Transportation | B36: Passenger | C36: Passenger Truck | E36: TRAPASLDTDMD | F36: M Vkm | G36: 0 | H36: 0 | I36: 0 | J36: 0 | K36: 0 | L36: 0 | M36: 0 | N36: 0 | O36: 0 | P36: 0 | Q36: 0 | R36: 0 | S36: 0 | T36: 0 | U36: 0 | V36: 0 | W36: 0 | X36: 0
A37: Transportation | B37: Passenger | C37: Motorcycle | E37: TRAPASMOTDMD | F37: M Vkm | G37: 0 | H37: 0 | I37: 0 | J37: 0 | K37: 0 | L37: 0 | M37: 0 | N37: 0 | O37: 0 | P37: 0 | Q37: 0 | R37: 0 | S37: 0 | T37: 0 | U37: 0 | V37: 0 | W37: 0 | X37: 0
A38: Transportation | B38: Freight | C38: Light Commercial Truck | E38: TRAFRECLTDMD | F38: M Vkm | G38: 1578.5179 | H38: 1586.4105 | I38: 1626.0707 | J38: 1666.7225 | K38: 1708.3906 | L38: 1751.1003 | M38: 1794.8778 | N38: 1839.7498 | O38: 1885.7435 | P38: 1932.8871 | Q38: 1981.2093 | R38: 2030.7395 | S38: 2081.508 | T38: 2133.5457 | U38: 2186.8844 | V38: 2241.5565 | W38: 2297.5954 | X38: 2355.0353
A39: Transportation | B39: Freight | C39: Refuse Truck | E39: TRAFRERFTDMD | F39: M Vkm | G39: 70.026308 | H39: 70.37644 | I39: 72.135851 | J39: 73.939247 | K39: 75.787728 | L39: 77.682421 | M39: 79.624482 | N39: 81.615094 | O39: 83.655471 | P39: 85.746858 | Q39: 87.89053 | R39: 90.087793 | S39: 92.339988 | T39: 94.648487 | U39: 97.0147 | V39: 99.440067 | W39: 101.92607 | X39: 104.47422
A40: Transportation | B40: Freight | C40: Single Unit Long-haul Truck | E40: TRAFRESLHDMD | F40: M Vkm | G40: 0 | H40: 0 | I40: 0 | J40: 0 | K40: 0 | L40: 0 | M40: 0 | N40: 0 | O40: 0 | P40: 0 | Q40: 0 | R40: 0 | S40: 0 | T40: 0 | U40: 0 | V40: 0 | W40: 0 | X40: 0
A41: Transportation | B41: Freight | C41: Single Unit Short-haul Truck | E41: TRAFRESSHDMD | F41: M Vkm | G41: 0 | H41: 0 | I41: 0 | J41: 0 | K41: 0 | L41: 0 | M41: 0 | N41: 0 | O41: 0 | P41: 0 | Q41: 0 | R41: 0 | S41: 0 | T41: 0 | U41: 0 | V41: 0 | W41: 0 | X41: 0
A42: Transportation | B42: Freight | C42: Combination Long-haul Truck | E42: TRAFRECLHDMD | F42: M Vkm | G42: 1367.6202 | H42: 1374.4583 | I42: 1408.8197 | J42: 1444.0402 | K42: 1480.1412 | L42: 1517.1447 | M42: 1555.0734 | N42: 1593.9502 | O42: 1633.7989 | P42: 1674.6439 | Q42: 1716.51 | R42: 1759.4228 | S42: 1803.4083 | T42: 1848.4935 | U42: 1894.7059 | V42: 1942.0735 | W42: 1990.6254 | X42: 2040.391
A43: Transportation | B43: Freight | C43: Combination Short-haul Truck | E43: TRAFRECSHDMD | F43: M Vkm | G43: 0 | H43: 0 | I43: 0 | J43: 0 | K43: 0 | L43: 0 | M43: 0 | N43: 0 | O43: 0 | P43: 0 | Q43: 0 | R43: 0 | S43: 0 | T43: 0 | U43: 0 | V43: 0 | W43: 0 | X43: 0
A44: Transportation | B44: Passenger | C44: Transit Bus | E44: TRAPASTBUDMD | F44: M Vkm | G44: 498.20419 | H44: 500.69521 | I44: 513.21259 | J44: 526.0429 | K44: 539.19397 | L44: 552.67382 | M44: 566.49067 | N44: 580.65294 | O44: 595.16926 | P44: 610.04849 | Q44: 625.2997 | R44: 640.93219 | S44: 656.9555 | T44: 673.37939 | U44: 690.21387 | V44: 707.46922 | W44: 725.15595 | X44: 743.28485
A45: Transportation | B45: Passenger | C45: School Bus | E45: TRAPASSBUDMD | F45: M Vkm | G45: 86.053217 | H45: 86.483483 | I45: 88.645571 | J45: 90.86171 | K45: 93.133253 | L45: 95.461584 | M45: 97.848123 | N45: 100.29433 | O45: 102.80168 | P45: 105.37173 | Q45: 108.00602 | R45: 110.70617 | S45: 113.47382 | T45: 116.31067 | U45: 119.21844 | V45: 122.1989 | W45: 125.25387 | X45: 128.38522
A46: Transportation | B46: Passenger | C46: Other Buses | E46: TRAPASOBUDMD | F46: M Vkm | G46: 0 | H46: 0 | I46: 0 | J46: 0 | K46: 0 | L46: 0 | M46: 0 | N46: 0 | O46: 0 | P46: 0 | Q46: 0 | R46: 0 | S46: 0 | T46: 0 | U46: 0 | V46: 0 | W46: 0 | X46: 0
...

Sheet >> TIMES

Sheet Def_Tech
B2: ~FI_Process
B3: Sets | C3: Region | D3: TechName | E3: TechDesc | F3: Tact | G3: Tcap | H3: Tslvl | I3: PrimaryCG | J3: Vintage
B4: *Process Set Membership | C4: Region | D4: Technology Name | E4: Technology Description | F4: Activity Unit | G4: Capacity Unit | H4: TimeSlice level of Process Activity | I4: Primary Commodity Group | J4: Vintage Tracking
B5: {=IF(SUMPRODUCT(('ELC RESID'!O3:AF51)*('ELC RESID'!H3:H51=D5))=0,"*",IF(_xlfn.XLOOKUP($D5,'ELC RESID'!$H:$H,'ELC RESID'!$E:$E)="Storage","STG",IF(_xlfn.XLOOKUP($D5,'ELC RESID'!$H:$H,'ELC RESID'!$E:$E)="Import","IMP","ELE")))} -> ELE | C5: =IF(_xlfn.XLOOKUP(D5,'ELC RESID'!H:H,'ELC RESID'!B:B)="Decentralized","CITY","EGRID") -> EGRID | D5: ='ELC RESID'!H3 -> ELCNGAGRDCTU19 | E5: ='ELC RESID'!A3&" "&'ELC RESID'!B3&" "&'ELC RESID'!D3&" "&'ELC RESID'!F3&" "&'ELC RESID'!G3 -> Electricity Grid 2019 Combustion turbine Natural gas | F5: TJ | G5: MW | H5: DAYNITE
B6: {=IF(SUMPRODUCT(('ELC RESID'!O4:AF52)*('ELC RESID'!H4:H52=D6))=0,"*",IF(_xlfn.XLOOKUP($D6,'ELC RESID'!$H:$H,'ELC RESID'!$E:$E)="Storage","STG",IF(_xlfn.XLOOKUP($D6,'ELC RESID'!$H:$H,'ELC RESID'!$E:$E)="Import","IMP","ELE")))} -> ELE | C6: =IF(_xlfn.XLOOKUP(D6,'ELC RESID'!H:H,'ELC RESID'!B:B)="Decentralized","CITY","EGRID") -> EGRID | D6: ='ELC RESID'!H4 -> ELCNGAGRDSTU19 | E6: ='ELC RESID'!A4&" "&'ELC RESID'!B4&" "&'ELC RESID'!D4&" "&'ELC RESID'!F4&" "&'ELC RESID'!G4 -> Electricity Grid 2019 Steam turbine Natural gas | F6: TJ | G6: MW | H6: DAYNITE
B7: {=IF(SUMPRODUCT(('ELC RESID'!O5:AF53)*('ELC RESID'!H5:H53=D7))=0,"*",IF(_xlfn.XLOOKUP($D7,'ELC RESID'!$H:$H,'ELC RESID'!$E:$E)="Storage","STG",IF(_xlfn.XLOOKUP($D7,'ELC RESID'!$H:$H,'ELC RESID'!$E:$E)="Import","IMP","ELE")))} -> ELE | C7: =IF(_xlfn.XLOOKUP(D7,'ELC RESID'!H:H,'ELC RESID'!B:B)="Decentralized","CITY","EGRID") -> EGRID | D7: ='ELC RESID'!H5 -> ELCNGAGRDCCC19 | E7: ='ELC RESID'!A5&" "&'ELC RESID'!B5&" "&'ELC RESID'!D5&" "&'ELC RESID'!F5&" "&'ELC RESID'!G5 -> Electricity Grid 2019 Combined cycle combustion turbine Natural gas | F7: TJ | G7: MW | H7: DAYNITE
B8: {=IF(SUMPRODUCT(('ELC RESID'!O6:AF54)*('ELC RESID'!H6:H54=D8))=0,"*",IF(_xlfn.XLOOKUP($D8,'ELC RESID'!$H:$H,'ELC RESID'!$E:$E)="Storage","STG",IF(_xlfn.XLOOKUP($D8,'ELC RESID'!$H:$H,'ELC RESID'!$E:$E)="Import","IMP","ELE")))} -> ELE | C8: =IF(_xlfn.XLOOKUP(D8,'ELC RESID'!H:H,'ELC RESID'!B:B)="Decentralized","CITY","EGRID") -> EGRID | D8: ='ELC RESID'!H6 -> ELCNGAGRDCCS19 | E8: ='ELC RESID'!A6&" "&'ELC RESID'!B6&" "&'ELC RESID'!D6&" "&'ELC RESID'!F6&" "&'ELC RESID'!G6 -> Electricity Grid 2019 Combined cycle steam turbine Natural gas | F8: TJ | G8: MW | H8: DAYNITE
B9: {=IF(SUMPRODUCT(('ELC RESID'!O7:AF55)*('ELC RESID'!H7:H55=D9))=0,"*",IF(_xlfn.XLOOKUP($D9,'ELC RESID'!$H:$H,'ELC RESID'!$E:$E)="Storage","STG",IF(_xlfn.XLOOKUP($D9,'ELC RESID'!$H:$H,'ELC RESID'!$E:$E)="Import","IMP","ELE")))} -> * | C9: =IF(_xlfn.XLOOKUP(D9,'ELC RESID'!H:H,'ELC RESID'!B:B)="Decentralized","CITY","EGRID") -> EGRID | D9: ='ELC RESID'!H7 -> ELCNGAGRDACC19 | E9: ='ELC RESID'!A7&" "&'ELC RESID'!B7&" "&'ELC RESID'!D7&" "&'ELC RESID'!F7&" "&'ELC RESID'!G7 -> Electricity Grid 2019 Combined cycle - single shaft Natural gas | F9: TJ | G9: MW | H9: DAYNITE
B10: {=IF(SUMPRODUCT(('ELC RESID'!O8:AF56)*('ELC RESID'!H8:H56=D10))=0,"*",IF(_xlfn.XLOOKUP($D10,'ELC RESID'!$H:$H,'ELC RESID'!$E:$E)="Storage","STG",IF(_xlfn.XLOOKUP($D10,'ELC RESID'!$H:$H,'ELC RESID'!$E:$E)="Import","IMP","ELE")))} -> * | C10: =IF(_xlfn.XLOOKUP(D10,'ELC RESID'!H:H,'ELC RESID'!B:B)="Decentralized","CITY","EGRID") -> EGRID | D10: ='ELC RESID'!H8 -> ELCNGAGRDOTT19 | E10: ='ELC RESID'!A8&" "&'ELC RESID'!B8&" "&'ELC RESID'!D8&" "&'ELC RESID'!F8&" "&'ELC RESID'!G8 -> Electricity Grid 2019 Other turbine Natural gas | F10: TJ | G10: MW | H10: DAYNITE
B11: {=IF(SUMPRODUCT(('ELC RESID'!O9:AF57)*('ELC RESID'!H9:H57=D11))=0,"*",IF(_xlfn.XLOOKUP($D11,'ELC RESID'!$H:$H,'ELC RESID'!$E:$E)="Storage","STG",IF(_xlfn.XLOOKUP($D11,'ELC RESID'!$H:$H,'ELC RESID'!$E:$E)="Import","IMP","ELE")))} -> ELE | C11: =IF(_xlfn.XLOOKUP(D11,'ELC RESID'!H:H,'ELC RESID'!B:B)="Decentralized","CITY","EGRID") -> EGRID | D11: ='ELC RESID'!H9 -> ELCNGAGRDICE19 | E11: ='ELC RESID'!A9&" "&'ELC RESID'!B9&" "&'ELC RESID'!D9&" "&'ELC RESID'!F9&" "&'ELC RESID'!G9 -> Electricity Grid 2019 Internal combustion engine Natural gas | F11: TJ | G11: MW | H11: DAYNITE
B12: {=IF(SUMPRODUCT(('ELC RESID'!O10:AF58)*('ELC RESID'!H10:H58=D12))=0,"*",IF(_xlfn.XLOOKUP($D12,'ELC RESID'!$H:$H,'ELC RESID'!$E:$E)="Storage","STG",IF(_xlfn.XLOOKUP($D12,'ELC RESID'!$H:$H,'ELC RESID'!$E:$E)="Import","IMP","ELE")))} -> ELE | C12: =IF(_xlfn.XLOOKUP(D12,'ELC RESID'!H:H,'ELC RESID'!B:B)="Decentralized","CITY","EGRID") -> EGRID | D12: ='ELC RESID'!H10 -> ELCNGAGRDFCE19 | E12: ='ELC RESID'!A10&" "&'ELC RESID'!B10&" "&'ELC RESID'!D10&" "&'ELC RESID'!F10&" "&'ELC RESID'!G10 -> Electricity Grid 2019 Fuel cell Natural gas | F12: TJ | G12: MW | H12: DAYNITE
B13: {=IF(SUMPRODUCT(('ELC RESID'!O11:AF59)*('ELC RESID'!H11:H59=D13))=0,"*",IF(_xlfn.XLOOKUP($D13,'ELC RESID'!$H:$H,'ELC RESID'!$E:$E)="Storage","STG",IF(_xlfn.XLOOKUP($D13,'ELC RESID'!$H:$H,'ELC RESID'!$E:$E)="Import","IMP","ELE")))} -> * | C13: =IF(_xlfn.XLOOKUP(D13,'ELC RESID'!H:H,'ELC RESID'!B:B)="Decentralized","CITY","EGRID") -> EGRID | D13: ='ELC RESID'!H11 -> ELCRNGGRDCTU19 | E13: ='ELC RESID'!A11&" "&'ELC RESID'!B11&" "&'ELC RESID'!D11&" "&'ELC RESID'!F11&" "&'ELC RESID'!G11 -> Electricity Grid 2019 Combustion turbine RNG | F13: TJ | G13: MW | H13: DAYNITE
B14: {=IF(SUMPRODUCT(('ELC RESID'!O12:AF60)*('ELC RESID'!H12:H60=D14))=0,"*",IF(_xlfn.XLOOKUP($D14,'ELC RESID'!$H:$H,'ELC RESID'!$E:$E)="Storage","STG",IF(_xlfn.XLOOKUP($D14,'ELC RESID'!$H:$H,'ELC RESID'!$E:$E)="Import","IMP","ELE")))} -> * | C14: =IF(_xlfn.XLOOKUP(D14,'ELC RESID'!H:H,'ELC RESID'!B:B)="Decentralized","CITY","EGRID") -> EGRID | D14: ='ELC RESID'!H12 -> ELCRNGGRDSTU19 | E14: ='ELC RESID'!A12&" "&'ELC RESID'!B12&" "&'ELC RESID'!D12&" "&'ELC RESID'!F12&" "&'ELC RESID'!G12 -> Electricity Grid 2019 Steam turbine RNG | F14: TJ | G14: MW | H14: DAYNITE
B15: {=IF(SUMPRODUCT(('ELC RESID'!O13:AF61)*('ELC RESID'!H13:H61=D15))=0,"*",IF(_xlfn.XLOOKUP($D15,'ELC RESID'!$H:$H,'ELC RESID'!$E:$E)="Storage","STG",IF(_xlfn.XLOOKUP($D15,'ELC RESID'!$H:$H,'ELC RESID'!$E:$E)="Import","IMP","ELE")))} -> * | C15: =IF(_xlfn.XLOOKUP(D15,'ELC RESID'!H:H,'ELC RESID'!B:B)="Decentralized","CITY","EGRID") -> EGRID | D15: ='ELC RESID'!H13 -> ELCRNGGRDCCC19 | E15: ='ELC RESID'!A13&" "&'ELC RESID'!B13&" "&'ELC RESID'!D13&" "&'ELC RESID'!F13&" "&'ELC RESID'!G13 -> Electricity Grid 2019 Combined cycle combustion turbine RNG | F15: TJ | G15: MW | H15: DAYNITE
B16: {=IF(SUMPRODUCT(('ELC RESID'!O14:AF62)*('ELC RESID'!H14:H62=D16))=0,"*",IF(_xlfn.XLOOKUP($D16,'ELC RESID'!$H:$H,'ELC RESID'!$E:$E)="Storage","STG",IF(_xlfn.XLOOKUP($D16,'ELC RESID'!$H:$H,'ELC RESID'!$E:$E)="Import","IMP","ELE")))} -> * | C16: =IF(_xlfn.XLOOKUP(D16,'ELC RESID'!H:H,'ELC RESID'!B:B)="Decentralized","CITY","EGRID") -> EGRID | D16: ='ELC RESID'!H14 -> ELCRNGGRDCCS19 | E16: ='ELC RESID'!A14&" "&'ELC RESID'!B14&" "&'ELC RESID'!D14&" "&'ELC RESID'!F14&" "&'ELC RESID'!G14 -> Electricity Grid 2019 Combined cycle steam turbine RNG | F16: TJ | G16: MW | H16: DAYNITE
... B51: {=IF(SUMPRODUCT(('ELC RESID'!O49:AF97)*('ELC RESID'!H49:H97=D51))=0,"*",IF(_xlfn.XLOOKUP($D51,'ELC RESID'!$H:$H,'ELC RESID'!$E:$E)="Storage","STG",IF(_xlfn.XLOOKUP($D51,'ELC RESID'!$H:$H,'ELC RESID'!$E:$E)="Import","IMP","ELE")))} -> ELE | C51: =IF(_xlfn.XLOOKUP(D51,'ELC RESID'!H:H,'ELC RESID'!B:B)="Decentralized","CITY","EGRID") -> CITY | D51: ='ELC RESID'!H49 -> ELCSOLDCEIPV19 | E51: ='ELC RESID'!A49&" "&'ELC RESID'!B49&" "&'ELC RESID'!D49&" "&'ELC RESID'!F49&" "&'ELC RESID'!G49 -> Electricity Decentralized 2019 Industrial Solar (Photovoltaic) Solar | F51: TJ | G51: MW | H51: DAYNITE
B52: {=IF(SUMPRODUCT(('ELC RESID'!O50:AF98)*('ELC RESID'!H50:H98=D52))=0,"*",IF(_xlfn.XLOOKUP($D52,'ELC RESID'!$H:$H,'ELC RESID'!$E:$E)="Storage","STG",IF(_xlfn.XLOOKUP($D52,'ELC RESID'!$H:$H,'ELC RESID'!$E:$E)="Import","IMP","ELE")))} -> IMP | C52: =IF(_xlfn.XLOOKUP(D52,'ELC RESID'!H:H,'ELC RESID'!B:B)="Decentralized","CITY","EGRID") -> EGRID | D52: ='ELC RESID'!H51 -> IMPELCEGRID | E52: ='ELC RESID'!A51&" "&'ELC RESID'!B51&" "&'ELC RESID'!D51&" "&'ELC RESID'!F51&" "&'ELC RESID'!G51 -> Electricty Grid 2019 Import to EGRID Electricity | F52: TJ | G52: MW | H52: DAYNITE
B53: *
B54: =IF('ELC RESID'!E51="Storage","STG","ELE") -> ELE | C54: EGRID | D54: =EGRID_PARAM!C6 -> ELCMISEGRID | E54: =Demand!B65 -> Miscellanous EGRID electricity demand | F54: TJ | G54: MW | H54: DAYNITE

Sheet Def_Comm
B2: ~FI_Comm
B3: Csets | C3: CommName | D3: CommDesc | E3: Unit | F3: LimType | G3: CTSLvl | H3: PeakTS | I3: Ctype
B4: *Commodity Set Membership | C4: Commodity Name | D4: Commodity Description | E4: Unit | F4: Sense of the Balance EQN. | G4: Timeslice Level | H4: Peak Monitoring | I4: Electricity Indicator
B5: DEM | C5: =Demand!E65 -> ELCMISEGRIDDMD | D5: =Demand!B65 -> Miscellanous EGRID electricity demand | E5: TJ | G5: DAYNITE | H5: ANNUAL | I5: ELC

Sheet ResidELC
Q1: Solar AF | R1: 0.47550939 | S1: 0.47550939 | T1: =S1*0.1 -> 0.047550939 | U1: 0 | V1: 0.5476587 | W1: 0.5476587 | X1: =W1*0.1 -> 0.05476587 | Y1: 0 | Z1: 0.45816402 | AA1: 0.45816402 | AB1: =AA1*0.1 -> 0.045816402 | AC1: 0 | AD1: 0.47550939 | AE1: 0.47550939 | AF1: =AE1*0.1 -> 0.047550939 | AG1: 0 | AH1: 0.5476587 | AI1: 0.5476587 | AJ1: =AI1*0.1 -> 0.05476587 | AK1: 0 | AL1: 0.45816402 | AM1: 0.45816402 | AN1: =AM1*0.1 -> 0.045816402 | AO1: 0
Q2: Wind AF | R2: 0.49405275 | S2: 0.49405275 | T2: =S2*0.1 -> 0.049405275 | U2: 0.39586365 | V2: 0.57489775 | W2: 0.57489775 | X2: =W2*0.1 -> 0.057489775 | Y2: 0.50939778 | Z2: 0.29772235 | AA2: 0.29772235 | AB2: =AA2*0.1 -> 0.029772235 | AC2: 0.21762049 | AD2: 0.49405275 | AE2: 0.49405275 | AF2: =AE2*0.1 -> 0.049405275 | AG2: 0.39586365 | AH2: 0.57489775 | AI2: 0.57489775 | AJ2: =AI2*0.1 -> 0.057489775 | AK2: 0.50939778 | AL2: 0.29772235 | AM2: 0.29772235 | AN2: =AM2*0.1 -> 0.029772235 | AO2: 0.21762049
R3: 0.0822 | S3: 0.0957 | T3: 0.1532 | U3: 0.0032 | V3: 0.0815 | W3: 0.1087 | X3: 0.1381 | Y3: 0.0032 | Z3: 0.0975 | AA3: 0.1087 | AB3: 0.1253 | AC3: 0.0027 | AD3: 0.0822 | AE3: 0.0957 | AF3: 0.1532 | AG3: 0.0032 | AH3: 0.0815 | AI3: 0.1087 | AJ3: 0.1381 | AK3: 0.0032 | AL3: 0.0975 | AM3: 0.1087 | AN3: 0.1253 | AO3: 0.0027
K4: ='City characteristics'!C20 -> 2019 | L4: 2020 | M4: 2100 | N4: ='City characteristics'!C20 -> 2019 | O4: 2020 | P4: 2100 | R4: IDAM | S4: IDPM | T4: IP | U4: IN | V4: WDAM | W4: WDPM | X4: WP | Y4: WN | Z4: SDAM | AA4: SDPM | AB4: SP | AC4: SN | AD4: IDAM | AE4: IDPM | AF4: IP | AG4: IN | AH4: WDAM | AI4: WDPM | AJ4: WP | AK4: WN | AL4: SDAM | AM4: SDPM | AN4: SP | AO4: SN | AP4: ='City characteristics'!C20 -> 2019 | AQ4: 2020 | AR4: 2025 | AS4: 2030 | AT4: 2035 | AU4: 2040 | AV4: 2045 | AW4: 2050 | AX4: 2055 | AY4: 2060 | AZ4: 2065 | BA4: 2070 | BB4: 2075 | BC4: 2080 | BD4: 2085 | BE4: 2090 | BF4: 2095 | BG4: 2100
K5: NCAP_AFA | L5: NCAP_AFA | M5: NCAP_AFA | N5: NCAP_AFC | O5: NCAP_AFC | P5: NCAP_AFC | Q5: NCAP_PKCNT | R5: NCAP_AF | S5: NCAP_AF | T5: NCAP_AF | U5: NCAP_AF | V5: NCAP_AF | W5: NCAP_AF | X5: NCAP_AF | Y5: NCAP_AF | Z5: NCAP_AF | AA5: NCAP_AF | AB5: NCAP_AF | AC5: NCAP_AF | AD5: NCAP_AFC | AE5: NCAP_AFC | AF5: NCAP_AFC | AG5: NCAP_AFC | AH5: NCAP_AFC | AI5: NCAP_AFC | AJ5: NCAP_AFC | AK5: NCAP_AFC | AL5: NCAP_AFC | AM5: NCAP_AFC | AN5: NCAP_AFC | AO5: NCAP_AFC | AP5: PRC_RESID | AQ5: PRC_RESID | AR5: PRC_RESID | AS5: PRC_RESID | AT5: PRC_RESID | AU5: PRC_RESID | AV5: PRC_RESID | AW5: PRC_RESID | AX5: PRC_RESID | AY5: PRC_RESID | AZ5: PRC_RESID | BA5: PRC_RESID | BB5: PRC_RESID | BC5: PRC_RESID | BD5: PRC_RESID | BE5: PRC_RESID | BF5: PRC_RESID | BG5: PRC_RESID
E7: ~FI_T
B8: Region | C8: TechName | D8: Comm-IN | E8: Comm-OUT | F8: EFF | G8: STG_EFF | H8: PRC_CAPACT | I8: ACT_COST | J8: NCAP_FOM | K8: =K5&"~"&K4 -> NCAP_AFA~2019 | L8: =L5&"~"&L4 -> NCAP_AFA~2020 | M8: =M5&"~"&M4 -> NCAP_AFA~2100 | N8: =N5&"~"&N4 -> NCAP_AFC~2019 | O8: =O5&"~"&O4 -> NCAP_AFC~2020 | P8: =P5&"~"&P4 -> NCAP_AFC~2100 | Q8: NCAP_PKCNT | R8: =R5&"~"&R4 -> NCAP_AF~IDAM | S8: =S5&"~"&S4 -> NCAP_AF~IDPM | T8: =T5&"~"&T4 -> NCAP_AF~IP | U8: =U5&"~"&U4 -> NCAP_AF~IN | V8: =V5&"~"&V4 -> NCAP_AF~WDAM | W8: =W5&"~"&W4 -> NCAP_AF~WDPM | X8: =X5&"~"&X4 -> NCAP_AF~WP | Y8: =Y5&"~"&Y4 -> NCAP_AF~WN | ... BG8: =BG5&"~"&BG4 -> PRC_RESID~2100
B9: * | C9: * | F9: Out/In | G9: Out/In | H9: TJ/MW | I9: $ / GJ | J9: $ / kW /Yr | K9: % | L9: % | M9: % | N9: % | O9: % | P9: % | Q9: % | AP9: MW | AQ9: MW | AR9: MW | AS9: MW | AT9: MW | AU9: MW | AV9: MW | AW9: MW | AX9: MW | AY9: MW | AZ9: MW | BA9: MW | BB9: MW | BC9: MW | BD9: MW | BE9: MW | BF9: MW | BG9: MW
B10: =IF(SUM(AP10:BG10)=0,"*",Def_Tech!C5) -> EGRID | C10: =Def_Tech!D5 -> ELCNGAGRDCTU19 | D10: =IF(_xlfn.XLOOKUP('ELC RESID'!G3,List!C:C,List!B:B)="STG",E10,"ELC"&_xlfn.XLOOKUP('ELC RESID'!G3,List!C:C,List!B:B)) -> ELCNGA | E10: CELC | F10: =IF('ELC RESID'!E3="Storage","",IF('ELC RESID'!L3="",1,'ELC RESID'!L3)) -> 0.35213238 | G10: =IF('ELC RESID'!E3<>"Storage","",IF('ELC RESID'!L3="",1,'ELC RESID'!L3)) | H10: =8760*0.0036 -> 31.536 | I10: =_xlfn.XLOOKUP(C10,'ELC RESID'!H:H,'ELC RESID'!N:N) -> 2.0228151 | J10: =_xlfn.XLOOKUP(C10,'ELC RESID'!H:H,'ELC RESID'!M:M) -> 27.138389 | K10: =IF('ELC RESID'!$E3="Storage","",IF('ELC RESID'!$K3>0,'ELC RESID'!$K3,-'ELC RESID'!$K3)) -> 0.13746195 | L10: =K10 -> 0.13746195 | M10: =L10 -> 0.13746195 | N10: =IF('ELC RESID'!$E3="Storage",IF('ELC RESID'!$K3>0,'ELC RESID'!$K3,-'ELC RESID'!$K3),"") | O10: =N10 | P10: =O10 | Q10: =IF('ELC RESID'!E3="Storage",0.3,IF('ELC RESID'!E3="Baseload",0.9,IF('ELC RESID'!E3="Non Dispatchable",0.05,IF('ELC RESID'!E3="Dispatchable",0.9,1)))) -> 0.9 | R10: =IF('ELC RESID'!$E3="Non Dispatchable",IFERROR(IF($D10="ELCSOL",$K10/SUMPRODUCT($R$1:$AC$1,$R$3:$AC$3)*R$1,IF($D10="ELCWND",$K10/SUMPRODUCT($R$2:$AC$2,$R$3:$AC$3)*R$2,0)),""),"") | S10: =IF('ELC RESID'!$E3="Non Dispatchable",IFERROR(IF($D10="ELCSOL",$K10/SUMPRODUCT($R$1:$AC$1,$R$3:$AC$3)*S$1,IF($D10="ELCWND",$K10/SUMPRODUCT($R$2:$AC$2,$R$3:$AC$3)*S$2,0)),""),"") | T10: =IF('ELC RESID'!$E3="Non Dispatchable",IFERROR(IF($D10="ELCSOL",$K10/SUMPRODUCT($R$1:$AC$1,$R$3:$AC$3)*T$1,IF($D10="ELCWND",$K10/SUMPRODUCT($R$2:$AC$2,$R$3:$AC$3)*T$2,0)),""),"") | U10: =IF('ELC RESID'!$E3="Non Dispatchable",IFERROR(IF($D10="ELCSOL",$K10/SUMPRODUCT($R$1:$AC$1,$R$3:$AC$3)*U$1,IF($D10="ELCWND",$K10/SUMPRODUCT($R$2:$AC$2,$R$3:$AC$3)*U$2,0)),""),"") | V10: =IF('ELC RESID'!$E3="Non Dispatchable",IFERROR(IF($D10="ELCSOL",$K10/SUMPRODUCT($R$1:$AC$1,$R$3:$AC$3)*V$1,IF($D10="ELCWND",$K10/SUMPRODUCT($R$2:$AC$2,$R$3:$AC$3)*V$2,0)),""),"") | W10: =IF('ELC RESID'!$E3="Non Dispatchable",IFERROR(IF($D10="ELCSOL",$K10/SUMPRODUCT($R$1:$AC$1,$R$3:$AC$3)*W$1,IF($D10="ELCWND",$K10/SUMPRODUCT($R$2:$AC$2,$R$3:$AC$3)*W$2,0)),""),"") | X10: =IF('ELC RESID'!$E3="Non Dispatchable",IFERROR(IF($D10="ELCSOL",$K10/SUMPRODUCT($R$1:$AC$1,$R$3:$AC$3)*X$1,IF($D10="ELCWND",$K10/SUMPRODUCT($R$2:$AC$2,$R$3:$AC$3)*X$2,0)),""),"") | Y10: =IF('ELC RESID'!$E3="Non Dispatchable",IFERROR(IF($D10="ELCSOL",$K10/SUMPRODUCT($R$1:$AC$1,$R$3:$AC$3)*Y$1,IF($D10="ELCWND",$K10/SUMPRODUCT($R$2:$AC$2,$R$3:$AC$3)*Y$2,0)),""),"") | ... AC10: =IF('ELC RESID'!$E3="Non Dispatchable",IFERROR(IF($D10="ELCSOL",$K10/SUMPRODUCT($R$1:$AC$1,$R$3:$AC$3)*AC$1,IF($D10="ELCWND",$K10/SUMPRODUCT($R$2:$AC$2,$R$3:$AC$3)*AC$2,0)),""),"") | AD10: =IF('ELC RESID'!$E3="Storage", ResidELC!R$3*$N10,"") | AE10: =IF('ELC RESID'!$E3="Storage", ResidELC!S$3*$N10,"") | AF10: =IF('ELC RESID'!$E3="Storage", ResidELC!T$3*$N10,"") | AG10: =IF('ELC RESID'!$E3="Storage", ResidELC!U$3*$N10,"") | AH10: =IF('ELC RESID'!$E3="Storage", ResidELC!V$3*$N10,"") | AI10: =IF('ELC RESID'!$E3="Storage", ResidELC!W$3*$N10,"") | AJ10: =IF('ELC RESID'!$E3="Storage", ResidELC!X$3*$N10,"") | AK10: =IF('ELC RESID'!$E3="Storage", ResidELC!Y$3*$N10,"") | ... AO10: =IF('ELC RESID'!$E3="Storage", ResidELC!AC$3*$N10,"") | AP10: ='ELC RESID'!O3 -> 2808.1 | AQ10: ='ELC RESID'!P3 -> 1517.2 | AR10: ='ELC RESID'!Q3 -> 1517.2 | AS10: ='ELC RESID'!R3 -> 1517.2 | AT10: ='ELC RESID'!S3 -> 1517.2 | AU10: ='ELC RESID'!T3 -> 681.9 | AV10: ='ELC RESID'!U3 -> 677.3 | AW10: ='ELC RESID'!V3 -> 139.5 | ... BG10: ='ELC RESID'!AF3 -> 0
B11: =IF(SUM(AP11:BG11)=0,"*",Def_Tech!C6) -> EGRID | C11: =Def_Tech!D6 -> ELCNGAGRDSTU19 | D11: =IF(_xlfn.XLOOKUP('ELC RESID'!G4,List!C:C,List!B:B)="STG",E11,"ELC"&_xlfn.XLOOKUP('ELC RESID'!G4,List!C:C,List!B:B)) -> ELCNGA | E11: CELC | F11: =IF('ELC RESID'!E4="Storage","",IF('ELC RESID'!L4="",1,'ELC RESID'!L4)) -> 0.36840957 | G11: =IF('ELC RESID'!E4<>"Storage","",IF('ELC RESID'!L4="",1,'ELC RESID'!L4)) | H11: =8760*0.0036 -> 31.536 | I11: =_xlfn.XLOOKUP(C11,'ELC RESID'!H:H,'ELC RESID'!N:N) -> 2.0228151 | J11: =_xlfn.XLOOKUP(C11,'ELC RESID'!H:H,'ELC RESID'!M:M) -> 27.138389 | K11: =IF('ELC RESID'!$E4="Storage","",IF('ELC RESID'!$K4>0,'ELC RESID'!$K4,-'ELC RESID'!$K4)) -> 0.084997091 | L11: =K11 -> 0.084997091 | M11: =L11 -> 0.084997091 | N11: =IF('ELC RESID'!$E4="Storage",IF('ELC RESID'!$K4>0,'ELC RESID'!$K4,-'ELC RESID'!$K4),"") | O11: =N11 | P11: =O11 | Q11: =IF('ELC RESID'!E4="Storage",0.3,IF('ELC RESID'!E4="Baseload",0.9,IF('ELC RESID'!E4="Non Dispatchable",0.05,IF('ELC RESID'!E4="Dispatchable",0.9,1)))) -> 0.9 | R11: =IF('ELC RESID'!$E4="Non Dispatchable",IFERROR(IF($D11="ELCSOL",$K11/SUMPRODUCT($R$1:$AC$1,$R$3:$AC$3)*R$1,IF($D11="ELCWND",$K11/SUMPRODUCT($R$2:$AC$2,$R$3:$AC$3)*R$2,0)),""),"") | S11: =IF('ELC RESID'!$E4="Non Dispatchable",IFERROR(IF($D11="ELCSOL",$K11/SUMPRODUCT($R$1:$AC$1,$R$3:$AC$3)*S$1,IF($D11="ELCWND",$K11/SUMPRODUCT($R$2:$AC$2,$R$3:$AC$3)*S$2,0)),""),"") | T11: =IF('ELC RESID'!$E4="Non Dispatchable",IFERROR(IF($D11="ELCSOL",$K11/SUMPRODUCT($R$1:$AC$1,$R$3:$AC$3)*T$1,IF($D11="ELCWND",$K11/SUMPRODUCT($R$2:$AC$2,$R$3:$AC$3)*T$2,0)),""),"") | U11: =IF('ELC RESID'!$E4="Non Dispatchable",IFERROR(IF($D11="ELCSOL",$K11/SUMPRODUCT($R$1:$AC$1,$R$3:$AC$3)*U$1,IF($D11="ELCWND",$K11/SUMPRODUCT($R$2:$AC$2,$R$3:$AC$3)*U$2,0)),""),"") | V11: =IF('ELC RESID'!$E4="Non Dispatchable",IFERROR(IF($D11="ELCSOL",$K11/SUMPRODUCT($R$1:$AC$1,$R$3:$AC$3)*V$1,IF($D11="ELCWND",$K11/SUMPRODUCT($R$2:$AC$2,$R$3:$AC$3)*V$2,0)),""),"") | W11: =IF('ELC RESID'!$E4="Non Dispatchable",IFERROR(IF($D11="ELCSOL",$K11/SUMPRODUCT($R$1:$AC$1,$R$3:$AC$3)*W$1,IF($D11="ELCWND",$K11/SUMPRODUCT($R$2:$AC$2,$R$3:$AC$3)*W$2,0)),""),"") | X11: =IF('ELC RESID'!$E4="Non Dispatchable",IFERROR(IF($D11="ELCSOL",$K11/SUMPRODUCT($R$1:$AC$1,$R$3:$AC$3)*X$1,IF($D11="ELCWND",$K11/SUMPRODUCT($R$2:$AC$2,$R$3:$AC$3)*X$2,0)),""),"") | Y11: =IF('ELC RESID'!$E4="Non Dispatchable",IFERROR(IF($D11="ELCSOL",$K11/SUMPRODUCT($R$1:$AC$1,$R$3:$AC$3)*Y$1,IF($D11="ELCWND",$K11/SUMPRODUCT($R$2:$AC$2,$R$3:$AC$3)*Y$2,0)),""),"") | ... AC11: =IF('ELC RESID'!$E4="Non Dispatchable",IFERROR(IF($D11="ELCSOL",$K11/SUMPRODUCT($R$1:$AC$1,$R$3:$AC$3)*AC$1,IF($D11="ELCWND",$K11/SUMPRODUCT($R$2:$AC$2,$R$3:$AC$3)*AC$2,0)),""),"") | AD11: =IF('ELC RESID'!$E4="Storage", ResidELC!R$3*$N11,"") | AE11: =IF('ELC RESID'!$E4="Storage", ResidELC!S$3*$N11,"") | AF11: =IF('ELC RESID'!$E4="Storage", ResidELC!T$3*$N11,"") | AG11: =IF('ELC RESID'!$E4="Storage", ResidELC!U$3*$N11,"") | AH11: =IF('ELC RESID'!$E4="Storage", ResidELC!V$3*$N11,"") | AI11: =IF('ELC RESID'!$E4="Storage", ResidELC!W$3*$N11,"") | AJ11: =IF('ELC RESID'!$E4="Storage", ResidELC!X$3*$N11,"") | AK11: =IF('ELC RESID'!$E4="Storage", ResidELC!Y$3*$N11,"") | ... AO11: =IF('ELC RESID'!$E4="Storage", ResidELC!AC$3*$N11,"") | AP11: ='ELC RESID'!O4 -> 4019.7 | AQ11: ='ELC RESID'!P4 -> 16 | AR11: ='ELC RESID'!Q4 -> 16 | AS11: ='ELC RESID'!R4 -> 16 | AT11: ='ELC RESID'!S4 -> 16 | AU11: ='ELC RESID'!T4 -> 16 | AV11: ='ELC RESID'!U4 -> 16 | AW11: ='ELC RESID'!V4 -> 0 | ... BG11: ='ELC RESID'!AF4 -> 0
B12: =IF(SUM(AP12:BG12)=0,"*",Def_Tech!C7) -> EGRID | C12: =Def_Tech!D7 -> ELCNGAGRDCCC19 | D12: =IF(_xlfn.XLOOKUP('ELC RESID'!G5,List!C:C,List!B:B)="STG",E12,"ELC"&_xlfn.XLOOKUP('ELC RESID'!G5,List!C:C,List!B:B)) -> ELCNGA | E12: CELC | F12: =IF('ELC RESID'!E5="Storage","",IF('ELC RESID'!L5="",1,'ELC RESID'!L5)) -> 0.50974827 | G12: =IF('ELC RESID'!E5<>"Storage","",IF('ELC RESID'!L5="",1,'ELC RESID'!L5)) | H12: =8760*0.0036 -> 31.536 | I12: =_xlfn.XLOOKUP(C12,'ELC RESID'!H:H,'ELC RESID'!N:N) -> 0.61563937 | J12: =_xlfn.XLOOKUP(C12,'ELC RESID'!H:H,'ELC RESID'!M:M) -> 35.166828 | K12: =IF('ELC RESID'!$E5="Storage","",IF('ELC RESID'!$K5>0,'ELC RESID'!$K5,-'ELC RESID'!$K5)) -> 0.64588452 | L12: =K12 -> 0.64588452 | M12: =L12 -> 0.64588452 | N12: =IF('ELC RESID'!$E5="Storage",IF('ELC RESID'!$K5>0,'ELC RESID'!$K5,-'ELC RESID'!$K5),"") | O12: =N12 | P12: =O12 | Q12: =IF('ELC RESID'!E5="Storage",0.3,IF('ELC RESID'!E5="Baseload",0.9,IF('ELC RESID'!E5="Non Dispatchable",0.05,IF('ELC RESID'!E5="Dispatchable",0.9,1)))) -> 0.9 | R12: =IF('ELC RESID'!$E5="Non Dispatchable",IFERROR(IF($D12="ELCSOL",$K12/SUMPRODUCT($R$1:$AC$1,$R$3:$AC$3)*R$1,IF($D12="ELCWND",$K12/SUMPRODUCT($R$2:$AC$2,$R$3:$AC$3)*R$2,0)),""),"") | S12: =IF('ELC RESID'!$E5="Non Dispatchable",IFERROR(IF($D12="ELCSOL",$K12/SUMPRODUCT($R$1:$AC$1,$R$3:$AC$3)*S$1,IF($D12="ELCWND",$K12/SUMPRODUCT($R$2:$AC$2,$R$3:$AC$3)*S$2,0)),""),"") | T12: =IF('ELC RESID'!$E5="Non Dispatchable",IFERROR(IF($D12="ELCSOL",$K12/SUMPRODUCT($R$1:$AC$1,$R$3:$AC$3)*T$1,IF($D12="ELCWND",$K12/SUMPRODUCT($R$2:$AC$2,$R$3:$AC$3)*T$2,0)),""),"") | U12: =IF('ELC RESID'!$E5="Non Dispatchable",IFERROR(IF($D12="ELCSOL",$K12/SUMPRODUCT($R$1:$AC$1,$R$3:$AC$3)*U$1,IF($D12="ELCWND",$K12/SUMPRODUCT($R$2:$AC$2,$R$3:$AC$3)*U$2,0)),""),"") | V12: =IF('ELC RESID'!$E5="Non Dispatchable",IFERROR(IF($D12="ELCSOL",$K12/SUMPRODUCT($R$1:$AC$1,$R$3:$AC$3)*V$1,IF($D12="ELCWND",$K12/SUMPRODUCT($R$2:$AC$2,$R$3:$AC$3)*V$2,0)),""),"") | W12: =IF('ELC RESID'!$E5="Non Dispatchable",IFERROR(IF($D12="ELCSOL",$K12/SUMPRODUCT($R$1:$AC$1,$R$3:$AC$3)*W$1,IF($D12="ELCWND",$K12/SUMPRODUCT($R$2:$AC$2,$R$3:$AC$3)*W$2,0)),""),"") | X12: =IF('ELC RESID'!$E5="Non Dispatchable",IFERROR(IF($D12="ELCSOL",$K12/SUMPRODUCT($R$1:$AC$1,$R$3:$AC$3)*X$1,IF($D12="ELCWND",$K12/SUMPRODUCT($R$2:$AC$2,$R$3:$AC$3)*X$2,0)),""),"") | Y12: =IF('ELC RESID'!$E5="Non Dispatchable",IFERROR(IF($D12="ELCSOL",$K12/SUMPRODUCT($R$1:$AC$1,$R$3:$AC$3)*Y$1,IF($D12="ELCWND",$K12/SUMPRODUCT($R$2:$AC$2,$R$3:$AC$3)*Y$2,0)),""),"") | ... AC12: =IF('ELC RESID'!$E5="Non Dispatchable",IFERROR(IF($D12="ELCSOL",$K12/SUMPRODUCT($R$1:$AC$1,$R$3:$AC$3)*AC$1,IF($D12="ELCWND",$K12/SUMPRODUCT($R$2:$AC$2,$R$3:$AC$3)*AC$2,0)),""),"") | AD12: =IF('ELC RESID'!$E5="Storage", ResidELC!R$3*$N12,"") | AE12: =IF('ELC RESID'!$E5="Storage", ResidELC!S$3*$N12,"") | AF12: =IF('ELC RESID'!$E5="Storage", ResidELC!T$3*$N12,"") | AG12: =IF('ELC RESID'!$E5="Storage", ResidELC!U$3*$N12,"") | AH12: =IF('ELC RESID'!$E5="Storage", ResidELC!V$3*$N12,"") | AI12: =IF('ELC RESID'!$E5="Storage", ResidELC!W$3*$N12,"") | AJ12: =IF('ELC RESID'!$E5="Storage", ResidELC!X$3*$N12,"") | AK12: =IF('ELC RESID'!$E5="Storage", ResidELC!Y$3*$N12,"") | ... AO12: =IF('ELC RESID'!$E5="Storage", ResidELC!AC$3*$N12,"") | AP12: ='ELC RESID'!O5 -> 2296.7 | AQ12: ='ELC RESID'!P5 -> 2296.7 | AR12: ='ELC RESID'!Q5 -> 2296.7 | AS12: ='ELC RESID'!R5 -> 1726.5 | AT12: ='ELC RESID'!S5 -> 1484.5 | AU12: ='ELC RESID'!T5 -> 751 | AV12: ='ELC RESID'!U5 -> 400 | AW12: ='ELC RESID'!V5 -> 0 | ... BG12: ='ELC RESID'!AF5 -> 0
B13: =IF(SUM(AP13:BG13)=0,"*",Def_Tech!C8) -> EGRID | C13: =Def_Tech!D8 -> ELCNGAGRDCCS19 | D13: =IF(_xlfn.XLOOKUP('ELC RESID'!G6,List!C:C,List!B:B)="STG",E13,"ELC"&_xlfn.XLOOKUP('ELC RESID'!G6,List!C:C,List!B:B)) -> ELCNGA | E13: CELC | F13: =IF('ELC RESID'!E6="Storage","",IF('ELC RESID'!L6="",1,'ELC RESID'!L6)) -> 0.50738283 | G13: =IF('ELC RESID'!E6<>"Storage","",IF('ELC RESID'!L6="",1,'ELC RESID'!L6)) | H13: =8760*0.0036 -> 31.536 | I13: =_xlfn.XLOOKUP(C13,'ELC RESID'!H:H,'ELC RESID'!N:N) -> 0.61563937 | J13: =_xlfn.XLOOKUP(C13,'ELC RESID'!H:H,'ELC RESID'!M:M) -> 35.166828 | K13: =IF('ELC RESID'!$E6="Storage","",IF('ELC RESID'!$K6>0,'ELC RESID'!$K6,-'ELC RESID'!$K6)) -> 0.47892182 | L13: =K13 -> 0.47892182 | M13: =L13 -> 0.47892182 | N13: =IF('ELC RESID'!$E6="Storage",IF('ELC RESID'!$K6>0,'ELC RESID'!$K6,-'ELC RESID'!$K6),"") | O13: =N13 | P13: =O13 | Q13: =IF('ELC RESID'!E6="Storage",0.3,IF('ELC RESID'!E6="Baseload",0.9,IF('ELC RESID'!E6="Non Dispatchable",0.05,IF('ELC RESID'!E6="Dispatchable",0.9,1)))) -> 0.9 | R13: =IF('ELC RESID'!$E6="Non Dispatchable",IFERROR(IF($D13="ELCSOL",$K13/SUMPRODUCT($R$1:$AC$1,$R$3:$AC$3)*R$1,IF($D13="ELCWND",$K13/SUMPRODUCT($R$2:$AC$2,$R$3:$AC$3)*R$2,0)),""),"") | S13: =IF('ELC RESID'!$E6="Non Dispatchable",IFERROR(IF($D13="ELCSOL",$K13/SUMPRODUCT($R$1:$AC$1,$R$3:$AC$3)*S$1,IF($D13="ELCWND",$K13/SUMPRODUCT($R$2:$AC$2,$R$3:$AC$3)*S$2,0)),""),"") | T13: =IF('ELC RESID'!$E6="Non Dispatchable",IFERROR(IF($D13="ELCSOL",$K13/SUMPRODUCT($R$1:$AC$1,$R$3:$AC$3)*T$1,IF($D13="ELCWND",$K13/SUMPRODUCT($R$2:$AC$2,$R$3:$AC$3)*T$2,0)),""),"") | U13: =IF('ELC RESID'!$E6="Non Dispatchable",IFERROR(IF($D13="ELCSOL",$K13/SUMPRODUCT($R$1:$AC$1,$R$3:$AC$3)*U$1,IF($D13="ELCWND",$K13/SUMPRODUCT($R$2:$AC$2,$R$3:$AC$3)*U$2,0)),""),"") | V13: =IF('ELC RESID'!$E6="Non Dispatchable",IFERROR(IF($D13="ELCSOL",$K13/SUMPRODUCT($R$1:$AC$1,$R$3:$AC$3)*V$1,IF($D13="ELCWND",$K13/SUMPRODUCT($R$2:$AC$2,$R$3:$AC$3)*V$2,0)),""),"") | W13: =IF('ELC RESID'!$E6="Non Dispatchable",IFERROR(IF($D13="ELCSOL",$K13/SUMPRODUCT($R$1:$AC$1,$R$3:$AC$3)*W$1,IF($D13="ELCWND",$K13/SUMPRODUCT($R$2:$AC$2,$R$3:$AC$3)*W$2,0)),""),"") | X13: =IF('ELC RESID'!$E6="Non Dispatchable",IFERROR(IF($D13="ELCSOL",$K13/SUMPRODUCT($R$1:$AC$1,$R$3:$AC$3)*X$1,IF($D13="ELCWND",$K13/SUMPRODUCT($R$2:$AC$2,$R$3:$AC$3)*X$2,0)),""),"") | Y13: =IF('ELC RESID'!$E6="Non Dispatchable",IFERROR(IF($D13="ELCSOL",$K13/SUMPRODUCT($R$1:$AC$1,$R$3:$AC$3)*Y$1,IF($D13="ELCWND",$K13/SUMPRODUCT($R$2:$AC$2,$R$3:$AC$3)*Y$2,0)),""),"") | ... AC13: =IF('ELC RESID'!$E6="Non Dispatchable",IFERROR(IF($D13="ELCSOL",$K13/SUMPRODUCT($R$1:$AC$1,$R$3:$AC$3)*AC$1,IF($D13="ELCWND",$K13/SUMPRODUCT($R$2:$AC$2,$R$3:$AC$3)*AC$2,0)),""),"") | AD13: =IF('ELC RESID'!$E6="Storage", ResidELC!R$3*$N13,"") | AE13: =IF('ELC RESID'!$E6="Storage", ResidELC!S$3*$N13,"") | AF13: =IF('ELC RESID'!$E6="Storage", ResidELC!T$3*$N13,"") | AG13: =IF('ELC RESID'!$E6="Storage", ResidELC!U$3*$N13,"") | AH13: =IF('ELC RESID'!$E6="Storage", ResidELC!V$3*$N13,"") | AI13: =IF('ELC RESID'!$E6="Storage", ResidELC!W$3*$N13,"") | AJ13: =IF('ELC RESID'!$E6="Storage", ResidELC!X$3*$N13,"") | AK13: =IF('ELC RESID'!$E6="Storage", ResidELC!Y$3*$N13,"") | ... AO13: =IF('ELC RESID'!$E6="Storage", ResidELC!AC$3*$N13,"") | AP13: ='ELC RESID'!O6 -> 1175.5 | AQ13: ='ELC RESID'!P6 -> 1173.1 | AR13: ='ELC RESID'!Q6 -> 1173.1 | AS13: ='ELC RESID'!R6 -> 860.5 | AT13: ='ELC RESID'!S6 -> 780.5 | AU13: ='ELC RESID'!T6 -> 505 | AV13: ='ELC RESID'!U6 -> 250 | AW13: ='ELC RESID'!V6 -> 0 | ... BG13: ='ELC RESID'!AF6 -> 0
