Workbook

Sheet ReadMe
A1: Generic Comet (GC) TIMES Supply
B3: Sheet color
C4: Raw Data and Parameters
C6: City Specific Data
C8: Post processing for TIMES
C10: Table formatted for TIMES

Sheet >> City Data

Sheet City characteristics
B2: City Basic Data
B4: Calibration methodology | C4: GHG Inventory
B6: A. City Characteristics
B7: Data Item | C7: Value | D7: Units
B8: City Name | C8: New York
B9: Latitude | C9: 40.5
B10: Longitude | C10: -75
B11: County | C11: New York County
B12: State | C12: New York
B13: Census Division | C13: Middle Atlantic
B14: Climate Division | C14: Northeast
B15: Egrid Region | C15: NPCC NYC/Westchester
B16: Area of city (excluding water, natural and agricultural areas) | C16: 778 | D16: square kilometers
B17: * Division and Region Map can be found in the Maps sheet.
B18: B. Planning Base Year and Target Years
B19: Year | C19: Value | D19: Units
B20: Base Year | C20: 2019 | D20: Acceptable range [2018,2021]
B21: End Year | C21: 2050
B23: C. City Population and GDP
B24: Data Item | C24: Value | D24: Units
B25: Population in Base Year | C25: 8337 | D25: Thousand of people
B26: Annual population growth (Base Year - End Year) | C26: 0.5 | D26: % people
B27: GDP in Base Year | C27: 1206000 | D27: Million US$
B28: Annual GDP growth rate | C28: 2 | D28: % US$
B29: Share of manufacturing GDP | C29: 5 | D29: % US$
B30: Share of State population | C30: 0.42835123
B31: Share of State GDP | C31: 0.67251772
B32: Adjustment from state manufacturing GDP | C32: 1.0638298
B34: D. Climate Data
B35: Data Item | C35: 2000 | D35: 2050 | E35: 2100 | F35: Units
B36: Heating degree days (HDD) | C36: 4473.4625 | D36: 4066.4182 | E36: 3763.8582 | F36: F
B37: Cooling degree days (CDD) | C37: 1020.7333 | D37: 1224.2555 | E37: 1375.5355 | F37: F
B39: Data Item | C39: Value | D39: Units
B40: Correction from State HDD | C40: 0.72727402
B41: Correction from State CDD | C41: 1.5583715
B42: Annual precipitation | C42: 762 | D42: mm / year
B43: Climate change scenario | C43: RCP4.5
B44: Average temperature increase in 1980-2020 | C44: 1.4617857 | D44: F
B45: Forecasted average temperature increase in 2035-2065 | C45: 3.13 | D45: F
B46: Forecasted average temperature increase in 2070-2100 | C46: 4.37 | D46: F
...

Sheet >> GC_Resid

Sheet COM RESID
A1: Sector | B1: Sub-sector | C1: Archetype | D1: Vintage | E1: End Use | F1: Technology | G1: Energy | H1: Input Label | I1: Output Label | J1: Technology Label | K1: DEMAND (Mm2) | L1: FINAL ENERGY (TJ) | M1: FINAL ENERGY SHARE (%) | N1: FINAL ENERGY EQ (TJ) | O1: USEFUL ENERGY (TJ,Mlm) | P1: RESID (MW,Mlma, Tja) | Q1: Capacity Unit | R1: EFF | S1: Residual life (Yr) | T1: Fixed O&M ($/kW/yr) | U1: Variable O&M ($/GJ) | V1: CFA | W1: C2A
A2: Commercial | B2: Hotel | D2: Old | E2: Space heating | F2: Electric furnace | G2: Electricity | H2: COMELC | I2: COMHOTOldSHEUE | J2: COMHOTOldSHFURELC19 | K2: 11.978701 | L2: 105.23941 | M2: 0.79219174 | N2: 83.369795 | O2: 81.702399 | P2: 37.362548 | Q2: MW | R2: 0.98 | S2: 15 | T2: 1 | V2: 0.069341257 | W2: 31.536
A3: Commercial | B3: Hotel | D3: Old | E3: Space heating | F3: Electric boiler | G3: Electricity | H3: COMELC | I3: COMHOTOldSHEUE | J3: COMHOTOldSHBOIELC19 | K3: 11.978701 | L3: 105.23941 | M3: 0.066806316 | N3: 7.0306576 | O3: 6.5884292 | P3: 3.5269956 | Q3: MW | R3: 0.9371 | S3: 7.5 | T3: 1 | V3: 0.059233905 | W3: 31.536
A4: Commercial | B4: Hotel | D4: Old | E4: Space heating | F4: Electric air heat pump | G4: Electricity | H4: COMELC | I4: COMHOTOldSHEUE | J4: COMHOTOldSHAHPELC19 | K4: 11.978701 | L4: 105.23941 | M4: 0.14100195 | N4: 14.838962 | O4: 46.000783 | P4: 14.674506 | Q4: MW | R4: 3.1 | S4: 10.5 | T4: 14.331048 | V4: 0.099402002 | W4: 31.536
A5: Commercial | B5: Hotel | D5: Old | E5: Space heating | F5: Electric ground heat pump | G5: Electricity | H5: COMELC | I5: COMHOTOldSHEUE | J5: COMHOTOldSHGHPELC19 | K5: 11.978701 | L5: 105.23941 | M5: 0 | N5: 0 | O5: 0 | P5: 0 | Q5: MW | R5: 3.4 | S5: 7.2 | T5: 13.001959 | V5: 0.10902155 | W5: 31.536
A6: Commercial | B6: Hotel | D6: Old | E6: Space heating | F6: Natural gas furnace | G6: Natural gas | H6: COMNGA | I6: COMHOTOldSHEUE | J6: COMHOTOldSHFURNGA19 | K6: 11.978701 | L6: 1635.3055 | M6: 0.2440729 | N6: 399.13375 | O6: 283.58453 | P6: 59.96843 | Q6: MW | R6: 0.7105 | S6: 11.5 | T6: 2.0235418 | V6: 0.14995234 | W6: 31.536 | Y6: 23
A7: Commercial | B7: Hotel | D7: Old | E7: Space heating | F7: Natural gas boiler | G7: Natural gas | H7: COMNGA | I7: COMHOTOldSHEUE | J7: COMHOTOldSHBOINGA19 | K7: 11.978701 | L7: 1635.3055 | M7: 0.73410948 | N7: 1200.4933 | O7: 912.37487 | P7: 157.49913 | Q7: MW | R7: 0.76 | S7: 12.5 | T7: 11.357594 | V7: 0.18369128 | W7: 31.536
A8: Commercial | B8: Hotel | D8: Old | E8: Space heating | F8: Natural gas heat pump | G8: Natural gas | H8: COMNGA | I8: COMHOTOldSHEUE | J8: COMHOTOldSHAHPNGA19 | K8: 11.978701 | L8: 1635.3055 | M8: 0.021817613 | N8: 35.678462 | O8: 46.382001 | P8: 5.123458 | Q8: MW | R8: 1.3 | S8: 7.5 | T8: 12 | V8: 0.28706464 | W8: 31.536
A9: Commercial | B9: Hotel | D9: Old | E9: Space heating | F9: Fuel oil boiler | G9: Fuel oil | H9: COMFOI | I9: COMHOTOldSHEUE | J9: COMHOTOldSHBOIFOI19 | K9: 11.978701 | L9: 136.24643 | M9: 0.96283873 | N9: 131.18334 | O9: 103.63484 | P9: 21.245855 | Q9: MW | R9: 0.79 | S9: 12.5 | T9: 14 | V9: 0.15467672 | W9: 31.536
A10: Commercial | B10: Hotel | D10: Old | E10: Space heating | F10: Fuel oil furnace | G10: Fuel oil | H10: COMFOI | I10: COMHOTOldSHEUE | J10: COMHOTOldSHFURFOI19 | K10: 11.978701 | L10: 136.24643 | M10: 0.037161272 | N10: 5.0630907 | O10: 3.8504805 | P10: 0.81999507 | Q10: MW | R10: 0.7605 | S10: 11.5 | T10: 4 | V10: 0.14890082 | W10: 31.536
A11: Commercial | B11: Hotel | D11: Old | E11: Space heating | F11: Propane furnace | G11: LPG | H11: COMLPG | I11: COMHOTOldSHEUE | J11: COMHOTOldSHFURPRO19 | K11: 11.978701 | L11: 0 | M11: 0.32032654 | N11: 0 | O11: 0 | P11: 0 | Q11: MW | R11: 0.7105 | S11: 11.5 | T11: 2.0235418 | V11: 0.14995234 | W11: 31.536
A12: Commercial | B12: Hotel | D12: Old | E12: Space heating | F12: Propane boiler | G12: LPG | H12: COMLPG | I12: COMHOTOldSHEUE | J12: COMHOTOldSHBOIPRO19 | K12: 11.978701 | L12: 0 | M12: 0.30268222 | N12: 0 | O12: 0 | P12: 0 | Q12: MW | R12: 0.76 | S12: 12.5 | T12: 11.357594 | V12: 0.18369128 | W12: 31.536
A13: Commercial | B13: Hotel | D13: Old | E13: Space heating | F13: Propane heat pump | G13: LPG | H13: COMLPG | I13: COMHOTOldSHEUE | J13: COMHOTOldSHAHPPRO19 | K13: 11.978701 | L13: 0 | M13: 0.37699124 | N13: 0 | O13: 0 | P13: 0 | Q13: MW | R13: 1.3 | S13: 7.5 | T13: 12 | V13: 0.28706464 | W13: 31.536
A14: Commercial | B14: Hotel | D14: Old | E14: Space heating | F14: District steam heating system | G14: Steam / Cooling | H14: COMSTM | I14: COMHOTOldSHEUE | J14: COMHOTOldSHDHESTM19 | K14: 11.978701 | L14: 68.809968 | M14: 1 | N14: 68.809968 | O14: 64.481821 | P14: 4.9913363 | Q14: MW | R14: 0.9371 | S14: 12.5 | T14: 1 | V14: 0.40965084 | W14: 31.536
A15: Commercial | B15: Hotel | D15: Old | E15: Space cooling | F15: Res type central AC electric | G15: Electricity | H15: COMELC | I15: COMHOTOldSCEUE | J15: COMHOTOldSCRESELC19 | K15: 11.978701 | L15: 393.15304 | M15: 0.015856174 | N15: 6.2339029 | O15: 20.828398 | P15: 3.282636 | Q15: MW | R15: 3.3411489 | S15: 9 | T15: 8 | V15: 0.20119933 | W15: 31.536
A16: Commercial | B16: Hotel | D16: Old | E16: Space cooling | F16: Room AC electric | G16: Electricity | H16: COMELC | I16: COMHOTOldSCEUE | J16: COMHOTOldSCRACELC19 | K16: 11.978701 | L16: 393.15304 | M16: 0.57192812 | N16: 224.85528 | O16: 573.34142 | P16: 57.718846 | Q16: MW | R16: 2.5498242 | S16: 5 | T16: 0 | V16: 0.31498442 | W16: 31.536
A17: Commercial | B17: Hotel | D17: Old | E17: Space cooling | F17: Central AC electric | G17: Electricity | H17: COMELC | I17: COMHOTOldSCEUE | J17: COMHOTOldSCCACELC19 | K17: 11.978701 | L17: 393.15304 | M17: 0.27581488 | N17: 108.43746 | O17: 331.62993 | P17: 76.852525 | Q17: MW | R17: 3.0582599 | S17: 9 | T17: 8 | V17: 0.13683241 | W17: 31.536
A18: Commercial | B18: Hotel | D18: Old | E18: Space cooling | F18: Rooftop Air HP electric | G18: Electricity | H18: COMELC | I18: COMHOTOldSCEUE | J18: COMHOTOldSCAHPELC19 | K18: 11.978701 | L18: 393.15304 | M18: 0.12372108 | N18: 48.64132 | O18: 132.58039 | P18: 13.27567 | Q18: MW | R18: 2.7256741 | S18: 10.5 | T18: 14 | V18: 0.31667678 | W18: 31.536
... A337: Commercial | B337: Other | D337: Old | E337: Other end use | F337: Electricity | G337: Electricity | H337: COMELC | I337: COMOTHOldOEEUE | J337: COMOTHOldOEELC19 | K337: 8.7602804 | L337: 2864.2761 | M337: 1 | N337: 2864.2761 | O337: 2864.2761 | P337: 6509.7185 | Q337: TJa | R337: 1 | S337: 12.5 | T337: 10 | V337: 0.44 | W337: 1

Sheet Demand
A1: Sector | B1: Sub-sector | C1: Archetype | D1: Vintage | E1: Demand Label | F1: Unit | G1: 2019 | H1: 2020 | I1: 2025 | J1: 2030 | K1: 2035 | L1: 2040 | M1: 2045 | N1: 2050 | O1: 2055 | P1: 2060 | Q1: 2065 | R1: 2070 | S1: 2075 | T1: 2080 | U1: 2085 | V1: 2090 | W1: 2095 | X1: 2100
A2: Commercial | B2: Hotel | D2: Old | E2: COMHOTOldDMD | F2: Mm2 | G2: 11.978701 | H2: 11.978701 | I2: 11.978701 | J2: 11.978701 | K2: 11.978701 | L2: 11.978701 | M2: 11.978701 | N2: 11.978701 | O2: 11.978701 | P2: 11.978701 | Q2: 11.978701 | R2: 11.978701 | S2: 11.978701 | T2: 11.978701 | U2: 11.978701 | V2: 11.978701 | W2: 11.978701 | X2: 11.978701
A3: Commercial | B3: Retail | D3: Old | E3: COMRETOldDMD | F3: Mm2 | G3: 23.081056 | H3: 23.081056 | I3: 23.081056 | J3: 23.081056 | K3: 23.081056 | L3: 23.081056 | M3: 23.081056 | N3: 23.081056 | O3: 23.081056 | P3: 23.081056 | Q3: 23.081056 | R3: 23.081056 | S3: 23.081056 | T3: 23.081056 | U3: 23.081056 | V3: 23.081056 | W3: 23.081056 | X3: 23.081056
A4: Commercial | B4: Office | D4: Old | E4: COMOFFOldDMD | F4: Mm2 | G4: 73.164819 | H4: 73.164819 | I4: 73.164819 | J4: 73.164819 | K4: 73.164819 | L4: 73.164819 | M4: 73.164819 | N4: 73.164819 | O4: 73.164819 | P4: 73.164819 | Q4: 73.164819 | R4: 73.164819 | S4: 73.164819 | T4: 73.164819 | U4: 73.164819 | V4: 73.164819 | W4: 73.164819 | X4: 73.164819
A5: Commercial | B5: Hospital | D5: Old | E5: COMHOPOldDMD | F5: Mm2 | G5: 44.382259 | H5: 44.382259 | I5: 44.382259 | J5: 44.382259 | K5: 44.382259 | L5: 44.382259 | M5: 44.382259 | N5: 44.382259 | O5: 44.382259 | P5: 44.382259 | Q5: 44.382259 | R5: 44.382259 | S5: 44.382259 | T5: 44.382259 | U5: 44.382259 | V5: 44.382259 | W5: 44.382259 | X5: 44.382259
A6: Commercial | B6: Educationnal | D6: Old | E6: COMEDUOldDMD | F6: Mm2 | G6: 48.565496 | H6: 48.565496 | I6: 48.565496 | J6: 48.565496 | K6: 48.565496 | L6: 48.565496 | M6: 48.565496 | N6: 48.565496 | O6: 48.565496 | P6: 48.565496 | Q6: 48.565496 | R6: 48.565496 | S6: 48.565496 | T6: 48.565496 | U6: 48.565496 | V6: 48.565496 | W6: 48.565496 | X6: 48.565496
A7: Commercial | B7: Warehouse | D7: Old | E7: COMWAROldDMD | F7: Mm2 | G7: 32.733587 | H7: 32.733587 | I7: 32.733587 | J7: 32.733587 | K7: 32.733587 | L7: 32.733587 | M7: 32.733587 | N7: 32.733587 | O7: 32.733587 | P7: 32.733587 | Q7: 32.733587 | R7: 32.733587 | S7: 32.733587 | T7: 32.733587 | U7: 32.733587 | V7: 32.733587 | W7: 32.733587 | X7: 32.733587
A8: Commercial | B8: Municipal | D8: Old | E8: COMMUNOldDMD | F8: Mm2 | G8: 16.841333 | H8: 16.841333 | I8: 16.841333 | J8: 16.841333 | K8: 16.841333 | L8: 16.841333 | M8: 16.841333 | N8: 16.841333 | O8: 16.841333 | P8: 16.841333 | Q8: 16.841333 | R8: 16.841333 | S8: 16.841333 | T8: 16.841333 | U8: 16.841333 | V8: 16.841333 | W8: 16.841333 | X8: 16.841333
A9: Commercial | B9: Other | D9: Old | E9: COMOTHOldDMD | F9: Mm2 | G9: 8.7602804 | H9: 8.7602804 | I9: 8.7602804 | J9: 8.7602804 | K9: 8.7602804 | L9: 8.7602804 | M9: 8.7602804 | N9: 8.7602804 | O9: 8.7602804 | P9: 8.7602804 | Q9: 8.7602804 | R9: 8.7602804 | S9: 8.7602804 | T9: 8.7602804 | U9: 8.7602804 | V9: 8.7602804 | W9: 8.7602804 | X9: 8.7602804
A10: Commercial | B10: Hotel | D10: New | E10: COMHOTNewDMD | F10: Mm2 | G10: 0 | H10: 0.23957402 | I10: 1.4374441 | J10: 2.6353143 | K10: 3.8331844 | L10: 5.0310545 | M10: 6.2289246 | N10: 7.4267947 | O10: 8.6246649 | P10: 9.822535 | Q10: 11.020405 | R10: 12.218275 | S10: 13.416145 | T10: 14.614015 | U10: 15.811886 | V10: 17.009756 | W10: 18.207626 | X10: 19.405496
A11: Commercial | B11: Retail | D11: New | E11: COMRETNewDMD | F11: Mm2 | G11: 0 | H11: 0.46162113 | I11: 2.7697268 | J11: 5.0778324 | K11: 7.3859381 | L11: 9.6940437 | M11: 12.002149 | N11: 14.310255 | O11: 16.618361 | P11: 18.926466 | Q11: 21.234572 | R11: 23.542678 | S11: 25.850783 | T11: 28.158889 | U11: 30.466995 | V11: 32.7751 | W11: 35.083206 | X11: 37.391311
A12: Commercial | B12: Office | D12: New | E12: COMOFFNewDMD | F12: Mm2 | G12: 0 | H12: 1.4632964 | I12: 8.7797783 | J12: 16.09626 | K12: 23.412742 | L12: 30.729224 | M12: 38.045706 | N12: 45.362188 | O12: 52.67867 | P12: 59.995152 | Q12: 67.311633 | R12: 74.628115 | S12: 81.944597 | T12: 89.261079 | U12: 96.577561 | V12: 103.89404 | W12: 111.21052 | X12: 118.52701
A13: Commercial | B13: Hospital | D13: New | E13: COMHOPNewDMD | F13: Mm2 | G13: 0 | H13: 0.88764519 | I13: 5.3258711 | J13: 9.764097 | K13: 14.202323 | L13: 18.640549 | M13: 23.078775 | N13: 27.517001 | O13: 31.955227 | P13: 36.393453 | Q13: 40.831679 | R13: 45.269904 | S13: 49.70813 | T13: 54.146356 | U13: 58.584582 | V13: 63.022808 | W13: 67.461034 | X13: 71.89926
... A17: Commercial | B17: Other | D17: New | E17: COMOTHNewDMD | F17: Mm2 | G17: 0 | H17: 0.17520561 | I17: 1.0512337 | J17: 1.9272617 | K17: 2.8032897 | L17: 3.6793178 | M17: 4.5553458 | N17: 5.4313739 | O17: 6.3074019 | P17: 7.18343 | Q17: 8.059458 | R17: 8.9354861 | S17: 9.8115141 | T17: 10.687542 | U17: 11.56357 | V17: 12.439598 | W17: 13.315626 | X17: 14.191654
A18: Residential | B18: Apartment | C18: Low Income | D18: Old | E18: RESAPALOOldDMD | F18: Mm2 | G18: 51.807877 | H18: 51.807877 | I18: 51.807877 | J18: 51.807877 | K18: 51.807877 | L18: 51.807877 | M18: 51.807877 | N18: 51.807877 | O18: 51.807877 | P18: 51.807877 | Q18: 51.807877 | R18: 51.807877 | S18: 51.807877 | T18: 51.807877 | U18: 51.807877 | V18: 51.807877 | W18: 51.807877 | X18: 51.807877
A19: Residential | B19: House | C19: Low Income | D19: Old | E19: RESHOULOOldDMD | F19: Mm2 | G19: 14.956798 | H19: 14.956798 | I19: 14.956798 | J19: 14.956798 | K19: 14.956798 | L19: 14.956798 | M19: 14.956798 | N19: 14.956798 | O19: 14.956798 | P19: 14.956798 | Q19: 14.956798 | R19: 14.956798 | S19: 14.956798 | T19: 14.956798 | U19: 14.956798 | V19: 14.956798 | W19: 14.956798 | X19: 14.956798
A20: Residential | B20: Apartment | C20: Lower-Middle Income | D20: Old | E20: RESAPALMOldDMD | F20: Mm2 | G20: 57.121976 | H20: 57.121976 | I20: 57.121976 | J20: 57.121976 | K20: 57.121976 | L20: 57.121976 | M20: 57.121976 | N20: 57.121976 | O20: 57.121976 | P20: 57.121976 | Q20: 57.121976 | R20: 57.121976 | S20: 57.121976 | T20: 57.121976 | U20: 57.121976 | V20: 57.121976 | W20: 57.121976 | X20: 57.121976
A21: Residential | B21: House | C21: Lower-Middle Income | D21: Old | E21: RESHOULMOldDMD | F21: Mm2 | G21: 38.299259 | H21: 38.299259 | I21: 38.299259 | J21: 38.299259 | K21: 38.299259 | L21: 38.299259 | M21: 38.299259 | N21: 38.299259 | O21: 38.299259 | P21: 38.299259 | Q21: 38.299259 | R21: 38.299259 | S21: 38.299259 | T21: 38.299259 | U21: 38.299259 | V21: 38.299259 | W21: 38.299259 | X21: 38.299259
A22: Residential | B22: Apartment | C22: Upper-Middle Income | D22: Old | E22: RESAPAUMOldDMD | F22: Mm2 | G22: 15.495888 | H22: 15.495888 | I22: 15.495888 | J22: 15.495888 | K22: 15.495888 | L22: 15.495888 | M22: 15.495888 | N22: 15.495888 | O22: 15.495888 | P22: 15.495888 | Q22: 15.495888 | R22: 15.495888 | S22: 15.495888 | T22: 15.495888 | U22: 15.495888 | V22: 15.495888 | W22: 15.495888 | X22: 15.495888
A23: Residential | B23: House | C23: Upper-Middle Income | D23: Old | E23: RESHOUUMOldDMD | F23: Mm2 | G23: 19.187214 | H23: 19.187214 | I23: 19.187214 | J23: 19.187214 | K23: 19.187214 | L23: 19.187214 | M23: 19.187214 | N23: 19.187214 | O23: 19.187214 | P23: 19.187214 | Q23: 19.187214 | R23: 19.187214 | S23: 19.187214 | T23: 19.187214 | U23: 19.187214 | V23: 19.187214 | W23: 19.187214 | X23: 19.187214
A24: Residential | B24: Apartment | C24: High Income | D24: Old | E24: RESAPAHIOldDMD | F24: Mm2 | G24: 66.398717 | H24: 66.398717 | I24: 66.398717 | J24: 66.398717 | K24: 66.398717 | L24: 66.398717 | M24: 66.398717 | N24: 66.398717 | O24: 66.398717 | P24: 66.398717 | Q24: 66.398717 | R24: 66.398717 | S24: 66.398717 | T24: 66.398717 | U24: 66.398717 | V24: 66.398717 | W24: 66.398717 | X24: 66.398717
A25: Residential | B25: House | C25: High Income | D25: Old | E25: RESHOUHIOldDMD | F25: Mm2 | G25: 96.552051 | H25: 96.552051 | I25: 96.552051 | J25: 96.552051 | K25: 96.552051 | L25: 96.552051 | M25: 96.552051 | N25: 96.552051 | O25: 96.552051 | P25: 96.552051 | Q25: 96.552051 | R25: 96.552051 | S25: 96.552051 | T25: 96.552051 | U25: 96.552051 | V25: 96.552051 | W25: 96.552051 | X25: 96.552051
A26: Residential | B26: Apartment | C26: Low Income | D26: New | E26: RESAPALONewDMD | F26: Mm2 | G26: 0 | H26: 0.25903939 | I26: 1.5542363 | J26: 2.8494333 | K26: 4.1446302 | L26: 5.4398271 | M26: 6.7350241 | N26: 8.030221 | O26: 9.3254179 | P26: 10.620615 | Q26: 11.915812 | R26: 13.211009 | S26: 14.506206 | T26: 15.801403 | U26: 17.0966 | V26: 18.391797 | W26: 19.686993 | X26: 20.98219
A27: Residential | B27: House | C27: Low Income | D27: New | E27: RESHOULONewDMD | F27: Mm2 | G27: 0 | H27: 0.07478399 | I27: 0.44870394 | J27: 0.82262389 | K27: 1.1965438 | L27: 1.5704638 | M27: 1.9443837 | N27: 2.3183037 | O27: 2.6922236 | P27: 3.0661436 | Q27: 3.4400635 | R27: 3.8139835 | S27: 4.1879034 | T27: 4.5618234 | U27: 4.9357433 | V27: 5.3096633 | W27: 5.6835832 | X27: 6.0575032
A28: Residential | B28: Apartment | C28: Lower-Middle Income | D28: New | E28: RESAPALMNewDMD | F28: Mm2 | G28: 0 | H28: 0.28560988 | I28: 1.7136593 | J28: 3.1417087 | K28: 4.5697581 | L28: 5.9978075 | M28: 7.4258569 | N28: 8.8539063 | O28: 10.281956 | P28: 11.710005 | Q28: 13.138055 | R28: 14.566104 | S28: 15.994153 | T28: 17.422203 | U28: 18.850252 | V28: 20.278302 | W28: 21.706351 | X28: 23.1344
A29: Residential | B29: House | C29: Lower-Middle Income | D29: New | E29: RESHOULMNewDMD | F29: Mm2 | G29: 0 | H29: 0.19149629 | I29: 1.1489778 | J29: 2.1064592 | K29: 3.0639407 | L29: 4.0214222 | M29: 4.9789036 | N29: 5.9363851 | O29: 6.8938665 | P29: 7.851348 | Q29: 8.8088295 | R29: 9.7663109 | S29: 10.723792 | T29: 11.681274 | U29: 12.638755 | V29: 13.596237 | W29: 14.553718 | X29: 15.5112
... A33: Residential | B33: House | C33: High Income | D33: New | E33: RESHOUHINewDMD | F33: Mm2 | G33: 0 | H33: 0.48276025 | I33: 2.8965615 | J33: 5.3103628 | K33: 7.7241641 | L33: 10.137965 | M33: 12.551767 | N33: 14.965568 | O33: 17.379369 | P33: 19.79317 | Q33: 22.206972 | R33: 24.620773 | S33: 27.034574 | T33: 29.448376 | U33: 31.862177 | V33: 34.275978 | W33: 36.689779 | X33: 39.103581
A34: Industrial | B34: All Industries | E34: INDAINDMD | F34: TJ | G34: 66716.461 | H34: 68050.79 | I34: 74855.869 | J34: 82341.456 | K34: 90575.602 | L34: 99633.162 | M34: 109596.48 | N34: 120556.13 | O34: 132611.74 | P34: 145872.91 | Q34: 160460.2 | R34: 176506.22 | S34: 194156.85 | T34: 213572.53 | U34: 234929.78 | V34: 258422.76 | W34: 284265.04 | X34: 312691.54
A35: Transportation | B35: Passenger | C35: Passenger Car | E35: TRAPASCARDMD | F35: M Vkm | G35: 68921.251 | H35: 69265.857 | I35: 70997.504 | J35: 72772.441 | K35: 74591.752 | L35: 76456.546 | M35: 78367.96 | N35: 80327.159 | O35: 82335.338 | P35: 84393.721 | Q35: 86503.564 | R35: 88666.153 | S35: 90882.807 | T35: 93154.877 | U35: 95483.749 | V35: 97870.843 | W35: 100317.61 | X35: 102825.55
A36: Transportation | B36: Passenger | C36: Passenger Truck | E36: TRAPASLDTDMD | F36: M Vkm | G36: 0 | H36: 0 | I36: 0 | J36: 0 | K36: 0 | L36: 0 | M36: 0 | N36: 0 | O36: 0 | P36: 0 | Q36: 0 | R36: 0 | S36: 0 | T36: 0 | U36: 0 | V36: 0 | W36: 0 | X36: 0
A37: Transportation | B37: Passenger | C37: Motorcycle | E37: TRAPASMOTDMD | F37: M Vkm | G37: 0 | H37: 0 | I37: 0 | J37: 0 | K37: 0 | L37: 0 | M37: 0 | N37: 0 | O37: 0 | P37: 0 | Q37: 0 | R37: 0 | S37: 0 | T37: 0 | U37: 0 | V37: 0 | W37: 0 | X37: 0
A38: Transportation | B38: Freight | C38: Light Commercial Truck | E38: TRAFRECLTDMD | F38: M Vkm | G38: 1578.5179 | H38: 1586.4105 | I38: 1626.0707 | J38: 1666.7225 | K38: 1708.3906 | L38: 1751.1003 | M38: 1794.8778 | N38: 1839.7498 | O38: 1885.7435 | P38: 1932.8871 | Q38: 1981.2093 | R38: 2030.7395 | S38: 2081.508 | T38: 2133.5457 | U38: 2186.8844 | V38: 2241.5565 | W38: 2297.5954 | X38: 2355.0353
A39: Transportation | B39: Freight | C39: Refuse Truck | E39: TRAFRERFTDMD | F39: M Vkm | G39: 70.026308 | H39: 70.37644 | I39: 72.135851 | J39: 73.939247 | K39: 75.787728 | L39: 77.682421 | M39: 79.624482 | N39: 81.615094 | O39: 83.655471 | P39: 85.746858 | Q39: 87.89053 | R39: 90.087793 | S39: 92.339988 | T39: 94.648487 | U39: 97.0147 | V39: 99.440067 | W39: 101.92607 | X39: 104.47422
A40: Transportation | B40: Freight | C40: Single Unit Long-haul Truck | E40: TRAFRESLHDMD | F40: M Vkm | G40: 0 | H40: 0 | I40: 0 | J40: 0 | K40: 0 | L40: 0 | M40: 0 | N40: 0 | O40: 0 | P40: 0 | Q40: 0 | R40: 0 | S40: 0 | T40: 0 | U40: 0 | V40: 0 | W40: 0 | X40: 0
A41: Transportation | B41: Freight | C41: Single Unit Short-haul Truck | E41: TRAFRESSHDMD | F41: M Vkm | G41: 0 | H41: 0 | I41: 0 | J41: 0 | K41: 0 | L41: 0 | M41: 0 | N41: 0 | O41: 0 | P41: 0 | Q41: 0 | R41: 0 | S41: 0 | T41: 0 | U41: 0 | V41: 0 | W41: 0 | X41: 0
A42: Transportation | B42: Freight | C42: Combination Long-haul Truck | E42: TRAFRECLHDMD | F42: M Vkm | G42: 1367.6202 | H42: 1374.4583 | I42: 1408.8197 | J42: 1444.0402 | K42: 1480.1412 | L42: 1517.1447 | M42: 1555.0734 | N42: 1593.9502 | O42: 1633.7989 | P42: 1674.6439 | Q42: 1716.51 | R42: 1759.4228 | S42: 1803.4083 | T42: 1848.4935 | U42: 1894.7059 | V42: 1942.0735 | W42: 1990.6254 | X42: 2040.391
A43: Transportation | B43: Freight | C43: Combination Short-haul Truck | E43: TRAFRECSHDMD | F43: M Vkm | G43: 0 | H43: 0 | I43: 0 | J43: 0 | K43: 0 | L43: 0 | M43: 0 | N43: 0 | O43: 0 | P43: 0 | Q43: 0 | R43: 0 | S43: 0 | T43: 0 | U43: 0 | V43: 0 | W43: 0 | X43: 0
A44: Transportation | B44: Passenger | C44: Transit Bus | E44: TRAPASTBUDMD | F44: M Vkm | G44: 498.20419 | H44: 500.69521 | I44: 513.21259 | J44: 526.0429 | K44: 539.19397 | L44: 552.67382 | M44: 566.49067 | N44: 580.65294 | O44: 595.16926 | P44: 610.04849 | Q44: 625.2997 | R44: 640.93219 | S44: 656.9555 | T44: 673.37939 | U44: 690.21387 | V44: 707.46922 | W44: 725.15595 | X44: 743.28485
A45: Transportation | B45: Passenger | C45: School Bus | E45: TRAPASSBUDMD | F45: M Vkm | G45: 86.053217 | H45: 86.483483 | I45: 88.645571 | J45: 90.86171 | K45: 93.133253 | L45: 95.461584 | M45: 97.848123 | N45: 100.29433 | O45: 102.80168 | P45: 105.37173 | Q45: 108.00602 | R45: 110.70617 | S45: 113.47382 | T45: 116.31067 | U45: 119.21844 | V45: 122.1989 | W45: 125.25387 | X45: 128.38522
A46: Transportation | B46: Passenger | C46: Other Buses | E46: TRAPASOBUDMD | F46: M Vkm | G46: 0 | H46: 0 | I46: 0 | J46: 0 | K46: 0 | L46: 0 | M46: 0 | N46: 0 | O46: 0 | P46: 0 | Q46: 0 | R46: 0 | S46: 0 | T46: 0 | U46: 0 | V46: 0 | W46: 0 | X46: 0
...

Sheet BDG Intensity
A1: Sector | B1: Sub-sector | C1: Archetype | D1: Vintage | E1: End Use | F1: Technology Label | G1: Input Unit | H1: Efficiency Unit | I1: 2019 | J1: 2020 | K1: 2025 | L1: 2030 | M1: 2035 | N1: 2040 | O1: 2045 | P1: 2050 | Q1: 2055 | R1: 2060 | S1: 2065 | T1: 2070 | U1: 2075 | V1: 2080 | W1: 2085 | X1: 2090 | Y1: 2095 | Z1: 2100
A2: Commercial | B2: Hotel | D2: Old | E2: Space heating | F2: COMHOTOldSH | G2: TJ | H2: TJ / Mm2 | I2: 129.27947 | J2: 128.90001 | K2: 127.00271 | L2: 125.10541 | M2: 123.20812 | N2: 121.31082 | O2: 119.41352 | P2: 117.51622 | Q2: 116.64184 | R2: 115.76747 | S2: 114.8931 | T2: 114.01872 | U2: 113.14435 | V2: 112.26997 | W2: 111.3956 | X2: 110.52123 | Y2: 109.64685 | Z2: 108.77248
A3: Commercial | B3: Retail | D3: Old | E3: Space heating | F3: COMRETOldSH | G3: TJ | H3: TJ / Mm2 | I3: 210.3111 | J3: 209.6938 | K3: 206.60728 | L3: 203.52077 | M3: 200.43425 | N3: 197.34774 | O3: 194.26122 | P3: 191.17471 | Q3: 189.75228 | R3: 188.32985 | S3: 186.90743 | T3: 185.485 | U3: 184.06257 | V3: 182.64015 | W3: 181.21772 | X3: 179.79529 | Y3: 178.37287 | Z3: 176.95044
A4: Commercial | B4: Office | D4: Old | E4: Space heating | F4: COMOFFOldSH | G4: TJ | H4: TJ / Mm2 | I4: 307.55127 | J4: 306.64855 | K4: 302.13495 | L4: 297.62134 | M4: 293.10773 | N4: 288.59413 | O4: 284.08052 | P4: 279.56691 | Q4: 277.48681 | R4: 275.4067 | S4: 273.3266 | T4: 271.24649 | U4: 269.16639 | V4: 267.08628 | W4: 265.00618 | X4: 262.92607 | Y4: 260.84597 | Z4: 258.76586
A5: Commercial | B5: Hospital | D5: Old | E5: Space heating | F5: COMHOPOldSH | G5: TJ | H5: TJ / Mm2 | I5: 472.42392 | J5: 471.03726 | K5: 464.10399 | L5: 457.17072 | M5: 450.23745 | N5: 443.30419 | O5: 436.37092 | P5: 429.43765 | Q5: 426.24244 | R5: 423.04723 | S5: 419.85201 | T5: 416.6568 | U5: 413.46159 | V5: 410.26638 | W5: 407.07117 | X5: 403.87596 | Y5: 400.68075 | Z5: 397.48553
A6: Commercial | B6: Educationnal | D6: Old | E6: Space heating | F6: COMEDUOldSH | G6: TJ | H6: TJ / Mm2 | I6: 275.63255 | J6: 274.82352 | K6: 270.77835 | L6: 266.73318 | M6: 262.68801 | N6: 258.64284 | O6: 254.59767 | P6: 250.5525 | Q6: 248.68828 | R6: 246.82406 | S6: 244.95983 | T6: 243.09561 | U6: 241.23138 | V6: 239.36716 | W6: 237.50293 | X6: 235.63871 | Y6: 233.77448 | Z6: 231.91026
A7: Commercial | B7: Warehouse | D7: Old | E7: Space heating | F7: COMWAROldSH | G7: TJ | H7: TJ / Mm2 | I7: 138.18369 | J7: 137.77809 | K7: 135.75012 | L7: 133.72214 | M7: 131.69416 | N7: 129.66619 | O7: 127.63821 | P7: 125.61023 | Q7: 124.67564 | R7: 123.74104 | S7: 122.80644 | T7: 121.87184 | U7: 120.93725 | V7: 120.00265 | W7: 119.06805 | X7: 118.13346 | Y7: 117.19886 | Z7: 116.26426
A8: Commercial | B8: Municipal | D8: Old | E8: Space heating | F8: COMMUNOldSH | G8: TJ | H8: TJ / Mm2 | I8: 637.37305 | J8: 635.50224 | K8: 626.14819 | L8: 616.79413 | M8: 607.44008 | N8: 598.08602 | O8: 588.73197 | P8: 579.37792 | Q8: 575.06708 | R8: 570.75625 | S8: 566.44541 | T8: 562.13458 | U8: 557.82374 | V8: 553.51291 | W8: 549.20207 | X8: 544.89124 | Y8: 540.5804 | Z8: 536.26957
A9: Commercial | B9: Other | D9: Old | E9: Space heating | F9: COMOTHOldSH | G9: TJ | H9: TJ / Mm2 | I9: 512.32862 | J9: 510.82484 | K9: 503.30593 | L9: 495.78702 | M9: 488.26812 | N9: 480.74921 | O9: 473.2303 | P9: 465.71139 | Q9: 462.24629 | R9: 458.78118 | S9: 455.31608 | T9: 451.85097 | U9: 448.38587 | V9: 444.92076 | W9: 441.45566 | X9: 437.99056 | Y9: 434.52545 | Z9: 431.06035
A10: Commercial | B10: Hotel | D10: Old | E10: Space cooling | F10: COMHOTOldSC | G10: TJ | H10: TJ / Mm2 | I10: 88.604863 | J10: 89.174759 | K10: 92.024236 | L10: 94.873714 | M10: 97.723191 | N10: 100.57267 | O10: 103.42215 | P10: 106.27162 | Q10: 107.58481 | R10: 108.898 | S10: 110.21119 | T10: 111.52437 | U10: 112.83756 | V10: 114.15075 | W10: 115.46394 | X10: 116.77712 | Y10: 118.09031 | Z10: 119.4035
A11: Commercial | B11: Retail | D11: Old | E11: Space cooling | F11: COMRETOldSC | G11: TJ | H11: TJ / Mm2 | I11: 41.937414 | J11: 42.20715 | K11: 43.555831 | L11: 44.904512 | M11: 46.253194 | N11: 47.601875 | O11: 48.950556 | P11: 50.299237 | Q11: 50.92078 | R11: 51.542322 | S11: 52.163865 | T11: 52.785407 | U11: 53.40695 | V11: 54.028493 | W11: 54.650035 | X11: 55.271578 | Y11: 55.89312 | Z11: 56.514663
A12: Commercial | B12: Office | D12: Old | E12: Space cooling | F12: COMOFFOldSC | G12: TJ | H12: TJ / Mm2 | I12: 47.27198 | J12: 47.576028 | K12: 49.096265 | L12: 50.616503 | M12: 52.13674 | N12: 53.656978 | O12: 55.177216 | P12: 56.697453 | Q12: 57.398058 | R12: 58.098662 | S12: 58.799267 | T12: 59.499872 | U12: 60.200476 | V12: 60.901081 | W12: 61.601686 | X12: 62.30229 | Y12: 63.002895 | Z12: 63.7035
A13: Commercial | B13: Hospital | D13: Old | E13: Space cooling | F13: COMHOPOldSC | G13: TJ | H13: TJ / Mm2 | I13: 129.66222 | J13: 130.49619 | K13: 134.66605 | L13: 138.83591 | M13: 143.00576 | N13: 147.17562 | O13: 151.34548 | P13: 155.51533 | Q13: 157.43702 | R13: 159.35871 | S13: 161.2804 | T13: 163.20208 | U13: 165.12377 | V13: 167.04546 | W13: 168.96714 | X13: 170.88883 | Y13: 172.81052 | Z13: 174.73221
... A45: Commercial | B45: Hospital | D45: Old | E45: Cooking | F45: COMHOPOldCK | G45: TJ | H45: TJ / Mm2 | I45: 84.801098 | J45: 84.801098 | K45: 84.801098 | L45: 84.801098 | M45: 84.801098 | N45: 84.801098 | O45: 84.801098 | P45: 84.801098 | Q45: 84.801098 | R45: 84.801098 | S45: 84.801098 | T45: 84.801098 | U45: 84.801098 | V45: 84.801098 | W45: 84.801098 | X45: 84.801098 | Y45: 84.801098 | Z45: 84.801098
A46: Commercial | B46: Educationnal | D46: Old | E46: Cooking | F46: COMEDUOldCK | G46: TJ | H46: TJ / Mm2 | I46: 20.119699 | J46: 20.119699 | K46: 20.119699 | L46: 20.119699 | M46: 20.119699 | N46: 20.119699 | O46: 20.119699 | P46: 20.119699 | Q46: 20.119699 | R46: 20.119699 | S46: 20.119699 | T46: 20.119699 | U46: 20.119699 | V46: 20.119699 | W46: 20.119699 | X46: 20.119699 | Y46: 20.119699 | Z46: 20.119699 | AA46: 1.2368805
A47: Commercial | B47: Warehouse | D47: Old | E47: Cooking | F47: COMWAROldCK | G47: TJ | H47: TJ / Mm2 | I47: 0.65967771 | J47: 0.65967771 | K47: 0.65967771 | L47: 0.65967771 | M47: 0.65967771 | N47: 0.65967771 | O47: 0.65967771 | P47: 0.65967771 | Q47: 0.65967771 | R47: 0.65967771 | S47: 0.65967771 | T47: 0.65967771 | U47: 0.65967771 | V47: 0.65967771 | W47: 0.65967771 | X47: 0.65967771 | Y47: 0.65967771 | Z47: 0.65967771
A48: Commercial | B48: Municipal | D48: Old | E48: Cooking | F48: COMMUNOldCK | G48: TJ | H48: TJ / Mm2 | I48: 45.22305 | J48: 45.22305 | K48: 45.22305 | L48: 45.22305 | M48: 45.22305 | N48: 45.22305 | O48: 45.22305 | P48: 45.22305 | Q48: 45.22305 | R48: 45.22305 | S48: 45.22305 | T48: 45.22305 | U48: 45.22305 | V48: 45.22305 | W48: 45.22305 | X48: 45.22305 | Y48: 45.22305 | Z48: 45.22305
A49: Commercial | B49: Other | D49: Old | E49: Cooking | F49: COMOTHOldCK | G49: TJ | H49: TJ / Mm2 | I49: 14.956655 | J49: 14.956655 | K49: 14.956655 | L49: 14.956655 | M49: 14.956655 | N49: 14.956655 | O49: 14.956655 | P49: 14.956655 | Q49: 14.956655 | R49: 14.956655 | S49: 14.956655 | T49: 14.956655 | U49: 14.956655 | V49: 14.956655 | W49: 14.956655 | X49: 14.956655 | Y49: 14.956655 | Z49: 14.956655
A50: Commercial | B50: Hotel | D50: Old | E50: Refrigeration | F50: COMHOTOldRE | G50: TJ | H50: TJ / Mm2 | I50: 30.095991 | J50: 30.095991 | K50: 30.095991 | L50: 30.095991 | M50: 30.095991 | N50: 30.095991 | O50: 30.095991 | P50: 30.095991 | Q50: 30.095991 | R50: 30.095991 | S50: 30.095991 | T50: 30.095991 | U50: 30.095991 | V50: 30.095991 | W50: 30.095991 | X50: 30.095991 | Y50: 30.095991 | Z50: 30.095991
A51: Commercial | B51: Retail | D51: Old | E51: Refrigeration | F51: COMRETOldRE | G51: TJ | H51: TJ / Mm2 | I51: 27.991169 | J51: 27.991169 | K51: 27.991169 | L51: 27.991169 | M51: 27.991169 | N51: 27.991169 | O51: 27.991169 | P51: 27.991169 | Q51: 27.991169 | R51: 27.991169 | S51: 27.991169 | T51: 27.991169 | U51: 27.991169 | V51: 27.991169 | W51: 27.991169 | X51: 27.991169 | Y51: 27.991169 | Z51: 27.991169
A52: Commercial | B52: Office | D52: Old | E52: Refrigeration | F52: COMOFFOldRE | G52: TJ | H52: TJ / Mm2 | I52: 4.4814596 | J52: 4.4814596 | K52: 4.4814596 | L52: 4.4814596 | M52: 4.4814596 | N52: 4.4814596 | O52: 4.4814596 | P52: 4.4814596 | Q52: 4.4814596 | R52: 4.4814596 | S52: 4.4814596 | T52: 4.4814596 | U52: 4.4814596 | V52: 4.4814596 | W52: 4.4814596 | X52: 4.4814596 | Y52: 4.4814596 | Z52: 4.4814596
A53: Commercial | B53: Hospital | D53: Old | E53: Refrigeration | F53: COMHOPOldRE | G53: TJ | H53: TJ / Mm2 | I53: 21.969171 | J53: 21.969171 | K53: 21.969171 | L53: 21.969171 | M53: 21.969171 | N53: 21.969171 | O53: 21.969171 | P53: 21.969171 | Q53: 21.969171 | R53: 21.969171 | S53: 21.969171 | T53: 21.969171 | U53: 21.969171 | V53: 21.969171 | W53: 21.969171 | X53: 21.969171 | Y53: 21.969171 | Z53: 21.969171
A54: Commercial | B54: Educationnal | D54: Old | E54: Refrigeration | F54: COMEDUOldRE | G54: TJ | H54: TJ / Mm2 | I54: 11.765972 | J54: 11.765972 | K54: 11.765972 | L54: 11.765972 | M54: 11.765972 | N54: 11.765972 | O54: 11.765972 | P54: 11.765972 | Q54: 11.765972 | R54: 11.765972 | S54: 11.765972 | T54: 11.765972 | U54: 11.765972 | V54: 11.765972 | W54: 11.765972 | X54: 11.765972 | Y54: 11.765972 | Z54: 11.765972
A55: Commercial | B55: Warehouse | D55: Old | E55: Refrigeration | F55: COMWAROldRE | G55: TJ | H55: TJ / Mm2 | I55: 13.111522 | J55: 13.111522 | K55: 13.111522 | L55: 13.111522 | M55: 13.111522 | N55: 13.111522 | O55: 13.111522 | P55: 13.111522 | Q55: 13.111522 | R55: 13.111522 | S55: 13.111522 | T55: 13.111522 | U55: 13.111522 | V55: 13.111522 | W55: 13.111522 | X55: 13.111522 | Y55: 13.111522 | Z55: 13.111522
A56: Commercial | B56: Municipal | D56: Old | E56: Refrigeration | F56: COMMUNOldRE | G56: TJ | H56: TJ / Mm2 | I56: 31.823291 | J56: 31.823291 | K56: 31.823291 | L56: 31.823291 | M56: 31.823291 | N56: 31.823291 | O56: 31.823291 | P56: 31.823291 | Q56: 31.823291 | R56: 31.823291 | S56: 31.823291 | T56: 31.823291 | U56: 31.823291 | V56: 31.823291 | W56: 31.823291 | X56: 31.823291 | Y56: 31.823291 | Z56: 31.823291
A57: Commercial | B57: Other | D57: Old | E57: Refrigeration | F57: COMOTHOldRE | G57: TJ | H57: TJ / Mm2 | I57: 10.983671 | J57: 10.983671 | K57: 10.983671 | L57: 10.983671 | M57: 10.983671 | N57: 10.983671 | O57: 10.983671 | P57: 10.983671 | Q57: 10.983671 | R57: 10.983671 | S57: 10.983671 | T57: 10.983671 | U57: 10.983671 | V57: 10.983671 | W57: 10.983671 | X57: 10.983671 | Y57: 10.983671 | Z57: 10.983671
A58: Commercial | B58: Hotel | D58: Old | E58: Other end use | F58: COMHOTOldOE | G58: TJ | H58: TJ / Mm2 | I58: 202.44691 | J58: 202.44691 | K58: 202.44691 | L58: 202.44691 | M58: 202.44691 | N58: 202.44691 | O58: 202.44691 | P58: 202.44691 | Q58: 202.44691 | R58: 202.44691 | S58: 202.44691 | T58: 202.44691 | U58: 202.44691 | V58: 202.44691 | W58: 202.44691 | X58: 202.44691 | Y58: 202.44691 | Z58: 202.44691
... A129: Commercial | B129: Other | D129: New | E129: Other end use | F129: COMOTHNewOE | G129: TJ | H129: TJ / Mm2 | I129: 584.60586 | J129: 584.60586 | K129: 584.60586 | L129: 584.60586 | M129: 584.60586 | N129: 584.60586 | O129: 584.60586 | P129: 584.60586 | Q129: 584.60586 | R129: 584.60586 | S129: 584.60586 | T129: 584.60586 | U129: 584.60586 | V129: 584.60586 | W129: 584.60586 | X129: 584.60586 | Y129: 584.60586 | Z129: 584.60586
A130: Residential | B130: Apartment | C130: Low Income | D130: Old | E130: Space heating | F130: RESAPALOOldSH | G130: TJ | H130: TJ / Mm2 | I130: 250.95541 | J130: 250.95541 | K130: 246.5358 | L130: 242.85279 | M130: 239.16978 | N130: 235.48677 | O130: 231.80377 | P130: 228.12076 | Q130: 226.42343 | R130: 224.72611 | S130: 223.02879 | T130: 221.33147 | U130: 219.63415 | V130: 217.93682 | W130: 216.2395 | X130: 214.54218 | Y130: 212.84486 | Z130: 211.14754
A131: Residential | B131: House | C131: Low Income | D131: Old | E131: Space heating | F131: RESHOULOOldSH | G131: TJ | H131: TJ / Mm2 | I131: 477.33616 | J131: 477.33616 | K131: 468.92973 | L131: 461.92437 | M131: 454.91901 | N131: 447.91365 | O131: 440.90828 | P131: 433.90292 | Q131: 430.67449 | R131: 427.44605 | S131: 424.21762 | T131: 420.98918 | U131: 417.76075 | V131: 414.53231 | W131: 411.30388 | X131: 408.07544 | Y131: 404.84701 | Z131: 401.61857
A132: Residential | B132: Apartment | C132: Lower-Middle Income | D132: Old | E132: Space heating | F132: RESAPALMOldSH | G132: TJ | H132: TJ / Mm2 | I132: 279.92208 | J132: 279.92208 | K132: 274.99234 | L132: 270.88422 | M132: 266.77609 | N132: 262.66797 | O132: 258.55985 | P132: 254.45173 | Q132: 252.55849 | R132: 250.66526 | S132: 248.77202 | T132: 246.87878 | U132: 244.98555 | V132: 243.09231 | W132: 241.19907 | X132: 239.30584 | Y132: 237.4126 | Z132: 235.51936
A133: Residential | B133: House | C133: Lower-Middle Income | D133: Old | E133: Space heating | F133: RESHOULMOldSH | G133: TJ | H133: TJ / Mm2 | I133: 462.51081 | J133: 462.51081 | K133: 454.36547 | L133: 447.57769 | M133: 440.7899 | N133: 434.00212 | O133: 427.21433 | P133: 420.42655 | Q133: 417.29838 | R133: 414.17022 | S133: 411.04205 | T133: 407.91389 | U133: 404.78573 | V133: 401.65756 | W133: 398.5294 | X133: 395.40123 | Y133: 392.27307 | Z133: 389.1449
A134: Residential | B134: Apartment | C134: Upper-Middle Income | D134: Old | E134: Space heating | F134: RESAPAUMOldSH | G134: TJ | H134: TJ / Mm2 | I134: 261.1929 | J134: 261.1929 | K134: 256.593 | L134: 252.75975 | M134: 248.92649 | N134: 245.09324 | O134: 241.25999 | P134: 237.42673 | Q134: 235.66017 | R134: 233.89361 | S134: 232.12704 | T134: 230.36048 | U134: 228.59392 | V134: 226.82735 | W134: 225.06079 | X134: 223.29423 | Y134: 221.52767 | Z134: 219.7611
A135: Residential | B135: House | C135: Upper-Middle Income | D135: Old | E135: Space heating | F135: RESHOUUMOldSH | G135: TJ | H135: TJ / Mm2 | I135: 525.45185 | J135: 525.45185 | K135: 516.19804 | L135: 508.48654 | M135: 500.77504 | N135: 493.06353 | O135: 485.35203 | P135: 477.64052 | Q135: 474.08666 | R135: 470.5328 | S135: 466.97894 | T135: 463.42507 | U135: 459.87121 | V135: 456.31735 | W135: 452.76349 | X135: 449.20962 | Y135: 445.65576 | Z135: 442.1019
A136: Residential | B136: Apartment | C136: High Income | D136: Old | E136: Space heating | F136: RESAPAHIOldSH | G136: TJ | H136: TJ / Mm2 | I136: 242.87522 | J136: 242.87522 | K136: 238.59791 | L136: 235.03348 | M136: 231.46906 | N136: 227.90464 | O136: 224.34021 | P136: 220.77579 | Q136: 219.13311 | R136: 217.49044 | S136: 215.84777 | T136: 214.2051 | U136: 212.56243 | V136: 210.91975 | W136: 209.27708 | X136: 207.63441 | Y136: 205.99174 | Z136: 204.34906
A137: Residential | B137: House | C137: High Income | D137: Old | E137: Space heating | F137: RESHOUHIOldSH | G137: TJ | H137: TJ / Mm2 | I137: 460.64753 | J137: 460.64753 | K137: 452.535 | L137: 445.77456 | M137: 439.01412 | N137: 432.25369 | O137: 425.49325 | P137: 418.73281 | Q137: 415.61724 | R137: 412.50168 | S137: 409.38612 | T137: 406.27056 | U137: 403.15499 | V137: 400.03943 | W137: 396.92387 | X137: 393.80831 | Y137: 390.69275 | Z137: 387.57718
A138: Residential | B138: Apartment | C138: Low Income | D138: Old | E138: Space cooling | F138: RESAPALOOldSC | G138: TJ | H138: TJ / Mm2 | I138: 69.115623 | J138: 69.115623 | K138: 71.782882 | L138: 74.005598 | M138: 76.228313 | N138: 78.451029 | O138: 80.673745 | P138: 82.89646 | Q138: 83.920803 | R138: 84.945146 | S138: 85.969489 | T138: 86.993833 | U138: 88.018176 | V138: 89.042519 | W138: 90.066862 | X138: 91.091205 | Y138: 92.115548 | Z138: 93.139891
A139: Residential | B139: House | C139: Low Income | D139: Old | E139: Space cooling | F139: RESHOULOOldSC | G139: TJ | H139: TJ / Mm2 | I139: 87.185415 | J139: 87.185415 | K139: 90.550009 | L139: 93.353838 | M139: 96.157667 | N139: 98.961496 | O139: 101.76533 | P139: 104.56915 | Q139: 105.8613 | R139: 107.15345 | S139: 108.44561 | T139: 109.73776 | U139: 111.02991 | V139: 112.32206 | W139: 113.61421 | X139: 114.90636 | Y139: 116.19851 | Z139: 117.49066
A140: Residential | B140: Apartment | C140: Lower-Middle Income | D140: Old | E140: Space cooling | F140: RESAPALMOldSC | G140: TJ | H140: TJ / Mm2 | I140: 76.158562 | J140: 76.158562 | K140: 79.097617 | L140: 81.546829 | M140: 83.996041 | N140: 86.445253 | O140: 88.894466 | P140: 91.343678 | Q140: 92.472402 | R140: 93.601127 | S140: 94.729851 | T140: 95.858576 | U140: 96.9873 | V140: 98.116025 | W140: 99.244749 | X140: 100.37347 | Y140: 101.5022 | Z140: 102.63092
A141: Residential | B141: House | C141: Lower-Middle Income | D141: Old | E141: Space cooling | F141: RESHOULMOldSC | G141: TJ | H141: TJ / Mm2 | I141: 82.712671 | J141: 82.712671 | K141: 85.904657 | L141: 88.564646 | M141: 91.224634 | N141: 93.884622 | O141: 96.544611 | P141: 99.204599 | Q141: 100.43046 | R141: 101.65632 | S141: 102.88218 | T141: 104.10804 | U141: 105.3339 | V141: 106.55977 | W141: 107.78563 | X141: 109.01149 | Y141: 110.23735 | Z141: 111.46321
...

Sheet >> TIMES

Sheet Def_Tech
B2: ~FI_Process
B3: Sets | C3: Region | D3: TechName | E3: TechDesc | F3: Tact | G3: Tcap | H3: Tslvl | I3: PrimaryCG | J3: Vintage
B4: *Process Set Membership | C4: Region | D4: Technology Name | E4: Technology Description | F4: Activity Unit | G4: Capacity Unit | H4: TimeSlice level of Process Activity | I4: Primary Commodity Group | J4: Vintage Tracking
B5: PRE | C5: CITY | D5: =LEFT(Demand!E2,LEN(Demand!E2)-3) | E5: =Demand!A2&" "&Demand!B2&" "&Demand!C2&" "&Demand!D2&" "&"demand agg" | F5: Mm2 | G5: Mm2
C6: CITY | D6: =LEFT(Demand!E3,LEN(Demand!E3)-3) | E6: =Demand!A3&" "&Demand!B3&" "&Demand!C3&" "&Demand!D3&" "&"demand agg" | F6: Mm2 | G6: Mm2
C7: CITY | D7: =LEFT(Demand!E4,LEN(Demand!E4)-3) | E7: =Demand!A4&" "&Demand!B4&" "&Demand!C4&" "&Demand!D4&" "&"demand agg" | F7: Mm2 | G7: Mm2
C8: CITY | D8: =LEFT(Demand!E5,LEN(Demand!E5)-3) | E8: =Demand!A5&" "&Demand!B5&" "&Demand!C5&" "&Demand!D5&" "&"demand agg" | F8: Mm2 | G8: Mm2
C9: CITY | D9: =LEFT(Demand!E6,LEN(Demand!E6)-3) | E9: =Demand!A6&" "&Demand!B6&" "&Demand!C6&" "&Demand!D6&" "&"demand agg" | F9: Mm2 | G9: Mm2
C10: CITY | D10: =LEFT(Demand!E7,LEN(Demand!E7)-3) | E10: =Demand!A7&" "&Demand!B7&" "&Demand!C7&" "&Demand!D7&" "&"demand agg" | F10: Mm2 | G10: Mm2
C11: CITY | D11: =LEFT(Demand!E8,LEN(Demand!E8)-3) | E11: =Demand!A8&" "&Demand!B8&" "&Demand!C8&" "&Demand!D8&" "&"demand agg" | F11: Mm2 | G11: Mm2
C12: CITY | D12: =LEFT(Demand!E9,LEN(Demand!E9)-3) | E12: =Demand!A9&" "&Demand!B9&" "&Demand!C9&" "&Demand!D9&" "&"demand agg" | F12: Mm2 | G12: Mm2
C13: CITY | D13: =LEFT(Demand!E10,LEN(Demand!E10)-3) | E13: =Demand!A10&" "&Demand!B10&" "&Demand!C10&" "&Demand!D10&" "&"demand agg" | F13: Mm2 | G13: Mm2
C14: CITY | D14: =LEFT(Demand!E11,LEN(Demand!E11)-3) | E14: =Demand!A11&" "&Demand!B11&" "&Demand!C11&" "&Demand!D11&" "&"demand agg" | F14: Mm2 | G14: Mm2
C15: CITY | D15: =LEFT(Demand!E12,LEN(Demand!E12)-3) | E15: =Demand!A12&" "&Demand!B12&" "&Demand!C12&" "&Demand!D12&" "&"demand agg" | F15: Mm2 | G15: Mm2
C16: CITY | D16: =LEFT(Demand!E13,LEN(Demand!E13)-3) | E16: =Demand!A13&" "&Demand!B13&" "&Demand!C13&" "&Demand!D13&" "&"demand agg" | F16: Mm2 | G16: Mm2
C17: CITY | D17: =LEFT(Demand!E14,LEN(Demand!E14)-3) | E17: =Demand!A14&" "&Demand!B14&" "&Demand!C14&" "&Demand!D14&" "&"demand agg" | F17: Mm2 | G17: Mm2
... C20: CITY | D20: =LEFT(Demand!E17,LEN(Demand!E17)-3) | E20: =Demand!A17&" "&Demand!B17&" "&Demand!C17&" "&Demand!D17&" "&"demand agg" | F20: Mm2 | G20: Mm2
B21: *
B22: PRE | C22: CITY | D22: ='BDG Intensity'!F2 | E22: ='BDG Intensity'!A2&" "&'BDG Intensity'!B2&" "&'BDG Intensity'!C2&" "&'BDG Intensity'!D2&" "&'BDG Intensity'!E2&" "&"Building Efficiency" | F22: Mm2 | G22: Mm2
C23: CITY | D23: ='BDG Intensity'!F3 | E23: ='BDG Intensity'!A3&" "&'BDG Intensity'!B3&" "&'BDG Intensity'!C3&" "&'BDG Intensity'!D3&" "&'BDG Intensity'!E3&" "&"Building Efficiency" | F23: Mm2 | G23: Mm2
C24: CITY | D24: ='BDG Intensity'!F4 | E24: ='BDG Intensity'!A4&" "&'BDG Intensity'!B4&" "&'BDG Intensity'!C4&" "&'BDG Intensity'!D4&" "&'BDG Intensity'!E4&" "&"Building Efficiency" | F24: Mm2 | G24: Mm2
C25: CITY | D25: ='BDG Intensity'!F5 | E25: ='BDG Intensity'!A5&" "&'BDG Intensity'!B5&" "&'BDG Intensity'!C5&" "&'BDG Intensity'!D5&" "&'BDG Intensity'!E5&" "&"Building Efficiency" | F25: Mm2 | G25: Mm2
C26: CITY | D26: ='BDG Intensity'!F6 | E26: ='BDG Intensity'!A6&" "&'BDG Intensity'!B6&" "&'BDG Intensity'!C6&" "&'BDG Intensity'!D6&" "&'BDG Intensity'!E6&" "&"Building Efficiency" | F26: Mm2 | G26: Mm2
C27: CITY | D27: ='BDG Intensity'!F7 | E27: ='BDG Intensity'!A7&" "&'BDG Intensity'!B7&" "&'BDG Intensity'!C7&" "&'BDG Intensity'!D7&" "&'BDG Intensity'!E7&" "&"Building Efficiency" | F27: Mm2 | G27: Mm2
C28: CITY | D28: ='BDG Intensity'!F8 | E28: ='BDG Intensity'!A8&" "&'BDG Intensity'!B8&" "&'BDG Intensity'!C8&" "&'BDG Intensity'!D8&" "&'BDG Intensity'!E8&" "&"Building Efficiency" | F28: Mm2 | G28: Mm2
C29: CITY | D29: ='BDG Intensity'!F9 | E29: ='BDG Intensity'!A9&" "&'BDG Intensity'!B9&" "&'BDG Intensity'!C9&" "&'BDG Intensity'!D9&" "&'BDG Intensity'!E9&" "&"Building Efficiency" | F29: Mm2 | G29: Mm2
C30: CITY | D30: ='BDG Intensity'!F10 | E30: ='BDG Intensity'!A10&" "&'BDG Intensity'!B10&" "&'BDG Intensity'!C10&" "&'BDG Intensity'!D10&" "&'BDG Intensity'!E10&" "&"Building Efficiency" | F30: Mm2 | G30: Mm2
C31: CITY | D31: ='BDG Intensity'!F11 | E31: ='BDG Intensity'!A11&" "&'BDG Intensity'!B11&" "&'BDG Intensity'!C11&" "&'BDG Intensity'!D11&" "&'BDG Intensity'!E11&" "&"Building Efficiency" | F31: Mm2 | G31: Mm2
C32: CITY | D32: ='BDG Intensity'!F12 | E32: ='BDG Intensity'!A12&" "&'BDG Intensity'!B12&" "&'BDG Intensity'!C12&" "&'BDG Intensity'!D12&" "&'BDG Intensity'!E12&" "&"Building Efficiency" | F32: Mm2 | G32: Mm2
C33: CITY | D33: ='BDG Intensity'!F13 | E33: ='BDG Intensity'!A13&" "&'BDG Intensity'!B13&" "&'BDG Intensity'!C13&" "&'BDG Intensity'!D13&" "&'BDG Intensity'!E13&" "&"Building Efficiency" | F33: Mm2 | G33: Mm2
C34: CITY | D34: ='BDG Intensity'!F14 | E34: ='BDG Intensity'!A14&" "&'BDG Intensity'!B14&" "&'BDG Intensity'!C14&" "&'BDG Intensity'!D14&" "&'BDG Intensity'!E14&" "&"Building Efficiency" | F34: Mm2 | G34: Mm2
... C149: CITY | D149: ='BDG Intensity'!F129 | E149: ='BDG Intensity'!A129&" "&'BDG Intensity'!B129&" "&'BDG Intensity'!C129&" "&'BDG Intensity'!D129&" "&'BDG Intensity'!E129&" "&"Building Efficiency" | F149: Mm2 | G149: Mm2
B150: *
B151: =IF(_xlfn.XLOOKUP(D151,'COM RESID'!J:J,'COM RESID'!P:P)=0,"*","PRE") | C151: CITY | D151: ='COM RESID'!J2 | E151: ='COM RESID'!A2&" "&'COM RESID'!B2&" "&'COM RESID'!C2&" "&'COM RESID'!D2&" "&'COM RESID'!E2&" "&'COM RESID'!F2 | F151: =IF(G151="MW","TJ",LEFT(G151,LEN(G151)-1)) | G151: ='COM RESID'!Q2
B152: =IF(_xlfn.XLOOKUP(D152,'COM RESID'!J:J,'COM RESID'!P:P)=0,"*","PRE") | C152: CITY | D152: ='COM RESID'!J3 | E152: ='COM RESID'!A3&" "&'COM RESID'!B3&" "&'COM RESID'!C3&" "&'COM RESID'!D3&" "&'COM RESID'!E3&" "&'COM RESID'!F3 | F152: =IF(G152="MW","TJ",LEFT(G152,LEN(G152)-1)) | G152: ='COM RESID'!Q3
B153: =IF(_xlfn.XLOOKUP(D153,'COM RESID'!J:J,'COM RESID'!P:P)=0,"*","PRE") | C153: CITY | D153: ='COM RESID'!J4 | E153: ='COM RESID'!A4&" "&'COM RESID'!B4&" "&'COM RESID'!C4&" "&'COM RESID'!D4&" "&'COM RESID'!E4&" "&'COM RESID'!F4 | F153: =IF(G153="MW","TJ",LEFT(G153,LEN(G153)-1)) | G153: ='COM RESID'!Q4
B154: =IF(_xlfn.XLOOKUP(D154,'COM RESID'!J:J,'COM RESID'!P:P)=0,"*","PRE") | C154: CITY | D154: ='COM RESID'!J5 | E154: ='COM RESID'!A5&" "&'COM RESID'!B5&" "&'COM RESID'!C5&" "&'COM RESID'!D5&" "&'COM RESID'!E5&" "&'COM RESID'!F5 | F154: =IF(G154="MW","TJ",LEFT(G154,LEN(G154)-1)) | G154: ='COM RESID'!Q5
B155: =IF(_xlfn.XLOOKUP(D155,'COM RESID'!J:J,'COM RESID'!P:P)=0,"*","PRE") | C155: CITY | D155: ='COM RESID'!J6 | E155: ='COM RESID'!A6&" "&'COM RESID'!B6&" "&'COM RESID'!C6&" "&'COM RESID'!D6&" "&'COM RESID'!E6&" "&'COM RESID'!F6 | F155: =IF(G155="MW","TJ",LEFT(G155,LEN(G155)-1)) | G155: ='COM RESID'!Q6
B156: =IF(_xlfn.XLOOKUP(D156,'COM RESID'!J:J,'COM RESID'!P:P)=0,"*","PRE") | C156: CITY | D156: ='COM RESID'!J7 | E156: ='COM RESID'!A7&" "&'COM RESID'!B7&" "&'COM RESID'!C7&" "&'COM RESID'!D7&" "&'COM RESID'!E7&" "&'COM RESID'!F7 | F156: =IF(G156="MW","TJ",LEFT(G156,LEN(G156)-1)) | G156: ='COM RESID'!Q7
B157: =IF(_xlfn.XLOOKUP(D157,'COM RESID'!J:J,'COM RESID'!P:P)=0,"*","PRE") | C157: CITY | D157: ='COM RESID'!J8 | E157: ='COM RESID'!A8&" "&'COM RESID'!B8&" "&'COM RESID'!C8&" "&'COM RESID'!D8&" "&'COM RESID'!E8&" "&'COM RESID'!F8 | F157: =IF(G157="MW","TJ",LEFT(G157,LEN(G157)-1)) | G157: ='COM RESID'!Q8
...

Sheet Def_Comm
B2: ~FI_Comm
B3: Csets | C3: CommName | D3: CommDesc | E3: Unit | F3: LimType | G3: CTSLvl | H3: PeakTS | I3: Ctype
B4: *Commodity Set Membership | C4: Commodity Name | D4: Commodity Description | E4: Unit | F4: Sense of the Balance EQN. | G4: Timeslice Level | H4: Peak Monitoring | I4: Electricity Indicator
B5: DEM | C5: =Demand!E2 | D5: =Demand!A2&" "&Demand!B2&" "&Demand!C2&" "&Demand!D2&" "&"demand" | E5: Mm2
B6: DEM | C6: =Demand!E3 | D6: =Demand!A3&" "&Demand!B3&" "&Demand!C3&" "&Demand!D3&" "&"demand" | E6: Mm2
B7: DEM | C7: =Demand!E4 | D7: =Demand!A4&" "&Demand!B4&" "&Demand!C4&" "&Demand!D4&" "&"demand" | E7: Mm2
B8: DEM | C8: =Demand!E5 | D8: =Demand!A5&" "&Demand!B5&" "&Demand!C5&" "&Demand!D5&" "&"demand" | E8: Mm2
B9: DEM | C9: =Demand!E6 | D9: =Demand!A6&" "&Demand!B6&" "&Demand!C6&" "&Demand!D6&" "&"demand" | E9: Mm2
B10: DEM | C10: =Demand!E7 | D10: =Demand!A7&" "&Demand!B7&" "&Demand!C7&" "&Demand!D7&" "&"demand" | E10: Mm2
B11: DEM | C11: =Demand!E8 | D11: =Demand!A8&" "&Demand!B8&" "&Demand!C8&" "&Demand!D8&" "&"demand" | E11: Mm2
B12: DEM | C12: =Demand!E9 | D12: =Demand!A9&" "&Demand!B9&" "&Demand!C9&" "&Demand!D9&" "&"demand" | E12: Mm2
B13: DEM | C13: =Demand!E10 | D13: =Demand!A10&" "&Demand!B10&" "&Demand!C10&" "&Demand!D10&" "&"demand" | E13: Mm2
B14: DEM | C14: =Demand!E11 | D14: =Demand!A11&" "&Demand!B11&" "&Demand!C11&" "&Demand!D11&" "&"demand" | E14: Mm2
B15: DEM | C15: =Demand!E12 | D15: =Demand!A12&" "&Demand!B12&" "&Demand!C12&" "&Demand!D12&" "&"demand" | E15: Mm2
B16: DEM | C16: =Demand!E13 | D16: =Demand!A13&" "&Demand!B13&" "&Demand!C13&" "&Demand!D13&" "&"demand" | E16: Mm2
... B20: DEM | C20: =Demand!E17 | D20: =Demand!A17&" "&Demand!B17&" "&Demand!C17&" "&Demand!D17&" "&"demand" | E20: Mm2
B21: *
B22: MAT | C22: ='BDG Intensity'!F2&"DMD" | D22: ='BDG Intensity'!A2&" "&'BDG Intensity'!B2&" "&'BDG Intensity'!C2&" "&'BDG Intensity'!D2&" "&'BDG Intensity'!E2&" "&"demand" | E22: Mm2
B23: MAT | C23: ='BDG Intensity'!F3&"DMD" | D23: ='BDG Intensity'!A3&" "&'BDG Intensity'!B3&" "&'BDG Intensity'!C3&" "&'BDG Intensity'!D3&" "&'BDG Intensity'!E3&" "&"demand" | E23: Mm2
B24: MAT | C24: ='BDG Intensity'!F4&"DMD" | D24: ='BDG Intensity'!A4&" "&'BDG Intensity'!B4&" "&'BDG Intensity'!C4&" "&'BDG Intensity'!D4&" "&'BDG Intensity'!E4&" "&"demand" | E24: Mm2
B25: MAT | C25: ='BDG Intensity'!F5&"DMD" | D25: ='BDG Intensity'!A5&" "&'BDG Intensity'!B5&" "&'BDG Intensity'!C5&" "&'BDG Intensity'!D5&" "&'BDG Intensity'!E5&" "&"demand" | E25: Mm2
B26: MAT | C26: ='BDG Intensity'!F6&"DMD" | D26: ='BDG Intensity'!A6&" "&'BDG Intensity'!B6&" "&'BDG Intensity'!C6&" "&'BDG Intensity'!D6&" "&'BDG Intensity'!E6&" "&"demand" | E26: Mm2
B27: MAT | C27: ='BDG Intensity'!F7&"DMD" | D27: ='BDG Intensity'!A7&" "&'BDG Intensity'!B7&" "&'BDG Intensity'!C7&" "&'BDG Intensity'!D7&" "&'BDG Intensity'!E7&" "&"demand" | E27: Mm2
B28: MAT | C28: ='BDG Intensity'!F8&"DMD" | D28: ='BDG Intensity'!A8&" "&'BDG Intensity'!B8&" "&'BDG Intensity'!C8&" "&'BDG Intensity'!D8&" "&'BDG Intensity'!E8&" "&"demand" | E28: Mm2
B29: MAT | C29: ='BDG Intensity'!F9&"DMD" | D29: ='BDG Intensity'!A9&" "&'BDG Intensity'!B9&" "&'BDG Intensity'!C9&" "&'BDG Intensity'!D9&" "&'BDG Intensity'!E9&" "&"demand" | E29: Mm2
B30: MAT | C30: ='BDG Intensity'!F10&"DMD" | D30: ='BDG Intensity'!A10&" "&'BDG Intensity'!B10&" "&'BDG Intensity'!C10&" "&'BDG Intensity'!D10&" "&'BDG Intensity'!E10&" "&"demand" | E30: Mm2
B31: MAT | C31: ='BDG Intensity'!F11&"DMD" | D31: ='BDG Intensity'!A11&" "&'BDG Intensity'!B11&" "&'BDG Intensity'!C11&" "&'BDG Intensity'!D11&" "&'BDG Intensity'!E11&" "&"demand" | E31: Mm2
B32: MAT | C32: ='BDG Intensity'!F12&"DMD" | D32: ='BDG Intensity'!A12&" "&'BDG Intensity'!B12&" "&'BDG Intensity'!C12&" "&'BDG Intensity'!D12&" "&'BDG Intensity'!E12&" "&"demand" | E32: Mm2
B33: MAT | C33: ='BDG Intensity'!F13&"DMD" | D33: ='BDG Intensity'!A13&" "&'BDG Intensity'!B13&" "&'BDG Intensity'!C13&" "&'BDG Intensity'!D13&" "&'BDG Intensity'!E13&" "&"demand" | E33: Mm2
... B149: MAT | C149: ='BDG Intensity'!F129&"DMD" | D149: ='BDG Intensity'!A129&" "&'BDG Intensity'!B129&" "&'BDG Intensity'!C129&" "&'BDG Intensity'!D129&" "&'BDG Intensity'!E129&" "&"demand" | E149: Mm2
B150: *
B151: NRG | C151: ='BDG Intensity'!F2&"EUE" | D151: ='BDG Intensity'!A2&" "&'BDG Intensity'!B2&" "&'BDG Intensity'!C2&" "&'BDG Intensity'!D2&" "&'BDG Intensity'!E2&" "&"EUE" | E151: ='BDG Intensity'!G2
B152: NRG | C152: ='BDG Intensity'!F3&"EUE" | D152: ='BDG Intensity'!A3&" "&'BDG Intensity'!B3&" "&'BDG Intensity'!C3&" "&'BDG Intensity'!D3&" "&'BDG Intensity'!E3&" "&"EUE" | E152: ='BDG Intensity'!G3
B153: NRG | C153: ='BDG Intensity'!F4&"EUE" | D153: ='BDG Intensity'!A4&" "&'BDG Intensity'!B4&" "&'BDG Intensity'!C4&" "&'BDG Intensity'!D4&" "&'BDG Intensity'!E4&" "&"EUE" | E153: ='BDG Intensity'!G4
B154: NRG | C154: ='BDG Intensity'!F5&"EUE" | D154: ='BDG Intensity'!A5&" "&'BDG Intensity'!B5&" "&'BDG Intensity'!C5&" "&'BDG Intensity'!D5&" "&'BDG Intensity'!E5&" "&"EUE" | E154: ='BDG Intensity'!G5
B155: NRG | C155: ='BDG Intensity'!F6&"EUE" | D155: ='BDG Intensity'!A6&" "&'BDG Intensity'!B6&" "&'BDG Intensity'!C6&" "&'BDG Intensity'!D6&" "&'BDG Intensity'!E6&" "&"EUE" | E155: ='BDG Intensity'!G6
B156: NRG | C156: ='BDG Intensity'!F7&"EUE" | D156: ='BDG Intensity'!A7&" "&'BDG Intensity'!B7&" "&'BDG Intensity'!C7&" "&'BDG Intensity'!D7&" "&'BDG Intensity'!E7&" "&"EUE" | E156: ='BDG Intensity'!G7
B157: NRG | C157: ='BDG Intensity'!F8&"EUE" | D157: ='BDG Intensity'!A8&" "&'BDG Intensity'!B8&" "&'BDG Intensity'!C8&" "&'BDG Intensity'!D8&" "&'BDG Intensity'!E8&" "&"EUE" | E157: ='BDG Intensity'!G8
B158: NRG | C158: ='BDG Intensity'!F9&"EUE" | D158: ='BDG Intensity'!A9&" "&'BDG Intensity'!B9&" "&'BDG Intensity'!C9&" "&'BDG Intensity'!D9&" "&'BDG Intensity'!E9&" "&"EUE" | E158: ='BDG Intensity'!G9
B159: NRG | C159: ='BDG Intensity'!F10&"EUE" | D159: ='BDG Intensity'!A10&" "&'BDG Intensity'!B10&" "&'BDG Intensity'!C10&" "&'BDG Intensity'!D10&" "&'BDG Intensity'!E10&" "&"EUE" | E159: ='BDG Intensity'!G10
...

Sheet DemandSplit
D3: ~FI_T | K3: ~FI_T
B4: TechName | C4: Comm-IN | D4: Comm-OUT | E4: Attribute | F4: CITY | I4: TechName | J4: Comm-IN | K4: Comm-OUT | L4: Attribute | M4: CITY
B5: * | F5: MM2 In / MM2 Out | I5: * | M5: MM2 In / MM2 Out
B6: =Def_Tech!D5 | C6: =Def_Comm!C22 | D6: =Def_Comm!C5 | E6: Input | F6: 1 | I6: =Def_Tech!D13 | J6: =Def_Comm!C86 | K6: =Def_Comm!C13 | L6: Input | M6: 1
B7: =Def_Tech!D6 | C7: =Def_Comm!C23 | D7: =Def_Comm!C6 | E7: Input | F7: 1 | I7: =Def_Tech!D14 | J7: =Def_Comm!C87 | K7: =Def_Comm!C14 | L7: Input | M7: 1
B8: =Def_Tech!D7 | C8: =Def_Comm!C24 | D8: =Def_Comm!C7 | E8: Input | F8: 1 | I8: =Def_Tech!D15 | J8: =Def_Comm!C88 | K8: =Def_Comm!C15 | L8: Input | M8: 1
B9: =Def_Tech!D8 | C9: =Def_Comm!C25 | D9: =Def_Comm!C8 | E9: Input | F9: 1 | I9: =Def_Tech!D16 | J9: =Def_Comm!C89 | K9: =Def_Comm!C16 | L9: Input | M9: 1
B10: =Def_Tech!D9 | C10: =Def_Comm!C26 | D10: =Def_Comm!C9 | E10: Input | F10: 1 | I10: =Def_Tech!D17 | J10: =Def_Comm!C90 | K10: =Def_Comm!C17 | L10: Input | M10: 1
B11: =Def_Tech!D10 | C11: =Def_Comm!C27 | D11: =Def_Comm!C10 | E11: Input | F11: 1 | I11: =Def_Tech!D18 | J11: =Def_Comm!C91 | K11: =Def_Comm!C18 | L11: Input | M11: 1
B12: =Def_Tech!D11 | C12: =Def_Comm!C28 | D12: =Def_Comm!C11 | E12: Input | F12: 1 | I12: =Def_Tech!D19 | J12: =Def_Comm!C92 | K12: =Def_Comm!C19 | L12: Input | M12: 1
B13: =Def_Tech!D12 | C13: =Def_Comm!C29 | D13: =Def_Comm!C12 | E13: Input | F13: 1 | I13: =Def_Tech!D20 | J13: =Def_Comm!C93 | K13: =Def_Comm!C20 | L13: Input | M13: 1
B14: =B6 | C14: =Def_Comm!C30 | D14: =D6 | E14: Input | F14: 1 | I14: =I6 | J14: =Def_Comm!C94 | K14: =K6 | L14: Input | M14: 1
B15: =B7 | C15: =Def_Comm!C31 | D15: =D7 | E15: Input | F15: 1 | I15: =I7 | J15: =Def_Comm!C95 | K15: =K7 | L15: Input | M15: 1
B16: =B8 | C16: =Def_Comm!C32 | D16: =D8 | E16: Input | F16: 1 | I16: =I8 | J16: =Def_Comm!C96 | K16: =K8 | L16: Input | M16: 1
B17: =B9 | C17: =Def_Comm!C33 | D17: =D9 | E17: Input | F17: 1 | I17: =I9 | J17: =Def_Comm!C97 | K17: =K9 | L17: Input | M17: 1
B18: =B10 | C18: =Def_Comm!C34 | D18: =D10 | E18: Input | F18: 1 | I18: =I10 | J18: =Def_Comm!C98 | K18: =K10 | L18: Input | M18: 1
B19: =B11 | C19: =Def_Comm!C35 | D19: =D11 | E19: Input | F19: 1 | I19: =I11 | J19: =Def_Comm!C99 | K19: =K11 | L19: Input | M19: 1
B20: =B12 | C20: =Def_Comm!C36 | D20: =D12 | E20: Input | F20: 1 | I20: =I12 | J20: =Def_Comm!C100 | K20: =K12 | L20: Input | M20: 1
B21: =B13 | C21: =Def_Comm!C37 | D21: =D13 | E21: Input | F21: 1 | I21: =I13 | J21: =Def_Comm!C101 | K21: =K13 | L21: Input | M21: 1
B22: =B14 | C22: =Def_Comm!C38 | D22: =D14 | E22: Input | F22: 1 | I22: =I14 | J22: =Def_Comm!C102 | K22: =K14 | L22: Input | M22: 1
B23: =B15 | C23: =Def_Comm!C39 | D23: =D15 | E23: Input | F23: 1 | I23: =I15 | J23: =Def_Comm!C103 | K23: =K15 | L23: Input | M23: 1
B24: =B16 | C24: =Def_Comm!C40 | D24: =D16 | E24: Input | F24: 1 | I24: =I16 | J24: =Def_Comm!C104 | K24: =K16 | L24: Input | M24: 1
B25: =B17 | C25: =Def_Comm!C41 | D25: =D17 | E25: Input | F25: 1 | I25: =I17 | J25: =Def_Comm!C105 | K25: =K17 | L25: Input | M25: 1
... B69: =B61 | C69: =Def_Comm!C85 | D69: =D61 | E69: Input | F69: 1 | I69: =I61 | J69: =Def_Comm!C149 | K69: =K61 | L69: Input | M69: 1

Sheet BuildingEff
F1: ='BDG Intensity'!I1 | G1: ='BDG Intensity'!J1 | H1: ='BDG Intensity'!K1 | I1: ='BDG Intensity'!L1 | J1: ='BDG Intensity'!M1 | K1: ='BDG Intensity'!N1 | L1: ='BDG Intensity'!O1 | M1: ='BDG Intensity'!P1 | ... W1: ='BDG Intensity'!Z1
F2: Input | G2: Input | H2: Input | I2: Input | J2: Input | K2: Input | L2: Input | M2: Input | N2: Input | O2: Input | P2: Input | Q2: Input | R2: Input | S2: Input | T2: Input | U2: Input | V2: Input | W2: Input
E4: ~FI_T
B5: Region | C5: TechName | D5: Comm-IN | E5: Comm-OUT | F5: =F2&"~"&F1 | G5: =G2&"~"&G1 | H5: =H2&"~"&H1 | I5: =I2&"~"&I1 | J5: =J2&"~"&J1 | K5: =K2&"~"&K1 | L5: =L2&"~"&L1 | M5: =M2&"~"&M1 | ... W5: =W2&"~"&W1
B6: * | C6: * | F6: TJ /Mm2 | G6: Mm2 / TJ | H6: Mm2 / TJ | I6: Mm2 / TJ | J6: Mm2 / TJ | K6: Mm2 / TJ | L6: Mm2 / TJ | M6: Mm2 / TJ | N6: Mm2 / TJ | O6: Mm2 / TJ | P6: Mm2 / TJ | Q6: Mm2 / TJ | R6: Mm2 / TJ | S6: Mm2 / TJ | T6: Mm2 / TJ | U6: Mm2 / TJ | V6: Mm2 / TJ | W6: Mm2 / TJ
B7: =Def_Tech!C151 | C7: =Def_Tech!D22 | D7: =Def_Comm!C151 | E7: =Def_Comm!C22 | F7: =_xlfn.XLOOKUP($C7,'BDG Intensity'!$F:$F,'BDG Intensity'!I:I) | G7: =_xlfn.XLOOKUP($C7,'BDG Intensity'!$F:$F,'BDG Intensity'!J:J) | H7: =_xlfn.XLOOKUP($C7,'BDG Intensity'!$F:$F,'BDG Intensity'!K:K) | I7: =_xlfn.XLOOKUP($C7,'BDG Intensity'!$F:$F,'BDG Intensity'!L:L) | J7: =_xlfn.XLOOKUP($C7,'BDG Intensity'!$F:$F,'BDG Intensity'!M:M) | K7: =_xlfn.XLOOKUP($C7,'BDG Intensity'!$F:$F,'BDG Intensity'!N:N) | L7: =_xlfn.XLOOKUP($C7,'BDG Intensity'!$F:$F,'BDG Intensity'!O:O) | M7: =_xlfn.XLOOKUP($C7,'BDG Intensity'!$F:$F,'BDG Intensity'!P:P) | N7: =_xlfn.XLOOKUP($C7,'BDG Intensity'!$F:$F,'BDG Intensity'!Q:Q) | O7: =_xlfn.XLOOKUP($C7,'BDG Intensity'!$F:$F,'BDG Intensity'!R:R) | P7: =_xlfn.XLOOKUP($C7,'BDG Intensity'!$F:$F,'BDG Intensity'!S:S) | Q7: =_xlfn.XLOOKUP($C7,'BDG Intensity'!$F:$F,'BDG Intensity'!T:T) | R7: =_xlfn.XLOOKUP($C7,'BDG Intensity'!$F:$F,'BDG Intensity'!U:U) | S7: =_xlfn.XLOOKUP($C7,'BDG Intensity'!$F:$F,'BDG Intensity'!V:V) | T7: =_xlfn.XLOOKUP($C7,'BDG Intensity'!$F:$F,'BDG Intensity'!W:W) | U7: =_xlfn.XLOOKUP($C7,'BDG Intensity'!$F:$F,'BDG Intensity'!X:X) | V7: =_xlfn.XLOOKUP($C7,'BDG Intensity'!$F:$F,'BDG Intensity'!Y:Y) | W7: =_xlfn.XLOOKUP($C7,'BDG Intensity'!$F:$F,'BDG Intensity'!Z:Z)
