Workbook
Name _.DMD.: #REF!
Name _.DMD._2: #REF!
Name ____W.O.R.K.B.O.O.K..C.O.N.T.E.N.T.S____: #REF!
Name Cars_12: #REF!
Name Cars_12_2: #REF!
Name COUNTRY_WT_VERT: #REF!
Name CRF_4_KP__Doc: #REF!
Name CRF_4_KP__Main: #REF!
Name CRF_4_KP_I_A.1.1_Doc: #REF!
Name CRF_4_KP_I_A.1.1_Main: #REF!
Name CRF_4_KP_I_A.1_Doc: #REF!
Name CRF_4_KP_I_A.1_Main: #REF!
Name CRF_4_KP_I_A.2.1_Doc: #REF!
Name CRF_4_KP_I_A.2.1_Main: #REF!
Name CRF_4_KP_I_A.2_Doc: #REF!
Name CRF_4_KP_I_A.2_Main1: #REF!
Name CRF_4_KP_I_A.2_Main2: #REF!
Name CRF_4_KP_I_B.1.1_Doc: #REF!
Name CRF_4_KP_I_B.1.1_Main: #REF!
Name CRF_4_KP_I_B.1.2_Doc: #REF!
Name CRF_4_KP_I_B.1.2_Main: #REF!
Name CRF_4_KP_I_B.1.3_Doc: #REF!
Name CRF_4_KP_I_B.1.3_Main: #REF!
Name CRF_4_KP_I_B.1_Doc: #REF!
Name CRF_4_KP_I_B.1_Main: #REF!
Name CRF_4_KP_I_B.2_Doc: #REF!
Name CRF_4_KP_I_B.2_Main: #REF!
Name CRF_4_KP_I_B.3_Doc: #REF!
Name CRF_4_KP_I_B.3_Main: #REF!
Name CRF_4_KP_I_B.4_Doc: #REF!
Name CRF_4_KP_I_B.4_Main: #REF!
Name CRF_4_KP_I_B.5_Doc: #REF!
Name CRF_4_KP_I_B.5_Main: #REF!
Name CRF_4_KP_II_1_Doc: #REF!
Name CRF_4_KP_II_1_Main: #REF!
Name CRF_4_KP_II_2_Doc: #REF!
Name CRF_4_KP_II_2_Main: #REF!
Name CRF_4_KP_II_3_Doc: #REF!
Name CRF_4_KP_II_3_Main: #REF!
Name CRF_4_KP_II_4_Doc: #REF!
Name CRF_4_KP_II_4_Main: #REF!
Name CRF_4_KP_Recalculations_Doc: #REF!
Name CRF_4_KP_Recalculations_Main1: #REF!
Name CRF_4_KP_Recalculations_Main2: #REF!
Name CRF_accounting_Main: #REF!
Name CRF_NIR_1_Add: #REF!
Name CRF_NIR_1_Main: #REF!
Name CRF_NIR_2.1_Main: #REF!
Name CRF_NIR_2_Main: #REF!
Name CRF_NIR_3_Main: #REF!
Name CRF_Table1.B.1_Doc: #REF!
Name CRF_Table1.B.1_Main: #REF!
Name CRF_Table1.B.2_Doc: #REF!
Name CRF_Table1.B.2_Main: #REF!
Name CRF_Table1.C_Doc: #REF!
Name CRF_Table1.C_Main: #REF!
Name CRF_Table3.B_a_s2_Add: #REF!
Name CRF_Table3.D_Add: #REF!
Name CRF_Table3.D_Doc: #REF!
Name CRF_Table3.D_Main: #REF!

Sheet ReadMe
A1: Generic Comet (GC) TIMES Supply
B3: Sheet color
C4: Raw Data and Parameters
C6: City Specific Data
C8: Post processing for TIMES
C10: Table formatted for TIMES

Sheet >> City Data

Sheet City characteristics
B2: City Basic Data
B4: Calibration methodology | C4: GHG Inventory
B6: A. City Characteristics
B7: Data Item | C7: Value | D7: Units
B8: City Name | C8: New York
B9: Latitude | C9: 40.5
B10: Longitude | C10: -75
B11: County | C11: New York County
B12: State | C12: New York
B13: Census Division | C13: Middle Atlantic
B14: Climate Division | C14: Northeast
B15: Egrid Region | C15: NPCC NYC/Westchester
B16: Area of city (excluding water, natural and agricultural areas) | C16: 778 | D16: square kilometers
B17: * Division and Region Map can be found in the Maps sheet.
B18: B. Planning Base Year and Target Years
B19: Year | C19: Value | D19: Units
B20: Base Year | C20: 2019 | D20: Acceptable range [2018,2021]
B21: End Year | C21: 2050
B23: C. City Population and GDP
B24: Data Item | C24: Value | D24: Units
B25: Population in Base Year | C25: 8337 | D25: Thousand of people
B26: Annual population growth (Base Year - End Year) | C26: 0.5 | D26: % people
B27: GDP in Base Year | C27: 1206000 | D27: Million US$
B28: Annual GDP growth rate | C28: 2 | D28: % US$
B29: Share of manufacturing GDP | C29: 5 | D29: % US$
B30: Share of State population | C30: 0.42835123
B31: Share of State GDP | C31: 0.67251772
B32: Adjustment from state manufacturing GDP | C32: 1.0638298
B34: D. Climate Data
B35: Data Item | C35: 2000 | D35: 2050 | E35: 2100 | F35: Units
B36: Heating degree days (HDD) | C36: 4473.4625 | D36: 4066.4182 | E36: 3763.8582 | F36: F
B37: Cooling degree days (CDD) | C37: 1020.7333 | D37: 1224.2555 | E37: 1375.5355 | F37: F
B39: Data Item | C39: Value | D39: Units
B40: Correction from State HDD | C40: 0.72727402
B41: Correction from State CDD | C41: 1.5583715
B42: Annual precipitation | C42: 762 | D42: mm / year
B43: Climate change scenario | C43: RCP4.5
B44: Average temperature increase in 1980-2020 | C44: 1.4617857 | D44: F
B45: Forecasted average temperature increase in 2035-2065 | C45: 3.13 | D45: F
B46: Forecasted average temperature increase in 2070-2100 | C46: 4.37 | D46: F
...

Sheet >> GC_NewTech

Sheet ENE TECH
H1: 2023 Dollar / GJ
A2: GHGI Sector | B2: GHGI Energy | C2: AEO Sector | D2: AEO Energy | E2: Description | F2: Multiplicateur | G2: Commodity Label | H2: 2019 | I2: 2020 | J2: 2021 | K2: 2022 | L2: 2023 | M2: 2024 | N2: 2025 | O2: 2030 | P2: 2035 | Q2: 2040 | R2: 2045 | S2: 2050 | T2: 2055 | U2: 2060 | V2: 2065 | W2: 2070 | X2: 2075 | Y2: 2080 | Z2: 2085 | AA2: 2090 | AB2: 2095 | AC2: 2100
A3: Residential | B3: LPG | C3: Residential | D3: Propane | E3: Hydrocarbon gas liquids price in the residential sector | F3: 1 | G3: RESLPG | H3: 33.139282 | I3: 28.404792 | J3: 34.017648 | K3: 36.740013 | L3: 38.524662 | M3: 38.53425 | N3: 37.487506 | O3: 36.540775 | P3: 42.127352 | Q3: 46.993146 | R3: 51.097312 | S3: 54.209147 | T3: 54.209147 | U3: 54.209147 | V3: 54.209147 | W3: 54.209147 | X3: 54.209147 | Y3: 54.209147 | Z3: 54.209147 | AA3: 54.209147 | AB3: 54.209147 | AC3: 54.209147
A4: Residential | B4: Fuel oil | C4: Residential | D4: Distillate Fuel Oil | E4: Distillate fuel oil price in the residential sector | F4: 1 | G4: RESFOI | H4: 21.264373 | I4: 17.088445 | J4: 19.92401 | K4: 21.518489 | L4: 19.660523 | M4: 18.79016 | N4: 17.783449 | O4: 17.917993 | P4: 19.239678 | Q4: 20.738888 | R4: 22.093132 | S4: 23.258847 | T4: 23.258847 | U4: 23.258847 | V4: 23.258847 | W4: 23.258847 | X4: 23.258847 | Y4: 23.258847 | Z4: 23.258847 | AA4: 23.258847 | AB4: 23.258847 | AC4: 23.258847
A5: Residential | B5: Kerosene | C5: Residential | D5: Distillate Fuel Oil | E5: Kerosene price in the residential sector | F5: 1 | G5: RESKER | H5: 24.732951 | I5: 15.775618 | J5: 24.575447 | K5: 26.54217 | L5: 24.250446 | M5: 23.176889 | N5: 21.935152 | O5: 22.101108 | P5: 23.731351 | Q5: 25.580565 | R5: 27.250969 | S5: 28.68883 | T5: 28.68883 | U5: 28.68883 | V5: 28.68883 | W5: 28.68883 | X5: 28.68883 | Y5: 28.68883 | Z5: 28.68883 | AA5: 28.68883 | AB5: 28.68883 | AC5: 28.68883
A6: Residential | B6: Natural gas | C6: Residential | D6: Natural Gas | E6: Natural gas price in the residential sector (including supplemental gaseous fuels) | F6: 1 | G6: RESNGA | H6: 13.498734 | I6: 13.43206 | J6: 14.30799 | K6: 15.45303 | L6: 14.920712 | M6: 13.39134 | N6: 12.76654 | O6: 12.386274 | P6: 13.885007 | Q6: 15.199748 | R6: 16.020235 | S6: 16.83725 | T6: 16.83725 | U6: 16.83725 | V6: 16.83725 | W6: 16.83725 | X6: 16.83725 | Y6: 16.83725 | Z6: 16.83725 | AA6: 16.83725 | AB6: 16.83725 | AC6: 16.83725
A7: Residential | B7: RNG | C7: Residential | D7: Natural Gas | E7: Natural gas price in the residential sector (including supplemental gaseous fuels) | F7: 2 | G7: RESRNG | H7: 26.997469 | I7: 26.86412 | J7: 28.61598 | K7: 30.90606 | L7: 29.841423 | M7: 26.78268 | N7: 25.533081 | O7: 24.772548 | P7: 27.770013 | Q7: 30.399496 | R7: 32.04047 | S7: 33.6745 | T7: 33.6745 | U7: 33.6745 | V7: 33.6745 | W7: 33.6745 | X7: 33.6745 | Y7: 33.6745 | Z7: 33.6745 | AA7: 33.6745 | AB7: 33.6745 | AC7: 33.6745
A8: Residential | B8: Electricity | C8: Residential | D8: Electricity | E8: Electricity price in the residential sector | F8: 1 | G8: RESELC | H8: 58.082115 | I8: 58.393657 | J8: 61.197471 | K8: 66.094982 | L8: 62.991999 | M8: 60.939902 | N8: 59.863655 | O8: 61.403024 | P8: 67.073536 | Q8: 72.818505 | R8: 77.93633 | S8: 81.383542 | T8: 81.383542 | U8: 81.383542 | V8: 81.383542 | W8: 81.383542 | X8: 81.383542 | Y8: 81.383542 | Z8: 81.383542 | AA8: 81.383542 | AB8: 81.383542 | AC8: 81.383542
A9: Residential | B9: Hydrogen | C9: Residential | D9: Electricity | E9: Electricity price in the residential sector | F9: 2 | G9: RESH2G | H9: 116.16423 | I9: 116.78731 | J9: 122.39494 | K9: 132.18996 | L9: 125.984 | M9: 121.8798 | N9: 119.72731 | O9: 122.80605 | P9: 134.14707 | Q9: 145.63701 | R9: 155.87266 | S9: 162.76708 | T9: 162.76708 | U9: 162.76708 | V9: 162.76708 | W9: 162.76708 | X9: 162.76708 | Y9: 162.76708 | Z9: 162.76708 | AA9: 162.76708 | AB9: 162.76708 | AC9: 162.76708
A10: Residential | B10: Steam | C10: Residential | D10: Electricity | E10: Electricity price in the residential sector | F10: 2 | G10: RESSTM | H10: 116.16423 | I10: 116.78731 | J10: 122.39494 | K10: 132.18996 | L10: 125.984 | M10: 121.8798 | N10: 119.72731 | O10: 122.80605 | P10: 134.14707 | Q10: 145.63701 | R10: 155.87266 | S10: 162.76708 | T10: 162.76708 | U10: 162.76708 | V10: 162.76708 | W10: 162.76708 | X10: 162.76708 | Y10: 162.76708 | Z10: 162.76708 | AA10: 162.76708 | AB10: 162.76708 | AC10: 162.76708
A11: Residential | B11: Solar | C11: Residential | D11: Solar | F11: 1 | G11: RESSOL | H11: 0 | I11: 0 | J11: 0 | K11: 0 | L11: 0 | M11: 0 | N11: 0 | O11: 0 | P11: 0 | Q11: 0 | R11: 0 | S11: 0 | T11: 0 | U11: 0 | V11: 0 | W11: 0 | X11: 0 | Y11: 0 | Z11: 0 | AA11: 0 | AB11: 0 | AC11: 0
A12: Residential | B12: Wind | C12: Residential | D12: Wind | F12: 1 | G12: RESWND | H12: 0 | I12: 0 | J12: 0 | K12: 0 | L12: 0 | M12: 0 | N12: 0 | O12: 0 | P12: 0 | Q12: 0 | R12: 0 | S12: 0 | T12: 0 | U12: 0 | V12: 0 | W12: 0 | X12: 0 | Y12: 0 | Z12: 0 | AA12: 0 | AB12: 0 | AC12: 0
A13: Commercial | B13: LPG | C13: Commercial | D13: Propane | E13: Hydrocarbon gas liquids price in the commercial sector | F13: 1 | G13: COMLPG | H13: 15.796391 | I13: 14.365143 | J13: 21.949636 | K13: 23.706221 | L13: 22.146428 | M13: 20.587193 | N13: 19.055314 | O13: 19.150876 | P13: 22.286658 | Q13: 24.66189 | R13: 26.631887 | S13: 28.104431 | T13: 28.104431 | U13: 28.104431 | V13: 28.104431 | W13: 28.104431 | X13: 28.104431 | Y13: 28.104431 | Z13: 28.104431 | AA13: 28.104431 | AB13: 28.104431 | AC13: 28.104431
A14: Commercial | B14: Diesel | C14: Commercial | D14: Distillate Fuel Oil | E14: Distillate fuel oil price in the commercial sector | F14: 1 | G14: COMDSL | H14: 17.387077 | I14: 11.511644 | J14: 18.252065 | K14: 19.712741 | L14: 18.085099 | M14: 16.656612 | N14: 15.093246 | O14: 13.112384 | P14: 14.115668 | Q14: 15.25231 | R14: 16.270151 | S14: 17.126833 | T14: 17.126833 | U14: 17.126833 | V14: 17.126833 | W14: 17.126833 | X14: 17.126833 | Y14: 17.126833 | Z14: 17.126833 | AA14: 17.126833 | AB14: 17.126833 | AC14: 17.126833
A15: Commercial | B15: Fuel oil | C15: Commercial | D15: Residual Fuel Oil | E15: Distillate fuel oil price in the commercial sector | F15: 1 | G15: COMFOI | H15: 17.387077 | I15: 11.511644 | J15: 18.252065 | K15: 19.712741 | L15: 12.042501 | M15: 14.295152 | N15: 14.501626 | O15: 22.312094 | P15: 24.510554 | Q15: 26.868519 | R15: 29.144687 | S15: 31.154017 | T15: 31.154017 | U15: 31.154017 | V15: 31.154017 | W15: 31.154017 | X15: 31.154017 | Y15: 31.154017 | Z15: 31.154017 | AA15: 31.154017 | AB15: 31.154017 | AC15: 31.154017
A16: Commercial | B16: Kerosene | C16: Commercial | D16: Distillate Fuel Oil | E16: Kerosene price in the commercial sector | F16: 1 | G16: COMKER | H16: 24.732951 | I16: 15.775618 | J16: 24.575447 | K16: 26.54217 | L16: 24.350636 | M16: 22.427252 | N16: 20.322262 | O16: 17.655135 | P16: 19.006005 | Q16: 20.536434 | R16: 21.906903 | S16: 23.06038 | T16: 23.06038 | U16: 23.06038 | V16: 23.06038 | W16: 23.06038 | X16: 23.06038 | Y16: 23.06038 | Z16: 23.06038 | AA16: 23.06038 | AB16: 23.06038 | AC16: 23.06038
A17: Commercial | B17: Gasoline | C17: Commercial | D17: Distillate Fuel Oil | E17: Motor gasoline price in the commercial sector | F17: 1 | G17: COMGSL | H17: 23.164358 | I17: 19.377754 | J17: 25.582901 | K17: 27.630249 | L17: 25.348874 | M17: 23.346643 | N17: 21.15536 | O17: 18.378896 | P17: 19.785143 | Q17: 21.378311 | R17: 22.804962 | S17: 24.005725 | T17: 24.005725 | U17: 24.005725 | V17: 24.005725 | W17: 24.005725 | X17: 24.005725 | Y17: 24.005725 | Z17: 24.005725 | AA17: 24.005725 | AB17: 24.005725 | AC17: 24.005725
A18: Commercial | B18: Natural gas | C18: Commercial | D18: Natural Gas | E18: Natural gas price in the commercial sector (including supplemental gaseous fuels) | F18: 1 | G18: COMNGA | H18: 7.7104063 | I18: 7.2259709 | J18: 8.2096782 | K18: 8.8666823 | L18: 8.1872197 | M18: 7.255384 | N18: 6.9579136 | O18: 6.9767662 | P18: 7.8550132 | Q18: 8.6079722 | R18: 9.0230732 | S18: 9.4628453 | T18: 9.4628453 | U18: 9.4628453 | V18: 9.4628453 | W18: 9.4628453 | X18: 9.4628453 | Y18: 9.4628453 | Z18: 9.4628453 | AA18: 9.4628453 | AB18: 9.4628453 | AC18: 9.4628453
A19: Commercial | B19: RNG | C19: Residential | D19: Natural Gas | E19: Natural gas price in the commercial sector (including supplemental gaseous fuels) | F19: 2 | G19: COMRNG | H19: 15.420813 | I19: 14.451942 | J19: 16.419356 | K19: 17.733365 | L19: 17.122494 | M19: 15.36744 | N19: 14.650442 | O19: 14.214061 | P19: 15.933955 | Q19: 17.442707 | R19: 18.38427 | S19: 19.321848 | T19: 19.321848 | U19: 19.321848 | V19: 19.321848 | W19: 19.321848 | X19: 19.321848 | Y19: 19.321848 | Z19: 19.321848 | AA19: 19.321848 | AB19: 19.321848 | AC19: 19.321848
A20: Commercial | B20: Electricity | C20: Commercial | D20: Electricity | E20: Electricity price in the commercial sector | F20: 1 | G20: COMELC | H20: 45.511281 | I20: 46.296123 | J20: 50.490593 | K20: 54.531254 | L20: 52.397516 | M20: 49.460663 | N20: 48.055492 | O20: 48.075179 | P20: 51.458958 | Q20: 55.269325 | R20: 58.192769 | S20: 60.029189 | T20: 60.029189 | U20: 60.029189 | V20: 60.029189 | W20: 60.029189 | X20: 60.029189 | Y20: 60.029189 | Z20: 60.029189 | AA20: 60.029189 | AB20: 60.029189 | AC20: 60.029189
A21: Commercial | B21: Hydrogen | C21: Commercial | D21: Electricity | E21: Electricity price in the commercial sector | F21: 2 | G21: COMH2G | H21: 91.022562 | I21: 92.592246 | J21: 100.98119 | K21: 109.06251 | L21: 104.79503 | M21: 98.921325 | N21: 96.110985 | O21: 96.150359 | P21: 102.91792 | Q21: 110.53865 | R21: 116.38554 | S21: 120.05838 | T21: 120.05838 | U21: 120.05838 | V21: 120.05838 | W21: 120.05838 | X21: 120.05838 | Y21: 120.05838 | Z21: 120.05838 | AA21: 120.05838 | AB21: 120.05838 | AC21: 120.05838
A22: Commercial | B22: Steam | C22: Commercial | D22: Electricity | E22: Electricity price in the commercial sector | F22: 2 | G22: COMSTM | H22: 91.022562 | I22: 92.592246 | J22: 100.98119 | K22: 109.06251 | L22: 104.79503 | M22: 98.921325 | N22: 96.110985 | O22: 96.150359 | P22: 102.91792 | Q22: 110.53865 | R22: 116.38554 | S22: 120.05838 | T22: 120.05838 | U22: 120.05838 | V22: 120.05838 | W22: 120.05838 | X22: 120.05838 | Y22: 120.05838 | Z22: 120.05838 | AA22: 120.05838 | AB22: 120.05838 | AC22: 120.05838
A23: Commercial | B23: Solar | C23: Commercial | D23: Solar | F23: 1 | G23: COMSOL | H23: 0 | I23: 0 | J23: 0 | K23: 0 | L23: 0 | M23: 0 | N23: 0 | O23: 0 | P23: 0 | Q23: 0 | R23: 0 | S23: 0 | T23: 0 | U23: 0 | V23: 0 | W23: 0 | X23: 0 | Y23: 0 | Z23: 0 | AA23: 0 | AB23: 0 | AC23: 0
A24: Commercial | B24: Wind | C24: Commercial | D24: Wind | F24: 1 | G24: COMWND | H24: 0 | I24: 0 | J24: 0 | K24: 0 | L24: 0 | M24: 0 | N24: 0 | O24: 0 | P24: 0 | Q24: 0 | R24: 0 | S24: 0 | T24: 0 | U24: 0 | V24: 0 | W24: 0 | X24: 0 | Y24: 0 | Z24: 0 | AA24: 0 | AB24: 0 | AC24: 0
A25: Industrial | B25: LPG | C25: Industrial | D25: Propane | E25: Hydrocarbon gas liquids price in the industrial sector | F25: 1 | G25: INDLPG | H25: 15.144652 | I25: 13.529708 | J25: 22.453363 | K25: 24.25026 | L25: 21.481797 | M25: 19.265321 | N25: 17.113109 | O25: 16.995916 | P25: 20.560588 | Q25: 23.160107 | R25: 25.227695 | S25: 26.667272 | T25: 26.667272 | U25: 26.667272 | V25: 26.667272 | W25: 26.667272 | X25: 26.667272 | Y25: 26.667272 | Z25: 26.667272 | AA25: 26.667272 | AB25: 26.667272 | AC25: 26.667272
A26: Industrial | B26: Diesel | C26: Industrial | D26: Distillate Fuel Oil | E26: Distillate fuel oil price in the industrial sector | F26: 1 | G26: INDDSL | H26: 16.205109 | I26: 11.359747 | J26: 15.42262 | K26: 16.656861 | L26: 15.231331 | M26: 14.040168 | N26: 12.700199 | O26: 10.980378 | P26: 11.829788 | Q26: 12.813168 | R26: 13.701334 | S26: 14.458269 | T26: 14.458269 | U26: 14.458269 | V26: 14.458269 | W26: 14.458269 | X26: 14.458269 | Y26: 14.458269 | Z26: 14.458269 | AA26: 14.458269 | AB26: 14.458269 | AC26: 14.458269
A27: Industrial | B27: Fuel oil | C27: Industrial | D27: Residual Fuel Oil | E27: Residual fuel oil price in the industrial sector | F27: 1 | G27: INDFOI | H27: 10.803406 | I27: 8.3760503 | J27: 12.314517 | K27: 13.300023 | L27: 8.305852 | M27: 9.8242712 | N27: 10.264384 | O27: 15.911878 | P27: 17.519001 | Q27: 19.207624 | R27: 20.805142 | S27: 22.199438 | T27: 22.199438 | U27: 22.199438 | V27: 22.199438 | W27: 22.199438 | X27: 22.199438 | Y27: 22.199438 | Z27: 22.199438 | AA27: 22.199438 | AB27: 22.199438 | AC27: 22.199438
A28: Industrial | B28: Kerosene | C28: Industrial | D28: Distillate Fuel Oil | E28: Kerosene price in the industrial sector | F28: 1 | G28: INDKER | H28: 18.734741 | I28: 13.594807 | J28: 17.801926 | K28: 19.226579 | L28: 17.581126 | M28: 16.206198 | N28: 14.659507 | O28: 12.674363 | P28: 13.654814 | Q28: 14.789904 | R28: 15.815091 | S28: 16.688801 | T28: 16.688801 | U28: 16.688801 | V28: 16.688801 | W28: 16.688801 | X28: 16.688801 | Y28: 16.688801 | Z28: 16.688801 | AA28: 16.688801 | AB28: 16.688801 | AC28: 16.688801
A29: Industrial | B29: Gasoline | C29: Industrial | D29: Distillate Fuel Oil | E29: Motor gasoline price in the industrial sector | F29: 1 | G29: INDGSL | H29: 23.164358 | I29: 19.377754 | J29: 25.582901 | K29: 27.630249 | L29: 25.265592 | M29: 23.289702 | N29: 21.066973 | O29: 18.214151 | P29: 19.623143 | Q29: 21.254366 | R29: 22.727647 | S29: 23.983244 | T29: 23.983244 | U29: 23.983244 | V29: 23.983244 | W29: 23.983244 | X29: 23.983244 | Y29: 23.983244 | Z29: 23.983244 | AA29: 23.983244 | AB29: 23.983244 | AC29: 23.983244
A30: Industrial | B30: Natural gas | C30: Industrial | D30: Natural Gas | E30: Natural gas price in the industrial sector (including supplemental gaseous fuels) | F30: 1 | G30: INDNGA | H30: 8.2406349 | I30: 7.3453188 | J30: 8.7026876 | K30: 9.3991463 | L30: 7.8406608 | M30: 6.3176618 | N30: 5.7092575 | O30: 5.4161205 | P30: 6.513417 | Q30: 7.3212058 | R30: 7.4682076 | S30: 7.6916073 | T30: 7.6916073 | U30: 7.6916073 | V30: 7.6916073 | W30: 7.6916073 | X30: 7.6916073 | Y30: 7.6916073 | Z30: 7.6916073 | AA30: 7.6916073 | AB30: 7.6916073 | AC30: 7.6916073
A31: Industrial | B31: RNG | C31: Industrial | D31: Natural Gas | E31: Natural gas price in the industrial sector (including supplemental gaseous fuels) | F31: 2 | G31: INDRNG | H31: 16.48127 | I31: 14.690638 | J31: 17.405375 | K31: 18.798293 | L31: 15.681322 | M31: 12.635324 | N31: 11.418515 | O31: 10.832241 | P31: 13.026834 | Q31: 14.642412 | R31: 14.936415 | S31: 15.383215 | T31: 15.383215 | U31: 15.383215 | V31: 15.383215 | W31: 15.383215 | X31: 15.383215 | Y31: 15.383215 | Z31: 15.383215 | AA31: 15.383215 | AB31: 15.383215 | AC31: 15.383215
A32: Industrial | B32: Petcoke | C32: Industrial | D32: Metallurgical Coal | E32: Coal price in the industrial sector | F32: 1 | G32: INDPCK | H32: 3.7778782 | I32: 3.9818789 | J32: 3.6011121 | K32: 3.8893019 | L32: 3.8487693 | M32: 3.941073 | N32: 4.0063417 | O32: 4.4118735 | P32: 4.9805162 | Q32: 5.5737404 | R32: 6.1313001 | S32: 6.6964864 | T32: 6.6964864 | U32: 6.6964864 | V32: 6.6964864 | W32: 6.6964864 | X32: 6.6964864 | Y32: 6.6964864 | Z32: 6.6964864 | AA32: 6.6964864 | AB32: 6.6964864 | AC32: 6.6964864
A33: Industrial | B33: Coal | C33: Industrial | D33: Other Industrial Coal | E33: Coal price in the industrial sector | F33: 1 | G33: INDCOA | H33: 3.7778782 | I33: 3.9818789 | J33: 3.6011121 | K33: 3.8893019 | L33: 3.7264743 | M33: 3.6977751 | N33: 3.7934473 | O33: 3.9236989 | P33: 4.1425814 | Q33: 4.4356799 | R33: 4.6979638 | S33: 4.9689665 | T33: 4.9689665 | U33: 4.9689665 | V33: 4.9689665 | W33: 4.9689665 | X33: 4.9689665 | Y33: 4.9689665 | Z33: 4.9689665 | AA33: 4.9689665 | AB33: 4.9689665 | AC33: 4.9689665
A34: Industrial | B34: Electricity | C34: Industrial | D34: Electricity | E34: Electricity price in the industrial sector | F34: 1 | G34: INDELC | H34: 18.171373 | I34: 17.630935 | J34: 19.92401 | K34: 21.518489 | L34: 20.695312 | M34: 18.778729 | N34: 18.127859 | O34: 17.722945 | P34: 19.063147 | Q34: 20.732893 | R34: 21.803489 | S34: 22.407178 | T34: 22.407178 | U34: 22.407178 | V34: 22.407178 | W34: 22.407178 | X34: 22.407178 | Y34: 22.407178 | Z34: 22.407178 | AA34: 22.407178 | AB34: 22.407178 | AC34: 22.407178
A35: Industrial | B35: Hydrogen | C35: Industrial | D35: Electricity | E35: Electricity price in the industrial sector | F35: 2 | G35: INDH2G | H35: 36.342746 | I35: 35.26187 | J35: 39.84802 | K35: 43.036978 | L35: 41.390623 | M35: 37.557459 | N35: 36.255717 | O35: 35.445891 | P35: 38.126294 | Q35: 41.465785 | R35: 43.606978 | S35: 44.814355 | T35: 44.814355 | U35: 44.814355 | V35: 44.814355 | W35: 44.814355 | X35: 44.814355 | Y35: 44.814355 | Z35: 44.814355 | AA35: 44.814355 | AB35: 44.814355 | AC35: 44.814355
A36: Industrial | B36: Steam | C36: Industrial | D36: Electricity | E36: Electricity price in the industrial sector | F36: 2 | G36: INDSTM | H36: 36.342746 | I36: 35.26187 | J36: 39.84802 | K36: 43.036978 | L36: 41.390623 | M36: 37.557459 | N36: 36.255717 | O36: 35.445891 | P36: 38.126294 | Q36: 41.465785 | R36: 43.606978 | S36: 44.814355 | T36: 44.814355 | U36: 44.814355 | V36: 44.814355 | W36: 44.814355 | X36: 44.814355 | Y36: 44.814355 | Z36: 44.814355 | AA36: 44.814355 | AB36: 44.814355 | AC36: 44.814355
A37: Industrial | B37: Solar | C37: Industrial | D37: Solar | F37: 1 | G37: INDSOL | H37: 0 | I37: 0 | J37: 0 | K37: 0 | L37: 0 | M37: 0 | N37: 0 | O37: 0 | P37: 0 | Q37: 0 | R37: 0 | S37: 0 | T37: 0 | U37: 0 | V37: 0 | W37: 0 | X37: 0 | Y37: 0 | Z37: 0 | AA37: 0 | AB37: 0 | AC37: 0
A38: Industrial | B38: Wind | C38: Industrial | D38: Wind | F38: 1 | G38: INDWND | H38: 0 | I38: 0 | J38: 0 | K38: 0 | L38: 0 | M38: 0 | N38: 0 | O38: 0 | P38: 0 | Q38: 0 | R38: 0 | S38: 0 | T38: 0 | U38: 0 | V38: 0 | W38: 0 | X38: 0 | Y38: 0 | Z38: 0 | AA38: 0 | AB38: 0 | AC38: 0
A39: Transportation | B39: LPG | C39: Transportation | D39: Propane | E39: Hydrocarbon gas liquids price in the transportation sector | F39: 1 | G39: TRALPG | H39: 16.470223 | I39: 15.026982 | J39: 22.646279 | K39: 24.458616 | L39: 22.342301 | M39: 20.794551 | N39: 19.365335 | O39: 19.716729 | P39: 22.748775 | Q39: 25.076457 | R39: 27.010912 | S39: 28.480687 | T39: 28.480687 | U39: 28.480687 | V39: 28.480687 | W39: 28.480687 | X39: 28.480687 | Y39: 28.480687 | Z39: 28.480687 | AA39: 28.480687 | AB39: 28.480687 | AC39: 28.480687
A40: Transportation | B40: Ethanol | C40: Transportation | D40: E85 | E40: Motor gasoline price in the transportation sector | F40: 1.2 | G40: TRAETH | H40: 27.79723 | I40: 23.253305 | J40: 30.699481 | K40: 33.156299 | L40: 28.73724 | M40: 27.204245 | N40: 25.274519 | O40: 26.267091 | P40: 28.182933 | Q40: 30.271527 | R40: 32.405294 | S40: 34.480395 | T40: 34.480395 | U40: 34.480395 | V40: 34.480395 | W40: 34.480395 | X40: 34.480395 | Y40: 34.480395 | Z40: 34.480395 | AA40: 34.480395 | AB40: 34.480395 | AC40: 34.480395
...

Sheet >> TIMES

Sheet Def_Tech
B2: ~FI_Process
B3: Sets | C3: Region | D3: TechName | E3: TechDesc | F3: Tact | G3: Tcap | H3: Tslvl | I3: PrimaryCG | J3: Vintage
B4: *Process Set Membership | C4: Region | D4: Technology Name | E4: Technology Description | F4: Activity Unit | G4: Capacity Unit | H4: TimeSlice level of Process Activity | I4: Primary Commodity Group | J4: Vintage Tracking
B5: PRE | C5: CITY | D5: ='ENE TECH'!G3&RIGHT('City characteristics'!$C$20,2) -> RESLPG19 | E5: ='ENE TECH'!A3&" "&'ENE TECH'!B3&" "&"Import" -> Residential LPG Import | F5: TJ | G5: TJa
C6: CITY | D6: ='ENE TECH'!G4&RIGHT('City characteristics'!$C$20,2) -> RESFOI19 | E6: ='ENE TECH'!A4&" "&'ENE TECH'!B4&" "&"Import" -> Residential Fuel oil Import | F6: TJ | G6: TJa
C7: CITY | D7: ='ENE TECH'!G5&RIGHT('City characteristics'!$C$20,2) -> RESKER19 | E7: ='ENE TECH'!A5&" "&'ENE TECH'!B5&" "&"Import" -> Residential Kerosene Import | F7: TJ | G7: TJa
C8: CITY | D8: ='ENE TECH'!G6&RIGHT('City characteristics'!$C$20,2) -> RESNGA19 | E8: ='ENE TECH'!A6&" "&'ENE TECH'!B6&" "&"Import" -> Residential Natural gas Import | F8: TJ | G8: TJa
C9: CITY | D9: ='ENE TECH'!G7&RIGHT('City characteristics'!$C$20,2) -> RESRNG19 | E9: ='ENE TECH'!A7&" "&'ENE TECH'!B7&" "&"Import" -> Residential RNG Import | F9: TJ | G9: TJa
C10: CITY | D10: ='ENE TECH'!G8&RIGHT('City characteristics'!$C$20,2) -> RESELC19 | E10: ='ENE TECH'!A8&" "&'ENE TECH'!B8&" "&"Import" -> Residential Electricity Import | F10: TJ | G10: TJa | H10: DAYNITE
C11: CITY | D11: ='ENE TECH'!G9&RIGHT('City characteristics'!$C$20,2) -> RESH2G19 | E11: ='ENE TECH'!A9&" "&'ENE TECH'!B9&" "&"Import" -> Residential Hydrogen Import | F11: TJ | G11: TJa | H11: DAYNITE
C12: CITY | D12: ='ENE TECH'!G10&RIGHT('City characteristics'!$C$20,2) -> RESSTM19 | E12: ='ENE TECH'!A10&" "&'ENE TECH'!B10&" "&"Import" -> Residential Steam Import | F12: TJ | G12: TJa
C13: CITY | D13: ='ENE TECH'!G11&RIGHT('City characteristics'!$C$20,2) -> RESSOL19 | E13: ='ENE TECH'!A11&" "&'ENE TECH'!B11&" "&"Import" -> Residential Solar Import | F13: TJ | G13: TJa
C14: CITY | D14: ='ENE TECH'!G12&RIGHT('City characteristics'!$C$20,2) -> RESWND19 | E14: ='ENE TECH'!A12&" "&'ENE TECH'!B12&" "&"Import" -> Residential Wind Import | F14: TJ | G14: TJa
C15: CITY | D15: ='ENE TECH'!G13&RIGHT('City characteristics'!$C$20,2) -> COMLPG19 | E15: ='ENE TECH'!A13&" "&'ENE TECH'!B13&" "&"Import" -> Commercial LPG Import | F15: TJ | G15: TJa
C16: CITY | D16: ='ENE TECH'!G14&RIGHT('City characteristics'!$C$20,2) -> COMDSL19 | E16: ='ENE TECH'!A14&" "&'ENE TECH'!B14&" "&"Import" -> Commercial Diesel Import | F16: TJ | G16: TJa
C17: CITY | D17: ='ENE TECH'!G15&RIGHT('City characteristics'!$C$20,2) -> COMFOI19 | E17: ='ENE TECH'!A15&" "&'ENE TECH'!B15&" "&"Import" -> Commercial Fuel oil Import | F17: TJ | G17: TJa
C18: CITY | D18: ='ENE TECH'!G16&RIGHT('City characteristics'!$C$20,2) -> COMKER19 | E18: ='ENE TECH'!A16&" "&'ENE TECH'!B16&" "&"Import" -> Commercial Kerosene Import | F18: TJ | G18: TJa
C19: CITY | D19: ='ENE TECH'!G17&RIGHT('City characteristics'!$C$20,2) -> COMGSL19 | E19: ='ENE TECH'!A17&" "&'ENE TECH'!B17&" "&"Import" -> Commercial Gasoline Import | F19: TJ | G19: TJa
C20: CITY | D20: ='ENE TECH'!G18&RIGHT('City characteristics'!$C$20,2) -> COMNGA19 | E20: ='ENE TECH'!A18&" "&'ENE TECH'!B18&" "&"Import" -> Commercial Natural gas Import | F20: TJ | G20: TJa
C21: CITY | D21: ='ENE TECH'!G19&RIGHT('City characteristics'!$C$20,2) -> COMRNG19 | E21: ='ENE TECH'!A19&" "&'ENE TECH'!B19&" "&"Import" -> Commercial RNG Import | F21: TJ | G21: TJa
C22: CITY | D22: ='ENE TECH'!G20&RIGHT('City characteristics'!$C$20,2) -> COMELC19 | E22: ='ENE TECH'!A20&" "&'ENE TECH'!B20&" "&"Import" -> Commercial Electricity Import | F22: TJ | G22: TJa | H22: DAYNITE
C23: CITY | D23: ='ENE TECH'!G21&RIGHT('City characteristics'!$C$20,2) -> COMH2G19 | E23: ='ENE TECH'!A21&" "&'ENE TECH'!B21&" "&"Import" -> Commercial Hydrogen Import | F23: TJ | G23: TJa | H23: DAYNITE
C24: CITY | D24: ='ENE TECH'!G22&RIGHT('City characteristics'!$C$20,2) -> COMSTM19 | E24: ='ENE TECH'!A22&" "&'ENE TECH'!B22&" "&"Import" -> Commercial Steam Import | F24: TJ | G24: TJa
C25: CITY | D25: ='ENE TECH'!G23&RIGHT('City characteristics'!$C$20,2) -> COMSOL19 | E25: ='ENE TECH'!A23&" "&'ENE TECH'!B23&" "&"Import" -> Commercial Solar Import | F25: TJ | G25: TJa
C26: CITY | D26: ='ENE TECH'!G24&RIGHT('City characteristics'!$C$20,2) -> COMWND19 | E26: ='ENE TECH'!A24&" "&'ENE TECH'!B24&" "&"Import" -> Commercial Wind Import | F26: TJ | G26: TJa
C27: CITY | D27: ='ENE TECH'!G25&RIGHT('City characteristics'!$C$20,2) -> INDLPG19 | E27: ='ENE TECH'!A25&" "&'ENE TECH'!B25&" "&"Import" -> Industrial LPG Import | F27: TJ | G27: TJa
C28: CITY | D28: ='ENE TECH'!G26&RIGHT('City characteristics'!$C$20,2) -> INDDSL19 | E28: ='ENE TECH'!A26&" "&'ENE TECH'!B26&" "&"Import" -> Industrial Diesel Import | F28: TJ | G28: TJa
C29: CITY | D29: ='ENE TECH'!G27&RIGHT('City characteristics'!$C$20,2) -> INDFOI19 | E29: ='ENE TECH'!A27&" "&'ENE TECH'!B27&" "&"Import" -> Industrial Fuel oil Import | F29: TJ | G29: TJa
C30: CITY | D30: ='ENE TECH'!G28&RIGHT('City characteristics'!$C$20,2) -> INDKER19 | E30: ='ENE TECH'!A28&" "&'ENE TECH'!B28&" "&"Import" -> Industrial Kerosene Import | F30: TJ | G30: TJa
C31: CITY | D31: ='ENE TECH'!G29&RIGHT('City characteristics'!$C$20,2) -> INDGSL19 | E31: ='ENE TECH'!A29&" "&'ENE TECH'!B29&" "&"Import" -> Industrial Gasoline Import | F31: TJ | G31: TJa
C32: CITY | D32: ='ENE TECH'!G30&RIGHT('City characteristics'!$C$20,2) -> INDNGA19 | E32: ='ENE TECH'!A30&" "&'ENE TECH'!B30&" "&"Import" -> Industrial Natural gas Import | F32: TJ | G32: TJa
C33: CITY | D33: ='ENE TECH'!G31&RIGHT('City characteristics'!$C$20,2) -> INDRNG19 | E33: ='ENE TECH'!A31&" "&'ENE TECH'!B31&" "&"Import" -> Industrial RNG Import | F33: TJ | G33: TJa
C34: CITY | D34: ='ENE TECH'!G32&RIGHT('City characteristics'!$C$20,2) -> INDPCK19 | E34: ='ENE TECH'!A32&" "&'ENE TECH'!B32&" "&"Import" -> Industrial Petcoke Import | F34: TJ | G34: TJa
C35: CITY | D35: ='ENE TECH'!G33&RIGHT('City characteristics'!$C$20,2) -> INDCOA19 | E35: ='ENE TECH'!A33&" "&'ENE TECH'!B33&" "&"Import" -> Industrial Coal Import | F35: TJ | G35: TJa
C36: CITY | D36: ='ENE TECH'!G34&RIGHT('City characteristics'!$C$20,2) -> INDELC19 | E36: ='ENE TECH'!A34&" "&'ENE TECH'!B34&" "&"Import" -> Industrial Electricity Import | F36: TJ | G36: TJa | H36: DAYNITE
C37: CITY | D37: ='ENE TECH'!G35&RIGHT('City characteristics'!$C$20,2) -> INDH2G19 | E37: ='ENE TECH'!A35&" "&'ENE TECH'!B35&" "&"Import" -> Industrial Hydrogen Import | F37: TJ | G37: TJa | H37: DAYNITE
C38: CITY | D38: ='ENE TECH'!G36&RIGHT('City characteristics'!$C$20,2) -> INDSTM19 | E38: ='ENE TECH'!A36&" "&'ENE TECH'!B36&" "&"Import" -> Industrial Steam Import | F38: TJ | G38: TJa
C39: CITY | D39: ='ENE TECH'!G37&RIGHT('City characteristics'!$C$20,2) -> INDSOL19 | E39: ='ENE TECH'!A37&" "&'ENE TECH'!B37&" "&"Import" -> Industrial Solar Import | F39: TJ | G39: TJa
C40: CITY | D40: ='ENE TECH'!G38&RIGHT('City characteristics'!$C$20,2) -> INDWND19 | E40: ='ENE TECH'!A38&" "&'ENE TECH'!B38&" "&"Import" -> Industrial Wind Import | F40: TJ | G40: TJa
C41: CITY | D41: ='ENE TECH'!G39&RIGHT('City characteristics'!$C$20,2) -> TRALPG19 | E41: ='ENE TECH'!A39&" "&'ENE TECH'!B39&" "&"Import" -> Transportation LPG Import | F41: TJ | G41: TJa
...

Sheet Def_Comm
B2: ~FI_Comm
B3: Csets | C3: CommName | D3: CommDesc | E3: Unit | F3: LimType | G3: CTSLvl | H3: PeakTS | I3: Ctype
B4: *Commodity Set Membership | C4: Commodity Name | D4: Commodity Description | E4: Unit | F4: Sense of the Balance EQN. | G4: Timeslice Level | H4: Peak Monitoring | I4: Electricity Indicator
B5: NRG | C5: ='ENE TECH'!G3 -> RESLPG | D5: ='ENE TECH'!A3&" "&'ENE TECH'!B3 -> Residential LPG | E5: TJ
C6: ='ENE TECH'!G4 -> RESFOI | D6: ='ENE TECH'!A4&" "&'ENE TECH'!B4 -> Residential Fuel oil | E6: TJ
C7: ='ENE TECH'!G5 -> RESKER | D7: ='ENE TECH'!A5&" "&'ENE TECH'!B5 -> Residential Kerosene | E7: TJ
C8: ='ENE TECH'!G6 -> RESNGA | D8: ='ENE TECH'!A6&" "&'ENE TECH'!B6 -> Residential Natural gas | E8: TJ
C9: ='ENE TECH'!G7 -> RESRNG | D9: ='ENE TECH'!A7&" "&'ENE TECH'!B7 -> Residential RNG | E9: TJ
C10: ='ENE TECH'!G8 -> RESELC | D10: ='ENE TECH'!A8&" "&'ENE TECH'!B8 -> Residential Electricity | E10: TJ | G10: DAYNITE | H10: ANNUAL | I10: ELC
C11: ='ENE TECH'!G9 -> RESH2G | D11: ='ENE TECH'!A9&" "&'ENE TECH'!B9 -> Residential Hydrogen | E11: TJ | G11: DAYNITE | H11: ANNUAL
C12: RESSTM | D12: Residential Steam | E12: TJ | I12: LTHEAT
C13: ='ENE TECH'!G11 -> RESSOL | D13: ='ENE TECH'!A11&" "&'ENE TECH'!B11 -> Residential Solar | E13: TJ
C14: ='ENE TECH'!G12 -> RESWND | D14: ='ENE TECH'!A12&" "&'ENE TECH'!B12 -> Residential Wind | E14: TJ
C15: ='ENE TECH'!G13 -> COMLPG | D15: ='ENE TECH'!A13&" "&'ENE TECH'!B13 -> Commercial LPG | E15: TJ
C16: ='ENE TECH'!G14 -> COMDSL | D16: ='ENE TECH'!A14&" "&'ENE TECH'!B14 -> Commercial Diesel | E16: TJ
C17: ='ENE TECH'!G15 -> COMFOI | D17: ='ENE TECH'!A15&" "&'ENE TECH'!B15 -> Commercial Fuel oil | E17: TJ
C18: ='ENE TECH'!G16 -> COMKER | D18: ='ENE TECH'!A16&" "&'ENE TECH'!B16 -> Commercial Kerosene | E18: TJ
C19: ='ENE TECH'!G17 -> COMGSL | D19: ='ENE TECH'!A17&" "&'ENE TECH'!B17 -> Commercial Gasoline | E19: TJ
C20: ='ENE TECH'!G18 -> COMNGA | D20: ='ENE TECH'!A18&" "&'ENE TECH'!B18 -> Commercial Natural gas | E20: TJ
C21: ='ENE TECH'!G19 -> COMRNG | D21: ='ENE TECH'!A19&" "&'ENE TECH'!B19 -> Commercial RNG | E21: TJ
C22: ='ENE TECH'!G20 -> COMELC | D22: ='ENE TECH'!A20&" "&'ENE TECH'!B20 -> Commercial Electricity | E22: TJ | G22: DAYNITE | H22: ANNUAL | I22: ELC
C23: ='ENE TECH'!G21 -> COMH2G | D23: ='ENE TECH'!A21&" "&'ENE TECH'!B21 -> Commercial Hydrogen | E23: TJ | G23: DAYNITE | H23: ANNUAL
C24: COMSTM | D24: Commercial Steam | E24: TJ | I24: LTHEAT
C25: ='ENE TECH'!G23 -> COMSOL | D25: ='ENE TECH'!A23&" "&'ENE TECH'!B23 -> Commercial Solar | E25: TJ
C26: ='ENE TECH'!G24 -> COMWND | D26: ='ENE TECH'!A24&" "&'ENE TECH'!B24 -> Commercial Wind | E26: TJ
C27: ='ENE TECH'!G25 -> INDLPG | D27: ='ENE TECH'!A25&" "&'ENE TECH'!B25 -> Industrial LPG | E27: TJ
C28: ='ENE TECH'!G26 -> INDDSL | D28: ='ENE TECH'!A26&" "&'ENE TECH'!B26 -> Industrial Diesel | E28: TJ
C29: ='ENE TECH'!G27 -> INDFOI | D29: ='ENE TECH'!A27&" "&'ENE TECH'!B27 -> Industrial Fuel oil | E29: TJ
C30: ='ENE TECH'!G28 -> INDKER | D30: ='ENE TECH'!A28&" "&'ENE TECH'!B28 -> Industrial Kerosene | E30: TJ
C31: ='ENE TECH'!G29 -> INDGSL | D31: ='ENE TECH'!A29&" "&'ENE TECH'!B29 -> Industrial Gasoline | E31: TJ
C32: ='ENE TECH'!G30 -> INDNGA | D32: ='ENE TECH'!A30&" "&'ENE TECH'!B30 -> Industrial Natural gas | E32: TJ
C33: ='ENE TECH'!G31 -> INDRNG | D33: ='ENE TECH'!A31&" "&'ENE TECH'!B31 -> Industrial RNG | E33: TJ
C34: ='ENE TECH'!G32 -> INDPCK | D34: ='ENE TECH'!A32&" "&'ENE TECH'!B32 -> Industrial Petcoke | E34: TJ
C35: ='ENE TECH'!G33 -> INDCOA | D35: ='ENE TECH'!A33&" "&'ENE TECH'!B33 -> Industrial Coal | E35: TJ
C36: ='ENE TECH'!G34 -> INDELC | D36: ='ENE TECH'!A34&" "&'ENE TECH'!B34 -> Industrial Electricity | E36: TJ | G36: DAYNITE | H36: ANNUAL | I36: ELC
C37: ='ENE TECH'!G35 -> INDH2G | D37: ='ENE TECH'!A35&" "&'ENE TECH'!B35 -> Industrial Hydrogen | E37: TJ | G37: DAYNITE | H37: ANNUAL
C38: ='ENE TECH'!G36 -> INDSTM | D38: ='ENE TECH'!A36&" "&'ENE TECH'!B36 -> Industrial Steam | E38: TJ | I38: LTHEAT
C39: ='ENE TECH'!G37 -> INDSOL | D39: ='ENE TECH'!A37&" "&'ENE TECH'!B37 -> Industrial Solar | E39: TJ
C40: ='ENE TECH'!G38 -> INDWND | D40: ='ENE TECH'!A38&" "&'ENE TECH'!B38 -> Industrial Wind | E40: TJ
C41: ='ENE TECH'!G39 -> TRALPG | D41: ='ENE TECH'!A39&" "&'ENE TECH'!B39 -> Transportation LPG | E41: TJ
...

Sheet TechMin
D2: ~FI_T
B3: TechName | C3: Comm-IN | D3: Comm-OUT | E3: Attribute | F3: CITY | G3: EGRID
B4: *
B5: =Def_Tech!D97 -> IMPLPG19 | D5: =Def_Comm!C84 -> LPG | E5: Input | F5: =1 -> 1 | G5: =1 -> 1
B6: =Def_Tech!D98 -> IMPFOI19 | D6: =Def_Comm!C85 -> FOI | E6: Input | F6: =1 -> 1 | G6: =1 -> 1
B7: =Def_Tech!D99 -> IMPKER19 | D7: =Def_Comm!C86 -> KER | E7: Input | F7: =1 -> 1 | G7: =1 -> 1
B8: =Def_Tech!D100 -> IMPNGA19 | D8: =Def_Comm!C87 -> NGA | E8: Input | F8: =1 -> 1 | G8: =1 -> 1
B9: =Def_Tech!D101 -> IMPRNG19 | D9: =Def_Comm!C88 -> RNG | E9: Input | F9: =1 -> 1 | G9: =1 -> 1
B10: =Def_Tech!D102 -> IMPDSL19 | D10: =Def_Comm!C89 -> DSL | E10: Input | F10: =1 -> 1 | G10: =1 -> 1
B11: =Def_Tech!D103 -> IMPGSL19 | D11: =Def_Comm!C90 -> GSL | E11: Input | F11: =1 -> 1 | G11: =1 -> 1
B12: =Def_Tech!D104 -> IMPPCK19 | D12: =Def_Comm!C91 -> PCK | E12: Input | F12: =1 -> 1 | G12: =1 -> 1
B13: =Def_Tech!D105 -> IMPCOA19 | D13: =Def_Comm!C92 -> COA | E13: Input | F13: =1 -> 1 | G13: =1 -> 1
B14: =Def_Tech!D106 -> IMPETH19 | D14: =Def_Comm!C93 -> ETH | E14: Input | F14: =1 -> 1 | G14: =1 -> 1
B15: =Def_Tech!D107 -> IMPAGA19 | D15: =Def_Comm!C94 -> AGA | E15: Input | F15: =1 -> 1 | G15: =1 -> 1
B16: =Def_Tech!D108 -> IMPATF19 | D16: =Def_Comm!C95 -> ATF | E16: Input | F16: =1 -> 1 | G16: =1 -> 1
... B30: =Def_Tech!D122 -> IMPHYD19 | D30: =Def_Comm!C109 -> HYD | E30: Input | F30: =1 -> 1 | G30: =1 -> 1
B31: =Def_Tech!D124 -> IMPH2G19 | D31: =Def_Comm!C112 -> CH2G | E31: Input | F31: =1 -> 1 | G31: =1 -> 1

Sheet TechImp
L1: ='ENE TECH'!H2 -> 2019 | M1: ='ENE TECH'!I2 -> 2020 | N1: ='ENE TECH'!J2 -> 2021 | O1: ='ENE TECH'!K2 -> 2022 | P1: ='ENE TECH'!L2 -> 2023 | Q1: ='ENE TECH'!M2 -> 2024 | R1: ='ENE TECH'!N2 -> 2025 | S1: ='ENE TECH'!O2 -> 2030 | ... AG1: ='ENE TECH'!AC2 -> 2100
L2: ACT_COST | M2: ACT_COST | N2: ACT_COST | O2: ACT_COST | P2: ACT_COST | Q2: ACT_COST | R2: ACT_COST | S2: ACT_COST | T2: ACT_COST | U2: ACT_COST | V2: ACT_COST | W2: ACT_COST | X2: ACT_COST | Y2: ACT_COST | Z2: ACT_COST | AA2: ACT_COST | AB2: ACT_COST | AC2: ACT_COST | AD2: ACT_COST | AE2: ACT_COST | AF2: ACT_COST | AG2: ACT_COST
D4: ~FI_T | L4: ~FI_T
B5: TechName | C5: Comm-IN | D5: Comm-OUT | E5: Attribute | F5: CITY | G5: EGRID | J5: TechName | K5: NCAP_PKCNT | L5: =L2&"~"&L1 -> ACT_COST~2019 | M5: =M2&"~"&M1 -> ACT_COST~2020 | N5: =N2&"~"&N1 -> ACT_COST~2021 | O5: =O2&"~"&O1 -> ACT_COST~2022 | P5: =P2&"~"&P1 -> ACT_COST~2023 | Q5: =Q2&"~"&Q1 -> ACT_COST~2024 | R5: =R2&"~"&R1 -> ACT_COST~2025 | S5: =S2&"~"&S1 -> ACT_COST~2030 | ... AG5: =AG2&"~"&AG1 -> ACT_COST~2100
F6: Out/In | G6: Out/In | K6: % | L6: $/GJ | M6: $/GJ | N6: $/GJ | O6: $/GJ | P6: $/GJ | Q6: $/GJ | R6: $/GJ | S6: $/GJ | T6: $/GJ | U6: $/GJ | V6: $/GJ | W6: $/GJ | X6: $/GJ | Y6: $/GJ | Z6: $/GJ | AA6: $/GJ | AB6: $/GJ | AC6: $/GJ | AD6: $/GJ | AE6: $/GJ | AF6: $/GJ | AG6: $/GJ
B7: =Def_Tech!D5 -> RESLPG19 | C7: =IF(OR(RIGHT(D7,LEN(D7)-3)="ELC",RIGHT(D7,LEN(D7)-3)="H2G"),"C"&RIGHT(D7,LEN(D7)-3),RIGHT(D7,LEN(D7)-3)) -> LPG | D7: =Def_Comm!C5 -> RESLPG | E7: Input | F7: 1 | J7: =B7 -> RESLPG19 | K7: =IF(_xlfn.XLOOKUP($J7,$B:$B,$C:$C)="CELC",1,"") | L7: =IF(_xlfn.XLOOKUP($J7,$B:$B,$C:$C)="CELC",'ENE TECH'!H3-5,'ENE TECH'!H3) -> 33.139282 | M7: =IF(_xlfn.XLOOKUP($J7,$B:$B,$C:$C)="CELC",L7,'ENE TECH'!I3) -> 28.404792 | N7: =IF(_xlfn.XLOOKUP($J7,$B:$B,$C:$C)="CELC",M7,'ENE TECH'!J3) -> 34.017648 | O7: =IF(_xlfn.XLOOKUP($J7,$B:$B,$C:$C)="CELC",N7,'ENE TECH'!K3) -> 36.740013 | P7: =IF(_xlfn.XLOOKUP($J7,$B:$B,$C:$C)="CELC",O7,'ENE TECH'!L3) -> 38.524662 | Q7: =IF(_xlfn.XLOOKUP($J7,$B:$B,$C:$C)="CELC",P7,'ENE TECH'!M3) -> 38.53425 | R7: =IF(_xlfn.XLOOKUP($J7,$B:$B,$C:$C)="CELC",Q7,'ENE TECH'!N3) -> 37.487506 | S7: =IF(_xlfn.XLOOKUP($J7,$B:$B,$C:$C)="CELC",R7,'ENE TECH'!O3) -> 36.540775 | T7: =IF(_xlfn.XLOOKUP($J7,$B:$B,$C:$C)="CELC",S7,'ENE TECH'!P3) -> 42.127352 | ... AG7: =IF(_xlfn.XLOOKUP($J7,$B:$B,$C:$C)="CELC",AF7,'ENE TECH'!AC3) -> 54.209147
B8: =Def_Tech!D6 -> RESFOI19 | C8: =IF(OR(RIGHT(D8,LEN(D8)-3)="ELC",RIGHT(D8,LEN(D8)-3)="H2G"),"C"&RIGHT(D8,LEN(D8)-3),RIGHT(D8,LEN(D8)-3)) -> FOI | D8: =Def_Comm!C6 -> RESFOI | E8: Input | F8: 1 | J8: =B8 -> RESFOI19 | K8: =IF(_xlfn.XLOOKUP($J8,$B:$B,$C:$C)="CELC",1,"") | L8: =IF(_xlfn.XLOOKUP($J8,$B:$B,$C:$C)="CELC",'ENE TECH'!H4-5,'ENE TECH'!H4) -> 21.264373 | M8: =IF(_xlfn.XLOOKUP($J8,$B:$B,$C:$C)="CELC",L8,'ENE TECH'!I4) -> 17.088445 | N8: =IF(_xlfn.XLOOKUP($J8,$B:$B,$C:$C)="CELC",M8,'ENE TECH'!J4) -> 19.92401 | O8: =IF(_xlfn.XLOOKUP($J8,$B:$B,$C:$C)="CELC",N8,'ENE TECH'!K4) -> 21.518489 | P8: =IF(_xlfn.XLOOKUP($J8,$B:$B,$C:$C)="CELC",O8,'ENE TECH'!L4) -> 19.660523 | Q8: =IF(_xlfn.XLOOKUP($J8,$B:$B,$C:$C)="CELC",P8,'ENE TECH'!M4) -> 18.79016 | R8: =IF(_xlfn.XLOOKUP($J8,$B:$B,$C:$C)="CELC",Q8,'ENE TECH'!N4) -> 17.783449 | S8: =IF(_xlfn.XLOOKUP($J8,$B:$B,$C:$C)="CELC",R8,'ENE TECH'!O4) -> 17.917993 | T8: =IF(_xlfn.XLOOKUP($J8,$B:$B,$C:$C)="CELC",S8,'ENE TECH'!P4) -> 19.239678 | ... AG8: =IF(_xlfn.XLOOKUP($J8,$B:$B,$C:$C)="CELC",AF8,'ENE TECH'!AC4) -> 23.258847
B9: =Def_Tech!D7 -> RESKER19 | C9: =IF(OR(RIGHT(D9,LEN(D9)-3)="ELC",RIGHT(D9,LEN(D9)-3)="H2G"),"C"&RIGHT(D9,LEN(D9)-3),RIGHT(D9,LEN(D9)-3)) -> KER | D9: =Def_Comm!C7 -> RESKER | E9: Input | F9: 1 | J9: =B9 -> RESKER19 | K9: =IF(_xlfn.XLOOKUP($J9,$B:$B,$C:$C)="CELC",1,"") | L9: =IF(_xlfn.XLOOKUP($J9,$B:$B,$C:$C)="CELC",'ENE TECH'!H5-5,'ENE TECH'!H5) -> 24.732951 | M9: =IF(_xlfn.XLOOKUP($J9,$B:$B,$C:$C)="CELC",L9,'ENE TECH'!I5) -> 15.775618 | N9: =IF(_xlfn.XLOOKUP($J9,$B:$B,$C:$C)="CELC",M9,'ENE TECH'!J5) -> 24.575447 | O9: =IF(_xlfn.XLOOKUP($J9,$B:$B,$C:$C)="CELC",N9,'ENE TECH'!K5) -> 26.54217 | P9: =IF(_xlfn.XLOOKUP($J9,$B:$B,$C:$C)="CELC",O9,'ENE TECH'!L5) -> 24.250446 | Q9: =IF(_xlfn.XLOOKUP($J9,$B:$B,$C:$C)="CELC",P9,'ENE TECH'!M5) -> 23.176889 | R9: =IF(_xlfn.XLOOKUP($J9,$B:$B,$C:$C)="CELC",Q9,'ENE TECH'!N5) -> 21.935152 | S9: =IF(_xlfn.XLOOKUP($J9,$B:$B,$C:$C)="CELC",R9,'ENE TECH'!O5) -> 22.101108 | T9: =IF(_xlfn.XLOOKUP($J9,$B:$B,$C:$C)="CELC",S9,'ENE TECH'!P5) -> 23.731351 | ... AG9: =IF(_xlfn.XLOOKUP($J9,$B:$B,$C:$C)="CELC",AF9,'ENE TECH'!AC5) -> 28.68883
B10: =Def_Tech!D8 -> RESNGA19 | C10: =IF(OR(RIGHT(D10,LEN(D10)-3)="ELC",RIGHT(D10,LEN(D10)-3)="H2G"),"C"&RIGHT(D10,LEN(D10)-3),RIGHT(D10,LEN(D10)-3)) -> NGA | D10: =Def_Comm!C8 -> RESNGA | E10: Input | F10: 1 | J10: =B10 -> RESNGA19 | K10: =IF(_xlfn.XLOOKUP($J10,$B:$B,$C:$C)="CELC",1,"") | L10: =IF(_xlfn.XLOOKUP($J10,$B:$B,$C:$C)="CELC",'ENE TECH'!H6-5,'ENE TECH'!H6) -> 13.498734 | M10: =IF(_xlfn.XLOOKUP($J10,$B:$B,$C:$C)="CELC",L10,'ENE TECH'!I6) -> 13.43206 | N10: =IF(_xlfn.XLOOKUP($J10,$B:$B,$C:$C)="CELC",M10,'ENE TECH'!J6) -> 14.30799 | O10: =IF(_xlfn.XLOOKUP($J10,$B:$B,$C:$C)="CELC",N10,'ENE TECH'!K6) -> 15.45303 | P10: =IF(_xlfn.XLOOKUP($J10,$B:$B,$C:$C)="CELC",O10,'ENE TECH'!L6) -> 14.920712 | Q10: =IF(_xlfn.XLOOKUP($J10,$B:$B,$C:$C)="CELC",P10,'ENE TECH'!M6) -> 13.39134 | R10: =IF(_xlfn.XLOOKUP($J10,$B:$B,$C:$C)="CELC",Q10,'ENE TECH'!N6) -> 12.76654 | S10: =IF(_xlfn.XLOOKUP($J10,$B:$B,$C:$C)="CELC",R10,'ENE TECH'!O6) -> 12.386274 | T10: =IF(_xlfn.XLOOKUP($J10,$B:$B,$C:$C)="CELC",S10,'ENE TECH'!P6) -> 13.885007 | ... AG10: =IF(_xlfn.XLOOKUP($J10,$B:$B,$C:$C)="CELC",AF10,'ENE TECH'!AC6) -> 16.83725
B11: =Def_Tech!D9 -> RESRNG19 | C11: =IF(OR(RIGHT(D11,LEN(D11)-3)="ELC",RIGHT(D11,LEN(D11)-3)="H2G"),"C"&RIGHT(D11,LEN(D11)-3),RIGHT(D11,LEN(D11)-3)) -> RNG | D11: =Def_Comm!C9 -> RESRNG | E11: Input | F11: 1 | J11: =B11 -> RESRNG19 | L11: =IF(_xlfn.XLOOKUP($J11,$B:$B,$C:$C)="CELC",'ENE TECH'!H7-5,'ENE TECH'!H7) -> 26.997469 | M11: =IF(_xlfn.XLOOKUP($J11,$B:$B,$C:$C)="CELC",L11,'ENE TECH'!I7) -> 26.86412 | N11: =IF(_xlfn.XLOOKUP($J11,$B:$B,$C:$C)="CELC",M11,'ENE TECH'!J7) -> 28.61598 | O11: =IF(_xlfn.XLOOKUP($J11,$B:$B,$C:$C)="CELC",N11,'ENE TECH'!K7) -> 30.90606 | P11: =IF(_xlfn.XLOOKUP($J11,$B:$B,$C:$C)="CELC",O11,'ENE TECH'!L7) -> 29.841423 | Q11: =IF(_xlfn.XLOOKUP($J11,$B:$B,$C:$C)="CELC",P11,'ENE TECH'!M7) -> 26.78268 | R11: =IF(_xlfn.XLOOKUP($J11,$B:$B,$C:$C)="CELC",Q11,'ENE TECH'!N7) -> 25.533081 | S11: =IF(_xlfn.XLOOKUP($J11,$B:$B,$C:$C)="CELC",R11,'ENE TECH'!O7) -> 24.772548 | T11: =IF(_xlfn.XLOOKUP($J11,$B:$B,$C:$C)="CELC",S11,'ENE TECH'!P7) -> 27.770013 | ... AG11: =IF(_xlfn.XLOOKUP($J11,$B:$B,$C:$C)="CELC",AF11,'ENE TECH'!AC7) -> 33.6745
B12: =Def_Tech!D10 -> RESELC19 | C12: =IF(OR(RIGHT(D12,LEN(D12)-3)="ELC",RIGHT(D12,LEN(D12)-3)="H2G"),"C"&RIGHT(D12,LEN(D12)-3),RIGHT(D12,LEN(D12)-3)) -> CELC | D12: =Def_Comm!C10 -> RESELC | E12: Input | F12: 1 | J12: =B12 -> RESELC19 | K12: =IF(_xlfn.XLOOKUP($J12,$B:$B,$C:$C)="CELC",1,"") -> 1 | L12: =IF(_xlfn.XLOOKUP($J12,$B:$B,$C:$C)="CELC",'ENE TECH'!H8-5,'ENE TECH'!H8) -> 53.082115 | M12: =IF(_xlfn.XLOOKUP($J12,$B:$B,$C:$C)="CELC",L12,'ENE TECH'!I8) -> 53.082115 | N12: =IF(_xlfn.XLOOKUP($J12,$B:$B,$C:$C)="CELC",M12,'ENE TECH'!J8) -> 53.082115 | O12: =IF(_xlfn.XLOOKUP($J12,$B:$B,$C:$C)="CELC",N12,'ENE TECH'!K8) -> 53.082115 | P12: =IF(_xlfn.XLOOKUP($J12,$B:$B,$C:$C)="CELC",O12,'ENE TECH'!L8) -> 53.082115 | Q12: =IF(_xlfn.XLOOKUP($J12,$B:$B,$C:$C)="CELC",P12,'ENE TECH'!M8) -> 53.082115 | R12: =IF(_xlfn.XLOOKUP($J12,$B:$B,$C:$C)="CELC",Q12,'ENE TECH'!N8) -> 53.082115 | S12: =IF(_xlfn.XLOOKUP($J12,$B:$B,$C:$C)="CELC",R12,'ENE TECH'!O8) -> 53.082115 | T12: =IF(_xlfn.XLOOKUP($J12,$B:$B,$C:$C)="CELC",S12,'ENE TECH'!P8) -> 53.082115 | ... AG12: =IF(_xlfn.XLOOKUP($J12,$B:$B,$C:$C)="CELC",AF12,'ENE TECH'!AC8) -> 53.082115
B13: =Def_Tech!D11 -> RESH2G19 | C13: =IF(OR(RIGHT(D13,LEN(D13)-3)="ELC",RIGHT(D13,LEN(D13)-3)="H2G"),"C"&RIGHT(D13,LEN(D13)-3),RIGHT(D13,LEN(D13)-3)) -> CH2G | D13: =Def_Comm!C11 -> RESH2G | E13: Input | F13: 1 | J13: =B13 -> RESH2G19 | K13: =IF(_xlfn.XLOOKUP($J13,$B:$B,$C:$C)="CELC",1,"") | L13: =IF(_xlfn.XLOOKUP($J13,$B:$B,$C:$C)="CELC",'ENE TECH'!H9-5,'ENE TECH'!H9) -> 116.16423 | M13: =IF(_xlfn.XLOOKUP($J13,$B:$B,$C:$C)="CELC",L13,'ENE TECH'!I9) -> 116.78731 | N13: =IF(_xlfn.XLOOKUP($J13,$B:$B,$C:$C)="CELC",M13,'ENE TECH'!J9) -> 122.39494 | O13: =IF(_xlfn.XLOOKUP($J13,$B:$B,$C:$C)="CELC",N13,'ENE TECH'!K9) -> 132.18996 | P13: =IF(_xlfn.XLOOKUP($J13,$B:$B,$C:$C)="CELC",O13,'ENE TECH'!L9) -> 125.984 | Q13: =IF(_xlfn.XLOOKUP($J13,$B:$B,$C:$C)="CELC",P13,'ENE TECH'!M9) -> 121.8798 | R13: =IF(_xlfn.XLOOKUP($J13,$B:$B,$C:$C)="CELC",Q13,'ENE TECH'!N9) -> 119.72731 | S13: =IF(_xlfn.XLOOKUP($J13,$B:$B,$C:$C)="CELC",R13,'ENE TECH'!O9) -> 122.80605 | T13: =IF(_xlfn.XLOOKUP($J13,$B:$B,$C:$C)="CELC",S13,'ENE TECH'!P9) -> 134.14707 | ... AG13: =IF(_xlfn.XLOOKUP($J13,$B:$B,$C:$C)="CELC",AF13,'ENE TECH'!AC9) -> 162.76708
B14: =Def_Tech!D12 -> RESSTM19 | C14: =IF(OR(RIGHT(D14,LEN(D14)-3)="ELC",RIGHT(D14,LEN(D14)-3)="H2G"),"C"&RIGHT(D14,LEN(D14)-3),RIGHT(D14,LEN(D14)-3)) -> STM | D14: =Def_Comm!C12 -> RESSTM | E14: Input | F14: 1 | J14: =B14 -> RESSTM19 | K14: =IF(_xlfn.XLOOKUP($J14,$B:$B,$C:$C)="CELC",1,"") | L14: =IF(_xlfn.XLOOKUP($J14,$B:$B,$C:$C)="CELC",'ENE TECH'!H10-5,'ENE TECH'!H10) -> 116.16423 | M14: =IF(_xlfn.XLOOKUP($J14,$B:$B,$C:$C)="CELC",L14,'ENE TECH'!I10) -> 116.78731 | N14: =IF(_xlfn.XLOOKUP($J14,$B:$B,$C:$C)="CELC",M14,'ENE TECH'!J10) -> 122.39494 | O14: =IF(_xlfn.XLOOKUP($J14,$B:$B,$C:$C)="CELC",N14,'ENE TECH'!K10) -> 132.18996 | P14: =IF(_xlfn.XLOOKUP($J14,$B:$B,$C:$C)="CELC",O14,'ENE TECH'!L10) -> 125.984 | Q14: =IF(_xlfn.XLOOKUP($J14,$B:$B,$C:$C)="CELC",P14,'ENE TECH'!M10) -> 121.8798 | R14: =IF(_xlfn.XLOOKUP($J14,$B:$B,$C:$C)="CELC",Q14,'ENE TECH'!N10) -> 119.72731 | S14: =IF(_xlfn.XLOOKUP($J14,$B:$B,$C:$C)="CELC",R14,'ENE TECH'!O10) -> 122.80605 | T14: =IF(_xlfn.XLOOKUP($J14,$B:$B,$C:$C)="CELC",S14,'ENE TECH'!P10) -> 134.14707 | ... AG14: =IF(_xlfn.XLOOKUP($J14,$B:$B,$C:$C)="CELC",AF14,'ENE TECH'!AC10) -> 162.76708
B15: =Def_Tech!D13 -> RESSOL19 | C15: =IF(OR(RIGHT(D15,LEN(D15)-3)="ELC",RIGHT(D15,LEN(D15)-3)="H2G"),"C"&RIGHT(D15,LEN(D15)-3),RIGHT(D15,LEN(D15)-3)) -> SOL | D15: =Def_Comm!C13 -> RESSOL | E15: Input | F15: 1 | J15: =B15 -> RESSOL19 | K15: =IF(_xlfn.XLOOKUP($J15,$B:$B,$C:$C)="CELC",1,"") | L15: =IF(_xlfn.XLOOKUP($J15,$B:$B,$C:$C)="CELC",'ENE TECH'!H11-5,'ENE TECH'!H11) -> 0 | M15: =IF(_xlfn.XLOOKUP($J15,$B:$B,$C:$C)="CELC",L15,'ENE TECH'!I11) -> 0 | N15: =IF(_xlfn.XLOOKUP($J15,$B:$B,$C:$C)="CELC",M15,'ENE TECH'!J11) -> 0 | O15: =IF(_xlfn.XLOOKUP($J15,$B:$B,$C:$C)="CELC",N15,'ENE TECH'!K11) -> 0 | P15: =IF(_xlfn.XLOOKUP($J15,$B:$B,$C:$C)="CELC",O15,'ENE TECH'!L11) -> 0 | Q15: =IF(_xlfn.XLOOKUP($J15,$B:$B,$C:$C)="CELC",P15,'ENE TECH'!M11) -> 0 | R15: =IF(_xlfn.XLOOKUP($J15,$B:$B,$C:$C)="CELC",Q15,'ENE TECH'!N11) -> 0 | S15: =IF(_xlfn.XLOOKUP($J15,$B:$B,$C:$C)="CELC",R15,'ENE TECH'!O11) -> 0 | T15: =IF(_xlfn.XLOOKUP($J15,$B:$B,$C:$C)="CELC",S15,'ENE TECH'!P11) -> 0 | ... AG15: =IF(_xlfn.XLOOKUP($J15,$B:$B,$C:$C)="CELC",AF15,'ENE TECH'!AC11) -> 0
B16: =Def_Tech!D14 -> RESWND19 | C16: =IF(OR(RIGHT(D16,LEN(D16)-3)="ELC",RIGHT(D16,LEN(D16)-3)="H2G"),"C"&RIGHT(D16,LEN(D16)-3),RIGHT(D16,LEN(D16)-3)) -> WND | D16: =Def_Comm!C14 -> RESWND | E16: Input | F16: 1 | J16: =B16 -> RESWND19 | K16: =IF(_xlfn.XLOOKUP($J16,$B:$B,$C:$C)="CELC",1,"") | L16: =IF(_xlfn.XLOOKUP($J16,$B:$B,$C:$C)="CELC",'ENE TECH'!H12-5,'ENE TECH'!H12) -> 0 | M16: =IF(_xlfn.XLOOKUP($J16,$B:$B,$C:$C)="CELC",L16,'ENE TECH'!I12) -> 0 | N16: =IF(_xlfn.XLOOKUP($J16,$B:$B,$C:$C)="CELC",M16,'ENE TECH'!J12) -> 0 | O16: =IF(_xlfn.XLOOKUP($J16,$B:$B,$C:$C)="CELC",N16,'ENE TECH'!K12) -> 0 | P16: =IF(_xlfn.XLOOKUP($J16,$B:$B,$C:$C)="CELC",O16,'ENE TECH'!L12) -> 0 | Q16: =IF(_xlfn.XLOOKUP($J16,$B:$B,$C:$C)="CELC",P16,'ENE TECH'!M12) -> 0 | R16: =IF(_xlfn.XLOOKUP($J16,$B:$B,$C:$C)="CELC",Q16,'ENE TECH'!N12) -> 0 | S16: =IF(_xlfn.XLOOKUP($J16,$B:$B,$C:$C)="CELC",R16,'ENE TECH'!O12) -> 0 | T16: =IF(_xlfn.XLOOKUP($J16,$B:$B,$C:$C)="CELC",S16,'ENE TECH'!P12) -> 0 | ... AG16: =IF(_xlfn.XLOOKUP($J16,$B:$B,$C:$C)="CELC",AF16,'ENE TECH'!AC12) -> 0
B17: =Def_Tech!D15 -> COMLPG19 | C17: =IF(OR(RIGHT(D17,LEN(D17)-3)="ELC",RIGHT(D17,LEN(D17)-3)="H2G"),"C"&RIGHT(D17,LEN(D17)-3),RIGHT(D17,LEN(D17)-3)) -> LPG | D17: =Def_Comm!C15 -> COMLPG | E17: Input | F17: 1 | J17: =B17 -> COMLPG19 | K17: =IF(_xlfn.XLOOKUP($J17,$B:$B,$C:$C)="CELC",1,"") | L17: =IF(_xlfn.XLOOKUP($J17,$B:$B,$C:$C)="CELC",'ENE TECH'!H13-5,'ENE TECH'!H13) -> 15.796391 | M17: =IF(_xlfn.XLOOKUP($J17,$B:$B,$C:$C)="CELC",L17,'ENE TECH'!I13) -> 14.365143 | N17: =IF(_xlfn.XLOOKUP($J17,$B:$B,$C:$C)="CELC",M17,'ENE TECH'!J13) -> 21.949636 | O17: =IF(_xlfn.XLOOKUP($J17,$B:$B,$C:$C)="CELC",N17,'ENE TECH'!K13) -> 23.706221 | P17: =IF(_xlfn.XLOOKUP($J17,$B:$B,$C:$C)="CELC",O17,'ENE TECH'!L13) -> 22.146428 | Q17: =IF(_xlfn.XLOOKUP($J17,$B:$B,$C:$C)="CELC",P17,'ENE TECH'!M13) -> 20.587193 | R17: =IF(_xlfn.XLOOKUP($J17,$B:$B,$C:$C)="CELC",Q17,'ENE TECH'!N13) -> 19.055314 | S17: =IF(_xlfn.XLOOKUP($J17,$B:$B,$C:$C)="CELC",R17,'ENE TECH'!O13) -> 19.150876 | T17: =IF(_xlfn.XLOOKUP($J17,$B:$B,$C:$C)="CELC",S17,'ENE TECH'!P13) -> 22.286658 | ... AG17: =IF(_xlfn.XLOOKUP($J17,$B:$B,$C:$C)="CELC",AF17,'ENE TECH'!AC13) -> 28.104431
B18: =Def_Tech!D16 -> COMDSL19 | C18: =IF(OR(RIGHT(D18,LEN(D18)-3)="ELC",RIGHT(D18,LEN(D18)-3)="H2G"),"C"&RIGHT(D18,LEN(D18)-3),RIGHT(D18,LEN(D18)-3)) -> DSL | D18: =Def_Comm!C16 -> COMDSL | E18: Input | F18: 1 | J18: =B18 -> COMDSL19 | K18: =IF(_xlfn.XLOOKUP($J18,$B:$B,$C:$C)="CELC",1,"") | L18: =IF(_xlfn.XLOOKUP($J18,$B:$B,$C:$C)="CELC",'ENE TECH'!H14-5,'ENE TECH'!H14) -> 17.387077 | M18: =IF(_xlfn.XLOOKUP($J18,$B:$B,$C:$C)="CELC",L18,'ENE TECH'!I14) -> 11.511644 | N18: =IF(_xlfn.XLOOKUP($J18,$B:$B,$C:$C)="CELC",M18,'ENE TECH'!J14) -> 18.252065 | O18: =IF(_xlfn.XLOOKUP($J18,$B:$B,$C:$C)="CELC",N18,'ENE TECH'!K14) -> 19.712741 | P18: =IF(_xlfn.XLOOKUP($J18,$B:$B,$C:$C)="CELC",O18,'ENE TECH'!L14) -> 18.085099 | Q18: =IF(_xlfn.XLOOKUP($J18,$B:$B,$C:$C)="CELC",P18,'ENE TECH'!M14) -> 16.656612 | R18: =IF(_xlfn.XLOOKUP($J18,$B:$B,$C:$C)="CELC",Q18,'ENE TECH'!N14) -> 15.093246 | S18: =IF(_xlfn.XLOOKUP($J18,$B:$B,$C:$C)="CELC",R18,'ENE TECH'!O14) -> 13.112384 | T18: =IF(_xlfn.XLOOKUP($J18,$B:$B,$C:$C)="CELC",S18,'ENE TECH'!P14) -> 14.115668 | ... AG18: =IF(_xlfn.XLOOKUP($J18,$B:$B,$C:$C)="CELC",AF18,'ENE TECH'!AC14) -> 17.126833
B19: =Def_Tech!D17 -> COMFOI19 | C19: =IF(OR(RIGHT(D19,LEN(D19)-3)="ELC",RIGHT(D19,LEN(D19)-3)="H2G"),"C"&RIGHT(D19,LEN(D19)-3),RIGHT(D19,LEN(D19)-3)) -> FOI | D19: =Def_Comm!C17 -> COMFOI | E19: Input | F19: 1 | J19: =B19 -> COMFOI19 | K19: =IF(_xlfn.XLOOKUP($J19,$B:$B,$C:$C)="CELC",1,"") | L19: =IF(_xlfn.XLOOKUP($J19,$B:$B,$C:$C)="CELC",'ENE TECH'!H15-5,'ENE TECH'!H15) -> 17.387077 | M19: =IF(_xlfn.XLOOKUP($J19,$B:$B,$C:$C)="CELC",L19,'ENE TECH'!I15) -> 11.511644 | N19: =IF(_xlfn.XLOOKUP($J19,$B:$B,$C:$C)="CELC",M19,'ENE TECH'!J15) -> 18.252065 | O19: =IF(_xlfn.XLOOKUP($J19,$B:$B,$C:$C)="CELC",N19,'ENE TECH'!K15) -> 19.712741 | P19: =IF(_xlfn.XLOOKUP($J19,$B:$B,$C:$C)="CELC",O19,'ENE TECH'!L15) -> 12.042501 | Q19: =IF(_xlfn.XLOOKUP($J19,$B:$B,$C:$C)="CELC",P19,'ENE TECH'!M15) -> 14.295152 | R19: =IF(_xlfn.XLOOKUP($J19,$B:$B,$C:$C)="CELC",Q19,'ENE TECH'!N15) -> 14.501626 | S19: =IF(_xlfn.XLOOKUP($J19,$B:$B,$C:$C)="CELC",R19,'ENE TECH'!O15) -> 22.312094 | T19: =IF(_xlfn.XLOOKUP($J19,$B:$B,$C:$C)="CELC",S19,'ENE TECH'!P15) -> 24.510554 | ... AG19: =IF(_xlfn.XLOOKUP($J19,$B:$B,$C:$C)="CELC",AF19,'ENE TECH'!AC15) -> 31.154017
B20: =Def_Tech!D18 -> COMKER19 | C20: =IF(OR(RIGHT(D20,LEN(D20)-3)="ELC",RIGHT(D20,LEN(D20)-3)="H2G"),"C"&RIGHT(D20,LEN(D20)-3),RIGHT(D20,LEN(D20)-3)) -> KER | D20: =Def_Comm!C18 -> COMKER | E20: Input | F20: 1 | J20: =B20 -> COMKER19 | K20: =IF(_xlfn.XLOOKUP($J20,$B:$B,$C:$C)="CELC",1,"") | L20: =IF(_xlfn.XLOOKUP($J20,$B:$B,$C:$C)="CELC",'ENE TECH'!H16-5,'ENE TECH'!H16) -> 24.732951 | M20: =IF(_xlfn.XLOOKUP($J20,$B:$B,$C:$C)="CELC",L20,'ENE TECH'!I16) -> 15.775618 | N20: =IF(_xlfn.XLOOKUP($J20,$B:$B,$C:$C)="CELC",M20,'ENE TECH'!J16) -> 24.575447 | O20: =IF(_xlfn.XLOOKUP($J20,$B:$B,$C:$C)="CELC",N20,'ENE TECH'!K16) -> 26.54217 | P20: =IF(_xlfn.XLOOKUP($J20,$B:$B,$C:$C)="CELC",O20,'ENE TECH'!L16) -> 24.350636 | Q20: =IF(_xlfn.XLOOKUP($J20,$B:$B,$C:$C)="CELC",P20,'ENE TECH'!M16) -> 22.427252 | R20: =IF(_xlfn.XLOOKUP($J20,$B:$B,$C:$C)="CELC",Q20,'ENE TECH'!N16) -> 20.322262 | S20: =IF(_xlfn.XLOOKUP($J20,$B:$B,$C:$C)="CELC",R20,'ENE TECH'!O16) -> 17.655135 | T20: =IF(_xlfn.XLOOKUP($J20,$B:$B,$C:$C)="CELC",S20,'ENE TECH'!P16) -> 19.006005 | ... AG20: =IF(_xlfn.XLOOKUP($J20,$B:$B,$C:$C)="CELC",AF20,'ENE TECH'!AC16) -> 23.06038
B21: =Def_Tech!D19 -> COMGSL19 | C21: =IF(OR(RIGHT(D21,LEN(D21)-3)="ELC",RIGHT(D21,LEN(D21)-3)="H2G"),"C"&RIGHT(D21,LEN(D21)-3),RIGHT(D21,LEN(D21)-3)) -> GSL | D21: =Def_Comm!C19 -> COMGSL | E21: Input | F21: 1 | J21: =B21 -> COMGSL19 | K21: =IF(_xlfn.XLOOKUP($J21,$B:$B,$C:$C)="CELC",1,"") | L21: =IF(_xlfn.XLOOKUP($J21,$B:$B,$C:$C)="CELC",'ENE TECH'!H17-5,'ENE TECH'!H17) -> 23.164358 | M21: =IF(_xlfn.XLOOKUP($J21,$B:$B,$C:$C)="CELC",L21,'ENE TECH'!I17) -> 19.377754 | N21: =IF(_xlfn.XLOOKUP($J21,$B:$B,$C:$C)="CELC",M21,'ENE TECH'!J17) -> 25.582901 | O21: =IF(_xlfn.XLOOKUP($J21,$B:$B,$C:$C)="CELC",N21,'ENE TECH'!K17) -> 27.630249 | P21: =IF(_xlfn.XLOOKUP($J21,$B:$B,$C:$C)="CELC",O21,'ENE TECH'!L17) -> 25.348874 | Q21: =IF(_xlfn.XLOOKUP($J21,$B:$B,$C:$C)="CELC",P21,'ENE TECH'!M17) -> 23.346643 | R21: =IF(_xlfn.XLOOKUP($J21,$B:$B,$C:$C)="CELC",Q21,'ENE TECH'!N17) -> 21.15536 | S21: =IF(_xlfn.XLOOKUP($J21,$B:$B,$C:$C)="CELC",R21,'ENE TECH'!O17) -> 18.378896 | T21: =IF(_xlfn.XLOOKUP($J21,$B:$B,$C:$C)="CELC",S21,'ENE TECH'!P17) -> 19.785143 | ... AG21: =IF(_xlfn.XLOOKUP($J21,$B:$B,$C:$C)="CELC",AF21,'ENE TECH'!AC17) -> 24.005725
B22: =Def_Tech!D20 -> COMNGA19 | C22: =IF(OR(RIGHT(D22,LEN(D22)-3)="ELC",RIGHT(D22,LEN(D22)-3)="H2G"),"C"&RIGHT(D22,LEN(D22)-3),RIGHT(D22,LEN(D22)-3)) -> NGA | D22: =Def_Comm!C20 -> COMNGA | E22: Input | F22: 1 | J22: =B22 -> COMNGA19 | K22: =IF(_xlfn.XLOOKUP($J22,$B:$B,$C:$C)="CELC",1,"") | L22: =IF(_xlfn.XLOOKUP($J22,$B:$B,$C:$C)="CELC",'ENE TECH'!H18-5,'ENE TECH'!H18) -> 7.7104063 | M22: =IF(_xlfn.XLOOKUP($J22,$B:$B,$C:$C)="CELC",L22,'ENE TECH'!I18) -> 7.2259709 | N22: =IF(_xlfn.XLOOKUP($J22,$B:$B,$C:$C)="CELC",M22,'ENE TECH'!J18) -> 8.2096782 | O22: =IF(_xlfn.XLOOKUP($J22,$B:$B,$C:$C)="CELC",N22,'ENE TECH'!K18) -> 8.8666823 | P22: =IF(_xlfn.XLOOKUP($J22,$B:$B,$C:$C)="CELC",O22,'ENE TECH'!L18) -> 8.1872197 | Q22: =IF(_xlfn.XLOOKUP($J22,$B:$B,$C:$C)="CELC",P22,'ENE TECH'!M18) -> 7.255384 | R22: =IF(_xlfn.XLOOKUP($J22,$B:$B,$C:$C)="CELC",Q22,'ENE TECH'!N18) -> 6.9579136 | S22: =IF(_xlfn.XLOOKUP($J22,$B:$B,$C:$C)="CELC",R22,'ENE TECH'!O18) -> 6.9767662 | T22: =IF(_xlfn.XLOOKUP($J22,$B:$B,$C:$C)="CELC",S22,'ENE TECH'!P18) -> 7.8550132 | ... AG22: =IF(_xlfn.XLOOKUP($J22,$B:$B,$C:$C)="CELC",AF22,'ENE TECH'!AC18) -> 9.4628453
B23: =Def_Tech!D21 -> COMRNG19 | C23: =IF(OR(RIGHT(D23,LEN(D23)-3)="ELC",RIGHT(D23,LEN(D23)-3)="H2G"),"C"&RIGHT(D23,LEN(D23)-3),RIGHT(D23,LEN(D23)-3)) -> RNG | D23: =Def_Comm!C21 -> COMRNG | E23: Input | F23: 1 | J23: =B23 -> COMRNG19 | K23: =IF(_xlfn.XLOOKUP($J23,$B:$B,$C:$C)="CELC",1,"") | L23: =IF(_xlfn.XLOOKUP($J23,$B:$B,$C:$C)="CELC",'ENE TECH'!H19-5,'ENE TECH'!H19) -> 15.420813 | M23: =IF(_xlfn.XLOOKUP($J23,$B:$B,$C:$C)="CELC",L23,'ENE TECH'!I19) -> 14.451942 | N23: =IF(_xlfn.XLOOKUP($J23,$B:$B,$C:$C)="CELC",M23,'ENE TECH'!J19) -> 16.419356 | O23: =IF(_xlfn.XLOOKUP($J23,$B:$B,$C:$C)="CELC",N23,'ENE TECH'!K19) -> 17.733365 | P23: =IF(_xlfn.XLOOKUP($J23,$B:$B,$C:$C)="CELC",O23,'ENE TECH'!L19) -> 17.122494 | Q23: =IF(_xlfn.XLOOKUP($J23,$B:$B,$C:$C)="CELC",P23,'ENE TECH'!M19) -> 15.36744 | R23: =IF(_xlfn.XLOOKUP($J23,$B:$B,$C:$C)="CELC",Q23,'ENE TECH'!N19) -> 14.650442 | S23: =IF(_xlfn.XLOOKUP($J23,$B:$B,$C:$C)="CELC",R23,'ENE TECH'!O19) -> 14.214061 | T23: =IF(_xlfn.XLOOKUP($J23,$B:$B,$C:$C)="CELC",S23,'ENE TECH'!P19) -> 15.933955 | ... AG23: =IF(_xlfn.XLOOKUP($J23,$B:$B,$C:$C)="CELC",AF23,'ENE TECH'!AC19) -> 19.321848
... B42: =Def_Tech!D40 -> INDWND19 | C42: =IF(OR(RIGHT(D42,LEN(D42)-3)="ELC",RIGHT(D42,LEN(D42)-3)="H2G"),"C"&RIGHT(D42,LEN(D42)-3),RIGHT(D42,LEN(D42)-3)) -> WND | D42: =Def_Comm!C40 -> INDWND | E42: Input | F42: 1 | J42: =B42 -> INDWND19 | K42: =IF(_xlfn.XLOOKUP($J42,$B:$B,$C:$C)="CELC",1,"") | L42: =IF(_xlfn.XLOOKUP($J42,$B:$B,$C:$C)="CELC",'ENE TECH'!H38-5,'ENE TECH'!H38) -> 0 | M42: =IF(_xlfn.XLOOKUP($J42,$B:$B,$C:$C)="CELC",L42,'ENE TECH'!I38) -> 0 | N42: =IF(_xlfn.XLOOKUP($J42,$B:$B,$C:$C)="CELC",M42,'ENE TECH'!J38) -> 0 | O42: =IF(_xlfn.XLOOKUP($J42,$B:$B,$C:$C)="CELC",N42,'ENE TECH'!K38) -> 0 | P42: =IF(_xlfn.XLOOKUP($J42,$B:$B,$C:$C)="CELC",O42,'ENE TECH'!L38) -> 0 | Q42: =IF(_xlfn.XLOOKUP($J42,$B:$B,$C:$C)="CELC",P42,'ENE TECH'!M38) -> 0 | R42: =IF(_xlfn.XLOOKUP($J42,$B:$B,$C:$C)="CELC",Q42,'ENE TECH'!N38) -> 0 | S42: =IF(_xlfn.XLOOKUP($J42,$B:$B,$C:$C)="CELC",R42,'ENE TECH'!O38) -> 0 | T42: =IF(_xlfn.XLOOKUP($J42,$B:$B,$C:$C)="CELC",S42,'ENE TECH'!P38) -> 0 | ... AG42: =IF(_xlfn.XLOOKUP($J42,$B:$B,$C:$C)="CELC",AF42,'ENE TECH'!AC38) -> 0
B43: =Def_Tech!D54 -> TRALPG19 | C43: =IF(OR(RIGHT(D43,LEN(D43)-3)="ELC",RIGHT(D43,LEN(D43)-3)="H2G"),"C"&RIGHT(D43,LEN(D43)-3),RIGHT(D43,LEN(D43)-3)) -> LPG | D43: =Def_Comm!C41 -> TRALPG | E43: Input | F43: 1 | J43: =B43 -> TRALPG19 | K43: =IF(_xlfn.XLOOKUP($J43,$B:$B,$C:$C)="CELC",1,"") | L43: =IF(_xlfn.XLOOKUP($J43,$B:$B,$C:$C)="CELC",'ENE TECH'!H39-5,'ENE TECH'!H39) -> 16.470223 | M43: =IF(_xlfn.XLOOKUP($J43,$B:$B,$C:$C)="CELC",L43,'ENE TECH'!I39) -> 15.026982 | N43: =IF(_xlfn.XLOOKUP($J43,$B:$B,$C:$C)="CELC",M43,'ENE TECH'!J39) -> 22.646279 | O43: =IF(_xlfn.XLOOKUP($J43,$B:$B,$C:$C)="CELC",N43,'ENE TECH'!K39) -> 24.458616 | P43: =IF(_xlfn.XLOOKUP($J43,$B:$B,$C:$C)="CELC",O43,'ENE TECH'!L39) -> 22.342301 | Q43: =IF(_xlfn.XLOOKUP($J43,$B:$B,$C:$C)="CELC",P43,'ENE TECH'!M39) -> 20.794551 | R43: =IF(_xlfn.XLOOKUP($J43,$B:$B,$C:$C)="CELC",Q43,'ENE TECH'!N39) -> 19.365335 | S43: =IF(_xlfn.XLOOKUP($J43,$B:$B,$C:$C)="CELC",R43,'ENE TECH'!O39) -> 19.716729 | T43: =IF(_xlfn.XLOOKUP($J43,$B:$B,$C:$C)="CELC",S43,'ENE TECH'!P39) -> 22.748775 | ... AG43: =IF(_xlfn.XLOOKUP($J43,$B:$B,$C:$C)="CELC",AF43,'ENE TECH'!AC39) -> 28.480687
B44: =Def_Tech!D55 -> TRAETH19 | C44: =IF(OR(RIGHT(D44,LEN(D44)-3)="ELC",RIGHT(D44,LEN(D44)-3)="H2G"),"C"&RIGHT(D44,LEN(D44)-3),RIGHT(D44,LEN(D44)-3)) -> ETH | D44: =Def_Comm!C42 -> TRAETH | E44: Input | F44: 1 | J44: =B44 -> TRAETH19 | K44: =IF(_xlfn.XLOOKUP($J44,$B:$B,$C:$C)="CELC",1,"") | L44: =IF(_xlfn.XLOOKUP($J44,$B:$B,$C:$C)="CELC",'ENE TECH'!H40-5,'ENE TECH'!H40) -> 27.79723 | M44: =IF(_xlfn.XLOOKUP($J44,$B:$B,$C:$C)="CELC",L44,'ENE TECH'!I40) -> 23.253305 | N44: =IF(_xlfn.XLOOKUP($J44,$B:$B,$C:$C)="CELC",M44,'ENE TECH'!J40) -> 30.699481 | O44: =IF(_xlfn.XLOOKUP($J44,$B:$B,$C:$C)="CELC",N44,'ENE TECH'!K40) -> 33.156299 | P44: =IF(_xlfn.XLOOKUP($J44,$B:$B,$C:$C)="CELC",O44,'ENE TECH'!L40) -> 28.73724 | Q44: =IF(_xlfn.XLOOKUP($J44,$B:$B,$C:$C)="CELC",P44,'ENE TECH'!M40) -> 27.204245 | R44: =IF(_xlfn.XLOOKUP($J44,$B:$B,$C:$C)="CELC",Q44,'ENE TECH'!N40) -> 25.274519 | S44: =IF(_xlfn.XLOOKUP($J44,$B:$B,$C:$C)="CELC",R44,'ENE TECH'!O40) -> 26.267091 | T44: =IF(_xlfn.XLOOKUP($J44,$B:$B,$C:$C)="CELC",S44,'ENE TECH'!P40) -> 28.182933 | ... AG44: =IF(_xlfn.XLOOKUP($J44,$B:$B,$C:$C)="CELC",AF44,'ENE TECH'!AC40) -> 34.480395
