Workbook

Sheet ReadMe
A1: Generic Comet (GC) TIMES Supply
B3: Sheet color
C4: Raw Data and Parameters
C6: City Specific Data
C8: Post processing for TIMES
C10: Table formatted for TIMES

Sheet >> City Data

Sheet City characteristics
B2: City Basic Data
B4: Calibration methodology | C4: GHG Inventory
B6: A. City Characteristics
B7: Data Item | C7: Value | D7: Units
B8: City Name | C8: New York
B9: Latitude | C9: 40.5
B10: Longitude | C10: -75
B11: County | C11: New York County
B12: State | C12: New York
B13: Census Division | C13: Middle Atlantic
B14: Climate Division | C14: Northeast
B15: Egrid Region | C15: NPCC NYC/Westchester
B16: Area of city (excluding water, natural and agricultural areas) | C16: 778 | D16: square kilometers
B17: * Division and Region Map can be found in the Maps sheet.
B18: B. Planning Base Year and Target Years
B19: Year | C19: Value | D19: Units
B20: Base Year | C20: 2019 | D20: Acceptable range [2018,2021]
B21: End Year | C21: 2050
B23: C. City Population and GDP
B24: Data Item | C24: Value | D24: Units
B25: Population in Base Year | C25: 8337 | D25: Thousand of people
B26: Annual population growth (Base Year - End Year) | C26: 0.5 | D26: % people
B27: GDP in Base Year | C27: 1206000 | D27: Million US$
B28: Annual GDP growth rate | C28: 2 | D28: % US$
B29: Share of manufacturing GDP | C29: 5 | D29: % US$
B30: Share of State population | C30: 0.42835123
B31: Share of State GDP | C31: 0.67251772
B32: Adjustment from state manufacturing GDP | C32: 1.0638298
B34: D. Climate Data
B35: Data Item | C35: 2000 | D35: 2050 | E35: 2100 | F35: Units
B36: Heating degree days (HDD) | C36: 4473.4625 | D36: 4066.4182 | E36: 3763.8582 | F36: F
B37: Cooling degree days (CDD) | C37: 1020.7333 | D37: 1224.2555 | E37: 1375.5355 | F37: F
B39: Data Item | C39: Value | D39: Units
B40: Correction from State HDD | C40: 0.72727402
B41: Correction from State CDD | C41: 1.5583715
B42: Annual precipitation | C42: 762 | D42: mm / year
B43: Climate change scenario | C43: RCP4.5
B44: Average temperature increase in 1980-2020 | C44: 1.4617857 | D44: F
B45: Forecasted average temperature increase in 2035-2065 | C45: 3.13 | D45: F
B46: Forecasted average temperature increase in 2070-2100 | C46: 4.37 | D46: F
...

Sheet >> GC_Resid

Sheet TRA RESID
A1: Sector | B1: Sub-sector | C1: Archetype | D1: Vintage | E1: End Use | F1: Technology | G1: Energy | H1: Input Label | I1: Output Label | J1: Technology Label | K1: Main fuel | L1: MODE DEMAND (MVkm) | M1: Demand SHARE (%) | N1: Minimum fuel share (%) | O1: Maximum fuel share (%) | P1: DEMAND (MVkm) | Q1: FINAL ENERGY (GJ) | R1: RESID (Mvkma) | S1: EFF (Vkm/MJ) | T1: Residual life (Yr) | U1: Fixed O&M (Thousands $/Mvkm/yr) | V1: Variable O&M (Thousands $/Mvkm) | W1: CFA | X1: C2A
A2: Transportation | B2: Passenger | C2: Passenger Car | F2: Gasoline ICE Vehicle (spark ignition) | G2: Gasoline | H2: TRAGSL | I2: TRAPASCARDMD | J2: TRAPASCARICEVGSL19 | K2: 1 | L2: 68921.251 | M2: 0.97948822 | N2: 0.9 | O2: 1 | P2: 67507.553 | Q2: 205180.58 | R2: 67507.553 | S2: 0.32901532 | T2: 12 | U2: 6.472949 | W2: 1 | X2: 1
A3: Transportation | B3: Passenger | C3: Passenger Car | F3: Gasoline ICE Vehicle (spark ignition) | G3: Ethanol | H3: TRAETH | I3: TRAPASCARDMD | J3: TRAPASCARICEVGSL19 | K3: 0 | L3: 68921.251 | M3: 0 | N3: 0 | O3: 0.1 | P3: 0 | Q3: 0 | R3: 0 | S3: 0.32901532 | T3: 12 | U3: 6.472949 | W3: 1 | X3: 1
A4: Transportation | B4: Passenger | C4: Passenger Car | F4: Diesel Conventional Compression Ignition Vehicle | G4: Diesel | H4: TRADSL | I4: TRAPASCARDMD | J4: TRAPASCARICEVDSL19 | K4: 1 | L4: 68921.251 | M4: 0.011074786 | N4: 0 | O4: 1 | P4: 763.2881 | Q4: 2284.357 | R4: 763.2881 | S4: 0.33413696 | T4: 12 | U4: 6.472949 | W4: 1 | X4: 1
A5: Transportation | B5: Passenger | C5: Passenger Car | F5: Diesel Conventional Compression Ignition Vehicle | G5: Renewable diesel | H5: TRARDS | I5: TRAPASCARDMD | J5: TRAPASCARICEVDSL19 | K5: 0 | L5: 68921.251 | M5: 0 | N5: 0 | O5: 1 | P5: 0 | Q5: 0 | R5: 0 | S5: 0.33413696 | T5: 12 | U5: 6.472949 | W5: 1 | X5: 1
A6: Transportation | B6: Passenger | C6: Passenger Car | F6: Diesel Conventional Compression Ignition Vehicle | G6: Bio diesel | H6: TRABDS | I6: TRAPASCARDMD | J6: TRAPASCARICEVDSL19 | K6: 0 | L6: 68921.251 | M6: 0 | N6: 0 | O6: 0.1 | P6: 0 | Q6: 0 | R6: 0 | S6: 0.33413696 | T6: 12 | U6: 6.472949 | W6: 1 | X6: 1
A7: Transportation | B7: Passenger | C7: Passenger Car | F7: Compressed Natural Gas Conventional Vehicle | G7: CNG | H7: TRACNG | I7: TRAPASCARDMD | J7: TRAPASCARICEVCNG19 | K7: 1 | L7: 68921.251 | M7: 0 | N7: 0 | O7: 1 | P7: 0 | Q7: 0 | R7: 0 | S7: 0.25976728 | T7: 12 | U7: 6.472949 | W7: 1 | X7: 1
A8: Transportation | B8: Passenger | C8: Passenger Car | F8: Compressed Natural Gas Conventional Vehicle | G8: RNG | H8: TRARNG | I8: TRAPASCARDMD | J8: TRAPASCARICEVCNG19 | K8: 0 | L8: 68921.251 | M8: 0 | N8: 0 | O8: 1 | P8: 0 | Q8: 0 | R8: 0 | S8: 0.25976728 | T8: 12 | U8: 6.472949 | W8: 1 | X8: 1
A9: Transportation | B9: Passenger | C9: Passenger Car | F9: Battery Electric Vehicle (300-mile range) | G9: Battery | H9: TRABAT | I9: TRAPASCARDMD | J9: TRAPASCAR300BEV19 | K9: 1 | L9: 68921.251 | M9: 0.0094369922 | N9: 1 | O9: 1 | P9: 650.4093 | Q9: 884.34672 | R9: 650.4093 | S9: 0.73546867 | T9: 12 | U9: 6.472949 | W9: 1 | X9: 1
A10: Transportation | B10: Passenger | C10: Passenger Car | F10: Hydrogen Fuel Cell Electric Vehicle (300-mile range) | G10: Hydrogen | H10: TRAH2G | I10: TRAPASCARDMD | J10: TRAPASCAR300FCEV19 | K10: 1 | L10: 68921.251 | M10: 0 | N10: 1 | O10: 1 | P10: 0 | Q10: 0 | R10: 0 | S10: 0.73546867 | T10: 12 | U10: 6.472949 | W10: 1 | X10: 1
A11: Transportation | B11: Passenger | C11: Passenger Truck | F11: Gasoline ICE Vehicle (spark ignition) | G11: Gasoline | H11: TRAGSL | I11: TRAPASLDTDMD | J11: TRAPASLDTICEVGSL19 | K11: 1 | L11: 0 | M11: 0 | N11: 0.9 | O11: 1 | P11: 0 | Q11: 0 | R11: 0 | S11: 0.24925979 | T11: 13 | U11: 5.8122532 | W11: 1 | X11: 1
A12: Transportation | B12: Passenger | C12: Passenger Truck | F12: Gasoline ICE Vehicle (spark ignition) | G12: Ethanol | H12: TRAETH | I12: TRAPASLDTDMD | J12: TRAPASLDTICEVGSL19 | K12: 0 | L12: 0 | M12: 0 | N12: 0 | O12: 0.1 | P12: 0 | Q12: 0 | R12: 0 | S12: 0.24925979 | T12: 13 | U12: 5.8122532 | W12: 1 | X12: 1
A13: Transportation | B13: Passenger | C13: Passenger Truck | F13: Diesel Conventional Compression Ignition Vehicle | G13: Diesel | H13: TRADSL | I13: TRAPASLDTDMD | J13: TRAPASLDTICEVDSL19 | K13: 1 | L13: 0 | M13: 0 | N13: 0 | O13: 1 | P13: 0 | Q13: 0 | R13: 0 | S13: 0.19756987 | T13: 13 | U13: 5.8122532 | W13: 1 | X13: 1
... A123: Transportation | B123: Passenger | C123: Subway | F123: Electric Propulsion Vehicle | G123: Electricity | H123: TRAELC | I123: TRAPASSUBDMD | J123: TRAPASSUBPROELC19 | K123: 1 | L123: 0 | M123: 0 | N123: 1 | O123: 1 | P123: 0 | Q123: 0 | R123: 0 | S123: 0.080703906 | T123: 30 | U123: 158.59239 | W123: 1 | X123: 1
A124: Transportation | B124: Passenger | C124: Bicycle | F124: N/a | G124: N/a | I124: TRAPASBICDMD | J124: TRAPASBIC19 | K124: 1 | L124: 783.71641 | M124: 1 | N124: 0 | O124: 0 | P124: 783.71641 | Q124: 0 | R124: 783.71641 | S124: 1 | T124: 50 | U124: 0 | W124: 1 | X124: 1
A125: Transportation | B125: Passenger | C125: Walk | F125: N/a | G125: N/a | I125: TRAPASWALDMD | J125: TRAPASWAL19 | K125: 1 | L125: 4185.0617 | M125: 1 | N125: 0 | O125: 0 | P125: 4185.0617 | Q125: 0 | R125: 4185.0617 | S125: 1 | T125: 100 | U125: 0 | W125: 1 | X125: 1
A126: Transportation | B126: Other | C126: Off-Road | F126: Gasoline ICE Vehicle | G126: Gasoline | H126: TRAGSL | I126: TRAOTHOFRDMD | J126: TRAOTHOFRICEVGSL19 | K126: 1 | L126: 0 | M126: 0 | N126: 0.9 | O126: 1 | P126: 0 | Q126: 0 | R126: 0 | S126: 0.10837963 | T126: 8 | U126: 10.491572 | W126: 1 | X126: 1
A127: Transportation | B127: Other | C127: Off-Road | F127: Gasoline ICE Vehicle | G127: Ethanol | H127: TRAETH | I127: TRAOTHOFRDMD | J127: TRAOTHOFRICEVGSL19 | K127: 0 | L127: 0 | M127: 0 | N127: 0 | O127: 0.1 | P127: 0 | Q127: 0 | R127: 0 | S127: 0.10837963 | T127: 8 | U127: 10.491572 | W127: 1 | X127: 1
A128: Transportation | B128: Other | C128: Off-Road | F128: Diesel ICE Vehicle | G128: Diesel | H128: TRADSL | I128: TRAOTHOFRDMD | J128: TRAOTHOFRICEVDSL19 | K128: 1 | L128: 0 | M128: 0 | N128: 0 | O128: 1 | P128: 0 | Q128: 0 | R128: 0 | S128: 0.1046149 | T128: 8 | U128: 10.491572 | W128: 1 | X128: 1
A129: Transportation | B129: Other | C129: Off-Road | F129: Diesel ICE Vehicle | G129: Renewable diesel | H129: TRARDS | I129: TRAOTHOFRDMD | J129: TRAOTHOFRICEVDSL19 | K129: 0 | L129: 0 | M129: 0 | N129: 0 | O129: 1 | P129: 0 | Q129: 0 | R129: 0 | S129: 0.1046149 | T129: 8 | U129: 10.491572 | W129: 1 | X129: 1
A130: Transportation | B130: Other | C130: Off-Road | F130: Diesel ICE Vehicle | G130: Bio diesel | H130: TRABDS | I130: TRAOTHOFRDMD | J130: TRAOTHOFRICEVDSL19 | K130: 0 | L130: 0 | M130: 0 | N130: 0 | O130: 0.1 | P130: 0 | Q130: 0 | R130: 0 | S130: 0.1046149 | T130: 8 | U130: 10.491572 | W130: 1 | X130: 1
A131: Transportation | B131: Other | C131: Off-Road | F131: Compressed Natural Gas Conventional Vehicle | G131: CNG | H131: TRACNG | I131: TRAOTHOFRDMD | J131: TRAOTHOFRICEVCNG19 | K131: 1 | L131: 0 | M131: 0 | N131: 0 | O131: 1 | P131: 0 | Q131: 0 | R131: 0 | S131: 0.10837963 | T131: 8 | U131: 10.491572 | W131: 1 | X131: 1
A132: Transportation | B132: Other | C132: Off-Road | F132: Compressed Natural Gas Conventional Vehicle | G132: RNG | H132: TRARNG | I132: TRAOTHOFRDMD | J132: TRAOTHOFRICEVCNG19 | K132: 0 | L132: 0 | M132: 0 | N132: 0 | O132: 1 | P132: 0 | Q132: 0 | R132: 0 | S132: 0.10837963 | T132: 8 | U132: 10.491572 | W132: 1 | X132: 1
A133: Transportation | B133: Other | C133: Off-Road | F133: Battery Electric Vehicle | G133: Battery Freight | H133: TRABAF | I133: TRAOTHOFRDMD | J133: TRAOTHOFRBEV19 | K133: 1 | L133: 0 | M133: 0 | N133: 1 | O133: 1 | P133: 0 | Q133: 0 | R133: 0 | S133: 0.21465702 | T133: 8 | U133: 10.491572 | W133: 1 | X133: 1
A134: Transportation | B134: Other | C134: Off-Road | F134: Hydrogen Fuel Cell Electric Vehicle | G134: Hydrogen | H134: TRAH2G | I134: TRAOTHOFRDMD | J134: TRAOTHOFRFCEV19 | K134: 1 | L134: 0 | M134: 0 | N134: 1 | O134: 1 | P134: 0 | Q134: 0 | R134: 0 | S134: 0.21465702 | T134: 8 | U134: 10.491572 | W134: 1 | X134: 1
A135: Transportation | B135: Other | C135: Waterborne | F135: Gasoline ICE Vehicle | G135: Gasoline | H135: TRAGSL | I135: TRAOTHWATDMD | J135: TRAOTHWATICEVGSL19 | K135: 1 | L135: 1.6054304 | M135: 0 | N135: 0.9 | O135: 1 | P135: 0 | Q135: 0 | R135: 0 | S135: 0.0012937722 | T135: 30 | U135: 6522.2354 | W135: 1 | X135: 1
A136: Transportation | B136: Other | C136: Waterborne | F136: Gasoline ICE Vehicle | G136: Ethanol | H136: TRAETH | I136: TRAOTHWATDMD | J136: TRAOTHWATICEVGSL19 | K136: 0 | L136: 1.6054304 | M136: 0 | N136: 0 | O136: 0.1 | P136: 0 | Q136: 0 | R136: 0 | S136: 0.0012937722 | T136: 30 | U136: 6522.2354 | W136: 1 | X136: 1
A137: Transportation | B137: Other | C137: Waterborne | F137: Diesel ICE Vehicle | G137: Diesel | H137: TRADSL | I137: TRAOTHWATDMD | J137: TRAOTHWATICEVDSL19 | K137: 1 | L137: 1.6054304 | M137: 1 | N137: 0 | O137: 1 | P137: 1.6054304 | Q137: 1400.5379 | R137: 1.6054304 | S137: 0.0011462956 | T137: 30 | U137: 6522.2354 | W137: 1 | X137: 1
... A143: Transportation | B143: Other | C143: Aviation | F143: Turbo-reactor | G143: Sustainable aviation fuel | H143: TRASAF | I143: TRAOTHAIRDMD | J143: TRAOTHAIRTURREA19 | K143: 0 | L143: 0.12571557 | M143: 0 | N143: 0 | O143: 1 | P143: 0 | Q143: 0 | R143: 0 | S143: 0.0043975374 | T143: 24 | U143: 1249.4626 | W143: 1 | X143: 1

Sheet Demand
A1: Sector | B1: Sub-sector | C1: Archetype | D1: Vintage | E1: Demand Label | F1: Unit | G1: 2019 | H1: 2020 | I1: 2025 | J1: 2030 | K1: 2035 | L1: 2040 | M1: 2045 | N1: 2050 | O1: 2055 | P1: 2060 | Q1: 2065 | R1: 2070 | S1: 2075 | T1: 2080 | U1: 2085 | V1: 2090 | W1: 2095 | X1: 2100
A2: Commercial | B2: Hotel | D2: Old | E2: COMHOTOldDMD | F2: Mm2 | G2: 11.978701 | H2: 11.978701 | I2: 11.978701 | J2: 11.978701 | K2: 11.978701 | L2: 11.978701 | M2: 11.978701 | N2: 11.978701 | O2: 11.978701 | P2: 11.978701 | Q2: 11.978701 | R2: 11.978701 | S2: 11.978701 | T2: 11.978701 | U2: 11.978701 | V2: 11.978701 | W2: 11.978701 | X2: 11.978701
A3: Commercial | B3: Retail | D3: Old | E3: COMRETOldDMD | F3: Mm2 | G3: 23.081056 | H3: 23.081056 | I3: 23.081056 | J3: 23.081056 | K3: 23.081056 | L3: 23.081056 | M3: 23.081056 | N3: 23.081056 | O3: 23.081056 | P3: 23.081056 | Q3: 23.081056 | R3: 23.081056 | S3: 23.081056 | T3: 23.081056 | U3: 23.081056 | V3: 23.081056 | W3: 23.081056 | X3: 23.081056
A4: Commercial | B4: Office | D4: Old | E4: COMOFFOldDMD | F4: Mm2 | G4: 73.164819 | H4: 73.164819 | I4: 73.164819 | J4: 73.164819 | K4: 73.164819 | L4: 73.164819 | M4: 73.164819 | N4: 73.164819 | O4: 73.164819 | P4: 73.164819 | Q4: 73.164819 | R4: 73.164819 | S4: 73.164819 | T4: 73.164819 | U4: 73.164819 | V4: 73.164819 | W4: 73.164819 | X4: 73.164819
A5: Commercial | B5: Hospital | D5: Old | E5: COMHOPOldDMD | F5: Mm2 | G5: 44.382259 | H5: 44.382259 | I5: 44.382259 | J5: 44.382259 | K5: 44.382259 | L5: 44.382259 | M5: 44.382259 | N5: 44.382259 | O5: 44.382259 | P5: 44.382259 | Q5: 44.382259 | R5: 44.382259 | S5: 44.382259 | T5: 44.382259 | U5: 44.382259 | V5: 44.382259 | W5: 44.382259 | X5: 44.382259
A6: Commercial | B6: Educationnal | D6: Old | E6: COMEDUOldDMD | F6: Mm2 | G6: 48.565496 | H6: 48.565496 | I6: 48.565496 | J6: 48.565496 | K6: 48.565496 | L6: 48.565496 | M6: 48.565496 | N6: 48.565496 | O6: 48.565496 | P6: 48.565496 | Q6: 48.565496 | R6: 48.565496 | S6: 48.565496 | T6: 48.565496 | U6: 48.565496 | V6: 48.565496 | W6: 48.565496 | X6: 48.565496
A7: Commercial | B7: Warehouse | D7: Old | E7: COMWAROldDMD | F7: Mm2 | G7: 32.733587 | H7: 32.733587 | I7: 32.733587 | J7: 32.733587 | K7: 32.733587 | L7: 32.733587 | M7: 32.733587 | N7: 32.733587 | O7: 32.733587 | P7: 32.733587 | Q7: 32.733587 | R7: 32.733587 | S7: 32.733587 | T7: 32.733587 | U7: 32.733587 | V7: 32.733587 | W7: 32.733587 | X7: 32.733587
A8: Commercial | B8: Municipal | D8: Old | E8: COMMUNOldDMD | F8: Mm2 | G8: 16.841333 | H8: 16.841333 | I8: 16.841333 | J8: 16.841333 | K8: 16.841333 | L8: 16.841333 | M8: 16.841333 | N8: 16.841333 | O8: 16.841333 | P8: 16.841333 | Q8: 16.841333 | R8: 16.841333 | S8: 16.841333 | T8: 16.841333 | U8: 16.841333 | V8: 16.841333 | W8: 16.841333 | X8: 16.841333
A9: Commercial | B9: Other | D9: Old | E9: COMOTHOldDMD | F9: Mm2 | G9: 8.7602804 | H9: 8.7602804 | I9: 8.7602804 | J9: 8.7602804 | K9: 8.7602804 | L9: 8.7602804 | M9: 8.7602804 | N9: 8.7602804 | O9: 8.7602804 | P9: 8.7602804 | Q9: 8.7602804 | R9: 8.7602804 | S9: 8.7602804 | T9: 8.7602804 | U9: 8.7602804 | V9: 8.7602804 | W9: 8.7602804 | X9: 8.7602804
A10: Commercial | B10: Hotel | D10: New | E10: COMHOTNewDMD | F10: Mm2 | G10: 0 | H10: 0.23957402 | I10: 1.4374441 | J10: 2.6353143 | K10: 3.8331844 | L10: 5.0310545 | M10: 6.2289246 | N10: 7.4267947 | O10: 8.6246649 | P10: 9.822535 | Q10: 11.020405 | R10: 12.218275 | S10: 13.416145 | T10: 14.614015 | U10: 15.811886 | V10: 17.009756 | W10: 18.207626 | X10: 19.405496
A11: Commercial | B11: Retail | D11: New | E11: COMRETNewDMD | F11: Mm2 | G11: 0 | H11: 0.46162113 | I11: 2.7697268 | J11: 5.0778324 | K11: 7.3859381 | L11: 9.6940437 | M11: 12.002149 | N11: 14.310255 | O11: 16.618361 | P11: 18.926466 | Q11: 21.234572 | R11: 23.542678 | S11: 25.850783 | T11: 28.158889 | U11: 30.466995 | V11: 32.7751 | W11: 35.083206 | X11: 37.391311
A12: Commercial | B12: Office | D12: New | E12: COMOFFNewDMD | F12: Mm2 | G12: 0 | H12: 1.4632964 | I12: 8.7797783 | J12: 16.09626 | K12: 23.412742 | L12: 30.729224 | M12: 38.045706 | N12: 45.362188 | O12: 52.67867 | P12: 59.995152 | Q12: 67.311633 | R12: 74.628115 | S12: 81.944597 | T12: 89.261079 | U12: 96.577561 | V12: 103.89404 | W12: 111.21052 | X12: 118.52701
A13: Commercial | B13: Hospital | D13: New | E13: COMHOPNewDMD | F13: Mm2 | G13: 0 | H13: 0.88764519 | I13: 5.3258711 | J13: 9.764097 | K13: 14.202323 | L13: 18.640549 | M13: 23.078775 | N13: 27.517001 | O13: 31.955227 | P13: 36.393453 | Q13: 40.831679 | R13: 45.269904 | S13: 49.70813 | T13: 54.146356 | U13: 58.584582 | V13: 63.022808 | W13: 67.461034 | X13: 71.89926
... A17: Commercial | B17: Other | D17: New | E17: COMOTHNewDMD | F17: Mm2 | G17: 0 | H17: 0.17520561 | I17: 1.0512337 | J17: 1.9272617 | K17: 2.8032897 | L17: 3.6793178 | M17: 4.5553458 | N17: 5.4313739 | O17: 6.3074019 | P17: 7.18343 | Q17: 8.059458 | R17: 8.9354861 | S17: 9.8115141 | T17: 10.687542 | U17: 11.56357 | V17: 12.439598 | W17: 13.315626 | X17: 14.191654
A18: Residential | B18: Apartment | C18: Low Income | D18: Old | E18: RESAPALOOldDMD | F18: Mm2 | G18: 51.807877 | H18: 51.807877 | I18: 51.807877 | J18: 51.807877 | K18: 51.807877 | L18: 51.807877 | M18: 51.807877 | N18: 51.807877 | O18: 51.807877 | P18: 51.807877 | Q18: 51.807877 | R18: 51.807877 | S18: 51.807877 | T18: 51.807877 | U18: 51.807877 | V18: 51.807877 | W18: 51.807877 | X18: 51.807877
A19: Residential | B19: House | C19: Low Income | D19: Old | E19: RESHOULOOldDMD | F19: Mm2 | G19: 14.956798 | H19: 14.956798 | I19: 14.956798 | J19: 14.956798 | K19: 14.956798 | L19: 14.956798 | M19: 14.956798 | N19: 14.956798 | O19: 14.956798 | P19: 14.956798 | Q19: 14.956798 | R19: 14.956798 | S19: 14.956798 | T19: 14.956798 | U19: 14.956798 | V19: 14.956798 | W19: 14.956798 | X19: 14.956798
A20: Residential | B20: Apartment | C20: Lower-Middle Income | D20: Old | E20: RESAPALMOldDMD | F20: Mm2 | G20: 57.121976 | H20: 57.121976 | I20: 57.121976 | J20: 57.121976 | K20: 57.121976 | L20: 57.121976 | M20: 57.121976 | N20: 57.121976 | O20: 57.121976 | P20: 57.121976 | Q20: 57.121976 | R20: 57.121976 | S20: 57.121976 | T20: 57.121976 | U20: 57.121976 | V20: 57.121976 | W20: 57.121976 | X20: 57.121976
A21: Residential | B21: House | C21: Lower-Middle Income | D21: Old | E21: RESHOULMOldDMD | F21: Mm2 | G21: 38.299259 | H21: 38.299259 | I21: 38.299259 | J21: 38.299259 | K21: 38.299259 | L21: 38.299259 | M21: 38.299259 | N21: 38.299259 | O21: 38.299259 | P21: 38.299259 | Q21: 38.299259 | R21: 38.299259 | S21: 38.299259 | T21: 38.299259 | U21: 38.299259 | V21: 38.299259 | W21: 38.299259 | X21: 38.299259
A22: Residential | B22: Apartment | C22: Upper-Middle Income | D22: Old | E22: RESAPAUMOldDMD | F22: Mm2 | G22: 15.495888 | H22: 15.495888 | I22: 15.495888 | J22: 15.495888 | K22: 15.495888 | L22: 15.495888 | M22: 15.495888 | N22: 15.495888 | O22: 15.495888 | P22: 15.495888 | Q22: 15.495888 | R22: 15.495888 | S22: 15.495888 | T22: 15.495888 | U22: 15.495888 | V22: 15.495888 | W22: 15.495888 | X22: 15.495888
A23: Residential | B23: House | C23: Upper-Middle Income | D23: Old | E23: RESHOUUMOldDMD | F23: Mm2 | G23: 19.187214 | H23: 19.187214 | I23: 19.187214 | J23: 19.187214 | K23: 19.187214 | L23: 19.187214 | M23: 19.187214 | N23: 19.187214 | O23: 19.187214 | P23: 19.187214 | Q23: 19.187214 | R23: 19.187214 | S23: 19.187214 | T23: 19.187214 | U23: 19.187214 | V23: 19.187214 | W23: 19.187214 | X23: 19.187214
A24: Residential | B24: Apartment | C24: High Income | D24: Old | E24: RESAPAHIOldDMD | F24: Mm2 | G24: 66.398717 | H24: 66.398717 | I24: 66.398717 | J24: 66.398717 | K24: 66.398717 | L24: 66.398717 | M24: 66.398717 | N24: 66.398717 | O24: 66.398717 | P24: 66.398717 | Q24: 66.398717 | R24: 66.398717 | S24: 66.398717 | T24: 66.398717 | U24: 66.398717 | V24: 66.398717 | W24: 66.398717 | X24: 66.398717
A25: Residential | B25: House | C25: High Income | D25: Old | E25: RESHOUHIOldDMD | F25: Mm2 | G25: 96.552051 | H25: 96.552051 | I25: 96.552051 | J25: 96.552051 | K25: 96.552051 | L25: 96.552051 | M25: 96.552051 | N25: 96.552051 | O25: 96.552051 | P25: 96.552051 | Q25: 96.552051 | R25: 96.552051 | S25: 96.552051 | T25: 96.552051 | U25: 96.552051 | V25: 96.552051 | W25: 96.552051 | X25: 96.552051
A26: Residential | B26: Apartment | C26: Low Income | D26: New | E26: RESAPALONewDMD | F26: Mm2 | G26: 0 | H26: 0.25903939 | I26: 1.5542363 | J26: 2.8494333 | K26: 4.1446302 | L26: 5.4398271 | M26: 6.7350241 | N26: 8.030221 | O26: 9.3254179 | P26: 10.620615 | Q26: 11.915812 | R26: 13.211009 | S26: 14.506206 | T26: 15.801403 | U26: 17.0966 | V26: 18.391797 | W26: 19.686993 | X26: 20.98219
A27: Residential | B27: House | C27: Low Income | D27: New | E27: RESHOULONewDMD | F27: Mm2 | G27: 0 | H27: 0.07478399 | I27: 0.44870394 | J27: 0.82262389 | K27: 1.1965438 | L27: 1.5704638 | M27: 1.9443837 | N27: 2.3183037 | O27: 2.6922236 | P27: 3.0661436 | Q27: 3.4400635 | R27: 3.8139835 | S27: 4.1879034 | T27: 4.5618234 | U27: 4.9357433 | V27: 5.3096633 | W27: 5.6835832 | X27: 6.0575032
A28: Residential | B28: Apartment | C28: Lower-Middle Income | D28: New | E28: RESAPALMNewDMD | F28: Mm2 | G28: 0 | H28: 0.28560988 | I28: 1.7136593 | J28: 3.1417087 | K28: 4.5697581 | L28: 5.9978075 | M28: 7.4258569 | N28: 8.8539063 | O28: 10.281956 | P28: 11.710005 | Q28: 13.138055 | R28: 14.566104 | S28: 15.994153 | T28: 17.422203 | U28: 18.850252 | V28: 20.278302 | W28: 21.706351 | X28: 23.1344
A29: Residential | B29: House | C29: Lower-Middle Income | D29: New | E29: RESHOULMNewDMD | F29: Mm2 | G29: 0 | H29: 0.19149629 | I29: 1.1489778 | J29: 2.1064592 | K29: 3.0639407 | L29: 4.0214222 | M29: 4.9789036 | N29: 5.9363851 | O29: 6.8938665 | P29: 7.851348 | Q29: 8.8088295 | R29: 9.7663109 | S29: 10.723792 | T29: 11.681274 | U29: 12.638755 | V29: 13.596237 | W29: 14.553718 | X29: 15.5112
... A33: Residential | B33: House | C33: High Income | D33: New | E33: RESHOUHINewDMD | F33: Mm2 | G33: 0 | H33: 0.48276025 | I33: 2.8965615 | J33: 5.3103628 | K33: 7.7241641 | L33: 10.137965 | M33: 12.551767 | N33: 14.965568 | O33: 17.379369 | P33: 19.79317 | Q33: 22.206972 | R33: 24.620773 | S33: 27.034574 | T33: 29.448376 | U33: 31.862177 | V33: 34.275978 | W33: 36.689779 | X33: 39.103581
A34: Industrial | B34: All Industries | E34: INDAINDMD | F34: TJ | G34: 66716.461 | H34: 68050.79 | I34: 74855.869 | J34: 82341.456 | K34: 90575.602 | L34: 99633.162 | M34: 109596.48 | N34: 120556.13 | O34: 132611.74 | P34: 145872.91 | Q34: 160460.2 | R34: 176506.22 | S34: 194156.85 | T34: 213572.53 | U34: 234929.78 | V34: 258422.76 | W34: 284265.04 | X34: 312691.54
A35: Transportation | B35: Passenger | C35: Passenger Car | E35: TRAPASCARDMD | F35: M Vkm | G35: 68921.251 | H35: 69265.857 | I35: 70997.504 | J35: 72772.441 | K35: 74591.752 | L35: 76456.546 | M35: 78367.96 | N35: 80327.159 | O35: 82335.338 | P35: 84393.721 | Q35: 86503.564 | R35: 88666.153 | S35: 90882.807 | T35: 93154.877 | U35: 95483.749 | V35: 97870.843 | W35: 100317.61 | X35: 102825.55
A36: Transportation | B36: Passenger | C36: Passenger Truck | E36: TRAPASLDTDMD | F36: M Vkm | G36: 0 | H36: 0 | I36: 0 | J36: 0 | K36: 0 | L36: 0 | M36: 0 | N36: 0 | O36: 0 | P36: 0 | Q36: 0 | R36: 0 | S36: 0 | T36: 0 | U36: 0 | V36: 0 | W36: 0 | X36: 0
A37: Transportation | B37: Passenger | C37: Motorcycle | E37: TRAPASMOTDMD | F37: M Vkm | G37: 0 | H37: 0 | I37: 0 | J37: 0 | K37: 0 | L37: 0 | M37: 0 | N37: 0 | O37: 0 | P37: 0 | Q37: 0 | R37: 0 | S37: 0 | T37: 0 | U37: 0 | V37: 0 | W37: 0 | X37: 0
A38: Transportation | B38: Freight | C38: Light Commercial Truck | E38: TRAFRECLTDMD | F38: M Vkm | G38: 1578.5179 | H38: 1586.4105 | I38: 1626.0707 | J38: 1666.7225 | K38: 1708.3906 | L38: 1751.1003 | M38: 1794.8778 | N38: 1839.7498 | O38: 1885.7435 | P38: 1932.8871 | Q38: 1981.2093 | R38: 2030.7395 | S38: 2081.508 | T38: 2133.5457 | U38: 2186.8844 | V38: 2241.5565 | W38: 2297.5954 | X38: 2355.0353
A39: Transportation | B39: Freight | C39: Refuse Truck | E39: TRAFRERFTDMD | F39: M Vkm | G39: 70.026308 | H39: 70.37644 | I39: 72.135851 | J39: 73.939247 | K39: 75.787728 | L39: 77.682421 | M39: 79.624482 | N39: 81.615094 | O39: 83.655471 | P39: 85.746858 | Q39: 87.89053 | R39: 90.087793 | S39: 92.339988 | T39: 94.648487 | U39: 97.0147 | V39: 99.440067 | W39: 101.92607 | X39: 104.47422
A40: Transportation | B40: Freight | C40: Single Unit Long-haul Truck | E40: TRAFRESLHDMD | F40: M Vkm | G40: 0 | H40: 0 | I40: 0 | J40: 0 | K40: 0 | L40: 0 | M40: 0 | N40: 0 | O40: 0 | P40: 0 | Q40: 0 | R40: 0 | S40: 0 | T40: 0 | U40: 0 | V40: 0 | W40: 0 | X40: 0
A41: Transportation | B41: Freight | C41: Single Unit Short-haul Truck | E41: TRAFRESSHDMD | F41: M Vkm | G41: 0 | H41: 0 | I41: 0 | J41: 0 | K41: 0 | L41: 0 | M41: 0 | N41: 0 | O41: 0 | P41: 0 | Q41: 0 | R41: 0 | S41: 0 | T41: 0 | U41: 0 | V41: 0 | W41: 0 | X41: 0
A42: Transportation | B42: Freight | C42: Combination Long-haul Truck | E42: TRAFRECLHDMD | F42: M Vkm | G42: 1367.6202 | H42: 1374.4583 | I42: 1408.8197 | J42: 1444.0402 | K42: 1480.1412 | L42: 1517.1447 | M42: 1555.0734 | N42: 1593.9502 | O42: 1633.7989 | P42: 1674.6439 | Q42: 1716.51 | R42: 1759.4228 | S42: 1803.4083 | T42: 1848.4935 | U42: 1894.7059 | V42: 1942.0735 | W42: 1990.6254 | X42: 2040.391
A43: Transportation | B43: Freight | C43: Combination Short-haul Truck | E43: TRAFRECSHDMD | F43: M Vkm | G43: 0 | H43: 0 | I43: 0 | J43: 0 | K43: 0 | L43: 0 | M43: 0 | N43: 0 | O43: 0 | P43: 0 | Q43: 0 | R43: 0 | S43: 0 | T43: 0 | U43: 0 | V43: 0 | W43: 0 | X43: 0
A44: Transportation | B44: Passenger | C44: Transit Bus | E44: TRAPASTBUDMD | F44: M Vkm | G44: 498.20419 | H44: 500.69521 | I44: 513.21259 | J44: 526.0429 | K44: 539.19397 | L44: 552.67382 | M44: 566.49067 | N44: 580.65294 | O44: 595.16926 | P44: 610.04849 | Q44: 625.2997 | R44: 640.93219 | S44: 656.9555 | T44: 673.37939 | U44: 690.21387 | V44: 707.46922 | W44: 725.15595 | X44: 743.28485
A45: Transportation | B45: Passenger | C45: School Bus | E45: TRAPASSBUDMD | F45: M Vkm | G45: 86.053217 | H45: 86.483483 | I45: 88.645571 | J45: 90.86171 | K45: 93.133253 | L45: 95.461584 | M45: 97.848123 | N45: 100.29433 | O45: 102.80168 | P45: 105.37173 | Q45: 108.00602 | R45: 110.70617 | S45: 113.47382 | T45: 116.31067 | U45: 119.21844 | V45: 122.1989 | W45: 125.25387 | X45: 128.38522
A46: Transportation | B46: Passenger | C46: Other Buses | E46: TRAPASOBUDMD | F46: M Vkm | G46: 0 | H46: 0 | I46: 0 | J46: 0 | K46: 0 | L46: 0 | M46: 0 | N46: 0 | O46: 0 | P46: 0 | Q46: 0 | R46: 0 | S46: 0 | T46: 0 | U46: 0 | V46: 0 | W46: 0 | X46: 0
...

Sheet >> TIMES

Sheet Def_Tech
B2: ~FI_Process
B3: Sets | C3: Region | D3: TechName | E3: TechDesc | F3: Tact | G3: Tcap | H3: Tslvl | I3: PrimaryCG | J3: Vintage
B4: *Process Set Membership | C4: Region | D4: Technology Name | E4: Technology Description | F4: Activity Unit | G4: Capacity Unit | H4: TimeSlice level of Process Activity | I4: Primary Commodity Group | J4: Vintage Tracking
B5: =IF('TRA RESID'!K2=0,"*",IF(SUMIFS('TRA RESID'!R:R,'TRA RESID'!J:J,D5)=0,"*","PRE")) -> PRE | C5: CITY | D5: ='TRA RESID'!J2 -> TRAPASCARICEVGSL19 | E5: ='TRA RESID'!A2&" "&'TRA RESID'!B2&" "&'TRA RESID'!C2&" "&'TRA RESID'!F2 -> Transportation Passenger Passenger Car Gasoline ICE Vehicle (spark ignition) | F5: Mvkm | G5: =F5 -> Mvkm
B6: =IF('TRA RESID'!K3=0,"*",IF(SUMIFS('TRA RESID'!R:R,'TRA RESID'!J:J,D6)=0,"*","PRE")) -> * | C6: CITY | D6: ='TRA RESID'!J3 -> TRAPASCARICEVGSL19 | E6: ='TRA RESID'!A3&" "&'TRA RESID'!B3&" "&'TRA RESID'!C3&" "&'TRA RESID'!F3 -> Transportation Passenger Passenger Car Gasoline ICE Vehicle (spark ignition) | F6: Mvkm | G6: =F6 -> Mvkm
B7: =IF('TRA RESID'!K4=0,"*",IF(SUMIFS('TRA RESID'!R:R,'TRA RESID'!J:J,D7)=0,"*","PRE")) -> PRE | C7: CITY | D7: ='TRA RESID'!J4 -> TRAPASCARICEVDSL19 | E7: ='TRA RESID'!A4&" "&'TRA RESID'!B4&" "&'TRA RESID'!C4&" "&'TRA RESID'!F4 -> Transportation Passenger Passenger Car Diesel Conventional Compression Ignition Vehicle | F7: Mvkm | G7: =F7 -> Mvkm
B8: =IF('TRA RESID'!K5=0,"*",IF(SUMIFS('TRA RESID'!R:R,'TRA RESID'!J:J,D8)=0,"*","PRE")) -> * | C8: CITY | D8: ='TRA RESID'!J5 -> TRAPASCARICEVDSL19 | E8: ='TRA RESID'!A5&" "&'TRA RESID'!B5&" "&'TRA RESID'!C5&" "&'TRA RESID'!F5 -> Transportation Passenger Passenger Car Diesel Conventional Compression Ignition Vehicle | F8: Mvkm | G8: =F8 -> Mvkm
B9: =IF('TRA RESID'!K6=0,"*",IF(SUMIFS('TRA RESID'!R:R,'TRA RESID'!J:J,D9)=0,"*","PRE")) -> * | C9: CITY | D9: ='TRA RESID'!J6 -> TRAPASCARICEVDSL19 | E9: ='TRA RESID'!A6&" "&'TRA RESID'!B6&" "&'TRA RESID'!C6&" "&'TRA RESID'!F6 -> Transportation Passenger Passenger Car Diesel Conventional Compression Ignition Vehicle | F9: Mvkm | G9: =F9 -> Mvkm
B10: =IF('TRA RESID'!K7=0,"*",IF(SUMIFS('TRA RESID'!R:R,'TRA RESID'!J:J,D10)=0,"*","PRE")) -> * | C10: CITY | D10: ='TRA RESID'!J7 -> TRAPASCARICEVCNG19 | E10: ='TRA RESID'!A7&" "&'TRA RESID'!B7&" "&'TRA RESID'!C7&" "&'TRA RESID'!F7 -> Transportation Passenger Passenger Car Compressed Natural Gas Conventional Vehicle | F10: Mvkm | G10: =F10 -> Mvkm
B11: =IF('TRA RESID'!K8=0,"*",IF(SUMIFS('TRA RESID'!R:R,'TRA RESID'!J:J,D11)=0,"*","PRE")) -> * | C11: CITY | D11: ='TRA RESID'!J8 -> TRAPASCARICEVCNG19 | E11: ='TRA RESID'!A8&" "&'TRA RESID'!B8&" "&'TRA RESID'!C8&" "&'TRA RESID'!F8 -> Transportation Passenger Passenger Car Compressed Natural Gas Conventional Vehicle | F11: Mvkm | G11: =F11 -> Mvkm
B12: =IF('TRA RESID'!K9=0,"*",IF(SUMIFS('TRA RESID'!R:R,'TRA RESID'!J:J,D12)=0,"*","PRE")) -> PRE | C12: CITY | D12: ='TRA RESID'!J9 -> TRAPASCAR300BEV19 | E12: ='TRA RESID'!A9&" "&'TRA RESID'!B9&" "&'TRA RESID'!C9&" "&'TRA RESID'!F9 -> Transportation Passenger Passenger Car Battery Electric Vehicle (300-mile range) | F12: Mvkm | G12: =F12 -> Mvkm
B13: =IF('TRA RESID'!K10=0,"*",IF(SUMIFS('TRA RESID'!R:R,'TRA RESID'!J:J,D13)=0,"*","PRE")) -> * | C13: CITY | D13: ='TRA RESID'!J10 -> TRAPASCAR300FCEV19 | E13: ='TRA RESID'!A10&" "&'TRA RESID'!B10&" "&'TRA RESID'!C10&" "&'TRA RESID'!F10 -> Transportation Passenger Passenger Car Hydrogen Fuel Cell Electric Vehicle (300-mile range) | F13: Mvkm | G13: =F13 -> Mvkm
B14: =IF('TRA RESID'!K11=0,"*",IF(SUMIFS('TRA RESID'!R:R,'TRA RESID'!J:J,D14)=0,"*","PRE")) -> * | C14: CITY | D14: ='TRA RESID'!J11 -> TRAPASLDTICEVGSL19 | E14: ='TRA RESID'!A11&" "&'TRA RESID'!B11&" "&'TRA RESID'!C11&" "&'TRA RESID'!F11 -> Transportation Passenger Passenger Truck Gasoline ICE Vehicle (spark ignition) | F14: Mvkm | G14: =F14 -> Mvkm
B15: =IF('TRA RESID'!K12=0,"*",IF(SUMIFS('TRA RESID'!R:R,'TRA RESID'!J:J,D15)=0,"*","PRE")) -> * | C15: CITY | D15: ='TRA RESID'!J12 -> TRAPASLDTICEVGSL19 | E15: ='TRA RESID'!A12&" "&'TRA RESID'!B12&" "&'TRA RESID'!C12&" "&'TRA RESID'!F12 -> Transportation Passenger Passenger Truck Gasoline ICE Vehicle (spark ignition) | F15: Mvkm | G15: =F15 -> Mvkm
B16: =IF('TRA RESID'!K13=0,"*",IF(SUMIFS('TRA RESID'!R:R,'TRA RESID'!J:J,D16)=0,"*","PRE")) -> * | C16: CITY | D16: ='TRA RESID'!J13 -> TRAPASLDTICEVDSL19 | E16: ='TRA RESID'!A13&" "&'TRA RESID'!B13&" "&'TRA RESID'!C13&" "&'TRA RESID'!F13 -> Transportation Passenger Passenger Truck Diesel Conventional Compression Ignition Vehicle | F16: Mvkm | G16: =F16 -> Mvkm
... B146: =IF('TRA RESID'!K143=0,"*",IF(SUMIFS('TRA RESID'!R:R,'TRA RESID'!J:J,D146)=0,"*","PRE")) -> * | C146: CITY | D146: ='TRA RESID'!J143 -> TRAOTHAIRTURREA19 | E146: ='TRA RESID'!A143&" "&'TRA RESID'!B143&" "&'TRA RESID'!C143&" "&'TRA RESID'!F143 -> Transportation Other Aviation Turbo-reactor | F146: Mvkm | G146: =F146 -> Mvkm

Sheet Def_Comm
B2: ~FI_Comm
B3: Csets | C3: CommName | D3: CommDesc | E3: Unit | F3: LimType | G3: CTSLvl | H3: PeakTS | I3: Ctype
B4: *Commodity Set Membership | C4: Commodity Name | D4: Commodity Description | E4: Unit | F4: Sense of the Balance EQN. | G4: Timeslice Level | H4: Peak Monitoring | I4: Electricity Indicator
B5: DEM | C5: =Demand!E35 -> TRAPASCARDMD | D5: =Demand!A35&" "&Demand!B35&" "&Demand!C35&" "&Demand!D35&" "&"demand" -> Transportation Passenger Passenger Car demand | E5: Mvkm
B6: DEM | C6: =Demand!E36 -> TRAPASLDTDMD | D6: =Demand!A36&" "&Demand!B36&" "&Demand!C36&" "&Demand!D36&" "&"demand" -> Transportation Passenger Passenger Truck demand | E6: Mvkm
B7: DEM | C7: =Demand!E37 -> TRAPASMOTDMD | D7: =Demand!A37&" "&Demand!B37&" "&Demand!C37&" "&Demand!D37&" "&"demand" -> Transportation Passenger Motorcycle demand | E7: Mvkm
B8: DEM | C8: =Demand!E38 -> TRAFRECLTDMD | D8: =Demand!A38&" "&Demand!B38&" "&Demand!C38&" "&Demand!D38&" "&"demand" -> Transportation Freight Light Commercial Truck demand | E8: Mvkm
B9: DEM | C9: =Demand!E39 -> TRAFRERFTDMD | D9: =Demand!A39&" "&Demand!B39&" "&Demand!C39&" "&Demand!D39&" "&"demand" -> Transportation Freight Refuse Truck demand | E9: Mvkm
B10: DEM | C10: =Demand!E40 -> TRAFRESLHDMD | D10: =Demand!A40&" "&Demand!B40&" "&Demand!C40&" "&Demand!D40&" "&"demand" -> Transportation Freight Single Unit Long-haul Truck demand | E10: Mvkm
B11: DEM | C11: =Demand!E41 -> TRAFRESSHDMD | D11: =Demand!A41&" "&Demand!B41&" "&Demand!C41&" "&Demand!D41&" "&"demand" -> Transportation Freight Single Unit Short-haul Truck demand | E11: Mvkm
B12: DEM | C12: =Demand!E42 -> TRAFRECLHDMD | D12: =Demand!A42&" "&Demand!B42&" "&Demand!C42&" "&Demand!D42&" "&"demand" -> Transportation Freight Combination Long-haul Truck demand | E12: Mvkm
B13: DEM | C13: =Demand!E43 -> TRAFRECSHDMD | D13: =Demand!A43&" "&Demand!B43&" "&Demand!C43&" "&Demand!D43&" "&"demand" -> Transportation Freight Combination Short-haul Truck demand | E13: Mvkm
B14: DEM | C14: =Demand!E44 -> TRAPASTBUDMD | D14: =Demand!A44&" "&Demand!B44&" "&Demand!C44&" "&Demand!D44&" "&"demand" -> Transportation Passenger Transit Bus demand | E14: Mvkm
B15: DEM | C15: =Demand!E45 -> TRAPASSBUDMD | D15: =Demand!A45&" "&Demand!B45&" "&Demand!C45&" "&Demand!D45&" "&"demand" -> Transportation Passenger School Bus demand | E15: Mvkm
B16: DEM | C16: =Demand!E46 -> TRAPASOBUDMD | D16: =Demand!A46&" "&Demand!B46&" "&Demand!C46&" "&Demand!D46&" "&"demand" -> Transportation Passenger Other Buses demand | E16: Mvkm
... B24: DEM | C24: =Demand!E54 -> TRAOTHAIRDMD | D24: =Demand!A54&" "&Demand!B54&" "&Demand!C54&" "&Demand!D54&" "&"demand" -> Transportation Other Aviation demand | E24: Mvkm
B25: NRG | C25: ='TRA RESID'!H9 -> TRABAT | D25: Transportation Battery | E25: TJ
B26: NRG | C26: ='TRA RESID'!H45 -> TRABAF | D26: Transportation Battery Freight | E26: TJ

Sheet ResidTRA
V1: ='City characteristics'!C20 -> 2019 | W1: 0.98
V2: PRC_RESID
C4: ~FI_T | I4: ~FI_T | P4: ~FI_T
B5: TechName | C5: Comm-IN | D5: Attribute | E5: CITY | H5: TechName | I5: Comm-IN | J5: Attribute | K5: CITY | N5: Region | O5: TechName | P5: Comm-OUT | Q5: EFF | R5: PRC_CAPACT | S5: NCAP_AFA~UP | T5: NCAP_TLIFE | U5: NCAP_FOM | V5: =V2&"~"&V1 -> PRC_RESID~2019 | W5: NCAP_AFA~LO
B6: * | H6: * | N6: * | O6: * | Q6: Out/In | R6: TJ/MW | S6: % | T6: Yr | U6: $ / KW /Yr | V6: Mvkm | W6: %
B7: =IF(C7="","*",IF(SUMIFS('TRA RESID'!R:R,'TRA RESID'!J:J,'TRA RESID'!J2)=0,"*",'TRA RESID'!J2)) -> TRAPASCARICEVGSL19 | C7: =IF('TRA RESID'!H2="","",'TRA RESID'!H2) -> TRAGSL | D7: Share~UP | E7: =IF(B7="*",1,SUMIFS('TRA RESID'!O:O,'TRA RESID'!J:J,B7,'TRA RESID'!H:H,C7)) -> 1 | H7: =IF(I7="","*",IF(SUMIFS('TRA RESID'!R:R,'TRA RESID'!J:J,'TRA RESID'!J2)=0,"*",'TRA RESID'!J2)) -> TRAPASCARICEVGSL19 | I7: =IF('TRA RESID'!H2="","",'TRA RESID'!H2) -> TRAGSL | J7: ="Share~LO~"&'City characteristics'!$C$20 -> Share~LO~2019 | K7: =IF(B7="*",0,SUMIFS('TRA RESID'!N:N,'TRA RESID'!J:J,B7,'TRA RESID'!H:H,C7)) -> 0.9 | N7: =IF(Def_Tech!B5="*","*",Def_Tech!C5) -> CITY | O7: =Def_Tech!D5 -> TRAPASCARICEVGSL19 | P7: =_xlfn.XLOOKUP(O7,'TRA RESID'!J:J,'TRA RESID'!I:I) -> TRAPASCARDMD | Q7: =_xlfn.XLOOKUP(O7,'TRA RESID'!J:J,'TRA RESID'!S:S) -> 0.32901532 | R7: =_xlfn.XLOOKUP(O7,'TRA RESID'!J:J,'TRA RESID'!X:X) -> 1 | S7: =_xlfn.XLOOKUP(O7,'TRA RESID'!J:J,'TRA RESID'!W:W) -> 1 | T7: =_xlfn.XLOOKUP(O7,'TRA RESID'!J:J,'TRA RESID'!T:T) -> 12 | U7: =_xlfn.XLOOKUP(O7,'TRA RESID'!J:J,'TRA RESID'!U:U) -> 6.472949 | V7: =SUMIFS('TRA RESID'!R:R,'TRA RESID'!J:J,O7) -> 67507.553 | W7: =S7*W$1 -> 0.98
B8: =IF(C8="","*",IF(SUMIFS('TRA RESID'!R:R,'TRA RESID'!J:J,'TRA RESID'!J3)=0,"*",'TRA RESID'!J3)) -> TRAPASCARICEVGSL19 | C8: =IF('TRA RESID'!H3="","",'TRA RESID'!H3) -> TRAETH | D8: Share~UP | E8: =IF(B8="*",1,SUMIFS('TRA RESID'!O:O,'TRA RESID'!J:J,B8,'TRA RESID'!H:H,C8)) -> 0.1 | H8: =IF(I8="","*",IF(SUMIFS('TRA RESID'!R:R,'TRA RESID'!J:J,'TRA RESID'!J3)=0,"*",'TRA RESID'!J3)) -> TRAPASCARICEVGSL19 | I8: =IF('TRA RESID'!H3="","",'TRA RESID'!H3) -> TRAETH | J8: ="Share~LO~"&'City characteristics'!$C$20 -> Share~LO~2019 | K8: =IF(B8="*",0,SUMIFS('TRA RESID'!N:N,'TRA RESID'!J:J,B8,'TRA RESID'!H:H,C8)) -> 0 | N8: =IF(Def_Tech!B6="*","*",Def_Tech!C6) -> * | O8: =Def_Tech!D6 -> TRAPASCARICEVGSL19 | P8: =_xlfn.XLOOKUP(O8,'TRA RESID'!J:J,'TRA RESID'!I:I) -> TRAPASCARDMD | Q8: =_xlfn.XLOOKUP(O8,'TRA RESID'!J:J,'TRA RESID'!S:S) -> 0.32901532 | R8: =_xlfn.XLOOKUP(O8,'TRA RESID'!J:J,'TRA RESID'!X:X) -> 1 | S8: =_xlfn.XLOOKUP(O8,'TRA RESID'!J:J,'TRA RESID'!W:W) -> 1 | T8: =_xlfn.XLOOKUP(O8,'TRA RESID'!J:J,'TRA RESID'!T:T) -> 12 | U8: =_xlfn.XLOOKUP(O8,'TRA RESID'!J:J,'TRA RESID'!U:U) -> 6.472949 | V8: =SUMIFS('TRA RESID'!R:R,'TRA RESID'!J:J,O8) -> 67507.553 | W8: =S8*W$1 -> 0.98
B9: =IF(C9="","*",IF(SUMIFS('TRA RESID'!R:R,'TRA RESID'!J:J,'TRA RESID'!J4)=0,"*",'TRA RESID'!J4)) -> TRAPASCARICEVDSL19 | C9: =IF('TRA RESID'!H4="","",'TRA RESID'!H4) -> TRADSL | D9: Share~UP | E9: =IF(B9="*",1,SUMIFS('TRA RESID'!O:O,'TRA RESID'!J:J,B9,'TRA RESID'!H:H,C9)) -> 1 | H9: =IF(I9="","*",IF(SUMIFS('TRA RESID'!R:R,'TRA RESID'!J:J,'TRA RESID'!J4)=0,"*",'TRA RESID'!J4)) -> TRAPASCARICEVDSL19 | I9: =IF('TRA RESID'!H4="","",'TRA RESID'!H4) -> TRADSL | J9: ="Share~LO~"&'City characteristics'!$C$20 -> Share~LO~2019 | K9: =IF(B9="*",0,SUMIFS('TRA RESID'!N:N,'TRA RESID'!J:J,B9,'TRA RESID'!H:H,C9)) -> 0 | N9: =IF(Def_Tech!B7="*","*",Def_Tech!C7) -> CITY | O9: =Def_Tech!D7 -> TRAPASCARICEVDSL19 | P9: =_xlfn.XLOOKUP(O9,'TRA RESID'!J:J,'TRA RESID'!I:I) -> TRAPASCARDMD | Q9: =_xlfn.XLOOKUP(O9,'TRA RESID'!J:J,'TRA RESID'!S:S) -> 0.33413696 | R9: =_xlfn.XLOOKUP(O9,'TRA RESID'!J:J,'TRA RESID'!X:X) -> 1 | S9: =_xlfn.XLOOKUP(O9,'TRA RESID'!J:J,'TRA RESID'!W:W) -> 1 | T9: =_xlfn.XLOOKUP(O9,'TRA RESID'!J:J,'TRA RESID'!T:T) -> 12 | U9: =_xlfn.XLOOKUP(O9,'TRA RESID'!J:J,'TRA RESID'!U:U) -> 6.472949 | V9: =SUMIFS('TRA RESID'!R:R,'TRA RESID'!J:J,O9) -> 763.2881 | W9: =S9*W$1 -> 0.98
B10: =IF(C10="","*",IF(SUMIFS('TRA RESID'!R:R,'TRA RESID'!J:J,'TRA RESID'!J5)=0,"*",'TRA RESID'!J5)) -> TRAPASCARICEVDSL19 | C10: =IF('TRA RESID'!H5="","",'TRA RESID'!H5) -> TRARDS | D10: Share~UP | E10: =IF(B10="*",1,SUMIFS('TRA RESID'!O:O,'TRA RESID'!J:J,B10,'TRA RESID'!H:H,C10)) -> 1 | H10: =IF(I10="","*",IF(SUMIFS('TRA RESID'!R:R,'TRA RESID'!J:J,'TRA RESID'!J5)=0,"*",'TRA RESID'!J5)) -> TRAPASCARICEVDSL19 | I10: =IF('TRA RESID'!H5="","",'TRA RESID'!H5) -> TRARDS | J10: ="Share~LO~"&'City characteristics'!$C$20 -> Share~LO~2019 | K10: =IF(B10="*",0,SUMIFS('TRA RESID'!N:N,'TRA RESID'!J:J,B10,'TRA RESID'!H:H,C10)) -> 0 | N10: =IF(Def_Tech!B8="*","*",Def_Tech!C8) -> * | O10: =Def_Tech!D8 -> TRAPASCARICEVDSL19 | P10: =_xlfn.XLOOKUP(O10,'TRA RESID'!J:J,'TRA RESID'!I:I) -> TRAPASCARDMD | Q10: =_xlfn.XLOOKUP(O10,'TRA RESID'!J:J,'TRA RESID'!S:S) -> 0.33413696 | R10: =_xlfn.XLOOKUP(O10,'TRA RESID'!J:J,'TRA RESID'!X:X) -> 1 | S10: =_xlfn.XLOOKUP(O10,'TRA RESID'!J:J,'TRA RESID'!W:W) -> 1 | T10: =_xlfn.XLOOKUP(O10,'TRA RESID'!J:J,'TRA RESID'!T:T) -> 12 | U10: =_xlfn.XLOOKUP(O10,'TRA RESID'!J:J,'TRA RESID'!U:U) -> 6.472949 | V10: =SUMIFS('TRA RESID'!R:R,'TRA RESID'!J:J,O10) -> 763.2881 | W10: =S10*W$1 -> 0.98
B11: =IF(C11="","*",IF(SUMIFS('TRA RESID'!R:R,'TRA RESID'!J:J,'TRA RESID'!J6)=0,"*",'TRA RESID'!J6)) -> TRAPASCARICEVDSL19 | C11: =IF('TRA RESID'!H6="","",'TRA RESID'!H6) -> TRABDS | D11: Share~UP | E11: =IF(B11="*",1,SUMIFS('TRA RESID'!O:O,'TRA RESID'!J:J,B11,'TRA RESID'!H:H,C11)) -> 0.1 | H11: =IF(I11="","*",IF(SUMIFS('TRA RESID'!R:R,'TRA RESID'!J:J,'TRA RESID'!J6)=0,"*",'TRA RESID'!J6)) -> TRAPASCARICEVDSL19 | I11: =IF('TRA RESID'!H6="","",'TRA RESID'!H6) -> TRABDS | J11: ="Share~LO~"&'City characteristics'!$C$20 -> Share~LO~2019 | K11: =IF(B11="*",0,SUMIFS('TRA RESID'!N:N,'TRA RESID'!J:J,B11,'TRA RESID'!H:H,C11)) -> 0 | N11: =IF(Def_Tech!B9="*","*",Def_Tech!C9) -> * | O11: =Def_Tech!D9 -> TRAPASCARICEVDSL19 | P11: =_xlfn.XLOOKUP(O11,'TRA RESID'!J:J,'TRA RESID'!I:I) -> TRAPASCARDMD | Q11: =_xlfn.XLOOKUP(O11,'TRA RESID'!J:J,'TRA RESID'!S:S) -> 0.33413696 | R11: =_xlfn.XLOOKUP(O11,'TRA RESID'!J:J,'TRA RESID'!X:X) -> 1 | S11: =_xlfn.XLOOKUP(O11,'TRA RESID'!J:J,'TRA RESID'!W:W) -> 1 | T11: =_xlfn.XLOOKUP(O11,'TRA RESID'!J:J,'TRA RESID'!T:T) -> 12 | U11: =_xlfn.XLOOKUP(O11,'TRA RESID'!J:J,'TRA RESID'!U:U) -> 6.472949 | V11: =SUMIFS('TRA RESID'!R:R,'TRA RESID'!J:J,O11) -> 763.2881 | W11: =S11*W$1 -> 0.98
B12: =IF(C12="","*",IF(SUMIFS('TRA RESID'!R:R,'TRA RESID'!J:J,'TRA RESID'!J7)=0,"*",'TRA RESID'!J7)) -> * | C12: =IF('TRA RESID'!H7="","",'TRA RESID'!H7) -> TRACNG | D12: Share~UP | E12: =IF(B12="*",1,SUMIFS('TRA RESID'!O:O,'TRA RESID'!J:J,B12,'TRA RESID'!H:H,C12)) -> 1 | H12: =IF(I12="","*",IF(SUMIFS('TRA RESID'!R:R,'TRA RESID'!J:J,'TRA RESID'!J7)=0,"*",'TRA RESID'!J7)) -> * | I12: =IF('TRA RESID'!H7="","",'TRA RESID'!H7) -> TRACNG | J12: ="Share~LO~"&'City characteristics'!$C$20 -> Share~LO~2019 | K12: =IF(B12="*",0,SUMIFS('TRA RESID'!N:N,'TRA RESID'!J:J,B12,'TRA RESID'!H:H,C12)) -> 0 | N12: =IF(Def_Tech!B10="*","*",Def_Tech!C10) -> * | O12: =Def_Tech!D10 -> TRAPASCARICEVCNG19 | P12: =_xlfn.XLOOKUP(O12,'TRA RESID'!J:J,'TRA RESID'!I:I) -> TRAPASCARDMD | Q12: =_xlfn.XLOOKUP(O12,'TRA RESID'!J:J,'TRA RESID'!S:S) -> 0.25976728 | R12: =_xlfn.XLOOKUP(O12,'TRA RESID'!J:J,'TRA RESID'!X:X) -> 1 | S12: =_xlfn.XLOOKUP(O12,'TRA RESID'!J:J,'TRA RESID'!W:W) -> 1 | T12: =_xlfn.XLOOKUP(O12,'TRA RESID'!J:J,'TRA RESID'!T:T) -> 12 | U12: =_xlfn.XLOOKUP(O12,'TRA RESID'!J:J,'TRA RESID'!U:U) -> 6.472949 | V12: =SUMIFS('TRA RESID'!R:R,'TRA RESID'!J:J,O12) -> 0 | W12: =S12*W$1 -> 0.98
B13: =IF(C13="","*",IF(SUMIFS('TRA RESID'!R:R,'TRA RESID'!J:J,'TRA RESID'!J8)=0,"*",'TRA RESID'!J8)) -> * | C13: =IF('TRA RESID'!H8="","",'TRA RESID'!H8) -> TRARNG | D13: Share~UP | E13: =IF(B13="*",1,SUMIFS('TRA RESID'!O:O,'TRA RESID'!J:J,B13,'TRA RESID'!H:H,C13)) -> 1 | H13: =IF(I13="","*",IF(SUMIFS('TRA RESID'!R:R,'TRA RESID'!J:J,'TRA RESID'!J8)=0,"*",'TRA RESID'!J8)) -> * | I13: =IF('TRA RESID'!H8="","",'TRA RESID'!H8) -> TRARNG | J13: ="Share~LO~"&'City characteristics'!$C$20 -> Share~LO~2019 | K13: =IF(B13="*",0,SUMIFS('TRA RESID'!N:N,'TRA RESID'!J:J,B13,'TRA RESID'!H:H,C13)) -> 0 | N13: =IF(Def_Tech!B11="*","*",Def_Tech!C11) -> * | O13: =Def_Tech!D11 -> TRAPASCARICEVCNG19 | P13: =_xlfn.XLOOKUP(O13,'TRA RESID'!J:J,'TRA RESID'!I:I) -> TRAPASCARDMD | Q13: =_xlfn.XLOOKUP(O13,'TRA RESID'!J:J,'TRA RESID'!S:S) -> 0.25976728 | R13: =_xlfn.XLOOKUP(O13,'TRA RESID'!J:J,'TRA RESID'!X:X) -> 1 | S13: =_xlfn.XLOOKUP(O13,'TRA RESID'!J:J,'TRA RESID'!W:W) -> 1 | T13: =_xlfn.XLOOKUP(O13,'TRA RESID'!J:J,'TRA RESID'!T:T) -> 12 | U13: =_xlfn.XLOOKUP(O13,'TRA RESID'!J:J,'TRA RESID'!U:U) -> 6.472949 | V13: =SUMIFS('TRA RESID'!R:R,'TRA RESID'!J:J,O13) -> 0 | W13: =S13*W$1 -> 0.98
B14: =IF(C14="","*",IF(SUMIFS('TRA RESID'!R:R,'TRA RESID'!J:J,'TRA RESID'!J9)=0,"*",'TRA RESID'!J9)) -> TRAPASCAR300BEV19 | C14: =IF('TRA RESID'!H9="","",'TRA RESID'!H9) -> TRABAT | D14: Share~UP | E14: =IF(B14="*",1,SUMIFS('TRA RESID'!O:O,'TRA RESID'!J:J,B14,'TRA RESID'!H:H,C14)) -> 1 | H14: =IF(I14="","*",IF(SUMIFS('TRA RESID'!R:R,'TRA RESID'!J:J,'TRA RESID'!J9)=0,"*",'TRA RESID'!J9)) -> TRAPASCAR300BEV19 | I14: =IF('TRA RESID'!H9="","",'TRA RESID'!H9) -> TRABAT | J14: ="Share~LO~"&'City characteristics'!$C$20 -> Share~LO~2019 | K14: =IF(B14="*",0,SUMIFS('TRA RESID'!N:N,'TRA RESID'!J:J,B14,'TRA RESID'!H:H,C14)) -> 1 | N14: =IF(Def_Tech!B12="*","*",Def_Tech!C12) -> CITY | O14: =Def_Tech!D12 -> TRAPASCAR300BEV19 | P14: =_xlfn.XLOOKUP(O14,'TRA RESID'!J:J,'TRA RESID'!I:I) -> TRAPASCARDMD | Q14: =_xlfn.XLOOKUP(O14,'TRA RESID'!J:J,'TRA RESID'!S:S) -> 0.73546867 | R14: =_xlfn.XLOOKUP(O14,'TRA RESID'!J:J,'TRA RESID'!X:X) -> 1 | S14: =_xlfn.XLOOKUP(O14,'TRA RESID'!J:J,'TRA RESID'!W:W) -> 1 | T14: =_xlfn.XLOOKUP(O14,'TRA RESID'!J:J,'TRA RESID'!T:T) -> 12 | U14: =_xlfn.XLOOKUP(O14,'TRA RESID'!J:J,'TRA RESID'!U:U) -> 6.472949 | V14: =SUMIFS('TRA RESID'!R:R,'TRA RESID'!J:J,O14) -> 650.4093 | W14: =S14*W$1 -> 0.98
B15: =IF(C15="","*",IF(SUMIFS('TRA RESID'!R:R,'TRA RESID'!J:J,'TRA RESID'!J10)=0,"*",'TRA RESID'!J10)) -> * | C15: =IF('TRA RESID'!H10="","",'TRA RESID'!H10) -> TRAH2G | D15: Share~UP | E15: =IF(B15="*",1,SUMIFS('TRA RESID'!O:O,'TRA RESID'!J:J,B15,'TRA RESID'!H:H,C15)) -> 1 | H15: =IF(I15="","*",IF(SUMIFS('TRA RESID'!R:R,'TRA RESID'!J:J,'TRA RESID'!J10)=0,"*",'TRA RESID'!J10)) -> * | I15: =IF('TRA RESID'!H10="","",'TRA RESID'!H10) -> TRAH2G | J15: ="Share~LO~"&'City characteristics'!$C$20 -> Share~LO~2019 | K15: =IF(B15="*",0,SUMIFS('TRA RESID'!N:N,'TRA RESID'!J:J,B15,'TRA RESID'!H:H,C15)) -> 0 | N15: =IF(Def_Tech!B13="*","*",Def_Tech!C13) -> * | O15: =Def_Tech!D13 -> TRAPASCAR300FCEV19 | P15: =_xlfn.XLOOKUP(O15,'TRA RESID'!J:J,'TRA RESID'!I:I) -> TRAPASCARDMD | Q15: =_xlfn.XLOOKUP(O15,'TRA RESID'!J:J,'TRA RESID'!S:S) -> 0.73546867 | R15: =_xlfn.XLOOKUP(O15,'TRA RESID'!J:J,'TRA RESID'!X:X) -> 1 | S15: =_xlfn.XLOOKUP(O15,'TRA RESID'!J:J,'TRA RESID'!W:W) -> 1 | T15: =_xlfn.XLOOKUP(O15,'TRA RESID'!J:J,'TRA RESID'!T:T) -> 12 | U15: =_xlfn.XLOOKUP(O15,'TRA RESID'!J:J,'TRA RESID'!U:U) -> 6.472949 | V15: =SUMIFS('TRA RESID'!R:R,'TRA RESID'!J:J,O15) -> 0 | W15: =S15*W$1 -> 0.98
B16: =IF(C16="","*",IF(SUMIFS('TRA RESID'!R:R,'TRA RESID'!J:J,'TRA RESID'!J11)=0,"*",'TRA RESID'!J11)) -> * | C16: =IF('TRA RESID'!H11="","",'TRA RESID'!H11) -> TRAGSL | D16: Share~UP | E16: =IF(B16="*",1,SUMIFS('TRA RESID'!O:O,'TRA RESID'!J:J,B16,'TRA RESID'!H:H,C16)) -> 1 | H16: =IF(I16="","*",IF(SUMIFS('TRA RESID'!R:R,'TRA RESID'!J:J,'TRA RESID'!J11)=0,"*",'TRA RESID'!J11)) -> * | I16: =IF('TRA RESID'!H11="","",'TRA RESID'!H11) -> TRAGSL | J16: ="Share~LO~"&'City characteristics'!$C$20 -> Share~LO~2019 | K16: =IF(B16="*",0,SUMIFS('TRA RESID'!N:N,'TRA RESID'!J:J,B16,'TRA RESID'!H:H,C16)) -> 0 | N16: =IF(Def_Tech!B14="*","*",Def_Tech!C14) -> * | O16: =Def_Tech!D14 -> TRAPASLDTICEVGSL19 | P16: =_xlfn.XLOOKUP(O16,'TRA RESID'!J:J,'TRA RESID'!I:I) -> TRAPASLDTDMD | Q16: =_xlfn.XLOOKUP(O16,'TRA RESID'!J:J,'TRA RESID'!S:S) -> 0.24925979 | R16: =_xlfn.XLOOKUP(O16,'TRA RESID'!J:J,'TRA RESID'!X:X) -> 1 | S16: =_xlfn.XLOOKUP(O16,'TRA RESID'!J:J,'TRA RESID'!W:W) -> 1 | T16: =_xlfn.XLOOKUP(O16,'TRA RESID'!J:J,'TRA RESID'!T:T) -> 13 | U16: =_xlfn.XLOOKUP(O16,'TRA RESID'!J:J,'TRA RESID'!U:U) -> 5.8122532 | V16: =SUMIFS('TRA RESID'!R:R,'TRA RESID'!J:J,O16) -> 0 | W16: =S16*W$1 -> 0.98
B17: =IF(C17="","*",IF(SUMIFS('TRA RESID'!R:R,'TRA RESID'!J:J,'TRA RESID'!J12)=0,"*",'TRA RESID'!J12)) -> * | C17: =IF('TRA RESID'!H12="","",'TRA RESID'!H12) -> TRAETH | D17: Share~UP | E17: =IF(B17="*",1,SUMIFS('TRA RESID'!O:O,'TRA RESID'!J:J,B17,'TRA RESID'!H:H,C17)) -> 1 | H17: =IF(I17="","*",IF(SUMIFS('TRA RESID'!R:R,'TRA RESID'!J:J,'TRA RESID'!J12)=0,"*",'TRA RESID'!J12)) -> * | I17: =IF('TRA RESID'!H12="","",'TRA RESID'!H12) -> TRAETH | J17: ="Share~LO~"&'City characteristics'!$C$20 -> Share~LO~2019 | K17: =IF(B17="*",0,SUMIFS('TRA RESID'!N:N,'TRA RESID'!J:J,B17,'TRA RESID'!H:H,C17)) -> 0 | N17: =IF(Def_Tech!B15="*","*",Def_Tech!C15) -> * | O17: =Def_Tech!D15 -> TRAPASLDTICEVGSL19 | P17: =_xlfn.XLOOKUP(O17,'TRA RESID'!J:J,'TRA RESID'!I:I) -> TRAPASLDTDMD | Q17: =_xlfn.XLOOKUP(O17,'TRA RESID'!J:J,'TRA RESID'!S:S) -> 0.24925979 | R17: =_xlfn.XLOOKUP(O17,'TRA RESID'!J:J,'TRA RESID'!X:X) -> 1 | S17: =_xlfn.XLOOKUP(O17,'TRA RESID'!J:J,'TRA RESID'!W:W) -> 1 | T17: =_xlfn.XLOOKUP(O17,'TRA RESID'!J:J,'TRA RESID'!T:T) -> 13 | U17: =_xlfn.XLOOKUP(O17,'TRA RESID'!J:J,'TRA RESID'!U:U) -> 5.8122532 | V17: =SUMIFS('TRA RESID'!R:R,'TRA RESID'!J:J,O17) -> 0 | W17: =S17*W$1 -> 0.98
B18: =IF(C18="","*",IF(SUMIFS('TRA RESID'!R:R,'TRA RESID'!J:J,'TRA RESID'!J13)=0,"*",'TRA RESID'!J13)) -> * | C18: =IF('TRA RESID'!H13="","",'TRA RESID'!H13) -> TRADSL | D18: Share~UP | E18: =IF(B18="*",1,SUMIFS('TRA RESID'!O:O,'TRA RESID'!J:J,B18,'TRA RESID'!H:H,C18)) -> 1 | H18: =IF(I18="","*",IF(SUMIFS('TRA RESID'!R:R,'TRA RESID'!J:J,'TRA RESID'!J13)=0,"*",'TRA RESID'!J13)) -> * | I18: =IF('TRA RESID'!H13="","",'TRA RESID'!H13) -> TRADSL | J18: ="Share~LO~"&'City characteristics'!$C$20 -> Share~LO~2019 | K18: =IF(B18="*",0,SUMIFS('TRA RESID'!N:N,'TRA RESID'!J:J,B18,'TRA RESID'!H:H,C18)) -> 0 | N18: =IF(Def_Tech!B16="*","*",Def_Tech!C16) -> * | O18: =Def_Tech!D16 -> TRAPASLDTICEVDSL19 | P18: =_xlfn.XLOOKUP(O18,'TRA RESID'!J:J,'TRA RESID'!I:I) -> TRAPASLDTDMD | Q18: =_xlfn.XLOOKUP(O18,'TRA RESID'!J:J,'TRA RESID'!S:S) -> 0.19756987 | R18: =_xlfn.XLOOKUP(O18,'TRA RESID'!J:J,'TRA RESID'!X:X) -> 1 | S18: =_xlfn.XLOOKUP(O18,'TRA RESID'!J:J,'TRA RESID'!W:W) -> 1 | T18: =_xlfn.XLOOKUP(O18,'TRA RESID'!J:J,'TRA RESID'!T:T) -> 13 | U18: =_xlfn.XLOOKUP(O18,'TRA RESID'!J:J,'TRA RESID'!U:U) -> 5.8122532 | V18: =SUMIFS('TRA RESID'!R:R,'TRA RESID'!J:J,O18) -> 0 | W18: =S18*W$1 -> 0.98
... B148: =IF(C148="","*",IF(SUMIFS('TRA RESID'!R:R,'TRA RESID'!J:J,'TRA RESID'!J143)=0,"*",'TRA RESID'!J143)) -> TRAOTHAIRTURREA19 | C148: =IF('TRA RESID'!H143="","",'TRA RESID'!H143) -> TRASAF | D148: Share~UP | E148: =IF(B148="*",1,SUMIFS('TRA RESID'!O:O,'TRA RESID'!J:J,B148,'TRA RESID'!H:H,C148)) -> 1 | H148: =IF(I148="","*",IF(SUMIFS('TRA RESID'!R:R,'TRA RESID'!J:J,'TRA RESID'!J143)=0,"*",'TRA RESID'!J143)) -> TRAOTHAIRTURREA19 | I148: =IF('TRA RESID'!H143="","",'TRA RESID'!H143) -> TRASAF | J148: ="Share~LO~"&'City characteristics'!$C$20 -> Share~LO~2019 | K148: =IF(B148="*",0,SUMIFS('TRA RESID'!N:N,'TRA RESID'!J:J,B148,'TRA RESID'!H:H,C148)) -> 0 | N148: =IF(Def_Tech!B146="*","*",Def_Tech!C146) -> * | O148: =Def_Tech!D146 -> TRAOTHAIRTURREA19 | P148: =_xlfn.XLOOKUP(O148,'TRA RESID'!J:J,'TRA RESID'!I:I) -> TRAOTHAIRDMD | Q148: =_xlfn.XLOOKUP(O148,'TRA RESID'!J:J,'TRA RESID'!S:S) -> 0.0043975374 | R148: =_xlfn.XLOOKUP(O148,'TRA RESID'!J:J,'TRA RESID'!X:X) -> 1 | S148: =_xlfn.XLOOKUP(O148,'TRA RESID'!J:J,'TRA RESID'!W:W) -> 1 | T148: =_xlfn.XLOOKUP(O148,'TRA RESID'!J:J,'TRA RESID'!T:T) -> 24 | U148: =_xlfn.XLOOKUP(O148,'TRA RESID'!J:J,'TRA RESID'!U:U) -> 1249.4626 | V148: =SUMIFS('TRA RESID'!R:R,'TRA RESID'!J:J,O148) -> 0.12571557 | W148: =S148*W$1 -> 0.98

Sheet >> Parameters
