Workbook

Sheet ReadMe
A1: Generic Comet (GC) TIMES Supply
B3: Sheet color
C4: Raw Data and Parameters
C6: City Specific Data
C8: Post processing for TIMES
C10: Table formatted for TIMES

Sheet >> City Data

Sheet City characteristics
B2: City Basic Data
B4: Calibration methodology | C4: GHG Inventory
B6: A. City Characteristics
B7: Data Item | C7: Value | D7: Units
B8: City Name | C8: New York
B9: Latitude | C9: 40.5
B10: Longitude | C10: -75
B11: County | C11: New York County
B12: State | C12: New York
B13: Census Division | C13: Middle Atlantic
B14: Climate Division | C14: Northeast
B15: Egrid Region | C15: NPCC NYC/Westchester
B16: Area of city (excluding water, natural and agricultural areas) | C16: 778 | D16: square kilometers
B17: * Division and Region Map can be found in the Maps sheet.
B18: B. Planning Base Year and Target Years
B19: Year | C19: Value | D19: Units
B20: Base Year | C20: 2019 | D20: Acceptable range [2018,2021]
B21: End Year | C21: 2050
B23: C. City Population and GDP
B24: Data Item | C24: Value | D24: Units
B25: Population in Base Year | C25: 8337 | D25: Thousand of people
B26: Annual population growth (Base Year - End Year) | C26: 0.5 | D26: % people
B27: GDP in Base Year | C27: 1206000 | D27: Million US$
B28: Annual GDP growth rate | C28: 2 | D28: % US$
B29: Share of manufacturing GDP | C29: 5 | D29: % US$
B30: Share of State population | C30: 0.42835123
B31: Share of State GDP | C31: 0.67251772
B32: Adjustment from state manufacturing GDP | C32: 1.0638298
B34: D. Climate Data
B35: Data Item | C35: 2000 | D35: 2050 | E35: 2100 | F35: Units
B36: Heating degree days (HDD) | C36: 4473.4625 | D36: 4066.4182 | E36: 3763.8582 | F36: F
B37: Cooling degree days (CDD) | C37: 1020.7333 | D37: 1224.2555 | E37: 1375.5355 | F37: F
B39: Data Item | C39: Value | D39: Units
B40: Correction from State HDD | C40: 0.72727402
B41: Correction from State CDD | C41: 1.5583715
B42: Annual precipitation | C42: 762 | D42: mm / year
B43: Climate change scenario | C43: RCP4.5
B44: Average temperature increase in 1980-2020 | C44: 1.4617857 | D44: F
B45: Forecasted average temperature increase in 2035-2065 | C45: 3.13 | D45: F
B46: Forecasted average temperature increase in 2070-2100 | C46: 4.37 | D46: F
...

Sheet >> GC_Resid

Sheet Demand
A1: Sector | B1: Sub-sector | C1: Archetype | D1: Vintage | E1: Demand Label | F1: Unit | G1: 2019 | H1: 2020 | I1: 2025 | J1: 2030 | K1: 2035 | L1: 2040 | M1: 2045 | N1: 2050 | O1: 2055 | P1: 2060 | Q1: 2065 | R1: 2070 | S1: 2075 | T1: 2080 | U1: 2085 | V1: 2090 | W1: 2095 | X1: 2100
A2: Commercial | B2: Hotel | D2: Old | E2: COMHOTOldDMD | F2: Mm2 | G2: 11.978701 | H2: 11.978701 | I2: 11.978701 | J2: 11.978701 | K2: 11.978701 | L2: 11.978701 | M2: 11.978701 | N2: 11.978701 | O2: 11.978701 | P2: 11.978701 | Q2: 11.978701 | R2: 11.978701 | S2: 11.978701 | T2: 11.978701 | U2: 11.978701 | V2: 11.978701 | W2: 11.978701 | X2: 11.978701
A3: Commercial | B3: Retail | D3: Old | E3: COMRETOldDMD | F3: Mm2 | G3: 23.081056 | H3: 23.081056 | I3: 23.081056 | J3: 23.081056 | K3: 23.081056 | L3: 23.081056 | M3: 23.081056 | N3: 23.081056 | O3: 23.081056 | P3: 23.081056 | Q3: 23.081056 | R3: 23.081056 | S3: 23.081056 | T3: 23.081056 | U3: 23.081056 | V3: 23.081056 | W3: 23.081056 | X3: 23.081056
A4: Commercial | B4: Office | D4: Old | E4: COMOFFOldDMD | F4: Mm2 | G4: 73.164819 | H4: 73.164819 | I4: 73.164819 | J4: 73.164819 | K4: 73.164819 | L4: 73.164819 | M4: 73.164819 | N4: 73.164819 | O4: 73.164819 | P4: 73.164819 | Q4: 73.164819 | R4: 73.164819 | S4: 73.164819 | T4: 73.164819 | U4: 73.164819 | V4: 73.164819 | W4: 73.164819 | X4: 73.164819
A5: Commercial | B5: Hospital | D5: Old | E5: COMHOPOldDMD | F5: Mm2 | G5: 44.382259 | H5: 44.382259 | I5: 44.382259 | J5: 44.382259 | K5: 44.382259 | L5: 44.382259 | M5: 44.382259 | N5: 44.382259 | O5: 44.382259 | P5: 44.382259 | Q5: 44.382259 | R5: 44.382259 | S5: 44.382259 | T5: 44.382259 | U5: 44.382259 | V5: 44.382259 | W5: 44.382259 | X5: 44.382259
A6: Commercial | B6: Educationnal | D6: Old | E6: COMEDUOldDMD | F6: Mm2 | G6: 48.565496 | H6: 48.565496 | I6: 48.565496 | J6: 48.565496 | K6: 48.565496 | L6: 48.565496 | M6: 48.565496 | N6: 48.565496 | O6: 48.565496 | P6: 48.565496 | Q6: 48.565496 | R6: 48.565496 | S6: 48.565496 | T6: 48.565496 | U6: 48.565496 | V6: 48.565496 | W6: 48.565496 | X6: 48.565496
A7: Commercial | B7: Warehouse | D7: Old | E7: COMWAROldDMD | F7: Mm2 | G7: 32.733587 | H7: 32.733587 | I7: 32.733587 | J7: 32.733587 | K7: 32.733587 | L7: 32.733587 | M7: 32.733587 | N7: 32.733587 | O7: 32.733587 | P7: 32.733587 | Q7: 32.733587 | R7: 32.733587 | S7: 32.733587 | T7: 32.733587 | U7: 32.733587 | V7: 32.733587 | W7: 32.733587 | X7: 32.733587
A8: Commercial | B8: Municipal | D8: Old | E8: COMMUNOldDMD | F8: Mm2 | G8: 16.841333 | H8: 16.841333 | I8: 16.841333 | J8: 16.841333 | K8: 16.841333 | L8: 16.841333 | M8: 16.841333 | N8: 16.841333 | O8: 16.841333 | P8: 16.841333 | Q8: 16.841333 | R8: 16.841333 | S8: 16.841333 | T8: 16.841333 | U8: 16.841333 | V8: 16.841333 | W8: 16.841333 | X8: 16.841333
A9: Commercial | B9: Other | D9: Old | E9: COMOTHOldDMD | F9: Mm2 | G9: 8.7602804 | H9: 8.7602804 | I9: 8.7602804 | J9: 8.7602804 | K9: 8.7602804 | L9: 8.7602804 | M9: 8.7602804 | N9: 8.7602804 | O9: 8.7602804 | P9: 8.7602804 | Q9: 8.7602804 | R9: 8.7602804 | S9: 8.7602804 | T9: 8.7602804 | U9: 8.7602804 | V9: 8.7602804 | W9: 8.7602804 | X9: 8.7602804
A10: Commercial | B10: Hotel | D10: New | E10: COMHOTNewDMD | F10: Mm2 | G10: 0 | H10: 0.23957402 | I10: 1.4374441 | J10: 2.6353143 | K10: 3.8331844 | L10: 5.0310545 | M10: 6.2289246 | N10: 7.4267947 | O10: 8.6246649 | P10: 9.822535 | Q10: 11.020405 | R10: 12.218275 | S10: 13.416145 | T10: 14.614015 | U10: 15.811886 | V10: 17.009756 | W10: 18.207626 | X10: 19.405496
A11: Commercial | B11: Retail | D11: New | E11: COMRETNewDMD | F11: Mm2 | G11: 0 | H11: 0.46162113 | I11: 2.7697268 | J11: 5.0778324 | K11: 7.3859381 | L11: 9.6940437 | M11: 12.002149 | N11: 14.310255 | O11: 16.618361 | P11: 18.926466 | Q11: 21.234572 | R11: 23.542678 | S11: 25.850783 | T11: 28.158889 | U11: 30.466995 | V11: 32.7751 | W11: 35.083206 | X11: 37.391311
A12: Commercial | B12: Office | D12: New | E12: COMOFFNewDMD | F12: Mm2 | G12: 0 | H12: 1.4632964 | I12: 8.7797783 | J12: 16.09626 | K12: 23.412742 | L12: 30.729224 | M12: 38.045706 | N12: 45.362188 | O12: 52.67867 | P12: 59.995152 | Q12: 67.311633 | R12: 74.628115 | S12: 81.944597 | T12: 89.261079 | U12: 96.577561 | V12: 103.89404 | W12: 111.21052 | X12: 118.52701
A13: Commercial | B13: Hospital | D13: New | E13: COMHOPNewDMD | F13: Mm2 | G13: 0 | H13: 0.88764519 | I13: 5.3258711 | J13: 9.764097 | K13: 14.202323 | L13: 18.640549 | M13: 23.078775 | N13: 27.517001 | O13: 31.955227 | P13: 36.393453 | Q13: 40.831679 | R13: 45.269904 | S13: 49.70813 | T13: 54.146356 | U13: 58.584582 | V13: 63.022808 | W13: 67.461034 | X13: 71.89926
... A17: Commercial | B17: Other | D17: New | E17: COMOTHNewDMD | F17: Mm2 | G17: 0 | H17: 0.17520561 | I17: 1.0512337 | J17: 1.9272617 | K17: 2.8032897 | L17: 3.6793178 | M17: 4.5553458 | N17: 5.4313739 | O17: 6.3074019 | P17: 7.18343 | Q17: 8.059458 | R17: 8.9354861 | S17: 9.8115141 | T17: 10.687542 | U17: 11.56357 | V17: 12.439598 | W17: 13.315626 | X17: 14.191654
A18: Residential | B18: Apartment | C18: Low Income | D18: Old | E18: RESAPALOOldDMD | F18: Mm2 | G18: 51.807877 | H18: 51.807877 | I18: 51.807877 | J18: 51.807877 | K18: 51.807877 | L18: 51.807877 | M18: 51.807877 | N18: 51.807877 | O18: 51.807877 | P18: 51.807877 | Q18: 51.807877 | R18: 51.807877 | S18: 51.807877 | T18: 51.807877 | U18: 51.807877 | V18: 51.807877 | W18: 51.807877 | X18: 51.807877
A19: Residential | B19: House | C19: Low Income | D19: Old | E19: RESHOULOOldDMD | F19: Mm2 | G19: 14.956798 | H19: 14.956798 | I19: 14.956798 | J19: 14.956798 | K19: 14.956798 | L19: 14.956798 | M19: 14.956798 | N19: 14.956798 | O19: 14.956798 | P19: 14.956798 | Q19: 14.956798 | R19: 14.956798 | S19: 14.956798 | T19: 14.956798 | U19: 14.956798 | V19: 14.956798 | W19: 14.956798 | X19: 14.956798
A20: Residential | B20: Apartment | C20: Lower-Middle Income | D20: Old | E20: RESAPALMOldDMD | F20: Mm2 | G20: 57.121976 | H20: 57.121976 | I20: 57.121976 | J20: 57.121976 | K20: 57.121976 | L20: 57.121976 | M20: 57.121976 | N20: 57.121976 | O20: 57.121976 | P20: 57.121976 | Q20: 57.121976 | R20: 57.121976 | S20: 57.121976 | T20: 57.121976 | U20: 57.121976 | V20: 57.121976 | W20: 57.121976 | X20: 57.121976
A21: Residential | B21: House | C21: Lower-Middle Income | D21: Old | E21: RESHOULMOldDMD | F21: Mm2 | G21: 38.299259 | H21: 38.299259 | I21: 38.299259 | J21: 38.299259 | K21: 38.299259 | L21: 38.299259 | M21: 38.299259 | N21: 38.299259 | O21: 38.299259 | P21: 38.299259 | Q21: 38.299259 | R21: 38.299259 | S21: 38.299259 | T21: 38.299259 | U21: 38.299259 | V21: 38.299259 | W21: 38.299259 | X21: 38.299259
A22: Residential | B22: Apartment | C22: Upper-Middle Income | D22: Old | E22: RESAPAUMOldDMD | F22: Mm2 | G22: 15.495888 | H22: 15.495888 | I22: 15.495888 | J22: 15.495888 | K22: 15.495888 | L22: 15.495888 | M22: 15.495888 | N22: 15.495888 | O22: 15.495888 | P22: 15.495888 | Q22: 15.495888 | R22: 15.495888 | S22: 15.495888 | T22: 15.495888 | U22: 15.495888 | V22: 15.495888 | W22: 15.495888 | X22: 15.495888
A23: Residential | B23: House | C23: Upper-Middle Income | D23: Old | E23: RESHOUUMOldDMD | F23: Mm2 | G23: 19.187214 | H23: 19.187214 | I23: 19.187214 | J23: 19.187214 | K23: 19.187214 | L23: 19.187214 | M23: 19.187214 | N23: 19.187214 | O23: 19.187214 | P23: 19.187214 | Q23: 19.187214 | R23: 19.187214 | S23: 19.187214 | T23: 19.187214 | U23: 19.187214 | V23: 19.187214 | W23: 19.187214 | X23: 19.187214
A24: Residential | B24: Apartment | C24: High Income | D24: Old | E24: RESAPAHIOldDMD | F24: Mm2 | G24: 66.398717 | H24: 66.398717 | I24: 66.398717 | J24: 66.398717 | K24: 66.398717 | L24: 66.398717 | M24: 66.398717 | N24: 66.398717 | O24: 66.398717 | P24: 66.398717 | Q24: 66.398717 | R24: 66.398717 | S24: 66.398717 | T24: 66.398717 | U24: 66.398717 | V24: 66.398717 | W24: 66.398717 | X24: 66.398717
A25: Residential | B25: House | C25: High Income | D25: Old | E25: RESHOUHIOldDMD | F25: Mm2 | G25: 96.552051 | H25: 96.552051 | I25: 96.552051 | J25: 96.552051 | K25: 96.552051 | L25: 96.552051 | M25: 96.552051 | N25: 96.552051 | O25: 96.552051 | P25: 96.552051 | Q25: 96.552051 | R25: 96.552051 | S25: 96.552051 | T25: 96.552051 | U25: 96.552051 | V25: 96.552051 | W25: 96.552051 | X25: 96.552051
A26: Residential | B26: Apartment | C26: Low Income | D26: New | E26: RESAPALONewDMD | F26: Mm2 | G26: 0 | H26: 0.25903939 | I26: 1.5542363 | J26: 2.8494333 | K26: 4.1446302 | L26: 5.4398271 | M26: 6.7350241 | N26: 8.030221 | O26: 9.3254179 | P26: 10.620615 | Q26: 11.915812 | R26: 13.211009 | S26: 14.506206 | T26: 15.801403 | U26: 17.0966 | V26: 18.391797 | W26: 19.686993 | X26: 20.98219
A27: Residential | B27: House | C27: Low Income | D27: New | E27: RESHOULONewDMD | F27: Mm2 | G27: 0 | H27: 0.07478399 | I27: 0.44870394 | J27: 0.82262389 | K27: 1.1965438 | L27: 1.5704638 | M27: 1.9443837 | N27: 2.3183037 | O27: 2.6922236 | P27: 3.0661436 | Q27: 3.4400635 | R27: 3.8139835 | S27: 4.1879034 | T27: 4.5618234 | U27: 4.9357433 | V27: 5.3096633 | W27: 5.6835832 | X27: 6.0575032
A28: Residential | B28: Apartment | C28: Lower-Middle Income | D28: New | E28: RESAPALMNewDMD | F28: Mm2 | G28: 0 | H28: 0.28560988 | I28: 1.7136593 | J28: 3.1417087 | K28: 4.5697581 | L28: 5.9978075 | M28: 7.4258569 | N28: 8.8539063 | O28: 10.281956 | P28: 11.710005 | Q28: 13.138055 | R28: 14.566104 | S28: 15.994153 | T28: 17.422203 | U28: 18.850252 | V28: 20.278302 | W28: 21.706351 | X28: 23.1344
A29: Residential | B29: House | C29: Lower-Middle Income | D29: New | E29: RESHOULMNewDMD | F29: Mm2 | G29: 0 | H29: 0.19149629 | I29: 1.1489778 | J29: 2.1064592 | K29: 3.0639407 | L29: 4.0214222 | M29: 4.9789036 | N29: 5.9363851 | O29: 6.8938665 | P29: 7.851348 | Q29: 8.8088295 | R29: 9.7663109 | S29: 10.723792 | T29: 11.681274 | U29: 12.638755 | V29: 13.596237 | W29: 14.553718 | X29: 15.5112
... A33: Residential | B33: House | C33: High Income | D33: New | E33: RESHOUHINewDMD | F33: Mm2 | G33: 0 | H33: 0.48276025 | I33: 2.8965615 | J33: 5.3103628 | K33: 7.7241641 | L33: 10.137965 | M33: 12.551767 | N33: 14.965568 | O33: 17.379369 | P33: 19.79317 | Q33: 22.206972 | R33: 24.620773 | S33: 27.034574 | T33: 29.448376 | U33: 31.862177 | V33: 34.275978 | W33: 36.689779 | X33: 39.103581
A34: Industrial | B34: All Industries | E34: INDAINDMD | F34: TJ | G34: 66716.461 | H34: 68050.79 | I34: 74855.869 | J34: 82341.456 | K34: 90575.602 | L34: 99633.162 | M34: 109596.48 | N34: 120556.13 | O34: 132611.74 | P34: 145872.91 | Q34: 160460.2 | R34: 176506.22 | S34: 194156.85 | T34: 213572.53 | U34: 234929.78 | V34: 258422.76 | W34: 284265.04 | X34: 312691.54
A35: Transportation | B35: Passenger | C35: Passenger Car | E35: TRAPASCARDMD | F35: M Vkm | G35: 68921.251 | H35: 69265.857 | I35: 70997.504 | J35: 72772.441 | K35: 74591.752 | L35: 76456.546 | M35: 78367.96 | N35: 80327.159 | O35: 82335.338 | P35: 84393.721 | Q35: 86503.564 | R35: 88666.153 | S35: 90882.807 | T35: 93154.877 | U35: 95483.749 | V35: 97870.843 | W35: 100317.61 | X35: 102825.55
A36: Transportation | B36: Passenger | C36: Passenger Truck | E36: TRAPASLDTDMD | F36: M Vkm | G36: 0 | H36: 0 | I36: 0 | J36: 0 | K36: 0 | L36: 0 | M36: 0 | N36: 0 | O36: 0 | P36: 0 | Q36: 0 | R36: 0 | S36: 0 | T36: 0 | U36: 0 | V36: 0 | W36: 0 | X36: 0
A37: Transportation | B37: Passenger | C37: Motorcycle | E37: TRAPASMOTDMD | F37: M Vkm | G37: 0 | H37: 0 | I37: 0 | J37: 0 | K37: 0 | L37: 0 | M37: 0 | N37: 0 | O37: 0 | P37: 0 | Q37: 0 | R37: 0 | S37: 0 | T37: 0 | U37: 0 | V37: 0 | W37: 0 | X37: 0
A38: Transportation | B38: Freight | C38: Light Commercial Truck | E38: TRAFRECLTDMD | F38: M Vkm | G38: 1578.5179 | H38: 1586.4105 | I38: 1626.0707 | J38: 1666.7225 | K38: 1708.3906 | L38: 1751.1003 | M38: 1794.8778 | N38: 1839.7498 | O38: 1885.7435 | P38: 1932.8871 | Q38: 1981.2093 | R38: 2030.7395 | S38: 2081.508 | T38: 2133.5457 | U38: 2186.8844 | V38: 2241.5565 | W38: 2297.5954 | X38: 2355.0353
A39: Transportation | B39: Freight | C39: Refuse Truck | E39: TRAFRERFTDMD | F39: M Vkm | G39: 70.026308 | H39: 70.37644 | I39: 72.135851 | J39: 73.939247 | K39: 75.787728 | L39: 77.682421 | M39: 79.624482 | N39: 81.615094 | O39: 83.655471 | P39: 85.746858 | Q39: 87.89053 | R39: 90.087793 | S39: 92.339988 | T39: 94.648487 | U39: 97.0147 | V39: 99.440067 | W39: 101.92607 | X39: 104.47422
A40: Transportation | B40: Freight | C40: Single Unit Long-haul Truck | E40: TRAFRESLHDMD | F40: M Vkm | G40: 0 | H40: 0 | I40: 0 | J40: 0 | K40: 0 | L40: 0 | M40: 0 | N40: 0 | O40: 0 | P40: 0 | Q40: 0 | R40: 0 | S40: 0 | T40: 0 | U40: 0 | V40: 0 | W40: 0 | X40: 0
A41: Transportation | B41: Freight | C41: Single Unit Short-haul Truck | E41: TRAFRESSHDMD | F41: M Vkm | G41: 0 | H41: 0 | I41: 0 | J41: 0 | K41: 0 | L41: 0 | M41: 0 | N41: 0 | O41: 0 | P41: 0 | Q41: 0 | R41: 0 | S41: 0 | T41: 0 | U41: 0 | V41: 0 | W41: 0 | X41: 0
A42: Transportation | B42: Freight | C42: Combination Long-haul Truck | E42: TRAFRECLHDMD | F42: M Vkm | G42: 1367.6202 | H42: 1374.4583 | I42: 1408.8197 | J42: 1444.0402 | K42: 1480.1412 | L42: 1517.1447 | M42: 1555.0734 | N42: 1593.9502 | O42: 1633.7989 | P42: 1674.6439 | Q42: 1716.51 | R42: 1759.4228 | S42: 1803.4083 | T42: 1848.4935 | U42: 1894.7059 | V42: 1942.0735 | W42: 1990.6254 | X42: 2040.391
A43: Transportation | B43: Freight | C43: Combination Short-haul Truck | E43: TRAFRECSHDMD | F43: M Vkm | G43: 0 | H43: 0 | I43: 0 | J43: 0 | K43: 0 | L43: 0 | M43: 0 | N43: 0 | O43: 0 | P43: 0 | Q43: 0 | R43: 0 | S43: 0 | T43: 0 | U43: 0 | V43: 0 | W43: 0 | X43: 0
A44: Transportation | B44: Passenger | C44: Transit Bus | E44: TRAPASTBUDMD | F44: M Vkm | G44: 498.20419 | H44: 500.69521 | I44: 513.21259 | J44: 526.0429 | K44: 539.19397 | L44: 552.67382 | M44: 566.49067 | N44: 580.65294 | O44: 595.16926 | P44: 610.04849 | Q44: 625.2997 | R44: 640.93219 | S44: 656.9555 | T44: 673.37939 | U44: 690.21387 | V44: 707.46922 | W44: 725.15595 | X44: 743.28485
A45: Transportation | B45: Passenger | C45: School Bus | E45: TRAPASSBUDMD | F45: M Vkm | G45: 86.053217 | H45: 86.483483 | I45: 88.645571 | J45: 90.86171 | K45: 93.133253 | L45: 95.461584 | M45: 97.848123 | N45: 100.29433 | O45: 102.80168 | P45: 105.37173 | Q45: 108.00602 | R45: 110.70617 | S45: 113.47382 | T45: 116.31067 | U45: 119.21844 | V45: 122.1989 | W45: 125.25387 | X45: 128.38522
A46: Transportation | B46: Passenger | C46: Other Buses | E46: TRAPASOBUDMD | F46: M Vkm | G46: 0 | H46: 0 | I46: 0 | J46: 0 | K46: 0 | L46: 0 | M46: 0 | N46: 0 | O46: 0 | P46: 0 | Q46: 0 | R46: 0 | S46: 0 | T46: 0 | U46: 0 | V46: 0 | W46: 0 | X46: 0
...

Sheet WAS RESID
A1: Sector | B1: Sub-sector | C1: Archetype | D1: Vintage | E1: End Use | F1: Technology | G1: Energy | H1: Input Label | I1: Output Label | J1: Demand Label | K1: Technology Label | L1: Included | M1: MODE DEMAND (k tonnes/ M m3) | N1: SPLIT (%) | O1: DEMAND (k tonnes / Mm3) | P1: RESID (k tonnes / Mm3) | Q1: CFA | R1: C2A | S1: Energy flow (TJ/ktonnes) | T1: CH4 (tonnes/ktonnes) | U1: CO2 (tonnes/ktonnes) | V1: N2O (tonnes/ktonnes) | W1: Energy flow (TJ)
A2: Waste | B2: Solid | C2: Paper | E2: Compost | F2: IN | G2: Electricity | H2: WASELC | J2: WASSOLPAPDMDTOT | K2: WASSOLPAPCMP19 | L2: 1 | M2: 3375.0741 | N2: 0 | O2: 0 | P2: 0 | Q2: 0.9 | R2: 1 | S2: 0.0037198608 | T2: 0.59045559 | U2: 0 | V2: 0.011231423 | W2: 0
A3: Waste | B3: Solid | C3: Paper | E3: Compost | F3: IN | G3: Diesel | H3: WASDSL | J3: WASSOLPAPDMDTOT | K3: WASSOLPAPCMP19 | L3: 1 | M3: 3375.0741 | N3: 0 | O3: 0 | P3: 0 | Q3: 0.9 | R3: 1 | S3: 0.0050435779 | T3: 0.59045559 | U3: 0 | V3: 0.011231423 | W3: 0
A4: Waste | B4: Solid | C4: Glass | E4: Compost | F4: IN | G4: Electricity | H4: WASELC | J4: WASSOLGLADMDTOT | K4: WASSOLGLACMP19 | L4: 0 | M4: 405.00889 | N4: 0 | O4: 0 | P4: 0 | Q4: 0.9 | R4: 1 | S4: 0.0032929234 | T4: 0 | U4: 0 | V4: 0 | W4: 0
A5: Waste | B5: Solid | C5: Glass | E5: Compost | F5: IN | G5: Diesel | H5: WASDSL | J5: WASSOLGLADMDTOT | K5: WASSOLGLACMP19 | L5: 0 | M5: 405.00889 | N5: 0 | O5: 0 | P5: 0 | Q5: 0.9 | R5: 1 | S5: 0.0038630599 | T5: 0 | U5: 0 | V5: 0 | W5: 0
A6: Waste | B6: Solid | C6: Metals | E6: Compost | F6: IN | G6: Electricity | H6: WASELC | J6: WASSOLMETDMDTOT | K6: WASSOLMETCMP19 | L6: 0 | M6: 540.01185 | N6: 0 | O6: 0 | P6: 0 | Q6: 0.9 | R6: 1 | S6: 0.0032855945 | T6: 0 | U6: 0 | V6: 0.0076625933 | W6: 0
A7: Waste | B7: Solid | C7: Metals | E7: Compost | F7: IN | G7: Diesel | H7: WASDSL | J7: WASSOLMETDMDTOT | K7: WASSOLMETCMP19 | L7: 0 | M7: 540.01185 | N7: 0 | O7: 0 | P7: 0 | Q7: 0.9 | R7: 1 | S7: 0.0038606586 | T7: 0 | U7: 0 | V7: 0.0076625933 | W7: 0
A8: Waste | B8: Solid | C8: Plastics | E8: Compost | F8: IN | G8: Electricity | H8: WASELC | J8: WASSOLPLADMDTOT | K8: WASSOLPLACMP19 | L8: 0 | M8: 1350.0296 | N8: 0 | O8: 0 | P8: 0 | Q8: 0.9 | R8: 1 | S8: 0.0032574407 | T8: 0 | U8: 0 | V8: 0.048992718 | W8: 0
A9: Waste | B9: Solid | C9: Plastics | E9: Compost | F9: IN | G9: Diesel | H9: WASDSL | J9: WASSOLPLADMDTOT | K9: WASSOLPLACMP19 | L9: 0 | M9: 1350.0296 | N9: 0 | O9: 0 | P9: 0 | Q9: 0.9 | R9: 1 | S9: 0.0041616592 | T9: 0 | U9: 0 | V9: 0.048992718 | W9: 0
A10: Waste | B10: Solid | C10: Food | E10: Compost | F10: IN | G10: Electricity | H10: WASELC | J10: WASSOLFOODMDTOT | K10: WASSOLFOOCMP19 | L10: 1 | M10: 1485.0326 | N10: 0.063636364 | O10: 94.502074 | P10: 105.0023 | Q10: 0.9 | R10: 1 | S10: 0.0048784913 | T10: 1.9885477 | U10: 0 | V10: 0.22987519 | W10: 0.46102755
A11: Waste | B11: Solid | C11: Food | E11: Compost | F11: IN | G11: Diesel | H11: WASDSL | J11: WASSOLFOODMDTOT | K11: WASSOLFOOCMP19 | L11: 1 | M11: 1485.0326 | N11: 0.063636364 | O11: 94.502074 | P11: 105.0023 | Q11: 0.9 | R11: 1 | S11: 0.0065600031 | T11: 1.9885477 | U11: 0 | V11: 0.22987519 | W11: 0.6199339
A12: Waste | B12: Solid | C12: Yard trimmings | E12: Compost | F12: IN | G12: Electricity | H12: WASELC | J12: WASSOLYARDMDTOT | K12: WASSOLYARCMP19 | L12: 1 | M12: 1080.0237 | N12: 0.026530134 | O12: 28.653174 | P12: 31.83686 | Q12: 0.9 | R12: 1 | S12: 0.0044521368 | T12: 1.969548 | U12: 0 | V12: 0.2558003 | W12: 0.12756785
A13: Waste | B13: Solid | C13: Yard trimmings | E13: Compost | F13: IN | G13: Diesel | H13: WASDSL | J13: WASSOLYARDMDTOT | K13: WASSOLYARCMP19 | L13: 1 | M13: 1080.0237 | N13: 0.026530134 | O13: 28.653174 | P13: 31.83686 | Q13: 0.9 | R13: 1 | S13: 0.0088196441 | T13: 1.969548 | U13: 0 | V13: 0.2558003 | W13: 0.25271079
... A17: Waste | B17: Solid | C17: Paper | E17: Anaerobic Digestion | F17: IN | G17: Diesel | H17: WASDSL | J17: WASSOLPAPDMDTOT | K17: WASSOLPAPADG19 | L17: 1 | M17: 3375.0741 | N17: 0 | O17: 0 | P17: 0 | Q17: 0.9 | R17: 1 | S17: 0.020209815 | T17: 4.0822852 | U17: 0 | V17: 0.048656387 | W17: 0
A18: Waste | B18: Solid | C18: Paper | E18: Anaerobic Digestion | F18: OUT | G18: Biogas | I18: WASSOLADGBGA | J18: WASSOLPAPDMDTOT | K18: WASSOLPAPADG19 | L18: 1 | M18: 3375.0741 | N18: 0 | O18: 0 | P18: 0 | Q18: 0.9 | R18: 1 | S18: 2.5551929 | T18: 4.0822852 | U18: 0 | V18: 0.048656387 | W18: 0
A19: Waste | B19: Solid | C19: Glass | E19: Anaerobic Digestion | F19: IN | G19: Electricity | H19: WASELC | J19: WASSOLGLADMDTOT | K19: WASSOLGLAADG19 | L19: 0 | M19: 405.00889 | N19: 0 | O19: 0 | P19: 0 | Q19: 0.9 | R19: 1 | S19: 0.22186353 | T19: 0 | U19: 0 | V19: 0 | W19: 0
A20: Waste | B20: Solid | C20: Glass | E20: Anaerobic Digestion | F20: IN | G20: Diesel | H20: WASDSL | J20: WASSOLGLADMDTOT | K20: WASSOLGLAADG19 | L20: 0 | M20: 405.00889 | N20: 0 | O20: 0 | P20: 0 | Q20: 0.9 | R20: 1 | S20: 0.0025027737 | T20: 0 | U20: 0 | V20: 0 | W20: 0
A21: Waste | B21: Solid | C21: Glass | E21: Anaerobic Digestion | F21: OUT | G21: Biogas | I21: WASSOLADGBGA | J21: WASSOLGLADMDTOT | K21: WASSOLGLAADG19 | L21: 0 | M21: 405.00889 | N21: 0 | O21: 0 | P21: 0 | Q21: 0.9 | R21: 1 | S21: 0 | T21: 0 | U21: 0 | V21: 0 | W21: 0
A22: Waste | B22: Solid | C22: Metals | E22: Anaerobic Digestion | F22: IN | G22: Electricity | H22: WASELC | J22: WASSOLMETDMDTOT | K22: WASSOLMETADG19 | L22: 0 | M22: 540.01185 | N22: 0 | O22: 0 | P22: 0 | Q22: 0.9 | R22: 1 | S22: 0.22087012 | T22: 0 | U22: 0 | V22: 0 | W22: 0
A23: Waste | B23: Solid | C23: Metals | E23: Anaerobic Digestion | F23: IN | G23: Diesel | H23: WASDSL | J23: WASSOLMETDMDTOT | K23: WASSOLMETADG19 | L23: 0 | M23: 540.01185 | N23: 0 | O23: 0 | P23: 0 | Q23: 0.9 | R23: 1 | S23: 0.0023948008 | T23: 0 | U23: 0 | V23: 0 | W23: 0
A24: Waste | B24: Solid | C24: Metals | E24: Anaerobic Digestion | F24: OUT | G24: Biogas | I24: WASSOLADGBGA | J24: WASSOLMETDMDTOT | K24: WASSOLMETADG19 | L24: 0 | M24: 540.01185 | N24: 0 | O24: 0 | P24: 0 | Q24: 0.9 | R24: 1 | S24: 0 | T24: 0 | U24: 0 | V24: 0 | W24: 0
A25: Waste | B25: Solid | C25: Plastics | E25: Anaerobic Digestion | F25: IN | G25: Electricity | H25: WASELC | J25: WASSOLPLADMDTOT | K25: WASSOLPLAADG19 | L25: 0 | M25: 1350.0296 | N25: 0 | O25: 0 | P25: 0 | Q25: 0.9 | R25: 1 | S25: 0.22185413 | T25: 0 | U25: 0 | V25: 0 | W25: 0
A26: Waste | B26: Solid | C26: Plastics | E26: Anaerobic Digestion | F26: IN | G26: Diesel | H26: WASDSL | J26: WASSOLPLADMDTOT | K26: WASSOLPLAADG19 | L26: 0 | M26: 1350.0296 | N26: 0 | O26: 0 | P26: 0 | Q26: 0.9 | R26: 1 | S26: 0.0025017494 | T26: 0 | U26: 0 | V26: 0 | W26: 0
A27: Waste | B27: Solid | C27: Plastics | E27: Anaerobic Digestion | F27: OUT | G27: Biogas | I27: WASSOLADGBGA | J27: WASSOLPLADMDTOT | K27: WASSOLPLAADG19 | L27: 0 | M27: 1350.0296 | N27: 0 | O27: 0 | P27: 0 | Q27: 0.9 | R27: 1 | S27: 0 | T27: 0 | U27: 0 | V27: 0 | W27: 0
A28: Waste | B28: Solid | C28: Food | E28: Anaerobic Digestion | F28: IN | G28: Electricity | H28: WASELC | J28: WASSOLFOODMDTOT | K28: WASSOLFOOADG19 | L28: 1 | M28: 1485.0326 | N28: 0 | O28: 0 | P28: 0 | Q28: 0.9 | R28: 1 | S28: 0.24057902 | T28: 3.9766619 | U28: 0 | V28: 0.53538242 | W28: 0
A29: Waste | B29: Solid | C29: Food | E29: Anaerobic Digestion | F29: IN | G29: Diesel | H29: WASDSL | J29: WASSOLFOODMDTOT | K29: WASSOLFOOADG19 | L29: 1 | M29: 1485.0326 | N29: 0 | O29: 0 | P29: 0 | Q29: 0.9 | R29: 1 | S29: 0.0041551694 | T29: 3.9766619 | U29: 0 | V29: 0.53538242 | W29: 0
A30: Waste | B30: Solid | C30: Food | E30: Anaerobic Digestion | F30: OUT | G30: Biogas | I30: WASSOLADGBGA | J30: WASSOLFOODMDTOT | K30: WASSOLFOOADG19 | L30: 1 | M30: 1485.0326 | N30: 0 | O30: 0 | P30: 0 | Q30: 0.9 | R30: 1 | S30: 4.2239471 | T30: 3.9766619 | U30: 0 | V30: 0.53538242 | W30: 0
A31: Waste | B31: Solid | C31: Yard trimmings | E31: Anaerobic Digestion | F31: IN | G31: Electricity | H31: WASELC | J31: WASSOLYARDMDTOT | K31: WASSOLYARADG19 | L31: 1 | M31: 1080.0237 | N31: 0 | O31: 0 | P31: 0 | Q31: 0.9 | R31: 1 | S31: 0.3146294 | T31: 3.1453229 | U31: 0 | V31: 0.23841367 | W31: 0
A32: Waste | B32: Solid | C32: Yard trimmings | E32: Anaerobic Digestion | F32: IN | G32: Diesel | H32: WASDSL | J32: WASSOLYARDMDTOT | K32: WASSOLYARADG19 | L32: 1 | M32: 1080.0237 | N32: 0 | O32: 0 | P32: 0 | Q32: 0.9 | R32: 1 | S32: 0.011869074 | T32: 3.1453229 | U32: 0 | V32: 0.23841367 | W32: 0
A33: Waste | B33: Solid | C33: Yard trimmings | E33: Anaerobic Digestion | F33: OUT | G33: Biogas | I33: WASSOLADGBGA | J33: WASSOLYARDMDTOT | K33: WASSOLYARADG19 | L33: 1 | M33: 1080.0237 | N33: 0 | O33: 0 | P33: 0 | Q33: 0.9 | R33: 1 | S33: 1.2089642 | T33: 3.1453229 | U33: 0 | V33: 0.23841367 | W33: 0
A34: Waste | B34: Solid | C34: All Other | E34: Anaerobic Digestion | F34: IN | G34: Electricity | H34: WASELC | J34: WASSOLAOTDMDTOT | K34: WASSOLAOTADG19 | L34: 1 | M34: 5265.1156 | N34: 0 | O34: 0 | P34: 0 | Q34: 0.9 | R34: 1 | S34: 0.30609766 | T34: 0.14920915 | U34: 0 | V34: 0.15032975 | W34: 0
A35: Waste | B35: Solid | C35: All Other | E35: Anaerobic Digestion | F35: IN | G35: Diesel | H35: WASDSL | J35: WASSOLAOTDMDTOT | K35: WASSOLAOTADG19 | L35: 1 | M35: 5265.1156 | N35: 0 | O35: 0 | P35: 0 | Q35: 0.9 | R35: 1 | S35: 0.011309843 | T35: 0.14920915 | U35: 0 | V35: 0.15032975 | W35: 0
A36: Waste | B36: Solid | C36: All Other | E36: Anaerobic Digestion | F36: OUT | G36: Biogas | I36: WASSOLADGBGA | J36: WASSOLAOTDMDTOT | K36: WASSOLAOTADG19 | L36: 1 | M36: 5265.1156 | N36: 0 | O36: 0 | P36: 0 | Q36: 0.9 | R36: 1 | S36: 0.19326305 | T36: 0.14920915 | U36: 0 | V36: 0.15032975 | W36: 0
A37: Waste | B37: Solid | C37: Paper | E37: Incineration | F37: OUT | G37: Electricity | I37: CELC | J37: WASSOLPAPDMDTOT | K37: WASSOLPAPINC19 | L37: 1 | M37: 3375.0741 | N37: 0 | O37: 0 | P37: 0 | Q37: 0.9 | R37: 1 | S37: 2.70904 | T37: 0.011449374 | U37: 20.609799 | V37: 0.014901106 | W37: 0
A38: Waste | B38: Solid | C38: Paper | E38: Incineration | F38: OUT | G38: Steam | I38: STM | J38: WASSOLPAPDMDTOT | K38: WASSOLPAPINC19 | L38: 1 | M38: 3375.0741 | N38: 0 | O38: 0 | P38: 0 | Q38: 0.9 | R38: 1 | S38: 5.41808 | T38: 0.011449374 | U38: 20.609799 | V38: 0.014901106 | W38: 0
A39: Waste | B39: Solid | C39: Glass | E39: Incineration | F39: OUT | G39: Electricity | I39: CELC | J39: WASSOLGLADMDTOT | K39: WASSOLGLAINC19 | L39: 1 | M39: 405.00889 | N39: 0 | O39: 0 | P39: 0 | Q39: 0.9 | R39: 1 | S39: 0 | T39: 0.011858224 | U39: 10.258114 | V39: 0.016227641 | W39: 0
A40: Waste | B40: Solid | C40: Glass | E40: Incineration | F40: OUT | G40: Steam | I40: STM | J40: WASSOLGLADMDTOT | K40: WASSOLGLAINC19 | L40: 1 | M40: 405.00889 | N40: 0 | O40: 0 | P40: 0 | Q40: 0.9 | R40: 1 | S40: 0 | T40: 0.011858224 | U40: 10.258114 | V40: 0.016227641 | W40: 0
A41: Waste | B41: Solid | C41: Metals | E41: Incineration | F41: OUT | G41: Electricity | I41: CELC | J41: WASSOLMETDMDTOT | K41: WASSOLMETINC19 | L41: 1 | M41: 540.01185 | N41: 0 | O41: 0 | P41: 0 | Q41: 0.9 | R41: 1 | S41: 0.25614365 | T41: 0.011480252 | U41: 12.099667 | V41: 0.015001292 | W41: 0
A42: Waste | B42: Solid | C42: Metals | E42: Incineration | F42: OUT | G42: Steam | I42: STM | J42: WASSOLMETDMDTOT | K42: WASSOLMETINC19 | L42: 1 | M42: 540.01185 | N42: 0 | O42: 0 | P42: 0 | Q42: 0.9 | R42: 1 | S42: 0.5122873 | T42: 0.011480252 | U42: 12.099667 | V42: 0.015001292 | W42: 0
A43: Waste | B43: Solid | C43: Plastics | E43: Incineration | F43: OUT | G43: Electricity | I43: CELC | J43: WASSOLPLADMDTOT | K43: WASSOLPLAINC19 | L43: 1 | M43: 1350.0296 | N43: 0 | O43: 0 | P43: 0 | Q43: 0.9 | R43: 1 | S43: 7.6697525 | T43: 0.011854638 | U43: 2402.8615 | V43: 0.016216007 | W43: 0
...

Sheet >> TIMES

Sheet Def_Tech
B2: ~FI_Process
B3: Sets | C3: Region | D3: TechName | E3: TechDesc | F3: Tact | G3: Tcap | H3: Tslvl | I3: PrimaryCG | J3: Vintage
B4: *Process Set Membership | C4: Region | D4: Technology Name | E4: Technology Description | F4: Activity Unit | G4: Capacity Unit | H4: TimeSlice level of Process Activity | I4: Primary Commodity Group | J4: Vintage Tracking
B5: PRW | C5: CITY | D5: =LEFT(Def_Comm!C5,LEN(Def_Comm!C5)-3)&"INV" -> WASSOLPAPINV | E5: =Def_Comm!D5&" Inversion" -> Waste Solid Paper demand Inversion | F5: =Def_Comm!E5 -> kt | G5: =F5&"a" -> kta
C6: CITY | D6: =LEFT(Def_Comm!C6,LEN(Def_Comm!C6)-3)&"INV" -> WASSOLGLAINV | E6: =Def_Comm!D6&" Inversion" -> Waste Solid Glass demand Inversion | F6: =Def_Comm!E6 -> kt | G6: =F6&"a" -> kta
C7: CITY | D7: =LEFT(Def_Comm!C7,LEN(Def_Comm!C7)-3)&"INV" -> WASSOLMETINV | E7: =Def_Comm!D7&" Inversion" -> Waste Solid Metals demand Inversion | F7: =Def_Comm!E7 -> kt | G7: =F7&"a" -> kta
C8: CITY | D8: =LEFT(Def_Comm!C8,LEN(Def_Comm!C8)-3)&"INV" -> WASSOLPLAINV | E8: =Def_Comm!D8&" Inversion" -> Waste Solid Plastics demand Inversion | F8: =Def_Comm!E8 -> kt | G8: =F8&"a" -> kta
C9: CITY | D9: =LEFT(Def_Comm!C9,LEN(Def_Comm!C9)-3)&"INV" -> WASSOLFOOINV | E9: =Def_Comm!D9&" Inversion" -> Waste Solid Food demand Inversion | F9: =Def_Comm!E9 -> kt | G9: =F9&"a" -> kta
C10: CITY | D10: =LEFT(Def_Comm!C10,LEN(Def_Comm!C10)-3)&"INV" -> WASSOLYARINV | E10: =Def_Comm!D10&" Inversion" -> Waste Solid Yard trimmings demand Inversion | F10: =Def_Comm!E10 -> kt | G10: =F10&"a" -> kta
C11: CITY | D11: =LEFT(Def_Comm!C11,LEN(Def_Comm!C11)-3)&"INV" -> WASSOLAOTINV | E11: =Def_Comm!D11&" Inversion" -> Waste Solid All other demand Inversion | F11: =Def_Comm!E11 -> kt | G11: =F11&"a" -> kta
C12: CITY | D12: =LEFT(Def_Comm!C12,LEN(Def_Comm!C12)-3)&"INV" -> WASSOLHISINV | E12: =Def_Comm!D12&" Inversion" -> Waste Solid Historical demand Inversion | F12: =Def_Comm!E12 -> kt | G12: =F12&"a" -> kta
C13: CITY | D13: =LEFT(Def_Comm!C13,LEN(Def_Comm!C13)-3)&"INV" -> WASWATFWAINV | E13: =Def_Comm!D13&" Inversion" -> Waste Water Fresh Water demand Inversion | F13: =Def_Comm!E13 -> Mm3 | G13: =F13&"a" -> Mm3a
C14: CITY | D14: =LEFT(Def_Comm!C14,LEN(Def_Comm!C14)-3)&"INV" -> WASWATAPRINV | E14: =Def_Comm!D14&" Inversion" -> Waste Water Annual Precipitation demand Inversion | F14: =Def_Comm!E14 -> Mm3 | G14: =F14&"a" -> Mm3a
C15: CITY | D15: =LEFT(Def_Comm!C15,LEN(Def_Comm!C15)-3)&"INV" -> WASWATTRTINV | E15: =Def_Comm!D15&" Inversion" -> Waste Water Treatment demand Inversion | F15: =Def_Comm!E15 -> Mm3 | G15: =F15&"a" -> Mm3a
B16: *
B17: PRW | C17: CITY | D17: =LEFT(Def_Comm!C5,LEN(Def_Comm!C5)-3)&"TOLDF" -> WASSOLPAPTOLDF | E17: =Def_Comm!D5&" to landfill" -> Waste Solid Paper demand to landfill | F17: =Def_Comm!E17 -> kt | G17: =F17&"a" -> kta
C18: CITY | D18: =LEFT(Def_Comm!C6,LEN(Def_Comm!C6)-3)&"TOLDF" -> WASSOLGLATOLDF | E18: =Def_Comm!D6&" to landfill" -> Waste Solid Glass demand to landfill | F18: =Def_Comm!E18 -> kt | G18: =F18&"a" -> kta
C19: CITY | D19: =LEFT(Def_Comm!C7,LEN(Def_Comm!C7)-3)&"TOLDF" -> WASSOLMETTOLDF | E19: =Def_Comm!D7&" to landfill" -> Waste Solid Metals demand to landfill | F19: =Def_Comm!E19 -> kt | G19: =F19&"a" -> kta
C20: CITY | D20: =LEFT(Def_Comm!C8,LEN(Def_Comm!C8)-3)&"TOLDF" -> WASSOLPLATOLDF | E20: =Def_Comm!D8&" to landfill" -> Waste Solid Plastics demand to landfill | F20: =Def_Comm!E20 -> kt | G20: =F20&"a" -> kta
C21: CITY | D21: =LEFT(Def_Comm!C9,LEN(Def_Comm!C9)-3)&"TOLDF" -> WASSOLFOOTOLDF | E21: =Def_Comm!D9&" to landfill" -> Waste Solid Food demand to landfill | F21: =Def_Comm!E21 -> kt | G21: =F21&"a" -> kta
C22: CITY | D22: =LEFT(Def_Comm!C10,LEN(Def_Comm!C10)-3)&"TOLDF" -> WASSOLYARTOLDF | E22: =Def_Comm!D10&" to landfill" -> Waste Solid Yard trimmings demand to landfill | F22: =Def_Comm!E22 -> kt | G22: =F22&"a" -> kta
C23: CITY | D23: =LEFT(Def_Comm!C11,LEN(Def_Comm!C11)-3)&"TOLDF" -> WASSOLAOTTOLDF | E23: =Def_Comm!D11&" to landfill" -> Waste Solid All other demand to landfill | F23: =Def_Comm!E23 -> kt | G23: =F23&"a" -> kta
C24: CITY | D24: =LEFT(Def_Comm!C12,LEN(Def_Comm!C12)-3)&"TOLDF" -> WASSOLHISTOLDF | E24: =Def_Comm!D12&" to landfill" -> Waste Solid Historical demand to landfill | F24: =Def_Comm!E24 -> kt | G24: =F24&"a" -> kta
B25: *
B26: PRW | C26: CITY | D26: {=_xlfn.UNIQUE('WAS RESID'!K2:K93)} -> WASSOLPAPCMP19 | E26: =_xlfn.XLOOKUP(D26,'WAS RESID'!K:K,'WAS RESID'!A:A)&" "&_xlfn.XLOOKUP(D26,'WAS RESID'!K:K,'WAS RESID'!B:B)&" "&_xlfn.XLOOKUP(D26,'WAS RESID'!K:K,'WAS RESID'!C:C)&" "&_xlfn.XLOOKUP(D26,'WAS RESID'!K:K,'WAS RESID'!E:E) -> Waste Solid Paper Compost | F26: =IF(_xlfn.XLOOKUP(D26,'WAS RESID'!K:K,'WAS RESID'!B:B)="Solid","kt","Mm3") -> kt | G26: =IF(_xlfn.XLOOKUP(D26,'WAS RESID'!K:K,'WAS RESID'!B:B)="Solid","kta","Mm3a") -> kta | I26: =_xlfn.XLOOKUP(D26,'WAS RESID'!K:K,'WAS RESID'!J:J) -> WASSOLPAPDMDTOT
C27: CITY | D27: WASSOLGLACMP19 | E27: =_xlfn.XLOOKUP(D27,'WAS RESID'!K:K,'WAS RESID'!A:A)&" "&_xlfn.XLOOKUP(D27,'WAS RESID'!K:K,'WAS RESID'!B:B)&" "&_xlfn.XLOOKUP(D27,'WAS RESID'!K:K,'WAS RESID'!C:C)&" "&_xlfn.XLOOKUP(D27,'WAS RESID'!K:K,'WAS RESID'!E:E) -> Waste Solid Glass Compost | F27: =IF(_xlfn.XLOOKUP(D27,'WAS RESID'!K:K,'WAS RESID'!B:B)="Solid","kt","Mm3") -> kt | G27: =IF(_xlfn.XLOOKUP(D27,'WAS RESID'!K:K,'WAS RESID'!B:B)="Solid","kta","Mm3a") -> kta | I27: =_xlfn.XLOOKUP(D27,'WAS RESID'!K:K,'WAS RESID'!J:J) -> WASSOLGLADMDTOT
C28: CITY | D28: WASSOLMETCMP19 | E28: =_xlfn.XLOOKUP(D28,'WAS RESID'!K:K,'WAS RESID'!A:A)&" "&_xlfn.XLOOKUP(D28,'WAS RESID'!K:K,'WAS RESID'!B:B)&" "&_xlfn.XLOOKUP(D28,'WAS RESID'!K:K,'WAS RESID'!C:C)&" "&_xlfn.XLOOKUP(D28,'WAS RESID'!K:K,'WAS RESID'!E:E) -> Waste Solid Metals Compost | F28: =IF(_xlfn.XLOOKUP(D28,'WAS RESID'!K:K,'WAS RESID'!B:B)="Solid","kt","Mm3") -> kt | G28: =IF(_xlfn.XLOOKUP(D28,'WAS RESID'!K:K,'WAS RESID'!B:B)="Solid","kta","Mm3a") -> kta | I28: =_xlfn.XLOOKUP(D28,'WAS RESID'!K:K,'WAS RESID'!J:J) -> WASSOLMETDMDTOT
C29: CITY | D29: WASSOLPLACMP19 | E29: =_xlfn.XLOOKUP(D29,'WAS RESID'!K:K,'WAS RESID'!A:A)&" "&_xlfn.XLOOKUP(D29,'WAS RESID'!K:K,'WAS RESID'!B:B)&" "&_xlfn.XLOOKUP(D29,'WAS RESID'!K:K,'WAS RESID'!C:C)&" "&_xlfn.XLOOKUP(D29,'WAS RESID'!K:K,'WAS RESID'!E:E) -> Waste Solid Plastics Compost | F29: =IF(_xlfn.XLOOKUP(D29,'WAS RESID'!K:K,'WAS RESID'!B:B)="Solid","kt","Mm3") -> kt | G29: =IF(_xlfn.XLOOKUP(D29,'WAS RESID'!K:K,'WAS RESID'!B:B)="Solid","kta","Mm3a") -> kta | I29: =_xlfn.XLOOKUP(D29,'WAS RESID'!K:K,'WAS RESID'!J:J) -> WASSOLPLADMDTOT
C30: CITY | D30: WASSOLFOOCMP19 | E30: =_xlfn.XLOOKUP(D30,'WAS RESID'!K:K,'WAS RESID'!A:A)&" "&_xlfn.XLOOKUP(D30,'WAS RESID'!K:K,'WAS RESID'!B:B)&" "&_xlfn.XLOOKUP(D30,'WAS RESID'!K:K,'WAS RESID'!C:C)&" "&_xlfn.XLOOKUP(D30,'WAS RESID'!K:K,'WAS RESID'!E:E) -> Waste Solid Food Compost | F30: =IF(_xlfn.XLOOKUP(D30,'WAS RESID'!K:K,'WAS RESID'!B:B)="Solid","kt","Mm3") -> kt | G30: =IF(_xlfn.XLOOKUP(D30,'WAS RESID'!K:K,'WAS RESID'!B:B)="Solid","kta","Mm3a") -> kta | I30: =_xlfn.XLOOKUP(D30,'WAS RESID'!K:K,'WAS RESID'!J:J) -> WASSOLFOODMDTOT
C31: CITY | D31: WASSOLYARCMP19 | E31: =_xlfn.XLOOKUP(D31,'WAS RESID'!K:K,'WAS RESID'!A:A)&" "&_xlfn.XLOOKUP(D31,'WAS RESID'!K:K,'WAS RESID'!B:B)&" "&_xlfn.XLOOKUP(D31,'WAS RESID'!K:K,'WAS RESID'!C:C)&" "&_xlfn.XLOOKUP(D31,'WAS RESID'!K:K,'WAS RESID'!E:E) -> Waste Solid Yard trimmings Compost | F31: =IF(_xlfn.XLOOKUP(D31,'WAS RESID'!K:K,'WAS RESID'!B:B)="Solid","kt","Mm3") -> kt | G31: =IF(_xlfn.XLOOKUP(D31,'WAS RESID'!K:K,'WAS RESID'!B:B)="Solid","kta","Mm3a") -> kta | I31: =_xlfn.XLOOKUP(D31,'WAS RESID'!K:K,'WAS RESID'!J:J) -> WASSOLYARDMDTOT
C32: CITY | D32: WASSOLAOTCMP19 | E32: =_xlfn.XLOOKUP(D32,'WAS RESID'!K:K,'WAS RESID'!A:A)&" "&_xlfn.XLOOKUP(D32,'WAS RESID'!K:K,'WAS RESID'!B:B)&" "&_xlfn.XLOOKUP(D32,'WAS RESID'!K:K,'WAS RESID'!C:C)&" "&_xlfn.XLOOKUP(D32,'WAS RESID'!K:K,'WAS RESID'!E:E) -> Waste Solid All Other Compost | F32: =IF(_xlfn.XLOOKUP(D32,'WAS RESID'!K:K,'WAS RESID'!B:B)="Solid","kt","Mm3") -> kt | G32: =IF(_xlfn.XLOOKUP(D32,'WAS RESID'!K:K,'WAS RESID'!B:B)="Solid","kta","Mm3a") -> kta | I32: =_xlfn.XLOOKUP(D32,'WAS RESID'!K:K,'WAS RESID'!J:J) -> WASSOLAOTDMDTOT
C33: CITY | D33: WASSOLPAPADG19 | E33: =_xlfn.XLOOKUP(D33,'WAS RESID'!K:K,'WAS RESID'!A:A)&" "&_xlfn.XLOOKUP(D33,'WAS RESID'!K:K,'WAS RESID'!B:B)&" "&_xlfn.XLOOKUP(D33,'WAS RESID'!K:K,'WAS RESID'!C:C)&" "&_xlfn.XLOOKUP(D33,'WAS RESID'!K:K,'WAS RESID'!E:E) -> Waste Solid Paper Anaerobic Digestion | F33: =IF(_xlfn.XLOOKUP(D33,'WAS RESID'!K:K,'WAS RESID'!B:B)="Solid","kt","Mm3") -> kt | G33: =IF(_xlfn.XLOOKUP(D33,'WAS RESID'!K:K,'WAS RESID'!B:B)="Solid","kta","Mm3a") -> kta | I33: =_xlfn.XLOOKUP(D33,'WAS RESID'!K:K,'WAS RESID'!J:J) -> WASSOLPAPDMDTOT
C34: CITY | D34: WASSOLGLAADG19 | E34: =_xlfn.XLOOKUP(D34,'WAS RESID'!K:K,'WAS RESID'!A:A)&" "&_xlfn.XLOOKUP(D34,'WAS RESID'!K:K,'WAS RESID'!B:B)&" "&_xlfn.XLOOKUP(D34,'WAS RESID'!K:K,'WAS RESID'!C:C)&" "&_xlfn.XLOOKUP(D34,'WAS RESID'!K:K,'WAS RESID'!E:E) -> Waste Solid Glass Anaerobic Digestion | F34: =IF(_xlfn.XLOOKUP(D34,'WAS RESID'!K:K,'WAS RESID'!B:B)="Solid","kt","Mm3") -> kt | G34: =IF(_xlfn.XLOOKUP(D34,'WAS RESID'!K:K,'WAS RESID'!B:B)="Solid","kta","Mm3a") -> kta | I34: =_xlfn.XLOOKUP(D34,'WAS RESID'!K:K,'WAS RESID'!J:J) -> WASSOLGLADMDTOT
C35: CITY | D35: WASSOLMETADG19 | E35: =_xlfn.XLOOKUP(D35,'WAS RESID'!K:K,'WAS RESID'!A:A)&" "&_xlfn.XLOOKUP(D35,'WAS RESID'!K:K,'WAS RESID'!B:B)&" "&_xlfn.XLOOKUP(D35,'WAS RESID'!K:K,'WAS RESID'!C:C)&" "&_xlfn.XLOOKUP(D35,'WAS RESID'!K:K,'WAS RESID'!E:E) -> Waste Solid Metals Anaerobic Digestion | F35: =IF(_xlfn.XLOOKUP(D35,'WAS RESID'!K:K,'WAS RESID'!B:B)="Solid","kt","Mm3") -> kt | G35: =IF(_xlfn.XLOOKUP(D35,'WAS RESID'!K:K,'WAS RESID'!B:B)="Solid","kta","Mm3a") -> kta | I35: =_xlfn.XLOOKUP(D35,'WAS RESID'!K:K,'WAS RESID'!J:J) -> WASSOLMETDMDTOT
C36: CITY | D36: WASSOLPLAADG19 | E36: =_xlfn.XLOOKUP(D36,'WAS RESID'!K:K,'WAS RESID'!A:A)&" "&_xlfn.XLOOKUP(D36,'WAS RESID'!K:K,'WAS RESID'!B:B)&" "&_xlfn.XLOOKUP(D36,'WAS RESID'!K:K,'WAS RESID'!C:C)&" "&_xlfn.XLOOKUP(D36,'WAS RESID'!K:K,'WAS RESID'!E:E) -> Waste Solid Plastics Anaerobic Digestion | F36: =IF(_xlfn.XLOOKUP(D36,'WAS RESID'!K:K,'WAS RESID'!B:B)="Solid","kt","Mm3") -> kt | G36: =IF(_xlfn.XLOOKUP(D36,'WAS RESID'!K:K,'WAS RESID'!B:B)="Solid","kta","Mm3a") -> kta | I36: =_xlfn.XLOOKUP(D36,'WAS RESID'!K:K,'WAS RESID'!J:J) -> WASSOLPLADMDTOT
C37: CITY | D37: WASSOLFOOADG19 | E37: =_xlfn.XLOOKUP(D37,'WAS RESID'!K:K,'WAS RESID'!A:A)&" "&_xlfn.XLOOKUP(D37,'WAS RESID'!K:K,'WAS RESID'!B:B)&" "&_xlfn.XLOOKUP(D37,'WAS RESID'!K:K,'WAS RESID'!C:C)&" "&_xlfn.XLOOKUP(D37,'WAS RESID'!K:K,'WAS RESID'!E:E) -> Waste Solid Food Anaerobic Digestion | F37: =IF(_xlfn.XLOOKUP(D37,'WAS RESID'!K:K,'WAS RESID'!B:B)="Solid","kt","Mm3") -> kt | G37: =IF(_xlfn.XLOOKUP(D37,'WAS RESID'!K:K,'WAS RESID'!B:B)="Solid","kta","Mm3a") -> kta | I37: =_xlfn.XLOOKUP(D37,'WAS RESID'!K:K,'WAS RESID'!J:J) -> WASSOLFOODMDTOT
C38: CITY | D38: WASSOLYARADG19 | E38: =_xlfn.XLOOKUP(D38,'WAS RESID'!K:K,'WAS RESID'!A:A)&" "&_xlfn.XLOOKUP(D38,'WAS RESID'!K:K,'WAS RESID'!B:B)&" "&_xlfn.XLOOKUP(D38,'WAS RESID'!K:K,'WAS RESID'!C:C)&" "&_xlfn.XLOOKUP(D38,'WAS RESID'!K:K,'WAS RESID'!E:E) -> Waste Solid Yard trimmings Anaerobic Digestion | F38: =IF(_xlfn.XLOOKUP(D38,'WAS RESID'!K:K,'WAS RESID'!B:B)="Solid","kt","Mm3") -> kt | G38: =IF(_xlfn.XLOOKUP(D38,'WAS RESID'!K:K,'WAS RESID'!B:B)="Solid","kta","Mm3a") -> kta | I38: =_xlfn.XLOOKUP(D38,'WAS RESID'!K:K,'WAS RESID'!J:J) -> WASSOLYARDMDTOT
C39: CITY | D39: WASSOLAOTADG19 | E39: =_xlfn.XLOOKUP(D39,'WAS RESID'!K:K,'WAS RESID'!A:A)&" "&_xlfn.XLOOKUP(D39,'WAS RESID'!K:K,'WAS RESID'!B:B)&" "&_xlfn.XLOOKUP(D39,'WAS RESID'!K:K,'WAS RESID'!C:C)&" "&_xlfn.XLOOKUP(D39,'WAS RESID'!K:K,'WAS RESID'!E:E) -> Waste Solid All Other Anaerobic Digestion | F39: =IF(_xlfn.XLOOKUP(D39,'WAS RESID'!K:K,'WAS RESID'!B:B)="Solid","kt","Mm3") -> kt | G39: =IF(_xlfn.XLOOKUP(D39,'WAS RESID'!K:K,'WAS RESID'!B:B)="Solid","kta","Mm3a") -> kta | I39: =_xlfn.XLOOKUP(D39,'WAS RESID'!K:K,'WAS RESID'!J:J) -> WASSOLAOTDMDTOT
B40: ELE | C40: CITY | D40: WASSOLPAPINC19 | E40: =_xlfn.XLOOKUP(D40,'WAS RESID'!K:K,'WAS RESID'!A:A)&" "&_xlfn.XLOOKUP(D40,'WAS RESID'!K:K,'WAS RESID'!B:B)&" "&_xlfn.XLOOKUP(D40,'WAS RESID'!K:K,'WAS RESID'!C:C)&" "&_xlfn.XLOOKUP(D40,'WAS RESID'!K:K,'WAS RESID'!E:E) -> Waste Solid Paper Incineration | F40: =IF(_xlfn.XLOOKUP(D40,'WAS RESID'!K:K,'WAS RESID'!B:B)="Solid","kt","Mm3") -> kt | G40: =IF(_xlfn.XLOOKUP(D40,'WAS RESID'!K:K,'WAS RESID'!B:B)="Solid","kta","Mm3a") -> kta | H40: DAYNITE | I40: =_xlfn.XLOOKUP(D40,'WAS RESID'!K:K,'WAS RESID'!J:J) -> WASSOLPAPDMDTOT
C41: CITY | D41: WASSOLGLAINC19 | E41: =_xlfn.XLOOKUP(D41,'WAS RESID'!K:K,'WAS RESID'!A:A)&" "&_xlfn.XLOOKUP(D41,'WAS RESID'!K:K,'WAS RESID'!B:B)&" "&_xlfn.XLOOKUP(D41,'WAS RESID'!K:K,'WAS RESID'!C:C)&" "&_xlfn.XLOOKUP(D41,'WAS RESID'!K:K,'WAS RESID'!E:E) -> Waste Solid Glass Incineration | F41: =IF(_xlfn.XLOOKUP(D41,'WAS RESID'!K:K,'WAS RESID'!B:B)="Solid","kt","Mm3") -> kt | G41: =IF(_xlfn.XLOOKUP(D41,'WAS RESID'!K:K,'WAS RESID'!B:B)="Solid","kta","Mm3a") -> kta | H41: DAYNITE | I41: =_xlfn.XLOOKUP(D41,'WAS RESID'!K:K,'WAS RESID'!J:J) -> WASSOLGLADMDTOT
...

Sheet Def_Comm
B2: ~FI_Comm
B3: Csets | C3: CommName | D3: CommDesc | E3: Unit | F3: LimType | G3: CTSLvl | H3: PeakTS | I3: Ctype
B4: *Commodity Set Membership | C4: Commodity Name | D4: Commodity Description | E4: Unit | F4: Sense of the Balance EQN. | G4: Timeslice Level | H4: Peak Monitoring | I4: Electricity Indicator
B5: DEM | C5: =Demand!E55 -> WASSOLPAPDMD | D5: =Demand!A55&" "&Demand!B55&" "&Demand!C55&" "&Demand!D55&" "&"demand" -> Waste Solid Paper demand | E5: =IF(Demand!B55="Solid","kt","Mm3") -> kt | F5: FX
B6: DEM | C6: =Demand!E56 -> WASSOLGLADMD | D6: =Demand!A56&" "&Demand!B56&" "&Demand!C56&" "&Demand!D56&" "&"demand" -> Waste Solid Glass demand | E6: =IF(Demand!B56="Solid","kt","Mm3") -> kt | F6: FX
B7: DEM | C7: =Demand!E57 -> WASSOLMETDMD | D7: =Demand!A57&" "&Demand!B57&" "&Demand!C57&" "&Demand!D57&" "&"demand" -> Waste Solid Metals demand | E7: =IF(Demand!B57="Solid","kt","Mm3") -> kt | F7: FX
B8: DEM | C8: =Demand!E58 -> WASSOLPLADMD | D8: =Demand!A58&" "&Demand!B58&" "&Demand!C58&" "&Demand!D58&" "&"demand" -> Waste Solid Plastics demand | E8: =IF(Demand!B58="Solid","kt","Mm3") -> kt | F8: FX
B9: DEM | C9: =Demand!E59 -> WASSOLFOODMD | D9: =Demand!A59&" "&Demand!B59&" "&Demand!C59&" "&Demand!D59&" "&"demand" -> Waste Solid Food demand | E9: =IF(Demand!B59="Solid","kt","Mm3") -> kt | F9: FX
B10: DEM | C10: =Demand!E60 -> WASSOLYARDMD | D10: =Demand!A60&" "&Demand!B60&" "&Demand!C60&" "&Demand!D60&" "&"demand" -> Waste Solid Yard trimmings demand | E10: =IF(Demand!B60="Solid","kt","Mm3") -> kt | F10: FX
B11: DEM | C11: =Demand!E61 -> WASSOLAOTDMD | D11: =Demand!A61&" "&Demand!B61&" "&Demand!C61&" "&Demand!D61&" "&"demand" -> Waste Solid All other demand | E11: =IF(Demand!B61="Solid","kt","Mm3") -> kt | F11: FX
B12: DEM | C12: =Demand!E62 -> WASSOLHISDMD | D12: =Demand!A62&" "&Demand!B62&" "&Demand!C62&" "&Demand!D62&" "&"demand" -> Waste Solid Historical demand | E12: =IF(Demand!B62="Solid","kt","Mm3") -> kt | F12: FX
B13: DEM | C13: =Demand!E63 -> WASWATFWADMD | D13: =Demand!A63&" "&Demand!B63&" "&Demand!C63&" "&Demand!D63&" "&"demand" -> Waste Water Fresh Water demand | E13: =IF(Demand!B63="Solid","kt","Mm3") -> Mm3 | F13: FX
B14: DEM | C14: =Demand!E64 -> WASWATAPRDMD | D14: =Demand!A64&" "&Demand!B64&" "&Demand!C64&" "&Demand!D64&" "&"demand" -> Waste Water Annual Precipitation demand | E14: =IF(Demand!B64="Solid","kt","Mm3") -> Mm3 | F14: FX
B15: DEM | C15: =Demand!E66 -> WASWATTRTDMD | D15: =Demand!A66&" "&Demand!B66&" "&Demand!C66&" "&Demand!D66&" "&"demand" -> Waste Water Treatment demand | E15: =IF(Demand!B66="Solid","kt","Mm3") -> Mm3 | F15: FX
B16: *
B17: MAT | C17: =C5&"TOT" -> WASSOLPAPDMDTOT | D17: =D5&" total" -> Waste Solid Paper demand total | E17: =IF(Demand!B55="Solid","kt","Mm3") -> kt | F17: FX
B18: MAT | C18: =C6&"TOT" -> WASSOLGLADMDTOT | D18: =D6&" total" -> Waste Solid Glass demand total | E18: =IF(Demand!B56="Solid","kt","Mm3") -> kt | F18: FX
B19: MAT | C19: =C7&"TOT" -> WASSOLMETDMDTOT | D19: =D7&" total" -> Waste Solid Metals demand total | E19: =IF(Demand!B57="Solid","kt","Mm3") -> kt | F19: FX
B20: MAT | C20: =C8&"TOT" -> WASSOLPLADMDTOT | D20: =D8&" total" -> Waste Solid Plastics demand total | E20: =IF(Demand!B58="Solid","kt","Mm3") -> kt | F20: FX
B21: MAT | C21: =C9&"TOT" -> WASSOLFOODMDTOT | D21: =D9&" total" -> Waste Solid Food demand total | E21: =IF(Demand!B59="Solid","kt","Mm3") -> kt | F21: FX
B22: MAT | C22: =C10&"TOT" -> WASSOLYARDMDTOT | D22: =D10&" total" -> Waste Solid Yard trimmings demand total | E22: =IF(Demand!B60="Solid","kt","Mm3") -> kt | F22: FX
B23: MAT | C23: =C11&"TOT" -> WASSOLAOTDMDTOT | D23: =D11&" total" -> Waste Solid All other demand total | E23: =IF(Demand!B61="Solid","kt","Mm3") -> kt | F23: FX
B24: MAT | C24: =C12&"TOT" -> WASSOLHISDMDTOT | D24: =D12&" total" -> Waste Solid Historical demand total | E24: =IF(Demand!B62="Solid","kt","Mm3") -> kt | F24: FX
B25: MAT | C25: =C13&"TOT" -> WASWATFWADMDTOT | D25: =D13&" total" -> Waste Water Fresh Water demand total | E25: =IF(Demand!B63="Solid","kt","Mm3") -> Mm3 | F25: FX
B26: MAT | C26: =C14&"TOT" -> WASWATAPRDMDTOT | D26: =D14&" total" -> Waste Water Annual Precipitation demand total | E26: =IF(Demand!B64="Solid","kt","Mm3") -> Mm3 | F26: FX
B27: MAT | C27: =C15&"TOT" -> WASWATTRTDMDTOT | D27: =D15&" total" -> Waste Water Treatment demand total | E27: =IF(Demand!B66="Solid","kt","Mm3") -> Mm3 | F27: FX
B28: *
B29: MAT | C29: =C17&"TOLDF" -> WASSOLPAPDMDTOTTOLDF | D29: =D17&" to landfill" -> Waste Solid Paper demand total to landfill | E29: =E17 -> kt | F29: FX
B30: MAT | C30: =C18&"TOLDF" -> WASSOLGLADMDTOTTOLDF | D30: =D18&" to landfill" -> Waste Solid Glass demand total to landfill | E30: =E18 -> kt | F30: FX
B31: MAT | C31: =C19&"TOLDF" -> WASSOLMETDMDTOTTOLDF | D31: =D19&" to landfill" -> Waste Solid Metals demand total to landfill | E31: =E19 -> kt | F31: FX
B32: MAT | C32: =C20&"TOLDF" -> WASSOLPLADMDTOTTOLDF | D32: =D20&" to landfill" -> Waste Solid Plastics demand total to landfill | E32: =E20 -> kt | F32: FX
B33: MAT | C33: =C21&"TOLDF" -> WASSOLFOODMDTOTTOLDF | D33: =D21&" to landfill" -> Waste Solid Food demand total to landfill | E33: =E21 -> kt | F33: FX
B34: MAT | C34: =C22&"TOLDF" -> WASSOLYARDMDTOTTOLDF | D34: =D22&" to landfill" -> Waste Solid Yard trimmings demand total to landfill | E34: =E22 -> kt | F34: FX
B35: MAT | C35: =C23&"TOLDF" -> WASSOLAOTDMDTOTTOLDF | D35: =D23&" to landfill" -> Waste Solid All other demand total to landfill | E35: =E23 -> kt | F35: FX
B36: MAT | C36: =C24&"TOLDF" -> WASSOLHISDMDTOTTOLDF | D36: =D24&" to landfill" -> Waste Solid Historical demand total to landfill | E36: =E24 -> kt | F36: FX
B37: *
B38: NRG | C38: {=_xlfn._xlws.FILTER(_xlfn.UNIQUE('WAS RESID'!H114:H145),_xlfn.UNIQUE('WAS RESID'!H114:H145)<>0,"")} -> WASSOLADGBGA | D38: =_xlfn.XLOOKUP(C38,'WAS RESID'!$H$114:$H$145,'WAS RESID'!$A$114:$A$145)&" "&_xlfn.XLOOKUP(C38,'WAS RESID'!$H$114:$H$145,'WAS RESID'!$B$114:$B$145)&" "&_xlfn.XLOOKUP(C38,'WAS RESID'!$H$114:$H$145,'WAS RESID'!$C$114:$C$145)&" "&_xlfn.XLOOKUP(C38,'WAS RESID'!$H$114:$H$145,'WAS RESID'!$G$114:$G$145) -> Waste Solid Anaerobic Digestion Biogas | E38: TJ | F38: FX
B39: NRG | C39: WASSOLLDFBGA | D39: =_xlfn.XLOOKUP(C39,'WAS RESID'!$H$114:$H$145,'WAS RESID'!$A$114:$A$145)&" "&_xlfn.XLOOKUP(C39,'WAS RESID'!$H$114:$H$145,'WAS RESID'!$B$114:$B$145)&" "&_xlfn.XLOOKUP(C39,'WAS RESID'!$H$114:$H$145,'WAS RESID'!$C$114:$C$145)&" "&_xlfn.XLOOKUP(C39,'WAS RESID'!$H$114:$H$145,'WAS RESID'!$G$114:$G$145) -> Waste Solid Landfill Biogas | E39: TJ | F39: FX
B40: NRG | C40: WASWATWADBGA | D40: =_xlfn.XLOOKUP(C40,'WAS RESID'!$H$114:$H$145,'WAS RESID'!$A$114:$A$145)&" "&_xlfn.XLOOKUP(C40,'WAS RESID'!$H$114:$H$145,'WAS RESID'!$B$114:$B$145)&" "&_xlfn.XLOOKUP(C40,'WAS RESID'!$H$114:$H$145,'WAS RESID'!$C$114:$C$145)&" "&_xlfn.XLOOKUP(C40,'WAS RESID'!$H$114:$H$145,'WAS RESID'!$G$114:$G$145) -> Waste Water Treatment Plant without De-Nitrification and with Anaerobic Digesters Biogas | E40: TJ | F40: FX
B41: NRG | C41: WASWATWANBGA | D41: =_xlfn.XLOOKUP(C41,'WAS RESID'!$H$114:$H$145,'WAS RESID'!$A$114:$A$145)&" "&_xlfn.XLOOKUP(C41,'WAS RESID'!$H$114:$H$145,'WAS RESID'!$B$114:$B$145)&" "&_xlfn.XLOOKUP(C41,'WAS RESID'!$H$114:$H$145,'WAS RESID'!$C$114:$C$145)&" "&_xlfn.XLOOKUP(C41,'WAS RESID'!$H$114:$H$145,'WAS RESID'!$G$114:$G$145) -> Waste Water Treatment Plant with De-Nitrification and with Anaerobic Digesters Biogas | E41: TJ | F41: FX
...

Sheet DemandTrans
C2: ~FI_T | J2: ~FI_T
B3: TechName | C3: Comm-OUT | D3: Attribute | E3: CITY | H3: TechName | I3: Comm-IN | J3: Comm-OUT | K3: Attribute | L3: CITY
B4: * | H4: *
B5: =Def_Tech!D5 -> WASSOLPAPINV | C5: =Def_Comm!C5 -> WASSOLPAPDMD | D5: Output | E5: 1 | H5: =Def_Tech!D17 -> WASSOLPAPTOLDF | I5: =C16 -> WASSOLPAPDMDTOT | J5: =Def_Comm!C29 -> WASSOLPAPDMDTOTTOLDF | K5: Output | L5: 1
B6: =Def_Tech!D6 -> WASSOLGLAINV | C6: =Def_Comm!C6 -> WASSOLGLADMD | D6: Output | E6: 1 | H6: =Def_Tech!D18 -> WASSOLGLATOLDF | I6: =C17 -> WASSOLGLADMDTOT | J6: =Def_Comm!C30 -> WASSOLGLADMDTOTTOLDF | K6: Output | L6: 1
B7: =Def_Tech!D7 -> WASSOLMETINV | C7: =Def_Comm!C7 -> WASSOLMETDMD | D7: Output | E7: 1 | H7: =Def_Tech!D19 -> WASSOLMETTOLDF | I7: =C18 -> WASSOLMETDMDTOT | J7: =Def_Comm!C31 -> WASSOLMETDMDTOTTOLDF | K7: Output | L7: 1
B8: =Def_Tech!D8 -> WASSOLPLAINV | C8: =Def_Comm!C8 -> WASSOLPLADMD | D8: Output | E8: 1 | H8: =Def_Tech!D20 -> WASSOLPLATOLDF | I8: =C19 -> WASSOLPLADMDTOT | J8: =Def_Comm!C32 -> WASSOLPLADMDTOTTOLDF | K8: Output | L8: 1
B9: =Def_Tech!D9 -> WASSOLFOOINV | C9: =Def_Comm!C9 -> WASSOLFOODMD | D9: Output | E9: 1 | H9: =Def_Tech!D21 -> WASSOLFOOTOLDF | I9: =C20 -> WASSOLFOODMDTOT | J9: =Def_Comm!C33 -> WASSOLFOODMDTOTTOLDF | K9: Output | L9: 1
B10: =Def_Tech!D10 -> WASSOLYARINV | C10: =Def_Comm!C10 -> WASSOLYARDMD | D10: Output | E10: 1 | H10: =Def_Tech!D22 -> WASSOLYARTOLDF | I10: =C21 -> WASSOLYARDMDTOT | J10: =Def_Comm!C34 -> WASSOLYARDMDTOTTOLDF | K10: Output | L10: 1
B11: =Def_Tech!D11 -> WASSOLAOTINV | C11: =Def_Comm!C11 -> WASSOLAOTDMD | D11: Output | E11: 1 | H11: =Def_Tech!D23 -> WASSOLAOTTOLDF | I11: =C22 -> WASSOLAOTDMDTOT | J11: =Def_Comm!C35 -> WASSOLAOTDMDTOTTOLDF | K11: Output | L11: 1
B12: =Def_Tech!D12 -> WASSOLHISINV | C12: =Def_Comm!C12 -> WASSOLHISDMD | D12: Output | E12: 1 | H12: =Def_Tech!D24 -> WASSOLHISTOLDF | I12: =C23 -> WASSOLHISDMDTOT | J12: =Def_Comm!C36 -> WASSOLHISDMDTOTTOLDF | K12: Output | L12: 1
B13: =Def_Tech!D13 -> WASWATFWAINV | C13: =Def_Comm!C13 -> WASWATFWADMD | D13: Output | E13: 1 | H13: =H5 -> WASSOLPAPTOLDF | I13: =I5 -> WASSOLPAPDMDTOT | J13: =J5 -> WASSOLPAPDMDTOTTOLDF | K13: Input | L13: 1
B14: =Def_Tech!D14 -> WASWATAPRINV | C14: =Def_Comm!C14 -> WASWATAPRDMD | D14: Output | E14: 1 | H14: =H6 -> WASSOLGLATOLDF | I14: =I6 -> WASSOLGLADMDTOT | J14: =J6 -> WASSOLGLADMDTOTTOLDF | K14: Input | L14: 1
B15: =Def_Tech!D15 -> WASWATTRTINV | C15: =Def_Comm!C15 -> WASWATTRTDMD | D15: Output | E15: 1 | H15: =H7 -> WASSOLMETTOLDF | I15: =I7 -> WASSOLMETDMDTOT | J15: =J7 -> WASSOLMETDMDTOTTOLDF | K15: Input | L15: 1
B16: =Def_Tech!D5 -> WASSOLPAPINV | C16: =Def_Comm!C17 -> WASSOLPAPDMDTOT | D16: Output | E16: 1 | H16: =H8 -> WASSOLPLATOLDF | I16: =I8 -> WASSOLPLADMDTOT | J16: =J8 -> WASSOLPLADMDTOTTOLDF | K16: Input | L16: 1
B17: =Def_Tech!D6 -> WASSOLGLAINV | C17: =Def_Comm!C18 -> WASSOLGLADMDTOT | D17: Output | E17: 1 | H17: =H9 -> WASSOLFOOTOLDF | I17: =I9 -> WASSOLFOODMDTOT | J17: =J9 -> WASSOLFOODMDTOTTOLDF | K17: Input | L17: 1
B18: =Def_Tech!D7 -> WASSOLMETINV | C18: =Def_Comm!C19 -> WASSOLMETDMDTOT | D18: Output | E18: 1 | H18: =H10 -> WASSOLYARTOLDF | I18: =I10 -> WASSOLYARDMDTOT | J18: =J10 -> WASSOLYARDMDTOTTOLDF | K18: Input | L18: 1
B19: =Def_Tech!D8 -> WASSOLPLAINV | C19: =Def_Comm!C20 -> WASSOLPLADMDTOT | D19: Output | E19: 1 | H19: =H11 -> WASSOLAOTTOLDF | I19: =I11 -> WASSOLAOTDMDTOT | J19: =J11 -> WASSOLAOTDMDTOTTOLDF | K19: Input | L19: 1
B20: =Def_Tech!D9 -> WASSOLFOOINV | C20: =Def_Comm!C21 -> WASSOLFOODMDTOT | D20: Output | E20: 1 | H20: =H12 -> WASSOLHISTOLDF | I20: =I12 -> WASSOLHISDMDTOT | J20: =J12 -> WASSOLHISDMDTOTTOLDF | K20: Input | L20: 1
B21: =Def_Tech!D10 -> WASSOLYARINV | C21: =Def_Comm!C22 -> WASSOLYARDMDTOT | D21: Output | E21: 1
B22: =Def_Tech!D11 -> WASSOLAOTINV | C22: =Def_Comm!C23 -> WASSOLAOTDMDTOT | D22: Output | E22: 1
B23: =Def_Tech!D12 -> WASSOLHISINV | C23: =Def_Comm!C24 -> WASSOLHISDMDTOT | D23: Output | E23: 1
B24: =Def_Tech!D13 -> WASWATFWAINV | C24: =Def_Comm!C25 -> WASWATFWADMDTOT | D24: Output | E24: 0
B25: =Def_Tech!D14 -> WASWATAPRINV | C25: =Def_Comm!C26 -> WASWATAPRDMDTOT | D25: Output | E25: 0
B26: =Def_Tech!D15 -> WASWATTRTINV | C26: =Def_Comm!C27 -> WASWATTRTDMDTOT | D26: Output | E26: 1

Sheet ResidWAS
AB1: ='City characteristics'!C20 -> 2019
AB2: PRC_RESID
C4: ~FI_T | H4: ~FI_T | M4: ~FI_T | R4: ~FI_T | X4: ~FI_T
B5: TechName | C5: Comm-IN | D5: Attribute | E5: CITY | G5: TechName | H5: Comm-OUT | I5: Attribute | J5: CITY | L5: TechName | M5: Comm-IN | N5: Attribute | O5: CITY | Q5: TechName | R5: Comm-OUT | S5: Attribute | T5: CITY | V5: Region | W5: TechName | X5: PRC_CAPACT | Y5: NCAP_AFA | Z5: NCAP_TLIFE | AA5: NCAP_FOM | AB5: =AB2&"~"&AB1 -> PRC_RESID~2019
B6: * | G6: * | L6: * | Q6: * | V6: * | W6: * | X6: kta/kt | Y6: % | Z6: Yr | AA6: $ /kW / Yr | AB6: kt
B7: =Def_Tech!D26 -> WASSOLPAPCMP19 | C7: =Def_Tech!I26 -> WASSOLPAPDMDTOT | D7: Input | E7: 1 | G7: =Def_Tech!D47 -> WASSOLPAPLDF19 | H7: =Def_Comm!C43 -> WASSOLPAPLDFDEC | I7: Output | J7: 1 | L7: {=_xlfn._xlws.FILTER('WAS RESID'!K2:K93,'WAS RESID'!F2:F93="IN","")} -> WASSOLPAPCMP19 | M7: {=_xlfn._xlws.FILTER('WAS RESID'!H2:H93,'WAS RESID'!F2:F93="IN","")} -> WASELC | N7: Input | O7: {=_xlfn._xlws.FILTER('WAS RESID'!S2:S93,'WAS RESID'!F2:F93="IN","")} -> 0.0037198608 | Q7: {=_xlfn._xlws.FILTER('WAS RESID'!K2:K93,'WAS RESID'!F2:F93="OUT","")} -> WASSOLPAPADG19 | R7: {=_xlfn._xlws.FILTER('WAS RESID'!I2:I93,'WAS RESID'!F2:F93="OUT","")} -> WASSOLADGBGA | S7: Output | T7: {=_xlfn._xlws.FILTER('WAS RESID'!S2:S93,'WAS RESID'!F2:F93="OUT","")} -> 2.5551929 | V7: =Def_Tech!C26 -> CITY | W7: =Def_Tech!D26 -> WASSOLPAPCMP19 | X7: =_xlfn.XLOOKUP(W7,'WAS RESID'!K:K,'WAS RESID'!R:R) -> 1 | Y7: =_xlfn.XLOOKUP(W7,'WAS RESID'!K:K,'WAS RESID'!Q:Q) -> 0.9 | Z7: 20 | AA7: 1 | AB7: =_xlfn.XLOOKUP(W7,'WAS RESID'!K:K,'WAS RESID'!P:P) -> 0
B8: =Def_Tech!D27 -> WASSOLGLACMP19 | C8: =Def_Tech!I27 -> WASSOLGLADMDTOT | D8: Input | E8: 1 | G8: =Def_Tech!D48 -> WASSOLGLALDF19 | H8: =Def_Comm!C44 -> WASSOLGLALDFDEC | I8: Output | J8: 1 | L8: WASSOLPAPCMP19 | M8: WASDSL | N8: Input | O8: 0.0050435779 | Q8: WASSOLGLAADG19 | R8: WASSOLADGBGA | S8: Output | T8: 0 | V8: =Def_Tech!C27 -> CITY | W8: =Def_Tech!D27 -> WASSOLGLACMP19 | X8: =_xlfn.XLOOKUP(W8,'WAS RESID'!K:K,'WAS RESID'!R:R) -> 1 | Y8: =_xlfn.XLOOKUP(W8,'WAS RESID'!K:K,'WAS RESID'!Q:Q) -> 0.9 | Z8: 20 | AA8: 1 | AB8: =_xlfn.XLOOKUP(W8,'WAS RESID'!K:K,'WAS RESID'!P:P) -> 0
B9: =Def_Tech!D28 -> WASSOLMETCMP19 | C9: =Def_Tech!I28 -> WASSOLMETDMDTOT | D9: Input | E9: 1 | G9: =Def_Tech!D49 -> WASSOLMETLDF19 | H9: =Def_Comm!C45 -> WASSOLMETLDFDEC | I9: Output | J9: 1 | L9: WASSOLGLACMP19 | M9: WASELC | N9: Input | O9: 0.0032929234 | Q9: WASSOLMETADG19 | R9: WASSOLADGBGA | S9: Output | T9: 0 | V9: =Def_Tech!C28 -> CITY | W9: =Def_Tech!D28 -> WASSOLMETCMP19 | X9: =_xlfn.XLOOKUP(W9,'WAS RESID'!K:K,'WAS RESID'!R:R) -> 1 | Y9: =_xlfn.XLOOKUP(W9,'WAS RESID'!K:K,'WAS RESID'!Q:Q) -> 0.9 | Z9: 20 | AA9: 1 | AB9: =_xlfn.XLOOKUP(W9,'WAS RESID'!K:K,'WAS RESID'!P:P) -> 0
B10: =Def_Tech!D29 -> WASSOLPLACMP19 | C10: =Def_Tech!I29 -> WASSOLPLADMDTOT | D10: Input | E10: 1 | G10: =Def_Tech!D50 -> WASSOLPLALDF19 | H10: =Def_Comm!C46 -> WASSOLPLALDFDEC | I10: Output | J10: 1 | L10: WASSOLGLACMP19 | M10: WASDSL | N10: Input | O10: 0.0038630599 | Q10: WASSOLPLAADG19 | R10: WASSOLADGBGA | S10: Output | T10: 0 | V10: =Def_Tech!C29 -> CITY | W10: =Def_Tech!D29 -> WASSOLPLACMP19 | X10: =_xlfn.XLOOKUP(W10,'WAS RESID'!K:K,'WAS RESID'!R:R) -> 1 | Y10: =_xlfn.XLOOKUP(W10,'WAS RESID'!K:K,'WAS RESID'!Q:Q) -> 0.9 | Z10: 20 | AA10: 1 | AB10: =_xlfn.XLOOKUP(W10,'WAS RESID'!K:K,'WAS RESID'!P:P) -> 0
B11: =Def_Tech!D30 -> WASSOLFOOCMP19 | C11: =Def_Tech!I30 -> WASSOLFOODMDTOT | D11: Input | E11: 1 | G11: =Def_Tech!D51 -> WASSOLFOOLDF19 | H11: =Def_Comm!C47 -> WASSOLFOOLDFDEC | I11: Output | J11: 1 | L11: WASSOLMETCMP19 | M11: WASELC | N11: Input | O11: 0.0032855945 | Q11: WASSOLFOOADG19 | R11: WASSOLADGBGA | S11: Output | T11: 4.2239471 | V11: =Def_Tech!C30 -> CITY | W11: =Def_Tech!D30 -> WASSOLFOOCMP19 | X11: =_xlfn.XLOOKUP(W11,'WAS RESID'!K:K,'WAS RESID'!R:R) -> 1 | Y11: =_xlfn.XLOOKUP(W11,'WAS RESID'!K:K,'WAS RESID'!Q:Q) -> 0.9 | Z11: 20 | AA11: 1 | AB11: =_xlfn.XLOOKUP(W11,'WAS RESID'!K:K,'WAS RESID'!P:P) -> 105.0023
B12: =Def_Tech!D31 -> WASSOLYARCMP19 | C12: =Def_Tech!I31 -> WASSOLYARDMDTOT | D12: Input | E12: 1 | G12: =Def_Tech!D52 -> WASSOLYARLDF19 | H12: =Def_Comm!C48 -> WASSOLYARLDFDEC | I12: Output | J12: 1 | L12: WASSOLMETCMP19 | M12: WASDSL | N12: Input | O12: 0.0038606586 | Q12: WASSOLYARADG19 | R12: WASSOLADGBGA | S12: Output | T12: 1.2089642 | V12: =Def_Tech!C31 -> CITY | W12: =Def_Tech!D31 -> WASSOLYARCMP19 | X12: =_xlfn.XLOOKUP(W12,'WAS RESID'!K:K,'WAS RESID'!R:R) -> 1 | Y12: =_xlfn.XLOOKUP(W12,'WAS RESID'!K:K,'WAS RESID'!Q:Q) -> 0.9 | Z12: 20 | AA12: 1 | AB12: =_xlfn.XLOOKUP(W12,'WAS RESID'!K:K,'WAS RESID'!P:P) -> 31.83686
B13: =Def_Tech!D32 -> WASSOLAOTCMP19 | C13: =Def_Tech!I32 -> WASSOLAOTDMDTOT | D13: Input | E13: 1 | G13: =Def_Tech!D53 -> WASSOLAOTLDF19 | H13: =Def_Comm!C49 -> WASSOLAOTLDFDEC | I13: Output | J13: 1 | L13: WASSOLPLACMP19 | M13: WASELC | N13: Input | O13: 0.0032574407 | Q13: WASSOLAOTADG19 | R13: WASSOLADGBGA | S13: Output | T13: 0.19326305 | V13: =Def_Tech!C32 -> CITY | W13: =Def_Tech!D32 -> WASSOLAOTCMP19 | X13: =_xlfn.XLOOKUP(W13,'WAS RESID'!K:K,'WAS RESID'!R:R) -> 1 | Y13: =_xlfn.XLOOKUP(W13,'WAS RESID'!K:K,'WAS RESID'!Q:Q) -> 0.9 | Z13: 20 | AA13: 1 | AB13: =_xlfn.XLOOKUP(W13,'WAS RESID'!K:K,'WAS RESID'!P:P) -> 0
B14: =Def_Tech!D33 -> WASSOLPAPADG19 | C14: =Def_Tech!I33 -> WASSOLPAPDMDTOT | D14: Input | E14: 1 | G14: =Def_Tech!D61 -> WASSOLHISLDF19 | H14: =Def_Comm!C50 -> WASSOLHISLDFDEC | I14: Output | J14: 1 | L14: WASSOLPLACMP19 | M14: WASDSL | N14: Input | O14: 0.0041616592 | Q14: WASSOLPAPINC19 | R14: CELC | S14: Output | T14: 2.70904 | V14: =Def_Tech!C33 -> CITY | W14: =Def_Tech!D33 -> WASSOLPAPADG19 | X14: =_xlfn.XLOOKUP(W14,'WAS RESID'!K:K,'WAS RESID'!R:R) -> 1 | Y14: =_xlfn.XLOOKUP(W14,'WAS RESID'!K:K,'WAS RESID'!Q:Q) -> 0.9 | Z14: 20 | AA14: 1 | AB14: =_xlfn.XLOOKUP(W14,'WAS RESID'!K:K,'WAS RESID'!P:P) -> 0
B15: =Def_Tech!D34 -> WASSOLGLAADG19 | C15: =Def_Tech!I34 -> WASSOLGLADMDTOT | D15: Input | E15: 1 | L15: WASSOLFOOCMP19 | M15: WASELC | N15: Input | O15: 0.0048784913 | Q15: WASSOLPAPINC19 | R15: STM | S15: Output | T15: 5.41808 | V15: =Def_Tech!C34 -> CITY | W15: =Def_Tech!D34 -> WASSOLGLAADG19 | X15: =_xlfn.XLOOKUP(W15,'WAS RESID'!K:K,'WAS RESID'!R:R) -> 1 | Y15: =_xlfn.XLOOKUP(W15,'WAS RESID'!K:K,'WAS RESID'!Q:Q) -> 0.9 | Z15: 20 | AA15: 1 | AB15: =_xlfn.XLOOKUP(W15,'WAS RESID'!K:K,'WAS RESID'!P:P) -> 0
