Workbook

Sheet ReadMe
A1: Generic Comet (GC) TIMES Supply
B3: Sheet color
C4: Raw Data and Parameters
C6: City Specific Data
C8: Post processing for TIMES
C10: Table formatted for TIMES

Sheet >> City Data

Sheet City characteristics
B2: City Basic Data
B4: Calibration methodology | C4: GHG Inventory
B6: A. City Characteristics
B7: Data Item | C7: Value | D7: Units
B8: City Name | C8: New York
B9: Latitude | C9: 40.5
B10: Longitude | C10: -75
B11: County | C11: New York County
B12: State | C12: New York
B13: Census Division | C13: Middle Atlantic
B14: Climate Division | C14: Northeast
B15: Egrid Region | C15: NPCC NYC/Westchester
B16: Area of city (excluding water, natural and agricultural areas) | C16: 778 | D16: square kilometers
B17: * Division and Region Map can be found in the Maps sheet.
B18: B. Planning Base Year and Target Years
B19: Year | C19: Value | D19: Units
B20: Base Year | C20: 2019 | D20: Acceptable range [2018,2021]
B21: End Year | C21: 2050
B23: C. City Population and GDP
B24: Data Item | C24: Value | D24: Units
B25: Population in Base Year | C25: 8337 | D25: Thousand of people
B26: Annual population growth (Base Year - End Year) | C26: 0.5 | D26: % people
B27: GDP in Base Year | C27: 1206000 | D27: Million US$
B28: Annual GDP growth rate | C28: 2 | D28: % US$
B29: Share of manufacturing GDP | C29: 5 | D29: % US$
B30: Share of State population | C30: 0.42835123
B31: Share of State GDP | C31: 0.67251772
B32: Adjustment from state manufacturing GDP | C32: 1.0638298
B34: D. Climate Data
B35: Data Item | C35: 2000 | D35: 2050 | E35: 2100 | F35: Units
B36: Heating degree days (HDD) | C36: 4473.4625 | D36: 4066.4182 | E36: 3763.8582 | F36: F
B37: Cooling degree days (CDD) | C37: 1020.7333 | D37: 1224.2555 | E37: 1375.5355 | F37: F
B39: Data Item | C39: Value | D39: Units
B40: Correction from State HDD | C40: 0.72727402
B41: Correction from State CDD | C41: 1.5583715
B42: Annual precipitation | C42: 762 | D42: mm / year
B43: Climate change scenario | C43: RCP4.5
B44: Average temperature increase in 1980-2020 | C44: 1.4617857 | D44: F
B45: Forecasted average temperature increase in 2035-2065 | C45: 3.13 | D45: F
B46: Forecasted average temperature increase in 2070-2100 | C46: 4.37 | D46: F
...

Sheet >> GC_NewTech

Sheet TRA TECH
Q1: 2020 | R1: 2025 | S1: 2030 | T1: 2035 | U1: 2040 | V1: 2045 | W1: 2050 | X1: 2020 | Y1: 2025 | Z1: 2030 | AA1: 2035 | AB1: 2040 | AC1: 2045 | AD1: 2050 | AE1: 2020 | AF1: 2025 | AG1: 2030 | AH1: 2035 | AI1: 2040 | AJ1: 2045 | AK1: 2050
A2: Sector | B2: Sub-sector | C2: Archetype | D2: Vintage | E2: End Use | F2: Technology | G2: Energy | H2: Input Label | I2: Output Label | J2: Technology Label | K2: Capacity Unit | L2: Main fuel | M2: To include | N2: First year of availability | O2: Lifetime (yr) | P2: MAX FUEL SHARE (%) | Q2: EFF (Vkm/MJ) | X2: CAPEX (Thousands US$ 2023 / Mvkm) | AE2: Fixed OPEX (Thousands US$ 2023 / Mvkm)
A3: Transportation | B3: Passenger | C3: Passenger Car | F3: Gasoline ICE Vehicle (spark ignition) | G3: Gasoline | H3: TRAGSL | I3: TRAPASCARDMD | J3: TRAPASCARICEVGSL20 | K3: Mvkm | L3: 1 | M3: 1 | N3: 2020 | O3: 16.861274 | P3: 1 | Q3: 0.37474421 | R3: 0.3694381 | S3: 0.42979513 | T3: 0.46959098 | U3: 0.49413175 | V3: 0.51800926 | W3: 0.54255003 | X3: 149.37153 | Y3: 151.86106 | Z3: 152.21671 | AA3: 163.95304 | AB3: 162.17481 | AC3: 160.04093 | AD3: 157.90705 | AE3: 5.2309413 | AF3: 5.2309413 | AG3: 5.2309413 | AH3: 5.2309413 | AI3: 5.2309413 | AJ3: 5.2309413 | AK3: 5.2309413
A4: Transportation | B4: Passenger | C4: Passenger Car | F4: Gasoline ICE Vehicle (spark ignition) | G4: Ethanol | H4: TRAETH | I4: TRAPASCARDMD | J4: TRAPASCARICEVGSL20 | K4: Mvkm | L4: 0 | M4: 1 | N4: 2020 | O4: 16.861274 | P4: 0.1 | Q4: 0.37474421 | R4: 0.3694381 | S4: 0.42979513 | T4: 0.46959098 | U4: 0.49413175 | V4: 0.51800926 | W4: 0.54255003 | X4: 149.37153 | Y4: 151.86106 | Z4: 152.21671 | AA4: 163.95304 | AB4: 162.17481 | AC4: 160.04093 | AD4: 157.90705 | AE4: 5.2309413 | AF4: 5.2309413 | AG4: 5.2309413 | AH4: 5.2309413 | AI4: 5.2309413 | AJ4: 5.2309413 | AK4: 5.2309413
A5: Transportation | B5: Passenger | C5: Passenger Car | F5: Gasoline ICE Vehicle (spark ignition with turbo) | G5: Gasoline | H5: TRAGSL | I5: TRAPASCARDMD | J5: TRAPASCARICEVTGSL20 | K5: Mvkm | L5: 1 | M5: 1 | N5: 2020 | O5: 16.861274 | P5: 1 | Q5: 0.41785638 | R5: 0.41586659 | S5: 0.46627466 | T5: 0.50540724 | U5: 0.53326433 | V5: 0.56112142 | W5: 0.59030504 | X5: 157.19576 | Y5: 156.12882 | Z5: 159.32964 | AA5: 165.73127 | AB5: 165.37563 | AC5: 165.01998 | AD5: 164.66433 | AE5: 5.2309413 | AF5: 5.2309413 | AG5: 5.2309413 | AH5: 5.2309413 | AI5: 5.2309413 | AJ5: 5.2309413 | AK5: 5.2309413
A6: Transportation | B6: Passenger | C6: Passenger Car | F6: Gasoline ICE Vehicle (spark ignition with turbo) | G6: Ethanol | H6: TRAETH | I6: TRAPASCARDMD | J6: TRAPASCARICEVTGSL20 | K6: Mvkm | L6: 0 | M6: 1 | N6: 2020 | O6: 16.861274 | P6: 0.1 | Q6: 0.41785638 | R6: 0.41586659 | S6: 0.46627466 | T6: 0.50540724 | U6: 0.53326433 | V6: 0.56112142 | W6: 0.59030504 | X6: 157.19576 | Y6: 156.12882 | Z6: 159.32964 | AA6: 165.73127 | AB6: 165.37563 | AC6: 165.01998 | AD6: 164.66433 | AE6: 5.2309413 | AF6: 5.2309413 | AG6: 5.2309413 | AH6: 5.2309413 | AI6: 5.2309413 | AJ6: 5.2309413 | AK6: 5.2309413
A7: Transportation | B7: Passenger | C7: Passenger Car | F7: Gasoline Micro Hybrid Electric Vehicle (spark ignition) | G7: Gasoline | H7: TRAGSL | I7: TRAPASCARDMD | J7: TRAPASCARHEVGSL20 | K7: Mvkm | L7: 1 | M7: 1 | N7: 2020 | O7: 16.861274 | P7: 1 | Q7: 0.38469318 | R7: 0.37938706 | S7: 0.44173389 | T7: 0.48351953 | U7: 0.5080603 | V7: 0.53326433 | W7: 0.55846837 | X7: 150.79412 | Y7: 153.28364 | Z7: 153.63929 | AA7: 165.01998 | AB7: 162.8861 | AC7: 161.10787 | AD7: 158.97399 | AE7: 4.9356462 | AF7: 4.9356462 | AG7: 4.9356462 | AH7: 4.9356462 | AI7: 4.9356462 | AJ7: 4.9356462 | AK7: 4.9356462
A8: Transportation | B8: Passenger | C8: Passenger Car | F8: Gasoline Micro Hybrid Electric Vehicle (spark ignition) | G8: Ethanol | H8: TRAETH | I8: TRAPASCARDMD | J8: TRAPASCARHEVGSL20 | K8: Mvkm | L8: 0 | M8: 1 | N8: 2020 | O8: 16.861274 | P8: 0.1 | Q8: 0.38469318 | R8: 0.37938706 | S8: 0.44173389 | T8: 0.48351953 | U8: 0.5080603 | V8: 0.53326433 | W8: 0.55846837 | X8: 150.79412 | Y8: 153.28364 | Z8: 153.63929 | AA8: 165.01998 | AB8: 162.8861 | AC8: 161.10787 | AD8: 158.97399 | AE8: 4.9356462 | AF8: 4.9356462 | AG8: 4.9356462 | AH8: 4.9356462 | AI8: 4.9356462 | AJ8: 4.9356462 | AK8: 4.9356462
A9: Transportation | B9: Passenger | C9: Passenger Car | F9: Gasoline Micro Hybrid Electric Vehicle (spark ignition with turbo) | G9: Gasoline | H9: TRAGSL | I9: TRAPASCARDMD | J9: TRAPASCARHEVTGSL20 | K9: Mvkm | L9: 1 | M9: 1 | N9: 2020 | O9: 16.861274 | P9: 1 | Q9: 0.42515228 | R9: 0.42249923 | S9: 0.47489709 | T9: 0.51601947 | U9: 0.54453982 | V9: 0.57306018 | W9: 0.6022438 | X9: 158.97399 | Y9: 157.5514 | Z9: 160.39657 | AA9: 166.79821 | AB9: 166.44257 | AC9: 166.08692 | AD9: 165.73127 | AE9: 4.9356462 | AF9: 4.9356462 | AG9: 4.9356462 | AH9: 4.9356462 | AI9: 4.9356462 | AJ9: 4.9356462 | AK9: 4.9356462
A10: Transportation | B10: Passenger | C10: Passenger Car | F10: Gasoline Micro Hybrid Electric Vehicle (spark ignition with turbo) | G10: Ethanol | H10: TRAETH | I10: TRAPASCARDMD | J10: TRAPASCARHEVTGSL20 | K10: Mvkm | L10: 0 | M10: 1 | N10: 2020 | O10: 16.861274 | P10: 0.1 | Q10: 0.42515228 | R10: 0.42249923 | S10: 0.47489709 | T10: 0.51601947 | U10: 0.54453982 | V10: 0.57306018 | W10: 0.6022438 | X10: 158.97399 | Y10: 157.5514 | Z10: 160.39657 | AA10: 166.79821 | AB10: 166.44257 | AC10: 166.08692 | AD10: 165.73127 | AE10: 4.9356462 | AF10: 4.9356462 | AG10: 4.9356462 | AH10: 4.9356462 | AI10: 4.9356462 | AJ10: 4.9356462 | AK10: 4.9356462
A11: Transportation | B11: Passenger | C11: Passenger Car | F11: Gasoline Mild Hybrid Electric Vehicle (belt-driven integrated starter generator with spark ignition) | G11: Gasoline | H11: TRAGSL | I11: TRAPASCARDMD | J11: TRAPASCARHEVIGSL20 | K11: Mvkm | L11: 1 | M11: 1 | N11: 2020 | O11: 16.861274 | P11: 1 | Q11: 0.3953054 | R11: 0.38933602 | S11: 0.45433591 | T11: 0.49612154 | U11: 0.52397864 | V11: 0.55117246 | W11: 0.57969282 | X11: 155.06188 | Y11: 156.84011 | Z11: 156.48446 | AA11: 167.5095 | AB11: 165.01998 | AC11: 163.24175 | AD11: 160.75222 | AE11: 4.9356462 | AF11: 4.9356462 | AG11: 4.9356462 | AH11: 4.9356462 | AI11: 4.9356462 | AJ11: 4.9356462 | AK11: 4.9356462
A12: Transportation | B12: Passenger | C12: Passenger Car | F12: Gasoline Mild Hybrid Electric Vehicle (belt-driven integrated starter generator with spark ignition) | G12: Ethanol | H12: TRAETH | I12: TRAPASCARDMD | J12: TRAPASCARHEVIGSL20 | K12: Mvkm | L12: 0 | M12: 1 | N12: 2020 | O12: 16.861274 | P12: 0.1 | Q12: 0.3953054 | R12: 0.38933602 | S12: 0.45433591 | T12: 0.49612154 | U12: 0.52397864 | V12: 0.55117246 | W12: 0.57969282 | X12: 155.06188 | Y12: 156.84011 | Z12: 156.48446 | AA12: 167.5095 | AB12: 165.01998 | AC12: 163.24175 | AD12: 160.75222 | AE12: 4.9356462 | AF12: 4.9356462 | AG12: 4.9356462 | AH12: 4.9356462 | AI12: 4.9356462 | AJ12: 4.9356462 | AK12: 4.9356462
A13: Transportation | B13: Passenger | C13: Passenger Car | F13: Gasoline Mild Hybrid Electric Vehicle (belt-driven integrated starter generator with spark ignition and turbo) | G13: Gasoline | H13: TRAGSL | I13: TRAPASCARDMD | J13: TRAPASCARHEVIGSL20 | K13: Mvkm | L13: 0 | M13: 1 | N13: 2020 | O13: 16.861274 | P13: 1 | Q13: 0.44505021 | R13: 0.44040736 | S13: 0.49744807 | T13: 0.53989697 | U13: 0.57173365 | V13: 0.60423359 | W13: 0.63607027 | X13: 162.8861 | Y13: 160.75222 | Z13: 163.24175 | AA13: 169.28774 | AB13: 168.57644 | AC13: 167.86515 | AD13: 167.15386 | AE13: 4.9356462 | AF13: 4.9356462 | AG13: 4.9356462 | AH13: 4.9356462 | AI13: 4.9356462 | AJ13: 4.9356462 | AK13: 4.9356462
A14: Transportation | B14: Passenger | C14: Passenger Car | F14: Gasoline Mild Hybrid Electric Vehicle (belt-driven integrated starter generator with spark ignition and turbo) | G14: Ethanol | H14: TRAETH | I14: TRAPASCARDMD | J14: TRAPASCARHEVIGSL20 | K14: Mvkm | L14: 0 | M14: 1 | N14: 2020 | O14: 16.861274 | P14: 0.1 | Q14: 0.44505021 | R14: 0.44040736 | S14: 0.49744807 | T14: 0.53989697 | U14: 0.57173365 | V14: 0.60423359 | W14: 0.63607027 | X14: 162.8861 | Y14: 160.75222 | Z14: 163.24175 | AA14: 169.28774 | AB14: 168.57644 | AC14: 167.86515 | AD14: 167.15386 | AE14: 4.9356462 | AF14: 4.9356462 | AG14: 4.9356462 | AH14: 4.9356462 | AI14: 4.9356462 | AJ14: 4.9356462 | AK14: 4.9356462
... A279: Transportation | B279: Other | C279: Off-Road | F279: Battery Electric Vehicle | G279: Battery Freight | H279: TRABAF | I279: TRAOTHOFRDMD | J279: TRAOTHOFRBEV20 | K279: Mvkm | L279: 1 | M279: 1 | N279: 2020 | O279: 8 | P279: 1 | Q279: 0.36877484 | R279: 0.36877484 | S279: 0.40061151 | T279: 0.43510125 | U279: 0.44969306 | V279: 0.46428487 | W279: 0.48152973 | X279: 508.57451 | Y279: 508.57451 | Z279: 462.34046 | AA279: 437.4452 | AB279: 426.06452 | AC279: 414.68383 | AD279: 403.30314 | AE279: 6.7572836 | AF279: 6.7572836 | AG279: 6.7572836 | AH279: 6.7572836 | AI279: 6.7572836 | AJ279: 6.7572836 | AK279: 6.7572836
A280: Transportation | B280: Passenger | C280: Bicycle | F280: N/a | G280: N/a | H280: TRA | I280: TRAPASBICDMD | J280: TRAPASBIC20 | K280: Mvkm | L280: 1 | M280: 1 | N280: 2020 | P280: 0
A281: Transportation | B281: Passenger | C281: Walk | F281: N/a | G281: N/a | H281: TRA | I281: TRAPASWALDMD | J281: TRAPASWAL20 | K281: Mvkm | L281: 1 | M281: 1 | N281: 2020 | P281: 0
A282: Transportation | B282: Passenger | C282: Rail | F282: Diesel ICE Vehicle | G282: Diesel | H282: TRADSL | I282: TRAPASRAIDMD | J282: TRAPASRAIICEVDSL20 | K282: Mvkm | L282: 1 | M282: 1 | N282: 2020 | O282: 30 | P282: 1 | Q282: 0.040874687 | R282: 0.040874687 | S282: 0.040874687 | T282: 0.040874687 | U282: 0.040874687 | V282: 0.040874687 | W282: 0.040874687 | X282: 35064.744 | Y282: 35064.744 | Z282: 35064.744 | AA282: 35064.744 | AB282: 35064.744 | AC282: 35064.744 | AD282: 35064.744 | AE282: 3506.4744 | AF282: 3506.4744 | AG282: 3506.4744 | AH282: 3506.4744 | AI282: 3506.4744 | AJ282: 3506.4744 | AK282: 3506.4744
A283: Transportation | B283: Passenger | C283: Rail | F283: Diesel ICE Vehicle | G283: Renewable diesel | H283: TRARDS | I283: TRAPASRAIDMD | J283: TRAPASRAIICEVDSL20 | K283: Mvkm | L283: 0 | M283: 1 | N283: 2020 | O283: 30 | P283: 1 | Q283: 0.040874687 | R283: 0.040874687 | S283: 0.040874687 | T283: 0.040874687 | U283: 0.040874687 | V283: 0.040874687 | W283: 0.040874687 | X283: 35064.744 | Y283: 35064.744 | Z283: 35064.744 | AA283: 35064.744 | AB283: 35064.744 | AC283: 35064.744 | AD283: 35064.744 | AE283: 3506.4744 | AF283: 3506.4744 | AG283: 3506.4744 | AH283: 3506.4744 | AI283: 3506.4744 | AJ283: 3506.4744 | AK283: 3506.4744
A284: Transportation | B284: Passenger | C284: Rail | F284: Diesel ICE Vehicle | G284: Bio diesel | H284: TRABDS | I284: TRAPASRAIDMD | J284: TRAPASRAIICEVDSL20 | K284: Mvkm | L284: 0 | M284: 1 | N284: 2020 | O284: 30 | P284: 0.1 | Q284: 0.040874687 | R284: 0.040874687 | S284: 0.040874687 | T284: 0.040874687 | U284: 0.040874687 | V284: 0.040874687 | W284: 0.040874687 | X284: 35064.744 | Y284: 35064.744 | Z284: 35064.744 | AA284: 35064.744 | AB284: 35064.744 | AC284: 35064.744 | AD284: 35064.744 | AE284: 3506.4744 | AF284: 3506.4744 | AG284: 3506.4744 | AH284: 3506.4744 | AI284: 3506.4744 | AJ284: 3506.4744 | AK284: 3506.4744
A285: Transportation | B285: Passenger | C285: Rail | F285: Electric Propulsion Vehicle | G285: Electricity | H285: TRAELC | I285: TRAPASRAIDMD | J285: TRAPASRAIPROELC20 | K285: Mvkm | L285: 1 | M285: 1 | N285: 2020 | O285: 30 | P285: 1 | Q285: 0.040874687 | R285: 0.040874687 | S285: 0.040874687 | T285: 0.040874687 | U285: 0.040874687 | V285: 0.040874687 | W285: 0.040874687 | X285: 35064.744 | Y285: 35064.744 | Z285: 35064.744 | AA285: 35064.744 | AB285: 35064.744 | AC285: 35064.744 | AD285: 35064.744 | AE285: 3506.4744 | AF285: 3506.4744 | AG285: 3506.4744 | AH285: 3506.4744 | AI285: 3506.4744 | AJ285: 3506.4744 | AK285: 3506.4744
A286: Transportation | B286: Passenger | C286: Rail | F286: Hydrogen Fuel Cell Electric Vehicle | G286: Hydrogen | H286: TRAH2G | I286: TRAPASRAIDMD | J286: TRAPASRAIFCEV20 | K286: Mvkm | L286: 1 | M286: 1 | N286: 2020 | O286: 30 | P286: 1 | Q286: 0.040874687 | R286: 0.040874687 | S286: 0.040874687 | T286: 0.040874687 | U286: 0.040874687 | V286: 0.040874687 | W286: 0.040874687 | X286: 35064.744 | Y286: 35064.744 | Z286: 35064.744 | AA286: 35064.744 | AB286: 35064.744 | AC286: 35064.744 | AD286: 35064.744 | AE286: 3506.4744 | AF286: 3506.4744 | AG286: 3506.4744 | AH286: 3506.4744 | AI286: 3506.4744 | AJ286: 3506.4744 | AK286: 3506.4744
A287: Transportation | B287: Passenger | C287: Tram | F287: Electric Propulsion Vehicle | G287: Electricity | H287: TRAELC | I287: TRAPASTRMDMD | J287: TRAPASTRMPROELC20 | K287: Mvkm | L287: 1 | M287: 1 | N287: 2020 | O287: 30 | P287: 1 | Q287: 0.07814652 | R287: 0.07814652 | S287: 0.07814652 | T287: 0.07814652 | U287: 0.07814652 | V287: 0.07814652 | W287: 0.07814652 | X287: 1585.9239 | Y287: 1585.9239 | Z287: 1585.9239 | AA287: 1585.9239 | AB287: 1585.9239 | AC287: 1585.9239 | AD287: 1585.9239 | AE287: 158.59239 | AF287: 158.59239 | AG287: 158.59239 | AH287: 158.59239 | AI287: 158.59239 | AJ287: 158.59239 | AK287: 158.59239
A288: Transportation | B288: Passenger | C288: Subway | F288: Electric Propulsion Vehicle | G288: Electricity | H288: TRAELC | I288: TRAPASSUBDMD | J288: TRAPASSUBPROELC20 | K288: Mvkm | L288: 1 | M288: 1 | N288: 2020 | O288: 30 | P288: 1 | Q288: 0.07814652 | R288: 0.07814652 | S288: 0.07814652 | T288: 0.07814652 | U288: 0.07814652 | V288: 0.07814652 | W288: 0.07814652 | X288: 1585.9239 | Y288: 1585.9239 | Z288: 1585.9239 | AA288: 1585.9239 | AB288: 1585.9239 | AC288: 1585.9239 | AD288: 1585.9239 | AE288: 158.59239 | AF288: 158.59239 | AG288: 158.59239 | AH288: 158.59239 | AI288: 158.59239 | AJ288: 158.59239 | AK288: 158.59239
A289: Transportation | B289: Other | C289: Waterborne | F289: Diesel ICE Vehicle | G289: Diesel | H289: TRADSL | I289: TRAOTHWATDMD | J289: TRAOTHWATICEVDSL20 | K289: Mvkm | L289: 1 | M289: 1 | N289: 2020 | O289: 30 | P289: 1 | Q289: 0.0011427622 | R289: 0.0011427622 | S289: 0.0011427622 | T289: 0.0011427622 | U289: 0.0011427622 | V289: 0.0011427622 | W289: 0.0011427622 | X289: 59271.955 | Y289: 59271.955 | Z289: 59271.955 | AA289: 59271.955 | AB289: 59271.955 | AC289: 59271.955 | AD289: 59271.955 | AE289: 2963.5978 | AF289: 2963.5978 | AG289: 2963.5978 | AH289: 2963.5978 | AI289: 2963.5978 | AJ289: 2963.5978 | AK289: 2963.5978
A290: Transportation | B290: Other | C290: Waterborne | F290: Diesel ICE Vehicle | G290: Renewable diesel | H290: TRARDS | I290: TRAOTHWATDMD | J290: TRAOTHWATICEVDSL20 | K290: Mvkm | L290: 0 | M290: 1 | N290: 2020 | O290: 30 | P290: 1 | Q290: 0.0011427622 | R290: 0.0011427622 | S290: 0.0011427622 | T290: 0.0011427622 | U290: 0.0011427622 | V290: 0.0011427622 | W290: 0.0011427622 | X290: 59271.955 | Y290: 59271.955 | Z290: 59271.955 | AA290: 59271.955 | AB290: 59271.955 | AC290: 59271.955 | AD290: 59271.955 | AE290: 2963.5978 | AF290: 2963.5978 | AG290: 2963.5978 | AH290: 2963.5978 | AI290: 2963.5978 | AJ290: 2963.5978 | AK290: 2963.5978
A291: Transportation | B291: Other | C291: Waterborne | F291: Diesel ICE Vehicle | G291: Bio diesel | H291: TRABDS | I291: TRAOTHWATDMD | J291: TRAOTHWATICEVDSL20 | K291: Mvkm | L291: 0 | M291: 1 | N291: 2020 | O291: 30 | P291: 0.1 | Q291: 0.0011427622 | R291: 0.0011427622 | S291: 0.0011427622 | T291: 0.0011427622 | U291: 0.0011427622 | V291: 0.0011427622 | W291: 0.0011427622 | X291: 59271.955 | Y291: 59271.955 | Z291: 59271.955 | AA291: 59271.955 | AB291: 59271.955 | AC291: 59271.955 | AD291: 59271.955 | AE291: 2963.5978 | AF291: 2963.5978 | AG291: 2963.5978 | AH291: 2963.5978 | AI291: 2963.5978 | AJ291: 2963.5978 | AK291: 2963.5978
A292: Transportation | B292: Other | C292: Waterborne | F292: Diesel ICE Vehicle Direct Injection | G292: Diesel | H292: TRADSL | I292: TRAOTHWATDMD | J292: TRAOTHWATICEVDSL20 | K292: Mvkm | L292: 0 | M292: 1 | N292: 2020 | O292: 30 | P292: 1 | Q292: 0.0012985934 | R292: 0.0012985934 | S292: 0.0012985934 | T292: 0.0012985934 | U292: 0.0012985934 | V292: 0.0012985934 | W292: 0.0012985934 | X292: 61074.415 | Y292: 61074.415 | Z292: 61074.415 | AA292: 61074.415 | AB292: 61074.415 | AC292: 61074.415 | AD292: 61074.415 | AE292: 3029.7957 | AF292: 3029.7957 | AG292: 3029.7957 | AH292: 3029.7957 | AI292: 3029.7957 | AJ292: 3029.7957 | AK292: 3029.7957
A293: Transportation | B293: Other | C293: Waterborne | F293: Diesel ICE Vehicle Direct Injection | G293: Renewable diesel | H293: TRARDS | I293: TRAOTHWATDMD | J293: TRAOTHWATICEVDSL20 | K293: Mvkm | L293: 0 | M293: 1 | N293: 2020 | O293: 30 | P293: 1 | Q293: 0.0012985934 | R293: 0.0012985934 | S293: 0.0012985934 | T293: 0.0012985934 | U293: 0.0012985934 | V293: 0.0012985934 | W293: 0.0012985934 | X293: 61074.415 | Y293: 61074.415 | Z293: 61074.415 | AA293: 61074.415 | AB293: 61074.415 | AC293: 61074.415 | AD293: 61074.415 | AE293: 3029.7957 | AF293: 3029.7957 | AG293: 3029.7957 | AH293: 3029.7957 | AI293: 3029.7957 | AJ293: 3029.7957 | AK293: 3029.7957
... A319: Transportation | B319: Other | C319: Aviation | F319: Aviation Gasoline ICE Vehicle Improved | G319: Aviation gasoline | H319: TRAAGA | I319: TRAOTHAIRDMD | J319: TRAOTHAIRICEIAGA20 | K319: Mvkm | L319: 1 | M319: 1 | N319: 2020 | O319: 20 | P319: 1 | Q319: 0.0040699936 | R319: 0.0040699936 | S319: 0.0040699936 | T319: 0.0040699936 | U319: 0.0040699936 | V319: 0.0040699936 | W319: 0.0040699936 | X319: 3154.2202 | Y319: 3154.2202 | Z319: 3154.2202 | AA319: 3154.2202 | AB319: 3154.2202 | AC319: 3154.2202 | AD319: 3154.2202 | AE319: 315.42202 | AF319: 315.42202 | AG319: 315.42202 | AH319: 315.42202 | AI319: 315.42202 | AJ319: 315.42202 | AK319: 315.42202
A320: * | B320: https://theicct.org/sites/default/files/publications/ICCT_EV_HDVs_Infrastructure_20190809.pdf | J320: * | L320: 0 | M320: *
A321: Transportation | B321: Light-duty | E321: Battery | F321: Residential Charging Station | G321: Electricity | H321: TRAELC | I321: TRABAT | J321: TRALDTRESCHA19 | K321: MW | L321: 1 | M321: 1 | N321: 2019 | O321: 25 | Q321: 0.9 | R321: 0.91 | S321: 0.92 | T321: 0.93 | U321: 0.94 | V321: 0.95 | W321: 0.95 | X321: 1083.8776 | Y321: 757.54886 | Z321: 692.28311 | AA321: 627.01737 | AB321: 561.75162 | AC321: 496.48587 | AD321: 431.22012 | AE321: 29.136495 | AF321: 26.805575 | AG321: 24.474656 | AH321: 22.143736 | AI321: 19.812816 | AJ321: 17.481897 | AK321: 15.150977
A322: Transportation | B322: Light-duty | E322: Battery | F322: Commercial 120V Charging Station | G322: Electricity | H322: TRAELC | I322: TRABAT | J322: TRALDTCOM1CHA19 | K322: MW | L322: 1 | M322: 1 | N322: 2019 | O322: 25 | Q322: 0.9 | R322: 0.91 | S322: 0.92 | T322: 0.93 | U322: 0.94 | V322: 0.95 | W322: 0.95 | X322: 970.828 | Y322: 675.96668 | Z322: 617.69369 | AA322: 559.4207 | AB322: 501.14771 | AC322: 442.87472 | AD322: 384.60173 | AE322: 37.294713 | AF322: 34.18682 | AG322: 31.078928 | AH322: 27.971035 | AI322: 24.863142 | AJ322: 21.755249 | AK322: 18.647357
A323: Transportation | B323: Light-duty | E323: Battery | F323: Commercial 240V Charging Station | G323: Electricity | H323: TRAELC | I323: TRABAT | J323: TRALDTCOM2CHA19 | K323: MW | L323: 1 | M323: 1 | N323: 2019 | O323: 25 | Q323: 0.9 | R323: 0.91 | S323: 0.92 | T323: 0.93 | U323: 0.94 | V323: 0.95 | W323: 0.95 | X323: 1165.4598 | Y323: 815.82185 | Z323: 745.89426 | AA323: 675.96668 | AB323: 606.03909 | AC323: 536.1115 | AD323: 466.18392 | AE323: 44.287472 | AF323: 40.596849 | AG323: 36.906227 | AH323: 33.215604 | AI323: 29.524981 | AJ323: 25.834359 | AK323: 22.143736
A324: Transportation | B324: Light-duty | E324: Battery | F324: Public Charging Station | G324: Electricity | H324: TRAELC | I324: TRABAT | J324: TRALDTPUBCHA19 | K324: MW | L324: 1 | M324: 1 | N324: 2019 | O324: 25 | Q324: 0.9 | R324: 0.91 | S324: 0.92 | T324: 0.93 | U324: 0.94 | V324: 0.95 | W324: 0.95 | X324: 1748.1897 | Y324: 1223.7328 | Z324: 1118.8414 | AA324: 1118.8414 | AB324: 1118.8414 | AC324: 1118.8414 | AD324: 699.27587 | AE324: 60.603909 | AF324: 55.553583 | AG324: 50.503257 | AH324: 45.452932 | AI324: 40.402606 | AJ324: 35.35228 | AK324: 30.301954
A325: Transportation | B325: Heavy-duty | E325: Battery Freight | F325: Slow Charging Station | G325: Electricity | H325: TRAELC | I325: TRABAF | J325: TRAHDTSLWCHA19 | K325: MW | L325: 1 | M325: 1 | N325: 2019 | O325: 25 | Q325: 0.9 | R325: 0.91 | S325: 0.92 | T325: 0.93 | U325: 0.94 | V325: 0.95 | W325: 0.95 | X325: 582.72989 | Y325: 524.4569 | Z325: 466.18392 | AA325: 466.18392 | AB325: 466.18392 | AC325: 466.18392 | AD325: 466.18392 | AE325: 163.16437 | AF325: 143.93428 | AG325: 124.7042 | AH325: 105.47411 | AI325: 86.244024 | AJ325: 67.013938 | AK325: 47.783851
A326: Transportation | B326: Heavy-duty | E326: Battery Freight | F326: Fast Charging Station | G326: Electricity | H326: TRAELC | I326: TRABAF | J326: TRAHDTFASCHA19 | K326: MW | L326: 1 | M326: 1 | N326: 2019 | O326: 25 | Q326: 0.9 | R326: 0.91 | S326: 0.92 | T326: 0.93 | U326: 0.94 | V326: 0.95 | W326: 0.95 | X326: 874.09484 | Y326: 757.54886 | Z326: 641.00288 | AA326: 641.00288 | AB326: 641.00288 | AC326: 641.00288 | AD326: 641.00288 | AE326: 174.81897 | AF326: 156.36585 | AG326: 137.91274 | AH326: 119.45963 | AI326: 101.00651 | AJ326: 82.553402 | AK326: 64.100288

Sheet >> TIMES

Sheet Tech_availability
B2: ~TFM_AVA
B3: PSET_SET | C3: PSET_PN | D3: PSET_PD | E3: PSET_CO | F3: PSET_CI | G3: CITY | H3: EGRID
B4: *
C5: ='TRA TECH'!J3 -> TRAPASCARICEVGSL20 | G5: =IF(SUMIFS('TRA TECH'!M:M,'TRA TECH'!J:J,C5)>0,1,0) -> 1 | H5: =IF(C5="","",IF(C5="*","*",0)) -> 0
C6: ='TRA TECH'!J4 -> TRAPASCARICEVGSL20 | G6: =IF(SUMIFS('TRA TECH'!M:M,'TRA TECH'!J:J,C6)>0,1,0) -> 1 | H6: =IF(C6="","",IF(C6="*","*",0)) -> 0
C7: ='TRA TECH'!J5 -> TRAPASCARICEVTGSL20 | G7: =IF(SUMIFS('TRA TECH'!M:M,'TRA TECH'!J:J,C7)>0,1,0) -> 1 | H7: =IF(C7="","",IF(C7="*","*",0)) -> 0
C8: ='TRA TECH'!J6 -> TRAPASCARICEVTGSL20 | G8: =IF(SUMIFS('TRA TECH'!M:M,'TRA TECH'!J:J,C8)>0,1,0) -> 1 | H8: =IF(C8="","",IF(C8="*","*",0)) -> 0
C9: ='TRA TECH'!J7 -> TRAPASCARHEVGSL20 | G9: =IF(SUMIFS('TRA TECH'!M:M,'TRA TECH'!J:J,C9)>0,1,0) -> 1 | H9: =IF(C9="","",IF(C9="*","*",0)) -> 0
C10: ='TRA TECH'!J8 -> TRAPASCARHEVGSL20 | G10: =IF(SUMIFS('TRA TECH'!M:M,'TRA TECH'!J:J,C10)>0,1,0) -> 1 | H10: =IF(C10="","",IF(C10="*","*",0)) -> 0
C11: ='TRA TECH'!J9 -> TRAPASCARHEVTGSL20 | G11: =IF(SUMIFS('TRA TECH'!M:M,'TRA TECH'!J:J,C11)>0,1,0) -> 1 | H11: =IF(C11="","",IF(C11="*","*",0)) -> 0
C12: ='TRA TECH'!J10 -> TRAPASCARHEVTGSL20 | G12: =IF(SUMIFS('TRA TECH'!M:M,'TRA TECH'!J:J,C12)>0,1,0) -> 1 | H12: =IF(C12="","",IF(C12="*","*",0)) -> 0
C13: ='TRA TECH'!J11 -> TRAPASCARHEVIGSL20 | G13: =IF(SUMIFS('TRA TECH'!M:M,'TRA TECH'!J:J,C13)>0,1,0) -> 1 | H13: =IF(C13="","",IF(C13="*","*",0)) -> 0
C14: ='TRA TECH'!J12 -> TRAPASCARHEVIGSL20 | G14: =IF(SUMIFS('TRA TECH'!M:M,'TRA TECH'!J:J,C14)>0,1,0) -> 1 | H14: =IF(C14="","",IF(C14="*","*",0)) -> 0
C15: ='TRA TECH'!J13 -> TRAPASCARHEVIGSL20 | G15: =IF(SUMIFS('TRA TECH'!M:M,'TRA TECH'!J:J,C15)>0,1,0) -> 1 | H15: =IF(C15="","",IF(C15="*","*",0)) -> 0
C16: ='TRA TECH'!J14 -> TRAPASCARHEVIGSL20 | G16: =IF(SUMIFS('TRA TECH'!M:M,'TRA TECH'!J:J,C16)>0,1,0) -> 1 | H16: =IF(C16="","",IF(C16="*","*",0)) -> 0
... C321: ='TRA TECH'!J319 -> TRAOTHAIRICEIAGA20 | G321: =IF(SUMIFS('TRA TECH'!M:M,'TRA TECH'!J:J,C321)>0,1,0) -> 1 | H321: =IF(C321="","",IF(C321="*","*",0)) -> 0
C322: ='TRA TECH'!J321 -> TRALDTRESCHA19 | G322: =IF(SUMIFS('TRA TECH'!M:M,'TRA TECH'!J:J,C322)>0,1,0) -> 1 | H322: =IF(C322="","",IF(C322="*","*",0)) -> 0
C323: ='TRA TECH'!J322 -> TRALDTCOM1CHA19 | G323: =IF(SUMIFS('TRA TECH'!M:M,'TRA TECH'!J:J,C323)>0,1,0) -> 1 | H323: =IF(C323="","",IF(C323="*","*",0)) -> 0
C324: ='TRA TECH'!J323 -> TRALDTCOM2CHA19 | G324: =IF(SUMIFS('TRA TECH'!M:M,'TRA TECH'!J:J,C324)>0,1,0) -> 1 | H324: =IF(C324="","",IF(C324="*","*",0)) -> 0
C325: ='TRA TECH'!J324 -> TRALDTPUBCHA19 | G325: =IF(SUMIFS('TRA TECH'!M:M,'TRA TECH'!J:J,C325)>0,1,0) -> 1 | H325: =IF(C325="","",IF(C325="*","*",0)) -> 0
C326: ='TRA TECH'!J325 -> TRAHDTSLWCHA19 | G326: =IF(SUMIFS('TRA TECH'!M:M,'TRA TECH'!J:J,C326)>0,1,0) -> 1 | H326: =IF(C326="","",IF(C326="*","*",0)) -> 0
C327: ='TRA TECH'!J326 -> TRAHDTFASCHA19 | G327: =IF(SUMIFS('TRA TECH'!M:M,'TRA TECH'!J:J,C327)>0,1,0) -> 1 | H327: =IF(C327="","",IF(C327="*","*",0)) -> 0
