Workbook

Sheet ReadMe
A1: Generic Comet (GC) TIMES Residential
B3: Sheet color
C4: Parameters
C6: City Dashboard
C8: GC Databases
C10: TIMES formatted

Sheet >> City Data

Sheet City characteristics
B2: City Basic Data
B4: Calibration methodology | C4: GHG Inventory
B6: A. City Characteristics
B7: Data Item | C7: Value | D7: Units
B8: City Name | C8: New York
B9: Latitude | C9: 40.5
B10: Longitude | C10: -75
B11: County | C11: New York County
B12: State | C12: New York
B13: Census Division | C13: Middle Atlantic
B14: Climate Division | C14: Northeast
B15: Egrid Region | C15: NPCC NYC/Westchester
B16: Area of city (excluding water, natural and agricultural areas) | C16: 778 | D16: square kilometers
B17: * Division and Region Map can be found in the Maps sheet.
B18: B. Planning Base Year and Target Years
B19: Year | C19: Value | D19: Units
B20: Base Year | C20: 2019 | D20: Acceptable range [2018,2021]
B21: End Year | C21: 2050
B23: C. City Population and GDP
B24: Data Item | C24: Value | D24: Units
B25: Population in Base Year | C25: 8337 | D25: Thousand of people
B26: Annual population growth (Base Year - End Year) | C26: 0.5 | D26: % people
B27: GDP in Base Year | C27: 1206000 | D27: Million US$
B28: Annual GDP growth rate | C28: 2 | D28: % US$
B29: Share of manufacturing GDP | C29: 5 | D29: % US$
B30: Share of State population | C30: 0.42835123
B31: Share of State GDP | C31: 0.67251772
B32: Adjustment from state manufacturing GDP | C32: 1.0638298
B34: D. Climate Data
B35: Data Item | C35: 2000 | D35: 2050 | E35: 2100 | F35: Units
B36: Heating degree days (HDD) | C36: 4473.4625 | D36: 4066.4182 | E36: 3763.8582 | F36: F
B37: Cooling degree days (CDD) | C37: 1020.7333 | D37: 1224.2555 | E37: 1375.5355 | F37: F
B39: Data Item | C39: Value | D39: Units
B40: Correction from State HDD | C40: 0.72727402
B41: Correction from State CDD | C41: 1.5583715
B42: Annual precipitation | C42: 762 | D42: mm / year
B43: Climate change scenario | C43: RCP4.5
B44: Average temperature increase in 1980-2020 | C44: 1.4617857 | D44: F
B45: Forecasted average temperature increase in 2035-2065 | C45: 3.13 | D45: F
B46: Forecasted average temperature increase in 2070-2100 | C46: 4.37 | D46: F
...

Sheet >> GC_NewTech

Sheet RET TECH
A2: Sector | B2: Sub-sector | C2: Archetype | D2: Vintage | E2: End Use | F2: Technology | G2: Class | H2: Energy | I2: First Year | J2: Description | K2: Input Label | L2: Output Label | M2: Technology Label | N2: To Include | O2: CAPEX (2023 US$ / unit) | P2: Average Gain (% TJ) | Q2: Base year building Intensity (TJ / Mm2) | R2: CAPEX (Thousands 2023 US$ / MW) | S2: Efficiency (TJ/Mm2) | T2: Average Lifetime (year) | U2: CFA | V2: C2A
A3: Residential | B3: Apartment | C3: Low Income | D3: New | E3: Space heating | F3: Building enveloppe | G3: ENERGY STAR | I3: 2020 | J3: Space heating Building enveloppe ClassENERGY STAR 2020 | K3: RESAPALONewSHRET | L3: RESAPALONewSHEUE | M3: RESAPALONewSHENVESTAR20 | N3: 1 | O3: 3036.1724 | P3: -0.13919003 | Q3: 250.95541 | R3: 27562.279 | S3: 34.930492 | T3: 30 | U3: 0.098628147 | V3: 31.536
A4: Residential | B4: Apartment | C4: Low Income | D4: New | E4: Space heating | F4: Building enveloppe | G4: PATH | I4: 2020 | J4: Space heating Building enveloppe ClassPATH 2020 | K4: RESAPALONewSHRET | L4: RESAPALONewSHEUE | M4: RESAPALONewSHENVPATH20 | N4: 1 | O4: 5041.7246 | P4: -0.49971985 | Q4: 250.95541 | R4: 12748.214 | S4: 125.4074 | T4: 30 | U4: 0.098628147 | V4: 31.536
A5: Residential | B5: Apartment | C5: Low Income | D5: New | E5: Space heating | F5: Building enveloppe | G5: IECC 2009 +40% | I5: 2020 | J5: Space heating Building enveloppe ClassIECC 2009 +40% 2020 | K5: RESAPALONewSHRET | L5: RESAPALONewSHEUE | M5: RESAPALONewSHENVIECC4020 | N5: 1 | O5: 4130.0517 | P5: -0.20096335 | Q5: 250.95541 | R5: 25967.818 | S5: 50.43284 | T5: 30 | U5: 0.098628147 | V5: 31.536
A6: Residential | B6: Apartment | C6: Low Income | D6: New | E6: Space heating | F6: Building enveloppe | G6: IECC 2009 | I6: 2020 | J6: Space heating Building enveloppe ClassIECC 2009 2020 | K6: RESAPALONewSHRET | L6: RESAPALONewSHEUE | M6: RESAPALONewSHENVIECC20 | N6: 1 | O6: 2694.9655 | P6: -0.12487787 | Q6: 250.95541 | R6: 27268.707 | S6: 31.338778 | T6: 30 | U6: 0.098628147 | V6: 31.536
A7: Residential | B7: Apartment | C7: Low Income | D7: New | E7: Space cooling | F7: Building enveloppe | G7: ENERGY STAR | I7: 2020 | J7: Space cooling Building enveloppe ClassENERGY STAR 2020 | K7: RESAPALONewSCRET | L7: RESAPALONewSCEUE | M7: RESAPALONewSCENVESTAR20 | N7: 0 | O7: 3036.1724 | P7: 0.11492607 | Q7: 69.115623 | R7: 0 | S7: -7.9431868 | T7: 30 | U7: 0.082748623 | V7: 31.536
A8: Residential | B8: Apartment | C8: Low Income | D8: New | E8: Space cooling | F8: Building enveloppe | G8: PATH | I8: 2020 | J8: Space cooling Building enveloppe ClassPATH 2020 | K8: RESAPALONewSCRET | L8: RESAPALONewSCEUE | M8: RESAPALONewSCENVPATH20 | N8: 0 | O8: 5041.7246 | P8: 0.081951034 | Q8: 69.115623 | R8: 0 | S8: -5.6640968 | T8: 30 | U8: 0.082748623 | V8: 31.536
A9: Residential | B9: Apartment | C9: Low Income | D9: New | E9: Space cooling | F9: Building enveloppe | G9: IECC 2009 +40% | I9: 2020 | J9: Space cooling Building enveloppe ClassIECC 2009 +40% 2020 | K9: RESAPALONewSCRET | L9: RESAPALONewSCEUE | M9: RESAPALONewSCENVIECC4020 | N9: 0 | O9: 4130.0517 | P9: 0.10051071 | Q9: 69.115623 | R9: 0 | S9: -6.9468601 | T9: 30 | U9: 0.082748623 | V9: 31.536
A10: Residential | B10: Apartment | C10: Low Income | D10: New | E10: Space cooling | F10: Building enveloppe | G10: IECC 2009 | I10: 2020 | J10: Space cooling Building enveloppe ClassIECC 2009 2020 | K10: RESAPALONewSCRET | L10: RESAPALONewSCEUE | M10: RESAPALONewSCENVIECC20 | N10: 0 | O10: 2694.9655 | P10: 0.12474853 | Q10: 69.115623 | R10: 0 | S10: -8.6220723 | T10: 30 | U10: 0.082748623 | V10: 31.536
A11: Residential | B11: House | C11: Low Income | D11: New | E11: Space heating | F11: Building enveloppe | G11: ENERGY STAR | I11: 2020 | J11: Space heating Building enveloppe ClassENERGY STAR 2020 | K11: RESHOULONewSHRET | L11: RESHOULONewSHEUE | M11: RESHOULONewSHENVESTAR20 | N11: 1 | O11: 15612.597 | P11: -0.33953104 | Q11: 477.33616 | R11: 15273.365 | S11: 162.07044 | T11: 30 | U11: 0.090305172 | V11: 31.536
A12: Residential | B12: House | C12: Low Income | D12: New | E12: Space heating | F12: Building enveloppe | G12: PATH | I12: 2020 | J12: Space heating Building enveloppe ClassPATH 2020 | K12: RESHOULONewSHRET | L12: RESHOULONewSHEUE | M12: RESHOULONewSHENVPATH20 | N12: 1 | O12: 23540.281 | P12: -0.51119236 | Q12: 477.33616 | R12: 15295.594 | S12: 244.0106 | T12: 30 | U12: 0.090305172 | V12: 31.536
A13: Residential | B13: House | C13: Low Income | D13: New | E13: Space heating | F13: Building enveloppe | G13: IECC 2009 +40% | I13: 2020 | J13: Space heating Building enveloppe ClassIECC 2009 +40% 2020 | K13: RESHOULONewSHRET | L13: RESHOULONewSHEUE | M13: RESHOULONewSHENVIECC4020 | N13: 1 | O13: 19829.56 | P13: -0.45261049 | Q13: 477.33616 | R13: 14552.162 | S13: 216.04735 | T13: 30 | U13: 0.090305172 | V13: 31.536
A14: Residential | B14: House | C14: Low Income | D14: New | E14: Space heating | F14: Building enveloppe | G14: IECC 2009 | I14: 2020 | J14: Space heating Building enveloppe ClassIECC 2009 2020 | K14: RESHOULONewSHRET | L14: RESHOULONewSHEUE | M14: RESHOULONewSHENVIECC20 | N14: 1 | O14: 14582.257 | P14: -0.24750738 | Q14: 477.33616 | R14: 19569.316 | S14: 118.14422 | T14: 30 | U14: 0.090305172 | V14: 31.536
... A66: Residential | B66: House | C66: High Income | D66: New | E66: Space cooling | F66: Building enveloppe | G66: IECC 2009 | I66: 2020 | J66: Space cooling Building enveloppe ClassIECC 2009 2020 | K66: RESHOUHINewSCRET | L66: RESHOUHINewSCEUE | M66: RESHOUHINewSCENVIECC20 | N66: 1 | O66: 14582.257 | P66: -0.16274435 | Q66: 98.984981 | R66: 143520.16 | S66: 16.109247 | T66: 30 | U66: 0.072863695 | V66: 31.536
A67: * | M67: * | N67: *
A68: Residential | B68: Apartment | C68: Low Income | D68: Old | E68: Space heating | F68: Building enveloppe | G68: ENERGY STAR | I68: 2020 | J68: Space heating Building enveloppe ClassENERGY STAR 2020 | K68: RESAPALOOldSHRET | L68: RESAPALOOldSHEUE | M68: RESAPALOOldSHENVESTAR20 | N68: 1 | O68: 3036.1724 | P68: -0.13919003 | Q68: 250.95541 | R68: 55124.558 | S68: 1 | T68: 30 | U68: 0.098628147 | V68: 31.536
A69: Residential | B69: Apartment | C69: Low Income | D69: Old | E69: Space heating | F69: Building enveloppe | G69: PATH | I69: 2020 | J69: Space heating Building enveloppe ClassPATH 2020 | K69: RESAPALOOldSHRET | L69: RESAPALOOldSHEUE | M69: RESAPALOOldSHENVPATH20 | N69: 1 | O69: 5041.7246 | P69: -0.49971985 | Q69: 250.95541 | R69: 25496.428 | S69: 1 | T69: 30 | U69: 0.098628147 | V69: 31.536
A70: Residential | B70: Apartment | C70: Low Income | D70: Old | E70: Space heating | F70: Building enveloppe | G70: IECC 2009 +40% | I70: 2020 | J70: Space heating Building enveloppe ClassIECC 2009 +40% 2020 | K70: RESAPALOOldSHRET | L70: RESAPALOOldSHEUE | M70: RESAPALOOldSHENVIECC4020 | N70: 1 | O70: 4130.0517 | P70: -0.20096335 | Q70: 250.95541 | R70: 51935.635 | S70: 1 | T70: 30 | U70: 0.098628147 | V70: 31.536
A71: Residential | B71: Apartment | C71: Low Income | D71: Old | E71: Space heating | F71: Building enveloppe | G71: IECC 2009 | I71: 2020 | J71: Space heating Building enveloppe ClassIECC 2009 2020 | K71: RESAPALOOldSHRET | L71: RESAPALOOldSHEUE | M71: RESAPALOOldSHENVIECC20 | N71: 1 | O71: 2694.9655 | P71: -0.12487787 | Q71: 250.95541 | R71: 54537.415 | S71: 1 | T71: 30 | U71: 0.098628147 | V71: 31.536
A72: Residential | B72: Apartment | C72: Low Income | D72: Old | E72: Space cooling | F72: Building enveloppe | G72: ENERGY STAR | I72: 2020 | J72: Space cooling Building enveloppe ClassENERGY STAR 2020 | K72: RESAPALOOldSCRET | L72: RESAPALOOldSCEUE | M72: RESAPALOOldSCENVESTAR20 | N72: 0 | O72: 3036.1724 | P72: 0.11492607 | Q72: 69.115623 | R72: 0 | S72: 1 | T72: 30 | U72: 0.082748623 | V72: 31.536
A73: Residential | B73: Apartment | C73: Low Income | D73: Old | E73: Space cooling | F73: Building enveloppe | G73: PATH | I73: 2020 | J73: Space cooling Building enveloppe ClassPATH 2020 | K73: RESAPALOOldSCRET | L73: RESAPALOOldSCEUE | M73: RESAPALOOldSCENVPATH20 | N73: 0 | O73: 5041.7246 | P73: 0.081951034 | Q73: 69.115623 | R73: 0 | S73: 1 | T73: 30 | U73: 0.082748623 | V73: 31.536
A74: Residential | B74: Apartment | C74: Low Income | D74: Old | E74: Space cooling | F74: Building enveloppe | G74: IECC 2009 +40% | I74: 2020 | J74: Space cooling Building enveloppe ClassIECC 2009 +40% 2020 | K74: RESAPALOOldSCRET | L74: RESAPALOOldSCEUE | M74: RESAPALOOldSCENVIECC4020 | N74: 0 | O74: 4130.0517 | P74: 0.10051071 | Q74: 69.115623 | R74: 0 | S74: 1 | T74: 30 | U74: 0.082748623 | V74: 31.536
A75: Residential | B75: Apartment | C75: Low Income | D75: Old | E75: Space cooling | F75: Building enveloppe | G75: IECC 2009 | I75: 2020 | J75: Space cooling Building enveloppe ClassIECC 2009 2020 | K75: RESAPALOOldSCRET | L75: RESAPALOOldSCEUE | M75: RESAPALOOldSCENVIECC20 | N75: 0 | O75: 2694.9655 | P75: 0.12474853 | Q75: 69.115623 | R75: 0 | S75: 1 | T75: 30 | U75: 0.082748623 | V75: 31.536
A76: Residential | B76: House | C76: Low Income | D76: Old | E76: Space heating | F76: Building enveloppe | G76: ENERGY STAR | I76: 2020 | J76: Space heating Building enveloppe ClassENERGY STAR 2020 | K76: RESHOULOOldSHRET | L76: RESHOULOOldSHEUE | M76: RESHOULOOldSHENVESTAR20 | N76: 1 | O76: 15612.597 | P76: -0.33953104 | Q76: 477.33616 | R76: 30546.73 | S76: 1 | T76: 30 | U76: 0.090305172 | V76: 31.536
A77: Residential | B77: House | C77: Low Income | D77: Old | E77: Space heating | F77: Building enveloppe | G77: PATH | I77: 2020 | J77: Space heating Building enveloppe ClassPATH 2020 | K77: RESHOULOOldSHRET | L77: RESHOULOOldSHEUE | M77: RESHOULOOldSHENVPATH20 | N77: 1 | O77: 23540.281 | P77: -0.51119236 | Q77: 477.33616 | R77: 30591.188 | S77: 1 | T77: 30 | U77: 0.090305172 | V77: 31.536
A78: Residential | B78: House | C78: Low Income | D78: Old | E78: Space heating | F78: Building enveloppe | G78: IECC 2009 +40% | I78: 2020 | J78: Space heating Building enveloppe ClassIECC 2009 +40% 2020 | K78: RESHOULOOldSHRET | L78: RESHOULOOldSHEUE | M78: RESHOULOOldSHENVIECC4020 | N78: 1 | O78: 19829.56 | P78: -0.45261049 | Q78: 477.33616 | R78: 29104.324 | S78: 1 | T78: 30 | U78: 0.090305172 | V78: 31.536
A79: Residential | B79: House | C79: Low Income | D79: Old | E79: Space heating | F79: Building enveloppe | G79: IECC 2009 | I79: 2020 | J79: Space heating Building enveloppe ClassIECC 2009 2020 | K79: RESHOULOOldSHRET | L79: RESHOULOOldSHEUE | M79: RESHOULOOldSHENVIECC20 | N79: 1 | O79: 14582.257 | P79: -0.24750738 | Q79: 477.33616 | R79: 39138.632 | S79: 1 | T79: 30 | U79: 0.090305172 | V79: 31.536
... A131: Residential | B131: House | C131: High Income | D131: Old | E131: Space cooling | F131: Building enveloppe | G131: IECC 2009 | I131: 2020 | J131: Space cooling Building enveloppe ClassIECC 2009 2020 | K131: RESHOUHIOldSCRET | L131: RESHOUHIOldSCEUE | M131: RESHOUHIOldSCENVIECC20 | N131: 1 | O131: 14582.257 | P131: -0.16274435 | Q131: 98.984981 | R131: 287040.32 | S131: 1 | T131: 30 | U131: 0.072863695 | V131: 31.536

Sheet Demand
A1: Sector | B1: Sub-sector | C1: Archetype | D1: Vintage | E1: Demand Label | F1: Unit | G1: 2019 | H1: 2020 | I1: 2025 | J1: 2030 | K1: 2035 | L1: 2040 | M1: 2045 | N1: 2050 | O1: 2055 | P1: 2060 | Q1: 2065 | R1: 2070 | S1: 2075 | T1: 2080 | U1: 2085 | V1: 2090 | W1: 2095 | X1: 2100
A2: Commercial | B2: Hotel | D2: Old | E2: COMHOTOldDMD | F2: Mm2 | G2: 11.978701 | H2: 11.978701 | I2: 11.978701 | J2: 11.978701 | K2: 11.978701 | L2: 11.978701 | M2: 11.978701 | N2: 11.978701 | O2: 11.978701 | P2: 11.978701 | Q2: 11.978701 | R2: 11.978701 | S2: 11.978701 | T2: 11.978701 | U2: 11.978701 | V2: 11.978701 | W2: 11.978701 | X2: 11.978701
A3: Commercial | B3: Retail | D3: Old | E3: COMRETOldDMD | F3: Mm2 | G3: 23.081056 | H3: 23.081056 | I3: 23.081056 | J3: 23.081056 | K3: 23.081056 | L3: 23.081056 | M3: 23.081056 | N3: 23.081056 | O3: 23.081056 | P3: 23.081056 | Q3: 23.081056 | R3: 23.081056 | S3: 23.081056 | T3: 23.081056 | U3: 23.081056 | V3: 23.081056 | W3: 23.081056 | X3: 23.081056
A4: Commercial | B4: Office | D4: Old | E4: COMOFFOldDMD | F4: Mm2 | G4: 73.164819 | H4: 73.164819 | I4: 73.164819 | J4: 73.164819 | K4: 73.164819 | L4: 73.164819 | M4: 73.164819 | N4: 73.164819 | O4: 73.164819 | P4: 73.164819 | Q4: 73.164819 | R4: 73.164819 | S4: 73.164819 | T4: 73.164819 | U4: 73.164819 | V4: 73.164819 | W4: 73.164819 | X4: 73.164819
A5: Commercial | B5: Hospital | D5: Old | E5: COMHOPOldDMD | F5: Mm2 | G5: 44.382259 | H5: 44.382259 | I5: 44.382259 | J5: 44.382259 | K5: 44.382259 | L5: 44.382259 | M5: 44.382259 | N5: 44.382259 | O5: 44.382259 | P5: 44.382259 | Q5: 44.382259 | R5: 44.382259 | S5: 44.382259 | T5: 44.382259 | U5: 44.382259 | V5: 44.382259 | W5: 44.382259 | X5: 44.382259
A6: Commercial | B6: Educationnal | D6: Old | E6: COMEDUOldDMD | F6: Mm2 | G6: 48.565496 | H6: 48.565496 | I6: 48.565496 | J6: 48.565496 | K6: 48.565496 | L6: 48.565496 | M6: 48.565496 | N6: 48.565496 | O6: 48.565496 | P6: 48.565496 | Q6: 48.565496 | R6: 48.565496 | S6: 48.565496 | T6: 48.565496 | U6: 48.565496 | V6: 48.565496 | W6: 48.565496 | X6: 48.565496
A7: Commercial | B7: Warehouse | D7: Old | E7: COMWAROldDMD | F7: Mm2 | G7: 32.733587 | H7: 32.733587 | I7: 32.733587 | J7: 32.733587 | K7: 32.733587 | L7: 32.733587 | M7: 32.733587 | N7: 32.733587 | O7: 32.733587 | P7: 32.733587 | Q7: 32.733587 | R7: 32.733587 | S7: 32.733587 | T7: 32.733587 | U7: 32.733587 | V7: 32.733587 | W7: 32.733587 | X7: 32.733587
A8: Commercial | B8: Municipal | D8: Old | E8: COMMUNOldDMD | F8: Mm2 | G8: 16.841333 | H8: 16.841333 | I8: 16.841333 | J8: 16.841333 | K8: 16.841333 | L8: 16.841333 | M8: 16.841333 | N8: 16.841333 | O8: 16.841333 | P8: 16.841333 | Q8: 16.841333 | R8: 16.841333 | S8: 16.841333 | T8: 16.841333 | U8: 16.841333 | V8: 16.841333 | W8: 16.841333 | X8: 16.841333
A9: Commercial | B9: Other | D9: Old | E9: COMOTHOldDMD | F9: Mm2 | G9: 8.7602804 | H9: 8.7602804 | I9: 8.7602804 | J9: 8.7602804 | K9: 8.7602804 | L9: 8.7602804 | M9: 8.7602804 | N9: 8.7602804 | O9: 8.7602804 | P9: 8.7602804 | Q9: 8.7602804 | R9: 8.7602804 | S9: 8.7602804 | T9: 8.7602804 | U9: 8.7602804 | V9: 8.7602804 | W9: 8.7602804 | X9: 8.7602804
A10: Commercial | B10: Hotel | D10: New | E10: COMHOTNewDMD | F10: Mm2 | G10: 0 | H10: 0.23957402 | I10: 1.4374441 | J10: 2.6353143 | K10: 3.8331844 | L10: 5.0310545 | M10: 6.2289246 | N10: 7.4267947 | O10: 8.6246649 | P10: 9.822535 | Q10: 11.020405 | R10: 12.218275 | S10: 13.416145 | T10: 14.614015 | U10: 15.811886 | V10: 17.009756 | W10: 18.207626 | X10: 19.405496
A11: Commercial | B11: Retail | D11: New | E11: COMRETNewDMD | F11: Mm2 | G11: 0 | H11: 0.46162113 | I11: 2.7697268 | J11: 5.0778324 | K11: 7.3859381 | L11: 9.6940437 | M11: 12.002149 | N11: 14.310255 | O11: 16.618361 | P11: 18.926466 | Q11: 21.234572 | R11: 23.542678 | S11: 25.850783 | T11: 28.158889 | U11: 30.466995 | V11: 32.7751 | W11: 35.083206 | X11: 37.391311
A12: Commercial | B12: Office | D12: New | E12: COMOFFNewDMD | F12: Mm2 | G12: 0 | H12: 1.4632964 | I12: 8.7797783 | J12: 16.09626 | K12: 23.412742 | L12: 30.729224 | M12: 38.045706 | N12: 45.362188 | O12: 52.67867 | P12: 59.995152 | Q12: 67.311633 | R12: 74.628115 | S12: 81.944597 | T12: 89.261079 | U12: 96.577561 | V12: 103.89404 | W12: 111.21052 | X12: 118.52701
A13: Commercial | B13: Hospital | D13: New | E13: COMHOPNewDMD | F13: Mm2 | G13: 0 | H13: 0.88764519 | I13: 5.3258711 | J13: 9.764097 | K13: 14.202323 | L13: 18.640549 | M13: 23.078775 | N13: 27.517001 | O13: 31.955227 | P13: 36.393453 | Q13: 40.831679 | R13: 45.269904 | S13: 49.70813 | T13: 54.146356 | U13: 58.584582 | V13: 63.022808 | W13: 67.461034 | X13: 71.89926
... A17: Commercial | B17: Other | D17: New | E17: COMOTHNewDMD | F17: Mm2 | G17: 0 | H17: 0.17520561 | I17: 1.0512337 | J17: 1.9272617 | K17: 2.8032897 | L17: 3.6793178 | M17: 4.5553458 | N17: 5.4313739 | O17: 6.3074019 | P17: 7.18343 | Q17: 8.059458 | R17: 8.9354861 | S17: 9.8115141 | T17: 10.687542 | U17: 11.56357 | V17: 12.439598 | W17: 13.315626 | X17: 14.191654
A18: Residential | B18: Apartment | C18: Low Income | D18: Old | E18: RESAPALOOldDMD | F18: Mm2 | G18: 51.807877 | H18: 51.807877 | I18: 51.807877 | J18: 51.807877 | K18: 51.807877 | L18: 51.807877 | M18: 51.807877 | N18: 51.807877 | O18: 51.807877 | P18: 51.807877 | Q18: 51.807877 | R18: 51.807877 | S18: 51.807877 | T18: 51.807877 | U18: 51.807877 | V18: 51.807877 | W18: 51.807877 | X18: 51.807877
A19: Residential | B19: House | C19: Low Income | D19: Old | E19: RESHOULOOldDMD | F19: Mm2 | G19: 14.956798 | H19: 14.956798 | I19: 14.956798 | J19: 14.956798 | K19: 14.956798 | L19: 14.956798 | M19: 14.956798 | N19: 14.956798 | O19: 14.956798 | P19: 14.956798 | Q19: 14.956798 | R19: 14.956798 | S19: 14.956798 | T19: 14.956798 | U19: 14.956798 | V19: 14.956798 | W19: 14.956798 | X19: 14.956798
A20: Residential | B20: Apartment | C20: Lower-Middle Income | D20: Old | E20: RESAPALMOldDMD | F20: Mm2 | G20: 57.121976 | H20: 57.121976 | I20: 57.121976 | J20: 57.121976 | K20: 57.121976 | L20: 57.121976 | M20: 57.121976 | N20: 57.121976 | O20: 57.121976 | P20: 57.121976 | Q20: 57.121976 | R20: 57.121976 | S20: 57.121976 | T20: 57.121976 | U20: 57.121976 | V20: 57.121976 | W20: 57.121976 | X20: 57.121976
A21: Residential | B21: House | C21: Lower-Middle Income | D21: Old | E21: RESHOULMOldDMD | F21: Mm2 | G21: 38.299259 | H21: 38.299259 | I21: 38.299259 | J21: 38.299259 | K21: 38.299259 | L21: 38.299259 | M21: 38.299259 | N21: 38.299259 | O21: 38.299259 | P21: 38.299259 | Q21: 38.299259 | R21: 38.299259 | S21: 38.299259 | T21: 38.299259 | U21: 38.299259 | V21: 38.299259 | W21: 38.299259 | X21: 38.299259
A22: Residential | B22: Apartment | C22: Upper-Middle Income | D22: Old | E22: RESAPAUMOldDMD | F22: Mm2 | G22: 15.495888 | H22: 15.495888 | I22: 15.495888 | J22: 15.495888 | K22: 15.495888 | L22: 15.495888 | M22: 15.495888 | N22: 15.495888 | O22: 15.495888 | P22: 15.495888 | Q22: 15.495888 | R22: 15.495888 | S22: 15.495888 | T22: 15.495888 | U22: 15.495888 | V22: 15.495888 | W22: 15.495888 | X22: 15.495888
A23: Residential | B23: House | C23: Upper-Middle Income | D23: Old | E23: RESHOUUMOldDMD | F23: Mm2 | G23: 19.187214 | H23: 19.187214 | I23: 19.187214 | J23: 19.187214 | K23: 19.187214 | L23: 19.187214 | M23: 19.187214 | N23: 19.187214 | O23: 19.187214 | P23: 19.187214 | Q23: 19.187214 | R23: 19.187214 | S23: 19.187214 | T23: 19.187214 | U23: 19.187214 | V23: 19.187214 | W23: 19.187214 | X23: 19.187214
A24: Residential | B24: Apartment | C24: High Income | D24: Old | E24: RESAPAHIOldDMD | F24: Mm2 | G24: 66.398717 | H24: 66.398717 | I24: 66.398717 | J24: 66.398717 | K24: 66.398717 | L24: 66.398717 | M24: 66.398717 | N24: 66.398717 | O24: 66.398717 | P24: 66.398717 | Q24: 66.398717 | R24: 66.398717 | S24: 66.398717 | T24: 66.398717 | U24: 66.398717 | V24: 66.398717 | W24: 66.398717 | X24: 66.398717
A25: Residential | B25: House | C25: High Income | D25: Old | E25: RESHOUHIOldDMD | F25: Mm2 | G25: 96.552051 | H25: 96.552051 | I25: 96.552051 | J25: 96.552051 | K25: 96.552051 | L25: 96.552051 | M25: 96.552051 | N25: 96.552051 | O25: 96.552051 | P25: 96.552051 | Q25: 96.552051 | R25: 96.552051 | S25: 96.552051 | T25: 96.552051 | U25: 96.552051 | V25: 96.552051 | W25: 96.552051 | X25: 96.552051
A26: Residential | B26: Apartment | C26: Low Income | D26: New | E26: RESAPALONewDMD | F26: Mm2 | G26: 0 | H26: 0.25903939 | I26: 1.5542363 | J26: 2.8494333 | K26: 4.1446302 | L26: 5.4398271 | M26: 6.7350241 | N26: 8.030221 | O26: 9.3254179 | P26: 10.620615 | Q26: 11.915812 | R26: 13.211009 | S26: 14.506206 | T26: 15.801403 | U26: 17.0966 | V26: 18.391797 | W26: 19.686993 | X26: 20.98219
A27: Residential | B27: House | C27: Low Income | D27: New | E27: RESHOULONewDMD | F27: Mm2 | G27: 0 | H27: 0.07478399 | I27: 0.44870394 | J27: 0.82262389 | K27: 1.1965438 | L27: 1.5704638 | M27: 1.9443837 | N27: 2.3183037 | O27: 2.6922236 | P27: 3.0661436 | Q27: 3.4400635 | R27: 3.8139835 | S27: 4.1879034 | T27: 4.5618234 | U27: 4.9357433 | V27: 5.3096633 | W27: 5.6835832 | X27: 6.0575032
A28: Residential | B28: Apartment | C28: Lower-Middle Income | D28: New | E28: RESAPALMNewDMD | F28: Mm2 | G28: 0 | H28: 0.28560988 | I28: 1.7136593 | J28: 3.1417087 | K28: 4.5697581 | L28: 5.9978075 | M28: 7.4258569 | N28: 8.8539063 | O28: 10.281956 | P28: 11.710005 | Q28: 13.138055 | R28: 14.566104 | S28: 15.994153 | T28: 17.422203 | U28: 18.850252 | V28: 20.278302 | W28: 21.706351 | X28: 23.1344
A29: Residential | B29: House | C29: Lower-Middle Income | D29: New | E29: RESHOULMNewDMD | F29: Mm2 | G29: 0 | H29: 0.19149629 | I29: 1.1489778 | J29: 2.1064592 | K29: 3.0639407 | L29: 4.0214222 | M29: 4.9789036 | N29: 5.9363851 | O29: 6.8938665 | P29: 7.851348 | Q29: 8.8088295 | R29: 9.7663109 | S29: 10.723792 | T29: 11.681274 | U29: 12.638755 | V29: 13.596237 | W29: 14.553718 | X29: 15.5112
... A33: Residential | B33: House | C33: High Income | D33: New | E33: RESHOUHINewDMD | F33: Mm2 | G33: 0 | H33: 0.48276025 | I33: 2.8965615 | J33: 5.3103628 | K33: 7.7241641 | L33: 10.137965 | M33: 12.551767 | N33: 14.965568 | O33: 17.379369 | P33: 19.79317 | Q33: 22.206972 | R33: 24.620773 | S33: 27.034574 | T33: 29.448376 | U33: 31.862177 | V33: 34.275978 | W33: 36.689779 | X33: 39.103581
A34: Industrial | B34: All Industries | E34: INDAINDMD | F34: TJ | G34: 66716.461 | H34: 68050.79 | I34: 74855.869 | J34: 82341.456 | K34: 90575.602 | L34: 99633.162 | M34: 109596.48 | N34: 120556.13 | O34: 132611.74 | P34: 145872.91 | Q34: 160460.2 | R34: 176506.22 | S34: 194156.85 | T34: 213572.53 | U34: 234929.78 | V34: 258422.76 | W34: 284265.04 | X34: 312691.54
A35: Transportation | B35: Passenger | C35: Passenger Car | E35: TRAPASCARDMD | F35: M Vkm | G35: 68921.251 | H35: 69265.857 | I35: 70997.504 | J35: 72772.441 | K35: 74591.752 | L35: 76456.546 | M35: 78367.96 | N35: 80327.159 | O35: 82335.338 | P35: 84393.721 | Q35: 86503.564 | R35: 88666.153 | S35: 90882.807 | T35: 93154.877 | U35: 95483.749 | V35: 97870.843 | W35: 100317.61 | X35: 102825.55
A36: Transportation | B36: Passenger | C36: Passenger Truck | E36: TRAPASLDTDMD | F36: M Vkm | G36: 0 | H36: 0 | I36: 0 | J36: 0 | K36: 0 | L36: 0 | M36: 0 | N36: 0 | O36: 0 | P36: 0 | Q36: 0 | R36: 0 | S36: 0 | T36: 0 | U36: 0 | V36: 0 | W36: 0 | X36: 0
A37: Transportation | B37: Passenger | C37: Motorcycle | E37: TRAPASMOTDMD | F37: M Vkm | G37: 0 | H37: 0 | I37: 0 | J37: 0 | K37: 0 | L37: 0 | M37: 0 | N37: 0 | O37: 0 | P37: 0 | Q37: 0 | R37: 0 | S37: 0 | T37: 0 | U37: 0 | V37: 0 | W37: 0 | X37: 0
A38: Transportation | B38: Freight | C38: Light Commercial Truck | E38: TRAFRECLTDMD | F38: M Vkm | G38: 1578.5179 | H38: 1586.4105 | I38: 1626.0707 | J38: 1666.7225 | K38: 1708.3906 | L38: 1751.1003 | M38: 1794.8778 | N38: 1839.7498 | O38: 1885.7435 | P38: 1932.8871 | Q38: 1981.2093 | R38: 2030.7395 | S38: 2081.508 | T38: 2133.5457 | U38: 2186.8844 | V38: 2241.5565 | W38: 2297.5954 | X38: 2355.0353
A39: Transportation | B39: Freight | C39: Refuse Truck | E39: TRAFRERFTDMD | F39: M Vkm | G39: 70.026308 | H39: 70.37644 | I39: 72.135851 | J39: 73.939247 | K39: 75.787728 | L39: 77.682421 | M39: 79.624482 | N39: 81.615094 | O39: 83.655471 | P39: 85.746858 | Q39: 87.89053 | R39: 90.087793 | S39: 92.339988 | T39: 94.648487 | U39: 97.0147 | V39: 99.440067 | W39: 101.92607 | X39: 104.47422
A40: Transportation | B40: Freight | C40: Single Unit Long-haul Truck | E40: TRAFRESLHDMD | F40: M Vkm | G40: 0 | H40: 0 | I40: 0 | J40: 0 | K40: 0 | L40: 0 | M40: 0 | N40: 0 | O40: 0 | P40: 0 | Q40: 0 | R40: 0 | S40: 0 | T40: 0 | U40: 0 | V40: 0 | W40: 0 | X40: 0
A41: Transportation | B41: Freight | C41: Single Unit Short-haul Truck | E41: TRAFRESSHDMD | F41: M Vkm | G41: 0 | H41: 0 | I41: 0 | J41: 0 | K41: 0 | L41: 0 | M41: 0 | N41: 0 | O41: 0 | P41: 0 | Q41: 0 | R41: 0 | S41: 0 | T41: 0 | U41: 0 | V41: 0 | W41: 0 | X41: 0
A42: Transportation | B42: Freight | C42: Combination Long-haul Truck | E42: TRAFRECLHDMD | F42: M Vkm | G42: 1367.6202 | H42: 1374.4583 | I42: 1408.8197 | J42: 1444.0402 | K42: 1480.1412 | L42: 1517.1447 | M42: 1555.0734 | N42: 1593.9502 | O42: 1633.7989 | P42: 1674.6439 | Q42: 1716.51 | R42: 1759.4228 | S42: 1803.4083 | T42: 1848.4935 | U42: 1894.7059 | V42: 1942.0735 | W42: 1990.6254 | X42: 2040.391
A43: Transportation | B43: Freight | C43: Combination Short-haul Truck | E43: TRAFRECSHDMD | F43: M Vkm | G43: 0 | H43: 0 | I43: 0 | J43: 0 | K43: 0 | L43: 0 | M43: 0 | N43: 0 | O43: 0 | P43: 0 | Q43: 0 | R43: 0 | S43: 0 | T43: 0 | U43: 0 | V43: 0 | W43: 0 | X43: 0
A44: Transportation | B44: Passenger | C44: Transit Bus | E44: TRAPASTBUDMD | F44: M Vkm | G44: 498.20419 | H44: 500.69521 | I44: 513.21259 | J44: 526.0429 | K44: 539.19397 | L44: 552.67382 | M44: 566.49067 | N44: 580.65294 | O44: 595.16926 | P44: 610.04849 | Q44: 625.2997 | R44: 640.93219 | S44: 656.9555 | T44: 673.37939 | U44: 690.21387 | V44: 707.46922 | W44: 725.15595 | X44: 743.28485
A45: Transportation | B45: Passenger | C45: School Bus | E45: TRAPASSBUDMD | F45: M Vkm | G45: 86.053217 | H45: 86.483483 | I45: 88.645571 | J45: 90.86171 | K45: 93.133253 | L45: 95.461584 | M45: 97.848123 | N45: 100.29433 | O45: 102.80168 | P45: 105.37173 | Q45: 108.00602 | R45: 110.70617 | S45: 113.47382 | T45: 116.31067 | U45: 119.21844 | V45: 122.1989 | W45: 125.25387 | X45: 128.38522
A46: Transportation | B46: Passenger | C46: Other Buses | E46: TRAPASOBUDMD | F46: M Vkm | G46: 0 | H46: 0 | I46: 0 | J46: 0 | K46: 0 | L46: 0 | M46: 0 | N46: 0 | O46: 0 | P46: 0 | Q46: 0 | R46: 0 | S46: 0 | T46: 0 | U46: 0 | V46: 0 | W46: 0 | X46: 0
...

Sheet >> TIMES

Sheet Def_Tech
B2: ~FI_Process
B3: Sets | C3: TechName | D3: TechDesc | E3: Tact | F3: Tcap | G3: Tslvl | H3: PrimaryCG | I3: Vintage
B4: *Process Set Membership | C4: Technology Name | D4: Technology Description | E4: Activity Unit | F4: Capacity Unit | G4: TimeSlice level of Process Activity | H4: Primary Commodity Group | I4: Vintage Tracking
B5: MIN | C5: =Def_Comm!C5&"MIN" -> RESAPALONewSHRETMIN | D5: =Def_Comm!D5&" Mining" -> Apartment Low Income New Space heating Retrofit potential Mining | E5: Mm2 | F5: Mm2
C6: =Def_Comm!C6&"MIN" -> RESAPALONewSCRETMIN | D6: =Def_Comm!D6&" Mining" -> Apartment Low Income New Space cooling Retrofit potential Mining | E6: Mm2 | F6: Mm2
C7: =Def_Comm!C7&"MIN" -> RESHOULONewSHRETMIN | D7: =Def_Comm!D7&" Mining" -> House Low Income New Space heating Retrofit potential Mining | E7: Mm2 | F7: Mm2
C8: =Def_Comm!C8&"MIN" -> RESHOULONewSCRETMIN | D8: =Def_Comm!D8&" Mining" -> House Low Income New Space cooling Retrofit potential Mining | E8: Mm2 | F8: Mm2
C9: =Def_Comm!C9&"MIN" -> RESAPALMNewSHRETMIN | D9: =Def_Comm!D9&" Mining" -> Apartment Lower-middle Income New Space heating Retrofit potential Mining | E9: Mm2 | F9: Mm2
C10: =Def_Comm!C10&"MIN" -> RESAPALMNewSCRETMIN | D10: =Def_Comm!D10&" Mining" -> Apartment Lower-middle Income New Space cooling Retrofit potential Mining | E10: Mm2 | F10: Mm2
C11: =Def_Comm!C11&"MIN" -> RESHOULMNewSHRETMIN | D11: =Def_Comm!D11&" Mining" -> House Lower-middle Income New Space heating Retrofit potential Mining | E11: Mm2 | F11: Mm2
C12: =Def_Comm!C12&"MIN" -> RESHOULMNewSCRETMIN | D12: =Def_Comm!D12&" Mining" -> House Lower-middle Income New Space cooling Retrofit potential Mining | E12: Mm2 | F12: Mm2
C13: =Def_Comm!C13&"MIN" -> RESAPAUMNewSHRETMIN | D13: =Def_Comm!D13&" Mining" -> Apartment Upper-middle Income New Space heating Retrofit potential Mining | E13: Mm2 | F13: Mm2
C14: =Def_Comm!C14&"MIN" -> RESAPAUMNewSCRETMIN | D14: =Def_Comm!D14&" Mining" -> Apartment Upper-middle Income New Space cooling Retrofit potential Mining | E14: Mm2 | F14: Mm2
C15: =Def_Comm!C15&"MIN" -> RESHOUUMNewSHRETMIN | D15: =Def_Comm!D15&" Mining" -> House Upper-middle Income New Space heating Retrofit potential Mining | E15: Mm2 | F15: Mm2
C16: =Def_Comm!C16&"MIN" -> RESHOUUMNewSCRETMIN | D16: =Def_Comm!D16&" Mining" -> House Upper-middle Income New Space cooling Retrofit potential Mining | E16: Mm2 | F16: Mm2
C17: =Def_Comm!C17&"MIN" -> RESAPAHINewSHRETMIN | D17: =Def_Comm!D17&" Mining" -> Apartment High Income New Space heating Retrofit potential Mining | E17: Mm2 | F17: Mm2
... C36: =Def_Comm!C36&"MIN" -> RESHOUHIOldSCRETMIN | D36: =Def_Comm!D36&" Mining" -> House High Income Old Space cooling Retrofit potential Mining | E36: Mm2 | F36: Mm2
B37: * | C37: *
B38: =IF('RET TECH'!N3=1,"PRE","*") -> PRE | C38: ='RET TECH'!M3 -> RESAPALONewSHENVESTAR20 | D38: =_xlfn.XLOOKUP(C38,'RET TECH'!$M:$M,'RET TECH'!$A:$A)&" "&_xlfn.XLOOKUP(C38,'RET TECH'!$M:$M,'RET TECH'!$B:$B)&" "&_xlfn.XLOOKUP(C38,'RET TECH'!$M:$M,'RET TECH'!$C:$C)&" "&_xlfn.XLOOKUP(C38,'RET TECH'!$M:$M,'RET TECH'!$D:$D)&" "&_xlfn.XLOOKUP(C38,'RET TECH'!$M:$M,'RET TECH'!$E:$E)&" "&_xlfn.XLOOKUP(C38,'RET TECH'!$M:$M,'RET TECH'!$F:$F)&" "&_xlfn.XLOOKUP(C38,'RET TECH'!$M:$M,'RET TECH'!$G:$G)&" "&_xlfn.XLOOKUP(C38,'RET TECH'!$M:$M,'RET TECH'!$H:$H) -> Residential Apartment Low Income New Space heating Building enveloppe ENERGY STAR | E38: =IF(F38="*","*",IF(F38="Mlma","Mlm","TJ")) -> TJ | F38: =IF(C38="*","*","MW") -> MW
B39: =IF('RET TECH'!N4=1,"PRE","*") -> PRE | C39: ='RET TECH'!M4 -> RESAPALONewSHENVPATH20 | D39: =_xlfn.XLOOKUP(C39,'RET TECH'!$M:$M,'RET TECH'!$A:$A)&" "&_xlfn.XLOOKUP(C39,'RET TECH'!$M:$M,'RET TECH'!$B:$B)&" "&_xlfn.XLOOKUP(C39,'RET TECH'!$M:$M,'RET TECH'!$C:$C)&" "&_xlfn.XLOOKUP(C39,'RET TECH'!$M:$M,'RET TECH'!$D:$D)&" "&_xlfn.XLOOKUP(C39,'RET TECH'!$M:$M,'RET TECH'!$E:$E)&" "&_xlfn.XLOOKUP(C39,'RET TECH'!$M:$M,'RET TECH'!$F:$F)&" "&_xlfn.XLOOKUP(C39,'RET TECH'!$M:$M,'RET TECH'!$G:$G)&" "&_xlfn.XLOOKUP(C39,'RET TECH'!$M:$M,'RET TECH'!$H:$H) -> Residential Apartment Low Income New Space heating Building enveloppe PATH | E39: =IF(F39="*","*",IF(F39="Mlma","Mlm","TJ")) -> TJ | F39: =IF(C39="*","*","MW") -> MW
B40: =IF('RET TECH'!N5=1,"PRE","*") -> PRE | C40: ='RET TECH'!M5 -> RESAPALONewSHENVIECC4020 | D40: =_xlfn.XLOOKUP(C40,'RET TECH'!$M:$M,'RET TECH'!$A:$A)&" "&_xlfn.XLOOKUP(C40,'RET TECH'!$M:$M,'RET TECH'!$B:$B)&" "&_xlfn.XLOOKUP(C40,'RET TECH'!$M:$M,'RET TECH'!$C:$C)&" "&_xlfn.XLOOKUP(C40,'RET TECH'!$M:$M,'RET TECH'!$D:$D)&" "&_xlfn.XLOOKUP(C40,'RET TECH'!$M:$M,'RET TECH'!$E:$E)&" "&_xlfn.XLOOKUP(C40,'RET TECH'!$M:$M,'RET TECH'!$F:$F)&" "&_xlfn.XLOOKUP(C40,'RET TECH'!$M:$M,'RET TECH'!$G:$G)&" "&_xlfn.XLOOKUP(C40,'RET TECH'!$M:$M,'RET TECH'!$H:$H) -> Residential Apartment Low Income New Space heating Building enveloppe IECC 2009 +40% | E40: =IF(F40="*","*",IF(F40="Mlma","Mlm","TJ")) -> TJ | F40: =IF(C40="*","*","MW") -> MW
B41: =IF('RET TECH'!N6=1,"PRE","*") -> PRE | C41: ='RET TECH'!M6 -> RESAPALONewSHENVIECC20 | D41: =_xlfn.XLOOKUP(C41,'RET TECH'!$M:$M,'RET TECH'!$A:$A)&" "&_xlfn.XLOOKUP(C41,'RET TECH'!$M:$M,'RET TECH'!$B:$B)&" "&_xlfn.XLOOKUP(C41,'RET TECH'!$M:$M,'RET TECH'!$C:$C)&" "&_xlfn.XLOOKUP(C41,'RET TECH'!$M:$M,'RET TECH'!$D:$D)&" "&_xlfn.XLOOKUP(C41,'RET TECH'!$M:$M,'RET TECH'!$E:$E)&" "&_xlfn.XLOOKUP(C41,'RET TECH'!$M:$M,'RET TECH'!$F:$F)&" "&_xlfn.XLOOKUP(C41,'RET TECH'!$M:$M,'RET TECH'!$G:$G)&" "&_xlfn.XLOOKUP(C41,'RET TECH'!$M:$M,'RET TECH'!$H:$H) -> Residential Apartment Low Income New Space heating Building enveloppe IECC 2009 | E41: =IF(F41="*","*",IF(F41="Mlma","Mlm","TJ")) -> TJ | F41: =IF(C41="*","*","MW") -> MW
B42: =IF('RET TECH'!N7=1,"PRE","*") -> * | C42: ='RET TECH'!M7 -> RESAPALONewSCENVESTAR20 | D42: =_xlfn.XLOOKUP(C42,'RET TECH'!$M:$M,'RET TECH'!$A:$A)&" "&_xlfn.XLOOKUP(C42,'RET TECH'!$M:$M,'RET TECH'!$B:$B)&" "&_xlfn.XLOOKUP(C42,'RET TECH'!$M:$M,'RET TECH'!$C:$C)&" "&_xlfn.XLOOKUP(C42,'RET TECH'!$M:$M,'RET TECH'!$D:$D)&" "&_xlfn.XLOOKUP(C42,'RET TECH'!$M:$M,'RET TECH'!$E:$E)&" "&_xlfn.XLOOKUP(C42,'RET TECH'!$M:$M,'RET TECH'!$F:$F)&" "&_xlfn.XLOOKUP(C42,'RET TECH'!$M:$M,'RET TECH'!$G:$G)&" "&_xlfn.XLOOKUP(C42,'RET TECH'!$M:$M,'RET TECH'!$H:$H) -> Residential Apartment Low Income New Space cooling Building enveloppe ENERGY STAR | E42: =IF(F42="*","*",IF(F42="Mlma","Mlm","TJ")) -> TJ | F42: =IF(C42="*","*","MW") -> MW
B43: =IF('RET TECH'!N8=1,"PRE","*") -> * | C43: ='RET TECH'!M8 -> RESAPALONewSCENVPATH20 | D43: =_xlfn.XLOOKUP(C43,'RET TECH'!$M:$M,'RET TECH'!$A:$A)&" "&_xlfn.XLOOKUP(C43,'RET TECH'!$M:$M,'RET TECH'!$B:$B)&" "&_xlfn.XLOOKUP(C43,'RET TECH'!$M:$M,'RET TECH'!$C:$C)&" "&_xlfn.XLOOKUP(C43,'RET TECH'!$M:$M,'RET TECH'!$D:$D)&" "&_xlfn.XLOOKUP(C43,'RET TECH'!$M:$M,'RET TECH'!$E:$E)&" "&_xlfn.XLOOKUP(C43,'RET TECH'!$M:$M,'RET TECH'!$F:$F)&" "&_xlfn.XLOOKUP(C43,'RET TECH'!$M:$M,'RET TECH'!$G:$G)&" "&_xlfn.XLOOKUP(C43,'RET TECH'!$M:$M,'RET TECH'!$H:$H) -> Residential Apartment Low Income New Space cooling Building enveloppe PATH | E43: =IF(F43="*","*",IF(F43="Mlma","Mlm","TJ")) -> TJ | F43: =IF(C43="*","*","MW") -> MW
B44: =IF('RET TECH'!N9=1,"PRE","*") -> * | C44: ='RET TECH'!M9 -> RESAPALONewSCENVIECC4020 | D44: =_xlfn.XLOOKUP(C44,'RET TECH'!$M:$M,'RET TECH'!$A:$A)&" "&_xlfn.XLOOKUP(C44,'RET TECH'!$M:$M,'RET TECH'!$B:$B)&" "&_xlfn.XLOOKUP(C44,'RET TECH'!$M:$M,'RET TECH'!$C:$C)&" "&_xlfn.XLOOKUP(C44,'RET TECH'!$M:$M,'RET TECH'!$D:$D)&" "&_xlfn.XLOOKUP(C44,'RET TECH'!$M:$M,'RET TECH'!$E:$E)&" "&_xlfn.XLOOKUP(C44,'RET TECH'!$M:$M,'RET TECH'!$F:$F)&" "&_xlfn.XLOOKUP(C44,'RET TECH'!$M:$M,'RET TECH'!$G:$G)&" "&_xlfn.XLOOKUP(C44,'RET TECH'!$M:$M,'RET TECH'!$H:$H) -> Residential Apartment Low Income New Space cooling Building enveloppe IECC 2009 +40% | E44: =IF(F44="*","*",IF(F44="Mlma","Mlm","TJ")) -> TJ | F44: =IF(C44="*","*","MW") -> MW
B45: =IF('RET TECH'!N10=1,"PRE","*") -> * | C45: ='RET TECH'!M10 -> RESAPALONewSCENVIECC20 | D45: =_xlfn.XLOOKUP(C45,'RET TECH'!$M:$M,'RET TECH'!$A:$A)&" "&_xlfn.XLOOKUP(C45,'RET TECH'!$M:$M,'RET TECH'!$B:$B)&" "&_xlfn.XLOOKUP(C45,'RET TECH'!$M:$M,'RET TECH'!$C:$C)&" "&_xlfn.XLOOKUP(C45,'RET TECH'!$M:$M,'RET TECH'!$D:$D)&" "&_xlfn.XLOOKUP(C45,'RET TECH'!$M:$M,'RET TECH'!$E:$E)&" "&_xlfn.XLOOKUP(C45,'RET TECH'!$M:$M,'RET TECH'!$F:$F)&" "&_xlfn.XLOOKUP(C45,'RET TECH'!$M:$M,'RET TECH'!$G:$G)&" "&_xlfn.XLOOKUP(C45,'RET TECH'!$M:$M,'RET TECH'!$H:$H) -> Residential Apartment Low Income New Space cooling Building enveloppe IECC 2009 | E45: =IF(F45="*","*",IF(F45="Mlma","Mlm","TJ")) -> TJ | F45: =IF(C45="*","*","MW") -> MW
B46: =IF('RET TECH'!N11=1,"PRE","*") -> PRE | C46: ='RET TECH'!M11 -> RESHOULONewSHENVESTAR20 | D46: =_xlfn.XLOOKUP(C46,'RET TECH'!$M:$M,'RET TECH'!$A:$A)&" "&_xlfn.XLOOKUP(C46,'RET TECH'!$M:$M,'RET TECH'!$B:$B)&" "&_xlfn.XLOOKUP(C46,'RET TECH'!$M:$M,'RET TECH'!$C:$C)&" "&_xlfn.XLOOKUP(C46,'RET TECH'!$M:$M,'RET TECH'!$D:$D)&" "&_xlfn.XLOOKUP(C46,'RET TECH'!$M:$M,'RET TECH'!$E:$E)&" "&_xlfn.XLOOKUP(C46,'RET TECH'!$M:$M,'RET TECH'!$F:$F)&" "&_xlfn.XLOOKUP(C46,'RET TECH'!$M:$M,'RET TECH'!$G:$G)&" "&_xlfn.XLOOKUP(C46,'RET TECH'!$M:$M,'RET TECH'!$H:$H) -> Residential House Low Income New Space heating Building enveloppe ENERGY STAR | E46: =IF(F46="*","*",IF(F46="Mlma","Mlm","TJ")) -> TJ | F46: =IF(C46="*","*","MW") -> MW
B47: =IF('RET TECH'!N12=1,"PRE","*") -> PRE | C47: ='RET TECH'!M12 -> RESHOULONewSHENVPATH20 | D47: =_xlfn.XLOOKUP(C47,'RET TECH'!$M:$M,'RET TECH'!$A:$A)&" "&_xlfn.XLOOKUP(C47,'RET TECH'!$M:$M,'RET TECH'!$B:$B)&" "&_xlfn.XLOOKUP(C47,'RET TECH'!$M:$M,'RET TECH'!$C:$C)&" "&_xlfn.XLOOKUP(C47,'RET TECH'!$M:$M,'RET TECH'!$D:$D)&" "&_xlfn.XLOOKUP(C47,'RET TECH'!$M:$M,'RET TECH'!$E:$E)&" "&_xlfn.XLOOKUP(C47,'RET TECH'!$M:$M,'RET TECH'!$F:$F)&" "&_xlfn.XLOOKUP(C47,'RET TECH'!$M:$M,'RET TECH'!$G:$G)&" "&_xlfn.XLOOKUP(C47,'RET TECH'!$M:$M,'RET TECH'!$H:$H) -> Residential House Low Income New Space heating Building enveloppe PATH | E47: =IF(F47="*","*",IF(F47="Mlma","Mlm","TJ")) -> TJ | F47: =IF(C47="*","*","MW") -> MW
B48: =IF('RET TECH'!N13=1,"PRE","*") -> PRE | C48: ='RET TECH'!M13 -> RESHOULONewSHENVIECC4020 | D48: =_xlfn.XLOOKUP(C48,'RET TECH'!$M:$M,'RET TECH'!$A:$A)&" "&_xlfn.XLOOKUP(C48,'RET TECH'!$M:$M,'RET TECH'!$B:$B)&" "&_xlfn.XLOOKUP(C48,'RET TECH'!$M:$M,'RET TECH'!$C:$C)&" "&_xlfn.XLOOKUP(C48,'RET TECH'!$M:$M,'RET TECH'!$D:$D)&" "&_xlfn.XLOOKUP(C48,'RET TECH'!$M:$M,'RET TECH'!$E:$E)&" "&_xlfn.XLOOKUP(C48,'RET TECH'!$M:$M,'RET TECH'!$F:$F)&" "&_xlfn.XLOOKUP(C48,'RET TECH'!$M:$M,'RET TECH'!$G:$G)&" "&_xlfn.XLOOKUP(C48,'RET TECH'!$M:$M,'RET TECH'!$H:$H) -> Residential House Low Income New Space heating Building enveloppe IECC 2009 +40% | E48: =IF(F48="*","*",IF(F48="Mlma","Mlm","TJ")) -> TJ | F48: =IF(C48="*","*","MW") -> MW
B49: =IF('RET TECH'!N14=1,"PRE","*") -> PRE | C49: ='RET TECH'!M14 -> RESHOULONewSHENVIECC20 | D49: =_xlfn.XLOOKUP(C49,'RET TECH'!$M:$M,'RET TECH'!$A:$A)&" "&_xlfn.XLOOKUP(C49,'RET TECH'!$M:$M,'RET TECH'!$B:$B)&" "&_xlfn.XLOOKUP(C49,'RET TECH'!$M:$M,'RET TECH'!$C:$C)&" "&_xlfn.XLOOKUP(C49,'RET TECH'!$M:$M,'RET TECH'!$D:$D)&" "&_xlfn.XLOOKUP(C49,'RET TECH'!$M:$M,'RET TECH'!$E:$E)&" "&_xlfn.XLOOKUP(C49,'RET TECH'!$M:$M,'RET TECH'!$F:$F)&" "&_xlfn.XLOOKUP(C49,'RET TECH'!$M:$M,'RET TECH'!$G:$G)&" "&_xlfn.XLOOKUP(C49,'RET TECH'!$M:$M,'RET TECH'!$H:$H) -> Residential House Low Income New Space heating Building enveloppe IECC 2009 | E49: =IF(F49="*","*",IF(F49="Mlma","Mlm","TJ")) -> TJ | F49: =IF(C49="*","*","MW") -> MW
... B166: =IF('RET TECH'!N131=1,"PRE","*") -> PRE | C166: ='RET TECH'!M131 -> RESHOUHIOldSCENVIECC20 | D166: =_xlfn.XLOOKUP(C166,'RET TECH'!$M:$M,'RET TECH'!$A:$A)&" "&_xlfn.XLOOKUP(C166,'RET TECH'!$M:$M,'RET TECH'!$B:$B)&" "&_xlfn.XLOOKUP(C166,'RET TECH'!$M:$M,'RET TECH'!$C:$C)&" "&_xlfn.XLOOKUP(C166,'RET TECH'!$M:$M,'RET TECH'!$D:$D)&" "&_xlfn.XLOOKUP(C166,'RET TECH'!$M:$M,'RET TECH'!$E:$E)&" "&_xlfn.XLOOKUP(C166,'RET TECH'!$M:$M,'RET TECH'!$F:$F)&" "&_xlfn.XLOOKUP(C166,'RET TECH'!$M:$M,'RET TECH'!$G:$G)&" "&_xlfn.XLOOKUP(C166,'RET TECH'!$M:$M,'RET TECH'!$H:$H) -> Residential House High Income Old Space cooling Building enveloppe IECC 2009 | E166: =IF(F166="*","*",IF(F166="Mlma","Mlm","TJ")) -> TJ | F166: =IF(C166="*","*","MW") -> MW
C3347: ='RET TECH'!M3312 -> 0 | D3347: ='RET TECH'!A3312&" "&'RET TECH'!B3312&" "&'RET TECH'!C3312&" "&'RET TECH'!D3312&" "&'RET TECH'!E3312&" "&'RET TECH'!F3312&" "&'RET TECH'!G3312&" "&'RET TECH'!H3312 | E3347: =IF(F3347="Mlma","Mlm","TJ") -> TJ | F3347: ='RET TECH'!Q3312 -> 0
C3348: ='RET TECH'!M3313 -> 0 | D3348: ='RET TECH'!A3313&" "&'RET TECH'!B3313&" "&'RET TECH'!C3313&" "&'RET TECH'!D3313&" "&'RET TECH'!E3313&" "&'RET TECH'!F3313&" "&'RET TECH'!G3313&" "&'RET TECH'!H3313 | E3348: =IF(F3348="Mlma","Mlm","TJ") -> TJ | F3348: ='RET TECH'!Q3313 -> 0
C3349: ='RET TECH'!M3314 -> 0 | D3349: ='RET TECH'!A3314&" "&'RET TECH'!B3314&" "&'RET TECH'!C3314&" "&'RET TECH'!D3314&" "&'RET TECH'!E3314&" "&'RET TECH'!F3314&" "&'RET TECH'!G3314&" "&'RET TECH'!H3314 | E3349: =IF(F3349="Mlma","Mlm","TJ") -> TJ | F3349: ='RET TECH'!Q3314 -> 0
C3350: ='RET TECH'!M3315 -> 0 | D3350: ='RET TECH'!A3315&" "&'RET TECH'!B3315&" "&'RET TECH'!C3315&" "&'RET TECH'!D3315&" "&'RET TECH'!E3315&" "&'RET TECH'!F3315&" "&'RET TECH'!G3315&" "&'RET TECH'!H3315 | E3350: =IF(F3350="Mlma","Mlm","TJ") -> TJ | F3350: ='RET TECH'!Q3315 -> 0
C3351: ='RET TECH'!M3316 -> 0 | D3351: ='RET TECH'!A3316&" "&'RET TECH'!B3316&" "&'RET TECH'!C3316&" "&'RET TECH'!D3316&" "&'RET TECH'!E3316&" "&'RET TECH'!F3316&" "&'RET TECH'!G3316&" "&'RET TECH'!H3316 | E3351: =IF(F3351="Mlma","Mlm","TJ") -> TJ | F3351: ='RET TECH'!Q3316 -> 0
C3352: ='RET TECH'!M3317 -> 0 | D3352: ='RET TECH'!A3317&" "&'RET TECH'!B3317&" "&'RET TECH'!C3317&" "&'RET TECH'!D3317&" "&'RET TECH'!E3317&" "&'RET TECH'!F3317&" "&'RET TECH'!G3317&" "&'RET TECH'!H3317 | E3352: =IF(F3352="Mlma","Mlm","TJ") -> TJ | F3352: ='RET TECH'!Q3317 -> 0

Sheet Def_Comm
B2: ~FI_Comm
B3: Csets | C3: CommName | D3: CommDesc | E3: Unit | F3: LimType | G3: CTSLvl | H3: PeakTS | I3: Ctype
B4: *Commodity Set Membership | C4: Commodity Name | D4: Commodity Description | E4: Unit | F4: Sense of the Balance EQN. | G4: Timeslice Level | H4: Peak Monitoring | I4: Electricity Indicator
C5: {=_xlfn._xlws.FILTER(_xlfn.UNIQUE('RET TECH'!K3:K131),_xlfn.UNIQUE('RET TECH'!K3:K131)<>0,"")} -> RESAPALONewSHRET | D5: =_xlfn.XLOOKUP(C5,'RET TECH'!K:K,'RET TECH'!B:B)&" "&_xlfn.XLOOKUP(C5,'RET TECH'!K:K,'RET TECH'!C:C)&" "&_xlfn.XLOOKUP(C5,'RET TECH'!K:K,'RET TECH'!D:D)&" "&_xlfn.XLOOKUP(C5,'RET TECH'!K:K,'RET TECH'!E:E)&" Retrofit potential" -> Apartment Low Income New Space heating Retrofit potential | E5: Mm2
C6: RESAPALONewSCRET | D6: =_xlfn.XLOOKUP(C6,'RET TECH'!K:K,'RET TECH'!B:B)&" "&_xlfn.XLOOKUP(C6,'RET TECH'!K:K,'RET TECH'!C:C)&" "&_xlfn.XLOOKUP(C6,'RET TECH'!K:K,'RET TECH'!D:D)&" "&_xlfn.XLOOKUP(C6,'RET TECH'!K:K,'RET TECH'!E:E)&" Retrofit potential" -> Apartment Low Income New Space cooling Retrofit potential | E6: Mm2
C7: RESHOULONewSHRET | D7: =_xlfn.XLOOKUP(C7,'RET TECH'!K:K,'RET TECH'!B:B)&" "&_xlfn.XLOOKUP(C7,'RET TECH'!K:K,'RET TECH'!C:C)&" "&_xlfn.XLOOKUP(C7,'RET TECH'!K:K,'RET TECH'!D:D)&" "&_xlfn.XLOOKUP(C7,'RET TECH'!K:K,'RET TECH'!E:E)&" Retrofit potential" -> House Low Income New Space heating Retrofit potential | E7: Mm2
C8: RESHOULONewSCRET | D8: =_xlfn.XLOOKUP(C8,'RET TECH'!K:K,'RET TECH'!B:B)&" "&_xlfn.XLOOKUP(C8,'RET TECH'!K:K,'RET TECH'!C:C)&" "&_xlfn.XLOOKUP(C8,'RET TECH'!K:K,'RET TECH'!D:D)&" "&_xlfn.XLOOKUP(C8,'RET TECH'!K:K,'RET TECH'!E:E)&" Retrofit potential" -> House Low Income New Space cooling Retrofit potential | E8: Mm2
C9: RESAPALMNewSHRET | D9: =_xlfn.XLOOKUP(C9,'RET TECH'!K:K,'RET TECH'!B:B)&" "&_xlfn.XLOOKUP(C9,'RET TECH'!K:K,'RET TECH'!C:C)&" "&_xlfn.XLOOKUP(C9,'RET TECH'!K:K,'RET TECH'!D:D)&" "&_xlfn.XLOOKUP(C9,'RET TECH'!K:K,'RET TECH'!E:E)&" Retrofit potential" -> Apartment Lower-middle Income New Space heating Retrofit potential | E9: Mm2
C10: RESAPALMNewSCRET | D10: =_xlfn.XLOOKUP(C10,'RET TECH'!K:K,'RET TECH'!B:B)&" "&_xlfn.XLOOKUP(C10,'RET TECH'!K:K,'RET TECH'!C:C)&" "&_xlfn.XLOOKUP(C10,'RET TECH'!K:K,'RET TECH'!D:D)&" "&_xlfn.XLOOKUP(C10,'RET TECH'!K:K,'RET TECH'!E:E)&" Retrofit potential" -> Apartment Lower-middle Income New Space cooling Retrofit potential | E10: Mm2
C11: RESHOULMNewSHRET | D11: =_xlfn.XLOOKUP(C11,'RET TECH'!K:K,'RET TECH'!B:B)&" "&_xlfn.XLOOKUP(C11,'RET TECH'!K:K,'RET TECH'!C:C)&" "&_xlfn.XLOOKUP(C11,'RET TECH'!K:K,'RET TECH'!D:D)&" "&_xlfn.XLOOKUP(C11,'RET TECH'!K:K,'RET TECH'!E:E)&" Retrofit potential" -> House Lower-middle Income New Space heating Retrofit potential | E11: Mm2
C12: RESHOULMNewSCRET | D12: =_xlfn.XLOOKUP(C12,'RET TECH'!K:K,'RET TECH'!B:B)&" "&_xlfn.XLOOKUP(C12,'RET TECH'!K:K,'RET TECH'!C:C)&" "&_xlfn.XLOOKUP(C12,'RET TECH'!K:K,'RET TECH'!D:D)&" "&_xlfn.XLOOKUP(C12,'RET TECH'!K:K,'RET TECH'!E:E)&" Retrofit potential" -> House Lower-middle Income New Space cooling Retrofit potential | E12: Mm2
C13: RESAPAUMNewSHRET | D13: =_xlfn.XLOOKUP(C13,'RET TECH'!K:K,'RET TECH'!B:B)&" "&_xlfn.XLOOKUP(C13,'RET TECH'!K:K,'RET TECH'!C:C)&" "&_xlfn.XLOOKUP(C13,'RET TECH'!K:K,'RET TECH'!D:D)&" "&_xlfn.XLOOKUP(C13,'RET TECH'!K:K,'RET TECH'!E:E)&" Retrofit potential" -> Apartment Upper-middle Income New Space heating Retrofit potential | E13: Mm2
C14: RESAPAUMNewSCRET | D14: =_xlfn.XLOOKUP(C14,'RET TECH'!K:K,'RET TECH'!B:B)&" "&_xlfn.XLOOKUP(C14,'RET TECH'!K:K,'RET TECH'!C:C)&" "&_xlfn.XLOOKUP(C14,'RET TECH'!K:K,'RET TECH'!D:D)&" "&_xlfn.XLOOKUP(C14,'RET TECH'!K:K,'RET TECH'!E:E)&" Retrofit potential" -> Apartment Upper-middle Income New Space cooling Retrofit potential | E14: Mm2
C15: RESHOUUMNewSHRET | D15: =_xlfn.XLOOKUP(C15,'RET TECH'!K:K,'RET TECH'!B:B)&" "&_xlfn.XLOOKUP(C15,'RET TECH'!K:K,'RET TECH'!C:C)&" "&_xlfn.XLOOKUP(C15,'RET TECH'!K:K,'RET TECH'!D:D)&" "&_xlfn.XLOOKUP(C15,'RET TECH'!K:K,'RET TECH'!E:E)&" Retrofit potential" -> House Upper-middle Income New Space heating Retrofit potential | E15: Mm2
C16: RESHOUUMNewSCRET | D16: =_xlfn.XLOOKUP(C16,'RET TECH'!K:K,'RET TECH'!B:B)&" "&_xlfn.XLOOKUP(C16,'RET TECH'!K:K,'RET TECH'!C:C)&" "&_xlfn.XLOOKUP(C16,'RET TECH'!K:K,'RET TECH'!D:D)&" "&_xlfn.XLOOKUP(C16,'RET TECH'!K:K,'RET TECH'!E:E)&" Retrofit potential" -> House Upper-middle Income New Space cooling Retrofit potential | E16: Mm2
C17: RESAPAHINewSHRET | D17: =_xlfn.XLOOKUP(C17,'RET TECH'!K:K,'RET TECH'!B:B)&" "&_xlfn.XLOOKUP(C17,'RET TECH'!K:K,'RET TECH'!C:C)&" "&_xlfn.XLOOKUP(C17,'RET TECH'!K:K,'RET TECH'!D:D)&" "&_xlfn.XLOOKUP(C17,'RET TECH'!K:K,'RET TECH'!E:E)&" Retrofit potential" -> Apartment High Income New Space heating Retrofit potential | E17: Mm2
... C36: RESHOUHIOldSCRET | D36: =_xlfn.XLOOKUP(C36,'RET TECH'!K:K,'RET TECH'!B:B)&" "&_xlfn.XLOOKUP(C36,'RET TECH'!K:K,'RET TECH'!C:C)&" "&_xlfn.XLOOKUP(C36,'RET TECH'!K:K,'RET TECH'!D:D)&" "&_xlfn.XLOOKUP(C36,'RET TECH'!K:K,'RET TECH'!E:E)&" Retrofit potential" -> House High Income Old Space cooling Retrofit potential | E36: Mm2

Sheet TECH RET
E2: =Demand!G1 -> 2019 | F2: =Demand!H1 -> 2020 | G2: =Demand!I1 -> 2025 | H2: =Demand!J1 -> 2030 | I2: =Demand!K1 -> 2035 | J2: =Demand!L1 -> 2040 | K2: =Demand!M1 -> 2045 | L2: =Demand!N1 -> 2050 | ... V2: =Demand!X1 -> 2100
E3: ACT_BND~UP | F3: ACT_BND~UP | G3: ACT_BND~UP | H3: ACT_BND~UP | I3: ACT_BND~UP | J3: ACT_BND~UP | K3: ACT_BND~UP | L3: ACT_BND~UP | M3: ACT_BND~UP | N3: ACT_BND~UP | O3: ACT_BND~UP | P3: ACT_BND~UP | Q3: ACT_BND~UP | R3: ACT_BND~UP | S3: ACT_BND~UP | T3: ACT_BND~UP | U3: ACT_BND~UP | V3: ACT_BND~UP
C5: ~FI_T | AA5: ~FI_T
B6: TechName | C6: Comm-OUT | D6: ACT_COST | E6: =E3&"~"&E2 -> ACT_BND~UP~2019 | F6: =F3&"~"&F2 -> ACT_BND~UP~2020 | G6: =G3&"~"&G2 -> ACT_BND~UP~2025 | H6: =H3&"~"&H2 -> ACT_BND~UP~2030 | I6: =I3&"~"&I2 -> ACT_BND~UP~2035 | J6: =J3&"~"&J2 -> ACT_BND~UP~2040 | K6: =K3&"~"&K2 -> ACT_BND~UP~2045 | L6: =L3&"~"&L2 -> ACT_BND~UP~2050 | ... V6: =V3&"~"&V2 -> ACT_BND~UP~2100 | Y6: TechName | Z6: Comm-IN | AA6: Comm-OUT | AB6: NCAP_START | AC6: NCAP_TLIFE | AD6: EFF | AE6: PRC_CAPACT | AF6: NCAP_AFA | AG6: NCAP_COST
B7: * | D7: k$/Mm2 | E7: Mm2 | F7: Mm2 | G7: Mm2 | H7: Mm2 | I7: Mm2 | J7: Mm2 | K7: Mm2 | L7: Mm2 | M7: Mm2 | N7: Mm2 | O7: Mm2 | P7: Mm2 | Q7: Mm2 | R7: Mm2 | S7: Mm2 | T7: Mm2 | U7: Mm2 | V7: Mm2 | Y7: * | AC7: Yr | AD7: Out/In | AE7: TJ/MW | AF7: % | AG7: $ /kW
B8: =Def_Tech!C5 -> RESAPALONewSHRETMIN | C8: =Def_Comm!C5 -> RESAPALONewSHRET | D8: 1 | E8: =_xlfn.XLOOKUP(LEFT($C8,LEN($C8)-5)&"DMD",Demand!$E:$E,Demand!G:G) -> 0 | F8: =_xlfn.XLOOKUP(LEFT($C8,LEN($C8)-5)&"DMD",Demand!$E:$E,Demand!H:H) -> 0.25903939 | G8: =_xlfn.XLOOKUP(LEFT($C8,LEN($C8)-5)&"DMD",Demand!$E:$E,Demand!I:I) -> 1.5542363 | H8: =_xlfn.XLOOKUP(LEFT($C8,LEN($C8)-5)&"DMD",Demand!$E:$E,Demand!J:J) -> 2.8494333 | I8: =_xlfn.XLOOKUP(LEFT($C8,LEN($C8)-5)&"DMD",Demand!$E:$E,Demand!K:K) -> 4.1446302 | J8: =_xlfn.XLOOKUP(LEFT($C8,LEN($C8)-5)&"DMD",Demand!$E:$E,Demand!L:L) -> 5.4398271 | K8: =_xlfn.XLOOKUP(LEFT($C8,LEN($C8)-5)&"DMD",Demand!$E:$E,Demand!M:M) -> 6.7350241 | L8: =_xlfn.XLOOKUP(LEFT($C8,LEN($C8)-5)&"DMD",Demand!$E:$E,Demand!N:N) -> 8.030221 | M8: =_xlfn.XLOOKUP(LEFT($C8,LEN($C8)-5)&"DMD",Demand!$E:$E,Demand!O:O) -> 9.3254179 | N8: =_xlfn.XLOOKUP(LEFT($C8,LEN($C8)-5)&"DMD",Demand!$E:$E,Demand!P:P) -> 10.620615 | O8: =_xlfn.XLOOKUP(LEFT($C8,LEN($C8)-5)&"DMD",Demand!$E:$E,Demand!Q:Q) -> 11.915812 | P8: =_xlfn.XLOOKUP(LEFT($C8,LEN($C8)-5)&"DMD",Demand!$E:$E,Demand!R:R) -> 13.211009 | Q8: =_xlfn.XLOOKUP(LEFT($C8,LEN($C8)-5)&"DMD",Demand!$E:$E,Demand!S:S) -> 14.506206 | R8: =_xlfn.XLOOKUP(LEFT($C8,LEN($C8)-5)&"DMD",Demand!$E:$E,Demand!T:T) -> 15.801403 | S8: =_xlfn.XLOOKUP(LEFT($C8,LEN($C8)-5)&"DMD",Demand!$E:$E,Demand!U:U) -> 17.0966 | T8: =_xlfn.XLOOKUP(LEFT($C8,LEN($C8)-5)&"DMD",Demand!$E:$E,Demand!V:V) -> 18.391797 | U8: =_xlfn.XLOOKUP(LEFT($C8,LEN($C8)-5)&"DMD",Demand!$E:$E,Demand!W:W) -> 19.686993 | V8: =_xlfn.XLOOKUP(LEFT($C8,LEN($C8)-5)&"DMD",Demand!$E:$E,Demand!X:X) -> 20.98219 | Y8: =IF('RET TECH'!N3=1,'RET TECH'!M3,"*") -> RESAPALONewSHENVESTAR20 | Z8: =IF(Y8="","",_xlfn.XLOOKUP(Y8,'RET TECH'!M:M,'RET TECH'!K:K)) -> RESAPALONewSHRET | AA8: =IF(Y8="","",_xlfn.XLOOKUP(Y8,'RET TECH'!M:M,'RET TECH'!L:L)) -> RESAPALONewSHEUE | AB8: =IF(Y8="","",'City characteristics'!$C$20+1) -> 2020 | AC8: =IF(Y8="","",_xlfn.XLOOKUP(Y8,'RET TECH'!M:M,'RET TECH'!T:T)) -> 30 | AD8: =IF(Y8="","",_xlfn.XLOOKUP(Y8,'RET TECH'!M:M,'RET TECH'!S:S)) -> 34.930492 | AE8: =IF(Y8="","",_xlfn.XLOOKUP(Y8,'RET TECH'!M:M,'RET TECH'!V:V)) -> 31.536 | AF8: =IF(Y8="","",_xlfn.XLOOKUP(Y8,'RET TECH'!M:M,'RET TECH'!U:U)) -> 0.098628147 | AG8: =IF(Y8="","",_xlfn.XLOOKUP(Y8,'RET TECH'!M:M,'RET TECH'!R:R)) -> 27562.279
B9: =Def_Tech!C6 -> RESAPALONewSCRETMIN | C9: =Def_Comm!C6 -> RESAPALONewSCRET | D9: 1 | E9: =_xlfn.XLOOKUP(LEFT($C9,LEN($C9)-5)&"DMD",Demand!$E:$E,Demand!G:G) -> 0 | F9: =_xlfn.XLOOKUP(LEFT($C9,LEN($C9)-5)&"DMD",Demand!$E:$E,Demand!H:H) -> 0.25903939 | G9: =_xlfn.XLOOKUP(LEFT($C9,LEN($C9)-5)&"DMD",Demand!$E:$E,Demand!I:I) -> 1.5542363 | H9: =_xlfn.XLOOKUP(LEFT($C9,LEN($C9)-5)&"DMD",Demand!$E:$E,Demand!J:J) -> 2.8494333 | I9: =_xlfn.XLOOKUP(LEFT($C9,LEN($C9)-5)&"DMD",Demand!$E:$E,Demand!K:K) -> 4.1446302 | J9: =_xlfn.XLOOKUP(LEFT($C9,LEN($C9)-5)&"DMD",Demand!$E:$E,Demand!L:L) -> 5.4398271 | K9: =_xlfn.XLOOKUP(LEFT($C9,LEN($C9)-5)&"DMD",Demand!$E:$E,Demand!M:M) -> 6.7350241 | L9: =_xlfn.XLOOKUP(LEFT($C9,LEN($C9)-5)&"DMD",Demand!$E:$E,Demand!N:N) -> 8.030221 | M9: =_xlfn.XLOOKUP(LEFT($C9,LEN($C9)-5)&"DMD",Demand!$E:$E,Demand!O:O) -> 9.3254179 | N9: =_xlfn.XLOOKUP(LEFT($C9,LEN($C9)-5)&"DMD",Demand!$E:$E,Demand!P:P) -> 10.620615 | O9: =_xlfn.XLOOKUP(LEFT($C9,LEN($C9)-5)&"DMD",Demand!$E:$E,Demand!Q:Q) -> 11.915812 | P9: =_xlfn.XLOOKUP(LEFT($C9,LEN($C9)-5)&"DMD",Demand!$E:$E,Demand!R:R) -> 13.211009 | Q9: =_xlfn.XLOOKUP(LEFT($C9,LEN($C9)-5)&"DMD",Demand!$E:$E,Demand!S:S) -> 14.506206 | R9: =_xlfn.XLOOKUP(LEFT($C9,LEN($C9)-5)&"DMD",Demand!$E:$E,Demand!T:T) -> 15.801403 | S9: =_xlfn.XLOOKUP(LEFT($C9,LEN($C9)-5)&"DMD",Demand!$E:$E,Demand!U:U) -> 17.0966 | T9: =_xlfn.XLOOKUP(LEFT($C9,LEN($C9)-5)&"DMD",Demand!$E:$E,Demand!V:V) -> 18.391797 | U9: =_xlfn.XLOOKUP(LEFT($C9,LEN($C9)-5)&"DMD",Demand!$E:$E,Demand!W:W) -> 19.686993 | V9: =_xlfn.XLOOKUP(LEFT($C9,LEN($C9)-5)&"DMD",Demand!$E:$E,Demand!X:X) -> 20.98219 | Y9: =IF('RET TECH'!N4=1,'RET TECH'!M4,"*") -> RESAPALONewSHENVPATH20 | Z9: =IF(Y9="","",_xlfn.XLOOKUP(Y9,'RET TECH'!M:M,'RET TECH'!K:K)) -> RESAPALONewSHRET | AA9: =IF(Y9="","",_xlfn.XLOOKUP(Y9,'RET TECH'!M:M,'RET TECH'!L:L)) -> RESAPALONewSHEUE | AB9: =IF(Y9="","",'City characteristics'!$C$20+1) -> 2020 | AC9: =IF(Y9="","",_xlfn.XLOOKUP(Y9,'RET TECH'!M:M,'RET TECH'!T:T)) -> 30 | AD9: =IF(Y9="","",_xlfn.XLOOKUP(Y9,'RET TECH'!M:M,'RET TECH'!S:S)) -> 125.4074 | AE9: =IF(Y9="","",_xlfn.XLOOKUP(Y9,'RET TECH'!M:M,'RET TECH'!V:V)) -> 31.536 | AF9: =IF(Y9="","",_xlfn.XLOOKUP(Y9,'RET TECH'!M:M,'RET TECH'!U:U)) -> 0.098628147 | AG9: =IF(Y9="","",_xlfn.XLOOKUP(Y9,'RET TECH'!M:M,'RET TECH'!R:R)) -> 12748.214
B10: =Def_Tech!C7 -> RESHOULONewSHRETMIN | C10: =Def_Comm!C7 -> RESHOULONewSHRET | D10: 1 | E10: =_xlfn.XLOOKUP(LEFT($C10,LEN($C10)-5)&"DMD",Demand!$E:$E,Demand!G:G) -> 0 | F10: =_xlfn.XLOOKUP(LEFT($C10,LEN($C10)-5)&"DMD",Demand!$E:$E,Demand!H:H) -> 0.07478399 | G10: =_xlfn.XLOOKUP(LEFT($C10,LEN($C10)-5)&"DMD",Demand!$E:$E,Demand!I:I) -> 0.44870394 | H10: =_xlfn.XLOOKUP(LEFT($C10,LEN($C10)-5)&"DMD",Demand!$E:$E,Demand!J:J) -> 0.82262389 | I10: =_xlfn.XLOOKUP(LEFT($C10,LEN($C10)-5)&"DMD",Demand!$E:$E,Demand!K:K) -> 1.1965438 | J10: =_xlfn.XLOOKUP(LEFT($C10,LEN($C10)-5)&"DMD",Demand!$E:$E,Demand!L:L) -> 1.5704638 | K10: =_xlfn.XLOOKUP(LEFT($C10,LEN($C10)-5)&"DMD",Demand!$E:$E,Demand!M:M) -> 1.9443837 | L10: =_xlfn.XLOOKUP(LEFT($C10,LEN($C10)-5)&"DMD",Demand!$E:$E,Demand!N:N) -> 2.3183037 | M10: =_xlfn.XLOOKUP(LEFT($C10,LEN($C10)-5)&"DMD",Demand!$E:$E,Demand!O:O) -> 2.6922236 | N10: =_xlfn.XLOOKUP(LEFT($C10,LEN($C10)-5)&"DMD",Demand!$E:$E,Demand!P:P) -> 3.0661436 | O10: =_xlfn.XLOOKUP(LEFT($C10,LEN($C10)-5)&"DMD",Demand!$E:$E,Demand!Q:Q) -> 3.4400635 | P10: =_xlfn.XLOOKUP(LEFT($C10,LEN($C10)-5)&"DMD",Demand!$E:$E,Demand!R:R) -> 3.8139835 | Q10: =_xlfn.XLOOKUP(LEFT($C10,LEN($C10)-5)&"DMD",Demand!$E:$E,Demand!S:S) -> 4.1879034 | R10: =_xlfn.XLOOKUP(LEFT($C10,LEN($C10)-5)&"DMD",Demand!$E:$E,Demand!T:T) -> 4.5618234 | S10: =_xlfn.XLOOKUP(LEFT($C10,LEN($C10)-5)&"DMD",Demand!$E:$E,Demand!U:U) -> 4.9357433 | T10: =_xlfn.XLOOKUP(LEFT($C10,LEN($C10)-5)&"DMD",Demand!$E:$E,Demand!V:V) -> 5.3096633 | U10: =_xlfn.XLOOKUP(LEFT($C10,LEN($C10)-5)&"DMD",Demand!$E:$E,Demand!W:W) -> 5.6835832 | V10: =_xlfn.XLOOKUP(LEFT($C10,LEN($C10)-5)&"DMD",Demand!$E:$E,Demand!X:X) -> 6.0575032 | Y10: =IF('RET TECH'!N5=1,'RET TECH'!M5,"*") -> RESAPALONewSHENVIECC4020 | Z10: =IF(Y10="","",_xlfn.XLOOKUP(Y10,'RET TECH'!M:M,'RET TECH'!K:K)) -> RESAPALONewSHRET | AA10: =IF(Y10="","",_xlfn.XLOOKUP(Y10,'RET TECH'!M:M,'RET TECH'!L:L)) -> RESAPALONewSHEUE | AB10: =IF(Y10="","",'City characteristics'!$C$20+1) -> 2020 | AC10: =IF(Y10="","",_xlfn.XLOOKUP(Y10,'RET TECH'!M:M,'RET TECH'!T:T)) -> 30 | AD10: =IF(Y10="","",_xlfn.XLOOKUP(Y10,'RET TECH'!M:M,'RET TECH'!S:S)) -> 50.43284 | AE10: =IF(Y10="","",_xlfn.XLOOKUP(Y10,'RET TECH'!M:M,'RET TECH'!V:V)) -> 31.536 | AF10: =IF(Y10="","",_xlfn.XLOOKUP(Y10,'RET TECH'!M:M,'RET TECH'!U:U)) -> 0.098628147 | AG10: =IF(Y10="","",_xlfn.XLOOKUP(Y10,'RET TECH'!M:M,'RET TECH'!R:R)) -> 25967.818
B11: =Def_Tech!C8 -> RESHOULONewSCRETMIN | C11: =Def_Comm!C8 -> RESHOULONewSCRET | D11: 1 | E11: =_xlfn.XLOOKUP(LEFT($C11,LEN($C11)-5)&"DMD",Demand!$E:$E,Demand!G:G) -> 0 | F11: =_xlfn.XLOOKUP(LEFT($C11,LEN($C11)-5)&"DMD",Demand!$E:$E,Demand!H:H) -> 0.07478399 | G11: =_xlfn.XLOOKUP(LEFT($C11,LEN($C11)-5)&"DMD",Demand!$E:$E,Demand!I:I) -> 0.44870394 | H11: =_xlfn.XLOOKUP(LEFT($C11,LEN($C11)-5)&"DMD",Demand!$E:$E,Demand!J:J) -> 0.82262389 | I11: =_xlfn.XLOOKUP(LEFT($C11,LEN($C11)-5)&"DMD",Demand!$E:$E,Demand!K:K) -> 1.1965438 | J11: =_xlfn.XLOOKUP(LEFT($C11,LEN($C11)-5)&"DMD",Demand!$E:$E,Demand!L:L) -> 1.5704638 | K11: =_xlfn.XLOOKUP(LEFT($C11,LEN($C11)-5)&"DMD",Demand!$E:$E,Demand!M:M) -> 1.9443837 | L11: =_xlfn.XLOOKUP(LEFT($C11,LEN($C11)-5)&"DMD",Demand!$E:$E,Demand!N:N) -> 2.3183037 | M11: =_xlfn.XLOOKUP(LEFT($C11,LEN($C11)-5)&"DMD",Demand!$E:$E,Demand!O:O) -> 2.6922236 | N11: =_xlfn.XLOOKUP(LEFT($C11,LEN($C11)-5)&"DMD",Demand!$E:$E,Demand!P:P) -> 3.0661436 | O11: =_xlfn.XLOOKUP(LEFT($C11,LEN($C11)-5)&"DMD",Demand!$E:$E,Demand!Q:Q) -> 3.4400635 | P11: =_xlfn.XLOOKUP(LEFT($C11,LEN($C11)-5)&"DMD",Demand!$E:$E,Demand!R:R) -> 3.8139835 | Q11: =_xlfn.XLOOKUP(LEFT($C11,LEN($C11)-5)&"DMD",Demand!$E:$E,Demand!S:S) -> 4.1879034 | R11: =_xlfn.XLOOKUP(LEFT($C11,LEN($C11)-5)&"DMD",Demand!$E:$E,Demand!T:T) -> 4.5618234 | S11: =_xlfn.XLOOKUP(LEFT($C11,LEN($C11)-5)&"DMD",Demand!$E:$E,Demand!U:U) -> 4.9357433 | T11: =_xlfn.XLOOKUP(LEFT($C11,LEN($C11)-5)&"DMD",Demand!$E:$E,Demand!V:V) -> 5.3096633 | U11: =_xlfn.XLOOKUP(LEFT($C11,LEN($C11)-5)&"DMD",Demand!$E:$E,Demand!W:W) -> 5.6835832 | V11: =_xlfn.XLOOKUP(LEFT($C11,LEN($C11)-5)&"DMD",Demand!$E:$E,Demand!X:X) -> 6.0575032 | Y11: =IF('RET TECH'!N6=1,'RET TECH'!M6,"*") -> RESAPALONewSHENVIECC20 | Z11: =IF(Y11="","",_xlfn.XLOOKUP(Y11,'RET TECH'!M:M,'RET TECH'!K:K)) -> RESAPALONewSHRET | AA11: =IF(Y11="","",_xlfn.XLOOKUP(Y11,'RET TECH'!M:M,'RET TECH'!L:L)) -> RESAPALONewSHEUE | AB11: =IF(Y11="","",'City characteristics'!$C$20+1) -> 2020 | AC11: =IF(Y11="","",_xlfn.XLOOKUP(Y11,'RET TECH'!M:M,'RET TECH'!T:T)) -> 30 | AD11: =IF(Y11="","",_xlfn.XLOOKUP(Y11,'RET TECH'!M:M,'RET TECH'!S:S)) -> 31.338778 | AE11: =IF(Y11="","",_xlfn.XLOOKUP(Y11,'RET TECH'!M:M,'RET TECH'!V:V)) -> 31.536 | AF11: =IF(Y11="","",_xlfn.XLOOKUP(Y11,'RET TECH'!M:M,'RET TECH'!U:U)) -> 0.098628147 | AG11: =IF(Y11="","",_xlfn.XLOOKUP(Y11,'RET TECH'!M:M,'RET TECH'!R:R)) -> 27268.707
B12: =Def_Tech!C9 -> RESAPALMNewSHRETMIN | C12: =Def_Comm!C9 -> RESAPALMNewSHRET | D12: 1 | E12: =_xlfn.XLOOKUP(LEFT($C12,LEN($C12)-5)&"DMD",Demand!$E:$E,Demand!G:G) -> 0 | F12: =_xlfn.XLOOKUP(LEFT($C12,LEN($C12)-5)&"DMD",Demand!$E:$E,Demand!H:H) -> 0.28560988 | G12: =_xlfn.XLOOKUP(LEFT($C12,LEN($C12)-5)&"DMD",Demand!$E:$E,Demand!I:I) -> 1.7136593 | H12: =_xlfn.XLOOKUP(LEFT($C12,LEN($C12)-5)&"DMD",Demand!$E:$E,Demand!J:J) -> 3.1417087 | I12: =_xlfn.XLOOKUP(LEFT($C12,LEN($C12)-5)&"DMD",Demand!$E:$E,Demand!K:K) -> 4.5697581 | J12: =_xlfn.XLOOKUP(LEFT($C12,LEN($C12)-5)&"DMD",Demand!$E:$E,Demand!L:L) -> 5.9978075 | K12: =_xlfn.XLOOKUP(LEFT($C12,LEN($C12)-5)&"DMD",Demand!$E:$E,Demand!M:M) -> 7.4258569 | L12: =_xlfn.XLOOKUP(LEFT($C12,LEN($C12)-5)&"DMD",Demand!$E:$E,Demand!N:N) -> 8.8539063 | M12: =_xlfn.XLOOKUP(LEFT($C12,LEN($C12)-5)&"DMD",Demand!$E:$E,Demand!O:O) -> 10.281956 | N12: =_xlfn.XLOOKUP(LEFT($C12,LEN($C12)-5)&"DMD",Demand!$E:$E,Demand!P:P) -> 11.710005 | O12: =_xlfn.XLOOKUP(LEFT($C12,LEN($C12)-5)&"DMD",Demand!$E:$E,Demand!Q:Q) -> 13.138055 | P12: =_xlfn.XLOOKUP(LEFT($C12,LEN($C12)-5)&"DMD",Demand!$E:$E,Demand!R:R) -> 14.566104 | Q12: =_xlfn.XLOOKUP(LEFT($C12,LEN($C12)-5)&"DMD",Demand!$E:$E,Demand!S:S) -> 15.994153 | R12: =_xlfn.XLOOKUP(LEFT($C12,LEN($C12)-5)&"DMD",Demand!$E:$E,Demand!T:T) -> 17.422203 | S12: =_xlfn.XLOOKUP(LEFT($C12,LEN($C12)-5)&"DMD",Demand!$E:$E,Demand!U:U) -> 18.850252 | T12: =_xlfn.XLOOKUP(LEFT($C12,LEN($C12)-5)&"DMD",Demand!$E:$E,Demand!V:V) -> 20.278302 | U12: =_xlfn.XLOOKUP(LEFT($C12,LEN($C12)-5)&"DMD",Demand!$E:$E,Demand!W:W) -> 21.706351 | V12: =_xlfn.XLOOKUP(LEFT($C12,LEN($C12)-5)&"DMD",Demand!$E:$E,Demand!X:X) -> 23.1344 | Y12: =IF('RET TECH'!N7=1,'RET TECH'!M7,"*") -> * | Z12: =IF(Y12="","",_xlfn.XLOOKUP(Y12,'RET TECH'!M:M,'RET TECH'!K:K)) -> 0 | AA12: =IF(Y12="","",_xlfn.XLOOKUP(Y12,'RET TECH'!M:M,'RET TECH'!L:L)) -> 0 | AB12: =IF(Y12="","",'City characteristics'!$C$20+1) -> 2020 | AC12: =IF(Y12="","",_xlfn.XLOOKUP(Y12,'RET TECH'!M:M,'RET TECH'!T:T)) -> 0 | AD12: =IF(Y12="","",_xlfn.XLOOKUP(Y12,'RET TECH'!M:M,'RET TECH'!S:S)) -> 0 | AE12: =IF(Y12="","",_xlfn.XLOOKUP(Y12,'RET TECH'!M:M,'RET TECH'!V:V)) -> 0 | AF12: =IF(Y12="","",_xlfn.XLOOKUP(Y12,'RET TECH'!M:M,'RET TECH'!U:U)) -> 0 | AG12: =IF(Y12="","",_xlfn.XLOOKUP(Y12,'RET TECH'!M:M,'RET TECH'!R:R)) -> 0
