Workbook

Sheet ReadMe
A1: Generic Comet (GC) TIMES Supply
B3: Sheet color
C4: Raw Data and Parameters
C6: City Specific Data
C8: Post processing for TIMES
C10: Table formatted for TIMES

Sheet >> City Data

Sheet City characteristics
B2: City Basic Data
B4: Calibration methodology | C4: GHG Inventory
B6: A. City Characteristics
B7: Data Item | C7: Value | D7: Units
B8: City Name | C8: New York
B9: Latitude | C9: 40.5
B10: Longitude | C10: -75
B11: County | C11: New York County
B12: State | C12: New York
B13: Census Division | C13: Middle Atlantic
B14: Climate Division | C14: Northeast
B15: Egrid Region | C15: NPCC NYC/Westchester
B16: Area of city (excluding water, natural and agricultural areas) | C16: 778 | D16: square kilometers
B17: * Division and Region Map can be found in the Maps sheet.
B18: B. Planning Base Year and Target Years
B19: Year | C19: Value | D19: Units
B20: Base Year | C20: 2019 | D20: Acceptable range [2018,2021]
B21: End Year | C21: 2050
B23: C. City Population and GDP
B24: Data Item | C24: Value | D24: Units
B25: Population in Base Year | C25: 8337 | D25: Thousand of people
B26: Annual population growth (Base Year - End Year) | C26: 0.5 | D26: % people
B27: GDP in Base Year | C27: 1206000 | D27: Million US$
B28: Annual GDP growth rate | C28: 2 | D28: % US$
B29: Share of manufacturing GDP | C29: 5 | D29: % US$
B30: Share of State population | C30: 0.42835123
B31: Share of State GDP | C31: 0.67251772
B32: Adjustment from state manufacturing GDP | C32: 1.0638298
B34: D. Climate Data
B35: Data Item | C35: 2000 | D35: 2050 | E35: 2100 | F35: Units
B36: Heating degree days (HDD) | C36: 4473.4625 | D36: 4066.4182 | E36: 3763.8582 | F36: F
B37: Cooling degree days (CDD) | C37: 1020.7333 | D37: 1224.2555 | E37: 1375.5355 | F37: F
B39: Data Item | C39: Value | D39: Units
B40: Correction from State HDD | C40: 0.72727402
B41: Correction from State CDD | C41: 1.5583715
B42: Annual precipitation | C42: 762 | D42: mm / year
B43: Climate change scenario | C43: RCP4.5
B44: Average temperature increase in 1980-2020 | C44: 1.4617857 | D44: F
B45: Forecasted average temperature increase in 2035-2065 | C45: 3.13 | D45: F
B46: Forecasted average temperature increase in 2070-2100 | C46: 4.37 | D46: F
...

Sheet >> GC_NewTech

Sheet WAS TECH
A1: Sector | B1: Sub-sector | C1: Archetype | D1: Vintage | E1: End Use | F1: Technology | G1: Energy | H1: Input Label | I1: Output Label | J1: Demand Label | K1: Technology Label | L1: Start Year | M1: Included | N1: CAPEX (2023 USD/ t) | O1: CFA | P1: C2A | Q1: Energy flow (TJ/ktonnes) | R1: CH4 (tonnes/ktonnes) | S1: CO2 (tonnes/ktonnes) | T1: N2O (tonnes/ktonnes)
A2: Waste | B2: Solid | C2: Paper | E2: Compost | F2: IN | G2: Electricity | H2: WASELC | J2: WASSOLPAPDMDTOT | K2: WASSOLPAPCMP20 | L2: 2020 | M2: 1 | N2: 56.952605 | O2: 0.9 | P2: 1 | Q2: 0.0037198608 | R2: 0.59045559 | S2: 0 | T2: 0.011231423
A3: Waste | B3: Solid | C3: Paper | E3: Compost | F3: IN | G3: Diesel | H3: WASDSL | J3: WASSOLPAPDMDTOT | K3: WASSOLPAPCMP20 | L3: 2020 | M3: 1 | N3: 56.952605 | O3: 0.9 | P3: 1 | Q3: 0.0050435779 | R3: 0.59045559 | S3: 0 | T3: 0.011231423
A4: Waste | B4: Solid | C4: Glass | E4: Compost | F4: IN | G4: Electricity | H4: WASELC | J4: WASSOLGLADMDTOT | K4: WASSOLGLACMP20 | L4: 2020 | M4: 0 | N4: 56.952605 | O4: 0.9 | P4: 1 | Q4: 0.0032929234 | R4: 0 | S4: 0 | T4: 0
A5: Waste | B5: Solid | C5: Glass | E5: Compost | F5: IN | G5: Diesel | H5: WASDSL | J5: WASSOLGLADMDTOT | K5: WASSOLGLACMP20 | L5: 2020 | M5: 0 | N5: 56.952605 | O5: 0.9 | P5: 1 | Q5: 0.0038630599 | R5: 0 | S5: 0 | T5: 0
A6: Waste | B6: Solid | C6: Metals | E6: Compost | F6: IN | G6: Electricity | H6: WASELC | J6: WASSOLMETDMDTOT | K6: WASSOLMETCMP20 | L6: 2020 | M6: 0 | N6: 56.952605 | O6: 0.9 | P6: 1 | Q6: 0.0032855945 | R6: 0 | S6: 0 | T6: 0.0076625933
A7: Waste | B7: Solid | C7: Metals | E7: Compost | F7: IN | G7: Diesel | H7: WASDSL | J7: WASSOLMETDMDTOT | K7: WASSOLMETCMP20 | L7: 2020 | M7: 0 | N7: 56.952605 | O7: 0.9 | P7: 1 | Q7: 0.0038606586 | R7: 0 | S7: 0 | T7: 0.0076625933
A8: Waste | B8: Solid | C8: Plastics | E8: Compost | F8: IN | G8: Electricity | H8: WASELC | J8: WASSOLPLADMDTOT | K8: WASSOLPLACMP20 | L8: 2020 | M8: 0 | N8: 56.952605 | O8: 0.9 | P8: 1 | Q8: 0.0032574407 | R8: 0 | S8: 0 | T8: 0.048992718
A9: Waste | B9: Solid | C9: Plastics | E9: Compost | F9: IN | G9: Diesel | H9: WASDSL | J9: WASSOLPLADMDTOT | K9: WASSOLPLACMP20 | L9: 2020 | M9: 0 | N9: 56.952605 | O9: 0.9 | P9: 1 | Q9: 0.0041616592 | R9: 0 | S9: 0 | T9: 0.048992718
A10: Waste | B10: Solid | C10: Food | E10: Compost | F10: IN | G10: Electricity | H10: WASELC | J10: WASSOLFOODMDTOT | K10: WASSOLFOOCMP20 | L10: 2020 | M10: 1 | N10: 56.952605 | O10: 0.9 | P10: 1 | Q10: 0.0048784913 | R10: 1.9885477 | S10: 0 | T10: 0.22987519
A11: Waste | B11: Solid | C11: Food | E11: Compost | F11: IN | G11: Diesel | H11: WASDSL | J11: WASSOLFOODMDTOT | K11: WASSOLFOOCMP20 | L11: 2020 | M11: 1 | N11: 56.952605 | O11: 0.9 | P11: 1 | Q11: 0.0065600031 | R11: 1.9885477 | S11: 0 | T11: 0.22987519
A12: Waste | B12: Solid | C12: Yard trimmings | E12: Compost | F12: IN | G12: Electricity | H12: WASELC | J12: WASSOLYARDMDTOT | K12: WASSOLYARCMP20 | L12: 2020 | M12: 1 | N12: 56.952605 | O12: 0.9 | P12: 1 | Q12: 0.0044521368 | R12: 1.969548 | S12: 0 | T12: 0.2558003
A13: Waste | B13: Solid | C13: Yard trimmings | E13: Compost | F13: IN | G13: Diesel | H13: WASDSL | J13: WASSOLYARDMDTOT | K13: WASSOLYARCMP20 | L13: 2020 | M13: 1 | N13: 56.952605 | O13: 0.9 | P13: 1 | Q13: 0.0088196441 | R13: 1.969548 | S13: 0 | T13: 0.2558003
... A17: Waste | B17: Solid | C17: Paper | E17: Anaerobic Digestion | F17: IN | G17: Diesel | H17: WASDSL | J17: WASSOLPAPDMDTOT | K17: WASSOLPAPADG20 | L17: 2020 | M17: 1 | N17: 766.13352 | O17: 0.9 | P17: 1 | Q17: 0.020209815 | R17: 4.0822852 | S17: 0 | T17: 0.048656387
A18: Waste | B18: Solid | C18: Paper | E18: Anaerobic Digestion | F18: OUT | G18: Biogas | I18: WASSOLADGBGA | J18: WASSOLPAPDMDTOT | K18: WASSOLPAPADG20 | L18: 2020 | M18: 1 | N18: 766.13352 | O18: 0.9 | P18: 1 | Q18: 2.5551929 | R18: 4.0822852 | S18: 0 | T18: 0.048656387
A19: Waste | B19: Solid | C19: Glass | E19: Anaerobic Digestion | F19: IN | G19: Electricity | H19: WASELC | J19: WASSOLGLADMDTOT | K19: WASSOLGLAADG20 | L19: 2020 | M19: 0 | N19: 766.13352 | O19: 0.9 | P19: 1 | Q19: 0.22186353 | R19: 0 | S19: 0 | T19: 0
A20: Waste | B20: Solid | C20: Glass | E20: Anaerobic Digestion | F20: IN | G20: Diesel | H20: WASDSL | J20: WASSOLGLADMDTOT | K20: WASSOLGLAADG20 | L20: 2020 | M20: 0 | N20: 766.13352 | O20: 0.9 | P20: 1 | Q20: 0.0025027737 | R20: 0 | S20: 0 | T20: 0
A21: Waste | B21: Solid | C21: Glass | E21: Anaerobic Digestion | F21: OUT | G21: Biogas | I21: WASSOLADGBGA | J21: WASSOLGLADMDTOT | K21: WASSOLGLAADG20 | L21: 2020 | M21: 0 | N21: 766.13352 | O21: 0.9 | P21: 1 | Q21: 0 | R21: 0 | S21: 0 | T21: 0
A22: Waste | B22: Solid | C22: Metals | E22: Anaerobic Digestion | F22: IN | G22: Electricity | H22: WASELC | J22: WASSOLMETDMDTOT | K22: WASSOLMETADG20 | L22: 2020 | M22: 0 | N22: 766.13352 | O22: 0.9 | P22: 1 | Q22: 0.22087012 | R22: 0 | S22: 0 | T22: 0
A23: Waste | B23: Solid | C23: Metals | E23: Anaerobic Digestion | F23: IN | G23: Diesel | H23: WASDSL | J23: WASSOLMETDMDTOT | K23: WASSOLMETADG20 | L23: 2020 | M23: 0 | N23: 766.13352 | O23: 0.9 | P23: 1 | Q23: 0.0023948008 | R23: 0 | S23: 0 | T23: 0
A24: Waste | B24: Solid | C24: Metals | E24: Anaerobic Digestion | F24: OUT | G24: Biogas | I24: WASSOLADGBGA | J24: WASSOLMETDMDTOT | K24: WASSOLMETADG20 | L24: 2020 | M24: 0 | N24: 766.13352 | O24: 0.9 | P24: 1 | Q24: 0 | R24: 0 | S24: 0 | T24: 0
A25: Waste | B25: Solid | C25: Plastics | E25: Anaerobic Digestion | F25: IN | G25: Electricity | H25: WASELC | J25: WASSOLPLADMDTOT | K25: WASSOLPLAADG20 | L25: 2020 | M25: 0 | N25: 766.13352 | O25: 0.9 | P25: 1 | Q25: 0.22185413 | R25: 0 | S25: 0 | T25: 0
A26: Waste | B26: Solid | C26: Plastics | E26: Anaerobic Digestion | F26: IN | G26: Diesel | H26: WASDSL | J26: WASSOLPLADMDTOT | K26: WASSOLPLAADG20 | L26: 2020 | M26: 0 | N26: 766.13352 | O26: 0.9 | P26: 1 | Q26: 0.0025017494 | R26: 0 | S26: 0 | T26: 0
A27: Waste | B27: Solid | C27: Plastics | E27: Anaerobic Digestion | F27: OUT | G27: Biogas | I27: WASSOLADGBGA | J27: WASSOLPLADMDTOT | K27: WASSOLPLAADG20 | L27: 2020 | M27: 0 | N27: 766.13352 | O27: 0.9 | P27: 1 | Q27: 0 | R27: 0 | S27: 0 | T27: 0
A28: Waste | B28: Solid | C28: Food | E28: Anaerobic Digestion | F28: IN | G28: Electricity | H28: WASELC | J28: WASSOLFOODMDTOT | K28: WASSOLFOOADG20 | L28: 2020 | M28: 1 | N28: 766.13352 | O28: 0.9 | P28: 1 | Q28: 0.24057902 | R28: 3.9766619 | S28: 0 | T28: 0.53538242
A29: Waste | B29: Solid | C29: Food | E29: Anaerobic Digestion | F29: IN | G29: Diesel | H29: WASDSL | J29: WASSOLFOODMDTOT | K29: WASSOLFOOADG20 | L29: 2020 | M29: 1 | N29: 766.13352 | O29: 0.9 | P29: 1 | Q29: 0.0041551694 | R29: 3.9766619 | S29: 0 | T29: 0.53538242
A30: Waste | B30: Solid | C30: Food | E30: Anaerobic Digestion | F30: OUT | G30: Biogas | I30: WASSOLADGBGA | J30: WASSOLFOODMDTOT | K30: WASSOLFOOADG20 | L30: 2020 | M30: 1 | N30: 766.13352 | O30: 0.9 | P30: 1 | Q30: 4.2239471 | R30: 3.9766619 | S30: 0 | T30: 0.53538242
A31: Waste | B31: Solid | C31: Yard trimmings | E31: Anaerobic Digestion | F31: IN | G31: Electricity | H31: WASELC | J31: WASSOLYARDMDTOT | K31: WASSOLYARADG20 | L31: 2020 | M31: 1 | N31: 766.13352 | O31: 0.9 | P31: 1 | Q31: 0.3146294 | R31: 3.1453229 | S31: 0 | T31: 0.23841367
A32: Waste | B32: Solid | C32: Yard trimmings | E32: Anaerobic Digestion | F32: IN | G32: Diesel | H32: WASDSL | J32: WASSOLYARDMDTOT | K32: WASSOLYARADG20 | L32: 2020 | M32: 1 | N32: 766.13352 | O32: 0.9 | P32: 1 | Q32: 0.011869074 | R32: 3.1453229 | S32: 0 | T32: 0.23841367
A33: Waste | B33: Solid | C33: Yard trimmings | E33: Anaerobic Digestion | F33: OUT | G33: Biogas | I33: WASSOLADGBGA | J33: WASSOLYARDMDTOT | K33: WASSOLYARADG20 | L33: 2020 | M33: 1 | N33: 766.13352 | O33: 0.9 | P33: 1 | Q33: 1.2089642 | R33: 3.1453229 | S33: 0 | T33: 0.23841367
A34: Waste | B34: Solid | C34: All Other | E34: Anaerobic Digestion | F34: IN | G34: Electricity | H34: WASELC | J34: WASSOLAOTDMDTOT | K34: WASSOLAOTADG20 | L34: 2020 | M34: 1 | N34: 766.13352 | O34: 0.9 | P34: 1 | Q34: 0.30609766 | R34: 0.14920915 | S34: 0 | T34: 0.15032975
A35: Waste | B35: Solid | C35: All Other | E35: Anaerobic Digestion | F35: IN | G35: Diesel | H35: WASDSL | J35: WASSOLAOTDMDTOT | K35: WASSOLAOTADG20 | L35: 2020 | M35: 1 | N35: 766.13352 | O35: 0.9 | P35: 1 | Q35: 0.011309843 | R35: 0.14920915 | S35: 0 | T35: 0.15032975
A36: Waste | B36: Solid | C36: All Other | E36: Anaerobic Digestion | F36: OUT | G36: Biogas | I36: WASSOLADGBGA | J36: WASSOLAOTDMDTOT | K36: WASSOLAOTADG20 | L36: 2020 | M36: 1 | N36: 766.13352 | O36: 0.9 | P36: 1 | Q36: 0.19326305 | R36: 0.14920915 | S36: 0 | T36: 0.15032975
A37: Waste | B37: Solid | C37: Paper | E37: Incineration | F37: OUT | G37: Electricity | I37: CELC | J37: WASSOLPAPDMDTOT | K37: WASSOLPAPINC20 | L37: 2020 | M37: 1 | N37: 595.25188 | O37: 0.9 | P37: 1 | Q37: 2.70904 | R37: 0.011449374 | S37: 20.609799 | T37: 0.014901106
A38: Waste | B38: Solid | C38: Paper | E38: Incineration | F38: OUT | G38: Steam | I38: STM | J38: WASSOLPAPDMDTOT | K38: WASSOLPAPINC20 | L38: 2020 | M38: 1 | N38: 595.25188 | O38: 0.9 | P38: 1 | Q38: 5.41808 | R38: 0.011449374 | S38: 20.609799 | T38: 0.014901106
A39: Waste | B39: Solid | C39: Glass | E39: Incineration | F39: OUT | G39: Electricity | I39: CELC | J39: WASSOLGLADMDTOT | K39: WASSOLGLAINC20 | L39: 2020 | M39: 1 | N39: 595.25188 | O39: 0.9 | P39: 1 | Q39: 0 | R39: 0.011858224 | S39: 10.258114 | T39: 0.016227641
A40: Waste | B40: Solid | C40: Glass | E40: Incineration | F40: OUT | G40: Steam | I40: STM | J40: WASSOLGLADMDTOT | K40: WASSOLGLAINC20 | L40: 2020 | M40: 1 | N40: 595.25188 | O40: 0.9 | P40: 1 | Q40: 0 | R40: 0.011858224 | S40: 10.258114 | T40: 0.016227641
A41: Waste | B41: Solid | C41: Metals | E41: Incineration | F41: OUT | G41: Electricity | I41: CELC | J41: WASSOLMETDMDTOT | K41: WASSOLMETINC20 | L41: 2020 | M41: 1 | N41: 595.25188 | O41: 0.9 | P41: 1 | Q41: 0.25614365 | R41: 0.011480252 | S41: 12.099667 | T41: 0.015001292
A42: Waste | B42: Solid | C42: Metals | E42: Incineration | F42: OUT | G42: Steam | I42: STM | J42: WASSOLMETDMDTOT | K42: WASSOLMETINC20 | L42: 2020 | M42: 1 | N42: 595.25188 | O42: 0.9 | P42: 1 | Q42: 0.5122873 | R42: 0.011480252 | S42: 12.099667 | T42: 0.015001292
A43: Waste | B43: Solid | C43: Plastics | E43: Incineration | F43: OUT | G43: Electricity | I43: CELC | J43: WASSOLPLADMDTOT | K43: WASSOLPLAINC20 | L43: 2020 | M43: 1 | N43: 595.25188 | O43: 0.9 | P43: 1 | Q43: 7.6697525 | R43: 0.011854638 | S43: 2402.8615 | T43: 0.016216007
...

Sheet >> TIMES

Sheet Tech_availability
B2: ~TFM_AVA
B3: PSET_SET | C3: PSET_PN | D3: PSET_PD | E3: PSET_CO | F3: PSET_CI | G3: CITY | H3: EGRID
B4: *
C5: {=_xlfn.UNIQUE('WAS TECH'!K2:K93)} -> WASSOLPAPCMP20 | G5: =_xlfn.XLOOKUP(C5,'WAS TECH'!K:K,'WAS TECH'!M:M) -> 1 | H5: 0
C6: WASSOLGLACMP20 | G6: =_xlfn.XLOOKUP(C6,'WAS TECH'!K:K,'WAS TECH'!M:M) -> 0 | H6: 0
C7: WASSOLMETCMP20 | G7: =_xlfn.XLOOKUP(C7,'WAS TECH'!K:K,'WAS TECH'!M:M) -> 0 | H7: 0
C8: WASSOLPLACMP20 | G8: =_xlfn.XLOOKUP(C8,'WAS TECH'!K:K,'WAS TECH'!M:M) -> 0 | H8: 0
C9: WASSOLFOOCMP20 | G9: =_xlfn.XLOOKUP(C9,'WAS TECH'!K:K,'WAS TECH'!M:M) -> 1 | H9: 0
C10: WASSOLYARCMP20 | G10: =_xlfn.XLOOKUP(C10,'WAS TECH'!K:K,'WAS TECH'!M:M) -> 1 | H10: 0
C11: WASSOLAOTCMP20 | G11: =_xlfn.XLOOKUP(C11,'WAS TECH'!K:K,'WAS TECH'!M:M) -> 0 | H11: 0
C12: WASSOLPAPADG20 | G12: =_xlfn.XLOOKUP(C12,'WAS TECH'!K:K,'WAS TECH'!M:M) -> 1 | H12: 0
C13: WASSOLGLAADG20 | G13: =_xlfn.XLOOKUP(C13,'WAS TECH'!K:K,'WAS TECH'!M:M) -> 0 | H13: 0
C14: WASSOLMETADG20 | G14: =_xlfn.XLOOKUP(C14,'WAS TECH'!K:K,'WAS TECH'!M:M) -> 0 | H14: 0
C15: WASSOLPLAADG20 | G15: =_xlfn.XLOOKUP(C15,'WAS TECH'!K:K,'WAS TECH'!M:M) -> 0 | H15: 0
C16: WASSOLFOOADG20 | G16: =_xlfn.XLOOKUP(C16,'WAS TECH'!K:K,'WAS TECH'!M:M) -> 1 | H16: 0
C17: WASSOLYARADG20 | G17: =_xlfn.XLOOKUP(C17,'WAS TECH'!K:K,'WAS TECH'!M:M) -> 1 | H17: 0
... C44: WASWATTRTWAN20 | G44: =_xlfn.XLOOKUP(C44,'WAS TECH'!K:K,'WAS TECH'!M:M) -> 1 | H44: 0
C45: {=_xlfn.UNIQUE('WAS TECH'!K96:K110)} -> WASSOLPAPLDFDEC20 | G45: =_xlfn.XLOOKUP(C45,'WAS TECH'!K:K,'WAS TECH'!M:M) -> 1 | H45: 0
C46: WASSOLGLALDFDEC20 | G46: =_xlfn.XLOOKUP(C46,'WAS TECH'!K:K,'WAS TECH'!M:M) -> 1 | H46: 0
C47: WASSOLMETLDFDEC20 | G47: =_xlfn.XLOOKUP(C47,'WAS TECH'!K:K,'WAS TECH'!M:M) -> 1 | H47: 0
C48: WASSOLPLALDFDEC20 | G48: =_xlfn.XLOOKUP(C48,'WAS TECH'!K:K,'WAS TECH'!M:M) -> 1 | H48: 0
C49: WASSOLFOOLDFDEC20 | G49: =_xlfn.XLOOKUP(C49,'WAS TECH'!K:K,'WAS TECH'!M:M) -> 1 | H49: 0
C50: WASSOLYARLDFDEC20 | G50: =_xlfn.XLOOKUP(C50,'WAS TECH'!K:K,'WAS TECH'!M:M) -> 1 | H50: 0
C51: WASSOLAOTLDFDEC20 | G51: =_xlfn.XLOOKUP(C51,'WAS TECH'!K:K,'WAS TECH'!M:M) -> 1 | H51: 0
C52: WASSOLHISLDFDEC20 | G52: =_xlfn.XLOOKUP(C52,'WAS TECH'!K:K,'WAS TECH'!M:M) -> 1 | H52: 0
C53: {=_xlfn.UNIQUE('WAS TECH'!K114:K149)} -> WASSOLADGVEN20 | G53: =_xlfn.XLOOKUP(C53,'WAS TECH'!K:K,'WAS TECH'!M:M) -> 1 | H53: 0
C54: WASSOLADGFLA20 | G54: =_xlfn.XLOOKUP(C54,'WAS TECH'!K:K,'WAS TECH'!M:M) -> 1 | H54: 0
C55: WASSOLADGCOG20 | G55: =_xlfn.XLOOKUP(C55,'WAS TECH'!K:K,'WAS TECH'!M:M) -> 1 | H55: 0
C56: WASSOLADGPOW20 | G56: =_xlfn.XLOOKUP(C56,'WAS TECH'!K:K,'WAS TECH'!M:M) -> 1 | H56: 0
C57: WASSOLADGPUR20 | G57: =_xlfn.XLOOKUP(C57,'WAS TECH'!K:K,'WAS TECH'!M:M) -> 1 | H57: 0
C58: WASSOLLDFVEN20 | G58: =_xlfn.XLOOKUP(C58,'WAS TECH'!K:K,'WAS TECH'!M:M) -> 1 | H58: 0
C59: WASSOLLDFFLA20 | G59: =_xlfn.XLOOKUP(C59,'WAS TECH'!K:K,'WAS TECH'!M:M) -> 1 | H59: 0
C60: WASSOLLDFCOG20 | G60: =_xlfn.XLOOKUP(C60,'WAS TECH'!K:K,'WAS TECH'!M:M) -> 1 | H60: 0
C61: WASSOLLDFPOW20 | G61: =_xlfn.XLOOKUP(C61,'WAS TECH'!K:K,'WAS TECH'!M:M) -> 1 | H61: 0
C62: WASSOLLDFPUR20 | G62: =_xlfn.XLOOKUP(C62,'WAS TECH'!K:K,'WAS TECH'!M:M) -> 1 | H62: 0
C63: WASWATWADVEN20 | G63: =_xlfn.XLOOKUP(C63,'WAS TECH'!K:K,'WAS TECH'!M:M) -> 1 | H63: 0
C64: WASWATWADFLA20 | G64: =_xlfn.XLOOKUP(C64,'WAS TECH'!K:K,'WAS TECH'!M:M) -> 1 | H64: 0
C65: WASWATWADCOG20 | G65: =_xlfn.XLOOKUP(C65,'WAS TECH'!K:K,'WAS TECH'!M:M) -> 1 | H65: 0
... C72: WASWATWANPUR20 | G72: =_xlfn.XLOOKUP(C72,'WAS TECH'!K:K,'WAS TECH'!M:M) -> 1 | H72: 0
