Workbook

Sheet ReadMe
A1: Generic Comet (GC) TIMES Residential
B3: Sheet color
C4: Parameters
C6: City Dashboard
C8: GC Databases
C10: TIMES formatted

Sheet >> City Data

Sheet City characteristics
B2: City Basic Data
B4: Calibration methodology | C4: GHG Inventory
B6: A. City Characteristics
B7: Data Item | C7: Value | D7: Units
B8: City Name | C8: New York
B9: Latitude | C9: 40.5
B10: Longitude | C10: -75
B11: County | C11: New York County
B12: State | C12: New York
B13: Census Division | C13: Middle Atlantic
B14: Climate Division | C14: Northeast
B15: Egrid Region | C15: NPCC NYC/Westchester
B16: Area of city (excluding water, natural and agricultural areas) | C16: 778 | D16: square kilometers
B17: * Division and Region Map can be found in the Maps sheet.
B18: B. Planning Base Year and Target Years
B19: Year | C19: Value | D19: Units
B20: Base Year | C20: 2019 | D20: Acceptable range [2018,2021]
B21: End Year | C21: 2050
B23: C. City Population and GDP
B24: Data Item | C24: Value | D24: Units
B25: Population in Base Year | C25: 8337 | D25: Thousand of people
B26: Annual population growth (Base Year - End Year) | C26: 0.5 | D26: % people
B27: GDP in Base Year | C27: 1206000 | D27: Million US$
B28: Annual GDP growth rate | C28: 2 | D28: % US$
B29: Share of manufacturing GDP | C29: 5 | D29: % US$
B30: Share of State population | C30: 0.42835123
B31: Share of State GDP | C31: 0.67251772
B32: Adjustment from state manufacturing GDP | C32: 1.0638298
B34: D. Climate Data
B35: Data Item | C35: 2000 | D35: 2050 | E35: 2100 | F35: Units
B36: Heating degree days (HDD) | C36: 4473.4625 | D36: 4066.4182 | E36: 3763.8582 | F36: F
B37: Cooling degree days (CDD) | C37: 1020.7333 | D37: 1224.2555 | E37: 1375.5355 | F37: F
B39: Data Item | C39: Value | D39: Units
B40: Correction from State HDD | C40: 0.72727402
B41: Correction from State CDD | C41: 1.5583715
B42: Annual precipitation | C42: 762 | D42: mm / year
B43: Climate change scenario | C43: RCP4.5
B44: Average temperature increase in 1980-2020 | C44: 1.4617857 | D44: F
B45: Forecasted average temperature increase in 2035-2065 | C45: 3.13 | D45: F
B46: Forecasted average temperature increase in 2070-2100 | C46: 4.37 | D46: F
...

Sheet >> GC_NewTech

Sheet Demand
A1: Sector | B1: Sub-sector | C1: Archetype | D1: Vintage | E1: Demand Label | F1: Unit | G1: 2019 | H1: 2020 | I1: 2025 | J1: 2030 | K1: 2035 | L1: 2040 | M1: 2045 | N1: 2050 | O1: 2055 | P1: 2060 | Q1: 2065 | R1: 2070 | S1: 2075 | T1: 2080 | U1: 2085 | V1: 2090 | W1: 2095 | X1: 2100
A2: Commercial | B2: Hotel | D2: Old | E2: COMHOTOldDMD | F2: Mm2 | G2: 11.978701 | H2: 11.978701 | I2: 11.978701 | J2: 11.978701 | K2: 11.978701 | L2: 11.978701 | M2: 11.978701 | N2: 11.978701 | O2: 11.978701 | P2: 11.978701 | Q2: 11.978701 | R2: 11.978701 | S2: 11.978701 | T2: 11.978701 | U2: 11.978701 | V2: 11.978701 | W2: 11.978701 | X2: 11.978701
A3: Commercial | B3: Retail | D3: Old | E3: COMRETOldDMD | F3: Mm2 | G3: 23.081056 | H3: 23.081056 | I3: 23.081056 | J3: 23.081056 | K3: 23.081056 | L3: 23.081056 | M3: 23.081056 | N3: 23.081056 | O3: 23.081056 | P3: 23.081056 | Q3: 23.081056 | R3: 23.081056 | S3: 23.081056 | T3: 23.081056 | U3: 23.081056 | V3: 23.081056 | W3: 23.081056 | X3: 23.081056
A4: Commercial | B4: Office | D4: Old | E4: COMOFFOldDMD | F4: Mm2 | G4: 73.164819 | H4: 73.164819 | I4: 73.164819 | J4: 73.164819 | K4: 73.164819 | L4: 73.164819 | M4: 73.164819 | N4: 73.164819 | O4: 73.164819 | P4: 73.164819 | Q4: 73.164819 | R4: 73.164819 | S4: 73.164819 | T4: 73.164819 | U4: 73.164819 | V4: 73.164819 | W4: 73.164819 | X4: 73.164819
A5: Commercial | B5: Hospital | D5: Old | E5: COMHOPOldDMD | F5: Mm2 | G5: 44.382259 | H5: 44.382259 | I5: 44.382259 | J5: 44.382259 | K5: 44.382259 | L5: 44.382259 | M5: 44.382259 | N5: 44.382259 | O5: 44.382259 | P5: 44.382259 | Q5: 44.382259 | R5: 44.382259 | S5: 44.382259 | T5: 44.382259 | U5: 44.382259 | V5: 44.382259 | W5: 44.382259 | X5: 44.382259
A6: Commercial | B6: Educationnal | D6: Old | E6: COMEDUOldDMD | F6: Mm2 | G6: 48.565496 | H6: 48.565496 | I6: 48.565496 | J6: 48.565496 | K6: 48.565496 | L6: 48.565496 | M6: 48.565496 | N6: 48.565496 | O6: 48.565496 | P6: 48.565496 | Q6: 48.565496 | R6: 48.565496 | S6: 48.565496 | T6: 48.565496 | U6: 48.565496 | V6: 48.565496 | W6: 48.565496 | X6: 48.565496
A7: Commercial | B7: Warehouse | D7: Old | E7: COMWAROldDMD | F7: Mm2 | G7: 32.733587 | H7: 32.733587 | I7: 32.733587 | J7: 32.733587 | K7: 32.733587 | L7: 32.733587 | M7: 32.733587 | N7: 32.733587 | O7: 32.733587 | P7: 32.733587 | Q7: 32.733587 | R7: 32.733587 | S7: 32.733587 | T7: 32.733587 | U7: 32.733587 | V7: 32.733587 | W7: 32.733587 | X7: 32.733587
A8: Commercial | B8: Municipal | D8: Old | E8: COMMUNOldDMD | F8: Mm2 | G8: 16.841333 | H8: 16.841333 | I8: 16.841333 | J8: 16.841333 | K8: 16.841333 | L8: 16.841333 | M8: 16.841333 | N8: 16.841333 | O8: 16.841333 | P8: 16.841333 | Q8: 16.841333 | R8: 16.841333 | S8: 16.841333 | T8: 16.841333 | U8: 16.841333 | V8: 16.841333 | W8: 16.841333 | X8: 16.841333
A9: Commercial | B9: Other | D9: Old | E9: COMOTHOldDMD | F9: Mm2 | G9: 8.7602804 | H9: 8.7602804 | I9: 8.7602804 | J9: 8.7602804 | K9: 8.7602804 | L9: 8.7602804 | M9: 8.7602804 | N9: 8.7602804 | O9: 8.7602804 | P9: 8.7602804 | Q9: 8.7602804 | R9: 8.7602804 | S9: 8.7602804 | T9: 8.7602804 | U9: 8.7602804 | V9: 8.7602804 | W9: 8.7602804 | X9: 8.7602804
A10: Commercial | B10: Hotel | D10: New | E10: COMHOTNewDMD | F10: Mm2 | G10: 0 | H10: 0.23957402 | I10: 1.4374441 | J10: 2.6353143 | K10: 3.8331844 | L10: 5.0310545 | M10: 6.2289246 | N10: 7.4267947 | O10: 8.6246649 | P10: 9.822535 | Q10: 11.020405 | R10: 12.218275 | S10: 13.416145 | T10: 14.614015 | U10: 15.811886 | V10: 17.009756 | W10: 18.207626 | X10: 19.405496
A11: Commercial | B11: Retail | D11: New | E11: COMRETNewDMD | F11: Mm2 | G11: 0 | H11: 0.46162113 | I11: 2.7697268 | J11: 5.0778324 | K11: 7.3859381 | L11: 9.6940437 | M11: 12.002149 | N11: 14.310255 | O11: 16.618361 | P11: 18.926466 | Q11: 21.234572 | R11: 23.542678 | S11: 25.850783 | T11: 28.158889 | U11: 30.466995 | V11: 32.7751 | W11: 35.083206 | X11: 37.391311
A12: Commercial | B12: Office | D12: New | E12: COMOFFNewDMD | F12: Mm2 | G12: 0 | H12: 1.4632964 | I12: 8.7797783 | J12: 16.09626 | K12: 23.412742 | L12: 30.729224 | M12: 38.045706 | N12: 45.362188 | O12: 52.67867 | P12: 59.995152 | Q12: 67.311633 | R12: 74.628115 | S12: 81.944597 | T12: 89.261079 | U12: 96.577561 | V12: 103.89404 | W12: 111.21052 | X12: 118.52701
A13: Commercial | B13: Hospital | D13: New | E13: COMHOPNewDMD | F13: Mm2 | G13: 0 | H13: 0.88764519 | I13: 5.3258711 | J13: 9.764097 | K13: 14.202323 | L13: 18.640549 | M13: 23.078775 | N13: 27.517001 | O13: 31.955227 | P13: 36.393453 | Q13: 40.831679 | R13: 45.269904 | S13: 49.70813 | T13: 54.146356 | U13: 58.584582 | V13: 63.022808 | W13: 67.461034 | X13: 71.89926
... A17: Commercial | B17: Other | D17: New | E17: COMOTHNewDMD | F17: Mm2 | G17: 0 | H17: 0.17520561 | I17: 1.0512337 | J17: 1.9272617 | K17: 2.8032897 | L17: 3.6793178 | M17: 4.5553458 | N17: 5.4313739 | O17: 6.3074019 | P17: 7.18343 | Q17: 8.059458 | R17: 8.9354861 | S17: 9.8115141 | T17: 10.687542 | U17: 11.56357 | V17: 12.439598 | W17: 13.315626 | X17: 14.191654
A18: Residential | B18: Apartment | C18: Low Income | D18: Old | E18: RESAPALOOldDMD | F18: Mm2 | G18: 51.807877 | H18: 51.807877 | I18: 51.807877 | J18: 51.807877 | K18: 51.807877 | L18: 51.807877 | M18: 51.807877 | N18: 51.807877 | O18: 51.807877 | P18: 51.807877 | Q18: 51.807877 | R18: 51.807877 | S18: 51.807877 | T18: 51.807877 | U18: 51.807877 | V18: 51.807877 | W18: 51.807877 | X18: 51.807877
A19: Residential | B19: House | C19: Low Income | D19: Old | E19: RESHOULOOldDMD | F19: Mm2 | G19: 14.956798 | H19: 14.956798 | I19: 14.956798 | J19: 14.956798 | K19: 14.956798 | L19: 14.956798 | M19: 14.956798 | N19: 14.956798 | O19: 14.956798 | P19: 14.956798 | Q19: 14.956798 | R19: 14.956798 | S19: 14.956798 | T19: 14.956798 | U19: 14.956798 | V19: 14.956798 | W19: 14.956798 | X19: 14.956798
A20: Residential | B20: Apartment | C20: Lower-Middle Income | D20: Old | E20: RESAPALMOldDMD | F20: Mm2 | G20: 57.121976 | H20: 57.121976 | I20: 57.121976 | J20: 57.121976 | K20: 57.121976 | L20: 57.121976 | M20: 57.121976 | N20: 57.121976 | O20: 57.121976 | P20: 57.121976 | Q20: 57.121976 | R20: 57.121976 | S20: 57.121976 | T20: 57.121976 | U20: 57.121976 | V20: 57.121976 | W20: 57.121976 | X20: 57.121976
A21: Residential | B21: House | C21: Lower-Middle Income | D21: Old | E21: RESHOULMOldDMD | F21: Mm2 | G21: 38.299259 | H21: 38.299259 | I21: 38.299259 | J21: 38.299259 | K21: 38.299259 | L21: 38.299259 | M21: 38.299259 | N21: 38.299259 | O21: 38.299259 | P21: 38.299259 | Q21: 38.299259 | R21: 38.299259 | S21: 38.299259 | T21: 38.299259 | U21: 38.299259 | V21: 38.299259 | W21: 38.299259 | X21: 38.299259
A22: Residential | B22: Apartment | C22: Upper-Middle Income | D22: Old | E22: RESAPAUMOldDMD | F22: Mm2 | G22: 15.495888 | H22: 15.495888 | I22: 15.495888 | J22: 15.495888 | K22: 15.495888 | L22: 15.495888 | M22: 15.495888 | N22: 15.495888 | O22: 15.495888 | P22: 15.495888 | Q22: 15.495888 | R22: 15.495888 | S22: 15.495888 | T22: 15.495888 | U22: 15.495888 | V22: 15.495888 | W22: 15.495888 | X22: 15.495888
A23: Residential | B23: House | C23: Upper-Middle Income | D23: Old | E23: RESHOUUMOldDMD | F23: Mm2 | G23: 19.187214 | H23: 19.187214 | I23: 19.187214 | J23: 19.187214 | K23: 19.187214 | L23: 19.187214 | M23: 19.187214 | N23: 19.187214 | O23: 19.187214 | P23: 19.187214 | Q23: 19.187214 | R23: 19.187214 | S23: 19.187214 | T23: 19.187214 | U23: 19.187214 | V23: 19.187214 | W23: 19.187214 | X23: 19.187214
A24: Residential | B24: Apartment | C24: High Income | D24: Old | E24: RESAPAHIOldDMD | F24: Mm2 | G24: 66.398717 | H24: 66.398717 | I24: 66.398717 | J24: 66.398717 | K24: 66.398717 | L24: 66.398717 | M24: 66.398717 | N24: 66.398717 | O24: 66.398717 | P24: 66.398717 | Q24: 66.398717 | R24: 66.398717 | S24: 66.398717 | T24: 66.398717 | U24: 66.398717 | V24: 66.398717 | W24: 66.398717 | X24: 66.398717
A25: Residential | B25: House | C25: High Income | D25: Old | E25: RESHOUHIOldDMD | F25: Mm2 | G25: 96.552051 | H25: 96.552051 | I25: 96.552051 | J25: 96.552051 | K25: 96.552051 | L25: 96.552051 | M25: 96.552051 | N25: 96.552051 | O25: 96.552051 | P25: 96.552051 | Q25: 96.552051 | R25: 96.552051 | S25: 96.552051 | T25: 96.552051 | U25: 96.552051 | V25: 96.552051 | W25: 96.552051 | X25: 96.552051
A26: Residential | B26: Apartment | C26: Low Income | D26: New | E26: RESAPALONewDMD | F26: Mm2 | G26: 0 | H26: 0.25903939 | I26: 1.5542363 | J26: 2.8494333 | K26: 4.1446302 | L26: 5.4398271 | M26: 6.7350241 | N26: 8.030221 | O26: 9.3254179 | P26: 10.620615 | Q26: 11.915812 | R26: 13.211009 | S26: 14.506206 | T26: 15.801403 | U26: 17.0966 | V26: 18.391797 | W26: 19.686993 | X26: 20.98219
A27: Residential | B27: House | C27: Low Income | D27: New | E27: RESHOULONewDMD | F27: Mm2 | G27: 0 | H27: 0.07478399 | I27: 0.44870394 | J27: 0.82262389 | K27: 1.1965438 | L27: 1.5704638 | M27: 1.9443837 | N27: 2.3183037 | O27: 2.6922236 | P27: 3.0661436 | Q27: 3.4400635 | R27: 3.8139835 | S27: 4.1879034 | T27: 4.5618234 | U27: 4.9357433 | V27: 5.3096633 | W27: 5.6835832 | X27: 6.0575032
A28: Residential | B28: Apartment | C28: Lower-Middle Income | D28: New | E28: RESAPALMNewDMD | F28: Mm2 | G28: 0 | H28: 0.28560988 | I28: 1.7136593 | J28: 3.1417087 | K28: 4.5697581 | L28: 5.9978075 | M28: 7.4258569 | N28: 8.8539063 | O28: 10.281956 | P28: 11.710005 | Q28: 13.138055 | R28: 14.566104 | S28: 15.994153 | T28: 17.422203 | U28: 18.850252 | V28: 20.278302 | W28: 21.706351 | X28: 23.1344
A29: Residential | B29: House | C29: Lower-Middle Income | D29: New | E29: RESHOULMNewDMD | F29: Mm2 | G29: 0 | H29: 0.19149629 | I29: 1.1489778 | J29: 2.1064592 | K29: 3.0639407 | L29: 4.0214222 | M29: 4.9789036 | N29: 5.9363851 | O29: 6.8938665 | P29: 7.851348 | Q29: 8.8088295 | R29: 9.7663109 | S29: 10.723792 | T29: 11.681274 | U29: 12.638755 | V29: 13.596237 | W29: 14.553718 | X29: 15.5112
... A33: Residential | B33: House | C33: High Income | D33: New | E33: RESHOUHINewDMD | F33: Mm2 | G33: 0 | H33: 0.48276025 | I33: 2.8965615 | J33: 5.3103628 | K33: 7.7241641 | L33: 10.137965 | M33: 12.551767 | N33: 14.965568 | O33: 17.379369 | P33: 19.79317 | Q33: 22.206972 | R33: 24.620773 | S33: 27.034574 | T33: 29.448376 | U33: 31.862177 | V33: 34.275978 | W33: 36.689779 | X33: 39.103581
A34: Industrial | B34: All Industries | E34: INDAINDMD | F34: TJ | G34: 66716.461 | H34: 68050.79 | I34: 74855.869 | J34: 82341.456 | K34: 90575.602 | L34: 99633.162 | M34: 109596.48 | N34: 120556.13 | O34: 132611.74 | P34: 145872.91 | Q34: 160460.2 | R34: 176506.22 | S34: 194156.85 | T34: 213572.53 | U34: 234929.78 | V34: 258422.76 | W34: 284265.04 | X34: 312691.54
A35: Transportation | B35: Passenger | C35: Passenger Car | E35: TRAPASCARDMD | F35: M Vkm | G35: 68921.251 | H35: 69265.857 | I35: 70997.504 | J35: 72772.441 | K35: 74591.752 | L35: 76456.546 | M35: 78367.96 | N35: 80327.159 | O35: 82335.338 | P35: 84393.721 | Q35: 86503.564 | R35: 88666.153 | S35: 90882.807 | T35: 93154.877 | U35: 95483.749 | V35: 97870.843 | W35: 100317.61 | X35: 102825.55
A36: Transportation | B36: Passenger | C36: Passenger Truck | E36: TRAPASLDTDMD | F36: M Vkm | G36: 0 | H36: 0 | I36: 0 | J36: 0 | K36: 0 | L36: 0 | M36: 0 | N36: 0 | O36: 0 | P36: 0 | Q36: 0 | R36: 0 | S36: 0 | T36: 0 | U36: 0 | V36: 0 | W36: 0 | X36: 0
A37: Transportation | B37: Passenger | C37: Motorcycle | E37: TRAPASMOTDMD | F37: M Vkm | G37: 0 | H37: 0 | I37: 0 | J37: 0 | K37: 0 | L37: 0 | M37: 0 | N37: 0 | O37: 0 | P37: 0 | Q37: 0 | R37: 0 | S37: 0 | T37: 0 | U37: 0 | V37: 0 | W37: 0 | X37: 0
A38: Transportation | B38: Freight | C38: Light Commercial Truck | E38: TRAFRECLTDMD | F38: M Vkm | G38: 1578.5179 | H38: 1586.4105 | I38: 1626.0707 | J38: 1666.7225 | K38: 1708.3906 | L38: 1751.1003 | M38: 1794.8778 | N38: 1839.7498 | O38: 1885.7435 | P38: 1932.8871 | Q38: 1981.2093 | R38: 2030.7395 | S38: 2081.508 | T38: 2133.5457 | U38: 2186.8844 | V38: 2241.5565 | W38: 2297.5954 | X38: 2355.0353
A39: Transportation | B39: Freight | C39: Refuse Truck | E39: TRAFRERFTDMD | F39: M Vkm | G39: 70.026308 | H39: 70.37644 | I39: 72.135851 | J39: 73.939247 | K39: 75.787728 | L39: 77.682421 | M39: 79.624482 | N39: 81.615094 | O39: 83.655471 | P39: 85.746858 | Q39: 87.89053 | R39: 90.087793 | S39: 92.339988 | T39: 94.648487 | U39: 97.0147 | V39: 99.440067 | W39: 101.92607 | X39: 104.47422
A40: Transportation | B40: Freight | C40: Single Unit Long-haul Truck | E40: TRAFRESLHDMD | F40: M Vkm | G40: 0 | H40: 0 | I40: 0 | J40: 0 | K40: 0 | L40: 0 | M40: 0 | N40: 0 | O40: 0 | P40: 0 | Q40: 0 | R40: 0 | S40: 0 | T40: 0 | U40: 0 | V40: 0 | W40: 0 | X40: 0
A41: Transportation | B41: Freight | C41: Single Unit Short-haul Truck | E41: TRAFRESSHDMD | F41: M Vkm | G41: 0 | H41: 0 | I41: 0 | J41: 0 | K41: 0 | L41: 0 | M41: 0 | N41: 0 | O41: 0 | P41: 0 | Q41: 0 | R41: 0 | S41: 0 | T41: 0 | U41: 0 | V41: 0 | W41: 0 | X41: 0
A42: Transportation | B42: Freight | C42: Combination Long-haul Truck | E42: TRAFRECLHDMD | F42: M Vkm | G42: 1367.6202 | H42: 1374.4583 | I42: 1408.8197 | J42: 1444.0402 | K42: 1480.1412 | L42: 1517.1447 | M42: 1555.0734 | N42: 1593.9502 | O42: 1633.7989 | P42: 1674.6439 | Q42: 1716.51 | R42: 1759.4228 | S42: 1803.4083 | T42: 1848.4935 | U42: 1894.7059 | V42: 1942.0735 | W42: 1990.6254 | X42: 2040.391
A43: Transportation | B43: Freight | C43: Combination Short-haul Truck | E43: TRAFRECSHDMD | F43: M Vkm | G43: 0 | H43: 0 | I43: 0 | J43: 0 | K43: 0 | L43: 0 | M43: 0 | N43: 0 | O43: 0 | P43: 0 | Q43: 0 | R43: 0 | S43: 0 | T43: 0 | U43: 0 | V43: 0 | W43: 0 | X43: 0
A44: Transportation | B44: Passenger | C44: Transit Bus | E44: TRAPASTBUDMD | F44: M Vkm | G44: 498.20419 | H44: 500.69521 | I44: 513.21259 | J44: 526.0429 | K44: 539.19397 | L44: 552.67382 | M44: 566.49067 | N44: 580.65294 | O44: 595.16926 | P44: 610.04849 | Q44: 625.2997 | R44: 640.93219 | S44: 656.9555 | T44: 673.37939 | U44: 690.21387 | V44: 707.46922 | W44: 725.15595 | X44: 743.28485
A45: Transportation | B45: Passenger | C45: School Bus | E45: TRAPASSBUDMD | F45: M Vkm | G45: 86.053217 | H45: 86.483483 | I45: 88.645571 | J45: 90.86171 | K45: 93.133253 | L45: 95.461584 | M45: 97.848123 | N45: 100.29433 | O45: 102.80168 | P45: 105.37173 | Q45: 108.00602 | R45: 110.70617 | S45: 113.47382 | T45: 116.31067 | U45: 119.21844 | V45: 122.1989 | W45: 125.25387 | X45: 128.38522
A46: Transportation | B46: Passenger | C46: Other Buses | E46: TRAPASOBUDMD | F46: M Vkm | G46: 0 | H46: 0 | I46: 0 | J46: 0 | K46: 0 | L46: 0 | M46: 0 | N46: 0 | O46: 0 | P46: 0 | Q46: 0 | R46: 0 | S46: 0 | T46: 0 | U46: 0 | V46: 0 | W46: 0 | X46: 0
...

Sheet IND TECH
A2: Sector | B2: Sub-sector | C2: Archetype | D2: Vintage | E2: End Use | F2: Technology | G2: Energy | H2: First Year | I2: Description | J2: Input Label | K2: Output Label | L2: Technology Label | M2: EFF | N2: CFA | O2: C2A | P2: CAPEX ($/kW) | Q2: To include
A3: Industrial | B3: All Industries | E3: All end use | G3: Coal | J3: INDCOA | K3: INDAINDMD | L3: INDAINAEUCOA20 | M3: 1 | N3: 0.9 | O3: 31.536 | P3: 1000 | Q3: 1
A4: Industrial | B4: All Industries | E4: All end use | G4: Petcoke | J4: INDPCK | K4: INDAINDMD | L4: INDAINAEUPCK20 | M4: 1 | N4: 0.9 | O4: 31.536 | P4: 1000 | Q4: 1
A5: Industrial | B5: All Industries | E5: All end use | G5: LPG | J5: INDLPG | K5: INDAINDMD | L5: INDAINAEULPG20 | M5: 1 | N5: 0.9 | O5: 31.536 | P5: 1000 | Q5: 1
A6: Industrial | B6: All Industries | E6: All end use | G6: Fuel oil | J6: INDFOI | K6: INDAINDMD | L6: INDAINAEUFOI20 | M6: 1 | N6: 0.9 | O6: 31.536 | P6: 1000 | Q6: 1
A7: Industrial | B7: All Industries | E7: All end use | G7: Natural gas | J7: INDNGA | K7: INDAINDMD | L7: INDAINAEUNGA20 | M7: 1 | N7: 0.9 | O7: 31.536 | P7: 1000 | Q7: 1
A8: Industrial | B8: All Industries | E8: All end use | G8: RNG | J8: INDRNG | K8: INDAINDMD | L8: INDAINAEURNG20 | M8: 1 | N8: 0.9 | O8: 31.536 | P8: 1000 | Q8: 1
A9: Industrial | B9: All Industries | E9: All end use | G9: Kerosene | J9: INDKER | K9: INDAINDMD | L9: INDAINAEUKER20 | M9: 1 | N9: 0.9 | O9: 31.536 | P9: 1000 | Q9: 1
A10: Industrial | B10: All Industries | E10: All end use | G10: Gasoline | J10: INDGSL | K10: INDAINDMD | L10: INDAINAEUGSL20 | M10: 1 | N10: 0.9 | O10: 31.536 | P10: 1000 | Q10: 1
A11: Industrial | B11: All Industries | E11: All end use | G11: Diesel | J11: INDDSL | K11: INDAINDMD | L11: INDAINAEUDSL20 | M11: 1 | N11: 0.9 | O11: 31.536 | P11: 1000 | Q11: 1
A12: Industrial | B12: All Industries | E12: All end use | G12: Electricity | J12: INDELC | K12: INDAINDMD | L12: INDAINAEUELC20 | M12: 1 | N12: 0.9 | O12: 31.536 | P12: 1000 | Q12: 1
A13: Industrial | B13: All Industries | E13: All end use | G13: Hydrogen | J13: INDH2G | K13: INDAINDMD | L13: INDAINAEUH2G20 | M13: 1 | N13: 0.9 | O13: 31.536 | P13: 1000 | Q13: 1
A14: * | L14: * | Q14: *
A15: Industrial | B15: All Industries | E15: All end use | G15: Retrofit | J15: INDRET | K15: INDAINDMD | L15: INDAINAEURET20 | M15: 1 | N15: 0.9 | O15: 31.536 | P15: 10000 | Q15: 1

Sheet >> TIMES

Sheet Def_Tech
B2: ~FI_Process
B3: Sets | C3: TechName | D3: TechDesc | E3: Tact | F3: Tcap | G3: Tslvl | H3: PrimaryCG | I3: Vintage
B4: *Process Set Membership | C4: Technology Name | D4: Technology Description | E4: Activity Unit | F4: Capacity Unit | G4: TimeSlice level of Process Activity | H4: Primary Commodity Group | I4: Vintage Tracking
B5: MIN | C5: =Def_Comm!C5&"MIN" -> INDRETMIN | D5: =Def_Comm!D5&" Mining" -> Industrial Retrofit potential Mining | E5: =IF(B5="*","*",IF(F5="Mlma","Mlm","TJ")) -> TJ | F5: =IF(B5="*","*","MW") -> MW
B6: =IF(C6="*","*",IF('IND TECH'!Q3=0,"*","PRE")) -> PRE | C6: ='IND TECH'!L3 -> INDAINAEUCOA20 | D6: =_xlfn.XLOOKUP($C6,'IND TECH'!$L:$L,'IND TECH'!$A:$A)&" "&_xlfn.XLOOKUP($C6,'IND TECH'!$L:$L,'IND TECH'!$B:$B)&" "&_xlfn.XLOOKUP($C6,'IND TECH'!$L:$L,'IND TECH'!$C:$C)&" "&_xlfn.XLOOKUP($C6,'IND TECH'!$L:$L,'IND TECH'!$D:$D)&" "&_xlfn.XLOOKUP($C6,'IND TECH'!$L:$L,'IND TECH'!$E:$E)&" "&_xlfn.XLOOKUP($C6,'IND TECH'!$L:$L,'IND TECH'!$F:$F)&" "&_xlfn.XLOOKUP($C6,'IND TECH'!$L:$L,'IND TECH'!$G:$G)&" "&_xlfn.XLOOKUP($C6,'IND TECH'!$L:$L,'IND TECH'!$H:$H) -> Industrial All Industries All end use Coal | E6: =IF(B6="*","*",IF(F6="Mlma","Mlm","TJ")) -> TJ | F6: =IF(B6="*","*","MW") -> MW
B7: =IF(C7="*","*",IF('IND TECH'!Q4=0,"*","PRE")) -> PRE | C7: ='IND TECH'!L4 -> INDAINAEUPCK20 | D7: =_xlfn.XLOOKUP($C7,'IND TECH'!$L:$L,'IND TECH'!$A:$A)&" "&_xlfn.XLOOKUP($C7,'IND TECH'!$L:$L,'IND TECH'!$B:$B)&" "&_xlfn.XLOOKUP($C7,'IND TECH'!$L:$L,'IND TECH'!$C:$C)&" "&_xlfn.XLOOKUP($C7,'IND TECH'!$L:$L,'IND TECH'!$D:$D)&" "&_xlfn.XLOOKUP($C7,'IND TECH'!$L:$L,'IND TECH'!$E:$E)&" "&_xlfn.XLOOKUP($C7,'IND TECH'!$L:$L,'IND TECH'!$F:$F)&" "&_xlfn.XLOOKUP($C7,'IND TECH'!$L:$L,'IND TECH'!$G:$G)&" "&_xlfn.XLOOKUP($C7,'IND TECH'!$L:$L,'IND TECH'!$H:$H) -> Industrial All Industries All end use Petcoke | E7: =IF(B7="*","*",IF(F7="Mlma","Mlm","TJ")) -> TJ | F7: =IF(B7="*","*","MW") -> MW
B8: =IF(C8="*","*",IF('IND TECH'!Q5=0,"*","PRE")) -> PRE | C8: ='IND TECH'!L5 -> INDAINAEULPG20 | D8: =_xlfn.XLOOKUP($C8,'IND TECH'!$L:$L,'IND TECH'!$A:$A)&" "&_xlfn.XLOOKUP($C8,'IND TECH'!$L:$L,'IND TECH'!$B:$B)&" "&_xlfn.XLOOKUP($C8,'IND TECH'!$L:$L,'IND TECH'!$C:$C)&" "&_xlfn.XLOOKUP($C8,'IND TECH'!$L:$L,'IND TECH'!$D:$D)&" "&_xlfn.XLOOKUP($C8,'IND TECH'!$L:$L,'IND TECH'!$E:$E)&" "&_xlfn.XLOOKUP($C8,'IND TECH'!$L:$L,'IND TECH'!$F:$F)&" "&_xlfn.XLOOKUP($C8,'IND TECH'!$L:$L,'IND TECH'!$G:$G)&" "&_xlfn.XLOOKUP($C8,'IND TECH'!$L:$L,'IND TECH'!$H:$H) -> Industrial All Industries All end use LPG | E8: =IF(B8="*","*",IF(F8="Mlma","Mlm","TJ")) -> TJ | F8: =IF(B8="*","*","MW") -> MW
B9: =IF(C9="*","*",IF('IND TECH'!Q6=0,"*","PRE")) -> PRE | C9: ='IND TECH'!L6 -> INDAINAEUFOI20 | D9: =_xlfn.XLOOKUP($C9,'IND TECH'!$L:$L,'IND TECH'!$A:$A)&" "&_xlfn.XLOOKUP($C9,'IND TECH'!$L:$L,'IND TECH'!$B:$B)&" "&_xlfn.XLOOKUP($C9,'IND TECH'!$L:$L,'IND TECH'!$C:$C)&" "&_xlfn.XLOOKUP($C9,'IND TECH'!$L:$L,'IND TECH'!$D:$D)&" "&_xlfn.XLOOKUP($C9,'IND TECH'!$L:$L,'IND TECH'!$E:$E)&" "&_xlfn.XLOOKUP($C9,'IND TECH'!$L:$L,'IND TECH'!$F:$F)&" "&_xlfn.XLOOKUP($C9,'IND TECH'!$L:$L,'IND TECH'!$G:$G)&" "&_xlfn.XLOOKUP($C9,'IND TECH'!$L:$L,'IND TECH'!$H:$H) -> Industrial All Industries All end use Fuel oil | E9: =IF(B9="*","*",IF(F9="Mlma","Mlm","TJ")) -> TJ | F9: =IF(B9="*","*","MW") -> MW
B10: =IF(C10="*","*",IF('IND TECH'!Q7=0,"*","PRE")) -> PRE | C10: ='IND TECH'!L7 -> INDAINAEUNGA20 | D10: =_xlfn.XLOOKUP($C10,'IND TECH'!$L:$L,'IND TECH'!$A:$A)&" "&_xlfn.XLOOKUP($C10,'IND TECH'!$L:$L,'IND TECH'!$B:$B)&" "&_xlfn.XLOOKUP($C10,'IND TECH'!$L:$L,'IND TECH'!$C:$C)&" "&_xlfn.XLOOKUP($C10,'IND TECH'!$L:$L,'IND TECH'!$D:$D)&" "&_xlfn.XLOOKUP($C10,'IND TECH'!$L:$L,'IND TECH'!$E:$E)&" "&_xlfn.XLOOKUP($C10,'IND TECH'!$L:$L,'IND TECH'!$F:$F)&" "&_xlfn.XLOOKUP($C10,'IND TECH'!$L:$L,'IND TECH'!$G:$G)&" "&_xlfn.XLOOKUP($C10,'IND TECH'!$L:$L,'IND TECH'!$H:$H) -> Industrial All Industries All end use Natural gas | E10: =IF(B10="*","*",IF(F10="Mlma","Mlm","TJ")) -> TJ | F10: =IF(B10="*","*","MW") -> MW
B11: =IF(C11="*","*",IF('IND TECH'!Q8=0,"*","PRE")) -> PRE | C11: ='IND TECH'!L8 -> INDAINAEURNG20 | D11: =_xlfn.XLOOKUP($C11,'IND TECH'!$L:$L,'IND TECH'!$A:$A)&" "&_xlfn.XLOOKUP($C11,'IND TECH'!$L:$L,'IND TECH'!$B:$B)&" "&_xlfn.XLOOKUP($C11,'IND TECH'!$L:$L,'IND TECH'!$C:$C)&" "&_xlfn.XLOOKUP($C11,'IND TECH'!$L:$L,'IND TECH'!$D:$D)&" "&_xlfn.XLOOKUP($C11,'IND TECH'!$L:$L,'IND TECH'!$E:$E)&" "&_xlfn.XLOOKUP($C11,'IND TECH'!$L:$L,'IND TECH'!$F:$F)&" "&_xlfn.XLOOKUP($C11,'IND TECH'!$L:$L,'IND TECH'!$G:$G)&" "&_xlfn.XLOOKUP($C11,'IND TECH'!$L:$L,'IND TECH'!$H:$H) -> Industrial All Industries All end use RNG | E11: =IF(B11="*","*",IF(F11="Mlma","Mlm","TJ")) -> TJ | F11: =IF(B11="*","*","MW") -> MW
B12: =IF(C12="*","*",IF('IND TECH'!Q9=0,"*","PRE")) -> PRE | C12: ='IND TECH'!L9 -> INDAINAEUKER20 | D12: =_xlfn.XLOOKUP($C12,'IND TECH'!$L:$L,'IND TECH'!$A:$A)&" "&_xlfn.XLOOKUP($C12,'IND TECH'!$L:$L,'IND TECH'!$B:$B)&" "&_xlfn.XLOOKUP($C12,'IND TECH'!$L:$L,'IND TECH'!$C:$C)&" "&_xlfn.XLOOKUP($C12,'IND TECH'!$L:$L,'IND TECH'!$D:$D)&" "&_xlfn.XLOOKUP($C12,'IND TECH'!$L:$L,'IND TECH'!$E:$E)&" "&_xlfn.XLOOKUP($C12,'IND TECH'!$L:$L,'IND TECH'!$F:$F)&" "&_xlfn.XLOOKUP($C12,'IND TECH'!$L:$L,'IND TECH'!$G:$G)&" "&_xlfn.XLOOKUP($C12,'IND TECH'!$L:$L,'IND TECH'!$H:$H) -> Industrial All Industries All end use Kerosene | E12: =IF(B12="*","*",IF(F12="Mlma","Mlm","TJ")) -> TJ | F12: =IF(B12="*","*","MW") -> MW
B13: =IF(C13="*","*",IF('IND TECH'!Q10=0,"*","PRE")) -> PRE | C13: ='IND TECH'!L10 -> INDAINAEUGSL20 | D13: =_xlfn.XLOOKUP($C13,'IND TECH'!$L:$L,'IND TECH'!$A:$A)&" "&_xlfn.XLOOKUP($C13,'IND TECH'!$L:$L,'IND TECH'!$B:$B)&" "&_xlfn.XLOOKUP($C13,'IND TECH'!$L:$L,'IND TECH'!$C:$C)&" "&_xlfn.XLOOKUP($C13,'IND TECH'!$L:$L,'IND TECH'!$D:$D)&" "&_xlfn.XLOOKUP($C13,'IND TECH'!$L:$L,'IND TECH'!$E:$E)&" "&_xlfn.XLOOKUP($C13,'IND TECH'!$L:$L,'IND TECH'!$F:$F)&" "&_xlfn.XLOOKUP($C13,'IND TECH'!$L:$L,'IND TECH'!$G:$G)&" "&_xlfn.XLOOKUP($C13,'IND TECH'!$L:$L,'IND TECH'!$H:$H) -> Industrial All Industries All end use Gasoline | E13: =IF(B13="*","*",IF(F13="Mlma","Mlm","TJ")) -> TJ | F13: =IF(B13="*","*","MW") -> MW
B14: =IF(C14="*","*",IF('IND TECH'!Q11=0,"*","PRE")) -> PRE | C14: ='IND TECH'!L11 -> INDAINAEUDSL20 | D14: =_xlfn.XLOOKUP($C14,'IND TECH'!$L:$L,'IND TECH'!$A:$A)&" "&_xlfn.XLOOKUP($C14,'IND TECH'!$L:$L,'IND TECH'!$B:$B)&" "&_xlfn.XLOOKUP($C14,'IND TECH'!$L:$L,'IND TECH'!$C:$C)&" "&_xlfn.XLOOKUP($C14,'IND TECH'!$L:$L,'IND TECH'!$D:$D)&" "&_xlfn.XLOOKUP($C14,'IND TECH'!$L:$L,'IND TECH'!$E:$E)&" "&_xlfn.XLOOKUP($C14,'IND TECH'!$L:$L,'IND TECH'!$F:$F)&" "&_xlfn.XLOOKUP($C14,'IND TECH'!$L:$L,'IND TECH'!$G:$G)&" "&_xlfn.XLOOKUP($C14,'IND TECH'!$L:$L,'IND TECH'!$H:$H) -> Industrial All Industries All end use Diesel | E14: =IF(B14="*","*",IF(F14="Mlma","Mlm","TJ")) -> TJ | F14: =IF(B14="*","*","MW") -> MW
B15: =IF(C15="*","*",IF('IND TECH'!Q12=0,"*","PRE")) -> PRE | C15: ='IND TECH'!L12 -> INDAINAEUELC20 | D15: =_xlfn.XLOOKUP($C15,'IND TECH'!$L:$L,'IND TECH'!$A:$A)&" "&_xlfn.XLOOKUP($C15,'IND TECH'!$L:$L,'IND TECH'!$B:$B)&" "&_xlfn.XLOOKUP($C15,'IND TECH'!$L:$L,'IND TECH'!$C:$C)&" "&_xlfn.XLOOKUP($C15,'IND TECH'!$L:$L,'IND TECH'!$D:$D)&" "&_xlfn.XLOOKUP($C15,'IND TECH'!$L:$L,'IND TECH'!$E:$E)&" "&_xlfn.XLOOKUP($C15,'IND TECH'!$L:$L,'IND TECH'!$F:$F)&" "&_xlfn.XLOOKUP($C15,'IND TECH'!$L:$L,'IND TECH'!$G:$G)&" "&_xlfn.XLOOKUP($C15,'IND TECH'!$L:$L,'IND TECH'!$H:$H) -> Industrial All Industries All end use Electricity | E15: =IF(B15="*","*",IF(F15="Mlma","Mlm","TJ")) -> TJ | F15: =IF(B15="*","*","MW") -> MW
B16: =IF(C16="*","*",IF('IND TECH'!Q13=0,"*","PRE")) -> PRE | C16: ='IND TECH'!L13 -> INDAINAEUH2G20 | D16: =_xlfn.XLOOKUP($C16,'IND TECH'!$L:$L,'IND TECH'!$A:$A)&" "&_xlfn.XLOOKUP($C16,'IND TECH'!$L:$L,'IND TECH'!$B:$B)&" "&_xlfn.XLOOKUP($C16,'IND TECH'!$L:$L,'IND TECH'!$C:$C)&" "&_xlfn.XLOOKUP($C16,'IND TECH'!$L:$L,'IND TECH'!$D:$D)&" "&_xlfn.XLOOKUP($C16,'IND TECH'!$L:$L,'IND TECH'!$E:$E)&" "&_xlfn.XLOOKUP($C16,'IND TECH'!$L:$L,'IND TECH'!$F:$F)&" "&_xlfn.XLOOKUP($C16,'IND TECH'!$L:$L,'IND TECH'!$G:$G)&" "&_xlfn.XLOOKUP($C16,'IND TECH'!$L:$L,'IND TECH'!$H:$H) -> Industrial All Industries All end use Hydrogen | E16: =IF(B16="*","*",IF(F16="Mlma","Mlm","TJ")) -> TJ | F16: =IF(B16="*","*","MW") -> MW
B17: =IF(C17="*","*",IF('IND TECH'!Q14=0,"*","PRE")) -> * | C17: ='IND TECH'!L14 -> * | D17: =_xlfn.XLOOKUP($C17,'IND TECH'!$L:$L,'IND TECH'!$A:$A)&" "&_xlfn.XLOOKUP($C17,'IND TECH'!$L:$L,'IND TECH'!$B:$B)&" "&_xlfn.XLOOKUP($C17,'IND TECH'!$L:$L,'IND TECH'!$C:$C)&" "&_xlfn.XLOOKUP($C17,'IND TECH'!$L:$L,'IND TECH'!$D:$D)&" "&_xlfn.XLOOKUP($C17,'IND TECH'!$L:$L,'IND TECH'!$E:$E)&" "&_xlfn.XLOOKUP($C17,'IND TECH'!$L:$L,'IND TECH'!$F:$F)&" "&_xlfn.XLOOKUP($C17,'IND TECH'!$L:$L,'IND TECH'!$G:$G)&" "&_xlfn.XLOOKUP($C17,'IND TECH'!$L:$L,'IND TECH'!$H:$H) -> * | E17: =IF(B17="*","*",IF(F17="Mlma","Mlm","TJ")) -> * | F17: =IF(B17="*","*","MW") -> *
B18: =IF(C18="*","*",IF('IND TECH'!Q15=0,"*","PRE")) -> PRE | C18: ='IND TECH'!L15 -> INDAINAEURET20 | D18: =_xlfn.XLOOKUP($C18,'IND TECH'!$L:$L,'IND TECH'!$A:$A)&" "&_xlfn.XLOOKUP($C18,'IND TECH'!$L:$L,'IND TECH'!$B:$B)&" "&_xlfn.XLOOKUP($C18,'IND TECH'!$L:$L,'IND TECH'!$C:$C)&" "&_xlfn.XLOOKUP($C18,'IND TECH'!$L:$L,'IND TECH'!$D:$D)&" "&_xlfn.XLOOKUP($C18,'IND TECH'!$L:$L,'IND TECH'!$E:$E)&" "&_xlfn.XLOOKUP($C18,'IND TECH'!$L:$L,'IND TECH'!$F:$F)&" "&_xlfn.XLOOKUP($C18,'IND TECH'!$L:$L,'IND TECH'!$G:$G)&" "&_xlfn.XLOOKUP($C18,'IND TECH'!$L:$L,'IND TECH'!$H:$H) -> Industrial All Industries All end use Retrofit | E18: =IF(B18="*","*",IF(F18="Mlma","Mlm","TJ")) -> TJ | F18: =IF(B18="*","*","MW") -> MW
B1427: PRE | C1427: ='IND TECH'!L1425 -> 0 | D1427: ='IND TECH'!A1425&" "&'IND TECH'!B1425&" "&'IND TECH'!C1425&" "&'IND TECH'!D1425&" "&'IND TECH'!E1425&" "&'IND TECH'!F1425&" "&'IND TECH'!G1425&" "&'IND TECH'!H1425 | E1427: =IF(F1427="Mlma","Mlm","TJ") -> #REF! | F1427: ='IND TECH'!#REF! -> #REF!
C1428: ='IND TECH'!L1426 -> 0 | D1428: ='IND TECH'!A1426&" "&'IND TECH'!B1426&" "&'IND TECH'!C1426&" "&'IND TECH'!D1426&" "&'IND TECH'!E1426&" "&'IND TECH'!F1426&" "&'IND TECH'!G1426&" "&'IND TECH'!H1426 | E1428: =IF(F1428="Mlma","Mlm","TJ") -> #REF! | F1428: ='IND TECH'!#REF! -> #REF!
C1429: ='IND TECH'!L1427 -> 0 | D1429: ='IND TECH'!A1427&" "&'IND TECH'!B1427&" "&'IND TECH'!C1427&" "&'IND TECH'!D1427&" "&'IND TECH'!E1427&" "&'IND TECH'!F1427&" "&'IND TECH'!G1427&" "&'IND TECH'!H1427 | E1429: =IF(F1429="Mlma","Mlm","TJ") -> #REF! | F1429: ='IND TECH'!#REF! -> #REF!
C1430: ='IND TECH'!L1428 -> 0 | D1430: ='IND TECH'!A1428&" "&'IND TECH'!B1428&" "&'IND TECH'!C1428&" "&'IND TECH'!D1428&" "&'IND TECH'!E1428&" "&'IND TECH'!F1428&" "&'IND TECH'!G1428&" "&'IND TECH'!H1428 | E1430: =IF(F1430="Mlma","Mlm","TJ") -> #REF! | F1430: ='IND TECH'!#REF! -> #REF!
C1431: ='IND TECH'!L1429 -> 0 | D1431: ='IND TECH'!A1429&" "&'IND TECH'!B1429&" "&'IND TECH'!C1429&" "&'IND TECH'!D1429&" "&'IND TECH'!E1429&" "&'IND TECH'!F1429&" "&'IND TECH'!G1429&" "&'IND TECH'!H1429 | E1431: =IF(F1431="Mlma","Mlm","TJ") -> #REF! | F1431: ='IND TECH'!#REF! -> #REF!
C1432: ='IND TECH'!L1430 -> 0 | D1432: ='IND TECH'!A1430&" "&'IND TECH'!B1430&" "&'IND TECH'!C1430&" "&'IND TECH'!D1430&" "&'IND TECH'!E1430&" "&'IND TECH'!F1430&" "&'IND TECH'!G1430&" "&'IND TECH'!H1430 | E1432: =IF(F1432="Mlma","Mlm","TJ") -> #REF! | F1432: ='IND TECH'!#REF! -> #REF!
C1433: ='IND TECH'!L1431 -> 0 | D1433: ='IND TECH'!A1431&" "&'IND TECH'!B1431&" "&'IND TECH'!C1431&" "&'IND TECH'!D1431&" "&'IND TECH'!E1431&" "&'IND TECH'!F1431&" "&'IND TECH'!G1431&" "&'IND TECH'!H1431 | E1433: =IF(F1433="Mlma","Mlm","TJ") -> #REF! | F1433: ='IND TECH'!#REF! -> #REF!
C1434: ='IND TECH'!L1432 -> 0 | D1434: ='IND TECH'!A1432&" "&'IND TECH'!B1432&" "&'IND TECH'!C1432&" "&'IND TECH'!D1432&" "&'IND TECH'!E1432&" "&'IND TECH'!F1432&" "&'IND TECH'!G1432&" "&'IND TECH'!H1432 | E1434: =IF(F1434="Mlma","Mlm","TJ") -> #REF! | F1434: ='IND TECH'!#REF! -> #REF!
C1435: ='IND TECH'!L1433 -> 0 | D1435: ='IND TECH'!A1433&" "&'IND TECH'!B1433&" "&'IND TECH'!C1433&" "&'IND TECH'!D1433&" "&'IND TECH'!E1433&" "&'IND TECH'!F1433&" "&'IND TECH'!G1433&" "&'IND TECH'!H1433 | E1435: =IF(F1435="Mlma","Mlm","TJ") -> #REF! | F1435: ='IND TECH'!#REF! -> #REF!
C1436: ='IND TECH'!L1434 -> 0 | D1436: ='IND TECH'!A1434&" "&'IND TECH'!B1434&" "&'IND TECH'!C1434&" "&'IND TECH'!D1434&" "&'IND TECH'!E1434&" "&'IND TECH'!F1434&" "&'IND TECH'!G1434&" "&'IND TECH'!H1434 | E1436: =IF(F1436="Mlma","Mlm","TJ") -> #REF! | F1436: ='IND TECH'!#REF! -> #REF!
C1437: ='IND TECH'!L1435 -> 0 | D1437: ='IND TECH'!A1435&" "&'IND TECH'!B1435&" "&'IND TECH'!C1435&" "&'IND TECH'!D1435&" "&'IND TECH'!E1435&" "&'IND TECH'!F1435&" "&'IND TECH'!G1435&" "&'IND TECH'!H1435 | E1437: =IF(F1437="Mlma","Mlm","TJ") -> #REF! | F1437: ='IND TECH'!#REF! -> #REF!
C1438: ='IND TECH'!L1436 -> 0 | D1438: ='IND TECH'!A1436&" "&'IND TECH'!B1436&" "&'IND TECH'!C1436&" "&'IND TECH'!D1436&" "&'IND TECH'!E1436&" "&'IND TECH'!F1436&" "&'IND TECH'!G1436&" "&'IND TECH'!H1436 | E1438: =IF(F1438="Mlma","Mlm","TJ") -> #REF! | F1438: ='IND TECH'!#REF! -> #REF!
C1439: ='IND TECH'!L1437 -> 0 | D1439: ='IND TECH'!A1437&" "&'IND TECH'!B1437&" "&'IND TECH'!C1437&" "&'IND TECH'!D1437&" "&'IND TECH'!E1437&" "&'IND TECH'!F1437&" "&'IND TECH'!G1437&" "&'IND TECH'!H1437 | E1439: =IF(F1439="Mlma","Mlm","TJ") -> #REF! | F1439: ='IND TECH'!#REF! -> #REF!
... C2850: ='IND TECH'!L2848 -> 0 | D2850: ='IND TECH'!A2848&" "&'IND TECH'!B2848&" "&'IND TECH'!C2848&" "&'IND TECH'!D2848&" "&'IND TECH'!E2848&" "&'IND TECH'!F2848&" "&'IND TECH'!G2848&" "&'IND TECH'!H2848 | E2850: =IF(F2850="Mlma","Mlm","TJ") -> #REF! | F2850: ='IND TECH'!#REF! -> #REF!
B2851: * | C2851: ='IND TECH'!L2849 -> 0
B2852: PRE | C2852: ='IND TECH'!L2850 -> 0 | D2852: ='IND TECH'!A2850&" "&'IND TECH'!B2850&" "&'IND TECH'!C2850&" "&'IND TECH'!D2850&" "&'IND TECH'!E2850&" "&'IND TECH'!F2850&" "&'IND TECH'!G2850&" "&'IND TECH'!H2850 | E2852: =IF(F2852="Mlma","Mlm","TJ") -> #REF! | F2852: ='IND TECH'!#REF! -> #REF!
C2853: ='IND TECH'!L2851 -> 0 | D2853: ='IND TECH'!A2851&" "&'IND TECH'!B2851&" "&'IND TECH'!C2851&" "&'IND TECH'!D2851&" "&'IND TECH'!E2851&" "&'IND TECH'!F2851&" "&'IND TECH'!G2851&" "&'IND TECH'!H2851 | E2853: =IF(F2853="Mlma","Mlm","TJ") -> #REF! | F2853: ='IND TECH'!#REF! -> #REF!
C2854: ='IND TECH'!L2852 -> 0 | D2854: ='IND TECH'!A2852&" "&'IND TECH'!B2852&" "&'IND TECH'!C2852&" "&'IND TECH'!D2852&" "&'IND TECH'!E2852&" "&'IND TECH'!F2852&" "&'IND TECH'!G2852&" "&'IND TECH'!H2852 | E2854: =IF(F2854="Mlma","Mlm","TJ") -> #REF! | F2854: ='IND TECH'!#REF! -> #REF!
C2855: ='IND TECH'!L2853 -> 0 | D2855: ='IND TECH'!A2853&" "&'IND TECH'!B2853&" "&'IND TECH'!C2853&" "&'IND TECH'!D2853&" "&'IND TECH'!E2853&" "&'IND TECH'!F2853&" "&'IND TECH'!G2853&" "&'IND TECH'!H2853 | E2855: =IF(F2855="Mlma","Mlm","TJ") -> #REF! | F2855: ='IND TECH'!#REF! -> #REF!
C2856: ='IND TECH'!L2854 -> 0 | D2856: ='IND TECH'!A2854&" "&'IND TECH'!B2854&" "&'IND TECH'!C2854&" "&'IND TECH'!D2854&" "&'IND TECH'!E2854&" "&'IND TECH'!F2854&" "&'IND TECH'!G2854&" "&'IND TECH'!H2854 | E2856: =IF(F2856="Mlma","Mlm","TJ") -> #REF! | F2856: ='IND TECH'!#REF! -> #REF!
C2857: ='IND TECH'!L2855 -> 0 | D2857: ='IND TECH'!A2855&" "&'IND TECH'!B2855&" "&'IND TECH'!C2855&" "&'IND TECH'!D2855&" "&'IND TECH'!E2855&" "&'IND TECH'!F2855&" "&'IND TECH'!G2855&" "&'IND TECH'!H2855 | E2857: =IF(F2857="Mlma","Mlm","TJ") -> #REF! | F2857: ='IND TECH'!#REF! -> #REF!
C2858: ='IND TECH'!L2856 -> 0 | D2858: ='IND TECH'!A2856&" "&'IND TECH'!B2856&" "&'IND TECH'!C2856&" "&'IND TECH'!D2856&" "&'IND TECH'!E2856&" "&'IND TECH'!F2856&" "&'IND TECH'!G2856&" "&'IND TECH'!H2856 | E2858: =IF(F2858="Mlma","Mlm","TJ") -> #REF! | F2858: ='IND TECH'!#REF! -> #REF!
C2859: ='IND TECH'!L2857 -> 0 | D2859: ='IND TECH'!A2857&" "&'IND TECH'!B2857&" "&'IND TECH'!C2857&" "&'IND TECH'!D2857&" "&'IND TECH'!E2857&" "&'IND TECH'!F2857&" "&'IND TECH'!G2857&" "&'IND TECH'!H2857 | E2859: =IF(F2859="Mlma","Mlm","TJ") -> #REF! | F2859: ='IND TECH'!#REF! -> #REF!
...

Sheet Def_Comm
B2: ~FI_Comm
B3: Csets | C3: CommName | D3: CommDesc | E3: Unit | F3: LimType | G3: CTSLvl | H3: PeakTS | I3: Ctype
B4: *Commodity Set Membership | C4: Commodity Name | D4: Commodity Description | E4: Unit | F4: Sense of the Balance EQN. | G4: Timeslice Level | H4: Peak Monitoring | I4: Electricity Indicator
C5: ='IND TECH'!J15 -> INDRET | D5: Industrial Retrofit potential | E5: TJ

Sheet TECH IND
D4: ~FI_T
B5: TechName | C5: Comm-IN | D5: Comm-OUT | E5: NCAP_START | F5: NCAP_TLIFE | G5: EFF | H5: PRC_CAPACT | I5: NCAP_AFA | J5: NCAP_AFA~LO | K5: NCAP_COST | L5: NCAP_FOM
B6: * | F6: Yr | G6: Out/In | H6: TJ/MW | I6: % | J6: % | K6: $ /kW | L6: $ /kW / Yr
B7: =IF('IND TECH'!Q3=1,'IND TECH'!L3,"*") -> INDAINAEUCOA20 | C7: =_xlfn.XLOOKUP(B7,'IND TECH'!L:L,'IND TECH'!J:J) -> INDCOA | D7: =_xlfn.XLOOKUP(B7,'IND TECH'!L:L,'IND TECH'!K:K) -> INDAINDMD | E7: ='City characteristics'!$C$20+1 -> 2020 | F7: 25 | G7: =_xlfn.XLOOKUP(B7,'IND TECH'!L:L,'IND TECH'!M:M) -> 1 | H7: =_xlfn.XLOOKUP(B7,'IND TECH'!L:L,'IND TECH'!O:O) -> 31.536 | I7: =_xlfn.XLOOKUP(B7,'IND TECH'!L:L,'IND TECH'!N:N) -> 0.9 | J7: =I7*0.9 -> 0.81 | K7: =_xlfn.XLOOKUP(B7,'IND TECH'!L:L,'IND TECH'!P:P) -> 1000 | L7: =5%*K7 -> 50
B8: =IF('IND TECH'!Q4=1,'IND TECH'!L4,"*") -> INDAINAEUPCK20 | C8: =_xlfn.XLOOKUP(B8,'IND TECH'!L:L,'IND TECH'!J:J) -> INDPCK | D8: =_xlfn.XLOOKUP(B8,'IND TECH'!L:L,'IND TECH'!K:K) -> INDAINDMD | E8: ='City characteristics'!$C$20+1 -> 2020 | F8: 25 | G8: =_xlfn.XLOOKUP(B8,'IND TECH'!L:L,'IND TECH'!M:M) -> 1 | H8: =_xlfn.XLOOKUP(B8,'IND TECH'!L:L,'IND TECH'!O:O) -> 31.536 | I8: =_xlfn.XLOOKUP(B8,'IND TECH'!L:L,'IND TECH'!N:N) -> 0.9 | J8: =I8*0.9 -> 0.81 | K8: =_xlfn.XLOOKUP(B8,'IND TECH'!L:L,'IND TECH'!P:P) -> 1000 | L8: =5%*K8 -> 50
B9: =IF('IND TECH'!Q5=1,'IND TECH'!L5,"*") -> INDAINAEULPG20 | C9: =_xlfn.XLOOKUP(B9,'IND TECH'!L:L,'IND TECH'!J:J) -> INDLPG | D9: =_xlfn.XLOOKUP(B9,'IND TECH'!L:L,'IND TECH'!K:K) -> INDAINDMD | E9: ='City characteristics'!$C$20+1 -> 2020 | F9: 25 | G9: =_xlfn.XLOOKUP(B9,'IND TECH'!L:L,'IND TECH'!M:M) -> 1 | H9: =_xlfn.XLOOKUP(B9,'IND TECH'!L:L,'IND TECH'!O:O) -> 31.536 | I9: =_xlfn.XLOOKUP(B9,'IND TECH'!L:L,'IND TECH'!N:N) -> 0.9 | J9: =I9*0.9 -> 0.81 | K9: =_xlfn.XLOOKUP(B9,'IND TECH'!L:L,'IND TECH'!P:P) -> 1000 | L9: =5%*K9 -> 50
B10: =IF('IND TECH'!Q6=1,'IND TECH'!L6,"*") -> INDAINAEUFOI20 | C10: =_xlfn.XLOOKUP(B10,'IND TECH'!L:L,'IND TECH'!J:J) -> INDFOI | D10: =_xlfn.XLOOKUP(B10,'IND TECH'!L:L,'IND TECH'!K:K) -> INDAINDMD | E10: ='City characteristics'!$C$20+1 -> 2020 | F10: 25 | G10: =_xlfn.XLOOKUP(B10,'IND TECH'!L:L,'IND TECH'!M:M) -> 1 | H10: =_xlfn.XLOOKUP(B10,'IND TECH'!L:L,'IND TECH'!O:O) -> 31.536 | I10: =_xlfn.XLOOKUP(B10,'IND TECH'!L:L,'IND TECH'!N:N) -> 0.9 | J10: =I10*0.9 -> 0.81 | K10: =_xlfn.XLOOKUP(B10,'IND TECH'!L:L,'IND TECH'!P:P) -> 1000 | L10: =5%*K10 -> 50
B11: =IF('IND TECH'!Q7=1,'IND TECH'!L7,"*") -> INDAINAEUNGA20 | C11: =_xlfn.XLOOKUP(B11,'IND TECH'!L:L,'IND TECH'!J:J) -> INDNGA | D11: =_xlfn.XLOOKUP(B11,'IND TECH'!L:L,'IND TECH'!K:K) -> INDAINDMD | E11: ='City characteristics'!$C$20+1 -> 2020 | F11: 25 | G11: =_xlfn.XLOOKUP(B11,'IND TECH'!L:L,'IND TECH'!M:M) -> 1 | H11: =_xlfn.XLOOKUP(B11,'IND TECH'!L:L,'IND TECH'!O:O) -> 31.536 | I11: =_xlfn.XLOOKUP(B11,'IND TECH'!L:L,'IND TECH'!N:N) -> 0.9 | J11: =I11*0.9 -> 0.81 | K11: =_xlfn.XLOOKUP(B11,'IND TECH'!L:L,'IND TECH'!P:P) -> 1000 | L11: =5%*K11 -> 50
B12: =IF('IND TECH'!Q8=1,'IND TECH'!L8,"*") -> INDAINAEURNG20 | C12: =_xlfn.XLOOKUP(B12,'IND TECH'!L:L,'IND TECH'!J:J) -> INDRNG | D12: =_xlfn.XLOOKUP(B12,'IND TECH'!L:L,'IND TECH'!K:K) -> INDAINDMD | E12: ='City characteristics'!$C$20+1 -> 2020 | F12: 25 | G12: =_xlfn.XLOOKUP(B12,'IND TECH'!L:L,'IND TECH'!M:M) -> 1 | H12: =_xlfn.XLOOKUP(B12,'IND TECH'!L:L,'IND TECH'!O:O) -> 31.536 | I12: =_xlfn.XLOOKUP(B12,'IND TECH'!L:L,'IND TECH'!N:N) -> 0.9 | J12: =I12*0.9 -> 0.81 | K12: =_xlfn.XLOOKUP(B12,'IND TECH'!L:L,'IND TECH'!P:P) -> 1000 | L12: =5%*K12 -> 50
B13: =IF('IND TECH'!Q9=1,'IND TECH'!L9,"*") -> INDAINAEUKER20 | C13: =_xlfn.XLOOKUP(B13,'IND TECH'!L:L,'IND TECH'!J:J) -> INDKER | D13: =_xlfn.XLOOKUP(B13,'IND TECH'!L:L,'IND TECH'!K:K) -> INDAINDMD | E13: ='City characteristics'!$C$20+1 -> 2020 | F13: 25 | G13: =_xlfn.XLOOKUP(B13,'IND TECH'!L:L,'IND TECH'!M:M) -> 1 | H13: =_xlfn.XLOOKUP(B13,'IND TECH'!L:L,'IND TECH'!O:O) -> 31.536 | I13: =_xlfn.XLOOKUP(B13,'IND TECH'!L:L,'IND TECH'!N:N) -> 0.9 | J13: =I13*0.9 -> 0.81 | K13: =_xlfn.XLOOKUP(B13,'IND TECH'!L:L,'IND TECH'!P:P) -> 1000 | L13: =5%*K13 -> 50
B14: =IF('IND TECH'!Q10=1,'IND TECH'!L10,"*") -> INDAINAEUGSL20 | C14: =_xlfn.XLOOKUP(B14,'IND TECH'!L:L,'IND TECH'!J:J) -> INDGSL | D14: =_xlfn.XLOOKUP(B14,'IND TECH'!L:L,'IND TECH'!K:K) -> INDAINDMD | E14: ='City characteristics'!$C$20+1 -> 2020 | F14: 25 | G14: =_xlfn.XLOOKUP(B14,'IND TECH'!L:L,'IND TECH'!M:M) -> 1 | H14: =_xlfn.XLOOKUP(B14,'IND TECH'!L:L,'IND TECH'!O:O) -> 31.536 | I14: =_xlfn.XLOOKUP(B14,'IND TECH'!L:L,'IND TECH'!N:N) -> 0.9 | J14: =I14*0.9 -> 0.81 | K14: =_xlfn.XLOOKUP(B14,'IND TECH'!L:L,'IND TECH'!P:P) -> 1000 | L14: =5%*K14 -> 50
B15: =IF('IND TECH'!Q11=1,'IND TECH'!L11,"*") -> INDAINAEUDSL20 | C15: =_xlfn.XLOOKUP(B15,'IND TECH'!L:L,'IND TECH'!J:J) -> INDDSL | D15: =_xlfn.XLOOKUP(B15,'IND TECH'!L:L,'IND TECH'!K:K) -> INDAINDMD | E15: ='City characteristics'!$C$20+1 -> 2020 | F15: 25 | G15: =_xlfn.XLOOKUP(B15,'IND TECH'!L:L,'IND TECH'!M:M) -> 1 | H15: =_xlfn.XLOOKUP(B15,'IND TECH'!L:L,'IND TECH'!O:O) -> 31.536 | I15: =_xlfn.XLOOKUP(B15,'IND TECH'!L:L,'IND TECH'!N:N) -> 0.9 | J15: =I15*0.9 -> 0.81 | K15: =_xlfn.XLOOKUP(B15,'IND TECH'!L:L,'IND TECH'!P:P) -> 1000 | L15: =5%*K15 -> 50
B16: =IF('IND TECH'!Q12=1,'IND TECH'!L12,"*") -> INDAINAEUELC20 | C16: =_xlfn.XLOOKUP(B16,'IND TECH'!L:L,'IND TECH'!J:J) -> INDELC | D16: =_xlfn.XLOOKUP(B16,'IND TECH'!L:L,'IND TECH'!K:K) -> INDAINDMD | E16: ='City characteristics'!$C$20+1 -> 2020 | F16: 25 | G16: =_xlfn.XLOOKUP(B16,'IND TECH'!L:L,'IND TECH'!M:M) -> 1 | H16: =_xlfn.XLOOKUP(B16,'IND TECH'!L:L,'IND TECH'!O:O) -> 31.536 | I16: =_xlfn.XLOOKUP(B16,'IND TECH'!L:L,'IND TECH'!N:N) -> 0.9 | J16: =I16*0.9 -> 0.81 | K16: =_xlfn.XLOOKUP(B16,'IND TECH'!L:L,'IND TECH'!P:P) -> 1000 | L16: =5%*K16 -> 50
B17: =IF('IND TECH'!Q13=1,'IND TECH'!L13,"*") -> INDAINAEUH2G20 | C17: =_xlfn.XLOOKUP(B17,'IND TECH'!L:L,'IND TECH'!J:J) -> INDH2G | D17: =_xlfn.XLOOKUP(B17,'IND TECH'!L:L,'IND TECH'!K:K) -> INDAINDMD | E17: ='City characteristics'!$C$20+1 -> 2020 | F17: 25 | G17: =_xlfn.XLOOKUP(B17,'IND TECH'!L:L,'IND TECH'!M:M) -> 1 | H17: =_xlfn.XLOOKUP(B17,'IND TECH'!L:L,'IND TECH'!O:O) -> 31.536 | I17: =_xlfn.XLOOKUP(B17,'IND TECH'!L:L,'IND TECH'!N:N) -> 0.9 | J17: =I17*0.9 -> 0.81 | K17: =_xlfn.XLOOKUP(B17,'IND TECH'!L:L,'IND TECH'!P:P) -> 1000 | L17: =5%*K17 -> 50
B18: =IF('IND TECH'!Q14=1,'IND TECH'!L14,"*") -> *
B19: =IF('IND TECH'!Q15=1,'IND TECH'!L15,"*") -> INDAINAEURET20 | C19: =_xlfn.XLOOKUP(B19,'IND TECH'!L:L,'IND TECH'!J:J) -> INDRET | D19: =_xlfn.XLOOKUP(B19,'IND TECH'!L:L,'IND TECH'!K:K) -> INDAINDMD | E19: ='City characteristics'!$C$20+1 -> 2020 | F19: 25 | G19: =_xlfn.XLOOKUP(B19,'IND TECH'!L:L,'IND TECH'!M:M) -> 1 | H19: =_xlfn.XLOOKUP(B19,'IND TECH'!L:L,'IND TECH'!O:O) -> 31.536 | I19: =_xlfn.XLOOKUP(B19,'IND TECH'!L:L,'IND TECH'!N:N) -> 0.9 | J19: =I19*0.9 -> 0.81 | K19: =_xlfn.XLOOKUP(B19,'IND TECH'!L:L,'IND TECH'!P:P) -> 10000 | L19: =5%*K19 -> 500
E25: 0 | F25: 0.01 | G25: 0.05 | H25: 0.1 | I25: 0.15 | J25: 0.2 | K25: 0.25 | L25: 0.3 | M25: =L25 -> 0.3 | N25: =M25 -> 0.3 | O25: =N25 -> 0.3 | P25: =O25 -> 0.3 | Q25: =P25 -> 0.3 | R25: =Q25 -> 0.3 | S25: =R25 -> 0.3 | T25: =S25 -> 0.3 | ... V25: =U25 -> 0.3
E26: 2019 | F26: 2020 | G26: 2025 | H26: 2030 | I26: 2035 | J26: 2040 | K26: 2045 | L26: 2050 | M26: 2055 | N26: 2060 | O26: 2065 | P26: 2070 | Q26: 2075 | R26: 2080 | S26: 2085 | T26: 2090 | U26: 2095 | V26: 2100
E27: ACT_BND~UP | F27: ACT_BND~UP | G27: ACT_BND~UP | H27: ACT_BND~UP | I27: ACT_BND~UP | J27: ACT_BND~UP | K27: ACT_BND~UP | L27: ACT_BND~UP | M27: ACT_BND~UP | N27: ACT_BND~UP | O27: ACT_BND~UP | P27: ACT_BND~UP | Q27: ACT_BND~UP | R27: ACT_BND~UP | S27: ACT_BND~UP | T27: ACT_BND~UP | U27: ACT_BND~UP | V27: ACT_BND~UP
C29: ~FI_T
B30: TechName | C30: Comm-OUT | D30: ACT_COST | E30: =E27&"~"&E26 -> ACT_BND~UP~2019 | F30: =F27&"~"&F26 -> ACT_BND~UP~2020 | G30: =G27&"~"&G26 -> ACT_BND~UP~2025 | H30: =H27&"~"&H26 -> ACT_BND~UP~2030 | I30: =I27&"~"&I26 -> ACT_BND~UP~2035 | J30: =J27&"~"&J26 -> ACT_BND~UP~2040 | K30: =K27&"~"&K26 -> ACT_BND~UP~2045 | L30: =L27&"~"&L26 -> ACT_BND~UP~2050 | ... V30: =V27&"~"&V26 -> ACT_BND~UP~2100
B31: * | D31: k$/Mm2 | E31: TJ | F31: TJ | G31: TJ | H31: TJ | I31: TJ | J31: TJ | K31: TJ | L31: TJ | M31: TJ | N31: TJ | O31: TJ | P31: TJ | Q31: TJ | R31: TJ | S31: TJ | T31: TJ | U31: TJ | V31: TJ
B32: =Def_Tech!C18 -> INDAINAEURET20 | C32: =_xlfn.XLOOKUP(B32,'IND TECH'!L:L,'IND TECH'!K:K) -> INDAINDMD | D32: 1 | E32: =Demand!G34*E$25 -> 0 | F32: =Demand!H34*F$25 -> 680.5079 | G32: =Demand!I34*G$25 -> 3742.7935 | H32: =Demand!J34*H$25 -> 8234.1456 | I32: =Demand!K34*I$25 -> 13586.34 | J32: =Demand!L34*J$25 -> 19926.632 | K32: =Demand!M34*K$25 -> 27399.119 | L32: =Demand!N34*L$25 -> 36166.838 | ... V32: =Demand!X34*V$25 -> 93807.463
