Workbook

Sheet ReadMe
A1: Generic Comet (GC) TIMES Supply
B3: Sheet color
C4: Raw Data and Parameters
C6: City Specific Data
C8: Post processing for TIMES
C10: Table formatted for TIMES

Sheet >> City Data

Sheet City characteristics
B2: City Basic Data
B4: Calibration methodology | C4: GHG Inventory
B6: A. City Characteristics
B7: Data Item | C7: Value | D7: Units
B8: City Name | C8: New York
B9: Latitude | C9: 40.5
B10: Longitude | C10: -75
B11: County | C11: New York County
B12: State | C12: New York
B13: Census Division | C13: Middle Atlantic
B14: Climate Division | C14: Northeast
B15: Egrid Region | C15: NPCC NYC/Westchester
B16: Area of city (excluding water, natural and agricultural areas) | C16: 778 | D16: square kilometers
B17: * Division and Region Map can be found in the Maps sheet.
B18: B. Planning Base Year and Target Years
B19: Year | C19: Value | D19: Units
B20: Base Year | C20: 2019 | D20: Acceptable range [2018,2021]
B21: End Year | C21: 2050
B23: C. City Population and GDP
B24: Data Item | C24: Value | D24: Units
B25: Population in Base Year | C25: 8337 | D25: Thousand of people
B26: Annual population growth (Base Year - End Year) | C26: 0.5 | D26: % people
B27: GDP in Base Year | C27: 1206000 | D27: Million US$
B28: Annual GDP growth rate | C28: 2 | D28: % US$
B29: Share of manufacturing GDP | C29: 5 | D29: % US$
B30: Share of State population | C30: 0.42835123
B31: Share of State GDP | C31: 0.67251772
B32: Adjustment from state manufacturing GDP | C32: 1.0638298
B34: D. Climate Data
B35: Data Item | C35: 2000 | D35: 2050 | E35: 2100 | F35: Units
B36: Heating degree days (HDD) | C36: 4473.4625 | D36: 4066.4182 | E36: 3763.8582 | F36: F
B37: Cooling degree days (CDD) | C37: 1020.7333 | D37: 1224.2555 | E37: 1375.5355 | F37: F
B39: Data Item | C39: Value | D39: Units
B40: Correction from State HDD | C40: 0.72727402
B41: Correction from State CDD | C41: 1.5583715
B42: Annual precipitation | C42: 762 | D42: mm / year
B43: Climate change scenario | C43: RCP4.5
B44: Average temperature increase in 1980-2020 | C44: 1.4617857 | D44: F
B45: Forecasted average temperature increase in 2035-2065 | C45: 3.13 | D45: F
B46: Forecasted average temperature increase in 2070-2100 | C46: 4.37 | D46: F
...

Sheet >> GC_NewTech

Sheet ELC TECH
M1: 2021 | N1: 2025 | O1: 2030 | P1: 2035 | Q1: 2040 | R1: 2045 | S1: 2050 | T1: 2100 | U1: 2021 | V1: 2025 | W1: 2030 | X1: 2035 | Y1: 2040 | Z1: 2045 | AA1: 2050 | AB1: 2100 | AC1: 2021 | AD1: 2025 | AE1: 2030 | AF1: 2035 | AG1: 2040 | AH1: 2045 | AI1: 2050 | AJ1: 2100 | AK1: 2021 | AL1: 2025 | AM1: 2030 | AN1: 2035 | AO1: 2040 | AP1: 2045 | AQ1: 2050 | AR1: 2100 | AS1: 2021 | AT1: 2025 | AU1: 2030 | AV1: 2035 | AW1: 2040 | AX1: 2045 | AY1: 2050 | AZ1: 2100
M2: OCC | N2: OCC | O2: OCC | P2: OCC | Q2: OCC | R2: OCC | S2: OCC | T2: OCC | U2: Fixed O&M | V2: Fixed O&M | W2: Fixed O&M | X2: Fixed O&M | Y2: Fixed O&M | Z2: Fixed O&M | AA2: Fixed O&M | AB2: Fixed O&M | AC2: Variable O&M | AD2: Variable O&M | AE2: Variable O&M | AF2: Variable O&M | AG2: Variable O&M | AH2: Variable O&M | AI2: Variable O&M | AJ2: Variable O&M | AK2: Heat Rate | AL2: Heat Rate | AM2: Heat Rate | AN2: Heat Rate | AO2: Heat Rate | AP2: Heat Rate | AQ2: Heat Rate | AR2: Heat Rate | AS2: CF | AT2: CF | AU2: CF | AV2: CF | AW2: CF | AX2: CF | AY2: CF | AZ2: CF
A3: Sector | B3: Sub-sector | C3: Archetype | D3: Vintage | E3: End Use | F3: Technology | G3: Energy | H3: Technology Label | I3: To include | J3: Capacity Potential (MW) | K3: Lifetime (yr) | L3: Capacity2Activity | M3: ATB CAPEX 2023 US$ / kW | U3: ATB Fixed OM 2023 US$ / kW . Yr | AC3: ATB Variable OM 2023 US$ / GJ | AK3: ATB Efficiency (Mwh e /Mwh th) | AS3: ATB ANNUAL CF %
A4: Electricity | B4: Grid | D4: 2020 | E4: Dispatchable | F4: Hydro New-Stream Dispatchable Class 1 | G4: Hydro | H4: ELCHYDGRDHNSDC120 | I4: 1 | J4: 0 | K4: 100 | L4: 31.536 | M4: 8970.3682 | N4: 8970.3682 | O4: 8970.3682 | P4: 8970.3682 | Q4: 8970.3682 | R4: 8970.3682 | S4: 8970.3682 | T4: 8970.3682 | U4: 161.69957 | V4: 161.69957 | W4: 161.69957 | X4: 161.69957 | Y4: 161.69957 | Z4: 161.69957 | AA4: 161.69957 | AB4: 161.69957 | AS4: 0.66 | AT4: 0.66 | AU4: 0.66 | AV4: 0.66 | AW4: 0.66 | AX4: 0.66 | AY4: 0.66 | AZ4: 0.66
A5: Electricity | B5: Grid | D5: 2020 | E5: Dispatchable | F5: Hydro New-Stream Dispatchable Class 2 | G5: Hydro | H5: ELCHYDGRDHNSDC220 | I5: 1 | J5: 0 | K5: 100 | L5: 31.536 | M5: 8008.0862 | N5: 8008.0862 | O5: 8008.0862 | P5: 8008.0862 | Q5: 8008.0862 | R5: 8008.0862 | S5: 8008.0862 | T5: 8008.0862 | U5: 53.146011 | V5: 53.146011 | W5: 53.146011 | X5: 53.146011 | Y5: 53.146011 | Z5: 53.146011 | AA5: 53.146011 | AB5: 53.146011 | AS5: 0.66 | AT5: 0.66 | AU5: 0.66 | AV5: 0.66 | AW5: 0.66 | AX5: 0.66 | AY5: 0.66 | AZ5: 0.66
A6: Electricity | B6: Grid | D6: 2020 | E6: Dispatchable | F6: Hydro New-Stream Dispatchable Class 3 | G6: Hydro | H6: ELCHYDGRDHNSDC320 | I6: 1 | J6: 0 | K6: 100 | L6: 31.536 | M6: 7842.9943 | N6: 7842.9943 | O6: 7842.9943 | P6: 7842.9943 | Q6: 7842.9943 | R6: 7842.9943 | S6: 7842.9943 | T6: 7842.9943 | U6: 152.65344 | V6: 152.65344 | W6: 152.65344 | X6: 152.65344 | Y6: 152.65344 | Z6: 152.65344 | AA6: 152.65344 | AB6: 152.65344 | AS6: 0.62 | AT6: 0.62 | AU6: 0.62 | AV6: 0.62 | AW6: 0.62 | AX6: 0.62 | AY6: 0.62 | AZ6: 0.62
A7: Electricity | B7: Grid | D7: 2020 | E7: Dispatchable | F7: Hydro New-Stream Dispatchable Class 4 | G7: Hydro | H7: ELCHYDGRDHNSDC420 | I7: 1 | J7: 0 | K7: 100 | L7: 31.536 | M7: 7060.5041 | N7: 7060.5041 | O7: 7060.5041 | P7: 7060.5041 | Q7: 7060.5041 | R7: 7060.5041 | S7: 7060.5041 | T7: 7060.5041 | U7: 37.315284 | V7: 37.315284 | W7: 37.315284 | X7: 37.315284 | Y7: 37.315284 | Z7: 37.315284 | AA7: 37.315284 | AB7: 37.315284 | AS7: 0.66 | AT7: 0.66 | AU7: 0.66 | AV7: 0.66 | AW7: 0.66 | AX7: 0.66 | AY7: 0.66 | AZ7: 0.66
A8: Electricity | B8: Grid | D8: 2020 | E8: Dispatchable | F8: Hydro New-Stream Dispatchable Class 5 | G8: Hydro | H8: ELCHYDGRDHNSDC520 | I8: 1 | J8: 0 | K8: 100 | L8: 31.536 | M8: 7060.5041 | N8: 7060.5041 | O8: 7060.5041 | P8: 7060.5041 | Q8: 7060.5041 | R8: 7060.5041 | S8: 7060.5041 | T8: 7060.5041 | U8: 37.315284 | V8: 37.315284 | W8: 37.315284 | X8: 37.315284 | Y8: 37.315284 | Z8: 37.315284 | AA8: 37.315284 | AB8: 37.315284 | AS8: 0.66 | AT8: 0.66 | AU8: 0.66 | AV8: 0.66 | AW8: 0.66 | AX8: 0.66 | AY8: 0.66 | AZ8: 0.66
A9: Electricity | B9: Grid | D9: 2020 | E9: Non Dispatchable | F9: Hydro New-Stream Non Dispatchable Class 1 | G9: Hydro | H9: ELCHYDGRDHNSNDC120 | I9: 1 | J9: 0 | K9: 100 | L9: 31.536 | M9: 8970.3682 | N9: 8970.3682 | O9: 8970.3682 | P9: 8970.3682 | Q9: 8970.3682 | R9: 8970.3682 | S9: 8970.3682 | T9: 8970.3682 | U9: 161.69957 | V9: 161.69957 | W9: 161.69957 | X9: 161.69957 | Y9: 161.69957 | Z9: 161.69957 | AA9: 161.69957 | AB9: 161.69957 | AS9: 0.66 | AT9: 0.66 | AU9: 0.66 | AV9: 0.66 | AW9: 0.66 | AX9: 0.66 | AY9: 0.66 | AZ9: 0.66
A10: Electricity | B10: Grid | D10: 2020 | E10: Non Dispatchable | F10: Hydro New-Stream Non Dispatchable Class 2 | G10: Hydro | H10: ELCHYDGRDHNSNDC220 | I10: 1 | J10: 0 | K10: 100 | L10: 31.536 | M10: 8008.0862 | N10: 8008.0862 | O10: 8008.0862 | P10: 8008.0862 | Q10: 8008.0862 | R10: 8008.0862 | S10: 8008.0862 | T10: 8008.0862 | U10: 53.146011 | V10: 53.146011 | W10: 53.146011 | X10: 53.146011 | Y10: 53.146011 | Z10: 53.146011 | AA10: 53.146011 | AB10: 53.146011 | AS10: 0.66 | AT10: 0.66 | AU10: 0.66 | AV10: 0.66 | AW10: 0.66 | AX10: 0.66 | AY10: 0.66 | AZ10: 0.66
A11: Electricity | B11: Grid | D11: 2020 | E11: Non Dispatchable | F11: Hydro New-Stream Non Dispatchable Class 3 | G11: Hydro | H11: ELCHYDGRDHNSNDC320 | I11: 1 | J11: 0 | K11: 100 | L11: 31.536 | M11: 7842.9943 | N11: 7842.9943 | O11: 7842.9943 | P11: 7842.9943 | Q11: 7842.9943 | R11: 7842.9943 | S11: 7842.9943 | T11: 7842.9943 | U11: 152.65344 | V11: 152.65344 | W11: 152.65344 | X11: 152.65344 | Y11: 152.65344 | Z11: 152.65344 | AA11: 152.65344 | AB11: 152.65344 | AS11: 0.62 | AT11: 0.62 | AU11: 0.62 | AV11: 0.62 | AW11: 0.62 | AX11: 0.62 | AY11: 0.62 | AZ11: 0.62
A12: Electricity | B12: Grid | D12: 2020 | E12: Non Dispatchable | F12: Hydro New-Stream Non Dispatchable Class 4 | G12: Hydro | H12: ELCHYDGRDHNSNDC420 | I12: 1 | J12: 0 | K12: 100 | L12: 31.536 | M12: 7060.5041 | N12: 7060.5041 | O12: 7060.5041 | P12: 7060.5041 | Q12: 7060.5041 | R12: 7060.5041 | S12: 7060.5041 | T12: 7060.5041 | U12: 37.315284 | V12: 37.315284 | W12: 37.315284 | X12: 37.315284 | Y12: 37.315284 | Z12: 37.315284 | AA12: 37.315284 | AB12: 37.315284 | AS12: 0.66 | AT12: 0.66 | AU12: 0.66 | AV12: 0.66 | AW12: 0.66 | AX12: 0.66 | AY12: 0.66 | AZ12: 0.66
A13: Electricity | B13: Grid | D13: 2020 | E13: Non Dispatchable | F13: Hydro New-Stream Non Dispatchable Class 5 | G13: Hydro | H13: ELCHYDGRDHNSNDC520 | I13: 1 | J13: 0 | K13: 100 | L13: 31.536 | M13: 7060.5041 | N13: 7060.5041 | O13: 7060.5041 | P13: 7060.5041 | Q13: 7060.5041 | R13: 7060.5041 | S13: 7060.5041 | T13: 7060.5041 | U13: 37.315284 | V13: 37.315284 | W13: 37.315284 | X13: 37.315284 | Y13: 37.315284 | Z13: 37.315284 | AA13: 37.315284 | AB13: 37.315284 | AS13: 0.66 | AT13: 0.66 | AU13: 0.66 | AV13: 0.66 | AW13: 0.66 | AX13: 0.66 | AY13: 0.66 | AZ13: 0.66
A14: Electricity | B14: Grid | D14: 2020 | E14: Non Dispatchable | F14: Hydro Non-Powered Non Dispatchable Class 1 | G14: Hydro | H14: ELCHYDGRDHNPNDC120 | I14: 1 | J14: 0 | K14: 100 | L14: 31.536 | M14: 3188.7607 | N14: 3188.7607 | O14: 3188.7607 | P14: 3188.7607 | Q14: 3060.9841 | R14: 3060.9841 | S14: 3060.9841 | T14: 3060.9841 | U14: 96.115126 | V14: 96.115126 | W14: 96.115126 | X14: 96.115126 | Y14: 92.722828 | Z14: 92.722828 | AA14: 92.722828 | AB14: 92.722828 | AS14: 0.33 | AT14: 0.33 | AU14: 0.33 | AV14: 0.33 | AW14: 0.33 | AX14: 0.33 | AY14: 0.33 | AZ14: 0.33
A15: Electricity | B15: Grid | D15: 2020 | E15: Non Dispatchable | F15: Hydro Non-Powered Non Dispatchable Class 2 | G15: Hydro | H15: ELCHYDGRDHNPNDC220 | I15: 1 | J15: 0 | K15: 100 | L15: 31.536 | M15: 6253.137 | N15: 6253.137 | O15: 4777.4871 | P15: 3300.7065 | Q15: 3168.4069 | R15: 3168.4069 | S15: 3168.4069 | T15: 3168.4069 | U15: 98.376658 | V15: 98.376658 | W15: 98.376658 | X15: 98.376658 | Y15: 93.853594 | Z15: 93.853594 | AA15: 93.853594 | AB15: 93.853594 | AS15: 0.41 | AT15: 0.41 | AU15: 0.38 | AV15: 0.38 | AW15: 0.38 | AX15: 0.38 | AY15: 0.38 | AZ15: 0.38
... A28: Electricity | B28: Grid | D28: 2020 | E28: Non Dispatchable | F28: Hydro Upgrade Non Dispatchable Class 5 | G28: Hydro | H28: ELCHYDGRDHUPNDC520 | I28: 1 | J28: 0 | K28: 100 | L28: 31.536 | M28: 14006.801 | N28: 14006.801 | O28: 11382.292 | P28: 8758.9149 | Q28: 8408.3774 | R28: 8408.3774 | S28: 8408.3774 | T28: 8408.3774 | U28: 196.75332 | V28: 196.75332 | W28: 196.75332 | X28: 196.75332 | Y28: 188.83795 | Z28: 188.83795 | AA28: 188.83795 | AB28: 188.83795 | AS28: 0.38 | AT28: 0.38 | AU28: 0.38 | AV28: 0.38 | AW28: 0.38 | AX28: 0.38 | AY28: 0.38 | AZ28: 0.38
A29: Electricity | B29: Grid | D29: 2020 | E29: Storage | F29: Pumped Hydro 12h Class 1 | G29: Storage | H29: ELCSTGGRDPSH12HC120 | I29: 1 | J29: 0 | K29: 100 | L29: 31.536 | M29: 2385.0938 | N29: 2385.0938 | O29: 2385.0938 | P29: 2385.0938 | Q29: 2385.0938 | R29: 2385.0938 | S29: 2385.0938 | T29: 2385.0938 | U29: 21.100097 | V29: 21.100097 | W29: 21.100097 | X29: 21.100097 | Y29: 21.100097 | Z29: 21.100097 | AA29: 21.100097 | AB29: 21.100097 | AC29: 0.16961493 | AD29: 0.16961493 | AE29: 0.16961493 | AF29: 0.16961493 | AG29: 0.16961493 | AH29: 0.16961493 | AI29: 0.16961493 | AJ29: 0.16961493 | AS29: 0.5 | AT29: 0.5 | AU29: 0.5 | AV29: 0.5 | AW29: 0.5 | AX29: 0.5 | AY29: 0.5 | AZ29: 0.5
A30: Electricity | B30: Grid | D30: 2020 | E30: Storage | F30: Pumped Hydro 12h Class 2 | G30: Storage | H30: ELCSTGGRDPSH12HC220 | I30: 1 | J30: 0 | K30: 100 | L30: 31.536 | M30: 2703.9531 | N30: 2703.9531 | O30: 2703.9531 | P30: 2703.9531 | Q30: 2703.9531 | R30: 2703.9531 | S30: 2703.9531 | T30: 2703.9531 | U30: 21.100097 | V30: 21.100097 | W30: 21.100097 | X30: 21.100097 | Y30: 21.100097 | Z30: 21.100097 | AA30: 21.100097 | AB30: 21.100097 | AC30: 0.16961493 | AD30: 0.16961493 | AE30: 0.16961493 | AF30: 0.16961493 | AG30: 0.16961493 | AH30: 0.16961493 | AI30: 0.16961493 | AJ30: 0.16961493 | AS30: 0.5 | AT30: 0.5 | AU30: 0.5 | AV30: 0.5 | AW30: 0.5 | AX30: 0.5 | AY30: 0.5 | AZ30: 0.5
A31: Electricity | B31: Grid | D31: 2020 | E31: Storage | F31: Pumped Hydro 12h Class 3 | G31: Storage | H31: ELCSTGGRDPSH12HC320 | I31: 1 | J31: 0 | K31: 100 | L31: 31.536 | M31: 2902.3052 | N31: 2902.3052 | O31: 2902.3052 | P31: 2902.3052 | Q31: 2902.3052 | R31: 2902.3052 | S31: 2902.3052 | T31: 2902.3052 | U31: 21.100097 | V31: 21.100097 | W31: 21.100097 | X31: 21.100097 | Y31: 21.100097 | Z31: 21.100097 | AA31: 21.100097 | AB31: 21.100097 | AC31: 0.16961493 | AD31: 0.16961493 | AE31: 0.16961493 | AF31: 0.16961493 | AG31: 0.16961493 | AH31: 0.16961493 | AI31: 0.16961493 | AJ31: 0.16961493 | AS31: 0.5 | AT31: 0.5 | AU31: 0.5 | AV31: 0.5 | AW31: 0.5 | AX31: 0.5 | AY31: 0.5 | AZ31: 0.5
A32: Electricity | B32: Grid | D32: 2020 | E32: Storage | F32: Pumped Hydro 12h Class 4 | G32: Storage | H32: ELCSTGGRDPSH12HC420 | I32: 1 | J32: 0 | K32: 100 | L32: 31.536 | M32: 3059.5593 | N32: 3059.5593 | O32: 3059.5593 | P32: 3059.5593 | Q32: 3059.5593 | R32: 3059.5593 | S32: 3059.5593 | T32: 3059.5593 | U32: 21.100097 | V32: 21.100097 | W32: 21.100097 | X32: 21.100097 | Y32: 21.100097 | Z32: 21.100097 | AA32: 21.100097 | AB32: 21.100097 | AC32: 0.16961493 | AD32: 0.16961493 | AE32: 0.16961493 | AF32: 0.16961493 | AG32: 0.16961493 | AH32: 0.16961493 | AI32: 0.16961493 | AJ32: 0.16961493 | AS32: 0.5 | AT32: 0.5 | AU32: 0.5 | AV32: 0.5 | AW32: 0.5 | AX32: 0.5 | AY32: 0.5 | AZ32: 0.5
A33: Electricity | B33: Grid | D33: 2020 | E33: Storage | F33: Pumped Hydro 12h Class 5 | G33: Storage | H33: ELCSTGGRDPSH12HC520 | I33: 1 | J33: 0 | K33: 100 | L33: 31.536 | M33: 3198.7824 | N33: 3198.7824 | O33: 3198.7824 | P33: 3198.7824 | Q33: 3198.7824 | R33: 3198.7824 | S33: 3198.7824 | T33: 3198.7824 | U33: 21.100097 | V33: 21.100097 | W33: 21.100097 | X33: 21.100097 | Y33: 21.100097 | Z33: 21.100097 | AA33: 21.100097 | AB33: 21.100097 | AC33: 0.16961493 | AD33: 0.16961493 | AE33: 0.16961493 | AF33: 0.16961493 | AG33: 0.16961493 | AH33: 0.16961493 | AI33: 0.16961493 | AJ33: 0.16961493 | AS33: 0.5 | AT33: 0.5 | AU33: 0.5 | AV33: 0.5 | AW33: 0.5 | AX33: 0.5 | AY33: 0.5 | AZ33: 0.5
A34: Electricity | B34: Grid | D34: 2020 | E34: Storage | F34: Pumped Hydro 12h Class 6 | G34: Storage | H34: ELCSTGGRDPSH12HC620 | I34: 1 | J34: 0 | K34: 100 | L34: 31.536 | M34: 3332.5121 | N34: 3332.5121 | O34: 3332.5121 | P34: 3332.5121 | Q34: 3332.5121 | R34: 3332.5121 | S34: 3332.5121 | T34: 3332.5121 | U34: 21.100097 | V34: 21.100097 | W34: 21.100097 | X34: 21.100097 | Y34: 21.100097 | Z34: 21.100097 | AA34: 21.100097 | AB34: 21.100097 | AC34: 0.16961493 | AD34: 0.16961493 | AE34: 0.16961493 | AF34: 0.16961493 | AG34: 0.16961493 | AH34: 0.16961493 | AI34: 0.16961493 | AJ34: 0.16961493 | AS34: 0.5 | AT34: 0.5 | AU34: 0.5 | AV34: 0.5 | AW34: 0.5 | AX34: 0.5 | AY34: 0.5 | AZ34: 0.5
A35: Electricity | B35: Grid | D35: 2020 | E35: Storage | F35: Pumped Hydro 12h Class 7 | G35: Storage | H35: ELCSTGGRDPSH12HC720 | I35: 1 | J35: 0 | K35: 100 | L35: 31.536 | M35: 3454.6144 | N35: 3454.6144 | O35: 3454.6144 | P35: 3454.6144 | Q35: 3454.6144 | R35: 3454.6144 | S35: 3454.6144 | T35: 3454.6144 | U35: 21.100097 | V35: 21.100097 | W35: 21.100097 | X35: 21.100097 | Y35: 21.100097 | Z35: 21.100097 | AA35: 21.100097 | AB35: 21.100097 | AC35: 0.16961493 | AD35: 0.16961493 | AE35: 0.16961493 | AF35: 0.16961493 | AG35: 0.16961493 | AH35: 0.16961493 | AI35: 0.16961493 | AJ35: 0.16961493 | AS35: 0.5 | AT35: 0.5 | AU35: 0.5 | AV35: 0.5 | AW35: 0.5 | AX35: 0.5 | AY35: 0.5 | AZ35: 0.5
A36: Electricity | B36: Grid | D36: 2020 | E36: Storage | F36: Pumped Hydro 12h Class 8 | G36: Storage | H36: ELCSTGGRDPSH12HC820 | I36: 1 | J36: 0 | K36: 100 | L36: 31.536 | M36: 3580.1996 | N36: 3580.1996 | O36: 3580.1996 | P36: 3580.1996 | Q36: 3580.1996 | R36: 3580.1996 | S36: 3580.1996 | T36: 3580.1996 | U36: 21.100097 | V36: 21.100097 | W36: 21.100097 | X36: 21.100097 | Y36: 21.100097 | Z36: 21.100097 | AA36: 21.100097 | AB36: 21.100097 | AC36: 0.16961493 | AD36: 0.16961493 | AE36: 0.16961493 | AF36: 0.16961493 | AG36: 0.16961493 | AH36: 0.16961493 | AI36: 0.16961493 | AJ36: 0.16961493 | AS36: 0.5 | AT36: 0.5 | AU36: 0.5 | AV36: 0.5 | AW36: 0.5 | AX36: 0.5 | AY36: 0.5 | AZ36: 0.5
A37: Electricity | B37: Grid | D37: 2020 | E37: Storage | F37: Pumped Hydro 12h Class 9 | G37: Storage | H37: ELCSTGGRDPSH12HC920 | I37: 1 | J37: 0 | K37: 100 | L37: 31.536 | M37: 3708.5882 | N37: 3708.5882 | O37: 3708.5882 | P37: 3708.5882 | Q37: 3708.5882 | R37: 3708.5882 | S37: 3708.5882 | T37: 3708.5882 | U37: 21.100097 | V37: 21.100097 | W37: 21.100097 | X37: 21.100097 | Y37: 21.100097 | Z37: 21.100097 | AA37: 21.100097 | AB37: 21.100097 | AC37: 0.16961493 | AD37: 0.16961493 | AE37: 0.16961493 | AF37: 0.16961493 | AG37: 0.16961493 | AH37: 0.16961493 | AI37: 0.16961493 | AJ37: 0.16961493 | AS37: 0.5 | AT37: 0.5 | AU37: 0.5 | AV37: 0.5 | AW37: 0.5 | AX37: 0.5 | AY37: 0.5 | AZ37: 0.5
A38: Electricity | B38: Grid | D38: 2020 | E38: Storage | F38: Pumped Hydro 12h Class 10 | G38: Storage | H38: ELCSTGGRDPSH12HC1020 | I38: 1 | J38: 0 | K38: 100 | L38: 31.536 | M38: 3847.159 | N38: 3847.159 | O38: 3847.159 | P38: 3847.159 | Q38: 3847.159 | R38: 3847.159 | S38: 3847.159 | T38: 3847.159 | U38: 21.100097 | V38: 21.100097 | W38: 21.100097 | X38: 21.100097 | Y38: 21.100097 | Z38: 21.100097 | AA38: 21.100097 | AB38: 21.100097 | AC38: 0.16961493 | AD38: 0.16961493 | AE38: 0.16961493 | AF38: 0.16961493 | AG38: 0.16961493 | AH38: 0.16961493 | AI38: 0.16961493 | AJ38: 0.16961493 | AS38: 0.5 | AT38: 0.5 | AU38: 0.5 | AV38: 0.5 | AW38: 0.5 | AX38: 0.5 | AY38: 0.5 | AZ38: 0.5
A39: Electricity | B39: Grid | D39: 2020 | E39: Storage | F39: Pumped Hydro 12h Class 11 | G39: Storage | H39: ELCSTGGRDPSH12HC1120 | I39: 1 | J39: 0 | K39: 100 | L39: 31.536 | M39: 3989.3388 | N39: 3989.3388 | O39: 3989.3388 | P39: 3989.3388 | Q39: 3989.3388 | R39: 3989.3388 | S39: 3989.3388 | T39: 3989.3388 | U39: 21.100097 | V39: 21.100097 | W39: 21.100097 | X39: 21.100097 | Y39: 21.100097 | Z39: 21.100097 | AA39: 21.100097 | AB39: 21.100097 | AC39: 0.16961493 | AD39: 0.16961493 | AE39: 0.16961493 | AF39: 0.16961493 | AG39: 0.16961493 | AH39: 0.16961493 | AI39: 0.16961493 | AJ39: 0.16961493 | AS39: 0.5 | AT39: 0.5 | AU39: 0.5 | AV39: 0.5 | AW39: 0.5 | AX39: 0.5 | AY39: 0.5 | AZ39: 0.5
A40: Electricity | B40: Grid | D40: 2020 | E40: Storage | F40: Pumped Hydro 12h Class 12 | G40: Storage | H40: ELCSTGGRDPSH12HC1220 | I40: 1 | J40: 0 | K40: 100 | L40: 31.536 | M40: 4141.3324 | N40: 4141.3324 | O40: 4141.3324 | P40: 4141.3324 | Q40: 4141.3324 | R40: 4141.3324 | S40: 4141.3324 | T40: 4141.3324 | U40: 21.100097 | V40: 21.100097 | W40: 21.100097 | X40: 21.100097 | Y40: 21.100097 | Z40: 21.100097 | AA40: 21.100097 | AB40: 21.100097 | AC40: 0.16961493 | AD40: 0.16961493 | AE40: 0.16961493 | AF40: 0.16961493 | AG40: 0.16961493 | AH40: 0.16961493 | AI40: 0.16961493 | AJ40: 0.16961493 | AS40: 0.5 | AT40: 0.5 | AU40: 0.5 | AV40: 0.5 | AW40: 0.5 | AX40: 0.5 | AY40: 0.5 | AZ40: 0.5
... A76: Electricity | B76: Grid | D76: 2020 | E76: Partly Dispatchable | F76: Concentrated Solar Class 3 | G76: Solar | H76: ELCSOLGRDCSPC320 | I76: 1 | J76: 0 | K76: 30 | L76: 31.536 | M76: 7714.0905 | N76: 6685.5451 | O76: 5399.8634 | P76: 5207.0111 | Q76: 5014.1588 | R76: 4821.3066 | S76: 4628.4543 | T76: 4628.4543 | U76: 78.138205 | V76: 69.456182 | W76: 58.603654 | X76: 58.603654 | Y76: 58.603654 | Z76: 58.603654 | AA76: 58.603654 | AB76: 58.603654 | AC76: 1.1510258 | AD76: 1.058261 | AE76: 0.94230516 | AF76: 0.94230516 | AG76: 0.94230516 | AH76: 0.94230516 | AI76: 0.94230516 | AJ76: 0.94230516 | AS76: 0.514 | AT76: 0.514 | AU76: 0.514 | AV76: 0.514 | AW76: 0.514 | AX76: 0.514 | AY76: 0.514 | AZ76: 0.514
A77: Electricity | B77: Grid | D77: 2020 | E77: Non Dispatchable | F77: Onshore Wind Turbine Class 1 | G77: Wind | H77: ELCWNDGRDWONC120 | I77: 1 | J77: 0 | K77: 30 | L77: 31.536 | M77: 1451.7715 | N77: 1350.9393 | O77: 1224.8989 | P77: 1164.5945 | Q77: 1104.2901 | R77: 1043.9857 | S77: 983.68133 | T77: 983.68133 | U77: 34.262216 | V77: 32.603758 | W77: 30.530687 | X77: 29.484728 | Y77: 28.43877 | Z77: 27.392811 | AA77: 26.346852 | AB77: 26.346852 | AS77: 0.49815 | AT77: 0.51345667 | AU77: 0.53259 | AV77: 0.5347425 | AW77: 0.536895 | AX77: 0.5390475 | AY77: 0.5412 | AZ77: 0.5412
A78: Electricity | B78: Grid | D78: 2020 | E78: Non Dispatchable | F78: Onshore Wind Turbine Class 2 | G78: Wind | H78: ELCWNDGRDWONC220 | I78: 1 | J78: 0 | K78: 30 | L78: 31.536 | M78: 1451.7715 | N78: 1350.9393 | O78: 1224.8989 | P78: 1164.5945 | Q78: 1104.2901 | R78: 1043.9857 | S78: 983.68133 | T78: 983.68133 | U78: 34.262216 | V78: 32.603758 | W78: 30.530687 | X78: 29.484728 | Y78: 28.43877 | Z78: 27.392811 | AA78: 26.346852 | AB78: 26.346852 | AS78: 0.46737 | AT78: 0.48173089 | AU78: 0.499682 | AV78: 0.5017015 | AW78: 0.503721 | AX78: 0.5057405 | AY78: 0.50776 | AZ78: 0.50776
A79: Electricity | B79: Grid | D79: 2020 | E79: Non Dispatchable | F79: Onshore Wind Turbine Class 3 | G79: Wind | H79: ELCWNDGRDWONC320 | I79: 1 | J79: 0 | K79: 30 | L79: 31.536 | M79: 1451.7715 | N79: 1350.9393 | O79: 1224.8989 | P79: 1164.5945 | Q79: 1104.2901 | R79: 1043.9857 | S79: 983.68133 | T79: 983.68133 | U79: 34.262216 | V79: 32.603758 | W79: 30.530687 | X79: 29.484728 | Y79: 28.43877 | Z79: 27.392811 | AA79: 26.346852 | AB79: 26.346852 | AS79: 0.45684 | AT79: 0.47087733 | AU79: 0.488424 | AV79: 0.490398 | AW79: 0.492372 | AX79: 0.494346 | AY79: 0.49632 | AZ79: 0.49632
A80: Electricity | B80: Grid | D80: 2020 | E80: Non Dispatchable | F80: Onshore Wind Turbine Class 4 | G80: Wind | H80: ELCWNDGRDWONC420 | I80: 1 | J80: 0 | K80: 30 | L80: 31.536 | M80: 1451.7715 | N80: 1350.9393 | O80: 1224.8989 | P80: 1164.5945 | Q80: 1104.2901 | R80: 1043.9857 | S80: 983.68133 | T80: 983.68133 | U80: 34.262216 | V80: 32.603758 | W80: 30.530687 | X80: 29.484728 | Y80: 28.43877 | Z80: 27.392811 | AA80: 26.346852 | AB80: 26.346852 | AS80: 0.44469 | AT80: 0.458354 | AU80: 0.475434 | AV80: 0.4773555 | AW80: 0.479277 | AX80: 0.4811985 | AY80: 0.48312 | AZ80: 0.48312
A81: Electricity | B81: Grid | D81: 2020 | E81: Non Dispatchable | F81: Onshore Wind Turbine Class 5 | G81: Wind | H81: ELCWNDGRDWONC520 | I81: 1 | J81: 0 | K81: 30 | L81: 31.536 | M81: 1451.7715 | N81: 1350.9393 | O81: 1224.8989 | P81: 1164.5945 | Q81: 1104.2901 | R81: 1043.9857 | S81: 983.68133 | T81: 983.68133 | U81: 34.262216 | V81: 32.603758 | W81: 30.530687 | X81: 29.484728 | Y81: 28.43877 | Z81: 27.392811 | AA81: 26.346852 | AB81: 26.346852 | AS81: 0.43011 | AT81: 0.443326 | AU81: 0.459846 | AV81: 0.4617045 | AW81: 0.463563 | AX81: 0.4654215 | AY81: 0.46728 | AZ81: 0.46728
A82: Electricity | B82: Grid | D82: 2020 | E82: Non Dispatchable | F82: Onshore Wind Turbine Class 6 | G82: Wind | H82: ELCWNDGRDWONC620 | I82: 1 | J82: 0 | K82: 30 | L82: 31.536 | M82: 1451.7715 | N82: 1350.9393 | O82: 1224.8989 | P82: 1164.5945 | Q82: 1104.2901 | R82: 1043.9857 | S82: 983.68133 | T82: 983.68133 | U82: 34.262216 | V82: 32.603758 | W82: 30.530687 | X82: 29.484728 | Y82: 28.43877 | Z82: 27.392811 | AA82: 26.346852 | AB82: 26.346852 | AS82: 0.40743 | AT82: 0.41994911 | AU82: 0.435598 | AV82: 0.4373585 | AW82: 0.439119 | AX82: 0.4408795 | AY82: 0.44264 | AZ82: 0.44264
A83: Electricity | B83: Grid | D83: 2020 | E83: Non Dispatchable | F83: Onshore Wind Turbine Class 7 | G83: Wind | H83: ELCWNDGRDWONC720 | I83: 1 | J83: 0 | K83: 30 | L83: 31.536 | M83: 1451.7715 | N83: 1350.9393 | O83: 1224.8989 | P83: 1164.5945 | Q83: 1104.2901 | R83: 1043.9857 | S83: 983.68133 | T83: 983.68133 | U83: 34.262216 | V83: 32.603758 | W83: 30.530687 | X83: 29.484728 | Y83: 28.43877 | Z83: 27.392811 | AA83: 26.346852 | AB83: 26.346852 | AS83: 0.37584 | AT83: 0.38738844 | AU83: 0.401824 | AV83: 0.403448 | AW83: 0.405072 | AX83: 0.406696 | AY83: 0.40832 | AZ83: 0.40832
A84: Electricity | B84: Grid | D84: 2020 | E84: Non Dispatchable | F84: Onshore Wind Turbine Class 8 | G84: Wind | H84: ELCWNDGRDWONC820 | I84: 1 | J84: 0 | K84: 30 | L84: 31.536 | M84: 1585.9778 | N84: 1451.0614 | O84: 1282.4159 | P84: 1219.7005 | Q84: 1156.985 | R84: 1094.2695 | S84: 1031.5541 | T84: 1031.5541 | U84: 32.226836 | V84: 30.266842 | W84: 27.816848 | X84: 26.883966 | Y84: 25.951084 | Z84: 25.018202 | AA84: 24.08532 | AB84: 24.08532 | AS84: 0.33939 | AT84: 0.34981844 | AU84: 0.362854 | AV84: 0.3643205 | AW84: 0.365787 | AX84: 0.3672535 | AY84: 0.36872 | AZ84: 0.36872
A85: Electricity | B85: Grid | D85: 2020 | E85: Non Dispatchable | F85: Onshore Wind Turbine Class 9 | G85: Wind | H85: ELCWNDGRDWONC920 | I85: 1 | J85: 0 | K85: 30 | L85: 31.536 | M85: 1508.2234 | N85: 1435.7946 | O85: 1345.2586 | P85: 1281.5798 | Q85: 1217.9009 | R85: 1154.2221 | S85: 1090.5433 | T85: 1090.5433 | U85: 43.421422 | V85: 41.762965 | W85: 39.689893 | X85: 38.13509 | Y85: 36.580286 | Z85: 35.025483 | AA85: 33.470679 | AB85: 33.470679 | AS85: 0.32805 | AT85: 0.33813 | AU85: 0.35073 | AV85: 0.3521475 | AW85: 0.353565 | AX85: 0.3549825 | AY85: 0.3564 | AZ85: 0.3564
A86: Electricity | B86: Grid | D86: 2020 | E86: Non Dispatchable | F86: Onshore Wind Turbine Class 10 | G86: Wind | H86: ELCWNDGRDWONC1020 | I86: 1 | J86: 0 | K86: 30 | L86: 31.536 | M86: 2088.719 | N86: 1887.5278 | O86: 1636.0389 | P86: 1557.4874 | Q86: 1478.9358 | R86: 1400.3842 | S86: 1321.8326 | T86: 1321.8326 | U86: 34.262216 | V86: 32.603758 | W86: 30.530687 | X86: 29.484728 | Y86: 28.43877 | Z86: 27.392811 | AA86: 26.346852 | AB86: 26.346852 | AS86: 0.25839 | AT86: 0.26632956 | AU86: 0.276254 | AV86: 0.2773705 | AW86: 0.278487 | AX86: 0.2796035 | AY86: 0.28072 | AZ86: 0.28072
A87: Electricity | B87: Grid | D87: 2020 | E87: Non Dispatchable | F87: Offshore Wind Turbine Class 1 | G87: Wind | H87: ELCWNDGRDWOFC120 | I87: 1 | J87: 0 | K87: 30 | L87: 31.536 | M87: 2535.3823 | N87: 2211.51 | O87: 2032.8204 | P87: 1922.3603 | Q87: 1842.1939 | R87: 1779.232 | S87: 1727.3792 | T87: 1727.3792 | U87: 121.32756 | V87: 107.77056 | W87: 98.274699 | X87: 91.909887 | Y87: 87.11563 | Z87: 83.268249 | AA87: 80.054708 | AB87: 80.054708 | AS87: 0.46351979 | AT87: 0.48634191 | AU87: 0.50892216 | AV87: 0.51900298 | AW87: 0.52783008 | AX87: 0.53590133 | AY87: 0.54346659 | AZ87: 0.54346659
...

Sheet >> TIMES

Sheet Def_Tech
B2: ~FI_Process
B3: Sets | C3: TechName | D3: TechDesc | E3: Tact | F3: Tcap | G3: Tslvl | H3: PrimaryCG | I3: Vintage
B4: *Process Set Membership | C4: Technology Name | D4: Technology Description | E4: Activity Unit | F4: Capacity Unit | G4: TimeSlice level of Process Activity | H4: Primary Commodity Group | I4: Vintage Tracking
B5: =IF('ELC TECH'!I4=0,"*",IF(_xlfn.XLOOKUP(C5,'ELC TECH'!H:H,'ELC TECH'!E:E)="Storage","STG","ELE")) -> ELE | C5: ='ELC TECH'!H4 -> ELCHYDGRDHNSDC120 | D5: =_xlfn.XLOOKUP(C5,'ELC TECH'!$H:$H,'ELC TECH'!$A:$A)&" "&_xlfn.XLOOKUP(C5,'ELC TECH'!$H:$H,'ELC TECH'!$B:$B)&" "&_xlfn.XLOOKUP(C5,'ELC TECH'!$H:$H,'ELC TECH'!$F:$F) -> Electricity Grid Hydro New-Stream Dispatchable Class 1 | E5: TJ | F5: MW | G5: DAYNITE
B6: =IF('ELC TECH'!I5=0,"*",IF(_xlfn.XLOOKUP(C6,'ELC TECH'!H:H,'ELC TECH'!E:E)="Storage","STG","ELE")) -> ELE | C6: ='ELC TECH'!H5 -> ELCHYDGRDHNSDC220 | D6: =_xlfn.XLOOKUP(C6,'ELC TECH'!$H:$H,'ELC TECH'!$A:$A)&" "&_xlfn.XLOOKUP(C6,'ELC TECH'!$H:$H,'ELC TECH'!$B:$B)&" "&_xlfn.XLOOKUP(C6,'ELC TECH'!$H:$H,'ELC TECH'!$F:$F) -> Electricity Grid Hydro New-Stream Dispatchable Class 2 | E6: TJ | F6: MW | G6: DAYNITE
B7: =IF('ELC TECH'!I6=0,"*",IF(_xlfn.XLOOKUP(C7,'ELC TECH'!H:H,'ELC TECH'!E:E)="Storage","STG","ELE")) -> ELE | C7: ='ELC TECH'!H6 -> ELCHYDGRDHNSDC320 | D7: =_xlfn.XLOOKUP(C7,'ELC TECH'!$H:$H,'ELC TECH'!$A:$A)&" "&_xlfn.XLOOKUP(C7,'ELC TECH'!$H:$H,'ELC TECH'!$B:$B)&" "&_xlfn.XLOOKUP(C7,'ELC TECH'!$H:$H,'ELC TECH'!$F:$F) -> Electricity Grid Hydro New-Stream Dispatchable Class 3 | E7: TJ | F7: MW | G7: DAYNITE
B8: =IF('ELC TECH'!I7=0,"*",IF(_xlfn.XLOOKUP(C8,'ELC TECH'!H:H,'ELC TECH'!E:E)="Storage","STG","ELE")) -> ELE | C8: ='ELC TECH'!H7 -> ELCHYDGRDHNSDC420 | D8: =_xlfn.XLOOKUP(C8,'ELC TECH'!$H:$H,'ELC TECH'!$A:$A)&" "&_xlfn.XLOOKUP(C8,'ELC TECH'!$H:$H,'ELC TECH'!$B:$B)&" "&_xlfn.XLOOKUP(C8,'ELC TECH'!$H:$H,'ELC TECH'!$F:$F) -> Electricity Grid Hydro New-Stream Dispatchable Class 4 | E8: TJ | F8: MW | G8: DAYNITE
B9: =IF('ELC TECH'!I8=0,"*",IF(_xlfn.XLOOKUP(C9,'ELC TECH'!H:H,'ELC TECH'!E:E)="Storage","STG","ELE")) -> ELE | C9: ='ELC TECH'!H8 -> ELCHYDGRDHNSDC520 | D9: =_xlfn.XLOOKUP(C9,'ELC TECH'!$H:$H,'ELC TECH'!$A:$A)&" "&_xlfn.XLOOKUP(C9,'ELC TECH'!$H:$H,'ELC TECH'!$B:$B)&" "&_xlfn.XLOOKUP(C9,'ELC TECH'!$H:$H,'ELC TECH'!$F:$F) -> Electricity Grid Hydro New-Stream Dispatchable Class 5 | E9: TJ | F9: MW | G9: DAYNITE
B10: =IF('ELC TECH'!I9=0,"*",IF(_xlfn.XLOOKUP(C10,'ELC TECH'!H:H,'ELC TECH'!E:E)="Storage","STG","ELE")) -> ELE | C10: ='ELC TECH'!H9 -> ELCHYDGRDHNSNDC120 | D10: =_xlfn.XLOOKUP(C10,'ELC TECH'!$H:$H,'ELC TECH'!$A:$A)&" "&_xlfn.XLOOKUP(C10,'ELC TECH'!$H:$H,'ELC TECH'!$B:$B)&" "&_xlfn.XLOOKUP(C10,'ELC TECH'!$H:$H,'ELC TECH'!$F:$F) -> Electricity Grid Hydro New-Stream Non Dispatchable Class 1 | E10: TJ | F10: MW | G10: DAYNITE
B11: =IF('ELC TECH'!I10=0,"*",IF(_xlfn.XLOOKUP(C11,'ELC TECH'!H:H,'ELC TECH'!E:E)="Storage","STG","ELE")) -> ELE | C11: ='ELC TECH'!H10 -> ELCHYDGRDHNSNDC220 | D11: =_xlfn.XLOOKUP(C11,'ELC TECH'!$H:$H,'ELC TECH'!$A:$A)&" "&_xlfn.XLOOKUP(C11,'ELC TECH'!$H:$H,'ELC TECH'!$B:$B)&" "&_xlfn.XLOOKUP(C11,'ELC TECH'!$H:$H,'ELC TECH'!$F:$F) -> Electricity Grid Hydro New-Stream Non Dispatchable Class 2 | E11: TJ | F11: MW | G11: DAYNITE
B12: =IF('ELC TECH'!I11=0,"*",IF(_xlfn.XLOOKUP(C12,'ELC TECH'!H:H,'ELC TECH'!E:E)="Storage","STG","ELE")) -> ELE | C12: ='ELC TECH'!H11 -> ELCHYDGRDHNSNDC320 | D12: =_xlfn.XLOOKUP(C12,'ELC TECH'!$H:$H,'ELC TECH'!$A:$A)&" "&_xlfn.XLOOKUP(C12,'ELC TECH'!$H:$H,'ELC TECH'!$B:$B)&" "&_xlfn.XLOOKUP(C12,'ELC TECH'!$H:$H,'ELC TECH'!$F:$F) -> Electricity Grid Hydro New-Stream Non Dispatchable Class 3 | E12: TJ | F12: MW | G12: DAYNITE
B13: =IF('ELC TECH'!I12=0,"*",IF(_xlfn.XLOOKUP(C13,'ELC TECH'!H:H,'ELC TECH'!E:E)="Storage","STG","ELE")) -> ELE | C13: ='ELC TECH'!H12 -> ELCHYDGRDHNSNDC420 | D13: =_xlfn.XLOOKUP(C13,'ELC TECH'!$H:$H,'ELC TECH'!$A:$A)&" "&_xlfn.XLOOKUP(C13,'ELC TECH'!$H:$H,'ELC TECH'!$B:$B)&" "&_xlfn.XLOOKUP(C13,'ELC TECH'!$H:$H,'ELC TECH'!$F:$F) -> Electricity Grid Hydro New-Stream Non Dispatchable Class 4 | E13: TJ | F13: MW | G13: DAYNITE
B14: =IF('ELC TECH'!I13=0,"*",IF(_xlfn.XLOOKUP(C14,'ELC TECH'!H:H,'ELC TECH'!E:E)="Storage","STG","ELE")) -> ELE | C14: ='ELC TECH'!H13 -> ELCHYDGRDHNSNDC520 | D14: =_xlfn.XLOOKUP(C14,'ELC TECH'!$H:$H,'ELC TECH'!$A:$A)&" "&_xlfn.XLOOKUP(C14,'ELC TECH'!$H:$H,'ELC TECH'!$B:$B)&" "&_xlfn.XLOOKUP(C14,'ELC TECH'!$H:$H,'ELC TECH'!$F:$F) -> Electricity Grid Hydro New-Stream Non Dispatchable Class 5 | E14: TJ | F14: MW | G14: DAYNITE
B15: =IF('ELC TECH'!I14=0,"*",IF(_xlfn.XLOOKUP(C15,'ELC TECH'!H:H,'ELC TECH'!E:E)="Storage","STG","ELE")) -> ELE | C15: ='ELC TECH'!H14 -> ELCHYDGRDHNPNDC120 | D15: =_xlfn.XLOOKUP(C15,'ELC TECH'!$H:$H,'ELC TECH'!$A:$A)&" "&_xlfn.XLOOKUP(C15,'ELC TECH'!$H:$H,'ELC TECH'!$B:$B)&" "&_xlfn.XLOOKUP(C15,'ELC TECH'!$H:$H,'ELC TECH'!$F:$F) -> Electricity Grid Hydro Non-Powered Non Dispatchable Class 1 | E15: TJ | F15: MW | G15: DAYNITE
B16: =IF('ELC TECH'!I15=0,"*",IF(_xlfn.XLOOKUP(C16,'ELC TECH'!H:H,'ELC TECH'!E:E)="Storage","STG","ELE")) -> ELE | C16: ='ELC TECH'!H15 -> ELCHYDGRDHNPNDC220 | D16: =_xlfn.XLOOKUP(C16,'ELC TECH'!$H:$H,'ELC TECH'!$A:$A)&" "&_xlfn.XLOOKUP(C16,'ELC TECH'!$H:$H,'ELC TECH'!$B:$B)&" "&_xlfn.XLOOKUP(C16,'ELC TECH'!$H:$H,'ELC TECH'!$F:$F) -> Electricity Grid Hydro Non-Powered Non Dispatchable Class 2 | E16: TJ | F16: MW | G16: DAYNITE
... B184: =IF('ELC TECH'!I183=0,"*",IF(_xlfn.XLOOKUP(C184,'ELC TECH'!H:H,'ELC TECH'!E:E)="Storage","STG","ELE")) -> STG | C184: ='ELC TECH'!H183 -> ELCSTGDCECBES8H20 | D184: =_xlfn.XLOOKUP(C184,'ELC TECH'!$H:$H,'ELC TECH'!$A:$A)&" "&_xlfn.XLOOKUP(C184,'ELC TECH'!$H:$H,'ELC TECH'!$B:$B)&" "&_xlfn.XLOOKUP(C184,'ELC TECH'!$H:$H,'ELC TECH'!$F:$F) -> Electricity Decentralized Commercial Battery Storage 8Hr | E184: TJ | F184: MW | G184: DAYNITE

Sheet Def_Comm
B2: ~FI_Comm
B3: Csets | C3: CommName | D3: CommDesc | E3: Unit | F3: LimType | G3: CTSLvl | H3: PeakTS | I3: Ctype
B4: *Commodity Set Membership | C4: Commodity Name | D4: Commodity Description | E4: Unit | F4: Sense of the Balance EQN. | G4: Timeslice Level | H4: Peak Monitoring | I4: Electricity Indicator

Sheet ResidELC
BM1: ELCSOL | BN1: 0.47550939 | BO1: 0.47550939 | BP1: =BN1*0.1 -> 0.047550939 | BQ1: 0 | BR1: 0.5476587 | BS1: 0.5476587 | BT1: =BR1*0.1 -> 0.05476587 | BU1: 0 | BV1: 0.45816402 | BW1: 0.45816402 | BX1: =BV1*0.1 -> 0.045816402 | BY1: 0 | BZ1: 0.47550939 | CA1: 0.47550939 | CB1: =BZ1*0.1 -> 0.047550939 | CC1: 0 | CD1: 0.5476587 | CE1: 0.5476587 | CF1: =CD1*0.1 -> 0.05476587 | CG1: 0 | CH1: 0.45816402 | CI1: 0.45816402 | CJ1: =CH1*0.1 -> 0.045816402 | CK1: 0 | CL1: 0.47550939 | CM1: 0.47550939 | CN1: =CL1*0.1 -> 0.047550939 | CO1: 0 | CP1: 0.5476587 | CQ1: 0.5476587 | CR1: =CP1*0.1 -> 0.05476587 | CS1: 0 | CT1: 0.45816402 | CU1: 0.45816402 | CV1: =CT1*0.1 -> 0.045816402 | CW1: 0 | CX1: 0.47550939 | CY1: 0.47550939 | CZ1: =CX1*0.1 -> 0.047550939 | DA1: 0 | DB1: 0.5476587 | DC1: 0.5476587 | DD1: =DB1*0.1 -> 0.05476587 | DE1: 0 | DF1: 0.45816402 | DG1: 0.45816402 | DH1: =DF1*0.1 -> 0.045816402 | DI1: 0
BM2: ELCWND | BN2: 0.49405275 | BO2: 0.49405275 | BP2: =BN2*0.1 -> 0.049405275 | BQ2: 0.39586365 | BR2: 0.57489775 | BS2: 0.57489775 | BT2: =BR2*0.1 -> 0.057489775 | BU2: 0.50939778 | BV2: 0.29772235 | BW2: 0.29772235 | BX2: =BV2*0.1 -> 0.029772235 | BY2: 0.21762049 | BZ2: 0.49405275 | CA2: 0.49405275 | CB2: =BZ2*0.1 -> 0.049405275 | CC2: 0.39586365 | CD2: 0.57489775 | CE2: 0.57489775 | CF2: =CD2*0.1 -> 0.057489775 | CG2: 0.50939778 | CH2: 0.29772235 | CI2: 0.29772235 | CJ2: =CH2*0.1 -> 0.029772235 | CK2: 0.21762049 | CL2: 0.49405275 | CM2: 0.49405275 | CN2: =CL2*0.1 -> 0.049405275 | CO2: 0.39586365 | CP2: 0.57489775 | CQ2: 0.57489775 | CR2: =CP2*0.1 -> 0.057489775 | CS2: 0.50939778 | CT2: 0.29772235 | CU2: 0.29772235 | CV2: =CT2*0.1 -> 0.029772235 | CW2: 0.21762049 | CX2: 0.49405275 | CY2: 0.49405275 | CZ2: =CX2*0.1 -> 0.049405275 | DA2: 0.39586365 | DB2: 0.57489775 | DC2: 0.57489775 | DD2: =DB2*0.1 -> 0.057489775 | DE2: 0.50939778 | DF2: 0.29772235 | DG2: 0.29772235 | DH2: =DF2*0.1 -> 0.029772235 | DI2: 0.21762049
BM3: ELCHYD | BN3: 0.0822 | BO3: 0.0957 | BP3: 0.1532 | BQ3: 0.0032 | BR3: 0.0815 | BS3: 0.1087 | BT3: 0.1381 | BU3: 0.0032 | BV3: 0.0975 | BW3: 0.1087 | BX3: 0.1253 | BY3: 0.0027 | BZ3: 0.0822 | CA3: 0.0957 | CB3: 0.1532 | CC3: 0.0032 | CD3: 0.0815 | CE3: 0.1087 | CF3: 0.1381 | CG3: 0.0032 | CH3: 0.0975 | CI3: 0.1087 | CJ3: 0.1253 | CK3: 0.0027 | CL3: 0.0822 | CM3: 0.0957 | CN3: 0.1532 | CO3: 0.0032 | CP3: 0.0815 | CQ3: 0.1087 | CR3: 0.1381 | CS3: 0.0032 | CT3: 0.0975 | CU3: 0.1087 | CV3: 0.1253 | CW3: 0.0027 | CX3: 0.0822 | CY3: 0.0957 | CZ3: 0.1532 | DA3: 0.0032 | DB3: 0.0815 | DC3: 0.1087 | DD3: 0.1381 | DE3: 0.0032 | DF3: 0.0975 | DG3: 0.1087 | DH3: 0.1253 | DI3: 0.0027
BN4: 0.0822 | BO4: 0.0957 | BP4: 0.1532 | BQ4: 0.0032 | BR4: 0.0815 | BS4: 0.1087 | BT4: 0.1381 | BU4: 0.0032 | BV4: 0.0975 | BW4: 0.1087 | BX4: 0.1253 | BY4: 0.0027 | BZ4: 0.0822 | CA4: 0.0957 | CB4: 0.1532 | CC4: 0.0032 | CD4: 0.0815 | CE4: 0.1087 | CF4: 0.1381 | CG4: 0.0032 | CH4: 0.0975 | CI4: 0.1087 | CJ4: 0.1253 | CK4: 0.0027 | CL4: 0.0822 | CM4: 0.0957 | CN4: 0.1532 | CO4: 0.0032 | CP4: 0.0815 | CQ4: 0.1087 | CR4: 0.1381 | CS4: 0.0032 | CT4: 0.0975 | CU4: 0.1087 | CV4: 0.1253 | CW4: 0.0027 | CX4: 0.0822 | CY4: 0.0957 | CZ4: 0.1532 | DA4: 0.0032 | DB4: 0.0815 | DC4: 0.1087 | DD4: 0.1381 | DE4: 0.0032 | DF4: 0.0975 | DG4: 0.1087 | DH4: 0.1253 | DI4: 0.0027
J5: ='City characteristics'!$C$20+1 -> 2020 | K5: 2025 | L5: 2030 | M5: 2035 | N5: 2040 | O5: 2045 | P5: 2050 | Q5: 2100 | R5: ='City characteristics'!$C$20+1 -> 2020 | S5: 2025 | T5: 2030 | U5: 2035 | V5: 2040 | W5: 2045 | X5: 2050 | Y5: 2100 | Z5: ='City characteristics'!$C$20+1 -> 2020 | AA5: 2025 | AB5: 2030 | AC5: 2035 | AD5: 2040 | AE5: 2045 | AF5: 2050 | AG5: 2100 | AH5: ='City characteristics'!$C$20+1 -> 2020 | AI5: 2025 | AJ5: 2030 | AK5: 2035 | AL5: 2040 | AM5: 2045 | AN5: 2050 | AO5: 2100 | AP5: ='City characteristics'!$C$20+1 -> 2020 | AQ5: 2025 | AR5: 2030 | AS5: 2035 | AT5: 2040 | AU5: 2045 | AV5: 2050 | AW5: 2100 | AX5: ='City characteristics'!$C$20+1 -> 2020 | AY5: 2025 | AZ5: 2030 | BA5: 2035 | BB5: 2040 | BC5: 2045 | BD5: 2050 | BE5: 2100 | BF5: ='City characteristics'!$C$20+1 -> 2020 | BG5: 2025 | BH5: 2030 | BI5: 2035 | BJ5: 2040 | BK5: 2045 | BL5: 2050 | BM5: 2100 | BN5: IDAM | BO5: IDPM | BP5: IP | BQ5: IN | BR5: WDAM | BS5: WDPM | BT5: WP | BU5: WN | BV5: SDAM | BW5: SDPM | BX5: SP | BY5: SN | BZ5: IDAM | CA5: IDPM | CB5: IP | CC5: IN | CD5: WDAM | CE5: WDPM | CF5: WP | CG5: WN | CH5: SDAM | CI5: SDPM | CJ5: SP | CK5: SN | CL5: IDAM | CM5: IDPM | CN5: IP | CO5: IN | CP5: WDAM | CQ5: WDPM | CR5: WP | CS5: WN | CT5: SDAM | CU5: SDPM | CV5: SP | CW5: SN | CX5: IDAM | CY5: IDPM | CZ5: IP | DA5: IN | DB5: WDAM | DC5: WDPM | DD5: WP | DE5: WN | DF5: SDAM | DG5: SDPM | DH5: SP | DI5: SN
J6: EFF | K6: EFF | L6: EFF | M6: EFF | N6: EFF | O6: EFF | P6: EFF | Q6: EFF | R6: STG_EFF | S6: STG_EFF | T6: STG_EFF | U6: STG_EFF | V6: STG_EFF | W6: STG_EFF | X6: STG_EFF | Y6: STG_EFF | Z6: NCAP_COST | AA6: NCAP_COST | AB6: NCAP_COST | AC6: NCAP_COST | AD6: NCAP_COST | AE6: NCAP_COST | AF6: NCAP_COST | AG6: NCAP_COST | AH6: NCAP_FOM | AI6: NCAP_FOM | AJ6: NCAP_FOM | AK6: NCAP_FOM | AL6: NCAP_FOM | AM6: NCAP_FOM | AN6: NCAP_FOM | AO6: NCAP_FOM | AP6: ACT_COST | AQ6: ACT_COST | AR6: ACT_COST | AS6: ACT_COST | AT6: ACT_COST | AU6: ACT_COST | AV6: ACT_COST | AW6: ACT_COST | AX6: NCAP_AFA | AY6: NCAP_AFA | AZ6: NCAP_AFA | BA6: NCAP_AFA | BB6: NCAP_AFA | BC6: NCAP_AFA | BD6: NCAP_AFA | BE6: NCAP_AFA | BF6: NCAP_AFC | BG6: NCAP_AFC | BH6: NCAP_AFC | BI6: NCAP_AFC | BJ6: NCAP_AFC | BK6: NCAP_AFC | BL6: NCAP_AFC | BM6: NCAP_AFC | BN6: NCAP_AF | BO6: NCAP_AF | BP6: NCAP_AF | BQ6: NCAP_AF | BR6: NCAP_AF | BS6: NCAP_AF | BT6: NCAP_AF | BU6: NCAP_AF | BV6: NCAP_AF | BW6: NCAP_AF | BX6: NCAP_AF | BY6: NCAP_AF | BZ6: NCAP_AF | CA6: NCAP_AF | CB6: NCAP_AF | CC6: NCAP_AF | CD6: NCAP_AF | CE6: NCAP_AF | CF6: NCAP_AF | CG6: NCAP_AF | CH6: NCAP_AF | CI6: NCAP_AF | CJ6: NCAP_AF | CK6: NCAP_AF | CL6: NCAP_AFC | CM6: NCAP_AFC | CN6: NCAP_AFC | CO6: NCAP_AFC | CP6: NCAP_AFC | CQ6: NCAP_AFC | CR6: NCAP_AFC | CS6: NCAP_AFC | CT6: NCAP_AFC | CU6: NCAP_AFC | CV6: NCAP_AFC | CW6: NCAP_AFC | CX6: NCAP_AFC | CY6: NCAP_AFC | CZ6: NCAP_AFC | DA6: NCAP_AFC | DB6: NCAP_AFC | DC6: NCAP_AFC | DD6: NCAP_AFC | DE6: NCAP_AFC | DF6: NCAP_AFC | DG6: NCAP_AFC | DH6: NCAP_AFC | DI6: NCAP_AFC
D8: ~FI_T
B9: TechName | C9: Comm-IN | D9: Comm-OUT | E9: NCAP_START | F9: NCAP_TLIFE | G9: PRC_CAPACT | H9: NCAP_PKCNT | I9: CAP_BND~UP | J9: =J6&"~"&J5 -> EFF~2020 | K9: =K6&"~"&K5 -> EFF~2025 | L9: =L6&"~"&L5 -> EFF~2030 | M9: =M6&"~"&M5 -> EFF~2035 | N9: =N6&"~"&N5 -> EFF~2040 | O9: =O6&"~"&O5 -> EFF~2045 | P9: =P6&"~"&P5 -> EFF~2050 | Q9: =Q6&"~"&Q5 -> EFF~2100 | ... BM9: =BM6&"~"&BM5 -> NCAP_AFC~2100 | BN9: =BN6&"~"&BN5&"~"&ResidELC!$AX$5 -> NCAP_AF~IDAM~2020 | BO9: =BO6&"~"&BO5&"~"&ResidELC!$AX$5 -> NCAP_AF~IDPM~2020 | BP9: =BP6&"~"&BP5&"~"&ResidELC!$AX$5 -> NCAP_AF~IP~2020 | BQ9: =BQ6&"~"&BQ5&"~"&ResidELC!$AX$5 -> NCAP_AF~IN~2020 | BR9: =BR6&"~"&BR5&"~"&ResidELC!$AX$5 -> NCAP_AF~WDAM~2020 | BS9: =BS6&"~"&BS5&"~"&ResidELC!$AX$5 -> NCAP_AF~WDPM~2020 | BT9: =BT6&"~"&BT5&"~"&ResidELC!$AX$5 -> NCAP_AF~WP~2020 | BU9: =BU6&"~"&BU5&"~"&ResidELC!$AX$5 -> NCAP_AF~WN~2020 | ... BY9: =BY6&"~"&BY5&"~"&ResidELC!$AX$5 -> NCAP_AF~SN~2020 | BZ9: =BZ6&"~"&BZ5&"~"&$BD$5 -> NCAP_AF~IDAM~2050 | CA9: =CA6&"~"&CA5&"~"&$BD$5 -> NCAP_AF~IDPM~2050 | CB9: =CB6&"~"&CB5&"~"&$BD$5 -> NCAP_AF~IP~2050 | CC9: =CC6&"~"&CC5&"~"&$BD$5 -> NCAP_AF~IN~2050 | CD9: =CD6&"~"&CD5&"~"&$BD$5 -> NCAP_AF~WDAM~2050 | CE9: =CE6&"~"&CE5&"~"&$BD$5 -> NCAP_AF~WDPM~2050 | CF9: =CF6&"~"&CF5&"~"&$BD$5 -> NCAP_AF~WP~2050 | CG9: =CG6&"~"&CG5&"~"&$BD$5 -> NCAP_AF~WN~2050 | ... CK9: =CK6&"~"&CK5&"~"&$BD$5 -> NCAP_AF~SN~2050 | CL9: =CL6&"~"&CL5&"~"&ResidELC!$AX$5 -> NCAP_AFC~IDAM~2020 | CM9: =CM6&"~"&CM5&"~"&ResidELC!$AX$5 -> NCAP_AFC~IDPM~2020 | CN9: =CN6&"~"&CN5&"~"&ResidELC!$AX$5 -> NCAP_AFC~IP~2020 | CO9: =CO6&"~"&CO5&"~"&ResidELC!$AX$5 -> NCAP_AFC~IN~2020 | CP9: =CP6&"~"&CP5&"~"&ResidELC!$AX$5 -> NCAP_AFC~WDAM~2020 | CQ9: =CQ6&"~"&CQ5&"~"&ResidELC!$AX$5 -> NCAP_AFC~WDPM~2020 | CR9: =CR6&"~"&CR5&"~"&ResidELC!$AX$5 -> NCAP_AFC~WP~2020 | CS9: =CS6&"~"&CS5&"~"&ResidELC!$AX$5 -> NCAP_AFC~WN~2020 | ... CW9: =CW6&"~"&CW5&"~"&ResidELC!$AX$5 -> NCAP_AFC~SN~2020 | CX9: =CX6&"~"&CX5&"~"&$BD$5 -> NCAP_AFC~IDAM~2050 | CY9: =CY6&"~"&CY5&"~"&$BD$5 -> NCAP_AFC~IDPM~2050 | CZ9: =CZ6&"~"&CZ5&"~"&$BD$5 -> NCAP_AFC~IP~2050 | DA9: =DA6&"~"&DA5&"~"&$BD$5 -> NCAP_AFC~IN~2050 | DB9: =DB6&"~"&DB5&"~"&$BD$5 -> NCAP_AFC~WDAM~2050 | DC9: =DC6&"~"&DC5&"~"&$BD$5 -> NCAP_AFC~WDPM~2050 | DD9: =DD6&"~"&DD5&"~"&$BD$5 -> NCAP_AFC~WP~2050 | DE9: =DE6&"~"&DE5&"~"&$BD$5 -> NCAP_AFC~WN~2050 | ... DI9: =DI6&"~"&DI5&"~"&$BD$5 -> NCAP_AFC~SN~2050
B10: * | F10: Yr | G10: TJ/MW | H10: % | I10: MW | J10: Out/In | K10: Out/In | L10: Out/In | M10: Out/In | N10: Out/In | O10: Out/In | P10: Out/In | Q10: Out/In | R10: Out/In | S10: Out/In | T10: Out/In | U10: Out/In | V10: Out/In | W10: Out/In | X10: Out/In | Y10: Out/In | Z10: $/kW | AA10: $/kW | AB10: $/kW | AC10: $/kW | AD10: $/kW | AE10: $/kW | AF10: $/kW | AG10: $/kW | AH10: $/kW/yr | AI10: $/kW/yr | AJ10: $/kW/yr | AK10: $/kW/yr | AL10: $/kW/yr | AM10: $/kW/yr | AN10: $/kW/yr | AO10: $/kW/yr | AP10: $/GJ | AQ10: $/GJ | AR10: $/GJ | AS10: $/GJ | AT10: $/GJ | AU10: $/GJ | AV10: $/GJ | AW10: $/GJ | AX10: % | AY10: % | AZ10: % | BA10: % | BB10: % | BC10: % | BD10: % | BE10: % | BF10: % | BG10: % | BH10: % | BI10: % | BJ10: % | BK10: % | BL10: % | BM10: % | BN10: % | BO10: % | BP10: % | BQ10: % | BR10: % | BS10: % | BT10: % | BU10: % | BV10: % | BW10: % | BX10: % | BY10: % | BZ10: % | CA10: % | CB10: % | CC10: % | CD10: % | CE10: % | CF10: % | CG10: % | CH10: % | CI10: % | CJ10: % | CK10: % | CL10: % | CM10: % | CN10: % | CO10: % | CP10: % | CQ10: % | CR10: % | CS10: % | CT10: % | CU10: % | CV10: % | CW10: % | CX10: % | CY10: % | CZ10: % | DA10: % | DB10: % | DC10: % | DD10: % | DE10: % | DF10: % | DG10: % | DH10: % | DI10: %
B11: =IF('ELC TECH'!I4=0,"*",'ELC TECH'!H4) -> ELCHYDGRDHNSDC120 | C11: =IF(_xlfn.XLOOKUP(_xlfn.XLOOKUP(B11,'ELC TECH'!$H:$H,'ELC TECH'!$G:$G),List!C:C,List!B:B)="STG",D11,"ELC"&_xlfn.XLOOKUP(_xlfn.XLOOKUP(B11,'ELC TECH'!H:H,'ELC TECH'!G:G),List!C:C,List!B:B)) -> ELCHYD | D11: CELC | E11: =_xlfn.XLOOKUP(B11,'ELC TECH'!H:H,'ELC TECH'!D:D) -> 2020 | F11: =_xlfn.XLOOKUP(B11,'ELC TECH'!H:H,'ELC TECH'!K:K) -> 100 | G11: =8760*0.0036 -> 31.536 | H11: =IF(_xlfn.XLOOKUP(B11,'ELC TECH'!$H:$H,'ELC TECH'!$E:$E)="Storage",0.3,IF(_xlfn.XLOOKUP(B11,'ELC TECH'!$H:$H,'ELC TECH'!$E:$E)="Baseload",0.9,IF(_xlfn.XLOOKUP(B11,'ELC TECH'!$H:$H,'ELC TECH'!$E:$E)="Non Dispatchable",0.05,IF(_xlfn.XLOOKUP(B11,'ELC TECH'!$H:$H,'ELC TECH'!$E:$E)="Dispatchable",0.9,1)))) -> 0.9 | I11: =IF(_xlfn.XLOOKUP(B11,'ELC TECH'!H:H,'ELC TECH'!J:J)="","",_xlfn.XLOOKUP(B11,'ELC TECH'!H:H,'ELC TECH'!J:J)) -> 0 | J11: =IF(_xlfn.XLOOKUP($B11,'ELC TECH'!$H:$H,'ELC TECH'!$E:$E)="Storage","",IF(_xlfn.XLOOKUP($B11,'ELC TECH'!$H:$H,'ELC TECH'!AK:AK)="",1,_xlfn.XLOOKUP($B11,'ELC TECH'!$H:$H,'ELC TECH'!AK:AK))) -> 1 | K11: =IF(_xlfn.XLOOKUP($B11,'ELC TECH'!$H:$H,'ELC TECH'!$E:$E)="Storage","",IF(_xlfn.XLOOKUP($B11,'ELC TECH'!$H:$H,'ELC TECH'!AL:AL)="",1,_xlfn.XLOOKUP($B11,'ELC TECH'!$H:$H,'ELC TECH'!AL:AL))) -> 1 | L11: =IF(_xlfn.XLOOKUP($B11,'ELC TECH'!$H:$H,'ELC TECH'!$E:$E)="Storage","",IF(_xlfn.XLOOKUP($B11,'ELC TECH'!$H:$H,'ELC TECH'!AM:AM)="",1,_xlfn.XLOOKUP($B11,'ELC TECH'!$H:$H,'ELC TECH'!AM:AM))) -> 1 | M11: =IF(_xlfn.XLOOKUP($B11,'ELC TECH'!$H:$H,'ELC TECH'!$E:$E)="Storage","",IF(_xlfn.XLOOKUP($B11,'ELC TECH'!$H:$H,'ELC TECH'!AN:AN)="",1,_xlfn.XLOOKUP($B11,'ELC TECH'!$H:$H,'ELC TECH'!AN:AN))) -> 1 | N11: =IF(_xlfn.XLOOKUP($B11,'ELC TECH'!$H:$H,'ELC TECH'!$E:$E)="Storage","",IF(_xlfn.XLOOKUP($B11,'ELC TECH'!$H:$H,'ELC TECH'!AO:AO)="",1,_xlfn.XLOOKUP($B11,'ELC TECH'!$H:$H,'ELC TECH'!AO:AO))) -> 1 | O11: =IF(_xlfn.XLOOKUP($B11,'ELC TECH'!$H:$H,'ELC TECH'!$E:$E)="Storage","",IF(_xlfn.XLOOKUP($B11,'ELC TECH'!$H:$H,'ELC TECH'!AP:AP)="",1,_xlfn.XLOOKUP($B11,'ELC TECH'!$H:$H,'ELC TECH'!AP:AP))) -> 1 | P11: =IF(_xlfn.XLOOKUP($B11,'ELC TECH'!$H:$H,'ELC TECH'!$E:$E)="Storage","",IF(_xlfn.XLOOKUP($B11,'ELC TECH'!$H:$H,'ELC TECH'!AQ:AQ)="",1,_xlfn.XLOOKUP($B11,'ELC TECH'!$H:$H,'ELC TECH'!AQ:AQ))) -> 1 | Q11: =IF(_xlfn.XLOOKUP($B11,'ELC TECH'!$H:$H,'ELC TECH'!$E:$E)="Storage","",IF(_xlfn.XLOOKUP($B11,'ELC TECH'!$H:$H,'ELC TECH'!AR:AR)="",1,_xlfn.XLOOKUP($B11,'ELC TECH'!$H:$H,'ELC TECH'!AR:AR))) -> 1 | R11: =IF(_xlfn.XLOOKUP($B11,'ELC TECH'!$H:$H,'ELC TECH'!$E:$E)<>"Storage","",IF(_xlfn.XLOOKUP($B11,'ELC TECH'!$H:$H,'ELC TECH'!AK:AK)="",0.8,_xlfn.XLOOKUP($B11,'ELC TECH'!$H:$H,'ELC TECH'!AK:AK))) | S11: =IF(_xlfn.XLOOKUP($B11,'ELC TECH'!$H:$H,'ELC TECH'!$E:$E)<>"Storage","",IF(_xlfn.XLOOKUP($B11,'ELC TECH'!$H:$H,'ELC TECH'!AL:AL)="",0.8,_xlfn.XLOOKUP($B11,'ELC TECH'!$H:$H,'ELC TECH'!AL:AL))) | T11: =IF(_xlfn.XLOOKUP($B11,'ELC TECH'!$H:$H,'ELC TECH'!$E:$E)<>"Storage","",IF(_xlfn.XLOOKUP($B11,'ELC TECH'!$H:$H,'ELC TECH'!AM:AM)="",0.8,_xlfn.XLOOKUP($B11,'ELC TECH'!$H:$H,'ELC TECH'!AM:AM))) | U11: =IF(_xlfn.XLOOKUP($B11,'ELC TECH'!$H:$H,'ELC TECH'!$E:$E)<>"Storage","",IF(_xlfn.XLOOKUP($B11,'ELC TECH'!$H:$H,'ELC TECH'!AN:AN)="",0.8,_xlfn.XLOOKUP($B11,'ELC TECH'!$H:$H,'ELC TECH'!AN:AN))) | V11: =IF(_xlfn.XLOOKUP($B11,'ELC TECH'!$H:$H,'ELC TECH'!$E:$E)<>"Storage","",IF(_xlfn.XLOOKUP($B11,'ELC TECH'!$H:$H,'ELC TECH'!AO:AO)="",0.8,_xlfn.XLOOKUP($B11,'ELC TECH'!$H:$H,'ELC TECH'!AO:AO))) | W11: =IF(_xlfn.XLOOKUP($B11,'ELC TECH'!$H:$H,'ELC TECH'!$E:$E)<>"Storage","",IF(_xlfn.XLOOKUP($B11,'ELC TECH'!$H:$H,'ELC TECH'!AP:AP)="",0.8,_xlfn.XLOOKUP($B11,'ELC TECH'!$H:$H,'ELC TECH'!AP:AP))) | X11: =IF(_xlfn.XLOOKUP($B11,'ELC TECH'!$H:$H,'ELC TECH'!$E:$E)<>"Storage","",IF(_xlfn.XLOOKUP($B11,'ELC TECH'!$H:$H,'ELC TECH'!AQ:AQ)="",0.8,_xlfn.XLOOKUP($B11,'ELC TECH'!$H:$H,'ELC TECH'!AQ:AQ))) | Y11: =IF(_xlfn.XLOOKUP($B11,'ELC TECH'!$H:$H,'ELC TECH'!$E:$E)<>"Storage","",IF(_xlfn.XLOOKUP($B11,'ELC TECH'!$H:$H,'ELC TECH'!AR:AR)="",0.8,_xlfn.XLOOKUP($B11,'ELC TECH'!$H:$H,'ELC TECH'!AR:AR))) | Z11: =_xlfn.XLOOKUP($B11,'ELC TECH'!$H:$H,'ELC TECH'!M:M) -> 8970.3682 | AA11: =_xlfn.XLOOKUP($B11,'ELC TECH'!$H:$H,'ELC TECH'!N:N) -> 8970.3682 | AB11: =_xlfn.XLOOKUP($B11,'ELC TECH'!$H:$H,'ELC TECH'!O:O) -> 8970.3682 | AC11: =_xlfn.XLOOKUP($B11,'ELC TECH'!$H:$H,'ELC TECH'!P:P) -> 8970.3682 | AD11: =_xlfn.XLOOKUP($B11,'ELC TECH'!$H:$H,'ELC TECH'!Q:Q) -> 8970.3682 | AE11: =_xlfn.XLOOKUP($B11,'ELC TECH'!$H:$H,'ELC TECH'!R:R) -> 8970.3682 | AF11: =_xlfn.XLOOKUP($B11,'ELC TECH'!$H:$H,'ELC TECH'!S:S) -> 8970.3682 | AG11: =_xlfn.XLOOKUP($B11,'ELC TECH'!$H:$H,'ELC TECH'!T:T) -> 8970.3682 | AH11: =_xlfn.XLOOKUP($B11,'ELC TECH'!$H:$H,'ELC TECH'!U:U) -> 161.69957 | AI11: =_xlfn.XLOOKUP($B11,'ELC TECH'!$H:$H,'ELC TECH'!V:V) -> 161.69957 | AJ11: =_xlfn.XLOOKUP($B11,'ELC TECH'!$H:$H,'ELC TECH'!W:W) -> 161.69957 | AK11: =_xlfn.XLOOKUP($B11,'ELC TECH'!$H:$H,'ELC TECH'!X:X) -> 161.69957 | AL11: =_xlfn.XLOOKUP($B11,'ELC TECH'!$H:$H,'ELC TECH'!Y:Y) -> 161.69957 | AM11: =_xlfn.XLOOKUP($B11,'ELC TECH'!$H:$H,'ELC TECH'!Z:Z) -> 161.69957 | AN11: =_xlfn.XLOOKUP($B11,'ELC TECH'!$H:$H,'ELC TECH'!AA:AA) -> 161.69957 | AO11: =_xlfn.XLOOKUP($B11,'ELC TECH'!$H:$H,'ELC TECH'!AB:AB) -> 161.69957 | AP11: =_xlfn.XLOOKUP($B11,'ELC TECH'!$H:$H,'ELC TECH'!AC:AC) -> 0 | AQ11: =_xlfn.XLOOKUP($B11,'ELC TECH'!$H:$H,'ELC TECH'!AD:AD) -> 0 | AR11: =_xlfn.XLOOKUP($B11,'ELC TECH'!$H:$H,'ELC TECH'!AE:AE) -> 0 | AS11: =_xlfn.XLOOKUP($B11,'ELC TECH'!$H:$H,'ELC TECH'!AF:AF) -> 0 | AT11: =_xlfn.XLOOKUP($B11,'ELC TECH'!$H:$H,'ELC TECH'!AG:AG) -> 0 | AU11: =_xlfn.XLOOKUP($B11,'ELC TECH'!$H:$H,'ELC TECH'!AH:AH) -> 0 | AV11: =_xlfn.XLOOKUP($B11,'ELC TECH'!$H:$H,'ELC TECH'!AI:AI) -> 0 | AW11: =_xlfn.XLOOKUP($B11,'ELC TECH'!$H:$H,'ELC TECH'!AJ:AJ) -> 0 | AX11: =IF(_xlfn.XLOOKUP($B11,'ELC TECH'!$H:$H,'ELC TECH'!$E:$E)="Storage","",_xlfn.XLOOKUP($B11,'ELC TECH'!$H:$H,'ELC TECH'!AS:AS)) -> 0.66 | AY11: =IF(_xlfn.XLOOKUP($B11,'ELC TECH'!$H:$H,'ELC TECH'!$E:$E)="Storage","",_xlfn.XLOOKUP($B11,'ELC TECH'!$H:$H,'ELC TECH'!AT:AT)) -> 0.66 | AZ11: =IF(_xlfn.XLOOKUP($B11,'ELC TECH'!$H:$H,'ELC TECH'!$E:$E)="Storage","",_xlfn.XLOOKUP($B11,'ELC TECH'!$H:$H,'ELC TECH'!AU:AU)) -> 0.66 | BA11: =IF(_xlfn.XLOOKUP($B11,'ELC TECH'!$H:$H,'ELC TECH'!$E:$E)="Storage","",_xlfn.XLOOKUP($B11,'ELC TECH'!$H:$H,'ELC TECH'!AV:AV)) -> 0.66 | BB11: =IF(_xlfn.XLOOKUP($B11,'ELC TECH'!$H:$H,'ELC TECH'!$E:$E)="Storage","",_xlfn.XLOOKUP($B11,'ELC TECH'!$H:$H,'ELC TECH'!AW:AW)) -> 0.66 | BC11: =IF(_xlfn.XLOOKUP($B11,'ELC TECH'!$H:$H,'ELC TECH'!$E:$E)="Storage","",_xlfn.XLOOKUP($B11,'ELC TECH'!$H:$H,'ELC TECH'!AX:AX)) -> 0.66 | BD11: =IF(_xlfn.XLOOKUP($B11,'ELC TECH'!$H:$H,'ELC TECH'!$E:$E)="Storage","",_xlfn.XLOOKUP($B11,'ELC TECH'!$H:$H,'ELC TECH'!AY:AY)) -> 0.66 | BE11: =IF(_xlfn.XLOOKUP($B11,'ELC TECH'!$H:$H,'ELC TECH'!$E:$E)="Storage","",_xlfn.XLOOKUP($B11,'ELC TECH'!$H:$H,'ELC TECH'!AZ:AZ)) -> 0.66 | BF11: =IF(_xlfn.XLOOKUP($B11,'ELC TECH'!$H:$H,'ELC TECH'!$E:$E)="Storage",_xlfn.XLOOKUP($B11,'ELC TECH'!$H:$H,'ELC TECH'!AS:AS),"") | BG11: =IF(_xlfn.XLOOKUP($B11,'ELC TECH'!$H:$H,'ELC TECH'!$E:$E)="Storage",_xlfn.XLOOKUP($B11,'ELC TECH'!$H:$H,'ELC TECH'!AT:AT),"") | BH11: =IF(_xlfn.XLOOKUP($B11,'ELC TECH'!$H:$H,'ELC TECH'!$E:$E)="Storage",_xlfn.XLOOKUP($B11,'ELC TECH'!$H:$H,'ELC TECH'!AU:AU),"") | BI11: =IF(_xlfn.XLOOKUP($B11,'ELC TECH'!$H:$H,'ELC TECH'!$E:$E)="Storage",_xlfn.XLOOKUP($B11,'ELC TECH'!$H:$H,'ELC TECH'!AV:AV),"") | BJ11: =IF(_xlfn.XLOOKUP($B11,'ELC TECH'!$H:$H,'ELC TECH'!$E:$E)="Storage",_xlfn.XLOOKUP($B11,'ELC TECH'!$H:$H,'ELC TECH'!AW:AW),"") | BK11: =IF(_xlfn.XLOOKUP($B11,'ELC TECH'!$H:$H,'ELC TECH'!$E:$E)="Storage",_xlfn.XLOOKUP($B11,'ELC TECH'!$H:$H,'ELC TECH'!AX:AX),"") | BL11: =IF(_xlfn.XLOOKUP($B11,'ELC TECH'!$H:$H,'ELC TECH'!$E:$E)="Storage",_xlfn.XLOOKUP($B11,'ELC TECH'!$H:$H,'ELC TECH'!AY:AY),"") | BM11: =IF(_xlfn.XLOOKUP($B11,'ELC TECH'!$H:$H,'ELC TECH'!$E:$E)="Storage",_xlfn.XLOOKUP($B11,'ELC TECH'!$H:$H,'ELC TECH'!AZ:AZ),"") | BN11: =IF(_xlfn.XLOOKUP($B11,'ELC TECH'!$H:$H,'ELC TECH'!$E:$E)="Non Dispatchable",IFERROR($AX11*_xlfn.XLOOKUP($C11,$BM$1:$BM$3,BN$1:BN$3)/SUMPRODUCT(_xlfn.XLOOKUP($C11,$BM$1:$BM$3,$BN$1:$BY$3),$BN$4:$BY$4),""), "") | BO11: =IF(_xlfn.XLOOKUP($B11,'ELC TECH'!$H:$H,'ELC TECH'!$E:$E)="Non Dispatchable",IFERROR($AX11*_xlfn.XLOOKUP($C11,$BM$1:$BM$3,BO$1:BO$3)/SUMPRODUCT(_xlfn.XLOOKUP($C11,$BM$1:$BM$3,$BN$1:$BY$3),$BN$4:$BY$4),""), "") | BP11: =IF(_xlfn.XLOOKUP($B11,'ELC TECH'!$H:$H,'ELC TECH'!$E:$E)="Non Dispatchable",IFERROR($AX11*_xlfn.XLOOKUP($C11,$BM$1:$BM$3,BP$1:BP$3)/SUMPRODUCT(_xlfn.XLOOKUP($C11,$BM$1:$BM$3,$BN$1:$BY$3),$BN$4:$BY$4),""), "") | BQ11: =IF(_xlfn.XLOOKUP($B11,'ELC TECH'!$H:$H,'ELC TECH'!$E:$E)="Non Dispatchable",IFERROR($AX11*_xlfn.XLOOKUP($C11,$BM$1:$BM$3,BQ$1:BQ$3)/SUMPRODUCT(_xlfn.XLOOKUP($C11,$BM$1:$BM$3,$BN$1:$BY$3),$BN$4:$BY$4),""), "") | BR11: =IF(_xlfn.XLOOKUP($B11,'ELC TECH'!$H:$H,'ELC TECH'!$E:$E)="Non Dispatchable",IFERROR($AX11*_xlfn.XLOOKUP($C11,$BM$1:$BM$3,BR$1:BR$3)/SUMPRODUCT(_xlfn.XLOOKUP($C11,$BM$1:$BM$3,$BN$1:$BY$3),$BN$4:$BY$4),""), "") | BS11: =IF(_xlfn.XLOOKUP($B11,'ELC TECH'!$H:$H,'ELC TECH'!$E:$E)="Non Dispatchable",IFERROR($AX11*_xlfn.XLOOKUP($C11,$BM$1:$BM$3,BS$1:BS$3)/SUMPRODUCT(_xlfn.XLOOKUP($C11,$BM$1:$BM$3,$BN$1:$BY$3),$BN$4:$BY$4),""), "") | BT11: =IF(_xlfn.XLOOKUP($B11,'ELC TECH'!$H:$H,'ELC TECH'!$E:$E)="Non Dispatchable",IFERROR($AX11*_xlfn.XLOOKUP($C11,$BM$1:$BM$3,BT$1:BT$3)/SUMPRODUCT(_xlfn.XLOOKUP($C11,$BM$1:$BM$3,$BN$1:$BY$3),$BN$4:$BY$4),""), "") | BU11: =IF(_xlfn.XLOOKUP($B11,'ELC TECH'!$H:$H,'ELC TECH'!$E:$E)="Non Dispatchable",IFERROR($AX11*_xlfn.XLOOKUP($C11,$BM$1:$BM$3,BU$1:BU$3)/SUMPRODUCT(_xlfn.XLOOKUP($C11,$BM$1:$BM$3,$BN$1:$BY$3),$BN$4:$BY$4),""), "") | ... CK11: =IF(_xlfn.XLOOKUP($B11,'ELC TECH'!$H:$H,'ELC TECH'!$E:$E)="Non Dispatchable",IFERROR($AX11*_xlfn.XLOOKUP($C11,$BM$1:$BM$3,CK$1:CK$3)/SUMPRODUCT(_xlfn.XLOOKUP($C11,$BM$1:$BM$3,$BN$1:$BY$3),$BN$4:$BY$4),""), "") | CL11: =IF(_xlfn.XLOOKUP($B11,'ELC TECH'!$H:$H,'ELC TECH'!$E:$E)="Storage",CL$4*$BF11,"") | CM11: =IF(_xlfn.XLOOKUP($B11,'ELC TECH'!$H:$H,'ELC TECH'!$E:$E)="Storage",CM$4*$BF11,"") | CN11: =IF(_xlfn.XLOOKUP($B11,'ELC TECH'!$H:$H,'ELC TECH'!$E:$E)="Storage",CN$4*$BF11,"") | CO11: =IF(_xlfn.XLOOKUP($B11,'ELC TECH'!$H:$H,'ELC TECH'!$E:$E)="Storage",CO$4*$BF11,"") | CP11: =IF(_xlfn.XLOOKUP($B11,'ELC TECH'!$H:$H,'ELC TECH'!$E:$E)="Storage",CP$4*$BF11,"") | CQ11: =IF(_xlfn.XLOOKUP($B11,'ELC TECH'!$H:$H,'ELC TECH'!$E:$E)="Storage",CQ$4*$BF11,"") | CR11: =IF(_xlfn.XLOOKUP($B11,'ELC TECH'!$H:$H,'ELC TECH'!$E:$E)="Storage",CR$4*$BF11,"") | CS11: =IF(_xlfn.XLOOKUP($B11,'ELC TECH'!$H:$H,'ELC TECH'!$E:$E)="Storage",CS$4*$BF11,"") | ... DI11: =IF(_xlfn.XLOOKUP($B11,'ELC TECH'!$H:$H,'ELC TECH'!$E:$E)="Storage",DI$4*$BF11,"")
