Workbook

Sheet ReadMe
A1: Generic Comet (GC) TIMES Supply
B3: Sheet color
C4: Raw Data and Parameters
C6: City Specific Data
C8: Post processing for TIMES
C10: Table formatted for TIMES

Sheet >> City Data

Sheet City characteristics
B2: City Basic Data
B4: Calibration methodology | C4: GHG Inventory
B6: A. City Characteristics
B7: Data Item | C7: Value | D7: Units
B8: City Name | C8: New York
B9: Latitude | C9: 40.5
B10: Longitude | C10: -75
B11: County | C11: New York County
B12: State | C12: New York
B13: Census Division | C13: Middle Atlantic
B14: Climate Division | C14: Northeast
B15: Egrid Region | C15: NPCC NYC/Westchester
B16: Area of city (excluding water, natural and agricultural areas) | C16: 778 | D16: square kilometers
B17: * Division and Region Map can be found in the Maps sheet.
B18: B. Planning Base Year and Target Years
B19: Year | C19: Value | D19: Units
B20: Base Year | C20: 2019 | D20: Acceptable range [2018,2021]
B21: End Year | C21: 2050
B23: C. City Population and GDP
B24: Data Item | C24: Value | D24: Units
B25: Population in Base Year | C25: 8337 | D25: Thousand of people
B26: Annual population growth (Base Year - End Year) | C26: 0.5 | D26: % people
B27: GDP in Base Year | C27: 1206000 | D27: Million US$
B28: Annual GDP growth rate | C28: 2 | D28: % US$
B29: Share of manufacturing GDP | C29: 5 | D29: % US$
B30: Share of State population | C30: 0.42835123
B31: Share of State GDP | C31: 0.67251772
B32: Adjustment from state manufacturing GDP | C32: 1.0638298
B34: D. Climate Data
B35: Data Item | C35: 2000 | D35: 2050 | E35: 2100 | F35: Units
B36: Heating degree days (HDD) | C36: 4473.4625 | D36: 4066.4182 | E36: 3763.8582 | F36: F
B37: Cooling degree days (CDD) | C37: 1020.7333 | D37: 1224.2555 | E37: 1375.5355 | F37: F
B39: Data Item | C39: Value | D39: Units
B40: Correction from State HDD | C40: 0.72727402
B41: Correction from State CDD | C41: 1.5583715
B42: Annual precipitation | C42: 762 | D42: mm / year
B43: Climate change scenario | C43: RCP4.5
B44: Average temperature increase in 1980-2020 | C44: 1.4617857 | D44: F
B45: Forecasted average temperature increase in 2035-2065 | C45: 3.13 | D45: F
B46: Forecasted average temperature increase in 2070-2100 | C46: 4.37 | D46: F
...

Sheet >> GC_Resid

Sheet ELC RESID
O1: 2019 | P1: 2020 | Q1: 2025 | R1: 2030 | S1: 2035 | T1: 2040 | U1: 2045 | V1: 2050 | W1: 2055 | X1: 2060 | Y1: 2065 | Z1: 2070 | AA1: 2075 | AB1: 2080 | AC1: 2085 | AD1: 2090 | AE1: 2095 | AF1: 2100 | AG1: 2019 | AH1: 2030 | AI1: 2050 | AJ1: 2100 | AK1: 2019 | AL1: 2030 | AM1: 2050 | AN1: 2100 | AO1: 2019 | AP1: 2030 | AQ1: 2050 | AR1: 2100
A2: Sector | B2: Sub-sector | C2: Archetype | D2: Vintage | E2: End Use | F2: Technology | G2: Energy | H2: Technology Label | I2: Generation (TJ) | J2: Fuel Input (MWh) | K2: Capacity Factor (%) | L2: Efficiency (%) | M2: Fixed OM 2023 US$ / kW . Yr | N2: Variable OM 2023 US$ / GJ | O2: Capacity base year (MW) | P2: Capacity 2020 (MW) | Q2: Capacity 2025 (MW) | R2: Capacity 2030 (MW) | S2: Capacity 2035 (MW) | T2: Capacity 2040 (MW) | U2: Capacity 2045 (MW) | V2: Capacity 2050 (MW) | W2: Capacity 2055 (MW) | X2: Capacity 2060 (MW) | Y2: Capacity 2065 (MW) | Z2: Capacity 2070 (MW) | AA2: Capacity 2075 (MW) | AB2: Capacity 2080 (MW) | AC2: Capacity 2085 (MW) | AD2: Capacity 2090 (MW) | AE2: Capacity 2095 (MW) | AF2: Capacity 2100 (MW) | AG2: Average CO2 emission factor ( t CO2 / TJ) | AH2: Average CO2 emission factor ( t CO2 / TJ) | AI2: Average CO2 emission factor ( t CO2 / TJ) | AJ2: Average CO2 emission factor ( t CO2 / TJ) | AK2: Average CH4 emission factor ( t CH4 / TJ) | AL2: Average CH4 emission factor ( t CH4 / TJ) | AM2: Average CH4 emission factor ( t CH4 / TJ) | AN2: Average CH4 emission factor ( t CH4 / TJ) | AO2: Average N2O emission factor ( t N2O / TJ) | AP2: Average N2O emission factor ( t N2O / TJ) | AQ2: Average N2O emission factor ( t N2O / TJ) | AR2: Average N2O emission factor ( t N2O / TJ)
A3: Electricity | B3: Grid | D3: 2019 | E3: Dispatchable | F3: Combustion turbine | G3: Natural gas | H3: ELCNGAGRDCTU19 | I3: 12173.114 | J3: 34569.709 | K3: 0.13746195 | L3: 0.35213238 | M3: 27.138389 | N3: 2.0228151 | O3: 2808.1 | P3: 1517.2 | Q3: 1517.2 | R3: 1517.2 | S3: 1517.2 | T3: 681.9 | U3: 677.3 | V3: 139.5 | W3: 0 | X3: 0 | Y3: 0 | Z3: 0 | AA3: 0 | AB3: 0 | AC3: 0 | AD3: 0 | AE3: 0 | AF3: 0
A4: Electricity | B4: Grid | D4: 2019 | E4: Dispatchable | F4: Steam turbine | G4: Natural gas | H4: ELCNGAGRDSTU19 | I4: 10774.678 | J4: 29246.467 | K4: 0.084997091 | L4: 0.36840957 | M4: 27.138389 | N4: 2.0228151 | O4: 4019.7 | P4: 16 | Q4: 16 | R4: 16 | S4: 16 | T4: 16 | U4: 16 | V4: 0 | W4: 0 | X4: 0 | Y4: 0 | Z4: 0 | AA4: 0 | AB4: 0 | AC4: 0 | AD4: 0 | AE4: 0 | AF4: 0
A5: Electricity | B5: Grid | D5: 2019 | E5: Dispatchable | F5: Combined cycle combustion turbine | G5: Natural gas | H5: ELCNGAGRDCCC19 | I5: 46780.596 | J5: 91771.957 | K5: 0.64588452 | L5: 0.50974827 | M5: 35.166828 | N5: 0.61563937 | O5: 2296.7 | P5: 2296.7 | Q5: 2296.7 | R5: 1726.5 | S5: 1484.5 | T5: 751 | U5: 400 | V5: 0 | W5: 0 | X5: 0 | Y5: 0 | Z5: 0 | AA5: 0 | AB5: 0 | AC5: 0 | AD5: 0 | AE5: 0 | AF5: 0
A6: Electricity | B6: Grid | D6: 2019 | E6: Dispatchable | F6: Combined cycle steam turbine | G6: Natural gas | H6: ELCNGAGRDCCS19 | I6: 17753.904 | J6: 34991.141 | K6: 0.47892182 | L6: 0.50738283 | M6: 35.166828 | N6: 0.61563937 | O6: 1175.5 | P6: 1173.1 | Q6: 1173.1 | R6: 860.5 | S6: 780.5 | T6: 505 | U6: 250 | V6: 0 | W6: 0 | X6: 0 | Y6: 0 | Z6: 0 | AA6: 0 | AB6: 0 | AC6: 0 | AD6: 0 | AE6: 0 | AF6: 0
A7: Electricity | B7: Grid | D7: 2019 | E7: Dispatchable | F7: Combined cycle - single shaft | G7: Natural gas | H7: ELCNGAGRDACC19 | I7: 0 | J7: 0 | M7: 34.827599 | N7: 0.61563937 | O7: 0 | P7: 0 | Q7: 0 | R7: 0 | S7: 0 | T7: 0 | U7: 0 | V7: 0 | W7: 0 | X7: 0 | Y7: 0 | Z7: 0 | AA7: 0 | AB7: 0 | AC7: 0 | AD7: 0 | AE7: 0 | AF7: 0
A8: Electricity | B8: Grid | D8: 2019 | E8: Dispatchable | F8: Other turbine | G8: Natural gas | H8: ELCNGAGRDOTT19 | I8: 0 | J8: 0 | M8: 34.827599 | N8: 0.61563937 | O8: 0 | P8: 0 | Q8: 0 | R8: 0 | S8: 0 | T8: 0 | U8: 0 | V8: 0 | W8: 0 | X8: 0 | Y8: 0 | Z8: 0 | AA8: 0 | AB8: 0 | AC8: 0 | AD8: 0 | AE8: 0 | AF8: 0
A9: Electricity | B9: Grid | D9: 2019 | E9: Dispatchable | F9: Internal combustion engine | G9: Natural gas | H9: ELCNGAGRDICE19 | I9: 234.73082 | J9: 538.0716 | K9: 0.23406495 | L9: 0.43624458 | M9: 27.138389 | N9: 2.0228151 | O9: 31.8 | P9: 31.8 | Q9: 31.8 | R9: 23.4 | S9: 22.5 | T9: 22.3 | U9: 2.4 | V9: 0 | W9: 0 | X9: 0 | Y9: 0 | Z9: 0 | AA9: 0 | AB9: 0 | AC9: 0 | AD9: 0 | AE9: 0 | AF9: 0
A10: Electricity | B10: Grid | D10: 2019 | E10: Dispatchable | F10: Fuel cell | G10: Natural gas | H10: ELCNGAGRDFCE19 | I10: 192.024 | J10: 392.5061 | K10: 0.92258198 | L10: 0.48922552 | M10: 34.827599 | N10: 0.61563937 | O10: 6.6 | P10: 6.6 | Q10: 6.6 | R10: 6.6 | S10: 6.6 | T10: 6.6 | U10: 6.6 | V10: 6.6 | W10: 0 | X10: 0 | Y10: 0 | Z10: 0 | AA10: 0 | AB10: 0 | AC10: 0 | AD10: 0 | AE10: 0 | AF10: 0
A11: Electricity | B11: Grid | D11: 2019 | E11: Dispatchable | F11: Combustion turbine | G11: RNG | H11: ELCRNGGRDCTU19 | I11: 0 | J11: 0 | M11: 27.138389 | N11: 2.0228151 | O11: 0 | P11: 0 | Q11: 0 | R11: 0 | S11: 0 | T11: 0 | U11: 0 | V11: 0 | W11: 0 | X11: 0 | Y11: 0 | Z11: 0 | AA11: 0 | AB11: 0 | AC11: 0 | AD11: 0 | AE11: 0 | AF11: 0
A12: Electricity | B12: Grid | D12: 2019 | E12: Dispatchable | F12: Steam turbine | G12: RNG | H12: ELCRNGGRDSTU19 | I12: 0 | J12: 0 | M12: 27.138389 | N12: 2.0228151 | O12: 0 | P12: 0 | Q12: 0 | R12: 0 | S12: 0 | T12: 0 | U12: 0 | V12: 0 | W12: 0 | X12: 0 | Y12: 0 | Z12: 0 | AA12: 0 | AB12: 0 | AC12: 0 | AD12: 0 | AE12: 0 | AF12: 0
A13: Electricity | B13: Grid | D13: 2019 | E13: Dispatchable | F13: Combined cycle combustion turbine | G13: RNG | H13: ELCRNGGRDCCC19 | I13: 0 | J13: 0 | M13: 35.166828 | N13: 0.61563937 | O13: 0 | P13: 0 | Q13: 0 | R13: 0 | S13: 0 | T13: 0 | U13: 0 | V13: 0 | W13: 0 | X13: 0 | Y13: 0 | Z13: 0 | AA13: 0 | AB13: 0 | AC13: 0 | AD13: 0 | AE13: 0 | AF13: 0
A14: Electricity | B14: Grid | D14: 2019 | E14: Dispatchable | F14: Combined cycle steam turbine | G14: RNG | H14: ELCRNGGRDCCS19 | I14: 0 | J14: 0 | M14: 35.166828 | N14: 0.61563937 | O14: 0 | P14: 0 | Q14: 0 | R14: 0 | S14: 0 | T14: 0 | U14: 0 | V14: 0 | W14: 0 | X14: 0 | Y14: 0 | Z14: 0 | AA14: 0 | AB14: 0 | AC14: 0 | AD14: 0 | AE14: 0 | AF14: 0
A15: Electricity | B15: Grid | D15: 2019 | E15: Dispatchable | F15: Internal combustion engine | G15: RNG | H15: ELCRNGGRDICE19 | I15: 0 | J15: 0 | M15: 27.138389 | N15: 2.0228151 | O15: 0 | P15: 0 | Q15: 0 | R15: 0 | S15: 0 | T15: 0 | U15: 0 | V15: 0 | W15: 0 | X15: 0 | Y15: 0 | Z15: 0 | AA15: 0 | AB15: 0 | AC15: 0 | AD15: 0 | AE15: 0 | AF15: 0
A16: Electricity | B16: Grid | D16: 2019 | E16: Dispatchable | F16: Fuel cell | G16: RNG | H16: ELCRNGGRDFCE19 | I16: 0 | J16: 0 | M16: 34.827599 | N16: 0.61563937 | O16: 0 | P16: 0 | Q16: 0 | R16: 0 | S16: 0 | T16: 0 | U16: 0 | V16: 0 | W16: 0 | X16: 0 | Y16: 0 | Z16: 0 | AA16: 0 | AB16: 0 | AC16: 0 | AD16: 0 | AE16: 0 | AF16: 0
A17: Electricity | B17: Grid | D17: 2019 | E17: Dispatchable | F17: Combustion turbine | G17: Fuel oil | H17: ELCFOIGRDCTU19 | I17: 16.1352 | J17: 99.921256 | K17: 0.0013132542 | L17: 0.16147915 | M17: 27.138389 | N17: 2.0228151 | O17: 389.6 | P17: 0 | Q17: 0 | R17: 0 | S17: 0 | T17: 0 | U17: 0 | V17: 0 | W17: 0 | X17: 0 | Y17: 0 | Z17: 0 | AA17: 0 | AB17: 0 | AC17: 0 | AD17: 0 | AE17: 0 | AF17: 0
A18: Electricity | B18: Grid | D18: 2019 | E18: Dispatchable | F18: Steam turbine | G18: Fuel oil | H18: ELCFOIGRDSTU19 | I18: 0 | J18: 0 | M18: 27.138389 | N18: 2.0228151 | O18: 0 | P18: 0 | Q18: 0 | R18: 0 | S18: 0 | T18: 0 | U18: 0 | V18: 0 | W18: 0 | X18: 0 | Y18: 0 | Z18: 0 | AA18: 0 | AB18: 0 | AC18: 0 | AD18: 0 | AE18: 0 | AF18: 0
A19: Electricity | B19: Grid | D19: 2019 | E19: Dispatchable | F19: Combined cycle combustion turbine | G19: Fuel oil | H19: ELCFOIGRDCCC19 | I19: 0 | J19: 0 | M19: 35.166828 | N19: 0.61563937 | O19: 0 | P19: 0 | Q19: 0 | R19: 0 | S19: 0 | T19: 0 | U19: 0 | V19: 0 | W19: 0 | X19: 0 | Y19: 0 | Z19: 0 | AA19: 0 | AB19: 0 | AC19: 0 | AD19: 0 | AE19: 0 | AF19: 0
A20: Electricity | B20: Grid | D20: 2019 | E20: Dispatchable | F20: Combined cycle steam turbine | G20: Fuel oil | H20: ELCFOIGRDCCS19 | I20: 0 | J20: 0 | M20: 35.166828 | N20: 0.61563937 | O20: 0 | P20: 0 | Q20: 0 | R20: 0 | S20: 0 | T20: 0 | U20: 0 | V20: 0 | W20: 0 | X20: 0 | Y20: 0 | Z20: 0 | AA20: 0 | AB20: 0 | AC20: 0 | AD20: 0 | AE20: 0 | AF20: 0
A21: Electricity | B21: Grid | D21: 2019 | E21: Dispatchable | F21: Other turbine | G21: Fuel oil | H21: ELCFOIGRDOTT19 | I21: 0 | J21: 0 | M21: 35.166828 | N21: 0.61563937 | O21: 0 | P21: 0 | Q21: 0 | R21: 0 | S21: 0 | T21: 0 | U21: 0 | V21: 0 | W21: 0 | X21: 0 | Y21: 0 | Z21: 0 | AA21: 0 | AB21: 0 | AC21: 0 | AD21: 0 | AE21: 0 | AF21: 0
A22: Electricity | B22: Grid | D22: 2019 | E22: Dispatchable | F22: Internal combustion engine | G22: Fuel oil | H22: ELCFOIGRDICE19 | I22: 8.6313024 | J22: 31.086118 | K22: 0.0012700548 | L22: 0.27765778 | M22: 34.827599 | N22: 0.61563937 | O22: 215.5 | P22: 186.1 | Q22: 178.8 | R22: 172 | S22: 141.7 | T22: 105 | U22: 55.6 | V22: 13 | W22: 0 | X22: 0 | Y22: 0 | Z22: 0 | AA22: 0 | AB22: 0 | AC22: 0 | AD22: 0 | AE22: 0 | AF22: 0
A23: Electricity | B23: Grid | D23: 2019 | E23: Dispatchable | F23: Steam turbine | G23: Coal | H23: ELCCOAGRDSTU19 | I23: 0 | J23: 0 | M23: 87.747456 | N23: 2.6573005 | O23: 0 | P23: 0 | Q23: 0 | R23: 0 | S23: 0 | T23: 0 | U23: 0 | V23: 0 | W23: 0 | X23: 0 | Y23: 0 | Z23: 0 | AA23: 0 | AB23: 0 | AC23: 0 | AD23: 0 | AE23: 0 | AF23: 0
A24: Electricity | B24: Grid | D24: 2019 | E24: Dispatchable | F24: Other turbine | G24: Coal | H24: ELCCOAGRDOTT19 | I24: 0 | J24: 0 | M24: 169.72801 | N24: 4.6392824 | O24: 0 | P24: 0 | Q24: 0 | R24: 0 | S24: 0 | T24: 0 | U24: 0 | V24: 0 | W24: 0 | X24: 0 | Y24: 0 | Z24: 0 | AA24: 0 | AB24: 0 | AC24: 0 | AD24: 0 | AE24: 0 | AF24: 0
A25: Electricity | B25: Grid | D25: 2019 | E25: Dispatchable | F25: Steam turbine | G25: Biomass | H25: ELCBIOGRDSTU19 | I25: 0 | J25: 0 | M25: 177.77906 | N25: 1.5830727 | O25: 0 | P25: 0 | Q25: 0 | R25: 0 | S25: 0 | T25: 0 | U25: 0 | V25: 0 | W25: 0 | X25: 0 | Y25: 0 | Z25: 0 | AA25: 0 | AB25: 0 | AC25: 0 | AD25: 0 | AE25: 0 | AF25: 0
A26: Electricity | B26: Grid | D26: 2019 | E26: Dispatchable | F26: Other turbine | G26: Biomass | H26: ELCBIOGRDOTT19 | I26: 0 | J26: 0 | M26: 177.77906 | N26: 1.5830727 | O26: 0 | P26: 0 | Q26: 0 | R26: 0 | S26: 0 | T26: 0 | U26: 0 | V26: 0 | W26: 0 | X26: 0 | Y26: 0 | Z26: 0 | AA26: 0 | AB26: 0 | AC26: 0 | AD26: 0 | AE26: 0 | AF26: 0
A27: Electricity | B27: Grid | D27: 2019 | E27: Dispatchable | F27: Internal combustion engine | G27: Other bioenergy | H27: ELCOTBGRDICE19 | I27: 0 | J27: 0 | M27: 177.77906 | N27: 1.5830727 | O27: 0 | P27: 0 | Q27: 0 | R27: 0 | S27: 0 | T27: 0 | U27: 0 | V27: 0 | W27: 0 | X27: 0 | Y27: 0 | Z27: 0 | AA27: 0 | AB27: 0 | AC27: 0 | AD27: 0 | AE27: 0 | AF27: 0
A28: Electricity | B28: Grid | D28: 2019 | E28: Dispatchable | F28: Steam turbine | G28: Waste | H28: ELCWASGRDSTU19 | I28: 1357.2108 | J28: 7369.616 | K28: 0.72088563 | L28: 0.18416303 | M28: 177.77906 | N28: 1.5830727 | O28: 59.7 | P28: 59.7 | Q28: 59.7 | R28: 59.7 | S28: 0 | T28: 0 | U28: 0 | V28: 0 | W28: 0 | X28: 0 | Y28: 0 | Z28: 0 | AA28: 0 | AB28: 0 | AC28: 0 | AD28: 0 | AE28: 0 | AF28: 0
A29: Electricity | B29: Grid | D29: 2019 | E29: Dispatchable | F29: Steam turbine | G29: Waste heat | H29: ELCHETGRDSTU19 | I29: 0 | J29: 0 | M29: 177.77906 | N29: 1.5830727 | O29: 0 | P29: 0 | Q29: 0 | R29: 0 | S29: 0 | T29: 0 | U29: 0 | V29: 0 | W29: 0 | X29: 0 | Y29: 0 | Z29: 0 | AA29: 0 | AB29: 0 | AC29: 0 | AD29: 0 | AE29: 0 | AF29: 0
A30: Electricity | B30: Grid | D30: 2019 | E30: Dispatchable | F30: Other turbine | G30: Waste heat | H30: ELCHETGRDOTT19 | I30: 0 | J30: 0 | M30: 177.77906 | N30: 1.5830727 | O30: 0 | P30: 0 | Q30: 0 | R30: 0 | S30: 0 | T30: 0 | U30: 0 | V30: 0 | W30: 0 | X30: 0 | Y30: 0 | Z30: 0 | AA30: 0 | AB30: 0 | AC30: 0 | AD30: 0 | AE30: 0 | AF30: 0
A31: Electricity | B31: Grid | D31: 2019 | E31: Dispatchable | F31: Steam turbine | G31: Steam | H31: ELCSTMGRDSTU19 | I31: 0 | J31: 0 | M31: 177.77906 | N31: 1.5830727 | O31: 0 | P31: 0 | Q31: 0 | R31: 0 | S31: 0 | T31: 0 | U31: 0 | V31: 0 | W31: 0 | X31: 0 | Y31: 0 | Z31: 0 | AA31: 0 | AB31: 0 | AC31: 0 | AD31: 0 | AE31: 0 | AF31: 0
A32: Electricity | B32: Grid | D32: 2019 | E32: Dispatchable | F32: Steam turbine | G32: Uranium | H32: ELCURNGRDSTU19 | I32: 60101.435 | J32: 182125.56 | K32: 0.82466638 | L32: 0.33 | M32: 172.01215 | N32: 0.77583125 | O32: 2311 | P32: 2311 | Q32: 0 | R32: 0 | S32: 0 | T32: 0 | U32: 0 | V32: 0 | W32: 0 | X32: 0 | Y32: 0 | Z32: 0 | AA32: 0 | AB32: 0 | AC32: 0 | AD32: 0 | AE32: 0 | AF32: 0
A33: Electricity | B33: Grid | D33: 2019 | E33: Storage | F33: Compressed air energy storage | G33: Storage | H33: ELCSTGGRDCES19 | I33: 0 | J33: 0 | M33: 44.870272 | N33: 0 | O33: 0 | P33: 0 | Q33: 0 | R33: 0 | S33: 0 | T33: 0 | U33: 0 | V33: 0 | W33: 0 | X33: 0 | Y33: 0 | Z33: 0 | AA33: 0 | AB33: 0 | AC33: 0 | AD33: 0 | AE33: 0 | AF33: 0
A34: Electricity | B34: Grid | D34: 2019 | E34: Storage | F34: Flywheel energy storage | G34: Storage | H34: ELCSTGGRDFES19 | I34: 0 | J34: 0 | M34: 44.870272 | N34: 0 | O34: 0 | P34: 0 | Q34: 0 | R34: 0 | S34: 0 | T34: 0 | U34: 0 | V34: 0 | W34: 0 | X34: 0 | Y34: 0 | Z34: 0 | AA34: 0 | AB34: 0 | AC34: 0 | AD34: 0 | AE34: 0 | AF34: 0
A35: Electricity | B35: Grid | D35: 2019 | E35: Storage | F35: Battery energy storage | G35: Storage | H35: ELCSTGGRDBES19 | I35: 0 | J35: 0 | L35: 0.8 | M35: 44.870272 | N35: 0 | O35: 0 | P35: 0 | Q35: 0 | R35: 0 | S35: 0 | T35: 0 | U35: 0 | V35: 0 | W35: 0 | X35: 0 | Y35: 0 | Z35: 0 | AA35: 0 | AB35: 0 | AC35: 0 | AD35: 0 | AE35: 0 | AF35: 0
A36: Electricity | B36: Grid | D36: 2019 | E36: Baseload | F36: Steam turbine | G36: Geothermal | H36: ELCGEOGRDSTU19 | I36: 0 | J36: 0 | L36: 1 | M36: 170.80991 | N36: 0 | O36: 0 | P36: 0 | Q36: 0 | R36: 0 | S36: 0 | T36: 0 | U36: 0 | V36: 0 | W36: 0 | X36: 0 | Y36: 0 | Z36: 0 | AA36: 0 | AB36: 0 | AC36: 0 | AD36: 0 | AE36: 0 | AF36: 0
A37: Electricity | B37: Grid | D37: 2019 | E37: Baseload | F37: Binary cycle turbine | G37: Geothermal | H37: ELCGEOGRDBCT19 | I37: 0 | J37: 0 | L37: 1 | M37: 128.47969 | N37: 0 | O37: 0 | P37: 0 | Q37: 0 | R37: 0 | S37: 0 | T37: 0 | U37: 0 | V37: 0 | W37: 0 | X37: 0 | Y37: 0 | Z37: 0 | AA37: 0 | AB37: 0 | AC37: 0 | AD37: 0 | AE37: 0 | AF37: 0
A38: Electricity | B38: Grid | D38: 2019 | E38: Non Dispatchable | F38: Wind turbine - onshore | G38: Wind | H38: ELCWNDGRDWON19 | I38: 0 | J38: 0 | L38: 1 | M38: 34.974598 | N38: 0 | O38: 0 | P38: 0 | Q38: 0 | R38: 0 | S38: 0 | T38: 0 | U38: 0 | V38: 0 | W38: 0 | X38: 0 | Y38: 0 | Z38: 0 | AA38: 0 | AB38: 0 | AC38: 0 | AD38: 0 | AE38: 0 | AF38: 0
A39: Electricity | B39: Grid | D39: 2019 | E39: Non Dispatchable | F39: Wind turbine - offshore | G39: Wind | H39: ELCWNDGRDWOF19 | I39: 0 | J39: 0 | L39: 1 | M39: 112.55896 | N39: 0 | O39: 0 | P39: 0 | Q39: 0 | R39: 0 | S39: 0 | T39: 0 | U39: 0 | V39: 0 | W39: 0 | X39: 0 | Y39: 0 | Z39: 0 | AA39: 0 | AB39: 0 | AC39: 0 | AD39: 0 | AE39: 0 | AF39: 0
A40: Electricity | B40: Grid | D40: 2019 | E40: Storage | F40: Hydraulic turbine - reversible | G40: Storage | H40: ELCSTGGRDHES19 | I40: 0 | J40: 0 | L40: 0.7 | M40: 21.100097 | N40: 0.16961493 | O40: 0 | P40: 0 | Q40: 0 | R40: 0 | S40: 0 | T40: 0 | U40: 0 | V40: 0 | W40: 0 | X40: 0 | Y40: 0 | Z40: 0 | AA40: 0 | AB40: 0 | AC40: 0 | AD40: 0 | AE40: 0 | AF40: 0
...

Sheet >> TIMES

Sheet TRANS
B3: ~TFM_INS
B4: TimeSlice | C4: LimType | D4: Attribute | E4: Year | F4: EGRID | G4: CITY | H4: Attrib_Cond | I4: Val_Cond | J4: AllRegions | K4: Pset_Set | L4: Pset_PN | M4: Pset_PD | N4: Pset_CI | O4: Pset_CO | P4: Cset_Set | Q4: Cset_CN | R4: Cset_CD
D5: ACT_COST | E5: ='City characteristics'!$C$20 -> 2019 | F5: 1 | G5: 1 | L5: TU_CELC_EGRID_CITY_01 | Q5: CELC
D6: ACT_COST | E6: ='City characteristics'!$C$20 -> 2019 | F6: 1 | G6: 1 | L6: TU_CELC_CITY_EGRID_01 | Q6: CELC
D7: ACT_COST | E7: ='City characteristics'!$C$20 -> 2019 | F7: 1 | G7: 1 | L7: TU_CH2G_EGRID_CITY_01 | Q7: CH2G
D8: ACT_COST | E8: ='City characteristics'!$C$20 -> 2019 | F8: 1 | G8: 1 | L8: TU_CH2G_CITY_EGRID_01 | Q8: CH2G
D9: NCAP_COST | E9: ='City characteristics'!$C$20 -> 2019 | F9: 300 | G9: 0 | L9: TU_CELC_EGRID_CITY_01 | Q9: CELC
D10: NCAP_COST | E10: ='City characteristics'!$C$20 -> 2019 | F10: 0 | G10: 300 | L10: TU_CELC_CITY_EGRID_01 | Q10: CELC
D11: NCAP_COST | E11: ='City characteristics'!$C$20 -> 2019 | F11: 300 | G11: 0 | L11: TU_CH2G_EGRID_CITY_01 | Q11: CH2G
D12: NCAP_COST | E12: ='City characteristics'!$C$20 -> 2019 | F12: 0 | G12: 300 | L12: TU_CH2G_CITY_EGRID_01 | Q12: CH2G
D13: PRC_CAPACT | F13: =8760*0.0036 -> 31.536 | G13: =8760*0.0036 -> 31.536 | L13: TU_CELC_EGRID_CITY_01 | Q13: CELC
D14: PRC_CAPACT | F14: =8760*0.0036 -> 31.536 | G14: =8760*0.0036 -> 31.536 | L14: TU_CELC_CITY_EGRID_01 | Q14: CELC
D15: PRC_CAPACT | F15: =8760*0.0036 -> 31.536 | G15: =8760*0.0036 -> 31.536 | L15: TU_CH2G_EGRID_CITY_01 | Q15: CH2G
D16: PRC_CAPACT | F16: =8760*0.0036 -> 31.536 | G16: =8760*0.0036 -> 31.536 | L16: TU_CH2G_CITY_EGRID_01 | Q16: CH2G
D17: PRC_RESID | E17: ='City characteristics'!$C$20 -> 2019 | F17: ='ELC RESID'!$O$50 -> 17429.084 | G17: ='ELC RESID'!$O$50 -> 17429.084 | L17: TU_CELC_EGRID_CITY_01 | Q17: CELC
D18: PRC_RESID | E18: ='City characteristics'!$C$20 -> 2019 | F18: ='ELC RESID'!$O$50 -> 17429.084 | G18: ='ELC RESID'!$O$50 -> 17429.084 | L18: TU_CELC_CITY_EGRID_01 | Q18: CELC
D19: PRC_RESID | E19: ='City characteristics'!$C$20 -> 2019 | F19: ='ELC RESID'!$O$50 -> 17429.084 | G19: ='ELC RESID'!$O$50 -> 17429.084 | L19: TU_CH2G_EGRID_CITY_01 | Q19: CH2G
D20: PRC_RESID | E20: ='City characteristics'!$C$20 -> 2019 | F20: ='ELC RESID'!$O$50 -> 17429.084 | G20: ='ELC RESID'!$O$50 -> 17429.084 | L20: TU_CH2G_CITY_EGRID_01 | Q20: CH2G
D21: NCAP_PKCNT | E21: ='City characteristics'!$C$20 -> 2019 | F21: 1 | G21: 1 | L21: TU_CELC_EGRID_CITY_01 | Q21: CELC
D22: NCAP_PKCNT | E22: ='City characteristics'!$C$20 -> 2019 | F22: 1 | G22: 1 | L22: TU_CELC_CITY_EGRID_01 | Q22: CELC
