Workbook

Sheet Control
A3: ~InputCell: 1-30
A4: 4 | C4: 2 | D4: 3 | E4: 4 | F4: 5 | G4: 6 | H4: 7 | I4: 8 | J4: 9 | K4: 10
C5: =VLOOKUP($A$4,$B$8:$K$163,C$4,FALSE) -> CITYCap4 | D5: =VLOOKUP($A$4,$B$8:$K$163,D$4,FALSE) -> EGRIDCap4
C7: CITY | D7: EGRID
A8: ="Scen."&C8&"." -> Scen.CITYCap1. | B8: 1 | C8: CITYCap1 | D8: EGRIDCap1 | O8: =IF(D8=D$8,"",D$1&"-"&D8&".") | P8: =IF(E8=E$8,"",E$1&"-"&E8&".")
A9: ="Scen."&C9&"." -> Scen.CITYCap2. | B9: 2 | C9: CITYCap2 | D9: EGRIDCap2 | P9: =IF(E9=E$8,"",E$1&"-"&E9&".")
A10: ="Scen."&C10&"." -> Scen.CITYCap3. | B10: 3 | C10: CITYCap3 | D10: EGRIDCap3 | P10: =IF(E10=E$8,"",E$1&"-"&E10&".")
A11: ="Scen."&C11&"." -> Scen.CITYCap4. | B11: 4 | C11: CITYCap4 | D11: EGRIDCap4 | P11: =IF(E11=E$8,"",E$1&"-"&E11&".")
A12: ="Scen."&C12&"." -> Scen.CITYCap5. | B12: 5 | C12: CITYCap5 | D12: EGRIDCap5 | P12: =IF(E12=E$8,"",E$1&"-"&E12&".")
A13: ="Scen."&C13&"." -> Scen.CITYCap6. | B13: 6 | C13: CITYCap6 | D13: EGRIDCap6 | P13: =IF(E13=E$8,"",E$1&"-"&E13&".")
A14: ="Scen."&C14&"." -> Scen.CITYCap7. | B14: 7 | C14: CITYCap7 | D14: EGRIDCap7 | P14: =IF(E14=E$8,"",E$1&"-"&E14&".")
A15: ="Scen."&C15&"." -> Scen.CITYCap8. | B15: 8 | C15: CITYCap8 | D15: EGRIDCap8 | P15: =IF(E15=E$8,"",E$1&"-"&E15&".")
A16: ="Scen."&C16&"." -> Scen.CITYCap9. | B16: 9 | C16: CITYCap9 | D16: EGRIDCap9
A17: ="Scen."&C17&"." -> Scen.CITYCap10. | B17: 10 | C17: CITYCap10 | D17: EGRIDCap10
A18: ="Scen."&C18&"." -> Scen.CITYCap11. | B18: 11 | C18: CITYCap11 | D18: EGRIDCap11
A19: ="Scen."&C19&"." -> Scen.CITYCap12. | B19: 12 | C19: CITYCap12 | D19: EGRIDCap12
A20: ="Scen."&C20&"." -> Scen.CITYCap13. | B20: 13 | C20: CITYCap13 | D20: EGRIDCap13
A21: ="Scen."&C21&"." -> Scen.CITYCap14. | B21: 14 | C21: CITYCap14 | D21: EGRIDCap14
A22: ="Scen."&C22&"." -> Scen.CITYCap15. | B22: 15 | C22: CITYCap15 | D22: EGRIDCap15
A23: ="Scen."&C23&"." -> Scen.CITYCap16. | B23: 16 | C23: CITYCap16 | D23: EGRIDCap16
A24: ="Scen."&C24&"." -> Scen.CITYCap17. | B24: 17 | C24: CITYCap17 | D24: EGRIDCap17
A25: ="Scen."&C25&"." -> Scen.CITYCap18. | B25: 18 | C25: CITYCap18 | D25: EGRIDCap18
A26: ="Scen."&C26&"." -> Scen.CITYCap19. | B26: 19 | C26: CITYCap19 | D26: EGRIDCap19
A27: ="Scen."&C27&"." -> Scen.CITYCap20. | B27: 20 | C27: CITYCap20 | D27: EGRIDCap20
... A37: ="Scen."&C37&"." -> Scen.CITYCap30. | B37: 30 | C37: CITYCap30 | D37: EGRIDCap30

Sheet CITY
A1: =Control!$C$5 -> CITYCap4
I3: Scenario | J3: Commodity\Period | K3: 2019 | L3: 2020 | M3: 2021 | N3: 2022 | O3: 2023 | P3: 2024 | Q3: 2025 | R3: 2027 | S3: 2030 | T3: 2032 | U3: 2035 | V3: 2040 | W3: 2045 | X3: 2050 | Y3: 2055 | Z3: 2060 | AA3: 2065 | AB3: 2070 | AC3: 2075 | AD3: 2080 | AE3: 2085 | AF3: 2090 | AG3: 2095 | AH3: 2100
I4: REF | J4: CO2 | K4: =REF!C6 -> 17051794 | L4: =REF!D6 -> 17411913 | M4: =REF!E6 -> 17042314 | N4: =REF!F6 -> 16738951 | O4: =REF!G6 -> 16467807 | P4: =REF!H6 -> 16169641 | Q4: =REF!I6 -> 15909010 | R4: =REF!J6 -> 15481949 | ... AH4: =REF!Z6 -> 15256424
I5: NZ | J5: CO2 | K5: ='NZ50'!I6 -> 17051794 | L5: ='NZ50'!J6 -> 16529239 | M5: ='NZ50'!K6 -> 16006684 | N5: ='NZ50'!L6 -> 15484129 | O5: ='NZ50'!M6 -> 14961574 | P5: ='NZ50'!N6 -> 14439019 | Q5: ='NZ50'!O6 -> 13916464 | R5: ='NZ50'!P6 -> 12871354 | ... AH5: ='NZ50'!AF6 -> 852589.72
B6: ~UC_Sets: R_S: CITY
K7: 2019 | L7: 2020 | M7: 2021 | N7: 2022 | O7: 2023 | P7: 2024 | Q7: 2025 | R7: 2027 | S7: 2030 | T7: 2032 | U7: 2035 | V7: 2040 | W7: 2045 | X7: 2050 | Y7: 2055 | Z7: 2060 | AA7: 2065 | AB7: 2070 | AC7: 2075 | AD7: 2080 | AE7: 2085 | AF7: 2090 | AG7: 2095 | AH7: 2100
D8: ~UC_T: UC_RHST | J8: CITYCap1 | K8: =K$4 -> 17051794 | L8: =L$4 -> 17411913 | M8: =M$4 -> 17042314 | N8: =N4 -> 16738951 | O8: =O4 -> 16467807 | P8: =P4 -> 16169641 | Q8: =Q4 -> 15909010 | R8: =R4 -> 15481949 | S8: =S4 -> 14551152 | T8: =T4 -> 14083056 | U8: =U4 -> 13838793 | ... AH8: =AH4 -> 15256424
B9: UC_N | C9: Cset_CN | D9: Year | E9: UC_COMNET | F9: UC_RHST~UP | G9: UC_RHST~UP~0 | J9: CITYCap2 | K9: =K8-K$42 -> 17051794 | L9: =L8-L$42 -> 17380389 | M9: =M8-M$42 -> 17005328 | N9: =N8-N$42 -> 16694136 | O9: =O8-O$42 -> 16414013 | P9: =P8-P$42 -> 16107833 | Q9: =Q8-Q$42 -> 15837848 | R9: =R8-R$42 -> 15388714 | ... AH9: =AH8-AH$42 -> 14742002
B10: ="UC_"&$A$1 -> UC_CITYCap4 | C10: CO2 | D10: 2020 | E10: 1 | F10: =IFERROR(OFFSET($L$7,MATCH(CITY!$A$1,CITY!$J$8:$J$38,0),0),"") -> 17317341 | G10: 15 | J10: CITYCap3 | K10: =K9-K$42 -> 17051794 | L10: =L9-L$42 -> 17348865 | M10: =M9-M$42 -> 16968341 | N10: =N9-N$42 -> 16649321 | O10: =O9-O$42 -> 16360218 | P10: =P9-P$42 -> 16046025 | Q10: =Q9-Q$42 -> 15766686 | R10: =R9-R$42 -> 15295478 | ... AH10: =AH9-AH$42 -> 14227579
C11: CO2 | D11: 2021 | E11: 1 | F11: =IFERROR(OFFSET($M$7,MATCH(CITY!$A$1,CITY!$J$8:$J$38,0),0),"") -> 16931354 | J11: CITYCap4 | K11: =K10-K$42 -> 17051794 | L11: =L10-L$42 -> 17317341 | M11: =M10-M$42 -> 16931354 | N11: =N10-N$42 -> 16604506 | O11: =O10-O$42 -> 16306424 | P11: =P10-P$42 -> 15984217 | Q11: =Q10-Q$42 -> 15695523 | R11: =R10-R$42 -> 15202243 | ... AH11: =AH10-AH$42 -> 13713156
C12: CO2 | D12: 2022 | E12: 1 | F12: =IFERROR(OFFSET($N$7,MATCH(CITY!$A$1,CITY!$J$8:$J$38,0),0),"") -> 16604506 | J12: CITYCap5 | K12: =K11-K$42 -> 17051794 | L12: =L11-L$42 -> 17285817 | M12: =M11-M$42 -> 16894367 | N12: =N11-N$42 -> 16559691 | O12: =O11-O$42 -> 16252630 | P12: =P11-P$42 -> 15922409 | Q12: =Q11-Q$42 -> 15624361 | R12: =R11-R$42 -> 15109007 | ... AH12: =AH11-AH$42 -> 13198734
C13: CO2 | D13: 2023 | E13: 1 | F13: =IFERROR(OFFSET($O$7,MATCH(CITY!$A$1,CITY!$J$8:$J$38,0),0),"") -> 16306424 | J13: CITYCap6 | K13: =K12-K$42 -> 17051794 | L13: =L12-L$42 -> 17254292 | M13: =M12-M$42 -> 16857380 | N13: =N12-N$42 -> 16514876 | O13: =O12-O$42 -> 16198836 | P13: =P12-P$42 -> 15860602 | Q13: =Q12-Q$42 -> 15553199 | R13: =R12-R$42 -> 15015772 | ... AH13: =AH12-AH$42 -> 12684311
C14: CO2 | D14: 2024 | E14: 1 | F14: =IFERROR(OFFSET($P$7,MATCH(CITY!$A$1,CITY!$J$8:$J$38,0),0),"") -> 15984217 | J14: CITYCap7 | K14: =K13-K$42 -> 17051794 | L14: =L13-L$42 -> 17222768 | M14: =M13-M$42 -> 16820394 | N14: =N13-N$42 -> 16470061 | O14: =O13-O$42 -> 16145042 | P14: =P13-P$42 -> 15798794 | Q14: =Q13-Q$42 -> 15482036 | R14: =R13-R$42 -> 14922536 | ... AH14: =AH13-AH$42 -> 12169888
C15: CO2 | D15: 2025 | E15: 1 | F15: =IFERROR(OFFSET($Q$7,MATCH(CITY!$A$1,CITY!$J$8:$J$38,0),0),"") -> 15695523 | J15: CITYCap8 | K15: =K14-K$42 -> 17051794 | L15: =L14-L$42 -> 17191244 | M15: =M14-M$42 -> 16783407 | N15: =N14-N$42 -> 16425246 | O15: =O14-O$42 -> 16091248 | P15: =P14-P$42 -> 15736986 | Q15: =Q14-Q$42 -> 15410874 | R15: =R14-R$42 -> 14829301 | ... AH15: =AH14-AH$42 -> 11655466
C16: CO2 | D16: 2027 | E16: 1 | F16: =IFERROR(OFFSET($R$7,MATCH(CITY!$A$1,CITY!$J$8:$J$38,0),0),"") -> 15202243 | J16: CITYCap9 | K16: =K15-K$42 -> 17051794 | L16: =L15-L$42 -> 17159720 | M16: =M15-M$42 -> 16746420 | N16: =N15-N$42 -> 16380431 | O16: =O15-O$42 -> 16037454 | P16: =P15-P$42 -> 15675178 | Q16: =Q15-Q$42 -> 15339712 | R16: =R15-R$42 -> 14736065 | ... AH16: =AH15-AH$42 -> 11141043
C17: CO2 | D17: 2030 | E17: 1 | F17: =IFERROR(OFFSET($S$7,MATCH(CITY!$A$1,CITY!$J$8:$J$38,0),0),"") -> 14203210 | J17: CITYCap10 | K17: =K16-K$42 -> 17051794 | L17: =L16-L$42 -> 17128196 | M17: =M16-M$42 -> 16709433 | N17: =N16-N$42 -> 16335615 | O17: =O16-O$42 -> 15983660 | P17: =P16-P$42 -> 15613370 | Q17: =Q16-Q$42 -> 15268549 | R17: =R16-R$42 -> 14642830 | ... AH17: =AH16-AH$42 -> 10626620
C18: CO2 | D18: 2032 | E18: 1 | F18: =IFERROR(OFFSET($T$7,MATCH(CITY!$A$1,CITY!$J$8:$J$38,0),0),"") -> 13673291 | J18: CITYCap11 | K18: =K17-K$42 -> 17051794 | L18: =L17-L$42 -> 17096672 | M18: =M17-M$42 -> 16672447 | N18: =N17-N$42 -> 16290800 | O18: =O17-O$42 -> 15929866 | P18: =P17-P$42 -> 15551562 | Q18: =Q17-Q$42 -> 15197387 | R18: =R17-R$42 -> 14549594 | ... AH18: =AH17-AH$42 -> 10112198
C19: CO2 | D19: 2035 | E19: 1 | F19: =IFERROR(OFFSET($U$7,MATCH(CITY!$A$1,CITY!$J$8:$J$38,0),0),"") -> 13287235 | J19: CITYCap12 | K19: =K18-K$42 -> 17051794 | L19: =L18-L$42 -> 17065148 | M19: =M18-M$42 -> 16635460 | N19: =N18-N$42 -> 16245985 | O19: =O18-O$42 -> 15876072 | P19: =P18-P$42 -> 15489754 | Q19: =Q18-Q$42 -> 15126225 | R19: =R18-R$42 -> 14456359 | ... AH19: =AH18-AH$42 -> 9597774.9
C20: CO2 | D20: 2040 | E20: 1 | F20: =IFERROR(OFFSET($V$7,MATCH(CITY!$A$1,CITY!$J$8:$J$38,0),0),"") -> 12553866 | J20: CITYCap13 | K20: =K19-K$42 -> 17051794 | L20: =L19-L$42 -> 17033624 | M20: =M19-M$42 -> 16598473 | N20: =N19-N$42 -> 16201170 | O20: =O19-O$42 -> 15822278 | P20: =P19-P$42 -> 15427946 | Q20: =Q19-Q$42 -> 15055062 | R20: =R19-R$42 -> 14363123 | ... AH20: =AH19-AH$42 -> 9083352.3
C21: CO2 | D21: 2045 | E21: 1 | F21: =IFERROR(OFFSET($W$7,MATCH(CITY!$A$1,CITY!$J$8:$J$38,0),0),"") -> 12277934 | J21: CITYCap14 | K21: =K20-K$42 -> 17051794 | L21: =L20-L$42 -> 17002100 | M21: =M20-M$42 -> 16561486 | N21: =N20-N$42 -> 16156355 | O21: =O20-O$42 -> 15768484 | P21: =P20-P$42 -> 15366138 | Q21: =Q20-Q$42 -> 14983900 | R21: =R20-R$42 -> 14269887 | ... AH21: =AH20-AH$42 -> 8568929.6
C22: CO2 | D22: 2050 | E22: 1 | F22: =IFERROR(OFFSET($X$7,MATCH(CITY!$A$1,CITY!$J$8:$J$38,0),0),"") -> 12023115 | J22: CITYCap15 | K22: =K21-K$42 -> 17051794 | L22: =L21-L$42 -> 16970576 | M22: =M21-M$42 -> 16524499 | N22: =N21-N$42 -> 16111540 | O22: =O21-O$42 -> 15714690 | P22: =P21-P$42 -> 15304330 | Q22: =Q21-Q$42 -> 14912737 | R22: =R21-R$42 -> 14176652 | ... AH22: =AH21-AH$42 -> 8054507
C23: CO2 | D23: 2055 | E23: 1 | F23: =IFERROR(OFFSET($Y$7,MATCH(CITY!$A$1,CITY!$J$8:$J$38,0),0),"") -> 11807695 | J23: CITYCap16 | K23: =K22-K$42 -> 17051794 | L23: =L22-L$42 -> 16939052 | M23: =M22-M$42 -> 16487513 | N23: =N22-N$42 -> 16066725 | O23: =O22-O$42 -> 15660896 | P23: =P22-P$42 -> 15242522 | Q23: =Q22-Q$42 -> 14841575 | R23: =R22-R$42 -> 14083416 | ... AH23: =AH22-AH$42 -> 7540084.3
C24: CO2 | D24: 2060 | E24: 1 | F24: =IFERROR(OFFSET($Z$7,MATCH(CITY!$A$1,CITY!$J$8:$J$38,0),0),"") -> 11865441 | J24: CITYCap17 | K24: =K23-K$42 -> 17051794 | L24: =L23-L$42 -> 16907528 | M24: =M23-M$42 -> 16450526 | N24: =N23-N$42 -> 16021910 | O24: =O23-O$42 -> 15607102 | P24: =P23-P$42 -> 15180714 | Q24: =Q23-Q$42 -> 14770413 | R24: =R23-R$42 -> 13990181 | ... AH24: =AH23-AH$42 -> 7025661.6
C25: CO2 | D25: 2065 | E25: 1 | F25: =IFERROR(OFFSET($AA$7,MATCH(CITY!$A$1,CITY!$J$8:$J$38,0),0),"") -> 12086527 | J25: CITYCap18 | K25: =K24-K$42 -> 17051794 | L25: =L24-L$42 -> 16876004 | M25: =M24-M$42 -> 16413539 | N25: =N24-N$42 -> 15977095 | O25: =O24-O$42 -> 15553308 | P25: =P24-P$42 -> 15118907 | Q25: =Q24-Q$42 -> 14699250 | R25: =R24-R$42 -> 13896945 | ... AH25: =AH24-AH$42 -> 6511239
C26: CO2 | D26: 2070 | E26: 1 | F26: =IFERROR(OFFSET($AB$7,MATCH(CITY!$A$1,CITY!$J$8:$J$38,0),0),"") -> 12313633 | J26: CITYCap19 | K26: =K25-K$42 -> 17051794 | L26: =L25-L$42 -> 16844480 | M26: =M25-M$42 -> 16376552 | N26: =N25-N$42 -> 15932280 | O26: =O25-O$42 -> 15499514 | P26: =P25-P$42 -> 15057099 | Q26: =Q25-Q$42 -> 14628088 | R26: =R25-R$42 -> 13803710 | ... AH26: =AH25-AH$42 -> 5996816.3
C27: CO2 | D27: 2075 | E27: 1 | F27: =IFERROR(OFFSET($AC$7,MATCH(CITY!$A$1,CITY!$J$8:$J$38,0),0),"") -> 12542575 | J27: CITYCap20 | K27: =K26-K$42 -> 17051794 | L27: =L26-L$42 -> 16812956 | M27: =M26-M$42 -> 16339565 | N27: =N26-N$42 -> 15887465 | O27: =O26-O$42 -> 15445720 | P27: =P26-P$42 -> 14995291 | Q27: =Q26-Q$42 -> 14556926 | R27: =R26-R$42 -> 13710474 | ... AH27: =AH26-AH$42 -> 5482393.7
C28: CO2 | D28: 2080 | E28: 1 | F28: =IFERROR(OFFSET($AD$7,MATCH(CITY!$A$1,CITY!$J$8:$J$38,0),0),"") -> 12772756 | J28: CITYCap21 | K28: =K27-K$42 -> 17051794 | L28: =L27-L$42 -> 16781432 | M28: =M27-M$42 -> 16302579 | N28: =N27-N$42 -> 15842650 | O28: =O27-O$42 -> 15391926 | P28: =P27-P$42 -> 14933483 | Q28: =Q27-Q$42 -> 14485763 | R28: =R27-R$42 -> 13617239 | ... AH28: =AH27-AH$42 -> 4967971
C29: CO2 | D29: 2085 | E29: 1 | F29: =IFERROR(OFFSET($AE$7,MATCH(CITY!$A$1,CITY!$J$8:$J$38,0),0),"") -> 13004350 | J29: CITYCap22 | K29: =K28-K$42 -> 17051794 | L29: =L28-L$42 -> 16749908 | M29: =M28-M$42 -> 16265592 | N29: =N28-N$42 -> 15797835 | O29: =O28-O$42 -> 15338132 | P29: =P28-P$42 -> 14871675 | Q29: =Q28-Q$42 -> 14414601 | R29: =R28-R$42 -> 13524003 | ... AH29: =AH28-AH$42 -> 4453548.3
C30: CO2 | D30: 2090 | E30: 1 | F30: =IFERROR(OFFSET($AF$7,MATCH(CITY!$A$1,CITY!$J$8:$J$38,0),0),"") -> 13237248 | J30: CITYCap23 | K30: =K29-K$42 -> 17051794 | L30: =L29-L$42 -> 16718384 | M30: =M29-M$42 -> 16228605 | N30: =N29-N$42 -> 15753020 | O30: =O29-O$42 -> 15284338 | P30: =P29-P$42 -> 14809867 | Q30: =Q29-Q$42 -> 14343439 | R30: =R29-R$42 -> 13430768 | ... AH30: =AH29-AH$42 -> 3939125.7
C31: CO2 | D31: 2095 | E31: 1 | F31: =IFERROR(OFFSET($AG$7,MATCH(CITY!$A$1,CITY!$J$8:$J$38,0),0),"") -> 13473734 | J31: CITYCap24 | K31: =K30-K$42 -> 17051794 | L31: =L30-L$42 -> 16686860 | M31: =M30-M$42 -> 16191618 | N31: =N30-N$42 -> 15708205 | O31: =O30-O$42 -> 15230544 | P31: =P30-P$42 -> 14748059 | Q31: =Q30-Q$42 -> 14272276 | R31: =R30-R$42 -> 13337532 | ... AH31: =AH30-AH$42 -> 3424703
C32: CO2 | D32: 2100 | E32: 1 | F32: =IFERROR(OFFSET($AH$7,MATCH(CITY!$A$1,CITY!$J$8:$J$38,0),0),"") -> 13713156 | J32: CITYCap25 | K32: =K31-K$42 -> 17051794 | L32: =L31-L$42 -> 16655336 | M32: =M31-M$42 -> 16154631 | N32: =N31-N$42 -> 15663390 | O32: =O31-O$42 -> 15176750 | P32: =P31-P$42 -> 14686251 | Q32: =Q31-Q$42 -> 14201114 | R32: =R31-R$42 -> 13244297 | ... AH32: =AH31-AH$42 -> 2910280.4
J33: CITYCap26 | K33: =K32-K$42 -> 17051794 | L33: =L32-L$42 -> 16623811 | M33: =M32-M$42 -> 16117645 | N33: =N32-N$42 -> 15618575 | O33: =O32-O$42 -> 15122956 | P33: =P32-P$42 -> 14624443 | Q33: =Q32-Q$42 -> 14129951 | R33: =R32-R$42 -> 13151061 | ... AH33: =AH32-AH$42 -> 2395857.7
J34: CITYCap27 | K34: =K33-K$42 -> 17051794 | L34: =L33-L$42 -> 16592287 | M34: =M33-M$42 -> 16080658 | N34: =N33-N$42 -> 15573759 | O34: =O33-O$42 -> 15069162 | P34: =P33-P$42 -> 14562635 | Q34: =Q33-Q$42 -> 14058789 | R34: =R33-R$42 -> 13057825 | ... AH34: =AH33-AH$42 -> 1881435
J35: CITYCap28 | K35: =K34-K$42 -> 17051794 | L35: =L34-L$42 -> 16560763 | M35: =M34-M$42 -> 16043671 | N35: =N34-N$42 -> 15528944 | O35: =O34-O$42 -> 15015368 | P35: =P34-P$42 -> 14500827 | Q35: =Q34-Q$42 -> 13987627 | R35: =R34-R$42 -> 12964590 | ... AH35: =AH34-AH$42 -> 1367012.4
J36: CITYCap29 | K36: =K35-K$42 -> 17051794 | L36: =L35-L$42 -> 16529239 | M36: =M35-M$42 -> 16006684 | N36: =N35-N$42 -> 15484129 | O36: =O35-O$42 -> 14961574 | P36: =P35-P$42 -> 14439019 | Q36: =Q35-Q$42 -> 13916464 | R36: =R35-R$42 -> 12871354 | ... AH36: =AH35-AH$42 -> 852589.72
B37: ~TFM_INS | J37: CITYCap30 | K37: =K36-K$42 -> 17051794 | L37: =L36-L$42 -> 16497715 | M37: =M36-M$42 -> 15969698 | N37: =N36-N$42 -> 15439314 | O37: =O36-O$42 -> 14907780 | P37: =P36-P$42 -> 14377211 | Q37: =Q36-Q$42 -> 13845302 | R37: =R36-R$42 -> 12778119 | ... AH37: =AH36-AH$42 -> 338167.06
B38: TimeSlice | C38: LimType | D38: Attribute | E38: Year | F38: AllRegions | G38: Cset_CN
C39: LO | D39: COM_BNDNET | E39: 2020 | F39: -100000000 | G39: CO2
C40: LO | D40: COM_BNDNET | E40: 2050 | F40: -100000000 | G40: CO2
C41: LO | D41: COM_BNDNET | E41: 0 | F41: 5 | G41: CO2 | K41: =K4-K5 -> 0 | L41: =L4-L5 -> 882673.4 | M41: =M4-M5 -> 1035630.1 | N41: =N4-N5 -> 1254821.6 | O41: =O4-O5 -> 1506232.1 | P41: =P4-P5 -> 1730621.8 | Q41: =Q4-Q5 -> 1992546.1 | R41: =R4-R5 -> 2610595 | ... AH41: =AH4-AH5 -> 14403834
...

Sheet EGRID
A1: =Control!$D$5 -> EGRIDCap4
I3: Scenario | J3: Commodity\Period | K3: 2019 | L3: 2020 | M3: 2021 | N3: 2022 | O3: 2023 | P3: 2024 | Q3: 2025 | R3: 2027 | S3: 2030 | T3: 2032 | U3: 2035 | V3: 2040 | W3: 2045 | X3: 2050 | Y3: 2055 | Z3: 2060 | AA3: 2065 | AB3: 2070 | AC3: 2075 | AD3: 2080 | AE3: 2085 | AF3: 2090 | AG3: 2095 | AH3: 2100
I4: REF | J4: CO2 | K4: =REF!C7 -> 1.4015481e+08 | L4: =REF!D7 -> 1.1679105e+08 | M4: =REF!E7 -> 1.1207702e+08 | N4: =REF!F7 -> 1.0731871e+08 | O4: =REF!G7 -> 1.0268916e+08 | P4: =REF!H7 -> 98021451 | Q4: =REF!I7 -> 93480479 | R4: =REF!J7 -> 86474338 | ... AH4: =REF!Z7 -> 8727202.8
I5: NZ | J5: CO2 | K5: ='NZ50'!I8 -> 1.4015481e+08 | L5: ='NZ50'!J8 -> 1.3585975e+08 | M5: ='NZ50'!K8 -> 1.3156468e+08 | N5: ='NZ50'!L8 -> 1.2726961e+08 | O5: ='NZ50'!M8 -> 1.2297454e+08 | P5: ='NZ50'!N8 -> 1.1867948e+08 | Q5: ='NZ50'!O8 -> 1.1438441e+08 | R5: ='NZ50'!P8 -> 1.0579428e+08 | ... AH5: ='NZ50'!AF8 -> 7007740.6
B6: ~UC_Sets: R_S: EGRID
K7: 2019 | L7: 2020 | M7: 2021 | N7: 2022 | O7: 2023 | P7: 2024 | Q7: 2025 | R7: 2027 | S7: 2030 | T7: 2032 | U7: 2035 | V7: 2040 | W7: 2045 | X7: 2050 | Y7: 2055 | Z7: 2060 | AA7: 2065 | AB7: 2070 | AC7: 2075 | AD7: 2080 | AE7: 2085 | AF7: 2090 | AG7: 2095 | AH7: 2100
D8: ~UC_T: UC_RHST | J8: EGRIDCap1 | K8: =K$4 -> 1.4015481e+08 | L8: =L$4 -> 1.1679105e+08 | M8: =M$4 -> 1.1207702e+08 | N8: =N4 -> 1.0731871e+08 | O8: =O4 -> 1.0268916e+08 | P8: =P4 -> 98021451 | Q8: =Q4 -> 93480479 | R8: =R4 -> 86474338 | S8: =S4 -> 75821480 | T8: =T4 -> 71157764 | U8: =U4 -> 63660712 | ... AH8: =AH4 -> 8727202.8
B9: UC_N | C9: Cset_CN | D9: Year | E9: UC_COMNET | F9: UC_RHST~UP | G9: UC_RHST~UP~0 | J9: EGRIDCap2 | K9: =K8-K$42 -> 1.4015481e+08 | L9: =L8-L$42 -> 1.1747207e+08 | M9: =M8-M$42 -> 1.12773e+08 | N9: =N8-N$42 -> 1.0803124e+08 | O9: =O8-O$42 -> 1.0341364e+08 | P9: =P8-P$42 -> 98759238 | Q9: =Q8-Q$42 -> 94227048 | R9: =R8-R$42 -> 87164335 | ... AH9: =AH8-AH$42 -> 8665793.4
B10: ="UC_"&$A$1 -> UC_EGRIDCap4 | C10: CO2 | D10: 2020 | E10: 1 | F10: =IFERROR(OFFSET($L$7,MATCH(EGRID!$A$1,EGRID!$J$8:$J$38,0),0),"") -> 1.1883412e+08 | G10: 15 | J10: EGRIDCap3 | K10: =K9-K$42 -> 1.4015481e+08 | L10: =L9-L$42 -> 1.181531e+08 | M10: =M9-M$42 -> 1.1346899e+08 | N10: =N9-N$42 -> 1.0874377e+08 | O10: =O9-O$42 -> 1.0413812e+08 | P10: =P9-P$42 -> 99497025 | Q10: =Q9-Q$42 -> 94973617 | R10: =R9-R$42 -> 87854333 | ... AH10: =AH9-AH$42 -> 8604384.1
C11: CO2 | D11: 2021 | E11: 1 | F11: =IFERROR(OFFSET($M$7,MATCH(EGRID!$A$1,EGRID!$J$8:$J$38,0),0),"") -> 1.1416498e+08 | J11: EGRIDCap4 | K11: =K10-K$42 -> 1.4015481e+08 | L11: =L10-L$42 -> 1.1883412e+08 | M11: =M10-M$42 -> 1.1416498e+08 | N11: =N10-N$42 -> 1.094563e+08 | O11: =O10-O$42 -> 1.048626e+08 | P11: =P10-P$42 -> 1.0023481e+08 | Q11: =Q10-Q$42 -> 95720186 | R11: =R10-R$42 -> 88544331 | ... AH11: =AH10-AH$42 -> 8542974.7
C12: CO2 | D12: 2022 | E12: 1 | F12: =IFERROR(OFFSET($N$7,MATCH(EGRID!$A$1,EGRID!$J$8:$J$38,0),0),"") -> 1.094563e+08 | J12: EGRIDCap5 | K12: =K11-K$42 -> 1.4015481e+08 | L12: =L11-L$42 -> 1.1951515e+08 | M12: =M11-M$42 -> 1.1486097e+08 | N12: =N11-N$42 -> 1.1016884e+08 | O12: =O11-O$42 -> 1.0558707e+08 | P12: =P11-P$42 -> 1.009726e+08 | Q12: =Q11-Q$42 -> 96466755 | R12: =R11-R$42 -> 89234329 | ... AH12: =AH11-AH$42 -> 8481565.3
C13: CO2 | D13: 2023 | E13: 1 | F13: =IFERROR(OFFSET($O$7,MATCH(EGRID!$A$1,EGRID!$J$8:$J$38,0),0),"") -> 1.048626e+08 | J13: EGRIDCap6 | K13: =K12-K$42 -> 1.4015481e+08 | L13: =L12-L$42 -> 1.2019617e+08 | M13: =M12-M$42 -> 1.1555696e+08 | N13: =N12-N$42 -> 1.1088137e+08 | O13: =O12-O$42 -> 1.0631155e+08 | P13: =P12-P$42 -> 1.0171038e+08 | Q13: =Q12-Q$42 -> 97213324 | R13: =R12-R$42 -> 89924327 | ... AH13: =AH12-AH$42 -> 8420156
C14: CO2 | D14: 2024 | E14: 1 | F14: =IFERROR(OFFSET($P$7,MATCH(EGRID!$A$1,EGRID!$J$8:$J$38,0),0),"") -> 1.0023481e+08 | J14: EGRIDCap7 | K14: =K13-K$42 -> 1.4015481e+08 | L14: =L13-L$42 -> 1.208772e+08 | M14: =M13-M$42 -> 1.1625294e+08 | N14: =N13-N$42 -> 1.115939e+08 | O14: =O13-O$42 -> 1.0703603e+08 | P14: =P13-P$42 -> 1.0244817e+08 | Q14: =Q13-Q$42 -> 97959893 | R14: =R13-R$42 -> 90614325 | ... AH14: =AH13-AH$42 -> 8358746.6
C15: CO2 | D15: 2025 | E15: 1 | F15: =IFERROR(OFFSET($Q$7,MATCH(EGRID!$A$1,EGRID!$J$8:$J$38,0),0),"") -> 95720186 | J15: EGRIDCap8 | K15: =K14-K$42 -> 1.4015481e+08 | L15: =L14-L$42 -> 1.2155822e+08 | M15: =M14-M$42 -> 1.1694893e+08 | N15: =N14-N$42 -> 1.1230643e+08 | O15: =O14-O$42 -> 1.0776051e+08 | P15: =P14-P$42 -> 1.0318596e+08 | Q15: =Q14-Q$42 -> 98706462 | R15: =R14-R$42 -> 91304323 | ... AH15: =AH14-AH$42 -> 8297337.2
C16: CO2 | D16: 2027 | E16: 1 | F16: =IFERROR(OFFSET($R$7,MATCH(EGRID!$A$1,EGRID!$J$8:$J$38,0),0),"") -> 88544331 | J16: EGRIDCap9 | K16: =K15-K$42 -> 1.4015481e+08 | L16: =L15-L$42 -> 1.2223925e+08 | M16: =M15-M$42 -> 1.1764492e+08 | N16: =N15-N$42 -> 1.1301897e+08 | O16: =O15-O$42 -> 1.0848499e+08 | P16: =P15-P$42 -> 1.0392374e+08 | Q16: =Q15-Q$42 -> 99453031 | R16: =R15-R$42 -> 91994320 | ... AH16: =AH15-AH$42 -> 8235927.9
C17: CO2 | D17: 2030 | E17: 1 | F17: =IFERROR(OFFSET($S$7,MATCH(EGRID!$A$1,EGRID!$J$8:$J$38,0),0),"") -> 77652294 | J17: EGRIDCap10 | K17: =K16-K$42 -> 1.4015481e+08 | L17: =L16-L$42 -> 1.2292027e+08 | M17: =M16-M$42 -> 1.1834091e+08 | N17: =N16-N$42 -> 1.137315e+08 | O17: =O16-O$42 -> 1.0920946e+08 | P17: =P16-P$42 -> 1.0466153e+08 | Q17: =Q16-Q$42 -> 1.001996e+08 | R17: =R16-R$42 -> 92684318 | ... AH17: =AH16-AH$42 -> 8174518.5
C18: CO2 | D18: 2032 | E18: 1 | F18: =IFERROR(OFFSET($T$7,MATCH(EGRID!$A$1,EGRID!$J$8:$J$38,0),0),"") -> 72567890 | J18: EGRIDCap11 | K18: =K17-K$42 -> 1.4015481e+08 | L18: =L17-L$42 -> 1.236013e+08 | M18: =M17-M$42 -> 1.190369e+08 | N18: =N17-N$42 -> 1.1444403e+08 | O18: =O17-O$42 -> 1.0993394e+08 | P18: =P17-P$42 -> 1.0539932e+08 | Q18: =Q17-Q$42 -> 1.0094617e+08 | R18: =R17-R$42 -> 93374316 | ... AH18: =AH17-AH$42 -> 8113109.2
C19: CO2 | D19: 2035 | E19: 1 | F19: =IFERROR(OFFSET($U$7,MATCH(EGRID!$A$1,EGRID!$J$8:$J$38,0),0),"") -> 64493537 | J19: EGRIDCap12 | K19: =K18-K$42 -> 1.4015481e+08 | L19: =L18-L$42 -> 1.2428232e+08 | M19: =M18-M$42 -> 1.1973288e+08 | N19: =N18-N$42 -> 1.1515656e+08 | O19: =O18-O$42 -> 1.1065842e+08 | P19: =P18-P$42 -> 1.061371e+08 | Q19: =Q18-Q$42 -> 1.0169274e+08 | R19: =R18-R$42 -> 94064314 | ... AH19: =AH18-AH$42 -> 8051699.8
C20: CO2 | D20: 2040 | E20: 1 | F20: =IFERROR(OFFSET($V$7,MATCH(EGRID!$A$1,EGRID!$J$8:$J$38,0),0),"") -> 63665053 | J20: EGRIDCap13 | K20: =K19-K$42 -> 1.4015481e+08 | L20: =L19-L$42 -> 1.2496335e+08 | M20: =M19-M$42 -> 1.2042887e+08 | N20: =N19-N$42 -> 1.1586909e+08 | O20: =O19-O$42 -> 1.113829e+08 | P20: =P19-P$42 -> 1.0687489e+08 | Q20: =Q19-Q$42 -> 1.0243931e+08 | R20: =R19-R$42 -> 94754312 | ... AH20: =AH19-AH$42 -> 7990290.4
C21: CO2 | D21: 2045 | E21: 1 | F21: =IFERROR(OFFSET($W$7,MATCH(EGRID!$A$1,EGRID!$J$8:$J$38,0),0),"") -> 59411792 | J21: EGRIDCap14 | K21: =K20-K$42 -> 1.4015481e+08 | L21: =L20-L$42 -> 1.2564437e+08 | M21: =M20-M$42 -> 1.2112486e+08 | N21: =N20-N$42 -> 1.1658163e+08 | O21: =O20-O$42 -> 1.1210738e+08 | P21: =P20-P$42 -> 1.0761268e+08 | Q21: =Q20-Q$42 -> 1.0318588e+08 | R21: =R20-R$42 -> 95444310 | ... AH21: =AH20-AH$42 -> 7928881.1
C22: CO2 | D22: 2050 | E22: 1 | F22: =IFERROR(OFFSET($X$7,MATCH(EGRID!$A$1,EGRID!$J$8:$J$38,0),0),"") -> 54088444 | J22: EGRIDCap15 | K22: =K21-K$42 -> 1.4015481e+08 | L22: =L21-L$42 -> 1.263254e+08 | M22: =M21-M$42 -> 1.2182085e+08 | N22: =N21-N$42 -> 1.1729416e+08 | O22: =O21-O$42 -> 1.1283185e+08 | P22: =P21-P$42 -> 1.0835046e+08 | Q22: =Q21-Q$42 -> 1.0393244e+08 | R22: =R21-R$42 -> 96134308 | ... AH22: =AH21-AH$42 -> 7867471.7
C23: CO2 | D23: 2055 | E23: 1 | F23: =IFERROR(OFFSET($Y$7,MATCH(EGRID!$A$1,EGRID!$J$8:$J$38,0),0),"") -> 55309744 | J23: EGRIDCap16 | K23: =K22-K$42 -> 1.4015481e+08 | L23: =L22-L$42 -> 1.2700642e+08 | M23: =M22-M$42 -> 1.2251684e+08 | N23: =N22-N$42 -> 1.1800669e+08 | O23: =O22-O$42 -> 1.1355633e+08 | P23: =P22-P$42 -> 1.0908825e+08 | Q23: =Q22-Q$42 -> 1.0467901e+08 | R23: =R22-R$42 -> 96824305 | ... AH23: =AH22-AH$42 -> 7806062.3
C24: CO2 | D24: 2060 | E24: 1 | F24: =IFERROR(OFFSET($Z$7,MATCH(EGRID!$A$1,EGRID!$J$8:$J$38,0),0),"") -> 41031707 | J24: EGRIDCap17 | K24: =K23-K$42 -> 1.4015481e+08 | L24: =L23-L$42 -> 1.2768745e+08 | M24: =M23-M$42 -> 1.2321282e+08 | N24: =N23-N$42 -> 1.1871922e+08 | O24: =O23-O$42 -> 1.1428081e+08 | P24: =P23-P$42 -> 1.0982604e+08 | Q24: =Q23-Q$42 -> 1.0542558e+08 | R24: =R23-R$42 -> 97514303 | ... AH24: =AH23-AH$42 -> 7744653
C25: CO2 | D25: 2065 | E25: 1 | F25: =IFERROR(OFFSET($AA$7,MATCH(EGRID!$A$1,EGRID!$J$8:$J$38,0),0),"") -> 22728062 | J25: EGRIDCap18 | K25: =K24-K$42 -> 1.4015481e+08 | L25: =L24-L$42 -> 1.2836847e+08 | M25: =M24-M$42 -> 1.2390881e+08 | N25: =N24-N$42 -> 1.1943176e+08 | O25: =O24-O$42 -> 1.1500529e+08 | P25: =P24-P$42 -> 1.1056382e+08 | Q25: =Q24-Q$42 -> 1.0617215e+08 | R25: =R24-R$42 -> 98204301 | ... AH25: =AH24-AH$42 -> 7683243.6
C26: CO2 | D26: 2070 | E26: 1 | F26: =IFERROR(OFFSET($AB$7,MATCH(EGRID!$A$1,EGRID!$J$8:$J$38,0),0),"") -> 8316693.8 | J26: EGRIDCap19 | K26: =K25-K$42 -> 1.4015481e+08 | L26: =L25-L$42 -> 1.290495e+08 | M26: =M25-M$42 -> 1.246048e+08 | N26: =N25-N$42 -> 1.2014429e+08 | O26: =O25-O$42 -> 1.1572977e+08 | P26: =P25-P$42 -> 1.1130161e+08 | Q26: =Q25-Q$42 -> 1.0691872e+08 | R26: =R25-R$42 -> 98894299 | ... AH26: =AH25-AH$42 -> 7621834.2
C27: CO2 | D27: 2075 | E27: 1 | F27: =IFERROR(OFFSET($AC$7,MATCH(EGRID!$A$1,EGRID!$J$8:$J$38,0),0),"") -> 8377668.1 | J27: EGRIDCap20 | K27: =K26-K$42 -> 1.4015481e+08 | L27: =L26-L$42 -> 1.2973052e+08 | M27: =M26-M$42 -> 1.2530079e+08 | N27: =N26-N$42 -> 1.2085682e+08 | O27: =O26-O$42 -> 1.1645424e+08 | P27: =P26-P$42 -> 1.120394e+08 | Q27: =Q26-Q$42 -> 1.0766529e+08 | R27: =R26-R$42 -> 99584297 | ... AH27: =AH26-AH$42 -> 7560424.9
C28: CO2 | D28: 2080 | E28: 1 | F28: =IFERROR(OFFSET($AD$7,MATCH(EGRID!$A$1,EGRID!$J$8:$J$38,0),0),"") -> 8389634 | J28: EGRIDCap21 | K28: =K27-K$42 -> 1.4015481e+08 | L28: =L27-L$42 -> 1.3041155e+08 | M28: =M27-M$42 -> 1.2599677e+08 | N28: =N27-N$42 -> 1.2156935e+08 | O28: =O27-O$42 -> 1.1717872e+08 | P28: =P27-P$42 -> 1.1277718e+08 | Q28: =Q27-Q$42 -> 1.0841186e+08 | R28: =R27-R$42 -> 1.0027429e+08 | ... AH28: =AH27-AH$42 -> 7499015.5
C29: CO2 | D29: 2085 | E29: 1 | F29: =IFERROR(OFFSET($AE$7,MATCH(EGRID!$A$1,EGRID!$J$8:$J$38,0),0),"") -> 8398657.3 | J29: EGRIDCap22 | K29: =K28-K$42 -> 1.4015481e+08 | L29: =L28-L$42 -> 1.3109257e+08 | M29: =M28-M$42 -> 1.2669276e+08 | N29: =N28-N$42 -> 1.2228189e+08 | O29: =O28-O$42 -> 1.179032e+08 | P29: =P28-P$42 -> 1.1351497e+08 | Q29: =Q28-Q$42 -> 1.0915843e+08 | R29: =R28-R$42 -> 1.0096429e+08 | ... AH29: =AH28-AH$42 -> 7437606.1
C30: CO2 | D30: 2090 | E30: 1 | F30: =IFERROR(OFFSET($AF$7,MATCH(EGRID!$A$1,EGRID!$J$8:$J$38,0),0),"") -> 8498428.8 | J30: EGRIDCap23 | K30: =K29-K$42 -> 1.4015481e+08 | L30: =L29-L$42 -> 1.317736e+08 | M30: =M29-M$42 -> 1.2738875e+08 | N30: =N29-N$42 -> 1.2299442e+08 | O30: =O29-O$42 -> 1.1862768e+08 | P30: =P29-P$42 -> 1.1425276e+08 | Q30: =Q29-Q$42 -> 1.09905e+08 | R30: =R29-R$42 -> 1.0165429e+08 | ... AH30: =AH29-AH$42 -> 7376196.8
C31: CO2 | D31: 2095 | E31: 1 | F31: =IFERROR(OFFSET($AG$7,MATCH(EGRID!$A$1,EGRID!$J$8:$J$38,0),0),"") -> 8531569.7 | J31: EGRIDCap24 | K31: =K30-K$42 -> 1.4015481e+08 | L31: =L30-L$42 -> 1.3245462e+08 | M31: =M30-M$42 -> 1.2808474e+08 | N31: =N30-N$42 -> 1.2370695e+08 | O31: =O30-O$42 -> 1.1935216e+08 | P31: =P30-P$42 -> 1.1499054e+08 | Q31: =Q30-Q$42 -> 1.1065157e+08 | R31: =R30-R$42 -> 1.0234429e+08 | ... AH31: =AH30-AH$42 -> 7314787.4
C32: CO2 | D32: 2100 | E32: 1 | F32: =IFERROR(OFFSET($AH$7,MATCH(EGRID!$A$1,EGRID!$J$8:$J$38,0),0),"") -> 8542974.7 | J32: EGRIDCap25 | K32: =K31-K$42 -> 1.4015481e+08 | L32: =L31-L$42 -> 1.3313565e+08 | M32: =M31-M$42 -> 1.2878073e+08 | N32: =N31-N$42 -> 1.2441948e+08 | O32: =O31-O$42 -> 1.2007663e+08 | P32: =P31-P$42 -> 1.1572833e+08 | Q32: =Q31-Q$42 -> 1.1139814e+08 | R32: =R31-R$42 -> 1.0303429e+08 | ... AH32: =AH31-AH$42 -> 7253378.1
J33: EGRIDCap26 | K33: =K32-K$42 -> 1.4015481e+08 | L33: =L32-L$42 -> 1.3381667e+08 | M33: =M32-M$42 -> 1.2947671e+08 | N33: =N32-N$42 -> 1.2513201e+08 | O33: =O32-O$42 -> 1.2080111e+08 | P33: =P32-P$42 -> 1.1646612e+08 | Q33: =Q32-Q$42 -> 1.121447e+08 | R33: =R32-R$42 -> 1.0372428e+08 | ... AH33: =AH32-AH$42 -> 7191968.7
J34: EGRIDCap27 | K34: =K33-K$42 -> 1.4015481e+08 | L34: =L33-L$42 -> 1.344977e+08 | M34: =M33-M$42 -> 1.301727e+08 | N34: =N33-N$42 -> 1.2584455e+08 | O34: =O33-O$42 -> 1.2152559e+08 | P34: =P33-P$42 -> 1.172039e+08 | Q34: =Q33-Q$42 -> 1.1289127e+08 | R34: =R33-R$42 -> 1.0441428e+08 | ... AH34: =AH33-AH$42 -> 7130559.3
J35: EGRIDCap28 | K35: =K34-K$42 -> 1.4015481e+08 | L35: =L34-L$42 -> 1.3517872e+08 | M35: =M34-M$42 -> 1.3086869e+08 | N35: =N34-N$42 -> 1.2655708e+08 | O35: =O34-O$42 -> 1.2225007e+08 | P35: =P34-P$42 -> 1.1794169e+08 | Q35: =Q34-Q$42 -> 1.1363784e+08 | R35: =R34-R$42 -> 1.0510428e+08 | ... AH35: =AH34-AH$42 -> 7069150
J36: EGRIDCap29 | K36: =K35-K$42 -> 1.4015481e+08 | L36: =L35-L$42 -> 1.3585975e+08 | M36: =M35-M$42 -> 1.3156468e+08 | N36: =N35-N$42 -> 1.2726961e+08 | O36: =O35-O$42 -> 1.2297454e+08 | P36: =P35-P$42 -> 1.1867948e+08 | Q36: =Q35-Q$42 -> 1.1438441e+08 | R36: =R35-R$42 -> 1.0579428e+08 | ... AH36: =AH35-AH$42 -> 7007740.6
B37: ~TFM_INS | J37: EGRIDCap30 | K37: =K36-K$42 -> 1.4015481e+08 | L37: =L36-L$42 -> 1.3654077e+08 | M37: =M36-M$42 -> 1.3226067e+08 | N37: =N36-N$42 -> 1.2798214e+08 | O37: =O36-O$42 -> 1.2369902e+08 | P37: =P36-P$42 -> 1.1941726e+08 | Q37: =Q36-Q$42 -> 1.1513098e+08 | R37: =R36-R$42 -> 1.0648428e+08 | ... AH37: =AH36-AH$42 -> 6946331.2
B38: TimeSlice | C38: LimType | D38: Attribute | E38: Year | F38: AllRegions | G38: Cset_CN
C39: LO | D39: COM_BNDNET | E39: 2020 | F39: -100000000 | G39: CO2
C40: LO | D40: COM_BNDNET | E40: 2050 | F40: -100000000 | G40: CO2
C41: LO | D41: COM_BNDNET | E41: 0 | F41: 5 | G41: CO2 | K41: =K4-K5 -> 0 | L41: =L4-L5 -> -19068699 | M41: =M4-M5 -> -19487662 | N41: =N4-N5 -> -19950904 | O41: =O4-O5 -> -20285382 | P41: =P4-P5 -> -20658027 | Q41: =Q4-Q5 -> -20903932 | R41: =R4-R5 -> -19319940 | ... AH41: =AH4-AH5 -> 1719462.2
...

Sheet >>> Data

Sheet REF
A1: Table = _Emissions_for_GHG_constraint
A4: Sum of Pv | C4: Period
A5: Commodity | B5: Region | C5: 2019 | D5: 2020 | E5: 2021 | F5: 2022 | G5: 2023 | H5: 2024 | I5: 2025 | J5: 2027 | K5: 2030 | L5: 2032 | M5: 2035 | N5: 2040 | O5: 2045 | P5: 2050 | Q5: 2055 | R5: 2060 | S5: 2065 | T5: 2070 | U5: 2075 | V5: 2080 | W5: 2085 | X5: 2090 | Y5: 2095 | Z5: 2100
A6: CO2 | B6: CITY | C6: 17051794 | D6: 17411913 | E6: 17042314 | F6: 16738951 | G6: 16467807 | H6: 16169641 | I6: 15909010 | J6: 15481949 | K6: 14551152 | L6: 14083056 | M6: 13838793 | N6: 13330953 | O6: 13335442 | P6: 13363578 | Q6: 13122308 | R6: 13186984 | S6: 13434599 | T6: 13688958 | U6: 13945373 | V6: 14203176 | W6: 14462561 | X6: 14723407 | Y6: 14988271 | Z6: 15256424
A7: CO2 | B7: EGRID | C7: 1.4015481e+08 | D7: 1.1679105e+08 | E7: 1.1207702e+08 | F7: 1.0731871e+08 | G7: 1.0268916e+08 | H7: 98021451 | I7: 93480479 | J7: 86474338 | K7: 75821480 | L7: 71157764 | M7: 63660712 | N7: 65309850 | O7: 63123238 | P7: 59738128 | Q7: 61105985 | R7: 45114583 | S7: 24614500 | T7: 8473768.2 | U7: 8542059.4 | V7: 8555461.2 | W7: 8565567.3 | X7: 8677311.3 | Y7: 8714429.2 | Z7: 8727202.8
A8: GrandTotal | B8: GrandTotal | C8: 1.5720661e+08 | D8: 1.3420296e+08 | E8: 1.2911933e+08 | F8: 1.2405766e+08 | G8: 1.1915697e+08 | H8: 1.1419109e+08 | I8: 1.0938949e+08 | J8: 1.0195629e+08 | K8: 90372632 | L8: 85240820 | M8: 77499505 | N8: 78640803 | O8: 76458681 | P8: 73101707 | Q8: 74228293 | R8: 58301567 | S8: 38049099 | T8: 22162726 | U8: 22487432 | V8: 22758638 | W8: 23028128 | X8: 23400718 | Y8: 23702700 | Z8: 23983627
A15: New York
A16: Sum of Pv | C16: Period
A17: Commodity | B17: Region | C17: 2019 | D17: 2020 | E17: 2021 | F17: 2022 | G17: 2023 | H17: 2024 | I17: 2025 | J17: 2027 | K17: 2030 | L17: 2032 | M17: 2035 | N17: 2040 | O17: 2045 | P17: 2050 | Q17: 2055 | R17: 2060 | S17: 2065 | T17: 2070 | U17: 2075 | V17: 2080 | W17: 2085 | X17: 2090 | Y17: 2095 | Z17: 2100
A18: CO2 | B18: EGRID | C18: 38627279 | D18: 41546699 | E18: 40934895 | F18: 40417389 | G18: 39925914 | H18: 39497230 | I18: 39117291 | J18: 38194832 | K18: 36194520 | L18: 35380259 | M18: 34993775 | N18: 32349669 | O18: 28704114 | P18: 27324792 | Q18: 27456074 | R18: 27959420 | S18: 28476331 | T18: 28999490 | U18: 29491504 | V18: 30050874 | W18: 30579354 | X18: 31103124 | Y18: 31641981 | Z18: 32176545
A19: CO2 | B19: CITY | C19: 11434915 | D19: 7535855.8 | E19: 8027883.4 | F19: 7560538.3 | G19: 7013467.8 | H19: 6513435.7 | I19: 6440342.5 | J19: 5858894.5 | K19: 5633948 | L19: 5461669.4 | M19: 3888295.2 | N19: 6056346.1 | O19: 9277221.7 | P19: 8062247 | Q19: 7179450.9 | R19: 7322101.3 | S19: 7395879.5 | T19: 7710440.4 | U19: 7766026.4 | V19: 8082155.4 | W19: 8407882.6 | X19: 8737543.8 | Y19: 9070452.1 | Z19: 9414203.6
A20: CO2 | B20: CO2 Total | C20: 50062194 | D20: 49082555 | E20: 48962779 | F20: 47977928 | G20: 46939382 | H20: 46010666 | I20: 45557633 | J20: 44053726 | K20: 41828468 | L20: 40841928 | M20: 38882070 | N20: 38406015 | O20: 37981336 | P20: 35387039 | Q20: 34635524 | R20: 35281522 | S20: 35872210 | T20: 36709930 | U20: 37257530 | V20: 38133029 | W20: 38987236 | X20: 39840668 | Y20: 40712433 | Z20: 41590749

Sheet NZ50
C3: Target | D3: Target | E3: Target | F3: Target | G3: Ref | H3: Ref
C4: 2030 | D4: 2040 | E4: 2050 | F4: 2060 | G4: 1990 | H4: 2005 | I4: 2019 | J4: 2020 | K4: 2021 | L4: 2022 | M4: 2023 | N4: 2024 | O4: 2025 | P4: 2027 | Q4: 2030 | R4: 2032 | S4: 2035 | T4: 2040 | U4: 2045 | V4: 2050 | W4: 2055 | X4: 2060 | Y4: 2065 | Z4: 2070 | AA4: 2075 | AB4: 2080 | AC4: 2085 | AD4: 2090 | AE4: 2095 | AF4: 2100
A5: REF - CO2 | B5: CITY | I5: =REF!$C6 -> 17051794 | J5: =REF!$D6 -> 17411913 | K5: =REF!$E6 -> 17042314 | L5: =REF!$F6 -> 16738951 | M5: =REF!$G6 -> 16467807 | N5: =REF!$H6 -> 16169641 | O5: =REF!$I6 -> 15909010 | P5: =REF!$J6 -> 15481949 | Q5: =REF!$K6 -> 14551152 | R5: =REF!$L6 -> 14083056 | S5: =REF!$M6 -> 13838793 | T5: =REF!$N6 -> 13330953 | U5: =REF!$O6 -> 13335442 | V5: =REF!$P6 -> 13363578 | W5: =REF!$Q6 -> 13122308 | X5: =REF!$R6 -> 13186984 | Y5: =REF!$S6 -> 13434599 | Z5: =REF!$T6 -> 13688958 | AA5: =REF!$U6 -> 13945373 | AB5: =REF!$V6 -> 14203176 | AC5: =REF!$W6 -> 14462561 | AD5: =REF!$X6 -> 14723407 | AE5: =REF!$Y6 -> 14988271 | AF5: =REF!$Z6 -> 15256424
A6: NZ50 - CO2 | B6: CITY | E6: 0.95 | I6: =I5 -> 17051794 | J6: =($V6-$I6)/($V$4-$I$4)*(J$4-$I$4)+$I6 -> 16529239 | K6: =($V6-$I6)/($V$4-$I$4)*(K$4-$I$4)+$I6 -> 16006684 | L6: =($V6-$I6)/($V$4-$I$4)*(L$4-$I$4)+$I6 -> 15484129 | M6: =($V6-$I6)/($V$4-$I$4)*(M$4-$I$4)+$I6 -> 14961574 | N6: =($V6-$I6)/($V$4-$I$4)*(N$4-$I$4)+$I6 -> 14439019 | O6: =($V6-$I6)/($V$4-$I$4)*(O$4-$I$4)+$I6 -> 13916464 | P6: =($V6-$I6)/($V$4-$I$4)*(P$4-$I$4)+$I6 -> 12871354 | Q6: =($V6-$I6)/($V$4-$I$4)*(Q$4-$I$4)+$I6 -> 11303689 | ... U6: =($V6-$I6)/($V$4-$I$4)*(U$4-$I$4)+$I6 -> 3465364.7 | V6: =I6*(1-E6) -> 852589.72 | W6: =V6 -> 852589.72 | X6: =W6 -> 852589.72 | Y6: =X6 -> 852589.72 | Z6: =Y6 -> 852589.72 | AA6: =Z6 -> 852589.72 | AB6: =AA6 -> 852589.72 | AC6: =AB6 -> 852589.72 | AD6: =AC6 -> 852589.72 | ... AF6: =AE6 -> 852589.72
A7: REF - CO2 | B7: EGRID | I7: =REF!$C7 -> 1.4015481e+08 | J7: =REF!$D7 -> 1.1679105e+08 | K7: =REF!$E7 -> 1.1207702e+08 | L7: =REF!$F7 -> 1.0731871e+08 | M7: =REF!$G7 -> 1.0268916e+08 | N7: =REF!$H7 -> 98021451 | O7: =REF!$I7 -> 93480479 | P7: =REF!$J7 -> 86474338 | Q7: =REF!$K7 -> 75821480 | R7: =REF!$L7 -> 71157764 | S7: =REF!$M7 -> 63660712 | T7: =REF!$N7 -> 65309850 | U7: =REF!$O7 -> 63123238 | V7: =REF!$P7 -> 59738128 | W7: =REF!$Q7 -> 61105985 | X7: =REF!$R7 -> 45114583 | Y7: =REF!$S7 -> 24614500 | Z7: =REF!$T7 -> 8473768.2 | AA7: =REF!$U7 -> 8542059.4 | AB7: =REF!$V7 -> 8555461.2 | AC7: =REF!$W7 -> 8565567.3 | AD7: =REF!$X7 -> 8677311.3 | AE7: =REF!$Y7 -> 8714429.2 | AF7: =REF!$Z7 -> 8727202.8
A8: NZ50 - CO2 | B8: EGRID | E8: 0.95 | I8: =I7 -> 1.4015481e+08 | J8: =($V8-$I8)/($V$4-$I$4)*(J$4-$I$4)+$I8 -> 1.3585975e+08 | K8: =($V8-$I8)/($V$4-$I$4)*(K$4-$I$4)+$I8 -> 1.3156468e+08 | L8: =($V8-$I8)/($V$4-$I$4)*(L$4-$I$4)+$I8 -> 1.2726961e+08 | M8: =($V8-$I8)/($V$4-$I$4)*(M$4-$I$4)+$I8 -> 1.2297454e+08 | N8: =($V8-$I8)/($V$4-$I$4)*(N$4-$I$4)+$I8 -> 1.1867948e+08 | O8: =($V8-$I8)/($V$4-$I$4)*(O$4-$I$4)+$I8 -> 1.1438441e+08 | P8: =($V8-$I8)/($V$4-$I$4)*(P$4-$I$4)+$I8 -> 1.0579428e+08 | Q8: =($V8-$I8)/($V$4-$I$4)*(Q$4-$I$4)+$I8 -> 92909077 | ... U8: =($V8-$I8)/($V$4-$I$4)*(U$4-$I$4)+$I8 -> 28483075 | V8: =I8*(1-E8) -> 7007740.6 | W8: =V8 -> 7007740.6 | X8: =W8 -> 7007740.6 | Y8: =X8 -> 7007740.6 | Z8: =Y8 -> 7007740.6 | AA8: =Z8 -> 7007740.6 | AB8: =AA8 -> 7007740.6 | AC8: =AB8 -> 7007740.6 | AD8: =AC8 -> 7007740.6 | ... AF8: =AE8 -> 7007740.6
