Workbook

Sheet ReadMe
A1: Generic Comet (GC) TIMES Supply
B3: Sheet color
C4: Raw Data and Parameters
C6: City Specific Data
C8: Post processing for TIMES
C10: Table formatted for TIMES

Sheet >> City Data

Sheet City characteristics
B2: City Basic Data
B4: Calibration methodology | C4: GHG Inventory
B6: A. City Characteristics
B7: Data Item | C7: Value | D7: Units
B8: City Name | C8: New York
B9: Latitude | C9: 40.5
B10: Longitude | C10: -75
B11: County | C11: New York County
B12: State | C12: New York
B13: Census Division | C13: Middle Atlantic
B14: Climate Division | C14: Northeast
B15: Egrid Region | C15: NPCC NYC/Westchester
B16: Area of city (excluding water, natural and agricultural areas) | C16: 778 | D16: square kilometers
B17: * Division and Region Map can be found in the Maps sheet.
B18: B. Planning Base Year and Target Years
B19: Year | C19: Value | D19: Units
B20: Base Year | C20: 2019 | D20: Acceptable range [2018,2021]
B21: End Year | C21: 2050
B23: C. City Population and GDP
B24: Data Item | C24: Value | D24: Units
B25: Population in Base Year | C25: 8337 | D25: Thousand of people
B26: Annual population growth (Base Year - End Year) | C26: 0.5 | D26: % people
B27: GDP in Base Year | C27: 1206000 | D27: Million US$
B28: Annual GDP growth rate | C28: 2 | D28: % US$
B29: Share of manufacturing GDP | C29: 5 | D29: % US$
B30: Share of State population | C30: 0.42835123
B31: Share of State GDP | C31: 0.67251772
B32: Adjustment from state manufacturing GDP | C32: 1.0638298
B34: D. Climate Data
B35: Data Item | C35: 2000 | D35: 2050 | E35: 2100 | F35: Units
B36: Heating degree days (HDD) | C36: 4473.4625 | D36: 4066.4182 | E36: 3763.8582 | F36: F
B37: Cooling degree days (CDD) | C37: 1020.7333 | D37: 1224.2555 | E37: 1375.5355 | F37: F
B39: Data Item | C39: Value | D39: Units
B40: Correction from State HDD | C40: 0.72727402
B41: Correction from State CDD | C41: 1.5583715
B42: Annual precipitation | C42: 762 | D42: mm / year
B43: Climate change scenario | C43: RCP4.5
B44: Average temperature increase in 1980-2020 | C44: 1.4617857 | D44: F
B45: Forecasted average temperature increase in 2035-2065 | C45: 3.13 | D45: F
B46: Forecasted average temperature increase in 2070-2100 | C46: 4.37 | D46: F
...

Sheet >> GC_Existing

Sheet >> TIMES

Sheet UC_ZEV
B3: ~UC_Sets: R_S: AllRegions
B4: ~UC_Sets: T_E:
G6: ~UC_T:UC_NCAP~LO
B7: UC_N | C7: Pset_PN | D7: Pset_PD | E7: Cset_CO | F7: Attrib_Cond | G7: Year | H7: UC_RHSRT | I7: UC_RHSRT~0 | J7: AllRegions
B8: UC_ZEVMandate | C8: TRAPASCAR*,TRAPASLDT* | D8: -*Battery Electric*,-*Hydrogen Fuel Cell* | F8: -PRC_RESID | G8: 2019 | H8: 0 | I8: 5 | J8: =-Data!B3 -> 0
C9: =C8 -> TRAPASCAR*,TRAPASLDT* | D9: *Battery Electric*,*Hydrogen Fuel Cell* | F9: -PRC_RESID | G9: 2019 | J9: =1-(J8*-1) -> 1
C10: =C8 -> TRAPASCAR*,TRAPASLDT* | D10: =D8 -> -*Battery Electric*,-*Hydrogen Fuel Cell* | F10: -PRC_RESID | G10: 2020 | J10: =-Data!B4 -> 0
C11: =C9 -> TRAPASCAR*,TRAPASLDT* | D11: =D9 -> *Battery Electric*,*Hydrogen Fuel Cell* | F11: -PRC_RESID | G11: 2020 | J11: =1-(J10*-1) -> 1
C12: =C10 -> TRAPASCAR*,TRAPASLDT* | D12: =D10 -> -*Battery Electric*,-*Hydrogen Fuel Cell* | F12: -PRC_RESID | G12: 2025 | J12: =-Data!B5 -> 0
C13: =C11 -> TRAPASCAR*,TRAPASLDT* | D13: =D11 -> *Battery Electric*,*Hydrogen Fuel Cell* | F13: -PRC_RESID | G13: 2025 | J13: =1-(J12*-1) -> 1
C14: =C12 -> TRAPASCAR*,TRAPASLDT* | D14: =D12 -> -*Battery Electric*,-*Hydrogen Fuel Cell* | F14: -PRC_RESID | G14: 2030 | J14: =-Data!B6 -> -0.1
C15: =C13 -> TRAPASCAR*,TRAPASLDT* | D15: =D13 -> *Battery Electric*,*Hydrogen Fuel Cell* | F15: -PRC_RESID | G15: 2030 | J15: =1-(J14*-1) -> 0.9
C16: =C14 -> TRAPASCAR*,TRAPASLDT* | D16: =D14 -> -*Battery Electric*,-*Hydrogen Fuel Cell* | F16: -PRC_RESID | G16: 2035 | J16: =-Data!B7 -> -0.2
C17: =C15 -> TRAPASCAR*,TRAPASLDT* | D17: =D15 -> *Battery Electric*,*Hydrogen Fuel Cell* | F17: -PRC_RESID | G17: 2035 | J17: =1-(J16*-1) -> 0.8
C18: =C16 -> TRAPASCAR*,TRAPASLDT* | D18: =D16 -> -*Battery Electric*,-*Hydrogen Fuel Cell* | F18: -PRC_RESID | G18: 2040 | J18: =-Data!B8 -> -0.5
C19: =C17 -> TRAPASCAR*,TRAPASLDT* | D19: =D17 -> *Battery Electric*,*Hydrogen Fuel Cell* | F19: -PRC_RESID | G19: 2040 | J19: =1-(J18*-1) -> 0.5
C20: =C18 -> TRAPASCAR*,TRAPASLDT* | D20: =D18 -> -*Battery Electric*,-*Hydrogen Fuel Cell* | F20: -PRC_RESID | G20: 2100 | J20: =-Data!B9 -> -0.5
C21: =C19 -> TRAPASCAR*,TRAPASLDT* | D21: =D19 -> *Battery Electric*,*Hydrogen Fuel Cell* | F21: -PRC_RESID | G21: 2100 | J21: =1-(J20*-1) -> 0.5

Sheet >> Parameters

Sheet Data
B2: Minimum sales of Zero emissions vehicules
A3: 2019 | B3: 0
A4: 2020 | B4: 0
A5: 2025 | B5: 0
A6: 2030 | B6: 0.1
A7: 2035 | B7: 0.2
A8: 2040 | B8: 0.5
A9: 2100 | B9: 0.5
