Workbook

Sheet ReadMe
A1: Generic Comet (GC) TIMES Supply
B3: Sheet color
C4: Raw Data and Parameters
C6: City Specific Data
C8: Post processing for TIMES
C10: Table formatted for TIMES

Sheet >> City Data

Sheet City characteristics
B2: City Basic Data
B4: Calibration methodology | C4: GHG Inventory
B6: A. City Characteristics
B7: Data Item | C7: Value | D7: Units
B8: City Name | C8: New York
B9: Latitude | C9: 40.5
B10: Longitude | C10: -75
B11: County | C11: New York County
B12: State | C12: New York
B13: Census Division | C13: Middle Atlantic
B14: Climate Division | C14: Northeast
B15: Egrid Region | C15: NPCC NYC/Westchester
B16: Area of city (excluding water, natural and agricultural areas) | C16: 778 | D16: square kilometers
B17: * Division and Region Map can be found in the Maps sheet.
B18: B. Planning Base Year and Target Years
B19: Year | C19: Value | D19: Units
B20: Base Year | C20: 2019 | D20: Acceptable range [2018,2021]
B21: End Year | C21: 2050
B23: C. City Population and GDP
B24: Data Item | C24: Value | D24: Units
B25: Population in Base Year | C25: 8337 | D25: Thousand of people
B26: Annual population growth (Base Year - End Year) | C26: 0.5 | D26: % people
B27: GDP in Base Year | C27: 1206000 | D27: Million US$
B28: Annual GDP growth rate | C28: 2 | D28: % US$
B29: Share of manufacturing GDP | C29: 5 | D29: % US$
B30: Share of State population | C30: 0.42835123
B31: Share of State GDP | C31: 0.67251772
B32: Adjustment from state manufacturing GDP | C32: 1.0638298
B34: D. Climate Data
B35: Data Item | C35: 2000 | D35: 2050 | E35: 2100 | F35: Units
B36: Heating degree days (HDD) | C36: 4473.4625 | D36: 4066.4182 | E36: 3763.8582 | F36: F
B37: Cooling degree days (CDD) | C37: 1020.7333 | D37: 1224.2555 | E37: 1375.5355 | F37: F
B39: Data Item | C39: Value | D39: Units
B40: Correction from State HDD | C40: 0.72727402
B41: Correction from State CDD | C41: 1.5583715
B42: Annual precipitation | C42: 762 | D42: mm / year
B43: Climate change scenario | C43: RCP4.5
B44: Average temperature increase in 1980-2020 | C44: 1.4617857 | D44: F
B45: Forecasted average temperature increase in 2035-2065 | C45: 3.13 | D45: F
B46: Forecasted average temperature increase in 2070-2100 | C46: 4.37 | D46: F
...

Sheet >> GC_NewTech

Sheet COM TECH
M1: Include
A2: Sector | B2: Sub-sector | C2: Archetype | D2: Vintage | E2: End Use | F2: Technology | G2: Class | H2: Energy | I2: First Year | J2: Description | K2: Input Label | L2: Output Label | M2: Technology Label | N2: Include | O2: First availability year | P2: CAPEX (2023 US$ / capacity) | Q2: OPEX (2023 US$ / capacity) | R2: Capacity NEMS | S2: Efficiency | T2: Efficiency Unit | U2: Efficiency (%TJ) | V2: CAPEX (Thousands 2023 US$ / capacity) | W2: OPEX (Thousands 2023 US$ / capacity) | X2: Capacity Unit | Y2: Life (Year) | Z2: CFA | AA2: C2A
A3: Commercial | B3: Hotel | D3: Old | E3: Space heating | F3: Rooftop AHP | G3: Standard | H3: Electricity | I3: 2061 | J3: Space heating Rooftop AHP Standard Electricity 2061 | K3: COMELC | L3: COMHOTOldSHEUE | M3: COMHOTOldSHRTPAHPSTDELC61 | N3: 0 | O3: 2061 | P3: 117.05847 | Q3: 4.2000146 | R3: Thousands Btu / hour | S3: 3.3 | T3: Btu / Btu | U3: 3.3 | V3: 399.42018 | W3: 14.331048 | X3: MW | Y3: 21 | Z3: 0.17628028 | AA3: 31.536
A4: Commercial | B4: Hotel | D4: Old | E4: Space heating | F4: Rooftop AHP | G4: High | H4: Electricity | I4: 2022 | J4: Space heating Rooftop AHP High Electricity 2022 | K4: COMELC | L4: COMHOTOldSHEUE | M4: COMHOTOldSHRTPAHPHIGELC20 | N4: 1 | O4: 2020 | P4: 200.78857 | Q4: 4.2000146 | R4: Thousands Btu / hour | S4: 3.7 | T4: Btu / Btu | U4: 3.7 | V4: 685.1192 | W4: 14.331048 | X4: MW | Y4: 21 | Z4: 0.17628028 | AA4: 31.536
A5: Commercial | B5: Hotel | D5: Old | E5: Space heating | F5: Rooftop AHP | G5: Standard | H5: Electricity | I5: 2023 | J5: Space heating Rooftop AHP Standard Electricity 2023 | K5: COMELC | L5: COMHOTOldSHEUE | M5: COMHOTOldSHRTPAHPSTDELC23 | N5: 0 | O5: 2023 | P5: 135.73558 | Q5: 4.2000146 | R5: Thousands Btu / hour | S5: 3.4 | T5: Btu / Btu | U5: 3.4 | V5: 463.14912 | W5: 14.331048 | X5: MW | Y5: 21 | Z5: 0.17628028 | AA5: 31.536
A6: Commercial | B6: Hotel | D6: Old | E6: Space heating | F6: Commercial GHP | G6: Standard | H6: Electricity | I6: 2033 | J6: Space heating Commercial GHP Standard Electricity 2033 | K6: COMELC | L6: COMHOTOldSHEUE | M6: COMHOTOldSHCOMGHPSTDELC33 | N6: 1 | O6: 2033 | P6: 483.93313 | Q6: 3.8104971 | R6: Thousands Btu / hour | S6: 3.7 | T6: Btu / Btu | U6: 3.7 | V6: 1651.2488 | W6: 13.001959 | X6: MW | Y6: 14.4 | Z6: 0.17628028 | AA6: 31.536
A7: Commercial | B7: Hotel | D7: Old | E7: Space heating | F7: Commercial GHP | G7: Mid | H7: Electricity | I7: 2033 | J7: Space heating Commercial GHP Mid Electricity 2033 | K7: COMELC | L7: COMHOTOldSHEUE | M7: COMHOTOldSHCOMGHPMIDELC33 | N7: 1 | O7: 2033 | P7: 497.90496 | Q7: 3.8104971 | R7: Thousands Btu / hour | S7: 3.8 | T7: Btu / Btu | U7: 3.8 | V7: 1698.9226 | W7: 13.001959 | X7: MW | Y7: 14.4 | Z7: 0.17628028 | AA7: 31.536
A8: Commercial | B8: Hotel | D8: Old | E8: Space heating | F8: Commercial GHP | G8: High | H8: Electricity | I8: 2033 | J8: Space heating Commercial GHP High Electricity 2033 | K8: COMELC | L8: COMHOTOldSHEUE | M8: COMHOTOldSHCOMGHPHIGELC33 | N8: 1 | O8: 2033 | P8: 513.14694 | Q8: 3.8104971 | R8: Thousands Btu / hour | S8: 4 | T8: Btu / Btu | U8: 4 | V8: 1750.9305 | W8: 13.001959 | X8: MW | Y8: 14.4 | Z8: 0.17628028 | AA8: 31.536
A9: Commercial | B9: Hotel | D9: Old | E9: Space heating | F9: Commercial GHP | G9: Standard | H9: Electricity | I9: 2023 | J9: Space heating Commercial GHP Standard Electricity 2023 | K9: COMELC | L9: COMHOTOldSHEUE | M9: COMHOTOldSHCOMGHPSTDELC23 | N9: 1 | O9: 2023 | P9: 483.93313 | Q9: 3.8104971 | R9: Thousands Btu / hour | S9: 3.7 | T9: Btu / Btu | U9: 3.7 | V9: 1651.2488 | W9: 13.001959 | X9: MW | Y9: 14.4 | Z9: 0.17628028 | AA9: 31.536
A10: Commercial | B10: Hotel | D10: Old | E10: Space heating | F10: Commercial GHP | G10: Mid | H10: Electricity | I10: 2023 | J10: Space heating Commercial GHP Mid Electricity 2023 | K10: COMELC | L10: COMHOTOldSHEUE | M10: COMHOTOldSHCOMGHPMIDELC23 | N10: 1 | O10: 2023 | P10: 497.90496 | Q10: 3.8104971 | R10: Thousands Btu / hour | S10: 3.8 | T10: Btu / Btu | U10: 3.8 | V10: 1698.9226 | W10: 13.001959 | X10: MW | Y10: 14.4 | Z10: 0.17628028 | AA10: 31.536
A11: Commercial | B11: Hotel | D11: Old | E11: Space heating | F11: Commercial GHP | G11: High | H11: Electricity | I11: 2023 | J11: Space heating Commercial GHP High Electricity 2023 | K11: COMELC | L11: COMHOTOldSHEUE | M11: COMHOTOldSHCOMGHPHIGELC23 | N11: 1 | O11: 2023 | P11: 513.14694 | Q11: 3.8104971 | R11: Thousands Btu / hour | S11: 4 | T11: Btu / Btu | U11: 4 | V11: 1750.9305 | W11: 13.001959 | X11: MW | Y11: 14.4 | Z11: 0.17628028 | AA11: 31.536
A12: Commercial | B12: Hotel | D12: Old | E12: Space heating | F12: ICE Rooftop AHP | G12: Standard | H12: Natural gas | I12: 2022 | J12: Space heating ICE Rooftop AHP Standard Natural gas 2022 | K12: COMNGA | L12: COMHOTOldSHEUE | M12: COMHOTOldSHICEAHPSTDNGA20 | N12: 1 | O12: 2020 | P12: 335.32375 | Q12: 6.3000219 | R12: Thousands Btu / hour | S12: 1.4 | T12: Btu / Btu | U12: 1.4 | V12: 1144.1724 | W12: 21.496572 | X12: MW | Y12: 15 | Z12: 0.17628028 | AA12: 31.536
A13: Commercial | B13: Hotel | D13: Old | E13: Space heating | F13: Boiler | G13: Standard | H13: Fuel oil | I13: 2030 | J13: Space heating Boiler Standard Fuel oil 2030 | K13: COMFOI | L13: COMHOTOldSHEUE | M13: COMHOTOldSHBOISTDFOI30 | N13: 1 | O13: 2030 | P13: 55.18651 | Q13: 4.0294912 | R13: Thousands Btu / hour | S13: 0.87 | T13: Btu / Btu | U13: 0.87 | V13: 188.30423 | W13: 13.749198 | X13: MW | Y13: 25 | Z13: 0.17628028 | AA13: 31.536
A14: Commercial | B14: Hotel | D14: Old | E14: Space heating | F14: Boiler | G14: Standard | H14: Fuel oil | I14: 2040 | J14: Space heating Boiler Standard Fuel oil 2040 | K14: COMFOI | L14: COMHOTOldSHEUE | M14: COMHOTOldSHBOISTDFOI40 | N14: 1 | O14: 2040 | P14: 53.946364 | Q14: 3.9389408 | R14: Thousands Btu / hour | S14: 0.89 | T14: Btu / Btu | U14: 0.89 | V14: 184.07268 | W14: 13.440227 | X14: MW | Y14: 25 | Z14: 0.17628028 | AA14: 31.536
... A170: Commercial | B170: Hotel | D170: Old | E170: Refrigeration | F170: Commercial Reach-In | G170: High | H170: Electricity | I170: 2025 | J170: Refrigeration Commercial Reach-In High Electricity 2025 | K170: COMELC | L170: COMHOTOldREEUE | M170: COMHOTOldRECOMRINHIGELC25 | N170: 1 | O170: 2025 | P170: 1758.0247 | Q170: 83.737017 | R170: Thousands Btu / hour | S170: 7.4409022 | T170: Btu / Btu | U170: 2.569611 | V170: 17370.421 | W170: 827.37588 | X170: MW | Y170: 10 | Z170: 0.44 | AA170: 31.536
A171: * | M171: * | N171: *
A172: Commercial | B172: Retail | D172: Old | E172: Space heating | F172: Rooftop AHP | G172: Standard | H172: Electricity | I172: 2061 | J172: Space heating Rooftop AHP Standard Electricity 2061 | K172: COMELC | L172: COMRETOldSHEUE | M172: COMRETOldSHRTPAHPSTDELC61 | N172: 1 | O172: 2061 | P172: 117.05847 | Q172: 4.2000146 | R172: Thousands Btu / hour | S172: 3.3 | T172: Btu / Btu | U172: 3.3 | V172: 399.42018 | W172: 14.331048 | X172: MW | Y172: 21 | Z172: 0.23552731 | AA172: 31.536
A173: Commercial | B173: Retail | D173: Old | E173: Space heating | F173: Rooftop AHP | G173: High | H173: Electricity | I173: 2022 | J173: Space heating Rooftop AHP High Electricity 2022 | K173: COMELC | L173: COMRETOldSHEUE | M173: COMRETOldSHRTPAHPHIGELC20 | N173: 1 | O173: 2020 | P173: 200.78857 | Q173: 4.2000146 | R173: Thousands Btu / hour | S173: 3.7 | T173: Btu / Btu | U173: 3.7 | V173: 685.1192 | W173: 14.331048 | X173: MW | Y173: 21 | Z173: 0.23552731 | AA173: 31.536
A174: Commercial | B174: Retail | D174: Old | E174: Space heating | F174: Rooftop AHP | G174: Standard | H174: Electricity | I174: 2023 | J174: Space heating Rooftop AHP Standard Electricity 2023 | K174: COMELC | L174: COMRETOldSHEUE | M174: COMRETOldSHRTPAHPSTDELC23 | N174: 1 | O174: 2023 | P174: 135.73558 | Q174: 4.2000146 | R174: Thousands Btu / hour | S174: 3.4 | T174: Btu / Btu | U174: 3.4 | V174: 463.14912 | W174: 14.331048 | X174: MW | Y174: 21 | Z174: 0.23552731 | AA174: 31.536
A175: Commercial | B175: Retail | D175: Old | E175: Space heating | F175: Commercial GHP | G175: Standard | H175: Electricity | I175: 2033 | J175: Space heating Commercial GHP Standard Electricity 2033 | K175: COMELC | L175: COMRETOldSHEUE | M175: COMRETOldSHCOMGHPSTDELC33 | N175: 1 | O175: 2033 | P175: 483.93313 | Q175: 3.8104971 | R175: Thousands Btu / hour | S175: 3.7 | T175: Btu / Btu | U175: 3.7 | V175: 1651.2488 | W175: 13.001959 | X175: MW | Y175: 14.4 | Z175: 0.23552731 | AA175: 31.536
A176: Commercial | B176: Retail | D176: Old | E176: Space heating | F176: Commercial GHP | G176: Mid | H176: Electricity | I176: 2033 | J176: Space heating Commercial GHP Mid Electricity 2033 | K176: COMELC | L176: COMRETOldSHEUE | M176: COMRETOldSHCOMGHPMIDELC33 | N176: 1 | O176: 2033 | P176: 497.90496 | Q176: 3.8104971 | R176: Thousands Btu / hour | S176: 3.8 | T176: Btu / Btu | U176: 3.8 | V176: 1698.9226 | W176: 13.001959 | X176: MW | Y176: 14.4 | Z176: 0.23552731 | AA176: 31.536
A177: Commercial | B177: Retail | D177: Old | E177: Space heating | F177: Commercial GHP | G177: High | H177: Electricity | I177: 2033 | J177: Space heating Commercial GHP High Electricity 2033 | K177: COMELC | L177: COMRETOldSHEUE | M177: COMRETOldSHCOMGHPHIGELC33 | N177: 1 | O177: 2033 | P177: 513.14694 | Q177: 3.8104971 | R177: Thousands Btu / hour | S177: 4 | T177: Btu / Btu | U177: 4 | V177: 1750.9305 | W177: 13.001959 | X177: MW | Y177: 14.4 | Z177: 0.23552731 | AA177: 31.536
A178: Commercial | B178: Retail | D178: Old | E178: Space heating | F178: Commercial GHP | G178: Standard | H178: Electricity | I178: 2023 | J178: Space heating Commercial GHP Standard Electricity 2023 | K178: COMELC | L178: COMRETOldSHEUE | M178: COMRETOldSHCOMGHPSTDELC23 | N178: 1 | O178: 2023 | P178: 483.93313 | Q178: 3.8104971 | R178: Thousands Btu / hour | S178: 3.7 | T178: Btu / Btu | U178: 3.7 | V178: 1651.2488 | W178: 13.001959 | X178: MW | Y178: 14.4 | Z178: 0.23552731 | AA178: 31.536
A179: Commercial | B179: Retail | D179: Old | E179: Space heating | F179: Commercial GHP | G179: Mid | H179: Electricity | I179: 2023 | J179: Space heating Commercial GHP Mid Electricity 2023 | K179: COMELC | L179: COMRETOldSHEUE | M179: COMRETOldSHCOMGHPMIDELC23 | N179: 1 | O179: 2023 | P179: 497.90496 | Q179: 3.8104971 | R179: Thousands Btu / hour | S179: 3.8 | T179: Btu / Btu | U179: 3.8 | V179: 1698.9226 | W179: 13.001959 | X179: MW | Y179: 14.4 | Z179: 0.23552731 | AA179: 31.536
A180: Commercial | B180: Retail | D180: Old | E180: Space heating | F180: Commercial GHP | G180: High | H180: Electricity | I180: 2023 | J180: Space heating Commercial GHP High Electricity 2023 | K180: COMELC | L180: COMRETOldSHEUE | M180: COMRETOldSHCOMGHPHIGELC23 | N180: 1 | O180: 2023 | P180: 513.14694 | Q180: 3.8104971 | R180: Thousands Btu / hour | S180: 4 | T180: Btu / Btu | U180: 4 | V180: 1750.9305 | W180: 13.001959 | X180: MW | Y180: 14.4 | Z180: 0.23552731 | AA180: 31.536
A181: Commercial | B181: Retail | D181: Old | E181: Space heating | F181: ICE Rooftop AHP | G181: Standard | H181: Natural gas | I181: 2022 | J181: Space heating ICE Rooftop AHP Standard Natural gas 2022 | K181: COMNGA | L181: COMRETOldSHEUE | M181: COMRETOldSHICEAHPSTDNGA20 | N181: 1 | O181: 2020 | P181: 335.32375 | Q181: 6.3000219 | R181: Thousands Btu / hour | S181: 1.4 | T181: Btu / Btu | U181: 1.4 | V181: 1144.1724 | W181: 21.496572 | X181: MW | Y181: 15 | Z181: 0.23552731 | AA181: 31.536
A182: Commercial | B182: Retail | D182: Old | E182: Space heating | F182: Boiler | G182: Standard | H182: Fuel oil | I182: 2030 | J182: Space heating Boiler Standard Fuel oil 2030 | K182: COMFOI | L182: COMRETOldSHEUE | M182: COMRETOldSHBOISTDFOI30 | N182: 1 | O182: 2030 | P182: 55.18651 | Q182: 4.0294912 | R182: Thousands Btu / hour | S182: 0.87 | T182: Btu / Btu | U182: 0.87 | V182: 188.30423 | W182: 13.749198 | X182: MW | Y182: 25 | Z182: 0.23552731 | AA182: 31.536
A183: Commercial | B183: Retail | D183: Old | E183: Space heating | F183: Boiler | G183: Standard | H183: Fuel oil | I183: 2040 | J183: Space heating Boiler Standard Fuel oil 2040 | K183: COMFOI | L183: COMRETOldSHEUE | M183: COMRETOldSHBOISTDFOI40 | N183: 1 | O183: 2040 | P183: 53.946364 | Q183: 3.9389408 | R183: Thousands Btu / hour | S183: 0.89 | T183: Btu / Btu | U183: 0.89 | V183: 184.07268 | W183: 13.440227 | X183: MW | Y183: 25 | Z183: 0.23552731 | AA183: 31.536
... A339: Commercial | B339: Retail | D339: Old | E339: Refrigeration | F339: Commercial Reach-In | G339: High | H339: Electricity | I339: 2025 | J339: Refrigeration Commercial Reach-In High Electricity 2025 | K339: COMELC | L339: COMRETOldREEUE | M339: COMRETOldRECOMRINHIGELC25 | N339: 1 | O339: 2025 | P339: 1758.0247 | Q339: 83.737017 | R339: Thousands Btu / hour | S339: 7.4409022 | T339: Btu / Btu | U339: 2.569611 | V339: 17370.421 | W339: 827.37588 | X339: MW | Y339: 10 | Z339: 0.44 | AA339: 31.536
A340: * | M340: * | N340: *
A341: Commercial | B341: Office | D341: Old | E341: Space heating | F341: Rooftop AHP | G341: Standard | H341: Electricity | I341: 2061 | J341: Space heating Rooftop AHP Standard Electricity 2061 | K341: COMELC | L341: COMOFFOldSHEUE | M341: COMOFFOldSHRTPAHPSTDELC61 | N341: 0 | O341: 2061 | P341: 117.05847 | Q341: 4.2000146 | R341: Thousands Btu / hour | S341: 3.3 | T341: Btu / Btu | U341: 3.3 | V341: 399.42018 | W341: 14.331048 | X341: MW | Y341: 21 | Z341: 0.28022106 | AA341: 31.536
A342: Commercial | B342: Office | D342: Old | E342: Space heating | F342: Rooftop AHP | G342: High | H342: Electricity | I342: 2022 | J342: Space heating Rooftop AHP High Electricity 2022 | K342: COMELC | L342: COMOFFOldSHEUE | M342: COMOFFOldSHRTPAHPHIGELC20 | N342: 1 | O342: 2020 | P342: 200.78857 | Q342: 4.2000146 | R342: Thousands Btu / hour | S342: 3.7 | T342: Btu / Btu | U342: 3.7 | V342: 685.1192 | W342: 14.331048 | X342: MW | Y342: 21 | Z342: 0.28022106 | AA342: 31.536
A343: Commercial | B343: Office | D343: Old | E343: Space heating | F343: Rooftop AHP | G343: Standard | H343: Electricity | I343: 2023 | J343: Space heating Rooftop AHP Standard Electricity 2023 | K343: COMELC | L343: COMOFFOldSHEUE | M343: COMOFFOldSHRTPAHPSTDELC23 | N343: 0 | O343: 2023 | P343: 135.73558 | Q343: 4.2000146 | R343: Thousands Btu / hour | S343: 3.4 | T343: Btu / Btu | U343: 3.4 | V343: 463.14912 | W343: 14.331048 | X343: MW | Y343: 21 | Z343: 0.28022106 | AA343: 31.536
A344: Commercial | B344: Office | D344: Old | E344: Space heating | F344: Commercial GHP | G344: Standard | H344: Electricity | I344: 2033 | J344: Space heating Commercial GHP Standard Electricity 2033 | K344: COMELC | L344: COMOFFOldSHEUE | M344: COMOFFOldSHCOMGHPSTDELC33 | N344: 0 | O344: 2033 | P344: 483.93313 | Q344: 3.8104971 | R344: Thousands Btu / hour | S344: 3.7 | T344: Btu / Btu | U344: 3.7 | V344: 1651.2488 | W344: 13.001959 | X344: MW | Y344: 14.4 | Z344: 0.28022106 | AA344: 31.536
A345: Commercial | B345: Office | D345: Old | E345: Space heating | F345: Commercial GHP | G345: Mid | H345: Electricity | I345: 2033 | J345: Space heating Commercial GHP Mid Electricity 2033 | K345: COMELC | L345: COMOFFOldSHEUE | M345: COMOFFOldSHCOMGHPMIDELC33 | N345: 0 | O345: 2033 | P345: 497.90496 | Q345: 3.8104971 | R345: Thousands Btu / hour | S345: 3.8 | T345: Btu / Btu | U345: 3.8 | V345: 1698.9226 | W345: 13.001959 | X345: MW | Y345: 14.4 | Z345: 0.28022106 | AA345: 31.536
A346: Commercial | B346: Office | D346: Old | E346: Space heating | F346: Commercial GHP | G346: High | H346: Electricity | I346: 2033 | J346: Space heating Commercial GHP High Electricity 2033 | K346: COMELC | L346: COMOFFOldSHEUE | M346: COMOFFOldSHCOMGHPHIGELC33 | N346: 0 | O346: 2033 | P346: 513.14694 | Q346: 3.8104971 | R346: Thousands Btu / hour | S346: 4 | T346: Btu / Btu | U346: 4 | V346: 1750.9305 | W346: 13.001959 | X346: MW | Y346: 14.4 | Z346: 0.28022106 | AA346: 31.536
A347: Commercial | B347: Office | D347: Old | E347: Space heating | F347: Commercial GHP | G347: Standard | H347: Electricity | I347: 2023 | J347: Space heating Commercial GHP Standard Electricity 2023 | K347: COMELC | L347: COMOFFOldSHEUE | M347: COMOFFOldSHCOMGHPSTDELC23 | N347: 0 | O347: 2023 | P347: 483.93313 | Q347: 3.8104971 | R347: Thousands Btu / hour | S347: 3.7 | T347: Btu / Btu | U347: 3.7 | V347: 1651.2488 | W347: 13.001959 | X347: MW | Y347: 14.4 | Z347: 0.28022106 | AA347: 31.536
A348: Commercial | B348: Office | D348: Old | E348: Space heating | F348: Commercial GHP | G348: Mid | H348: Electricity | I348: 2023 | J348: Space heating Commercial GHP Mid Electricity 2023 | K348: COMELC | L348: COMOFFOldSHEUE | M348: COMOFFOldSHCOMGHPMIDELC23 | N348: 0 | O348: 2023 | P348: 497.90496 | Q348: 3.8104971 | R348: Thousands Btu / hour | S348: 3.8 | T348: Btu / Btu | U348: 3.8 | V348: 1698.9226 | W348: 13.001959 | X348: MW | Y348: 14.4 | Z348: 0.28022106 | AA348: 31.536
A349: Commercial | B349: Office | D349: Old | E349: Space heating | F349: Commercial GHP | G349: High | H349: Electricity | I349: 2023 | J349: Space heating Commercial GHP High Electricity 2023 | K349: COMELC | L349: COMOFFOldSHEUE | M349: COMOFFOldSHCOMGHPHIGELC23 | N349: 0 | O349: 2023 | P349: 513.14694 | Q349: 3.8104971 | R349: Thousands Btu / hour | S349: 4 | T349: Btu / Btu | U349: 4 | V349: 1750.9305 | W349: 13.001959 | X349: MW | Y349: 14.4 | Z349: 0.28022106 | AA349: 31.536
A350: Commercial | B350: Office | D350: Old | E350: Space heating | F350: ICE Rooftop AHP | G350: Standard | H350: Natural gas | I350: 2022 | J350: Space heating ICE Rooftop AHP Standard Natural gas 2022 | K350: COMNGA | L350: COMOFFOldSHEUE | M350: COMOFFOldSHICEAHPSTDNGA20 | N350: 1 | O350: 2020 | P350: 335.32375 | Q350: 6.3000219 | R350: Thousands Btu / hour | S350: 1.4 | T350: Btu / Btu | U350: 1.4 | V350: 1144.1724 | W350: 21.496572 | X350: MW | Y350: 15 | Z350: 0.28022106 | AA350: 31.536
...

Sheet COM RESID
A1: Sector | B1: Sub-sector | C1: Archetype | D1: Vintage | E1: End Use | F1: Technology | G1: Energy | H1: Input Label | I1: Output Label | J1: Technology Label | K1: DEMAND (Mm2) | L1: FINAL ENERGY (TJ) | M1: FINAL ENERGY SHARE (%) | N1: FINAL ENERGY EQ (TJ) | O1: USEFUL ENERGY (TJ,Mlm) | P1: RESID (MW,Mlma, Tja) | Q1: Capacity Unit | R1: EFF | S1: Residual life (Yr) | T1: Fixed O&M ($/kW/yr) | U1: Variable O&M ($/GJ) | V1: CFA | W1: C2A
A2: Commercial | B2: Hotel | D2: Old | E2: Space heating | F2: Electric furnace | G2: Electricity | H2: COMELC | I2: COMHOTOldSHEUE | J2: COMHOTOldSHFURELC19 | K2: 11.978701 | L2: 105.23941 | M2: 0.79219174 | N2: 83.369795 | O2: 81.702399 | P2: 37.362548 | Q2: MW | R2: 0.98 | S2: 15 | T2: 1 | V2: 0.069341257 | W2: 31.536
A3: Commercial | B3: Hotel | D3: Old | E3: Space heating | F3: Electric boiler | G3: Electricity | H3: COMELC | I3: COMHOTOldSHEUE | J3: COMHOTOldSHBOIELC19 | K3: 11.978701 | L3: 105.23941 | M3: 0.066806316 | N3: 7.0306576 | O3: 6.5884292 | P3: 3.5269956 | Q3: MW | R3: 0.9371 | S3: 7.5 | T3: 1 | V3: 0.059233905 | W3: 31.536
A4: Commercial | B4: Hotel | D4: Old | E4: Space heating | F4: Electric air heat pump | G4: Electricity | H4: COMELC | I4: COMHOTOldSHEUE | J4: COMHOTOldSHAHPELC19 | K4: 11.978701 | L4: 105.23941 | M4: 0.14100195 | N4: 14.838962 | O4: 46.000783 | P4: 14.674506 | Q4: MW | R4: 3.1 | S4: 10.5 | T4: 14.331048 | V4: 0.099402002 | W4: 31.536
A5: Commercial | B5: Hotel | D5: Old | E5: Space heating | F5: Electric ground heat pump | G5: Electricity | H5: COMELC | I5: COMHOTOldSHEUE | J5: COMHOTOldSHGHPELC19 | K5: 11.978701 | L5: 105.23941 | M5: 0 | N5: 0 | O5: 0 | P5: 0 | Q5: MW | R5: 3.4 | S5: 7.2 | T5: 13.001959 | V5: 0.10902155 | W5: 31.536
A6: Commercial | B6: Hotel | D6: Old | E6: Space heating | F6: Natural gas furnace | G6: Natural gas | H6: COMNGA | I6: COMHOTOldSHEUE | J6: COMHOTOldSHFURNGA19 | K6: 11.978701 | L6: 1635.3055 | M6: 0.2440729 | N6: 399.13375 | O6: 283.58453 | P6: 59.96843 | Q6: MW | R6: 0.7105 | S6: 11.5 | T6: 2.0235418 | V6: 0.14995234 | W6: 31.536 | Y6: 23
A7: Commercial | B7: Hotel | D7: Old | E7: Space heating | F7: Natural gas boiler | G7: Natural gas | H7: COMNGA | I7: COMHOTOldSHEUE | J7: COMHOTOldSHBOINGA19 | K7: 11.978701 | L7: 1635.3055 | M7: 0.73410948 | N7: 1200.4933 | O7: 912.37487 | P7: 157.49913 | Q7: MW | R7: 0.76 | S7: 12.5 | T7: 11.357594 | V7: 0.18369128 | W7: 31.536
A8: Commercial | B8: Hotel | D8: Old | E8: Space heating | F8: Natural gas heat pump | G8: Natural gas | H8: COMNGA | I8: COMHOTOldSHEUE | J8: COMHOTOldSHAHPNGA19 | K8: 11.978701 | L8: 1635.3055 | M8: 0.021817613 | N8: 35.678462 | O8: 46.382001 | P8: 5.123458 | Q8: MW | R8: 1.3 | S8: 7.5 | T8: 12 | V8: 0.28706464 | W8: 31.536
A9: Commercial | B9: Hotel | D9: Old | E9: Space heating | F9: Fuel oil boiler | G9: Fuel oil | H9: COMFOI | I9: COMHOTOldSHEUE | J9: COMHOTOldSHBOIFOI19 | K9: 11.978701 | L9: 136.24643 | M9: 0.96283873 | N9: 131.18334 | O9: 103.63484 | P9: 21.245855 | Q9: MW | R9: 0.79 | S9: 12.5 | T9: 14 | V9: 0.15467672 | W9: 31.536
A10: Commercial | B10: Hotel | D10: Old | E10: Space heating | F10: Fuel oil furnace | G10: Fuel oil | H10: COMFOI | I10: COMHOTOldSHEUE | J10: COMHOTOldSHFURFOI19 | K10: 11.978701 | L10: 136.24643 | M10: 0.037161272 | N10: 5.0630907 | O10: 3.8504805 | P10: 0.81999507 | Q10: MW | R10: 0.7605 | S10: 11.5 | T10: 4 | V10: 0.14890082 | W10: 31.536
A11: Commercial | B11: Hotel | D11: Old | E11: Space heating | F11: Propane furnace | G11: LPG | H11: COMLPG | I11: COMHOTOldSHEUE | J11: COMHOTOldSHFURPRO19 | K11: 11.978701 | L11: 0 | M11: 0.32032654 | N11: 0 | O11: 0 | P11: 0 | Q11: MW | R11: 0.7105 | S11: 11.5 | T11: 2.0235418 | V11: 0.14995234 | W11: 31.536
A12: Commercial | B12: Hotel | D12: Old | E12: Space heating | F12: Propane boiler | G12: LPG | H12: COMLPG | I12: COMHOTOldSHEUE | J12: COMHOTOldSHBOIPRO19 | K12: 11.978701 | L12: 0 | M12: 0.30268222 | N12: 0 | O12: 0 | P12: 0 | Q12: MW | R12: 0.76 | S12: 12.5 | T12: 11.357594 | V12: 0.18369128 | W12: 31.536
A13: Commercial | B13: Hotel | D13: Old | E13: Space heating | F13: Propane heat pump | G13: LPG | H13: COMLPG | I13: COMHOTOldSHEUE | J13: COMHOTOldSHAHPPRO19 | K13: 11.978701 | L13: 0 | M13: 0.37699124 | N13: 0 | O13: 0 | P13: 0 | Q13: MW | R13: 1.3 | S13: 7.5 | T13: 12 | V13: 0.28706464 | W13: 31.536
A14: Commercial | B14: Hotel | D14: Old | E14: Space heating | F14: District steam heating system | G14: Steam / Cooling | H14: COMSTM | I14: COMHOTOldSHEUE | J14: COMHOTOldSHDHESTM19 | K14: 11.978701 | L14: 68.809968 | M14: 1 | N14: 68.809968 | O14: 64.481821 | P14: 4.9913363 | Q14: MW | R14: 0.9371 | S14: 12.5 | T14: 1 | V14: 0.40965084 | W14: 31.536
A15: Commercial | B15: Hotel | D15: Old | E15: Space cooling | F15: Res type central AC electric | G15: Electricity | H15: COMELC | I15: COMHOTOldSCEUE | J15: COMHOTOldSCRESELC19 | K15: 11.978701 | L15: 393.15304 | M15: 0.015856174 | N15: 6.2339029 | O15: 20.828398 | P15: 3.282636 | Q15: MW | R15: 3.3411489 | S15: 9 | T15: 8 | V15: 0.20119933 | W15: 31.536
A16: Commercial | B16: Hotel | D16: Old | E16: Space cooling | F16: Room AC electric | G16: Electricity | H16: COMELC | I16: COMHOTOldSCEUE | J16: COMHOTOldSCRACELC19 | K16: 11.978701 | L16: 393.15304 | M16: 0.57192812 | N16: 224.85528 | O16: 573.34142 | P16: 57.718846 | Q16: MW | R16: 2.5498242 | S16: 5 | T16: 0 | V16: 0.31498442 | W16: 31.536
A17: Commercial | B17: Hotel | D17: Old | E17: Space cooling | F17: Central AC electric | G17: Electricity | H17: COMELC | I17: COMHOTOldSCEUE | J17: COMHOTOldSCCACELC19 | K17: 11.978701 | L17: 393.15304 | M17: 0.27581488 | N17: 108.43746 | O17: 331.62993 | P17: 76.852525 | Q17: MW | R17: 3.0582599 | S17: 9 | T17: 8 | V17: 0.13683241 | W17: 31.536
A18: Commercial | B18: Hotel | D18: Old | E18: Space cooling | F18: Rooftop Air HP electric | G18: Electricity | H18: COMELC | I18: COMHOTOldSCEUE | J18: COMHOTOldSCAHPELC19 | K18: 11.978701 | L18: 393.15304 | M18: 0.12372108 | N18: 48.64132 | O18: 132.58039 | P18: 13.27567 | Q18: MW | R18: 2.7256741 | S18: 10.5 | T18: 14 | V18: 0.31667678 | W18: 31.536
... A337: Commercial | B337: Other | D337: Old | E337: Other end use | F337: Electricity | G337: Electricity | H337: COMELC | I337: COMOTHOldOEEUE | J337: COMOTHOldOEELC19 | K337: 8.7602804 | L337: 2864.2761 | M337: 1 | N337: 2864.2761 | O337: 2864.2761 | P337: 6509.7185 | Q337: TJa | R337: 1 | S337: 12.5 | T337: 10 | V337: 0.44 | W337: 1

Sheet >>> Data

Sheet Selected_constraint_UC
A1: Constraint number | B1: {=_xlfn.UNIQUE(_xlfn._xlws.FILTER('COM RESID'!$H:$I,'COM RESID'!$H:$H<>""))} -> Input Label | C1: Output Label | D1: Count | I1: Constraint number | J1: Input Label | K1: Output Label | L1: Count
A2: =COUNTA($B$2:B2) -> 1 | B2: COMELC | C2: COMHOTOldSHEUE | D2: {=COUNTA(_xlfn.UNIQUE(_xlfn._xlws.FILTER('COM TECH'!$K:$K,('COM TECH'!$L:$L=C2)*('COM TECH'!$N:$N=1))))} -> 3 | I2: 1 | J2: COMELC | K2: COMHOTOldSHEUE | L2: 3
A3: =COUNTA($B$2:B3) -> 2 | B3: COMNGA | C3: COMHOTOldSHEUE | D3: {=COUNTA(_xlfn.UNIQUE(_xlfn._xlws.FILTER('COM TECH'!$K:$K,('COM TECH'!$L:$L=C3)*('COM TECH'!$N:$N=1))))} -> 3 | I3: 2 | J3: COMNGA | K3: COMHOTOldSHEUE | L3: 3
A4: =COUNTA($B$2:B4) -> 3 | B4: COMFOI | C4: COMHOTOldSHEUE | D4: {=COUNTA(_xlfn.UNIQUE(_xlfn._xlws.FILTER('COM TECH'!$K:$K,('COM TECH'!$L:$L=C4)*('COM TECH'!$N:$N=1))))} -> 3 | I4: 3 | J4: COMFOI | K4: COMHOTOldSHEUE | L4: 3
A5: =COUNTA($B$2:B5) -> 4 | B5: COMLPG | C5: COMHOTOldSHEUE | D5: {=COUNTA(_xlfn.UNIQUE(_xlfn._xlws.FILTER('COM TECH'!$K:$K,('COM TECH'!$L:$L=C5)*('COM TECH'!$N:$N=1))))} -> 3 | I5: 4 | J5: COMLPG | K5: COMHOTOldSHEUE | L5: 3
A6: =COUNTA($B$2:B6) -> 5 | B6: COMSTM | C6: COMHOTOldSHEUE | D6: {=COUNTA(_xlfn.UNIQUE(_xlfn._xlws.FILTER('COM TECH'!$K:$K,('COM TECH'!$L:$L=C6)*('COM TECH'!$N:$N=1))))} -> 3 | I6: 5 | J6: COMSTM | K6: COMHOTOldSHEUE | L6: 3
A7: =COUNTA($B$2:B7) -> 6 | B7: COMELC | C7: COMHOTOldSCEUE | D7: {=COUNTA(_xlfn.UNIQUE(_xlfn._xlws.FILTER('COM TECH'!$K:$K,('COM TECH'!$L:$L=C7)*('COM TECH'!$N:$N=1))))} -> 2 | I7: 6 | J7: COMELC | K7: COMHOTOldSCEUE | L7: 2
A8: =COUNTA($B$2:B8) -> 7 | B8: COMELC | C8: COMHOTOldVTEUE | D8: {=COUNTA(_xlfn.UNIQUE(_xlfn._xlws.FILTER('COM TECH'!$K:$K,('COM TECH'!$L:$L=C8)*('COM TECH'!$N:$N=1))))} -> 1 | I8: 7 | J8: COMELC | K8: COMHOTOldVTEUE | L8: 1
A9: =COUNTA($B$2:B9) -> 8 | B9: COMFOI | C9: COMHOTOldWHEUE | D9: {=COUNTA(_xlfn.UNIQUE(_xlfn._xlws.FILTER('COM TECH'!$K:$K,('COM TECH'!$L:$L=C9)*('COM TECH'!$N:$N=1))))} -> 3 | I9: 8 | J9: COMFOI | K9: COMHOTOldWHEUE | L9: 3
A10: =COUNTA($B$2:B10) -> 9 | B10: COMNGA | C10: COMHOTOldWHEUE | D10: {=COUNTA(_xlfn.UNIQUE(_xlfn._xlws.FILTER('COM TECH'!$K:$K,('COM TECH'!$L:$L=C10)*('COM TECH'!$N:$N=1))))} -> 3 | I10: 9 | J10: COMNGA | K10: COMHOTOldWHEUE | L10: 3
A11: =COUNTA($B$2:B11) -> 10 | B11: COMSTM | C11: COMHOTOldWHEUE | D11: {=COUNTA(_xlfn.UNIQUE(_xlfn._xlws.FILTER('COM TECH'!$K:$K,('COM TECH'!$L:$L=C11)*('COM TECH'!$N:$N=1))))} -> 3 | I11: 10 | J11: COMSTM | K11: COMHOTOldWHEUE | L11: 3
A12: =COUNTA($B$2:B12) -> 11 | B12: COMELC | C12: COMHOTOldWHEUE | D12: {=COUNTA(_xlfn.UNIQUE(_xlfn._xlws.FILTER('COM TECH'!$K:$K,('COM TECH'!$L:$L=C12)*('COM TECH'!$N:$N=1))))} -> 3 | I12: 11 | J12: COMELC | K12: COMHOTOldWHEUE | L12: 3
A13: =COUNTA($B$2:B13) -> 12 | B13: COMELC | C13: COMHOTOldLTEUE | D13: {=COUNTA(_xlfn.UNIQUE(_xlfn._xlws.FILTER('COM TECH'!$K:$K,('COM TECH'!$L:$L=C13)*('COM TECH'!$N:$N=1))))} -> 1 | I13: 12 | J13: COMELC | K13: COMHOTOldLTEUE | L13: 1
... A169: =COUNTA($B$2:B169) -> 168 | B169: COMELC | C169: COMOTHOldOEEUE | D169: {=COUNTA(_xlfn.UNIQUE(_xlfn._xlws.FILTER('COM TECH'!$K:$K,('COM TECH'!$L:$L=C169)*('COM TECH'!$N:$N=1))))} -> 2 | I169: 168 | J169: COMELC | K169: COMOTHOldOEEUE | L169: 2

Sheet >> TIMES

Sheet UC
C2: ~UC_Sets: R_E: CITY | Q2: ~UC_Sets: R_E: CITY
H3: ~UC_T:UC_COMPRD | V3: ~UC_T:UC_COMPRD
C4: UC_N | D4: Pset_PN | E4: Pset: CI | F4: Pset: CO | G4: Cset: CN | H4: Year | I4: LimType | J4: UC_FLO | K4: CITY | L4: UC_RHSRTS | M4: UC_RHSRTS~0 | Q4: UC_N | R4: Pset_PN | S4: Pset: CI | T4: Pset: CO | U4: Cset: CN | V4: Year | W4: LimType | X4: UC_FLO | Y4: CITY | Z4: UC_RHSRTS | AA4: UC_RHSRTS~0
A5: 1 | C5: =IF(E5="","",IF(_xlfn.XLOOKUP($A5,Selected_constraint_UC!$A:$A,Selected_constraint_UC!$D:$D)=1,"*",IF(SUMIFS('COM TECH'!$N:$N,'COM TECH'!$K:$K,E5,'COM TECH'!$L:$L,F5)=0,"*",IF(SUMIFS('COM RESID'!$O:$O,'COM RESID'!$H:$H,$E5,'COM RESID'!$I:$I,$F5)=0,"*","UC_MarketShare_"&LEFT(F5,LEN(F5)-3)&"_"&RIGHT(E5,3)&"_MIN")))) -> UC_MarketShare_COMHOTOldSH_ELC_MIN | E5: =_xlfn.XLOOKUP($A5,Selected_constraint_UC!$A:$A,Selected_constraint_UC!$B:$B) -> COMELC | F5: =_xlfn.XLOOKUP($A5,Selected_constraint_UC!$A:$A,Selected_constraint_UC!$C:$C) -> COMHOTOldSHEUE | G5: =F5 -> COMHOTOldSHEUE | H5: 2019 | I5: LO | J5: 1 | K5: =-ROUNDDOWN(SUMIFS('COM RESID'!$O:$O,'COM RESID'!$H:$H,$E5,'COM RESID'!$I:$I,$F5)/SUMIFS('COM RESID'!$O:$O,'COM RESID'!$I:$I,$F5),3)*O5 -> -0.08428 | L5: 0 | M5: 5 | O5: 0.98 | Q5: =SUBSTITUTE(C5,"MIN","MAX") -> UC_MarketShare_COMHOTOldSH_ELC_MAX | S5: =E5 -> COMELC | T5: =F5 -> COMHOTOldSHEUE | U5: =G5 -> COMHOTOldSHEUE | V5: =H5 -> 2019 | W5: UP | X5: 1 | Y5: =-ROUNDUP(MIN(SUMIFS('COM RESID'!$O:$O,'COM RESID'!$H:$H,$E5,'COM RESID'!$I:$I,$F5)/SUMIFS('COM RESID'!$O:$O,'COM RESID'!$I:$I,$F5)*AC5,1),3) -> -0.089 | Z5: 0 | AA5: 5 | AC5: 1.02
A6: =A5 -> 1 | C6: =IF(C5="*",C5,"") | E6: =E5 -> COMELC | F6: =F5 -> COMHOTOldSHEUE | G6: =G5 -> COMHOTOldSHEUE | H6: 2025 | I6: =I5 -> LO | K6: =-ROUNDDOWN(SUMIFS('COM RESID'!$O:$O,'COM RESID'!$H:$H,$E6,'COM RESID'!$I:$I,$F6)/SUMIFS('COM RESID'!$O:$O,'COM RESID'!$I:$I,$F6),3)*O6 -> -0.0688 | O6: 0.8 | Q6: =SUBSTITUTE(C6,"MIN","MAX") | S6: =E6 -> COMELC | T6: =F6 -> COMHOTOldSHEUE | U6: =G6 -> COMHOTOldSHEUE | V6: 2025 | W6: =W5 -> UP | Y6: =-ROUNDUP(MIN(SUMIFS('COM RESID'!$O:$O,'COM RESID'!$H:$H,$E6,'COM RESID'!$I:$I,$F6)/SUMIFS('COM RESID'!$O:$O,'COM RESID'!$I:$I,$F6)*AC6,1),3) -> -0.25 | AC6: =IF(S6="COMELC",IF(SUMIFS('COM RESID'!$O:$O,'COM RESID'!$H:$H,$E6,'COM RESID'!$I:$I,$F6)/SUMIFS('COM RESID'!$O:$O,'COM RESID'!$I:$I,$F6)*1.2<0.25,0.25/(SUMIFS('COM RESID'!$O:$O,'COM RESID'!$H:$H,$E6,'COM RESID'!$I:$I,$F6)/SUMIFS('COM RESID'!$O:$O,'COM RESID'!$I:$I,$F6)),1.2),IF(ISNUMBER(SEARCH("WHEUE",T6)),IF(OR(S6="COMNGA",S6="COMFOI"),1,1.2),1.2)) -> 2.8829056
A7: =A6 -> 1 | C7: =IF(C6="*",C6,"") | E7: =E6 -> COMELC | F7: =F6 -> COMHOTOldSHEUE | G7: =G6 -> COMHOTOldSHEUE | H7: 2030 | I7: =I6 -> LO | K7: =-ROUNDDOWN(SUMIFS('COM RESID'!$O:$O,'COM RESID'!$H:$H,$E7,'COM RESID'!$I:$I,$F7)/SUMIFS('COM RESID'!$O:$O,'COM RESID'!$I:$I,$F7),3)*O7 -> -0.0645 | O7: 0.75 | Q7: =SUBSTITUTE(C7,"MIN","MAX") | S7: =E7 -> COMELC | T7: =F7 -> COMHOTOldSHEUE | U7: =G7 -> COMHOTOldSHEUE | V7: 2030 | W7: =W6 -> UP | Y7: =-ROUNDUP(MIN(SUMIFS('COM RESID'!$O:$O,'COM RESID'!$H:$H,$E7,'COM RESID'!$I:$I,$F7)/SUMIFS('COM RESID'!$O:$O,'COM RESID'!$I:$I,$F7)*AC7,1),3) -> -0.5 | AC7: =IF(S7="COMELC",IF(SUMIFS('COM RESID'!$O:$O,'COM RESID'!$H:$H,$E7,'COM RESID'!$I:$I,$F7)/SUMIFS('COM RESID'!$O:$O,'COM RESID'!$I:$I,$F7)*1.5<0.5,0.5/(SUMIFS('COM RESID'!$O:$O,'COM RESID'!$H:$H,$E7,'COM RESID'!$I:$I,$F7)/SUMIFS('COM RESID'!$O:$O,'COM RESID'!$I:$I,$F7)),1.5),IF(ISNUMBER(SEARCH("WHEUE",T6)),IF(OR(S6="COMNGA",S6="COMFOI"),0.9,1.5),1.5)) -> 5.7658112
A8: =A7 -> 1 | C8: =IF(C7="*",C7,"") | E8: =E7 -> COMELC | F8: =F7 -> COMHOTOldSHEUE | G8: =G7 -> COMHOTOldSHEUE | H8: 2050 | I8: =I7 -> LO | K8: =-ROUNDDOWN(SUMIFS('COM RESID'!$O:$O,'COM RESID'!$H:$H,$E8,'COM RESID'!$I:$I,$F8)/SUMIFS('COM RESID'!$O:$O,'COM RESID'!$I:$I,$F8),3)*O8 -> -0.0645 | O8: 0.75 | Q8: =SUBSTITUTE(C8,"MIN","MAX") | S8: =E8 -> COMELC | T8: =F8 -> COMHOTOldSHEUE | U8: =G8 -> COMHOTOldSHEUE | V8: 2050 | W8: =W7 -> UP | Y8: =-ROUNDUP(MIN(SUMIFS('COM RESID'!$O:$O,'COM RESID'!$H:$H,$E8,'COM RESID'!$I:$I,$F8)/SUMIFS('COM RESID'!$O:$O,'COM RESID'!$I:$I,$F8)*AC8,1),3) -> -1 | AC8: =IF(S8="COMELC",IF(SUMIFS('COM RESID'!$O:$O,'COM RESID'!$H:$H,$E8,'COM RESID'!$I:$I,$F8)/SUMIFS('COM RESID'!$O:$O,'COM RESID'!$I:$I,$F8)*3<1,1/(SUMIFS('COM RESID'!$O:$O,'COM RESID'!$H:$H,$E8,'COM RESID'!$I:$I,$F8)/SUMIFS('COM RESID'!$O:$O,'COM RESID'!$I:$I,$F8)),3),IF(ISNUMBER(SEARCH("WHEUE",T6)),IF(OR(S6="COMNGA",S6="COMFOI"),0.75,3),3)) -> 11.531622
A9: =A5+1 -> 2 | C9: =IF(E9="","",IF(_xlfn.XLOOKUP($A9,Selected_constraint_UC!$A:$A,Selected_constraint_UC!$D:$D)=1,"*",IF(SUMIFS('COM TECH'!$N:$N,'COM TECH'!$K:$K,E9,'COM TECH'!$L:$L,F9)=0,"*",IF(SUMIFS('COM RESID'!$O:$O,'COM RESID'!$H:$H,$E9,'COM RESID'!$I:$I,$F9)=0,"*","UC_MarketShare_"&LEFT(F9,LEN(F9)-3)&"_"&RIGHT(E9,3)&"_MIN")))) -> UC_MarketShare_COMHOTOldSH_NGA_MIN | E9: =_xlfn.XLOOKUP($A9,Selected_constraint_UC!$A:$A,Selected_constraint_UC!$B:$B) -> COMNGA | F9: =_xlfn.XLOOKUP($A9,Selected_constraint_UC!$A:$A,Selected_constraint_UC!$C:$C) -> COMHOTOldSHEUE | G9: =F9 -> COMHOTOldSHEUE | H9: 2019 | I9: LO | J9: 1 | K9: =-ROUNDDOWN(SUMIFS('COM RESID'!$O:$O,'COM RESID'!$H:$H,$E9,'COM RESID'!$I:$I,$F9)/SUMIFS('COM RESID'!$O:$O,'COM RESID'!$I:$I,$F9),3)*O9 -> -0.78596 | L9: 0 | M9: 5 | O9: 0.98 | Q9: =SUBSTITUTE(C9,"MIN","MAX") -> UC_MarketShare_COMHOTOldSH_NGA_MAX | S9: =E9 -> COMNGA | T9: =F9 -> COMHOTOldSHEUE | U9: =G9 -> COMHOTOldSHEUE | V9: 2019 | W9: UP | X9: 1 | Y9: =-ROUNDUP(MIN(SUMIFS('COM RESID'!$O:$O,'COM RESID'!$H:$H,$E9,'COM RESID'!$I:$I,$F9)/SUMIFS('COM RESID'!$O:$O,'COM RESID'!$I:$I,$F9)*AC9,1),3) -> -0.819 | Z9: 0 | AA9: 5 | AC9: 1.02
A10: =A9 -> 2 | C10: =IF(C9="*",C9,"") | E10: =E9 -> COMNGA | F10: =F9 -> COMHOTOldSHEUE | G10: =G9 -> COMHOTOldSHEUE | H10: 2025 | I10: =I9 -> LO | K10: =-ROUNDDOWN(SUMIFS('COM RESID'!$O:$O,'COM RESID'!$H:$H,$E10,'COM RESID'!$I:$I,$F10)/SUMIFS('COM RESID'!$O:$O,'COM RESID'!$I:$I,$F10),3)*O10 -> -0.6416 | O10: 0.8 | Q10: =SUBSTITUTE(C10,"MIN","MAX") | S10: =E10 -> COMNGA | T10: =F10 -> COMHOTOldSHEUE | U10: =G10 -> COMHOTOldSHEUE | V10: 2025 | W10: =W9 -> UP | Y10: =-ROUNDUP(MIN(SUMIFS('COM RESID'!$O:$O,'COM RESID'!$H:$H,$E10,'COM RESID'!$I:$I,$F10)/SUMIFS('COM RESID'!$O:$O,'COM RESID'!$I:$I,$F10)*AC10,1),3) -> -0.963 | AC10: =IF(S10="COMELC",IF(SUMIFS('COM RESID'!$O:$O,'COM RESID'!$H:$H,$E10,'COM RESID'!$I:$I,$F10)/SUMIFS('COM RESID'!$O:$O,'COM RESID'!$I:$I,$F10)*1.2<0.25,0.25/(SUMIFS('COM RESID'!$O:$O,'COM RESID'!$H:$H,$E10,'COM RESID'!$I:$I,$F10)/SUMIFS('COM RESID'!$O:$O,'COM RESID'!$I:$I,$F10)),1.2),IF(ISNUMBER(SEARCH("WHEUE",T10)),IF(OR(S10="COMNGA",S10="COMFOI"),1,1.2),1.2)) -> 1.2
A11: =A10 -> 2 | C11: =IF(C10="*",C10,"") | E11: =E10 -> COMNGA | F11: =F10 -> COMHOTOldSHEUE | G11: =G10 -> COMHOTOldSHEUE | H11: 2030 | I11: =I10 -> LO | K11: =-ROUNDDOWN(SUMIFS('COM RESID'!$O:$O,'COM RESID'!$H:$H,$E11,'COM RESID'!$I:$I,$F11)/SUMIFS('COM RESID'!$O:$O,'COM RESID'!$I:$I,$F11),3)*O11 -> -0.1604 | O11: 0.2 | Q11: =SUBSTITUTE(C11,"MIN","MAX") | S11: =E11 -> COMNGA | T11: =F11 -> COMHOTOldSHEUE | U11: =G11 -> COMHOTOldSHEUE | V11: 2030 | W11: =W10 -> UP | Y11: =-ROUNDUP(MIN(SUMIFS('COM RESID'!$O:$O,'COM RESID'!$H:$H,$E11,'COM RESID'!$I:$I,$F11)/SUMIFS('COM RESID'!$O:$O,'COM RESID'!$I:$I,$F11)*AC11,1),3) -> -1 | AC11: =IF(S11="COMELC",IF(SUMIFS('COM RESID'!$O:$O,'COM RESID'!$H:$H,$E11,'COM RESID'!$I:$I,$F11)/SUMIFS('COM RESID'!$O:$O,'COM RESID'!$I:$I,$F11)*1.5<0.5,0.5/(SUMIFS('COM RESID'!$O:$O,'COM RESID'!$H:$H,$E11,'COM RESID'!$I:$I,$F11)/SUMIFS('COM RESID'!$O:$O,'COM RESID'!$I:$I,$F11)),1.5),IF(ISNUMBER(SEARCH("WHEUE",T10)),IF(OR(S10="COMNGA",S10="COMFOI"),0.9,1.5),1.5)) -> 1.5
A12: =A11 -> 2 | C12: =IF(C11="*",C11,"") | E12: =E11 -> COMNGA | F12: =F11 -> COMHOTOldSHEUE | G12: =G11 -> COMHOTOldSHEUE | H12: 2050 | I12: =I11 -> LO | K12: =-ROUNDDOWN(SUMIFS('COM RESID'!$O:$O,'COM RESID'!$H:$H,$E12,'COM RESID'!$I:$I,$F12)/SUMIFS('COM RESID'!$O:$O,'COM RESID'!$I:$I,$F12),3)*O12 -> 0 | O12: 0 | Q12: =SUBSTITUTE(C12,"MIN","MAX") | S12: =E12 -> COMNGA | T12: =F12 -> COMHOTOldSHEUE | U12: =G12 -> COMHOTOldSHEUE | V12: 2050 | W12: =W11 -> UP | Y12: =-ROUNDUP(MIN(SUMIFS('COM RESID'!$O:$O,'COM RESID'!$H:$H,$E12,'COM RESID'!$I:$I,$F12)/SUMIFS('COM RESID'!$O:$O,'COM RESID'!$I:$I,$F12)*AC12,1),3) -> -1 | AC12: =IF(S12="COMELC",IF(SUMIFS('COM RESID'!$O:$O,'COM RESID'!$H:$H,$E12,'COM RESID'!$I:$I,$F12)/SUMIFS('COM RESID'!$O:$O,'COM RESID'!$I:$I,$F12)*3<1,1/(SUMIFS('COM RESID'!$O:$O,'COM RESID'!$H:$H,$E12,'COM RESID'!$I:$I,$F12)/SUMIFS('COM RESID'!$O:$O,'COM RESID'!$I:$I,$F12)),3),IF(ISNUMBER(SEARCH("WHEUE",T10)),IF(OR(S10="COMNGA",S10="COMFOI"),0.75,3),3)) -> 3
A13: =A9+1 -> 3 | C13: =IF(E13="","",IF(_xlfn.XLOOKUP($A13,Selected_constraint_UC!$A:$A,Selected_constraint_UC!$D:$D)=1,"*",IF(SUMIFS('COM TECH'!$N:$N,'COM TECH'!$K:$K,E13,'COM TECH'!$L:$L,F13)=0,"*",IF(SUMIFS('COM RESID'!$O:$O,'COM RESID'!$H:$H,$E13,'COM RESID'!$I:$I,$F13)=0,"*","UC_MarketShare_"&LEFT(F13,LEN(F13)-3)&"_"&RIGHT(E13,3)&"_MIN")))) -> UC_MarketShare_COMHOTOldSH_FOI_MIN | E13: =_xlfn.XLOOKUP($A13,Selected_constraint_UC!$A:$A,Selected_constraint_UC!$B:$B) -> COMFOI | F13: =_xlfn.XLOOKUP($A13,Selected_constraint_UC!$A:$A,Selected_constraint_UC!$C:$C) -> COMHOTOldSHEUE | G13: =F13 -> COMHOTOldSHEUE | H13: 2019 | I13: LO | J13: 1 | K13: =-ROUNDDOWN(SUMIFS('COM RESID'!$O:$O,'COM RESID'!$H:$H,$E13,'COM RESID'!$I:$I,$F13)/SUMIFS('COM RESID'!$O:$O,'COM RESID'!$I:$I,$F13),3)*O13 -> -0.06762 | L13: 0 | M13: 5 | O13: 0.98 | Q13: =SUBSTITUTE(C13,"MIN","MAX") -> UC_MarketShare_COMHOTOldSH_FOI_MAX | S13: =E13 -> COMFOI | T13: =F13 -> COMHOTOldSHEUE | U13: =G13 -> COMHOTOldSHEUE | V13: 2019 | W13: UP | X13: 1 | Y13: =-ROUNDUP(MIN(SUMIFS('COM RESID'!$O:$O,'COM RESID'!$H:$H,$E13,'COM RESID'!$I:$I,$F13)/SUMIFS('COM RESID'!$O:$O,'COM RESID'!$I:$I,$F13)*AC13,1),3) -> -0.071 | Z13: 0 | AA13: 5 | AC13: 1.02
A14: =A13 -> 3 | C14: =IF(C13="*",C13,"") | E14: =E13 -> COMFOI | F14: =F13 -> COMHOTOldSHEUE | G14: =G13 -> COMHOTOldSHEUE | H14: 2025 | I14: =I13 -> LO | K14: =-ROUNDDOWN(SUMIFS('COM RESID'!$O:$O,'COM RESID'!$H:$H,$E14,'COM RESID'!$I:$I,$F14)/SUMIFS('COM RESID'!$O:$O,'COM RESID'!$I:$I,$F14),3)*O14 -> -0.0552 | O14: 0.8 | Q14: =SUBSTITUTE(C14,"MIN","MAX") | S14: =E14 -> COMFOI | T14: =F14 -> COMHOTOldSHEUE | U14: =G14 -> COMHOTOldSHEUE | V14: 2025 | W14: =W13 -> UP | Y14: =-ROUNDUP(MIN(SUMIFS('COM RESID'!$O:$O,'COM RESID'!$H:$H,$E14,'COM RESID'!$I:$I,$F14)/SUMIFS('COM RESID'!$O:$O,'COM RESID'!$I:$I,$F14)*AC14,1),3) -> -0.084 | AC14: =IF(S14="COMELC",IF(SUMIFS('COM RESID'!$O:$O,'COM RESID'!$H:$H,$E14,'COM RESID'!$I:$I,$F14)/SUMIFS('COM RESID'!$O:$O,'COM RESID'!$I:$I,$F14)*1.2<0.25,0.25/(SUMIFS('COM RESID'!$O:$O,'COM RESID'!$H:$H,$E14,'COM RESID'!$I:$I,$F14)/SUMIFS('COM RESID'!$O:$O,'COM RESID'!$I:$I,$F14)),1.2),IF(ISNUMBER(SEARCH("WHEUE",T14)),IF(OR(S14="COMNGA",S14="COMFOI"),1,1.2),1.2)) -> 1.2
A15: =A14 -> 3 | C15: =IF(C14="*",C14,"") | E15: =E14 -> COMFOI | F15: =F14 -> COMHOTOldSHEUE | G15: =G14 -> COMHOTOldSHEUE | H15: 2030 | I15: =I14 -> LO | K15: =-ROUNDDOWN(SUMIFS('COM RESID'!$O:$O,'COM RESID'!$H:$H,$E15,'COM RESID'!$I:$I,$F15)/SUMIFS('COM RESID'!$O:$O,'COM RESID'!$I:$I,$F15),3)*O15 -> -0.0138 | O15: 0.2 | Q15: =SUBSTITUTE(C15,"MIN","MAX") | S15: =E15 -> COMFOI | T15: =F15 -> COMHOTOldSHEUE | U15: =G15 -> COMHOTOldSHEUE | V15: 2030 | W15: =W14 -> UP | Y15: =-ROUNDUP(MIN(SUMIFS('COM RESID'!$O:$O,'COM RESID'!$H:$H,$E15,'COM RESID'!$I:$I,$F15)/SUMIFS('COM RESID'!$O:$O,'COM RESID'!$I:$I,$F15)*AC15,1),3) -> -0.105 | AC15: =IF(S15="COMELC",IF(SUMIFS('COM RESID'!$O:$O,'COM RESID'!$H:$H,$E15,'COM RESID'!$I:$I,$F15)/SUMIFS('COM RESID'!$O:$O,'COM RESID'!$I:$I,$F15)*1.5<0.5,0.5/(SUMIFS('COM RESID'!$O:$O,'COM RESID'!$H:$H,$E15,'COM RESID'!$I:$I,$F15)/SUMIFS('COM RESID'!$O:$O,'COM RESID'!$I:$I,$F15)),1.5),IF(ISNUMBER(SEARCH("WHEUE",T14)),IF(OR(S14="COMNGA",S14="COMFOI"),0.9,1.5),1.5)) -> 1.5
A16: =A15 -> 3 | C16: =IF(C15="*",C15,"") | E16: =E15 -> COMFOI | F16: =F15 -> COMHOTOldSHEUE | G16: =G15 -> COMHOTOldSHEUE | H16: 2050 | I16: =I15 -> LO | K16: =-ROUNDDOWN(SUMIFS('COM RESID'!$O:$O,'COM RESID'!$H:$H,$E16,'COM RESID'!$I:$I,$F16)/SUMIFS('COM RESID'!$O:$O,'COM RESID'!$I:$I,$F16),3)*O16 -> 0 | O16: 0 | Q16: =SUBSTITUTE(C16,"MIN","MAX") | S16: =E16 -> COMFOI | T16: =F16 -> COMHOTOldSHEUE | U16: =G16 -> COMHOTOldSHEUE | V16: 2050 | W16: =W15 -> UP | Y16: =-ROUNDUP(MIN(SUMIFS('COM RESID'!$O:$O,'COM RESID'!$H:$H,$E16,'COM RESID'!$I:$I,$F16)/SUMIFS('COM RESID'!$O:$O,'COM RESID'!$I:$I,$F16)*AC16,1),3) -> -0.209 | AC16: =IF(S16="COMELC",IF(SUMIFS('COM RESID'!$O:$O,'COM RESID'!$H:$H,$E16,'COM RESID'!$I:$I,$F16)/SUMIFS('COM RESID'!$O:$O,'COM RESID'!$I:$I,$F16)*3<1,1/(SUMIFS('COM RESID'!$O:$O,'COM RESID'!$H:$H,$E16,'COM RESID'!$I:$I,$F16)/SUMIFS('COM RESID'!$O:$O,'COM RESID'!$I:$I,$F16)),3),IF(ISNUMBER(SEARCH("WHEUE",T14)),IF(OR(S14="COMNGA",S14="COMFOI"),0.75,3),3)) -> 3
A17: =A13+1 -> 4 | C17: =IF(E17="","",IF(_xlfn.XLOOKUP($A17,Selected_constraint_UC!$A:$A,Selected_constraint_UC!$D:$D)=1,"*",IF(SUMIFS('COM TECH'!$N:$N,'COM TECH'!$K:$K,E17,'COM TECH'!$L:$L,F17)=0,"*",IF(SUMIFS('COM RESID'!$O:$O,'COM RESID'!$H:$H,$E17,'COM RESID'!$I:$I,$F17)=0,"*","UC_MarketShare_"&LEFT(F17,LEN(F17)-3)&"_"&RIGHT(E17,3)&"_MIN")))) -> * | E17: =_xlfn.XLOOKUP($A17,Selected_constraint_UC!$A:$A,Selected_constraint_UC!$B:$B) -> COMLPG | F17: =_xlfn.XLOOKUP($A17,Selected_constraint_UC!$A:$A,Selected_constraint_UC!$C:$C) -> COMHOTOldSHEUE | G17: =F17 -> COMHOTOldSHEUE | H17: 2019 | I17: LO | J17: 1 | K17: =-ROUNDDOWN(SUMIFS('COM RESID'!$O:$O,'COM RESID'!$H:$H,$E17,'COM RESID'!$I:$I,$F17)/SUMIFS('COM RESID'!$O:$O,'COM RESID'!$I:$I,$F17),3)*O17 -> 0 | L17: 0 | M17: 5 | O17: 0.98 | Q17: =SUBSTITUTE(C17,"MIN","MAX") -> * | S17: =E17 -> COMLPG | T17: =F17 -> COMHOTOldSHEUE | U17: =G17 -> COMHOTOldSHEUE | V17: 2019 | W17: UP | X17: 1 | Y17: =-ROUNDUP(MIN(SUMIFS('COM RESID'!$O:$O,'COM RESID'!$H:$H,$E17,'COM RESID'!$I:$I,$F17)/SUMIFS('COM RESID'!$O:$O,'COM RESID'!$I:$I,$F17)*AC17,1),3) -> 0 | Z17: 0 | AA17: 5 | AC17: 1.02
A18: =A17 -> 4 | C18: =IF(C17="*",C17,"") -> * | E18: =E17 -> COMLPG | F18: =F17 -> COMHOTOldSHEUE | G18: =G17 -> COMHOTOldSHEUE | H18: 2025 | I18: =I17 -> LO | K18: =-ROUNDDOWN(SUMIFS('COM RESID'!$O:$O,'COM RESID'!$H:$H,$E18,'COM RESID'!$I:$I,$F18)/SUMIFS('COM RESID'!$O:$O,'COM RESID'!$I:$I,$F18),3)*O18 -> 0 | O18: 0.8 | Q18: =SUBSTITUTE(C18,"MIN","MAX") -> * | S18: =E18 -> COMLPG | T18: =F18 -> COMHOTOldSHEUE | U18: =G18 -> COMHOTOldSHEUE | V18: 2025 | W18: =W17 -> UP | Y18: =-ROUNDUP(MIN(SUMIFS('COM RESID'!$O:$O,'COM RESID'!$H:$H,$E18,'COM RESID'!$I:$I,$F18)/SUMIFS('COM RESID'!$O:$O,'COM RESID'!$I:$I,$F18)*AC18,1),3) -> 0 | AC18: =IF(S18="COMELC",IF(SUMIFS('COM RESID'!$O:$O,'COM RESID'!$H:$H,$E18,'COM RESID'!$I:$I,$F18)/SUMIFS('COM RESID'!$O:$O,'COM RESID'!$I:$I,$F18)*1.2<0.25,0.25/(SUMIFS('COM RESID'!$O:$O,'COM RESID'!$H:$H,$E18,'COM RESID'!$I:$I,$F18)/SUMIFS('COM RESID'!$O:$O,'COM RESID'!$I:$I,$F18)),1.2),IF(ISNUMBER(SEARCH("WHEUE",T18)),IF(OR(S18="COMNGA",S18="COMFOI"),1,1.2),1.2)) -> 1.2
A19: =A18 -> 4 | C19: =IF(C18="*",C18,"") -> * | E19: =E18 -> COMLPG | F19: =F18 -> COMHOTOldSHEUE | G19: =G18 -> COMHOTOldSHEUE | H19: 2030 | I19: =I18 -> LO | K19: =-ROUNDDOWN(SUMIFS('COM RESID'!$O:$O,'COM RESID'!$H:$H,$E19,'COM RESID'!$I:$I,$F19)/SUMIFS('COM RESID'!$O:$O,'COM RESID'!$I:$I,$F19),3)*O19 -> 0 | O19: 0.2 | Q19: =SUBSTITUTE(C19,"MIN","MAX") -> * | S19: =E19 -> COMLPG | T19: =F19 -> COMHOTOldSHEUE | U19: =G19 -> COMHOTOldSHEUE | V19: 2030 | W19: =W18 -> UP | Y19: =-ROUNDUP(MIN(SUMIFS('COM RESID'!$O:$O,'COM RESID'!$H:$H,$E19,'COM RESID'!$I:$I,$F19)/SUMIFS('COM RESID'!$O:$O,'COM RESID'!$I:$I,$F19)*AC19,1),3) -> 0 | AC19: =IF(S19="COMELC",IF(SUMIFS('COM RESID'!$O:$O,'COM RESID'!$H:$H,$E19,'COM RESID'!$I:$I,$F19)/SUMIFS('COM RESID'!$O:$O,'COM RESID'!$I:$I,$F19)*1.5<0.5,0.5/(SUMIFS('COM RESID'!$O:$O,'COM RESID'!$H:$H,$E19,'COM RESID'!$I:$I,$F19)/SUMIFS('COM RESID'!$O:$O,'COM RESID'!$I:$I,$F19)),1.5),IF(ISNUMBER(SEARCH("WHEUE",T18)),IF(OR(S18="COMNGA",S18="COMFOI"),0.9,1.5),1.5)) -> 1.5
A20: =A19 -> 4 | C20: =IF(C19="*",C19,"") -> * | E20: =E19 -> COMLPG | F20: =F19 -> COMHOTOldSHEUE | G20: =G19 -> COMHOTOldSHEUE | H20: 2050 | I20: =I19 -> LO | K20: =-ROUNDDOWN(SUMIFS('COM RESID'!$O:$O,'COM RESID'!$H:$H,$E20,'COM RESID'!$I:$I,$F20)/SUMIFS('COM RESID'!$O:$O,'COM RESID'!$I:$I,$F20),3)*O20 -> 0 | O20: 0 | Q20: =SUBSTITUTE(C20,"MIN","MAX") -> * | S20: =E20 -> COMLPG | T20: =F20 -> COMHOTOldSHEUE | U20: =G20 -> COMHOTOldSHEUE | V20: 2050 | W20: =W19 -> UP | Y20: =-ROUNDUP(MIN(SUMIFS('COM RESID'!$O:$O,'COM RESID'!$H:$H,$E20,'COM RESID'!$I:$I,$F20)/SUMIFS('COM RESID'!$O:$O,'COM RESID'!$I:$I,$F20)*AC20,1),3) -> 0 | AC20: =IF(S20="COMELC",IF(SUMIFS('COM RESID'!$O:$O,'COM RESID'!$H:$H,$E20,'COM RESID'!$I:$I,$F20)/SUMIFS('COM RESID'!$O:$O,'COM RESID'!$I:$I,$F20)*3<1,1/(SUMIFS('COM RESID'!$O:$O,'COM RESID'!$H:$H,$E20,'COM RESID'!$I:$I,$F20)/SUMIFS('COM RESID'!$O:$O,'COM RESID'!$I:$I,$F20)),3),IF(ISNUMBER(SEARCH("WHEUE",T18)),IF(OR(S18="COMNGA",S18="COMFOI"),0.75,3),3)) -> 3
A21: =A17+1 -> 5 | C21: =IF(E21="","",IF(_xlfn.XLOOKUP($A21,Selected_constraint_UC!$A:$A,Selected_constraint_UC!$D:$D)=1,"*",IF(SUMIFS('COM TECH'!$N:$N,'COM TECH'!$K:$K,E21,'COM TECH'!$L:$L,F21)=0,"*",IF(SUMIFS('COM RESID'!$O:$O,'COM RESID'!$H:$H,$E21,'COM RESID'!$I:$I,$F21)=0,"*","UC_MarketShare_"&LEFT(F21,LEN(F21)-3)&"_"&RIGHT(E21,3)&"_MIN")))) -> * | E21: =_xlfn.XLOOKUP($A21,Selected_constraint_UC!$A:$A,Selected_constraint_UC!$B:$B) -> COMSTM | F21: =_xlfn.XLOOKUP($A21,Selected_constraint_UC!$A:$A,Selected_constraint_UC!$C:$C) -> COMHOTOldSHEUE | G21: =F21 -> COMHOTOldSHEUE | H21: 2019 | I21: LO | J21: 1 | K21: =-ROUNDDOWN(SUMIFS('COM RESID'!$O:$O,'COM RESID'!$H:$H,$E21,'COM RESID'!$I:$I,$F21)/SUMIFS('COM RESID'!$O:$O,'COM RESID'!$I:$I,$F21),3)*O21 -> -0.04018 | L21: 0 | M21: 5 | O21: 0.98 | Q21: =SUBSTITUTE(C21,"MIN","MAX") -> * | S21: =E21 -> COMSTM | T21: =F21 -> COMHOTOldSHEUE | U21: =G21 -> COMHOTOldSHEUE | V21: 2019 | W21: UP | X21: 1 | Y21: =-ROUNDUP(MIN(SUMIFS('COM RESID'!$O:$O,'COM RESID'!$H:$H,$E21,'COM RESID'!$I:$I,$F21)/SUMIFS('COM RESID'!$O:$O,'COM RESID'!$I:$I,$F21)*AC21,1),3) -> -0.043 | Z21: 0 | AA21: 5 | AC21: 1.02
A22: =A21 -> 5 | C22: =IF(C21="*",C21,"") -> * | E22: =E21 -> COMSTM | F22: =F21 -> COMHOTOldSHEUE | G22: =G21 -> COMHOTOldSHEUE | H22: 2025 | I22: =I21 -> LO | K22: =-ROUNDDOWN(SUMIFS('COM RESID'!$O:$O,'COM RESID'!$H:$H,$E22,'COM RESID'!$I:$I,$F22)/SUMIFS('COM RESID'!$O:$O,'COM RESID'!$I:$I,$F22),3)*O22 -> -0.0328 | O22: 0.8 | Q22: =SUBSTITUTE(C22,"MIN","MAX") -> * | S22: =E22 -> COMSTM | T22: =F22 -> COMHOTOldSHEUE | U22: =G22 -> COMHOTOldSHEUE | V22: 2025 | W22: =W21 -> UP | Y22: =-ROUNDUP(MIN(SUMIFS('COM RESID'!$O:$O,'COM RESID'!$H:$H,$E22,'COM RESID'!$I:$I,$F22)/SUMIFS('COM RESID'!$O:$O,'COM RESID'!$I:$I,$F22)*AC22,1),3) -> -0.05 | AC22: =IF(S22="COMELC",IF(SUMIFS('COM RESID'!$O:$O,'COM RESID'!$H:$H,$E22,'COM RESID'!$I:$I,$F22)/SUMIFS('COM RESID'!$O:$O,'COM RESID'!$I:$I,$F22)*1.2<0.25,0.25/(SUMIFS('COM RESID'!$O:$O,'COM RESID'!$H:$H,$E22,'COM RESID'!$I:$I,$F22)/SUMIFS('COM RESID'!$O:$O,'COM RESID'!$I:$I,$F22)),1.2),IF(ISNUMBER(SEARCH("WHEUE",T22)),IF(OR(S22="COMNGA",S22="COMFOI"),1,1.2),1.2)) -> 1.2
A23: =A22 -> 5 | C23: =IF(C22="*",C22,"") -> * | E23: =E22 -> COMSTM | F23: =F22 -> COMHOTOldSHEUE | G23: =G22 -> COMHOTOldSHEUE | H23: 2030 | I23: =I22 -> LO | K23: =-ROUNDDOWN(SUMIFS('COM RESID'!$O:$O,'COM RESID'!$H:$H,$E23,'COM RESID'!$I:$I,$F23)/SUMIFS('COM RESID'!$O:$O,'COM RESID'!$I:$I,$F23),3)*O23 -> -0.0082 | O23: 0.2 | Q23: =SUBSTITUTE(C23,"MIN","MAX") -> * | S23: =E23 -> COMSTM | T23: =F23 -> COMHOTOldSHEUE | U23: =G23 -> COMHOTOldSHEUE | V23: 2030 | W23: =W22 -> UP | Y23: =-ROUNDUP(MIN(SUMIFS('COM RESID'!$O:$O,'COM RESID'!$H:$H,$E23,'COM RESID'!$I:$I,$F23)/SUMIFS('COM RESID'!$O:$O,'COM RESID'!$I:$I,$F23)*AC23,1),3) -> -0.063 | AC23: =IF(S23="COMELC",IF(SUMIFS('COM RESID'!$O:$O,'COM RESID'!$H:$H,$E23,'COM RESID'!$I:$I,$F23)/SUMIFS('COM RESID'!$O:$O,'COM RESID'!$I:$I,$F23)*1.5<0.5,0.5/(SUMIFS('COM RESID'!$O:$O,'COM RESID'!$H:$H,$E23,'COM RESID'!$I:$I,$F23)/SUMIFS('COM RESID'!$O:$O,'COM RESID'!$I:$I,$F23)),1.5),IF(ISNUMBER(SEARCH("WHEUE",T22)),IF(OR(S22="COMNGA",S22="COMFOI"),0.9,1.5),1.5)) -> 1.5
A24: =A23 -> 5 | C24: =IF(C23="*",C23,"") -> * | E24: =E23 -> COMSTM | F24: =F23 -> COMHOTOldSHEUE | G24: =G23 -> COMHOTOldSHEUE | H24: 2050 | I24: =I23 -> LO | K24: =-ROUNDDOWN(SUMIFS('COM RESID'!$O:$O,'COM RESID'!$H:$H,$E24,'COM RESID'!$I:$I,$F24)/SUMIFS('COM RESID'!$O:$O,'COM RESID'!$I:$I,$F24),3)*O24 -> 0 | O24: 0 | Q24: =SUBSTITUTE(C24,"MIN","MAX") -> * | S24: =E24 -> COMSTM | T24: =F24 -> COMHOTOldSHEUE | U24: =G24 -> COMHOTOldSHEUE | V24: 2050 | W24: =W23 -> UP | Y24: =-ROUNDUP(MIN(SUMIFS('COM RESID'!$O:$O,'COM RESID'!$H:$H,$E24,'COM RESID'!$I:$I,$F24)/SUMIFS('COM RESID'!$O:$O,'COM RESID'!$I:$I,$F24)*AC24,1),3) -> -0.125 | AC24: =IF(S24="COMELC",IF(SUMIFS('COM RESID'!$O:$O,'COM RESID'!$H:$H,$E24,'COM RESID'!$I:$I,$F24)/SUMIFS('COM RESID'!$O:$O,'COM RESID'!$I:$I,$F24)*3<1,1/(SUMIFS('COM RESID'!$O:$O,'COM RESID'!$H:$H,$E24,'COM RESID'!$I:$I,$F24)/SUMIFS('COM RESID'!$O:$O,'COM RESID'!$I:$I,$F24)),3),IF(ISNUMBER(SEARCH("WHEUE",T22)),IF(OR(S22="COMNGA",S22="COMFOI"),0.75,3),3)) -> 3
A25: =A21+1 -> 6 | C25: =IF(E25="","",IF(_xlfn.XLOOKUP($A25,Selected_constraint_UC!$A:$A,Selected_constraint_UC!$D:$D)=1,"*",IF(SUMIFS('COM TECH'!$N:$N,'COM TECH'!$K:$K,E25,'COM TECH'!$L:$L,F25)=0,"*",IF(SUMIFS('COM RESID'!$O:$O,'COM RESID'!$H:$H,$E25,'COM RESID'!$I:$I,$F25)=0,"*","UC_MarketShare_"&LEFT(F25,LEN(F25)-3)&"_"&RIGHT(E25,3)&"_MIN")))) -> UC_MarketShare_COMHOTOldSC_ELC_MIN | E25: =_xlfn.XLOOKUP($A25,Selected_constraint_UC!$A:$A,Selected_constraint_UC!$B:$B) -> COMELC | F25: =_xlfn.XLOOKUP($A25,Selected_constraint_UC!$A:$A,Selected_constraint_UC!$C:$C) -> COMHOTOldSCEUE | G25: =F25 -> COMHOTOldSCEUE | H25: 2019 | I25: LO | J25: 1 | K25: =-ROUNDDOWN(SUMIFS('COM RESID'!$O:$O,'COM RESID'!$H:$H,$E25,'COM RESID'!$I:$I,$F25)/SUMIFS('COM RESID'!$O:$O,'COM RESID'!$I:$I,$F25),3)*O25 -> -0.98 | L25: 0 | M25: 5 | O25: 0.98 | Q25: =SUBSTITUTE(C25,"MIN","MAX") -> UC_MarketShare_COMHOTOldSC_ELC_MAX | S25: =E25 -> COMELC | T25: =F25 -> COMHOTOldSCEUE | U25: =G25 -> COMHOTOldSCEUE | V25: 2019 | W25: UP | X25: 1 | Y25: =-ROUNDUP(MIN(SUMIFS('COM RESID'!$O:$O,'COM RESID'!$H:$H,$E25,'COM RESID'!$I:$I,$F25)/SUMIFS('COM RESID'!$O:$O,'COM RESID'!$I:$I,$F25)*AC25,1),3) -> -1 | Z25: 0 | AA25: 5 | AC25: 1.02
A26: =A25 -> 6 | C26: =IF(C25="*",C25,"") | E26: =E25 -> COMELC | F26: =F25 -> COMHOTOldSCEUE | G26: =G25 -> COMHOTOldSCEUE | H26: 2025 | I26: =I25 -> LO | K26: =-ROUNDDOWN(SUMIFS('COM RESID'!$O:$O,'COM RESID'!$H:$H,$E26,'COM RESID'!$I:$I,$F26)/SUMIFS('COM RESID'!$O:$O,'COM RESID'!$I:$I,$F26),3)*O26 -> -0.8 | O26: 0.8 | Q26: =SUBSTITUTE(C26,"MIN","MAX") | S26: =E26 -> COMELC | T26: =F26 -> COMHOTOldSCEUE | U26: =G26 -> COMHOTOldSCEUE | V26: 2025 | W26: =W25 -> UP | Y26: =-ROUNDUP(MIN(SUMIFS('COM RESID'!$O:$O,'COM RESID'!$H:$H,$E26,'COM RESID'!$I:$I,$F26)/SUMIFS('COM RESID'!$O:$O,'COM RESID'!$I:$I,$F26)*AC26,1),3) -> -1 | AC26: =IF(S26="COMELC",IF(SUMIFS('COM RESID'!$O:$O,'COM RESID'!$H:$H,$E26,'COM RESID'!$I:$I,$F26)/SUMIFS('COM RESID'!$O:$O,'COM RESID'!$I:$I,$F26)*1.2<0.25,0.25/(SUMIFS('COM RESID'!$O:$O,'COM RESID'!$H:$H,$E26,'COM RESID'!$I:$I,$F26)/SUMIFS('COM RESID'!$O:$O,'COM RESID'!$I:$I,$F26)),1.2),IF(ISNUMBER(SEARCH("WHEUE",T26)),IF(OR(S26="COMNGA",S26="COMFOI"),1,1.2),1.2)) -> 1.2
A27: =A26 -> 6 | C27: =IF(C26="*",C26,"") | E27: =E26 -> COMELC | F27: =F26 -> COMHOTOldSCEUE | G27: =G26 -> COMHOTOldSCEUE | H27: 2030 | I27: =I26 -> LO | K27: =-ROUNDDOWN(SUMIFS('COM RESID'!$O:$O,'COM RESID'!$H:$H,$E27,'COM RESID'!$I:$I,$F27)/SUMIFS('COM RESID'!$O:$O,'COM RESID'!$I:$I,$F27),3)*O27 -> -0.75 | O27: 0.75 | Q27: =SUBSTITUTE(C27,"MIN","MAX") | S27: =E27 -> COMELC | T27: =F27 -> COMHOTOldSCEUE | U27: =G27 -> COMHOTOldSCEUE | V27: 2030 | W27: =W26 -> UP | Y27: =-ROUNDUP(MIN(SUMIFS('COM RESID'!$O:$O,'COM RESID'!$H:$H,$E27,'COM RESID'!$I:$I,$F27)/SUMIFS('COM RESID'!$O:$O,'COM RESID'!$I:$I,$F27)*AC27,1),3) -> -1 | AC27: =IF(S27="COMELC",IF(SUMIFS('COM RESID'!$O:$O,'COM RESID'!$H:$H,$E27,'COM RESID'!$I:$I,$F27)/SUMIFS('COM RESID'!$O:$O,'COM RESID'!$I:$I,$F27)*1.5<0.5,0.5/(SUMIFS('COM RESID'!$O:$O,'COM RESID'!$H:$H,$E27,'COM RESID'!$I:$I,$F27)/SUMIFS('COM RESID'!$O:$O,'COM RESID'!$I:$I,$F27)),1.5),IF(ISNUMBER(SEARCH("WHEUE",T26)),IF(OR(S26="COMNGA",S26="COMFOI"),0.9,1.5),1.5)) -> 1.5
A28: =A27 -> 6 | C28: =IF(C27="*",C27,"") | E28: =E27 -> COMELC | F28: =F27 -> COMHOTOldSCEUE | G28: =G27 -> COMHOTOldSCEUE | H28: 2050 | I28: =I27 -> LO | K28: =-ROUNDDOWN(SUMIFS('COM RESID'!$O:$O,'COM RESID'!$H:$H,$E28,'COM RESID'!$I:$I,$F28)/SUMIFS('COM RESID'!$O:$O,'COM RESID'!$I:$I,$F28),3)*O28 -> -0.75 | O28: 0.75 | Q28: =SUBSTITUTE(C28,"MIN","MAX") | S28: =E28 -> COMELC | T28: =F28 -> COMHOTOldSCEUE | U28: =G28 -> COMHOTOldSCEUE | V28: 2050 | W28: =W27 -> UP | Y28: =-ROUNDUP(MIN(SUMIFS('COM RESID'!$O:$O,'COM RESID'!$H:$H,$E28,'COM RESID'!$I:$I,$F28)/SUMIFS('COM RESID'!$O:$O,'COM RESID'!$I:$I,$F28)*AC28,1),3) -> -1 | AC28: =IF(S28="COMELC",IF(SUMIFS('COM RESID'!$O:$O,'COM RESID'!$H:$H,$E28,'COM RESID'!$I:$I,$F28)/SUMIFS('COM RESID'!$O:$O,'COM RESID'!$I:$I,$F28)*3<1,1/(SUMIFS('COM RESID'!$O:$O,'COM RESID'!$H:$H,$E28,'COM RESID'!$I:$I,$F28)/SUMIFS('COM RESID'!$O:$O,'COM RESID'!$I:$I,$F28)),3),IF(ISNUMBER(SEARCH("WHEUE",T26)),IF(OR(S26="COMNGA",S26="COMFOI"),0.75,3),3)) -> 3
A29: =A25+1 -> 7 | C29: =IF(E29="","",IF(_xlfn.XLOOKUP($A29,Selected_constraint_UC!$A:$A,Selected_constraint_UC!$D:$D)=1,"*",IF(SUMIFS('COM TECH'!$N:$N,'COM TECH'!$K:$K,E29,'COM TECH'!$L:$L,F29)=0,"*",IF(SUMIFS('COM RESID'!$O:$O,'COM RESID'!$H:$H,$E29,'COM RESID'!$I:$I,$F29)=0,"*","UC_MarketShare_"&LEFT(F29,LEN(F29)-3)&"_"&RIGHT(E29,3)&"_MIN")))) -> * | E29: =_xlfn.XLOOKUP($A29,Selected_constraint_UC!$A:$A,Selected_constraint_UC!$B:$B) -> COMELC | F29: =_xlfn.XLOOKUP($A29,Selected_constraint_UC!$A:$A,Selected_constraint_UC!$C:$C) -> COMHOTOldVTEUE | G29: =F29 -> COMHOTOldVTEUE | H29: 2019 | I29: LO | J29: 1 | K29: =-ROUNDDOWN(SUMIFS('COM RESID'!$O:$O,'COM RESID'!$H:$H,$E29,'COM RESID'!$I:$I,$F29)/SUMIFS('COM RESID'!$O:$O,'COM RESID'!$I:$I,$F29),3)*O29 -> -0.98 | L29: 0 | M29: 5 | O29: 0.98 | Q29: =SUBSTITUTE(C29,"MIN","MAX") -> * | S29: =E29 -> COMELC | T29: =F29 -> COMHOTOldVTEUE | U29: =G29 -> COMHOTOldVTEUE | V29: 2019 | W29: UP | X29: 1 | Y29: =-ROUNDUP(MIN(SUMIFS('COM RESID'!$O:$O,'COM RESID'!$H:$H,$E29,'COM RESID'!$I:$I,$F29)/SUMIFS('COM RESID'!$O:$O,'COM RESID'!$I:$I,$F29)*AC29,1),3) -> -1 | Z29: 0 | AA29: 5 | AC29: 1.02
A30: =A29 -> 7 | C30: =IF(C29="*",C29,"") -> * | E30: =E29 -> COMELC | F30: =F29 -> COMHOTOldVTEUE | G30: =G29 -> COMHOTOldVTEUE | H30: 2025 | I30: =I29 -> LO | K30: =-ROUNDDOWN(SUMIFS('COM RESID'!$O:$O,'COM RESID'!$H:$H,$E30,'COM RESID'!$I:$I,$F30)/SUMIFS('COM RESID'!$O:$O,'COM RESID'!$I:$I,$F30),3)*O30 -> -0.8 | O30: 0.8 | Q30: =SUBSTITUTE(C30,"MIN","MAX") -> * | S30: =E30 -> COMELC | T30: =F30 -> COMHOTOldVTEUE | U30: =G30 -> COMHOTOldVTEUE | V30: 2025 | W30: =W29 -> UP | Y30: =-ROUNDUP(MIN(SUMIFS('COM RESID'!$O:$O,'COM RESID'!$H:$H,$E30,'COM RESID'!$I:$I,$F30)/SUMIFS('COM RESID'!$O:$O,'COM RESID'!$I:$I,$F30)*AC30,1),3) -> -1 | AC30: =IF(S30="COMELC",IF(SUMIFS('COM RESID'!$O:$O,'COM RESID'!$H:$H,$E30,'COM RESID'!$I:$I,$F30)/SUMIFS('COM RESID'!$O:$O,'COM RESID'!$I:$I,$F30)*1.2<0.25,0.25/(SUMIFS('COM RESID'!$O:$O,'COM RESID'!$H:$H,$E30,'COM RESID'!$I:$I,$F30)/SUMIFS('COM RESID'!$O:$O,'COM RESID'!$I:$I,$F30)),1.2),IF(ISNUMBER(SEARCH("WHEUE",T30)),IF(OR(S30="COMNGA",S30="COMFOI"),1,1.2),1.2)) -> 1.2
A31: =A30 -> 7 | C31: =IF(C30="*",C30,"") -> * | E31: =E30 -> COMELC | F31: =F30 -> COMHOTOldVTEUE | G31: =G30 -> COMHOTOldVTEUE | H31: 2030 | I31: =I30 -> LO | K31: =-ROUNDDOWN(SUMIFS('COM RESID'!$O:$O,'COM RESID'!$H:$H,$E31,'COM RESID'!$I:$I,$F31)/SUMIFS('COM RESID'!$O:$O,'COM RESID'!$I:$I,$F31),3)*O31 -> -0.2 | O31: 0.2 | Q31: =SUBSTITUTE(C31,"MIN","MAX") -> * | S31: =E31 -> COMELC | T31: =F31 -> COMHOTOldVTEUE | U31: =G31 -> COMHOTOldVTEUE | V31: 2030 | W31: =W30 -> UP | Y31: =-ROUNDUP(MIN(SUMIFS('COM RESID'!$O:$O,'COM RESID'!$H:$H,$E31,'COM RESID'!$I:$I,$F31)/SUMIFS('COM RESID'!$O:$O,'COM RESID'!$I:$I,$F31)*AC31,1),3) -> -1 | AC31: =IF(S31="COMELC",IF(SUMIFS('COM RESID'!$O:$O,'COM RESID'!$H:$H,$E31,'COM RESID'!$I:$I,$F31)/SUMIFS('COM RESID'!$O:$O,'COM RESID'!$I:$I,$F31)*1.5<0.5,0.5/(SUMIFS('COM RESID'!$O:$O,'COM RESID'!$H:$H,$E31,'COM RESID'!$I:$I,$F31)/SUMIFS('COM RESID'!$O:$O,'COM RESID'!$I:$I,$F31)),1.5),IF(ISNUMBER(SEARCH("WHEUE",T30)),IF(OR(S30="COMNGA",S30="COMFOI"),0.9,1.5),1.5)) -> 1.5
A32: =A31 -> 7 | C32: =IF(C31="*",C31,"") -> * | E32: =E31 -> COMELC | F32: =F31 -> COMHOTOldVTEUE | G32: =G31 -> COMHOTOldVTEUE | H32: 2050 | I32: =I31 -> LO | K32: =-ROUNDDOWN(SUMIFS('COM RESID'!$O:$O,'COM RESID'!$H:$H,$E32,'COM RESID'!$I:$I,$F32)/SUMIFS('COM RESID'!$O:$O,'COM RESID'!$I:$I,$F32),3)*O32 -> 0 | O32: 0 | Q32: =SUBSTITUTE(C32,"MIN","MAX") -> * | S32: =E32 -> COMELC | T32: =F32 -> COMHOTOldVTEUE | U32: =G32 -> COMHOTOldVTEUE | V32: 2050 | W32: =W31 -> UP | Y32: =-ROUNDUP(MIN(SUMIFS('COM RESID'!$O:$O,'COM RESID'!$H:$H,$E32,'COM RESID'!$I:$I,$F32)/SUMIFS('COM RESID'!$O:$O,'COM RESID'!$I:$I,$F32)*AC32,1),3) -> -1 | AC32: =IF(S32="COMELC",IF(SUMIFS('COM RESID'!$O:$O,'COM RESID'!$H:$H,$E32,'COM RESID'!$I:$I,$F32)/SUMIFS('COM RESID'!$O:$O,'COM RESID'!$I:$I,$F32)*3<1,1/(SUMIFS('COM RESID'!$O:$O,'COM RESID'!$H:$H,$E32,'COM RESID'!$I:$I,$F32)/SUMIFS('COM RESID'!$O:$O,'COM RESID'!$I:$I,$F32)),3),IF(ISNUMBER(SEARCH("WHEUE",T30)),IF(OR(S30="COMNGA",S30="COMFOI"),0.75,3),3)) -> 3
