Workbook

Sheet ReadMe
A1: Generic Comet (GC) TIMES Supply
B3: Sheet color
C4: Raw Data and Parameters
C6: City Specific Data
C8: Post processing for TIMES
C10: Table formatted for TIMES

Sheet >> City Data

Sheet City characteristics
B2: City Basic Data
B4: Calibration methodology | C4: GHG Inventory
B6: A. City Characteristics
B7: Data Item | C7: Value | D7: Units
B8: City Name | C8: New York
B9: Latitude | C9: 40.5
B10: Longitude | C10: -75
B11: County | C11: New York County
B12: State | C12: New York
B13: Census Division | C13: Middle Atlantic
B14: Climate Division | C14: Northeast
B15: Egrid Region | C15: NPCC NYC/Westchester
B16: Area of city (excluding water, natural and agricultural areas) | C16: 778 | D16: square kilometers
B17: * Division and Region Map can be found in the Maps sheet.
B18: B. Planning Base Year and Target Years
B19: Year | C19: Value | D19: Units
B20: Base Year | C20: 2019 | D20: Acceptable range [2018,2021]
B21: End Year | C21: 2050
B23: C. City Population and GDP
B24: Data Item | C24: Value | D24: Units
B25: Population in Base Year | C25: 8337 | D25: Thousand of people
B26: Annual population growth (Base Year - End Year) | C26: 0.5 | D26: % people
B27: GDP in Base Year | C27: 1206000 | D27: Million US$
B28: Annual GDP growth rate | C28: 2 | D28: % US$
B29: Share of manufacturing GDP | C29: 5 | D29: % US$
B30: Share of State population | C30: 0.42835123
B31: Share of State GDP | C31: 0.67251772
B32: Adjustment from state manufacturing GDP | C32: 1.0638298
B34: D. Climate Data
B35: Data Item | C35: 2000 | D35: 2050 | E35: 2100 | F35: Units
B36: Heating degree days (HDD) | C36: 4473.4625 | D36: 4066.4182 | E36: 3763.8582 | F36: F
B37: Cooling degree days (CDD) | C37: 1020.7333 | D37: 1224.2555 | E37: 1375.5355 | F37: F
B39: Data Item | C39: Value | D39: Units
B40: Correction from State HDD | C40: 0.72727402
B41: Correction from State CDD | C41: 1.5583715
B42: Annual precipitation | C42: 762 | D42: mm / year
B43: Climate change scenario | C43: RCP4.5
B44: Average temperature increase in 1980-2020 | C44: 1.4617857 | D44: F
B45: Forecasted average temperature increase in 2035-2065 | C45: 3.13 | D45: F
B46: Forecasted average temperature increase in 2070-2100 | C46: 4.37 | D46: F
...

Sheet >> GC RESID

Sheet ELC RESID
O1: 2019 | P1: 2020 | Q1: 2025 | R1: 2030 | S1: 2035 | T1: 2040 | U1: 2045 | V1: 2050 | W1: 2055 | X1: 2060 | Y1: 2065 | Z1: 2070 | AA1: 2075 | AB1: 2080 | AC1: 2085 | AD1: 2090 | AE1: 2095 | AF1: 2100 | AG1: 2019 | AH1: 2030 | AI1: 2050 | AJ1: 2100 | AK1: 2019 | AL1: 2030 | AM1: 2050 | AN1: 2100 | AO1: 2019 | AP1: 2030 | AQ1: 2050 | AR1: 2100
A2: Sector | B2: Sub-sector | C2: Archetype | D2: Vintage | E2: End Use | F2: Technology | G2: Energy | H2: Technology Label | I2: Generation (TJ) | J2: Fuel Input (MWh) | K2: Capacity Factor (%) | L2: Efficiency (%) | M2: Fixed OM 2023 US$ / kW . Yr | N2: Variable OM 2023 US$ / GJ | O2: Capacity base year (MW) | P2: Capacity 2020 (MW) | Q2: Capacity 2025 (MW) | R2: Capacity 2030 (MW) | S2: Capacity 2035 (MW) | T2: Capacity 2040 (MW) | U2: Capacity 2045 (MW) | V2: Capacity 2050 (MW) | W2: Capacity 2055 (MW) | X2: Capacity 2060 (MW) | Y2: Capacity 2065 (MW) | Z2: Capacity 2070 (MW) | AA2: Capacity 2075 (MW) | AB2: Capacity 2080 (MW) | AC2: Capacity 2085 (MW) | AD2: Capacity 2090 (MW) | AE2: Capacity 2095 (MW) | AF2: Capacity 2100 (MW) | AG2: Average CO2 emission factor ( t CO2 / TJ) | AH2: Average CO2 emission factor ( t CO2 / TJ) | AI2: Average CO2 emission factor ( t CO2 / TJ) | AJ2: Average CO2 emission factor ( t CO2 / TJ) | AK2: Average CH4 emission factor ( t CH4 / TJ) | AL2: Average CH4 emission factor ( t CH4 / TJ) | AM2: Average CH4 emission factor ( t CH4 / TJ) | AN2: Average CH4 emission factor ( t CH4 / TJ) | AO2: Average N2O emission factor ( t N2O / TJ) | AP2: Average N2O emission factor ( t N2O / TJ) | AQ2: Average N2O emission factor ( t N2O / TJ) | AR2: Average N2O emission factor ( t N2O / TJ)
A3: Electricity | B3: Grid | D3: 2019 | E3: Dispatchable | F3: Combustion turbine | G3: Natural gas | H3: ELCNGAGRDCTU19 | I3: 12173.114 | J3: 34569.709 | K3: 0.13746195 | L3: 0.35213238 | M3: 27.138389 | N3: 2.0228151 | O3: 2808.1 | P3: 1517.2 | Q3: 1517.2 | R3: 1517.2 | S3: 1517.2 | T3: 681.9 | U3: 677.3 | V3: 139.5 | W3: 0 | X3: 0 | Y3: 0 | Z3: 0 | AA3: 0 | AB3: 0 | AC3: 0 | AD3: 0 | AE3: 0 | AF3: 0
A4: Electricity | B4: Grid | D4: 2019 | E4: Dispatchable | F4: Steam turbine | G4: Natural gas | H4: ELCNGAGRDSTU19 | I4: 10774.678 | J4: 29246.467 | K4: 0.084997091 | L4: 0.36840957 | M4: 27.138389 | N4: 2.0228151 | O4: 4019.7 | P4: 16 | Q4: 16 | R4: 16 | S4: 16 | T4: 16 | U4: 16 | V4: 0 | W4: 0 | X4: 0 | Y4: 0 | Z4: 0 | AA4: 0 | AB4: 0 | AC4: 0 | AD4: 0 | AE4: 0 | AF4: 0
A5: Electricity | B5: Grid | D5: 2019 | E5: Dispatchable | F5: Combined cycle combustion turbine | G5: Natural gas | H5: ELCNGAGRDCCC19 | I5: 46780.596 | J5: 91771.957 | K5: 0.64588452 | L5: 0.50974827 | M5: 35.166828 | N5: 0.61563937 | O5: 2296.7 | P5: 2296.7 | Q5: 2296.7 | R5: 1726.5 | S5: 1484.5 | T5: 751 | U5: 400 | V5: 0 | W5: 0 | X5: 0 | Y5: 0 | Z5: 0 | AA5: 0 | AB5: 0 | AC5: 0 | AD5: 0 | AE5: 0 | AF5: 0
A6: Electricity | B6: Grid | D6: 2019 | E6: Dispatchable | F6: Combined cycle steam turbine | G6: Natural gas | H6: ELCNGAGRDCCS19 | I6: 17753.904 | J6: 34991.141 | K6: 0.47892182 | L6: 0.50738283 | M6: 35.166828 | N6: 0.61563937 | O6: 1175.5 | P6: 1173.1 | Q6: 1173.1 | R6: 860.5 | S6: 780.5 | T6: 505 | U6: 250 | V6: 0 | W6: 0 | X6: 0 | Y6: 0 | Z6: 0 | AA6: 0 | AB6: 0 | AC6: 0 | AD6: 0 | AE6: 0 | AF6: 0
A7: Electricity | B7: Grid | D7: 2019 | E7: Dispatchable | F7: Combined cycle - single shaft | G7: Natural gas | H7: ELCNGAGRDACC19 | I7: 0 | J7: 0 | M7: 34.827599 | N7: 0.61563937 | O7: 0 | P7: 0 | Q7: 0 | R7: 0 | S7: 0 | T7: 0 | U7: 0 | V7: 0 | W7: 0 | X7: 0 | Y7: 0 | Z7: 0 | AA7: 0 | AB7: 0 | AC7: 0 | AD7: 0 | AE7: 0 | AF7: 0
A8: Electricity | B8: Grid | D8: 2019 | E8: Dispatchable | F8: Other turbine | G8: Natural gas | H8: ELCNGAGRDOTT19 | I8: 0 | J8: 0 | M8: 34.827599 | N8: 0.61563937 | O8: 0 | P8: 0 | Q8: 0 | R8: 0 | S8: 0 | T8: 0 | U8: 0 | V8: 0 | W8: 0 | X8: 0 | Y8: 0 | Z8: 0 | AA8: 0 | AB8: 0 | AC8: 0 | AD8: 0 | AE8: 0 | AF8: 0
A9: Electricity | B9: Grid | D9: 2019 | E9: Dispatchable | F9: Internal combustion engine | G9: Natural gas | H9: ELCNGAGRDICE19 | I9: 234.73082 | J9: 538.0716 | K9: 0.23406495 | L9: 0.43624458 | M9: 27.138389 | N9: 2.0228151 | O9: 31.8 | P9: 31.8 | Q9: 31.8 | R9: 23.4 | S9: 22.5 | T9: 22.3 | U9: 2.4 | V9: 0 | W9: 0 | X9: 0 | Y9: 0 | Z9: 0 | AA9: 0 | AB9: 0 | AC9: 0 | AD9: 0 | AE9: 0 | AF9: 0
A10: Electricity | B10: Grid | D10: 2019 | E10: Dispatchable | F10: Fuel cell | G10: Natural gas | H10: ELCNGAGRDFCE19 | I10: 192.024 | J10: 392.5061 | K10: 0.92258198 | L10: 0.48922552 | M10: 34.827599 | N10: 0.61563937 | O10: 6.6 | P10: 6.6 | Q10: 6.6 | R10: 6.6 | S10: 6.6 | T10: 6.6 | U10: 6.6 | V10: 6.6 | W10: 0 | X10: 0 | Y10: 0 | Z10: 0 | AA10: 0 | AB10: 0 | AC10: 0 | AD10: 0 | AE10: 0 | AF10: 0
A11: Electricity | B11: Grid | D11: 2019 | E11: Dispatchable | F11: Combustion turbine | G11: RNG | H11: ELCRNGGRDCTU19 | I11: 0 | J11: 0 | M11: 27.138389 | N11: 2.0228151 | O11: 0 | P11: 0 | Q11: 0 | R11: 0 | S11: 0 | T11: 0 | U11: 0 | V11: 0 | W11: 0 | X11: 0 | Y11: 0 | Z11: 0 | AA11: 0 | AB11: 0 | AC11: 0 | AD11: 0 | AE11: 0 | AF11: 0
A12: Electricity | B12: Grid | D12: 2019 | E12: Dispatchable | F12: Steam turbine | G12: RNG | H12: ELCRNGGRDSTU19 | I12: 0 | J12: 0 | M12: 27.138389 | N12: 2.0228151 | O12: 0 | P12: 0 | Q12: 0 | R12: 0 | S12: 0 | T12: 0 | U12: 0 | V12: 0 | W12: 0 | X12: 0 | Y12: 0 | Z12: 0 | AA12: 0 | AB12: 0 | AC12: 0 | AD12: 0 | AE12: 0 | AF12: 0
A13: Electricity | B13: Grid | D13: 2019 | E13: Dispatchable | F13: Combined cycle combustion turbine | G13: RNG | H13: ELCRNGGRDCCC19 | I13: 0 | J13: 0 | M13: 35.166828 | N13: 0.61563937 | O13: 0 | P13: 0 | Q13: 0 | R13: 0 | S13: 0 | T13: 0 | U13: 0 | V13: 0 | W13: 0 | X13: 0 | Y13: 0 | Z13: 0 | AA13: 0 | AB13: 0 | AC13: 0 | AD13: 0 | AE13: 0 | AF13: 0
A14: Electricity | B14: Grid | D14: 2019 | E14: Dispatchable | F14: Combined cycle steam turbine | G14: RNG | H14: ELCRNGGRDCCS19 | I14: 0 | J14: 0 | M14: 35.166828 | N14: 0.61563937 | O14: 0 | P14: 0 | Q14: 0 | R14: 0 | S14: 0 | T14: 0 | U14: 0 | V14: 0 | W14: 0 | X14: 0 | Y14: 0 | Z14: 0 | AA14: 0 | AB14: 0 | AC14: 0 | AD14: 0 | AE14: 0 | AF14: 0
A15: Electricity | B15: Grid | D15: 2019 | E15: Dispatchable | F15: Internal combustion engine | G15: RNG | H15: ELCRNGGRDICE19 | I15: 0 | J15: 0 | M15: 27.138389 | N15: 2.0228151 | O15: 0 | P15: 0 | Q15: 0 | R15: 0 | S15: 0 | T15: 0 | U15: 0 | V15: 0 | W15: 0 | X15: 0 | Y15: 0 | Z15: 0 | AA15: 0 | AB15: 0 | AC15: 0 | AD15: 0 | AE15: 0 | AF15: 0
A16: Electricity | B16: Grid | D16: 2019 | E16: Dispatchable | F16: Fuel cell | G16: RNG | H16: ELCRNGGRDFCE19 | I16: 0 | J16: 0 | M16: 34.827599 | N16: 0.61563937 | O16: 0 | P16: 0 | Q16: 0 | R16: 0 | S16: 0 | T16: 0 | U16: 0 | V16: 0 | W16: 0 | X16: 0 | Y16: 0 | Z16: 0 | AA16: 0 | AB16: 0 | AC16: 0 | AD16: 0 | AE16: 0 | AF16: 0
A17: Electricity | B17: Grid | D17: 2019 | E17: Dispatchable | F17: Combustion turbine | G17: Fuel oil | H17: ELCFOIGRDCTU19 | I17: 16.1352 | J17: 99.921256 | K17: 0.0013132542 | L17: 0.16147915 | M17: 27.138389 | N17: 2.0228151 | O17: 389.6 | P17: 0 | Q17: 0 | R17: 0 | S17: 0 | T17: 0 | U17: 0 | V17: 0 | W17: 0 | X17: 0 | Y17: 0 | Z17: 0 | AA17: 0 | AB17: 0 | AC17: 0 | AD17: 0 | AE17: 0 | AF17: 0
A18: Electricity | B18: Grid | D18: 2019 | E18: Dispatchable | F18: Steam turbine | G18: Fuel oil | H18: ELCFOIGRDSTU19 | I18: 0 | J18: 0 | M18: 27.138389 | N18: 2.0228151 | O18: 0 | P18: 0 | Q18: 0 | R18: 0 | S18: 0 | T18: 0 | U18: 0 | V18: 0 | W18: 0 | X18: 0 | Y18: 0 | Z18: 0 | AA18: 0 | AB18: 0 | AC18: 0 | AD18: 0 | AE18: 0 | AF18: 0
A19: Electricity | B19: Grid | D19: 2019 | E19: Dispatchable | F19: Combined cycle combustion turbine | G19: Fuel oil | H19: ELCFOIGRDCCC19 | I19: 0 | J19: 0 | M19: 35.166828 | N19: 0.61563937 | O19: 0 | P19: 0 | Q19: 0 | R19: 0 | S19: 0 | T19: 0 | U19: 0 | V19: 0 | W19: 0 | X19: 0 | Y19: 0 | Z19: 0 | AA19: 0 | AB19: 0 | AC19: 0 | AD19: 0 | AE19: 0 | AF19: 0
A20: Electricity | B20: Grid | D20: 2019 | E20: Dispatchable | F20: Combined cycle steam turbine | G20: Fuel oil | H20: ELCFOIGRDCCS19 | I20: 0 | J20: 0 | M20: 35.166828 | N20: 0.61563937 | O20: 0 | P20: 0 | Q20: 0 | R20: 0 | S20: 0 | T20: 0 | U20: 0 | V20: 0 | W20: 0 | X20: 0 | Y20: 0 | Z20: 0 | AA20: 0 | AB20: 0 | AC20: 0 | AD20: 0 | AE20: 0 | AF20: 0
A21: Electricity | B21: Grid | D21: 2019 | E21: Dispatchable | F21: Other turbine | G21: Fuel oil | H21: ELCFOIGRDOTT19 | I21: 0 | J21: 0 | M21: 35.166828 | N21: 0.61563937 | O21: 0 | P21: 0 | Q21: 0 | R21: 0 | S21: 0 | T21: 0 | U21: 0 | V21: 0 | W21: 0 | X21: 0 | Y21: 0 | Z21: 0 | AA21: 0 | AB21: 0 | AC21: 0 | AD21: 0 | AE21: 0 | AF21: 0
A22: Electricity | B22: Grid | D22: 2019 | E22: Dispatchable | F22: Internal combustion engine | G22: Fuel oil | H22: ELCFOIGRDICE19 | I22: 8.6313024 | J22: 31.086118 | K22: 0.0012700548 | L22: 0.27765778 | M22: 34.827599 | N22: 0.61563937 | O22: 215.5 | P22: 186.1 | Q22: 178.8 | R22: 172 | S22: 141.7 | T22: 105 | U22: 55.6 | V22: 13 | W22: 0 | X22: 0 | Y22: 0 | Z22: 0 | AA22: 0 | AB22: 0 | AC22: 0 | AD22: 0 | AE22: 0 | AF22: 0
A23: Electricity | B23: Grid | D23: 2019 | E23: Dispatchable | F23: Steam turbine | G23: Coal | H23: ELCCOAGRDSTU19 | I23: 0 | J23: 0 | M23: 87.747456 | N23: 2.6573005 | O23: 0 | P23: 0 | Q23: 0 | R23: 0 | S23: 0 | T23: 0 | U23: 0 | V23: 0 | W23: 0 | X23: 0 | Y23: 0 | Z23: 0 | AA23: 0 | AB23: 0 | AC23: 0 | AD23: 0 | AE23: 0 | AF23: 0
A24: Electricity | B24: Grid | D24: 2019 | E24: Dispatchable | F24: Other turbine | G24: Coal | H24: ELCCOAGRDOTT19 | I24: 0 | J24: 0 | M24: 169.72801 | N24: 4.6392824 | O24: 0 | P24: 0 | Q24: 0 | R24: 0 | S24: 0 | T24: 0 | U24: 0 | V24: 0 | W24: 0 | X24: 0 | Y24: 0 | Z24: 0 | AA24: 0 | AB24: 0 | AC24: 0 | AD24: 0 | AE24: 0 | AF24: 0
A25: Electricity | B25: Grid | D25: 2019 | E25: Dispatchable | F25: Steam turbine | G25: Biomass | H25: ELCBIOGRDSTU19 | I25: 0 | J25: 0 | M25: 177.77906 | N25: 1.5830727 | O25: 0 | P25: 0 | Q25: 0 | R25: 0 | S25: 0 | T25: 0 | U25: 0 | V25: 0 | W25: 0 | X25: 0 | Y25: 0 | Z25: 0 | AA25: 0 | AB25: 0 | AC25: 0 | AD25: 0 | AE25: 0 | AF25: 0
A26: Electricity | B26: Grid | D26: 2019 | E26: Dispatchable | F26: Other turbine | G26: Biomass | H26: ELCBIOGRDOTT19 | I26: 0 | J26: 0 | M26: 177.77906 | N26: 1.5830727 | O26: 0 | P26: 0 | Q26: 0 | R26: 0 | S26: 0 | T26: 0 | U26: 0 | V26: 0 | W26: 0 | X26: 0 | Y26: 0 | Z26: 0 | AA26: 0 | AB26: 0 | AC26: 0 | AD26: 0 | AE26: 0 | AF26: 0
A27: Electricity | B27: Grid | D27: 2019 | E27: Dispatchable | F27: Internal combustion engine | G27: Other bioenergy | H27: ELCOTBGRDICE19 | I27: 0 | J27: 0 | M27: 177.77906 | N27: 1.5830727 | O27: 0 | P27: 0 | Q27: 0 | R27: 0 | S27: 0 | T27: 0 | U27: 0 | V27: 0 | W27: 0 | X27: 0 | Y27: 0 | Z27: 0 | AA27: 0 | AB27: 0 | AC27: 0 | AD27: 0 | AE27: 0 | AF27: 0
A28: Electricity | B28: Grid | D28: 2019 | E28: Dispatchable | F28: Steam turbine | G28: Waste | H28: ELCWASGRDSTU19 | I28: 1357.2108 | J28: 7369.616 | K28: 0.72088563 | L28: 0.18416303 | M28: 177.77906 | N28: 1.5830727 | O28: 59.7 | P28: 59.7 | Q28: 59.7 | R28: 59.7 | S28: 0 | T28: 0 | U28: 0 | V28: 0 | W28: 0 | X28: 0 | Y28: 0 | Z28: 0 | AA28: 0 | AB28: 0 | AC28: 0 | AD28: 0 | AE28: 0 | AF28: 0
A29: Electricity | B29: Grid | D29: 2019 | E29: Dispatchable | F29: Steam turbine | G29: Waste heat | H29: ELCHETGRDSTU19 | I29: 0 | J29: 0 | M29: 177.77906 | N29: 1.5830727 | O29: 0 | P29: 0 | Q29: 0 | R29: 0 | S29: 0 | T29: 0 | U29: 0 | V29: 0 | W29: 0 | X29: 0 | Y29: 0 | Z29: 0 | AA29: 0 | AB29: 0 | AC29: 0 | AD29: 0 | AE29: 0 | AF29: 0
A30: Electricity | B30: Grid | D30: 2019 | E30: Dispatchable | F30: Other turbine | G30: Waste heat | H30: ELCHETGRDOTT19 | I30: 0 | J30: 0 | M30: 177.77906 | N30: 1.5830727 | O30: 0 | P30: 0 | Q30: 0 | R30: 0 | S30: 0 | T30: 0 | U30: 0 | V30: 0 | W30: 0 | X30: 0 | Y30: 0 | Z30: 0 | AA30: 0 | AB30: 0 | AC30: 0 | AD30: 0 | AE30: 0 | AF30: 0
A31: Electricity | B31: Grid | D31: 2019 | E31: Dispatchable | F31: Steam turbine | G31: Steam | H31: ELCSTMGRDSTU19 | I31: 0 | J31: 0 | M31: 177.77906 | N31: 1.5830727 | O31: 0 | P31: 0 | Q31: 0 | R31: 0 | S31: 0 | T31: 0 | U31: 0 | V31: 0 | W31: 0 | X31: 0 | Y31: 0 | Z31: 0 | AA31: 0 | AB31: 0 | AC31: 0 | AD31: 0 | AE31: 0 | AF31: 0
A32: Electricity | B32: Grid | D32: 2019 | E32: Dispatchable | F32: Steam turbine | G32: Uranium | H32: ELCURNGRDSTU19 | I32: 60101.435 | J32: 182125.56 | K32: 0.82466638 | L32: 0.33 | M32: 172.01215 | N32: 0.77583125 | O32: 2311 | P32: 2311 | Q32: 0 | R32: 0 | S32: 0 | T32: 0 | U32: 0 | V32: 0 | W32: 0 | X32: 0 | Y32: 0 | Z32: 0 | AA32: 0 | AB32: 0 | AC32: 0 | AD32: 0 | AE32: 0 | AF32: 0
A33: Electricity | B33: Grid | D33: 2019 | E33: Storage | F33: Compressed air energy storage | G33: Storage | H33: ELCSTGGRDCES19 | I33: 0 | J33: 0 | M33: 44.870272 | N33: 0 | O33: 0 | P33: 0 | Q33: 0 | R33: 0 | S33: 0 | T33: 0 | U33: 0 | V33: 0 | W33: 0 | X33: 0 | Y33: 0 | Z33: 0 | AA33: 0 | AB33: 0 | AC33: 0 | AD33: 0 | AE33: 0 | AF33: 0
A34: Electricity | B34: Grid | D34: 2019 | E34: Storage | F34: Flywheel energy storage | G34: Storage | H34: ELCSTGGRDFES19 | I34: 0 | J34: 0 | M34: 44.870272 | N34: 0 | O34: 0 | P34: 0 | Q34: 0 | R34: 0 | S34: 0 | T34: 0 | U34: 0 | V34: 0 | W34: 0 | X34: 0 | Y34: 0 | Z34: 0 | AA34: 0 | AB34: 0 | AC34: 0 | AD34: 0 | AE34: 0 | AF34: 0
A35: Electricity | B35: Grid | D35: 2019 | E35: Storage | F35: Battery energy storage | G35: Storage | H35: ELCSTGGRDBES19 | I35: 0 | J35: 0 | L35: 0.8 | M35: 44.870272 | N35: 0 | O35: 0 | P35: 0 | Q35: 0 | R35: 0 | S35: 0 | T35: 0 | U35: 0 | V35: 0 | W35: 0 | X35: 0 | Y35: 0 | Z35: 0 | AA35: 0 | AB35: 0 | AC35: 0 | AD35: 0 | AE35: 0 | AF35: 0
A36: Electricity | B36: Grid | D36: 2019 | E36: Baseload | F36: Steam turbine | G36: Geothermal | H36: ELCGEOGRDSTU19 | I36: 0 | J36: 0 | L36: 1 | M36: 170.80991 | N36: 0 | O36: 0 | P36: 0 | Q36: 0 | R36: 0 | S36: 0 | T36: 0 | U36: 0 | V36: 0 | W36: 0 | X36: 0 | Y36: 0 | Z36: 0 | AA36: 0 | AB36: 0 | AC36: 0 | AD36: 0 | AE36: 0 | AF36: 0
A37: Electricity | B37: Grid | D37: 2019 | E37: Baseload | F37: Binary cycle turbine | G37: Geothermal | H37: ELCGEOGRDBCT19 | I37: 0 | J37: 0 | L37: 1 | M37: 128.47969 | N37: 0 | O37: 0 | P37: 0 | Q37: 0 | R37: 0 | S37: 0 | T37: 0 | U37: 0 | V37: 0 | W37: 0 | X37: 0 | Y37: 0 | Z37: 0 | AA37: 0 | AB37: 0 | AC37: 0 | AD37: 0 | AE37: 0 | AF37: 0
A38: Electricity | B38: Grid | D38: 2019 | E38: Non Dispatchable | F38: Wind turbine - onshore | G38: Wind | H38: ELCWNDGRDWON19 | I38: 0 | J38: 0 | L38: 1 | M38: 34.974598 | N38: 0 | O38: 0 | P38: 0 | Q38: 0 | R38: 0 | S38: 0 | T38: 0 | U38: 0 | V38: 0 | W38: 0 | X38: 0 | Y38: 0 | Z38: 0 | AA38: 0 | AB38: 0 | AC38: 0 | AD38: 0 | AE38: 0 | AF38: 0
A39: Electricity | B39: Grid | D39: 2019 | E39: Non Dispatchable | F39: Wind turbine - offshore | G39: Wind | H39: ELCWNDGRDWOF19 | I39: 0 | J39: 0 | L39: 1 | M39: 112.55896 | N39: 0 | O39: 0 | P39: 0 | Q39: 0 | R39: 0 | S39: 0 | T39: 0 | U39: 0 | V39: 0 | W39: 0 | X39: 0 | Y39: 0 | Z39: 0 | AA39: 0 | AB39: 0 | AC39: 0 | AD39: 0 | AE39: 0 | AF39: 0
A40: Electricity | B40: Grid | D40: 2019 | E40: Storage | F40: Hydraulic turbine - reversible | G40: Storage | H40: ELCSTGGRDHES19 | I40: 0 | J40: 0 | L40: 0.7 | M40: 21.100097 | N40: 0.16961493 | O40: 0 | P40: 0 | Q40: 0 | R40: 0 | S40: 0 | T40: 0 | U40: 0 | V40: 0 | W40: 0 | X40: 0 | Y40: 0 | Z40: 0 | AA40: 0 | AB40: 0 | AC40: 0 | AD40: 0 | AE40: 0 | AF40: 0
...

Sheet >> GC TECH

Sheet ENE TECH
H1: 2023 Dollar / GJ
A2: GHGI Sector | B2: GHGI Energy | C2: AEO Sector | D2: AEO Energy | E2: Description | F2: Multiplicateur | G2: Commodity Label | H2: 2019 | I2: 2020 | J2: 2021 | K2: 2022 | L2: 2023 | M2: 2024 | N2: 2025 | O2: 2030 | P2: 2035 | Q2: 2040 | R2: 2045 | S2: 2050 | T2: 2055 | U2: 2060 | V2: 2065 | W2: 2070 | X2: 2075 | Y2: 2080 | Z2: 2085 | AA2: 2090 | AB2: 2095 | AC2: 2100
A3: Residential | B3: LPG | C3: Residential | D3: Propane | E3: Hydrocarbon gas liquids price in the residential sector | F3: 1 | G3: RESLPG | H3: 33.139282 | I3: 28.404792 | J3: 34.017648 | K3: 36.740013 | L3: 38.524662 | M3: 38.53425 | N3: 37.487506 | O3: 36.540775 | P3: 42.127352 | Q3: 46.993146 | R3: 51.097312 | S3: 54.209147 | T3: 54.209147 | U3: 54.209147 | V3: 54.209147 | W3: 54.209147 | X3: 54.209147 | Y3: 54.209147 | Z3: 54.209147 | AA3: 54.209147 | AB3: 54.209147 | AC3: 54.209147
A4: Residential | B4: Fuel oil | C4: Residential | D4: Distillate Fuel Oil | E4: Distillate fuel oil price in the residential sector | F4: 1 | G4: RESFOI | H4: 21.264373 | I4: 17.088445 | J4: 19.92401 | K4: 21.518489 | L4: 19.660523 | M4: 18.79016 | N4: 17.783449 | O4: 17.917993 | P4: 19.239678 | Q4: 20.738888 | R4: 22.093132 | S4: 23.258847 | T4: 23.258847 | U4: 23.258847 | V4: 23.258847 | W4: 23.258847 | X4: 23.258847 | Y4: 23.258847 | Z4: 23.258847 | AA4: 23.258847 | AB4: 23.258847 | AC4: 23.258847
A5: Residential | B5: Kerosene | C5: Residential | D5: Distillate Fuel Oil | E5: Kerosene price in the residential sector | F5: 1 | G5: RESKER | H5: 24.732951 | I5: 15.775618 | J5: 24.575447 | K5: 26.54217 | L5: 24.250446 | M5: 23.176889 | N5: 21.935152 | O5: 22.101108 | P5: 23.731351 | Q5: 25.580565 | R5: 27.250969 | S5: 28.68883 | T5: 28.68883 | U5: 28.68883 | V5: 28.68883 | W5: 28.68883 | X5: 28.68883 | Y5: 28.68883 | Z5: 28.68883 | AA5: 28.68883 | AB5: 28.68883 | AC5: 28.68883
A6: Residential | B6: Natural gas | C6: Residential | D6: Natural Gas | E6: Natural gas price in the residential sector (including supplemental gaseous fuels) | F6: 1 | G6: RESNGA | H6: 13.498734 | I6: 13.43206 | J6: 14.30799 | K6: 15.45303 | L6: 14.920712 | M6: 13.39134 | N6: 12.76654 | O6: 12.386274 | P6: 13.885007 | Q6: 15.199748 | R6: 16.020235 | S6: 16.83725 | T6: 16.83725 | U6: 16.83725 | V6: 16.83725 | W6: 16.83725 | X6: 16.83725 | Y6: 16.83725 | Z6: 16.83725 | AA6: 16.83725 | AB6: 16.83725 | AC6: 16.83725
A7: Residential | B7: RNG | C7: Residential | D7: Natural Gas | E7: Natural gas price in the residential sector (including supplemental gaseous fuels) | F7: 2 | G7: RESRNG | H7: 26.997469 | I7: 26.86412 | J7: 28.61598 | K7: 30.90606 | L7: 29.841423 | M7: 26.78268 | N7: 25.533081 | O7: 24.772548 | P7: 27.770013 | Q7: 30.399496 | R7: 32.04047 | S7: 33.6745 | T7: 33.6745 | U7: 33.6745 | V7: 33.6745 | W7: 33.6745 | X7: 33.6745 | Y7: 33.6745 | Z7: 33.6745 | AA7: 33.6745 | AB7: 33.6745 | AC7: 33.6745
A8: Residential | B8: Electricity | C8: Residential | D8: Electricity | E8: Electricity price in the residential sector | F8: 1 | G8: RESELC | H8: 58.082115 | I8: 58.393657 | J8: 61.197471 | K8: 66.094982 | L8: 62.991999 | M8: 60.939902 | N8: 59.863655 | O8: 61.403024 | P8: 67.073536 | Q8: 72.818505 | R8: 77.93633 | S8: 81.383542 | T8: 81.383542 | U8: 81.383542 | V8: 81.383542 | W8: 81.383542 | X8: 81.383542 | Y8: 81.383542 | Z8: 81.383542 | AA8: 81.383542 | AB8: 81.383542 | AC8: 81.383542
A9: Residential | B9: Hydrogen | C9: Residential | D9: Electricity | E9: Electricity price in the residential sector | F9: 2 | G9: RESH2G | H9: 116.16423 | I9: 116.78731 | J9: 122.39494 | K9: 132.18996 | L9: 125.984 | M9: 121.8798 | N9: 119.72731 | O9: 122.80605 | P9: 134.14707 | Q9: 145.63701 | R9: 155.87266 | S9: 162.76708 | T9: 162.76708 | U9: 162.76708 | V9: 162.76708 | W9: 162.76708 | X9: 162.76708 | Y9: 162.76708 | Z9: 162.76708 | AA9: 162.76708 | AB9: 162.76708 | AC9: 162.76708
A10: Residential | B10: Steam | C10: Residential | D10: Electricity | E10: Electricity price in the residential sector | F10: 2 | G10: RESSTM | H10: 116.16423 | I10: 116.78731 | J10: 122.39494 | K10: 132.18996 | L10: 125.984 | M10: 121.8798 | N10: 119.72731 | O10: 122.80605 | P10: 134.14707 | Q10: 145.63701 | R10: 155.87266 | S10: 162.76708 | T10: 162.76708 | U10: 162.76708 | V10: 162.76708 | W10: 162.76708 | X10: 162.76708 | Y10: 162.76708 | Z10: 162.76708 | AA10: 162.76708 | AB10: 162.76708 | AC10: 162.76708
A11: Residential | B11: Solar | C11: Residential | D11: Solar | F11: 1 | G11: RESSOL | H11: 0 | I11: 0 | J11: 0 | K11: 0 | L11: 0 | M11: 0 | N11: 0 | O11: 0 | P11: 0 | Q11: 0 | R11: 0 | S11: 0 | T11: 0 | U11: 0 | V11: 0 | W11: 0 | X11: 0 | Y11: 0 | Z11: 0 | AA11: 0 | AB11: 0 | AC11: 0
A12: Residential | B12: Wind | C12: Residential | D12: Wind | F12: 1 | G12: RESWND | H12: 0 | I12: 0 | J12: 0 | K12: 0 | L12: 0 | M12: 0 | N12: 0 | O12: 0 | P12: 0 | Q12: 0 | R12: 0 | S12: 0 | T12: 0 | U12: 0 | V12: 0 | W12: 0 | X12: 0 | Y12: 0 | Z12: 0 | AA12: 0 | AB12: 0 | AC12: 0
A13: Commercial | B13: LPG | C13: Commercial | D13: Propane | E13: Hydrocarbon gas liquids price in the commercial sector | F13: 1 | G13: COMLPG | H13: 15.796391 | I13: 14.365143 | J13: 21.949636 | K13: 23.706221 | L13: 22.146428 | M13: 20.587193 | N13: 19.055314 | O13: 19.150876 | P13: 22.286658 | Q13: 24.66189 | R13: 26.631887 | S13: 28.104431 | T13: 28.104431 | U13: 28.104431 | V13: 28.104431 | W13: 28.104431 | X13: 28.104431 | Y13: 28.104431 | Z13: 28.104431 | AA13: 28.104431 | AB13: 28.104431 | AC13: 28.104431
A14: Commercial | B14: Diesel | C14: Commercial | D14: Distillate Fuel Oil | E14: Distillate fuel oil price in the commercial sector | F14: 1 | G14: COMDSL | H14: 17.387077 | I14: 11.511644 | J14: 18.252065 | K14: 19.712741 | L14: 18.085099 | M14: 16.656612 | N14: 15.093246 | O14: 13.112384 | P14: 14.115668 | Q14: 15.25231 | R14: 16.270151 | S14: 17.126833 | T14: 17.126833 | U14: 17.126833 | V14: 17.126833 | W14: 17.126833 | X14: 17.126833 | Y14: 17.126833 | Z14: 17.126833 | AA14: 17.126833 | AB14: 17.126833 | AC14: 17.126833
A15: Commercial | B15: Fuel oil | C15: Commercial | D15: Residual Fuel Oil | E15: Distillate fuel oil price in the commercial sector | F15: 1 | G15: COMFOI | H15: 17.387077 | I15: 11.511644 | J15: 18.252065 | K15: 19.712741 | L15: 12.042501 | M15: 14.295152 | N15: 14.501626 | O15: 22.312094 | P15: 24.510554 | Q15: 26.868519 | R15: 29.144687 | S15: 31.154017 | T15: 31.154017 | U15: 31.154017 | V15: 31.154017 | W15: 31.154017 | X15: 31.154017 | Y15: 31.154017 | Z15: 31.154017 | AA15: 31.154017 | AB15: 31.154017 | AC15: 31.154017
A16: Commercial | B16: Kerosene | C16: Commercial | D16: Distillate Fuel Oil | E16: Kerosene price in the commercial sector | F16: 1 | G16: COMKER | H16: 24.732951 | I16: 15.775618 | J16: 24.575447 | K16: 26.54217 | L16: 24.350636 | M16: 22.427252 | N16: 20.322262 | O16: 17.655135 | P16: 19.006005 | Q16: 20.536434 | R16: 21.906903 | S16: 23.06038 | T16: 23.06038 | U16: 23.06038 | V16: 23.06038 | W16: 23.06038 | X16: 23.06038 | Y16: 23.06038 | Z16: 23.06038 | AA16: 23.06038 | AB16: 23.06038 | AC16: 23.06038
A17: Commercial | B17: Gasoline | C17: Commercial | D17: Distillate Fuel Oil | E17: Motor gasoline price in the commercial sector | F17: 1 | G17: COMGSL | H17: 23.164358 | I17: 19.377754 | J17: 25.582901 | K17: 27.630249 | L17: 25.348874 | M17: 23.346643 | N17: 21.15536 | O17: 18.378896 | P17: 19.785143 | Q17: 21.378311 | R17: 22.804962 | S17: 24.005725 | T17: 24.005725 | U17: 24.005725 | V17: 24.005725 | W17: 24.005725 | X17: 24.005725 | Y17: 24.005725 | Z17: 24.005725 | AA17: 24.005725 | AB17: 24.005725 | AC17: 24.005725
A18: Commercial | B18: Natural gas | C18: Commercial | D18: Natural Gas | E18: Natural gas price in the commercial sector (including supplemental gaseous fuels) | F18: 1 | G18: COMNGA | H18: 7.7104063 | I18: 7.2259709 | J18: 8.2096782 | K18: 8.8666823 | L18: 8.1872197 | M18: 7.255384 | N18: 6.9579136 | O18: 6.9767662 | P18: 7.8550132 | Q18: 8.6079722 | R18: 9.0230732 | S18: 9.4628453 | T18: 9.4628453 | U18: 9.4628453 | V18: 9.4628453 | W18: 9.4628453 | X18: 9.4628453 | Y18: 9.4628453 | Z18: 9.4628453 | AA18: 9.4628453 | AB18: 9.4628453 | AC18: 9.4628453
A19: Commercial | B19: RNG | C19: Residential | D19: Natural Gas | E19: Natural gas price in the commercial sector (including supplemental gaseous fuels) | F19: 2 | G19: COMRNG | H19: 15.420813 | I19: 14.451942 | J19: 16.419356 | K19: 17.733365 | L19: 17.122494 | M19: 15.36744 | N19: 14.650442 | O19: 14.214061 | P19: 15.933955 | Q19: 17.442707 | R19: 18.38427 | S19: 19.321848 | T19: 19.321848 | U19: 19.321848 | V19: 19.321848 | W19: 19.321848 | X19: 19.321848 | Y19: 19.321848 | Z19: 19.321848 | AA19: 19.321848 | AB19: 19.321848 | AC19: 19.321848
A20: Commercial | B20: Electricity | C20: Commercial | D20: Electricity | E20: Electricity price in the commercial sector | F20: 1 | G20: COMELC | H20: 45.511281 | I20: 46.296123 | J20: 50.490593 | K20: 54.531254 | L20: 52.397516 | M20: 49.460663 | N20: 48.055492 | O20: 48.075179 | P20: 51.458958 | Q20: 55.269325 | R20: 58.192769 | S20: 60.029189 | T20: 60.029189 | U20: 60.029189 | V20: 60.029189 | W20: 60.029189 | X20: 60.029189 | Y20: 60.029189 | Z20: 60.029189 | AA20: 60.029189 | AB20: 60.029189 | AC20: 60.029189
A21: Commercial | B21: Hydrogen | C21: Commercial | D21: Electricity | E21: Electricity price in the commercial sector | F21: 2 | G21: COMH2G | H21: 91.022562 | I21: 92.592246 | J21: 100.98119 | K21: 109.06251 | L21: 104.79503 | M21: 98.921325 | N21: 96.110985 | O21: 96.150359 | P21: 102.91792 | Q21: 110.53865 | R21: 116.38554 | S21: 120.05838 | T21: 120.05838 | U21: 120.05838 | V21: 120.05838 | W21: 120.05838 | X21: 120.05838 | Y21: 120.05838 | Z21: 120.05838 | AA21: 120.05838 | AB21: 120.05838 | AC21: 120.05838
A22: Commercial | B22: Steam | C22: Commercial | D22: Electricity | E22: Electricity price in the commercial sector | F22: 2 | G22: COMSTM | H22: 91.022562 | I22: 92.592246 | J22: 100.98119 | K22: 109.06251 | L22: 104.79503 | M22: 98.921325 | N22: 96.110985 | O22: 96.150359 | P22: 102.91792 | Q22: 110.53865 | R22: 116.38554 | S22: 120.05838 | T22: 120.05838 | U22: 120.05838 | V22: 120.05838 | W22: 120.05838 | X22: 120.05838 | Y22: 120.05838 | Z22: 120.05838 | AA22: 120.05838 | AB22: 120.05838 | AC22: 120.05838
A23: Commercial | B23: Solar | C23: Commercial | D23: Solar | F23: 1 | G23: COMSOL | H23: 0 | I23: 0 | J23: 0 | K23: 0 | L23: 0 | M23: 0 | N23: 0 | O23: 0 | P23: 0 | Q23: 0 | R23: 0 | S23: 0 | T23: 0 | U23: 0 | V23: 0 | W23: 0 | X23: 0 | Y23: 0 | Z23: 0 | AA23: 0 | AB23: 0 | AC23: 0
A24: Commercial | B24: Wind | C24: Commercial | D24: Wind | F24: 1 | G24: COMWND | H24: 0 | I24: 0 | J24: 0 | K24: 0 | L24: 0 | M24: 0 | N24: 0 | O24: 0 | P24: 0 | Q24: 0 | R24: 0 | S24: 0 | T24: 0 | U24: 0 | V24: 0 | W24: 0 | X24: 0 | Y24: 0 | Z24: 0 | AA24: 0 | AB24: 0 | AC24: 0
A25: Industrial | B25: LPG | C25: Industrial | D25: Propane | E25: Hydrocarbon gas liquids price in the industrial sector | F25: 1 | G25: INDLPG | H25: 15.144652 | I25: 13.529708 | J25: 22.453363 | K25: 24.25026 | L25: 21.481797 | M25: 19.265321 | N25: 17.113109 | O25: 16.995916 | P25: 20.560588 | Q25: 23.160107 | R25: 25.227695 | S25: 26.667272 | T25: 26.667272 | U25: 26.667272 | V25: 26.667272 | W25: 26.667272 | X25: 26.667272 | Y25: 26.667272 | Z25: 26.667272 | AA25: 26.667272 | AB25: 26.667272 | AC25: 26.667272
A26: Industrial | B26: Diesel | C26: Industrial | D26: Distillate Fuel Oil | E26: Distillate fuel oil price in the industrial sector | F26: 1 | G26: INDDSL | H26: 16.205109 | I26: 11.359747 | J26: 15.42262 | K26: 16.656861 | L26: 15.231331 | M26: 14.040168 | N26: 12.700199 | O26: 10.980378 | P26: 11.829788 | Q26: 12.813168 | R26: 13.701334 | S26: 14.458269 | T26: 14.458269 | U26: 14.458269 | V26: 14.458269 | W26: 14.458269 | X26: 14.458269 | Y26: 14.458269 | Z26: 14.458269 | AA26: 14.458269 | AB26: 14.458269 | AC26: 14.458269
A27: Industrial | B27: Fuel oil | C27: Industrial | D27: Residual Fuel Oil | E27: Residual fuel oil price in the industrial sector | F27: 1 | G27: INDFOI | H27: 10.803406 | I27: 8.3760503 | J27: 12.314517 | K27: 13.300023 | L27: 8.305852 | M27: 9.8242712 | N27: 10.264384 | O27: 15.911878 | P27: 17.519001 | Q27: 19.207624 | R27: 20.805142 | S27: 22.199438 | T27: 22.199438 | U27: 22.199438 | V27: 22.199438 | W27: 22.199438 | X27: 22.199438 | Y27: 22.199438 | Z27: 22.199438 | AA27: 22.199438 | AB27: 22.199438 | AC27: 22.199438
A28: Industrial | B28: Kerosene | C28: Industrial | D28: Distillate Fuel Oil | E28: Kerosene price in the industrial sector | F28: 1 | G28: INDKER | H28: 18.734741 | I28: 13.594807 | J28: 17.801926 | K28: 19.226579 | L28: 17.581126 | M28: 16.206198 | N28: 14.659507 | O28: 12.674363 | P28: 13.654814 | Q28: 14.789904 | R28: 15.815091 | S28: 16.688801 | T28: 16.688801 | U28: 16.688801 | V28: 16.688801 | W28: 16.688801 | X28: 16.688801 | Y28: 16.688801 | Z28: 16.688801 | AA28: 16.688801 | AB28: 16.688801 | AC28: 16.688801
A29: Industrial | B29: Gasoline | C29: Industrial | D29: Distillate Fuel Oil | E29: Motor gasoline price in the industrial sector | F29: 1 | G29: INDGSL | H29: 23.164358 | I29: 19.377754 | J29: 25.582901 | K29: 27.630249 | L29: 25.265592 | M29: 23.289702 | N29: 21.066973 | O29: 18.214151 | P29: 19.623143 | Q29: 21.254366 | R29: 22.727647 | S29: 23.983244 | T29: 23.983244 | U29: 23.983244 | V29: 23.983244 | W29: 23.983244 | X29: 23.983244 | Y29: 23.983244 | Z29: 23.983244 | AA29: 23.983244 | AB29: 23.983244 | AC29: 23.983244
A30: Industrial | B30: Natural gas | C30: Industrial | D30: Natural Gas | E30: Natural gas price in the industrial sector (including supplemental gaseous fuels) | F30: 1 | G30: INDNGA | H30: 8.2406349 | I30: 7.3453188 | J30: 8.7026876 | K30: 9.3991463 | L30: 7.8406608 | M30: 6.3176618 | N30: 5.7092575 | O30: 5.4161205 | P30: 6.513417 | Q30: 7.3212058 | R30: 7.4682076 | S30: 7.6916073 | T30: 7.6916073 | U30: 7.6916073 | V30: 7.6916073 | W30: 7.6916073 | X30: 7.6916073 | Y30: 7.6916073 | Z30: 7.6916073 | AA30: 7.6916073 | AB30: 7.6916073 | AC30: 7.6916073
A31: Industrial | B31: RNG | C31: Industrial | D31: Natural Gas | E31: Natural gas price in the industrial sector (including supplemental gaseous fuels) | F31: 2 | G31: INDRNG | H31: 16.48127 | I31: 14.690638 | J31: 17.405375 | K31: 18.798293 | L31: 15.681322 | M31: 12.635324 | N31: 11.418515 | O31: 10.832241 | P31: 13.026834 | Q31: 14.642412 | R31: 14.936415 | S31: 15.383215 | T31: 15.383215 | U31: 15.383215 | V31: 15.383215 | W31: 15.383215 | X31: 15.383215 | Y31: 15.383215 | Z31: 15.383215 | AA31: 15.383215 | AB31: 15.383215 | AC31: 15.383215
A32: Industrial | B32: Petcoke | C32: Industrial | D32: Metallurgical Coal | E32: Coal price in the industrial sector | F32: 1 | G32: INDPCK | H32: 3.7778782 | I32: 3.9818789 | J32: 3.6011121 | K32: 3.8893019 | L32: 3.8487693 | M32: 3.941073 | N32: 4.0063417 | O32: 4.4118735 | P32: 4.9805162 | Q32: 5.5737404 | R32: 6.1313001 | S32: 6.6964864 | T32: 6.6964864 | U32: 6.6964864 | V32: 6.6964864 | W32: 6.6964864 | X32: 6.6964864 | Y32: 6.6964864 | Z32: 6.6964864 | AA32: 6.6964864 | AB32: 6.6964864 | AC32: 6.6964864
A33: Industrial | B33: Coal | C33: Industrial | D33: Other Industrial Coal | E33: Coal price in the industrial sector | F33: 1 | G33: INDCOA | H33: 3.7778782 | I33: 3.9818789 | J33: 3.6011121 | K33: 3.8893019 | L33: 3.7264743 | M33: 3.6977751 | N33: 3.7934473 | O33: 3.9236989 | P33: 4.1425814 | Q33: 4.4356799 | R33: 4.6979638 | S33: 4.9689665 | T33: 4.9689665 | U33: 4.9689665 | V33: 4.9689665 | W33: 4.9689665 | X33: 4.9689665 | Y33: 4.9689665 | Z33: 4.9689665 | AA33: 4.9689665 | AB33: 4.9689665 | AC33: 4.9689665
A34: Industrial | B34: Electricity | C34: Industrial | D34: Electricity | E34: Electricity price in the industrial sector | F34: 1 | G34: INDELC | H34: 18.171373 | I34: 17.630935 | J34: 19.92401 | K34: 21.518489 | L34: 20.695312 | M34: 18.778729 | N34: 18.127859 | O34: 17.722945 | P34: 19.063147 | Q34: 20.732893 | R34: 21.803489 | S34: 22.407178 | T34: 22.407178 | U34: 22.407178 | V34: 22.407178 | W34: 22.407178 | X34: 22.407178 | Y34: 22.407178 | Z34: 22.407178 | AA34: 22.407178 | AB34: 22.407178 | AC34: 22.407178
A35: Industrial | B35: Hydrogen | C35: Industrial | D35: Electricity | E35: Electricity price in the industrial sector | F35: 2 | G35: INDH2G | H35: 36.342746 | I35: 35.26187 | J35: 39.84802 | K35: 43.036978 | L35: 41.390623 | M35: 37.557459 | N35: 36.255717 | O35: 35.445891 | P35: 38.126294 | Q35: 41.465785 | R35: 43.606978 | S35: 44.814355 | T35: 44.814355 | U35: 44.814355 | V35: 44.814355 | W35: 44.814355 | X35: 44.814355 | Y35: 44.814355 | Z35: 44.814355 | AA35: 44.814355 | AB35: 44.814355 | AC35: 44.814355
A36: Industrial | B36: Steam | C36: Industrial | D36: Electricity | E36: Electricity price in the industrial sector | F36: 2 | G36: INDSTM | H36: 36.342746 | I36: 35.26187 | J36: 39.84802 | K36: 43.036978 | L36: 41.390623 | M36: 37.557459 | N36: 36.255717 | O36: 35.445891 | P36: 38.126294 | Q36: 41.465785 | R36: 43.606978 | S36: 44.814355 | T36: 44.814355 | U36: 44.814355 | V36: 44.814355 | W36: 44.814355 | X36: 44.814355 | Y36: 44.814355 | Z36: 44.814355 | AA36: 44.814355 | AB36: 44.814355 | AC36: 44.814355
A37: Industrial | B37: Solar | C37: Industrial | D37: Solar | F37: 1 | G37: INDSOL | H37: 0 | I37: 0 | J37: 0 | K37: 0 | L37: 0 | M37: 0 | N37: 0 | O37: 0 | P37: 0 | Q37: 0 | R37: 0 | S37: 0 | T37: 0 | U37: 0 | V37: 0 | W37: 0 | X37: 0 | Y37: 0 | Z37: 0 | AA37: 0 | AB37: 0 | AC37: 0
A38: Industrial | B38: Wind | C38: Industrial | D38: Wind | F38: 1 | G38: INDWND | H38: 0 | I38: 0 | J38: 0 | K38: 0 | L38: 0 | M38: 0 | N38: 0 | O38: 0 | P38: 0 | Q38: 0 | R38: 0 | S38: 0 | T38: 0 | U38: 0 | V38: 0 | W38: 0 | X38: 0 | Y38: 0 | Z38: 0 | AA38: 0 | AB38: 0 | AC38: 0
A39: Transportation | B39: LPG | C39: Transportation | D39: Propane | E39: Hydrocarbon gas liquids price in the transportation sector | F39: 1 | G39: TRALPG | H39: 16.470223 | I39: 15.026982 | J39: 22.646279 | K39: 24.458616 | L39: 22.342301 | M39: 20.794551 | N39: 19.365335 | O39: 19.716729 | P39: 22.748775 | Q39: 25.076457 | R39: 27.010912 | S39: 28.480687 | T39: 28.480687 | U39: 28.480687 | V39: 28.480687 | W39: 28.480687 | X39: 28.480687 | Y39: 28.480687 | Z39: 28.480687 | AA39: 28.480687 | AB39: 28.480687 | AC39: 28.480687
A40: Transportation | B40: Ethanol | C40: Transportation | D40: E85 | E40: Motor gasoline price in the transportation sector | F40: 1.2 | G40: TRAETH | H40: 27.79723 | I40: 23.253305 | J40: 30.699481 | K40: 33.156299 | L40: 28.73724 | M40: 27.204245 | N40: 25.274519 | O40: 26.267091 | P40: 28.182933 | Q40: 30.271527 | R40: 32.405294 | S40: 34.480395 | T40: 34.480395 | U40: 34.480395 | V40: 34.480395 | W40: 34.480395 | X40: 34.480395 | Y40: 34.480395 | Z40: 34.480395 | AA40: 34.480395 | AB40: 34.480395 | AC40: 34.480395
...

Sheet >> TIMES

Sheet GHG_IPCC
K2: CO2 | X2: CH4 | AK2: N2O | AX2: CO2e
C4: ~TFM_INS | P4: ~TFM_INS | AC4: ~TFM_INS | AP4: ~TFM_INS
C5: TimeSlice | D5: LimType | E5: Attribute | F5: Year | G5: Other_Indexes | H5: Pset_PN | I5: PSET_CI | J5: Pset_PD | K5: Cset_CN | L5: CITY | M5: EGRID | P5: TimeSlice | Q5: LimType | R5: Attribute | S5: Year | T5: Other_Indexes | U5: Pset_PN | V5: PSET_CI | W5: Pset_PD | X5: Cset_CN | Y5: CITY | Z5: EGRID | AC5: TimeSlice | AD5: LimType | AE5: Attribute | AF5: Year | AG5: Other_Indexes | AH5: Pset_PN | AI5: PSET_CI | AJ5: Pset_PD | AK5: Cset_CN | AL5: CITY | AM5: EGRID | AP5: TimeSlice | AQ5: LimType | AR5: Attribute | AS5: Year | AT5: Other_Indexes | AU5: Pset_PN | AV5: PSET_CI | AW5: Pset_PD | AX5: Cset_CN | AY5: CITY | AZ5: EGRID
E6: FLO_EMIS | F6: ='City characteristics'!$C$20 -> 2019 | G6: ='ENE TECH'!$G3 -> RESLPG | I6: ='ENE TECH'!$G3 -> RESLPG | K6: =LEFT(G6,3)&K$2 -> RESCO2 | L6: =_xlfn.IFNA(_xlfn.XLOOKUP(_xlfn.XLOOKUP(_xlfn.XLOOKUP(G6,'ENE TECH'!$G:$G,'ENE TECH'!$B:$B),Mapping!$B:$B,Mapping!$C:$C),'Emission Factors Hub'!$C:$C,'Emission Factors Hub'!$E:$E)/Parameters!$C$2*10^3,0) -> 58.489795 | M6: =IF(LEFT(I6,3)="ELC",L6,"") | R6: FLO_EMIS | S6: ='City characteristics'!$C$20 -> 2019 | T6: ='ENE TECH'!$G3 -> RESLPG | V6: ='ENE TECH'!$G3 -> RESLPG | X6: =LEFT(T6,3)&X$2 -> RESCH4 | Y6: =_xlfn.IFNA(_xlfn.XLOOKUP(_xlfn.XLOOKUP(_xlfn.XLOOKUP(T6,'ENE TECH'!$G:$G,'ENE TECH'!$B:$B),Mapping!$B:$B,Mapping!$C:$C),'Emission Factors Hub'!$C:$C,'Emission Factors Hub'!$F:$F)/Parameters!$C$2,0) -> 0.0028434514 | Z6: =IF(LEFT(V6,3)="ELC",Y6,"") | AE6: FLO_EMIS | AF6: ='City characteristics'!$C$20 -> 2019 | AG6: ='ENE TECH'!$G3 -> RESLPG | AI6: ='ENE TECH'!$G3 -> RESLPG | AK6: =LEFT(AG6,3)&AK$2 -> RESN2O | AL6: =_xlfn.IFNA(_xlfn.XLOOKUP(_xlfn.XLOOKUP(_xlfn.XLOOKUP(AG6,'ENE TECH'!$G:$G,'ENE TECH'!$B:$B),Mapping!$B:$B,Mapping!$C:$C),'Emission Factors Hub'!$C:$C,'Emission Factors Hub'!$G:$G)/Parameters!$C$2,0) -> 0.00056869027 | AM6: =IF(LEFT(AI6,3)="ELC",AL6,"") | AR6: FLO_EMIS | AS6: ='City characteristics'!$C$20 -> 2019 | AT6: ='ENE TECH'!$G3 -> RESLPG | AV6: ='ENE TECH'!$G3 -> RESLPG | AX6: =LEFT(AT6,3)&AX$2 -> RESCO2e | AY6: =L6+Y6*'Emission Factors Hub'!$E$8+AL6*'Emission Factors Hub'!$E$9 -> 58.730351 | AZ6: =IFERROR(M6+Z6*'Emission Factors Hub'!$E$8+AM6*'Emission Factors Hub'!$E$9,"")
E7: FLO_EMIS | F7: ='City characteristics'!$C$20 -> 2019 | G7: ='ENE TECH'!$G4 -> RESFOI | I7: ='ENE TECH'!$G4 -> RESFOI | K7: =LEFT(G7,3)&K$2 -> RESCO2 | L7: =_xlfn.IFNA(_xlfn.XLOOKUP(_xlfn.XLOOKUP(_xlfn.XLOOKUP(G7,'ENE TECH'!$G:$G,'ENE TECH'!$B:$B),Mapping!$B:$B,Mapping!$C:$C),'Emission Factors Hub'!$C:$C,'Emission Factors Hub'!$E:$E)/Parameters!$C$2*10^3,0) -> 71.181066 | M7: =IF(LEFT(I7,3)="ELC",L7,"") | R7: FLO_EMIS | S7: ='City characteristics'!$C$20 -> 2019 | T7: ='ENE TECH'!$G4 -> RESFOI | V7: ='ENE TECH'!$G4 -> RESFOI | X7: =LEFT(T7,3)&X$2 -> RESCH4 | Y7: =_xlfn.IFNA(_xlfn.XLOOKUP(_xlfn.XLOOKUP(_xlfn.XLOOKUP(T7,'ENE TECH'!$G:$G,'ENE TECH'!$B:$B),Mapping!$B:$B,Mapping!$C:$C),'Emission Factors Hub'!$C:$C,'Emission Factors Hub'!$F:$F)/Parameters!$C$2,0) -> 0.0028434514 | Z7: =IF(LEFT(V7,3)="ELC",Y7,"") | AE7: FLO_EMIS | AF7: ='City characteristics'!$C$20 -> 2019 | AG7: ='ENE TECH'!$G4 -> RESFOI | AI7: ='ENE TECH'!$G4 -> RESFOI | AK7: =LEFT(AG7,3)&AK$2 -> RESN2O | AL7: =_xlfn.IFNA(_xlfn.XLOOKUP(_xlfn.XLOOKUP(_xlfn.XLOOKUP(AG7,'ENE TECH'!$G:$G,'ENE TECH'!$B:$B),Mapping!$B:$B,Mapping!$C:$C),'Emission Factors Hub'!$C:$C,'Emission Factors Hub'!$G:$G)/Parameters!$C$2,0) -> 0.00056869027 | AM7: =IF(LEFT(AI7,3)="ELC",AL7,"") | AR7: FLO_EMIS | AS7: ='City characteristics'!$C$20 -> 2019 | AT7: ='ENE TECH'!$G4 -> RESFOI | AV7: ='ENE TECH'!$G4 -> RESFOI | AX7: =LEFT(AT7,3)&AX$2 -> RESCO2e | AY7: =L7+Y7*'Emission Factors Hub'!$E$8+AL7*'Emission Factors Hub'!$E$9 -> 71.421622 | AZ7: =IFERROR(M7+Z7*'Emission Factors Hub'!$E$8+AM7*'Emission Factors Hub'!$E$9,"")
E8: FLO_EMIS | F8: ='City characteristics'!$C$20 -> 2019 | G8: ='ENE TECH'!$G5 -> RESKER | I8: ='ENE TECH'!$G5 -> RESKER | K8: =LEFT(G8,3)&K$2 -> RESCO2 | L8: =_xlfn.IFNA(_xlfn.XLOOKUP(_xlfn.XLOOKUP(_xlfn.XLOOKUP(G8,'ENE TECH'!$G:$G,'ENE TECH'!$B:$B),Mapping!$B:$B,Mapping!$C:$C),'Emission Factors Hub'!$C:$C,'Emission Factors Hub'!$E:$E)/Parameters!$C$2*10^3,0) -> 71.275848 | M8: =IF(LEFT(I8,3)="ELC",L8,"") | R8: FLO_EMIS | S8: ='City characteristics'!$C$20 -> 2019 | T8: ='ENE TECH'!$G5 -> RESKER | V8: ='ENE TECH'!$G5 -> RESKER | X8: =LEFT(T8,3)&X$2 -> RESCH4 | Y8: =_xlfn.IFNA(_xlfn.XLOOKUP(_xlfn.XLOOKUP(_xlfn.XLOOKUP(T8,'ENE TECH'!$G:$G,'ENE TECH'!$B:$B),Mapping!$B:$B,Mapping!$C:$C),'Emission Factors Hub'!$C:$C,'Emission Factors Hub'!$F:$F)/Parameters!$C$2,0) -> 0.0028434514 | Z8: =IF(LEFT(V8,3)="ELC",Y8,"") | AE8: FLO_EMIS | AF8: ='City characteristics'!$C$20 -> 2019 | AG8: ='ENE TECH'!$G5 -> RESKER | AI8: ='ENE TECH'!$G5 -> RESKER | AK8: =LEFT(AG8,3)&AK$2 -> RESN2O | AL8: =_xlfn.IFNA(_xlfn.XLOOKUP(_xlfn.XLOOKUP(_xlfn.XLOOKUP(AG8,'ENE TECH'!$G:$G,'ENE TECH'!$B:$B),Mapping!$B:$B,Mapping!$C:$C),'Emission Factors Hub'!$C:$C,'Emission Factors Hub'!$G:$G)/Parameters!$C$2,0) -> 0.00056869027 | AM8: =IF(LEFT(AI8,3)="ELC",AL8,"") | AR8: FLO_EMIS | AS8: ='City characteristics'!$C$20 -> 2019 | AT8: ='ENE TECH'!$G5 -> RESKER | AV8: ='ENE TECH'!$G5 -> RESKER | AX8: =LEFT(AT8,3)&AX$2 -> RESCO2e | AY8: =L8+Y8*'Emission Factors Hub'!$E$8+AL8*'Emission Factors Hub'!$E$9 -> 71.516404 | AZ8: =IFERROR(M8+Z8*'Emission Factors Hub'!$E$8+AM8*'Emission Factors Hub'!$E$9,"")
E9: FLO_EMIS | F9: ='City characteristics'!$C$20 -> 2019 | G9: ='ENE TECH'!$G6 -> RESNGA | I9: ='ENE TECH'!$G6 -> RESNGA | K9: =LEFT(G9,3)&K$2 -> RESCO2 | L9: =_xlfn.IFNA(_xlfn.XLOOKUP(_xlfn.XLOOKUP(_xlfn.XLOOKUP(G9,'ENE TECH'!$G:$G,'ENE TECH'!$B:$B),Mapping!$B:$B,Mapping!$C:$C),'Emission Factors Hub'!$C:$C,'Emission Factors Hub'!$E:$E)/Parameters!$C$2*10^3,0) -> 50.291177 | M9: =IF(LEFT(I9,3)="ELC",L9,"") | R9: FLO_EMIS | S9: ='City characteristics'!$C$20 -> 2019 | T9: ='ENE TECH'!$G6 -> RESNGA | V9: ='ENE TECH'!$G6 -> RESNGA | X9: =LEFT(T9,3)&X$2 -> RESCH4 | Y9: =_xlfn.IFNA(_xlfn.XLOOKUP(_xlfn.XLOOKUP(_xlfn.XLOOKUP(T9,'ENE TECH'!$G:$G,'ENE TECH'!$B:$B),Mapping!$B:$B,Mapping!$C:$C),'Emission Factors Hub'!$C:$C,'Emission Factors Hub'!$F:$F)/Parameters!$C$2,0) -> 0.00094781712 | Z9: =IF(LEFT(V9,3)="ELC",Y9,"") | AE9: FLO_EMIS | AF9: ='City characteristics'!$C$20 -> 2019 | AG9: ='ENE TECH'!$G6 -> RESNGA | AI9: ='ENE TECH'!$G6 -> RESNGA | AK9: =LEFT(AG9,3)&AK$2 -> RESN2O | AL9: =_xlfn.IFNA(_xlfn.XLOOKUP(_xlfn.XLOOKUP(_xlfn.XLOOKUP(AG9,'ENE TECH'!$G:$G,'ENE TECH'!$B:$B),Mapping!$B:$B,Mapping!$C:$C),'Emission Factors Hub'!$C:$C,'Emission Factors Hub'!$G:$G)/Parameters!$C$2,0) -> 9.4781712e-05 | AM9: =IF(LEFT(AI9,3)="ELC",AL9,"") | AR9: FLO_EMIS | AS9: ='City characteristics'!$C$20 -> 2019 | AT9: ='ENE TECH'!$G6 -> RESNGA | AV9: ='ENE TECH'!$G6 -> RESNGA | AX9: =LEFT(AT9,3)&AX$2 -> RESCO2e | AY9: =L9+Y9*'Emission Factors Hub'!$E$8+AL9*'Emission Factors Hub'!$E$9 -> 50.343117 | AZ9: =IFERROR(M9+Z9*'Emission Factors Hub'!$E$8+AM9*'Emission Factors Hub'!$E$9,"")
E10: FLO_EMIS | F10: ='City characteristics'!$C$20 -> 2019 | G10: ='ENE TECH'!$G7 -> RESRNG | I10: ='ENE TECH'!$G7 -> RESRNG | K10: =LEFT(G10,3)&K$2 -> RESCO2 | L10: =_xlfn.IFNA(_xlfn.XLOOKUP(_xlfn.XLOOKUP(_xlfn.XLOOKUP(G10,'ENE TECH'!$G:$G,'ENE TECH'!$B:$B),Mapping!$B:$B,Mapping!$C:$C),'Emission Factors Hub'!$C:$C,'Emission Factors Hub'!$E:$E)/Parameters!$C$2*10^3,0) -> 49.352838 | M10: =IF(LEFT(I10,3)="ELC",L10,"") | R10: FLO_EMIS | S10: ='City characteristics'!$C$20 -> 2019 | T10: ='ENE TECH'!$G7 -> RESRNG | V10: ='ENE TECH'!$G7 -> RESRNG | X10: =LEFT(T10,3)&X$2 -> RESCH4 | Y10: =_xlfn.IFNA(_xlfn.XLOOKUP(_xlfn.XLOOKUP(_xlfn.XLOOKUP(T10,'ENE TECH'!$G:$G,'ENE TECH'!$B:$B),Mapping!$B:$B,Mapping!$C:$C),'Emission Factors Hub'!$C:$C,'Emission Factors Hub'!$F:$F)/Parameters!$C$2,0) -> 0.0030330148 | Z10: =IF(LEFT(V10,3)="ELC",Y10,"") | AE10: FLO_EMIS | AF10: ='City characteristics'!$C$20 -> 2019 | AG10: ='ENE TECH'!$G7 -> RESRNG | AI10: ='ENE TECH'!$G7 -> RESRNG | AK10: =LEFT(AG10,3)&AK$2 -> RESN2O | AL10: =_xlfn.IFNA(_xlfn.XLOOKUP(_xlfn.XLOOKUP(_xlfn.XLOOKUP(AG10,'ENE TECH'!$G:$G,'ENE TECH'!$B:$B),Mapping!$B:$B,Mapping!$C:$C),'Emission Factors Hub'!$C:$C,'Emission Factors Hub'!$G:$G)/Parameters!$C$2,0) -> 0.00059712479 | AM10: =IF(LEFT(AI10,3)="ELC",AL10,"") | AR10: FLO_EMIS | AS10: ='City characteristics'!$C$20 -> 2019 | AT10: ='ENE TECH'!$G7 -> RESRNG | AV10: ='ENE TECH'!$G7 -> RESRNG | AX10: =LEFT(AT10,3)&AX$2 -> RESCO2e | AY10: =L10+Y10*'Emission Factors Hub'!$E$8+AL10*'Emission Factors Hub'!$E$9 -> 49.606606 | AZ10: =IFERROR(M10+Z10*'Emission Factors Hub'!$E$8+AM10*'Emission Factors Hub'!$E$9,"")
E11: FLO_EMIS | F11: ='City characteristics'!$C$20 -> 2019 | G11: ='ENE TECH'!$G8 -> RESELC | I11: ='ENE TECH'!$G8 -> RESELC | K11: =LEFT(G11,3)&K$2 -> RESCO2 | L11: =_xlfn.IFNA(_xlfn.XLOOKUP(_xlfn.XLOOKUP(_xlfn.XLOOKUP(G11,'ENE TECH'!$G:$G,'ENE TECH'!$B:$B),Mapping!$B:$B,Mapping!$C:$C),'Emission Factors Hub'!$C:$C,'Emission Factors Hub'!$E:$E)/Parameters!$C$2*10^3,0) -> 0 | M11: =IF(LEFT(I11,3)="ELC",L11,"") | R11: FLO_EMIS | S11: ='City characteristics'!$C$20 -> 2019 | T11: ='ENE TECH'!$G8 -> RESELC | V11: ='ENE TECH'!$G8 -> RESELC | X11: =LEFT(T11,3)&X$2 -> RESCH4 | Y11: =_xlfn.IFNA(_xlfn.XLOOKUP(_xlfn.XLOOKUP(_xlfn.XLOOKUP(T11,'ENE TECH'!$G:$G,'ENE TECH'!$B:$B),Mapping!$B:$B,Mapping!$C:$C),'Emission Factors Hub'!$C:$C,'Emission Factors Hub'!$F:$F)/Parameters!$C$2,0) -> 0 | Z11: =IF(LEFT(V11,3)="ELC",Y11,"") | AE11: FLO_EMIS | AF11: ='City characteristics'!$C$20 -> 2019 | AG11: ='ENE TECH'!$G8 -> RESELC | AI11: ='ENE TECH'!$G8 -> RESELC | AK11: =LEFT(AG11,3)&AK$2 -> RESN2O | AL11: =_xlfn.IFNA(_xlfn.XLOOKUP(_xlfn.XLOOKUP(_xlfn.XLOOKUP(AG11,'ENE TECH'!$G:$G,'ENE TECH'!$B:$B),Mapping!$B:$B,Mapping!$C:$C),'Emission Factors Hub'!$C:$C,'Emission Factors Hub'!$G:$G)/Parameters!$C$2,0) -> 0 | AM11: =IF(LEFT(AI11,3)="ELC",AL11,"") | AR11: FLO_EMIS | AS11: ='City characteristics'!$C$20 -> 2019 | AT11: ='ENE TECH'!$G8 -> RESELC | AV11: ='ENE TECH'!$G8 -> RESELC | AX11: =LEFT(AT11,3)&AX$2 -> RESCO2e | AY11: =L11+Y11*'Emission Factors Hub'!$E$8+AL11*'Emission Factors Hub'!$E$9 -> 0 | AZ11: =IFERROR(M11+Z11*'Emission Factors Hub'!$E$8+AM11*'Emission Factors Hub'!$E$9,"")
E12: FLO_EMIS | F12: ='City characteristics'!$C$20 -> 2019 | G12: ='ENE TECH'!$G9 -> RESH2G | I12: ='ENE TECH'!$G9 -> RESH2G | K12: =LEFT(G12,3)&K$2 -> RESCO2 | L12: =_xlfn.IFNA(_xlfn.XLOOKUP(_xlfn.XLOOKUP(_xlfn.XLOOKUP(G12,'ENE TECH'!$G:$G,'ENE TECH'!$B:$B),Mapping!$B:$B,Mapping!$C:$C),'Emission Factors Hub'!$C:$C,'Emission Factors Hub'!$E:$E)/Parameters!$C$2*10^3,0) -> 0 | M12: =IF(LEFT(I12,3)="ELC",L12,"") | R12: FLO_EMIS | S12: ='City characteristics'!$C$20 -> 2019 | T12: ='ENE TECH'!$G9 -> RESH2G | V12: ='ENE TECH'!$G9 -> RESH2G | X12: =LEFT(T12,3)&X$2 -> RESCH4 | Y12: =_xlfn.IFNA(_xlfn.XLOOKUP(_xlfn.XLOOKUP(_xlfn.XLOOKUP(T12,'ENE TECH'!$G:$G,'ENE TECH'!$B:$B),Mapping!$B:$B,Mapping!$C:$C),'Emission Factors Hub'!$C:$C,'Emission Factors Hub'!$F:$F)/Parameters!$C$2,0) -> 0 | Z12: =IF(LEFT(V12,3)="ELC",Y12,"") | AE12: FLO_EMIS | AF12: ='City characteristics'!$C$20 -> 2019 | AG12: ='ENE TECH'!$G9 -> RESH2G | AI12: ='ENE TECH'!$G9 -> RESH2G | AK12: =LEFT(AG12,3)&AK$2 -> RESN2O | AL12: =_xlfn.IFNA(_xlfn.XLOOKUP(_xlfn.XLOOKUP(_xlfn.XLOOKUP(AG12,'ENE TECH'!$G:$G,'ENE TECH'!$B:$B),Mapping!$B:$B,Mapping!$C:$C),'Emission Factors Hub'!$C:$C,'Emission Factors Hub'!$G:$G)/Parameters!$C$2,0) -> 0 | AM12: =IF(LEFT(AI12,3)="ELC",AL12,"") | AR12: FLO_EMIS | AS12: ='City characteristics'!$C$20 -> 2019 | AT12: ='ENE TECH'!$G9 -> RESH2G | AV12: ='ENE TECH'!$G9 -> RESH2G | AX12: =LEFT(AT12,3)&AX$2 -> RESCO2e | AY12: =L12+Y12*'Emission Factors Hub'!$E$8+AL12*'Emission Factors Hub'!$E$9 -> 0 | AZ12: =IFERROR(M12+Z12*'Emission Factors Hub'!$E$8+AM12*'Emission Factors Hub'!$E$9,"")
E13: FLO_EMIS | F13: ='City characteristics'!$C$20 -> 2019 | G13: ='ENE TECH'!$G10 -> RESSTM | I13: ='ENE TECH'!$G10 -> RESSTM | K13: =LEFT(G13,3)&K$2 -> RESCO2 | L13: =_xlfn.IFNA(_xlfn.XLOOKUP(_xlfn.XLOOKUP(_xlfn.XLOOKUP(G13,'ENE TECH'!$G:$G,'ENE TECH'!$B:$B),Mapping!$B:$B,Mapping!$C:$C),'Emission Factors Hub'!$C:$C,'Emission Factors Hub'!$E:$E)/Parameters!$C$2*10^3,0) -> 0 | M13: =IF(LEFT(I13,3)="ELC",L13,"") | R13: FLO_EMIS | S13: ='City characteristics'!$C$20 -> 2019 | T13: ='ENE TECH'!$G10 -> RESSTM | V13: ='ENE TECH'!$G10 -> RESSTM | X13: =LEFT(T13,3)&X$2 -> RESCH4 | Y13: =_xlfn.IFNA(_xlfn.XLOOKUP(_xlfn.XLOOKUP(_xlfn.XLOOKUP(T13,'ENE TECH'!$G:$G,'ENE TECH'!$B:$B),Mapping!$B:$B,Mapping!$C:$C),'Emission Factors Hub'!$C:$C,'Emission Factors Hub'!$F:$F)/Parameters!$C$2,0) -> 0 | Z13: =IF(LEFT(V13,3)="ELC",Y13,"") | AE13: FLO_EMIS | AF13: ='City characteristics'!$C$20 -> 2019 | AG13: ='ENE TECH'!$G10 -> RESSTM | AI13: ='ENE TECH'!$G10 -> RESSTM | AK13: =LEFT(AG13,3)&AK$2 -> RESN2O | AL13: =_xlfn.IFNA(_xlfn.XLOOKUP(_xlfn.XLOOKUP(_xlfn.XLOOKUP(AG13,'ENE TECH'!$G:$G,'ENE TECH'!$B:$B),Mapping!$B:$B,Mapping!$C:$C),'Emission Factors Hub'!$C:$C,'Emission Factors Hub'!$G:$G)/Parameters!$C$2,0) -> 0 | AM13: =IF(LEFT(AI13,3)="ELC",AL13,"") | AR13: FLO_EMIS | AS13: ='City characteristics'!$C$20 -> 2019 | AT13: ='ENE TECH'!$G10 -> RESSTM | AV13: ='ENE TECH'!$G10 -> RESSTM | AX13: =LEFT(AT13,3)&AX$2 -> RESCO2e | AY13: =L13+Y13*'Emission Factors Hub'!$E$8+AL13*'Emission Factors Hub'!$E$9 -> 0 | AZ13: =IFERROR(M13+Z13*'Emission Factors Hub'!$E$8+AM13*'Emission Factors Hub'!$E$9,"")
E14: FLO_EMIS | F14: ='City characteristics'!$C$20 -> 2019 | G14: ='ENE TECH'!$G11 -> RESSOL | I14: ='ENE TECH'!$G11 -> RESSOL | K14: =LEFT(G14,3)&K$2 -> RESCO2 | L14: =_xlfn.IFNA(_xlfn.XLOOKUP(_xlfn.XLOOKUP(_xlfn.XLOOKUP(G14,'ENE TECH'!$G:$G,'ENE TECH'!$B:$B),Mapping!$B:$B,Mapping!$C:$C),'Emission Factors Hub'!$C:$C,'Emission Factors Hub'!$E:$E)/Parameters!$C$2*10^3,0) -> 0 | M14: =IF(LEFT(I14,3)="ELC",L14,"") | R14: FLO_EMIS | S14: ='City characteristics'!$C$20 -> 2019 | T14: ='ENE TECH'!$G11 -> RESSOL | V14: ='ENE TECH'!$G11 -> RESSOL | X14: =LEFT(T14,3)&X$2 -> RESCH4 | Y14: =_xlfn.IFNA(_xlfn.XLOOKUP(_xlfn.XLOOKUP(_xlfn.XLOOKUP(T14,'ENE TECH'!$G:$G,'ENE TECH'!$B:$B),Mapping!$B:$B,Mapping!$C:$C),'Emission Factors Hub'!$C:$C,'Emission Factors Hub'!$F:$F)/Parameters!$C$2,0) -> 0 | Z14: =IF(LEFT(V14,3)="ELC",Y14,"") | AE14: FLO_EMIS | AF14: ='City characteristics'!$C$20 -> 2019 | AG14: ='ENE TECH'!$G11 -> RESSOL | AI14: ='ENE TECH'!$G11 -> RESSOL | AK14: =LEFT(AG14,3)&AK$2 -> RESN2O | AL14: =_xlfn.IFNA(_xlfn.XLOOKUP(_xlfn.XLOOKUP(_xlfn.XLOOKUP(AG14,'ENE TECH'!$G:$G,'ENE TECH'!$B:$B),Mapping!$B:$B,Mapping!$C:$C),'Emission Factors Hub'!$C:$C,'Emission Factors Hub'!$G:$G)/Parameters!$C$2,0) -> 0 | AM14: =IF(LEFT(AI14,3)="ELC",AL14,"") | AR14: FLO_EMIS | AS14: ='City characteristics'!$C$20 -> 2019 | AT14: ='ENE TECH'!$G11 -> RESSOL | AV14: ='ENE TECH'!$G11 -> RESSOL | AX14: =LEFT(AT14,3)&AX$2 -> RESCO2e | AY14: =L14+Y14*'Emission Factors Hub'!$E$8+AL14*'Emission Factors Hub'!$E$9 -> 0 | AZ14: =IFERROR(M14+Z14*'Emission Factors Hub'!$E$8+AM14*'Emission Factors Hub'!$E$9,"")
E15: FLO_EMIS | F15: ='City characteristics'!$C$20 -> 2019 | G15: ='ENE TECH'!$G12 -> RESWND | I15: ='ENE TECH'!$G12 -> RESWND | K15: =LEFT(G15,3)&K$2 -> RESCO2 | L15: =_xlfn.IFNA(_xlfn.XLOOKUP(_xlfn.XLOOKUP(_xlfn.XLOOKUP(G15,'ENE TECH'!$G:$G,'ENE TECH'!$B:$B),Mapping!$B:$B,Mapping!$C:$C),'Emission Factors Hub'!$C:$C,'Emission Factors Hub'!$E:$E)/Parameters!$C$2*10^3,0) -> 0 | M15: =IF(LEFT(I15,3)="ELC",L15,"") | R15: FLO_EMIS | S15: ='City characteristics'!$C$20 -> 2019 | T15: ='ENE TECH'!$G12 -> RESWND | V15: ='ENE TECH'!$G12 -> RESWND | X15: =LEFT(T15,3)&X$2 -> RESCH4 | Y15: =_xlfn.IFNA(_xlfn.XLOOKUP(_xlfn.XLOOKUP(_xlfn.XLOOKUP(T15,'ENE TECH'!$G:$G,'ENE TECH'!$B:$B),Mapping!$B:$B,Mapping!$C:$C),'Emission Factors Hub'!$C:$C,'Emission Factors Hub'!$F:$F)/Parameters!$C$2,0) -> 0 | Z15: =IF(LEFT(V15,3)="ELC",Y15,"") | AE15: FLO_EMIS | AF15: ='City characteristics'!$C$20 -> 2019 | AG15: ='ENE TECH'!$G12 -> RESWND | AI15: ='ENE TECH'!$G12 -> RESWND | AK15: =LEFT(AG15,3)&AK$2 -> RESN2O | AL15: =_xlfn.IFNA(_xlfn.XLOOKUP(_xlfn.XLOOKUP(_xlfn.XLOOKUP(AG15,'ENE TECH'!$G:$G,'ENE TECH'!$B:$B),Mapping!$B:$B,Mapping!$C:$C),'Emission Factors Hub'!$C:$C,'Emission Factors Hub'!$G:$G)/Parameters!$C$2,0) -> 0 | AM15: =IF(LEFT(AI15,3)="ELC",AL15,"") | AR15: FLO_EMIS | AS15: ='City characteristics'!$C$20 -> 2019 | AT15: ='ENE TECH'!$G12 -> RESWND | AV15: ='ENE TECH'!$G12 -> RESWND | AX15: =LEFT(AT15,3)&AX$2 -> RESCO2e | AY15: =L15+Y15*'Emission Factors Hub'!$E$8+AL15*'Emission Factors Hub'!$E$9 -> 0 | AZ15: =IFERROR(M15+Z15*'Emission Factors Hub'!$E$8+AM15*'Emission Factors Hub'!$E$9,"")
E16: FLO_EMIS | F16: ='City characteristics'!$C$20 -> 2019 | G16: ='ENE TECH'!$G13 -> COMLPG | I16: ='ENE TECH'!$G13 -> COMLPG | K16: =LEFT(G16,3)&K$2 -> COMCO2 | L16: =_xlfn.IFNA(_xlfn.XLOOKUP(_xlfn.XLOOKUP(_xlfn.XLOOKUP(G16,'ENE TECH'!$G:$G,'ENE TECH'!$B:$B),Mapping!$B:$B,Mapping!$C:$C),'Emission Factors Hub'!$C:$C,'Emission Factors Hub'!$E:$E)/Parameters!$C$2*10^3,0) -> 58.489795 | M16: =IF(LEFT(I16,3)="ELC",L16,"") | R16: FLO_EMIS | S16: ='City characteristics'!$C$20 -> 2019 | T16: ='ENE TECH'!$G13 -> COMLPG | V16: ='ENE TECH'!$G13 -> COMLPG | X16: =LEFT(T16,3)&X$2 -> COMCH4 | Y16: =_xlfn.IFNA(_xlfn.XLOOKUP(_xlfn.XLOOKUP(_xlfn.XLOOKUP(T16,'ENE TECH'!$G:$G,'ENE TECH'!$B:$B),Mapping!$B:$B,Mapping!$C:$C),'Emission Factors Hub'!$C:$C,'Emission Factors Hub'!$F:$F)/Parameters!$C$2,0) -> 0.0028434514 | Z16: =IF(LEFT(V16,3)="ELC",Y16,"") | AE16: FLO_EMIS | AF16: ='City characteristics'!$C$20 -> 2019 | AG16: ='ENE TECH'!$G13 -> COMLPG | AI16: ='ENE TECH'!$G13 -> COMLPG | AK16: =LEFT(AG16,3)&AK$2 -> COMN2O | AL16: =_xlfn.IFNA(_xlfn.XLOOKUP(_xlfn.XLOOKUP(_xlfn.XLOOKUP(AG16,'ENE TECH'!$G:$G,'ENE TECH'!$B:$B),Mapping!$B:$B,Mapping!$C:$C),'Emission Factors Hub'!$C:$C,'Emission Factors Hub'!$G:$G)/Parameters!$C$2,0) -> 0.00056869027 | AM16: =IF(LEFT(AI16,3)="ELC",AL16,"") | AR16: FLO_EMIS | AS16: ='City characteristics'!$C$20 -> 2019 | AT16: ='ENE TECH'!$G13 -> COMLPG | AV16: ='ENE TECH'!$G13 -> COMLPG | AX16: =LEFT(AT16,3)&AX$2 -> COMCO2e | AY16: =L16+Y16*'Emission Factors Hub'!$E$8+AL16*'Emission Factors Hub'!$E$9 -> 58.730351 | AZ16: =IFERROR(M16+Z16*'Emission Factors Hub'!$E$8+AM16*'Emission Factors Hub'!$E$9,"")
E17: FLO_EMIS | F17: ='City characteristics'!$C$20 -> 2019 | G17: ='ENE TECH'!$G14 -> COMDSL | I17: ='ENE TECH'!$G14 -> COMDSL | K17: =LEFT(G17,3)&K$2 -> COMCO2 | L17: =_xlfn.IFNA(_xlfn.XLOOKUP(_xlfn.XLOOKUP(_xlfn.XLOOKUP(G17,'ENE TECH'!$G:$G,'ENE TECH'!$B:$B),Mapping!$B:$B,Mapping!$C:$C),'Emission Factors Hub'!$C:$C,'Emission Factors Hub'!$E:$E)/Parameters!$C$2*10^3,0) -> 70.100554 | M17: =IF(LEFT(I17,3)="ELC",L17,"") | R17: FLO_EMIS | S17: ='City characteristics'!$C$20 -> 2019 | T17: ='ENE TECH'!$G14 -> COMDSL | V17: ='ENE TECH'!$G14 -> COMDSL | X17: =LEFT(T17,3)&X$2 -> COMCH4 | Y17: =_xlfn.IFNA(_xlfn.XLOOKUP(_xlfn.XLOOKUP(_xlfn.XLOOKUP(T17,'ENE TECH'!$G:$G,'ENE TECH'!$B:$B),Mapping!$B:$B,Mapping!$C:$C),'Emission Factors Hub'!$C:$C,'Emission Factors Hub'!$F:$F)/Parameters!$C$2,0) -> 0.0028434514 | Z17: =IF(LEFT(V17,3)="ELC",Y17,"") | AE17: FLO_EMIS | AF17: ='City characteristics'!$C$20 -> 2019 | AG17: ='ENE TECH'!$G14 -> COMDSL | AI17: ='ENE TECH'!$G14 -> COMDSL | AK17: =LEFT(AG17,3)&AK$2 -> COMN2O | AL17: =_xlfn.IFNA(_xlfn.XLOOKUP(_xlfn.XLOOKUP(_xlfn.XLOOKUP(AG17,'ENE TECH'!$G:$G,'ENE TECH'!$B:$B),Mapping!$B:$B,Mapping!$C:$C),'Emission Factors Hub'!$C:$C,'Emission Factors Hub'!$G:$G)/Parameters!$C$2,0) -> 0.00056869027 | AM17: =IF(LEFT(AI17,3)="ELC",AL17,"") | AR17: FLO_EMIS | AS17: ='City characteristics'!$C$20 -> 2019 | AT17: ='ENE TECH'!$G14 -> COMDSL | AV17: ='ENE TECH'!$G14 -> COMDSL | AX17: =LEFT(AT17,3)&AX$2 -> COMCO2e | AY17: =L17+Y17*'Emission Factors Hub'!$E$8+AL17*'Emission Factors Hub'!$E$9 -> 70.34111 | AZ17: =IFERROR(M17+Z17*'Emission Factors Hub'!$E$8+AM17*'Emission Factors Hub'!$E$9,"")
... E57: FLO_EMIS | F57: ='City characteristics'!$C$20 -> 2019 | G57: ='ENE TECH'!$G54 -> ELCFOI | I57: ='ENE TECH'!$G54 -> ELCFOI | K57: =LEFT(G57,3)&K$2 -> ELCCO2 | L57: =_xlfn.IFNA(_xlfn.XLOOKUP(_xlfn.XLOOKUP(_xlfn.XLOOKUP(G57,'ENE TECH'!$G:$G,'ENE TECH'!$B:$B),Mapping!$B:$B,Mapping!$C:$C),'Emission Factors Hub'!$C:$C,'Emission Factors Hub'!$E:$E)/Parameters!$C$2*10^3,0) -> 71.181066 | M57: =IF(LEFT(I57,3)="ELC",L57,"") -> 71.181066 | R57: FLO_EMIS | S57: ='City characteristics'!$C$20 -> 2019 | T57: ='ENE TECH'!$G54 -> ELCFOI | V57: ='ENE TECH'!$G54 -> ELCFOI | X57: =LEFT(T57,3)&X$2 -> ELCCH4 | Y57: =_xlfn.IFNA(_xlfn.XLOOKUP(_xlfn.XLOOKUP(_xlfn.XLOOKUP(T57,'ENE TECH'!$G:$G,'ENE TECH'!$B:$B),Mapping!$B:$B,Mapping!$C:$C),'Emission Factors Hub'!$C:$C,'Emission Factors Hub'!$F:$F)/Parameters!$C$2,0) -> 0.0028434514 | Z57: =IF(LEFT(V57,3)="ELC",Y57,"") -> 0.0028434514 | AE57: FLO_EMIS | AF57: ='City characteristics'!$C$20 -> 2019 | AG57: ='ENE TECH'!$G54 -> ELCFOI | AI57: ='ENE TECH'!$G54 -> ELCFOI | AK57: =LEFT(AG57,3)&AK$2 -> ELCN2O | AL57: =_xlfn.IFNA(_xlfn.XLOOKUP(_xlfn.XLOOKUP(_xlfn.XLOOKUP(AG57,'ENE TECH'!$G:$G,'ENE TECH'!$B:$B),Mapping!$B:$B,Mapping!$C:$C),'Emission Factors Hub'!$C:$C,'Emission Factors Hub'!$G:$G)/Parameters!$C$2,0) -> 0.00056869027 | AM57: =IF(LEFT(AI57,3)="ELC",AL57,"") -> 0.00056869027 | AR57: FLO_EMIS | AS57: ='City characteristics'!$C$20 -> 2019 | AT57: ='ENE TECH'!$G54 -> ELCFOI | AV57: ='ENE TECH'!$G54 -> ELCFOI | AX57: =LEFT(AT57,3)&AX$2 -> ELCCO2e | AY57: =L57+Y57*'Emission Factors Hub'!$E$8+AL57*'Emission Factors Hub'!$E$9 -> 71.421622 | AZ57: =IFERROR(M57+Z57*'Emission Factors Hub'!$E$8+AM57*'Emission Factors Hub'!$E$9,"") -> 71.421622
E58: FLO_EMIS | F58: ='City characteristics'!$C$20 -> 2019 | G58: ='ENE TECH'!$G55 -> ELCNGA | H58: E*,-E*CCS* | I58: ='ENE TECH'!$G55 -> ELCNGA | K58: =LEFT(G58,3)&K$2 -> ELCCO2 | L58: =_xlfn.IFNA(_xlfn.XLOOKUP(_xlfn.XLOOKUP(_xlfn.XLOOKUP(G58,'ENE TECH'!$G:$G,'ENE TECH'!$B:$B),Mapping!$B:$B,Mapping!$C:$C),'Emission Factors Hub'!$C:$C,'Emission Factors Hub'!$E:$E)/Parameters!$C$2*10^3,0) -> 50.291177 | M58: =IF(LEFT(I58,3)="ELC",L58,"") -> 50.291177 | R58: FLO_EMIS | S58: ='City characteristics'!$C$20 -> 2019 | T58: ='ENE TECH'!$G55 -> ELCNGA | U58: E*,-E*CCS* | V58: ='ENE TECH'!$G55 -> ELCNGA | X58: =LEFT(T58,3)&X$2 -> ELCCH4 | Y58: =_xlfn.IFNA(_xlfn.XLOOKUP(_xlfn.XLOOKUP(_xlfn.XLOOKUP(T58,'ENE TECH'!$G:$G,'ENE TECH'!$B:$B),Mapping!$B:$B,Mapping!$C:$C),'Emission Factors Hub'!$C:$C,'Emission Factors Hub'!$F:$F)/Parameters!$C$2,0) -> 0.00094781712 | Z58: =IF(LEFT(V58,3)="ELC",Y58,"") -> 0.00094781712 | AE58: FLO_EMIS | AF58: ='City characteristics'!$C$20 -> 2019 | AG58: ='ENE TECH'!$G55 -> ELCNGA | AH58: E*,-E*CCS* | AI58: ='ENE TECH'!$G55 -> ELCNGA | AK58: =LEFT(AG58,3)&AK$2 -> ELCN2O | AL58: =_xlfn.IFNA(_xlfn.XLOOKUP(_xlfn.XLOOKUP(_xlfn.XLOOKUP(AG58,'ENE TECH'!$G:$G,'ENE TECH'!$B:$B),Mapping!$B:$B,Mapping!$C:$C),'Emission Factors Hub'!$C:$C,'Emission Factors Hub'!$G:$G)/Parameters!$C$2,0) -> 9.4781712e-05 | AM58: =IF(LEFT(AI58,3)="ELC",AL58,"") -> 9.4781712e-05 | AR58: FLO_EMIS | AS58: ='City characteristics'!$C$20 -> 2019 | AT58: ='ENE TECH'!$G55 -> ELCNGA | AU58: E*,-E*CCS* | AV58: ='ENE TECH'!$G55 -> ELCNGA | AX58: =LEFT(AT58,3)&AX$2 -> ELCCO2e | AY58: =L58+Y58*'Emission Factors Hub'!$E$8+AL58*'Emission Factors Hub'!$E$9 -> 50.343117 | AZ58: =IFERROR(M58+Z58*'Emission Factors Hub'!$E$8+AM58*'Emission Factors Hub'!$E$9,"") -> 50.343117
