Workbook

Sheet ReadMe
A1: Generic Comet (GC) TIMES Supply
B3: Sheet color
C4: Raw Data and Parameters
C6: City Specific Data
C8: Post processing for TIMES
C10: Table formatted for TIMES

Sheet >> City Data

Sheet City characteristics
B2: City Basic Data
B4: Calibration methodology | C4: GHG Inventory
B6: A. City Characteristics
B7: Data Item | C7: Value | D7: Units
B8: City Name | C8: New York
B9: Latitude | C9: 40.5
B10: Longitude | C10: -75
B11: County | C11: New York County
B12: State | C12: New York
B13: Census Division | C13: Middle Atlantic
B14: Climate Division | C14: Northeast
B15: Egrid Region | C15: NPCC NYC/Westchester
B16: Area of city (excluding water, natural and agricultural areas) | C16: 778 | D16: square kilometers
B17: * Division and Region Map can be found in the Maps sheet.
B18: B. Planning Base Year and Target Years
B19: Year | C19: Value | D19: Units
B20: Base Year | C20: 2019 | D20: Acceptable range [2018,2021]
B21: End Year | C21: 2050
B23: C. City Population and GDP
B24: Data Item | C24: Value | D24: Units
B25: Population in Base Year | C25: 8337 | D25: Thousand of people
B26: Annual population growth (Base Year - End Year) | C26: 0.5 | D26: % people
B27: GDP in Base Year | C27: 1206000 | D27: Million US$
B28: Annual GDP growth rate | C28: 2 | D28: % US$
B29: Share of manufacturing GDP | C29: 5 | D29: % US$
B30: Share of State population | C30: 0.42835123
B31: Share of State GDP | C31: 0.67251772
B32: Adjustment from state manufacturing GDP | C32: 1.0638298
B34: D. Climate Data
B35: Data Item | C35: 2000 | D35: 2050 | E35: 2100 | F35: Units
B36: Heating degree days (HDD) | C36: 4473.4625 | D36: 4066.4182 | E36: 3763.8582 | F36: F
B37: Cooling degree days (CDD) | C37: 1020.7333 | D37: 1224.2555 | E37: 1375.5355 | F37: F
B39: Data Item | C39: Value | D39: Units
B40: Correction from State HDD | C40: 0.72727402
B41: Correction from State CDD | C41: 1.5583715
B42: Annual precipitation | C42: 762 | D42: mm / year
B43: Climate change scenario | C43: RCP4.5
B44: Average temperature increase in 1980-2020 | C44: 1.4617857 | D44: F
B45: Forecasted average temperature increase in 2035-2065 | C45: 3.13 | D45: F
B46: Forecasted average temperature increase in 2070-2100 | C46: 4.37 | D46: F
...

Sheet >> GC_Existing

Sheet >> TIMES

Sheet UC_SUB
B3: ~TFM_INS
B4: TimeSlice | C4: LimType | D4: Attribute | E4: Year | F4: CITY | G4: Pset_PN | H4: Pset_PD | I4: Pset_CI
D5: NCAP_ISPCT | E5: ='Data '!$B$4 -> 2019 | F5: ='Data '!$B$5 -> 0 | G5: RES*SH*HP*ELC*,-*GHP* | H5: *Space heating*
D6: NCAP_ISPCT | E6: ='Data '!$C$4 -> 2024 | F6: ='Data '!$C$5 -> 0 | G6: =G5 -> RES*SH*HP*ELC*,-*GHP* | H6: =H5 -> *Space heating*
D7: NCAP_ISPCT | E7: ='Data '!$D$4 -> 2025 | F7: ='Data '!$D$5 -> 0.5 | G7: =G6 -> RES*SH*HP*ELC*,-*GHP* | H7: =H6 -> *Space heating*
D8: NCAP_ISPCT | E8: ='Data '!$E$4 -> 2034 | F8: ='Data '!$E$5 -> 0.5 | G8: =G7 -> RES*SH*HP*ELC*,-*GHP* | H8: =H7 -> *Space heating*
D9: NCAP_ISPCT | E9: ='Data '!$F$4 -> 2035 | F9: ='Data '!$F$5 -> 0 | G9: =G8 -> RES*SH*HP*ELC*,-*GHP* | H9: =H8 -> *Space heating*
D10: NCAP_ISPCT | E10: 2050 | F10: =F9 -> 0 | G10: =G9 -> RES*SH*HP*ELC*,-*GHP* | H10: =H9 -> *Space heating*
D12: NCAP_ISUB | E12: ='Data '!$B$4 -> 2019 | F12: ='Data '!G5 -> 0 | G12: RES*SH*HP*ELC*,-*GHP* | H12: *Space heating*
D13: =D12 -> NCAP_ISUB | E13: ='Data '!$C$4 -> 2024 | F13: ='Data '!H5 -> 0 | G13: =G12 -> RES*SH*HP*ELC*,-*GHP* | H13: =H12 -> *Space heating*
D14: =D13 -> NCAP_ISUB | E14: ='Data '!$D$4 -> 2025 | F14: ='Data '!I5 -> 210 | G14: =G13 -> RES*SH*HP*ELC*,-*GHP* | H14: =H13 -> *Space heating*
D15: =D14 -> NCAP_ISUB | E15: ='Data '!$E$4 -> 2034 | F15: ='Data '!J5 -> 210 | G15: =G14 -> RES*SH*HP*ELC*,-*GHP* | H15: =H14 -> *Space heating*
D16: =D15 -> NCAP_ISUB | E16: ='Data '!$F$4 -> 2035 | F16: ='Data '!K5 -> 0 | G16: =G15 -> RES*SH*HP*ELC*,-*GHP* | H16: =H15 -> *Space heating*
D17: =D16 -> NCAP_ISUB | E17: 2050 | F17: =F16 -> 0 | G17: =G16 -> RES*SH*HP*ELC*,-*GHP* | H17: =H16 -> *Space heating*

Sheet MaxSub
B3: ~UC_Sets: R_S: AllRegions
B4: ~UC_Sets: T_S:
I6: ~UC_T: UC_RHS
B7: UC_N | C7: PSet: PN | D7: PSet: PD | E7: PSet: CI | F7: PSet_CO | G7: UC_ATTR~LHS | H7: UC_ATTR~RHS | I7: LimType | J7: UC_NCAP | K7: UC_NCAP~RHS | L7: UC_RHS | M7: UC_Desc
B8: UC_SubResHPCum | C8: =UC_SUB!G5 -> RES*SH*HP*ELC*,-*GHP* | D8: =UC_SUB!H5 -> *Space heating* | G8: NCAP,SUB | I8: LO | J8: 1 | L8: =-'Data '!L5 -> -500000 | M8: Max lump-sum investment subsidies for BEV Cars (cumul)
B11: ~UC_Sets: R_S: AllRegions
B12: ~UC_Sets: T_E:
I13: ~UC_T: UC_RHST
B14: UC_N | C14: PSet: PN | D14: PSet: PD | E14: PSet: CI | F14: PSet_CO | G14: UC_ATTR~LHS | H14: UC_ATTR~RHS | I14: LimType | J14: UC_NCAP | K14: UC_NCAP~RHS | L14: UC_RHST~2019 | M14: UC_RHST~2024 | N14: UC_RHST~2025 | O14: UC_RHST~2027 | P14: UC_RHST~2030 | Q14: UC_RHST~2032 | R14: UC_RHST~2035 | S14: UC_RHST~2036 | T14: UC_RHST~2100 | U14: UC_RHST~0 | V14: UC_Desc
B15: UC_SubResGHPAnn | C15: =C8 -> RES*SH*HP*ELC*,-*GHP* | D15: =D8 -> *Space heating* | G15: NCAP,SUB | I15: LO | J15: 1 | L15: 0 | M15: 0 | N15: =-'Data '!M6 -> -38461.538 | O15: =-'Data '!N6 -> -23076.923 | P15: =-'Data '!O6 -> -23076.923 | Q15: =-'Data '!P6 -> -7692.3077 | R15: =-'Data '!Q6 -> -38461.538 | S15: =-$R$9*50% -> 0 | T15: =-$R$9*50% -> 0 | U15: 1 | V15: Max lump-sum investment subsidies for Passenger LDV BEV (annual)

Sheet >> Parameters

Sheet Data 
B2: Subsidies | L2: Policy budget - Cumulative | M2: Policy budget - Annual
B3: % of investment cost | G3: 2023 US $ / unit | L3: M 2023 US $ | M3: M 2023 US $ | N3: M 2023 US $ | O3: M 2023 US $ | P3: M 2023 US $ | Q3: M 2023 US $
B4: 2019 | C4: 2024 | D4: 2025 | E4: 2034 | F4: 2035 | G4: 2019 | H4: 2024 | I4: 2025 | J4: 2034 | K4: 2035 | M4: 2025 | N4: 2027 | O4: 2030 | P4: 2032 | Q4: 2035
A5: Residential - Space heating - Air source heat pumps | B5: 0 | C5: 0 | D5: 0.5 | E5: =D5 -> 0.5 | F5: 0 | G5: 0 | H5: 0 | I5: =420*0.5 -> 210 | J5: =I5 -> 210 | K5: 0 | L5: 500000 | M5: =L5*1/13 -> 38461.538 | N5: =100000*3/13 -> 23076.923 | O5: =100000*3/13 -> 23076.923 | P5: =100000*1/13 -> 7692.3077 | Q5: =100000*5/13 -> 38461.538
A6: Commercial - Space heating - Air source heat pumps | B6: 0 | C6: 0 | D6: 0.5 | E6: =D6 -> 0.5 | F6: 0 | G6: 0 | H6: 0 | I6: 500 | J6: =I6 -> 500 | K6: 0 | L6: =L5 -> 500000 | M6: =M5 -> 38461.538 | N6: =N5 -> 23076.923 | O6: =O5 -> 23076.923 | P6: =P5 -> 7692.3077 | Q6: =Q5 -> 38461.538
