Workbook

Sheet ReadMe
A1: Generic Comet (GC) TIMES Supply
B3: Sheet color
C4: Raw Data and Parameters
C6: City Specific Data
C8: Post processing for TIMES
C10: Table formatted for TIMES

Sheet >> City Data

Sheet City characteristics
B2: City Basic Data
B4: Calibration methodology | C4: GHG Inventory
B6: A. City Characteristics
B7: Data Item | C7: Value | D7: Units
B8: City Name | C8: New York
B9: Latitude | C9: 40.5
B10: Longitude | C10: -75
B11: County | C11: New York County
B12: State | C12: New York
B13: Census Division | C13: Middle Atlantic
B14: Climate Division | C14: Northeast
B15: Egrid Region | C15: NPCC NYC/Westchester
B16: Area of city (excluding water, natural and agricultural areas) | C16: 778 | D16: square kilometers
B17: * Division and Region Map can be found in the Maps sheet.
B18: B. Planning Base Year and Target Years
B19: Year | C19: Value | D19: Units
B20: Base Year | C20: 2019 | D20: Acceptable range [2018,2021]
B21: End Year | C21: 2050
B23: C. City Population and GDP
B24: Data Item | C24: Value | D24: Units
B25: Population in Base Year | C25: 8337 | D25: Thousand of people
B26: Annual population growth (Base Year - End Year) | C26: 0.5 | D26: % people
B27: GDP in Base Year | C27: 1206000 | D27: Million US$
B28: Annual GDP growth rate | C28: 2 | D28: % US$
B29: Share of manufacturing GDP | C29: 5 | D29: % US$
B30: Share of State population | C30: 0.42835123
B31: Share of State GDP | C31: 0.67251772
B32: Adjustment from state manufacturing GDP | C32: 1.0638298
B34: D. Climate Data
B35: Data Item | C35: 2000 | D35: 2050 | E35: 2100 | F35: Units
B36: Heating degree days (HDD) | C36: 4473.4625 | D36: 4066.4182 | E36: 3763.8582 | F36: F
B37: Cooling degree days (CDD) | C37: 1020.7333 | D37: 1224.2555 | E37: 1375.5355 | F37: F
B39: Data Item | C39: Value | D39: Units
B40: Correction from State HDD | C40: 0.72727402
B41: Correction from State CDD | C41: 1.5583715
B42: Annual precipitation | C42: 762 | D42: mm / year
B43: Climate change scenario | C43: RCP4.5
B44: Average temperature increase in 1980-2020 | C44: 1.4617857 | D44: F
B45: Forecasted average temperature increase in 2035-2065 | C45: 3.13 | D45: F
B46: Forecasted average temperature increase in 2070-2100 | C46: 4.37 | D46: F
...

Sheet >> GC_Existing

Sheet Demand
A1: Sector | B1: Sub-sector | C1: Archetype | D1: Vintage | E1: Demand Label | F1: Unit | G1: 2019 | H1: 2020 | I1: 2025 | J1: 2030 | K1: 2035 | L1: 2040 | M1: 2045 | N1: 2050 | O1: 2055 | P1: 2060 | Q1: 2065 | R1: 2070 | S1: 2075 | T1: 2080 | U1: 2085 | V1: 2090 | W1: 2095 | X1: 2100
A2: Commercial | B2: Hotel | D2: Old | E2: COMHOTOldDMD | F2: Mm2 | G2: 11.978701 | H2: 11.978701 | I2: 11.978701 | J2: 11.978701 | K2: 11.978701 | L2: 11.978701 | M2: 11.978701 | N2: 11.978701 | O2: 11.978701 | P2: 11.978701 | Q2: 11.978701 | R2: 11.978701 | S2: 11.978701 | T2: 11.978701 | U2: 11.978701 | V2: 11.978701 | W2: 11.978701 | X2: 11.978701
A3: Commercial | B3: Retail | D3: Old | E3: COMRETOldDMD | F3: Mm2 | G3: 23.081056 | H3: 23.081056 | I3: 23.081056 | J3: 23.081056 | K3: 23.081056 | L3: 23.081056 | M3: 23.081056 | N3: 23.081056 | O3: 23.081056 | P3: 23.081056 | Q3: 23.081056 | R3: 23.081056 | S3: 23.081056 | T3: 23.081056 | U3: 23.081056 | V3: 23.081056 | W3: 23.081056 | X3: 23.081056
A4: Commercial | B4: Office | D4: Old | E4: COMOFFOldDMD | F4: Mm2 | G4: 73.164819 | H4: 73.164819 | I4: 73.164819 | J4: 73.164819 | K4: 73.164819 | L4: 73.164819 | M4: 73.164819 | N4: 73.164819 | O4: 73.164819 | P4: 73.164819 | Q4: 73.164819 | R4: 73.164819 | S4: 73.164819 | T4: 73.164819 | U4: 73.164819 | V4: 73.164819 | W4: 73.164819 | X4: 73.164819
A5: Commercial | B5: Hospital | D5: Old | E5: COMHOPOldDMD | F5: Mm2 | G5: 44.382259 | H5: 44.382259 | I5: 44.382259 | J5: 44.382259 | K5: 44.382259 | L5: 44.382259 | M5: 44.382259 | N5: 44.382259 | O5: 44.382259 | P5: 44.382259 | Q5: 44.382259 | R5: 44.382259 | S5: 44.382259 | T5: 44.382259 | U5: 44.382259 | V5: 44.382259 | W5: 44.382259 | X5: 44.382259
A6: Commercial | B6: Educationnal | D6: Old | E6: COMEDUOldDMD | F6: Mm2 | G6: 48.565496 | H6: 48.565496 | I6: 48.565496 | J6: 48.565496 | K6: 48.565496 | L6: 48.565496 | M6: 48.565496 | N6: 48.565496 | O6: 48.565496 | P6: 48.565496 | Q6: 48.565496 | R6: 48.565496 | S6: 48.565496 | T6: 48.565496 | U6: 48.565496 | V6: 48.565496 | W6: 48.565496 | X6: 48.565496
A7: Commercial | B7: Warehouse | D7: Old | E7: COMWAROldDMD | F7: Mm2 | G7: 32.733587 | H7: 32.733587 | I7: 32.733587 | J7: 32.733587 | K7: 32.733587 | L7: 32.733587 | M7: 32.733587 | N7: 32.733587 | O7: 32.733587 | P7: 32.733587 | Q7: 32.733587 | R7: 32.733587 | S7: 32.733587 | T7: 32.733587 | U7: 32.733587 | V7: 32.733587 | W7: 32.733587 | X7: 32.733587
A8: Commercial | B8: Municipal | D8: Old | E8: COMMUNOldDMD | F8: Mm2 | G8: 16.841333 | H8: 16.841333 | I8: 16.841333 | J8: 16.841333 | K8: 16.841333 | L8: 16.841333 | M8: 16.841333 | N8: 16.841333 | O8: 16.841333 | P8: 16.841333 | Q8: 16.841333 | R8: 16.841333 | S8: 16.841333 | T8: 16.841333 | U8: 16.841333 | V8: 16.841333 | W8: 16.841333 | X8: 16.841333
A9: Commercial | B9: Other | D9: Old | E9: COMOTHOldDMD | F9: Mm2 | G9: 8.7602804 | H9: 8.7602804 | I9: 8.7602804 | J9: 8.7602804 | K9: 8.7602804 | L9: 8.7602804 | M9: 8.7602804 | N9: 8.7602804 | O9: 8.7602804 | P9: 8.7602804 | Q9: 8.7602804 | R9: 8.7602804 | S9: 8.7602804 | T9: 8.7602804 | U9: 8.7602804 | V9: 8.7602804 | W9: 8.7602804 | X9: 8.7602804
A10: Commercial | B10: Hotel | D10: New | E10: COMHOTNewDMD | F10: Mm2 | G10: 0 | H10: 0.23957402 | I10: 1.4374441 | J10: 2.6353143 | K10: 3.8331844 | L10: 5.0310545 | M10: 6.2289246 | N10: 7.4267947 | O10: 8.6246649 | P10: 9.822535 | Q10: 11.020405 | R10: 12.218275 | S10: 13.416145 | T10: 14.614015 | U10: 15.811886 | V10: 17.009756 | W10: 18.207626 | X10: 19.405496
A11: Commercial | B11: Retail | D11: New | E11: COMRETNewDMD | F11: Mm2 | G11: 0 | H11: 0.46162113 | I11: 2.7697268 | J11: 5.0778324 | K11: 7.3859381 | L11: 9.6940437 | M11: 12.002149 | N11: 14.310255 | O11: 16.618361 | P11: 18.926466 | Q11: 21.234572 | R11: 23.542678 | S11: 25.850783 | T11: 28.158889 | U11: 30.466995 | V11: 32.7751 | W11: 35.083206 | X11: 37.391311
A12: Commercial | B12: Office | D12: New | E12: COMOFFNewDMD | F12: Mm2 | G12: 0 | H12: 1.4632964 | I12: 8.7797783 | J12: 16.09626 | K12: 23.412742 | L12: 30.729224 | M12: 38.045706 | N12: 45.362188 | O12: 52.67867 | P12: 59.995152 | Q12: 67.311633 | R12: 74.628115 | S12: 81.944597 | T12: 89.261079 | U12: 96.577561 | V12: 103.89404 | W12: 111.21052 | X12: 118.52701
A13: Commercial | B13: Hospital | D13: New | E13: COMHOPNewDMD | F13: Mm2 | G13: 0 | H13: 0.88764519 | I13: 5.3258711 | J13: 9.764097 | K13: 14.202323 | L13: 18.640549 | M13: 23.078775 | N13: 27.517001 | O13: 31.955227 | P13: 36.393453 | Q13: 40.831679 | R13: 45.269904 | S13: 49.70813 | T13: 54.146356 | U13: 58.584582 | V13: 63.022808 | W13: 67.461034 | X13: 71.89926
... A17: Commercial | B17: Other | D17: New | E17: COMOTHNewDMD | F17: Mm2 | G17: 0 | H17: 0.17520561 | I17: 1.0512337 | J17: 1.9272617 | K17: 2.8032897 | L17: 3.6793178 | M17: 4.5553458 | N17: 5.4313739 | O17: 6.3074019 | P17: 7.18343 | Q17: 8.059458 | R17: 8.9354861 | S17: 9.8115141 | T17: 10.687542 | U17: 11.56357 | V17: 12.439598 | W17: 13.315626 | X17: 14.191654
A18: Residential | B18: Apartment | C18: Low Income | D18: Old | E18: RESAPALOOldDMD | F18: Mm2 | G18: 51.807877 | H18: 51.807877 | I18: 51.807877 | J18: 51.807877 | K18: 51.807877 | L18: 51.807877 | M18: 51.807877 | N18: 51.807877 | O18: 51.807877 | P18: 51.807877 | Q18: 51.807877 | R18: 51.807877 | S18: 51.807877 | T18: 51.807877 | U18: 51.807877 | V18: 51.807877 | W18: 51.807877 | X18: 51.807877
A19: Residential | B19: House | C19: Low Income | D19: Old | E19: RESHOULOOldDMD | F19: Mm2 | G19: 14.956798 | H19: 14.956798 | I19: 14.956798 | J19: 14.956798 | K19: 14.956798 | L19: 14.956798 | M19: 14.956798 | N19: 14.956798 | O19: 14.956798 | P19: 14.956798 | Q19: 14.956798 | R19: 14.956798 | S19: 14.956798 | T19: 14.956798 | U19: 14.956798 | V19: 14.956798 | W19: 14.956798 | X19: 14.956798
A20: Residential | B20: Apartment | C20: Lower-Middle Income | D20: Old | E20: RESAPALMOldDMD | F20: Mm2 | G20: 57.121976 | H20: 57.121976 | I20: 57.121976 | J20: 57.121976 | K20: 57.121976 | L20: 57.121976 | M20: 57.121976 | N20: 57.121976 | O20: 57.121976 | P20: 57.121976 | Q20: 57.121976 | R20: 57.121976 | S20: 57.121976 | T20: 57.121976 | U20: 57.121976 | V20: 57.121976 | W20: 57.121976 | X20: 57.121976
A21: Residential | B21: House | C21: Lower-Middle Income | D21: Old | E21: RESHOULMOldDMD | F21: Mm2 | G21: 38.299259 | H21: 38.299259 | I21: 38.299259 | J21: 38.299259 | K21: 38.299259 | L21: 38.299259 | M21: 38.299259 | N21: 38.299259 | O21: 38.299259 | P21: 38.299259 | Q21: 38.299259 | R21: 38.299259 | S21: 38.299259 | T21: 38.299259 | U21: 38.299259 | V21: 38.299259 | W21: 38.299259 | X21: 38.299259
A22: Residential | B22: Apartment | C22: Upper-Middle Income | D22: Old | E22: RESAPAUMOldDMD | F22: Mm2 | G22: 15.495888 | H22: 15.495888 | I22: 15.495888 | J22: 15.495888 | K22: 15.495888 | L22: 15.495888 | M22: 15.495888 | N22: 15.495888 | O22: 15.495888 | P22: 15.495888 | Q22: 15.495888 | R22: 15.495888 | S22: 15.495888 | T22: 15.495888 | U22: 15.495888 | V22: 15.495888 | W22: 15.495888 | X22: 15.495888
A23: Residential | B23: House | C23: Upper-Middle Income | D23: Old | E23: RESHOUUMOldDMD | F23: Mm2 | G23: 19.187214 | H23: 19.187214 | I23: 19.187214 | J23: 19.187214 | K23: 19.187214 | L23: 19.187214 | M23: 19.187214 | N23: 19.187214 | O23: 19.187214 | P23: 19.187214 | Q23: 19.187214 | R23: 19.187214 | S23: 19.187214 | T23: 19.187214 | U23: 19.187214 | V23: 19.187214 | W23: 19.187214 | X23: 19.187214
A24: Residential | B24: Apartment | C24: High Income | D24: Old | E24: RESAPAHIOldDMD | F24: Mm2 | G24: 66.398717 | H24: 66.398717 | I24: 66.398717 | J24: 66.398717 | K24: 66.398717 | L24: 66.398717 | M24: 66.398717 | N24: 66.398717 | O24: 66.398717 | P24: 66.398717 | Q24: 66.398717 | R24: 66.398717 | S24: 66.398717 | T24: 66.398717 | U24: 66.398717 | V24: 66.398717 | W24: 66.398717 | X24: 66.398717
A25: Residential | B25: House | C25: High Income | D25: Old | E25: RESHOUHIOldDMD | F25: Mm2 | G25: 96.552051 | H25: 96.552051 | I25: 96.552051 | J25: 96.552051 | K25: 96.552051 | L25: 96.552051 | M25: 96.552051 | N25: 96.552051 | O25: 96.552051 | P25: 96.552051 | Q25: 96.552051 | R25: 96.552051 | S25: 96.552051 | T25: 96.552051 | U25: 96.552051 | V25: 96.552051 | W25: 96.552051 | X25: 96.552051
A26: Residential | B26: Apartment | C26: Low Income | D26: New | E26: RESAPALONewDMD | F26: Mm2 | G26: 0 | H26: 0.25903939 | I26: 1.5542363 | J26: 2.8494333 | K26: 4.1446302 | L26: 5.4398271 | M26: 6.7350241 | N26: 8.030221 | O26: 9.3254179 | P26: 10.620615 | Q26: 11.915812 | R26: 13.211009 | S26: 14.506206 | T26: 15.801403 | U26: 17.0966 | V26: 18.391797 | W26: 19.686993 | X26: 20.98219
A27: Residential | B27: House | C27: Low Income | D27: New | E27: RESHOULONewDMD | F27: Mm2 | G27: 0 | H27: 0.07478399 | I27: 0.44870394 | J27: 0.82262389 | K27: 1.1965438 | L27: 1.5704638 | M27: 1.9443837 | N27: 2.3183037 | O27: 2.6922236 | P27: 3.0661436 | Q27: 3.4400635 | R27: 3.8139835 | S27: 4.1879034 | T27: 4.5618234 | U27: 4.9357433 | V27: 5.3096633 | W27: 5.6835832 | X27: 6.0575032
A28: Residential | B28: Apartment | C28: Lower-Middle Income | D28: New | E28: RESAPALMNewDMD | F28: Mm2 | G28: 0 | H28: 0.28560988 | I28: 1.7136593 | J28: 3.1417087 | K28: 4.5697581 | L28: 5.9978075 | M28: 7.4258569 | N28: 8.8539063 | O28: 10.281956 | P28: 11.710005 | Q28: 13.138055 | R28: 14.566104 | S28: 15.994153 | T28: 17.422203 | U28: 18.850252 | V28: 20.278302 | W28: 21.706351 | X28: 23.1344
A29: Residential | B29: House | C29: Lower-Middle Income | D29: New | E29: RESHOULMNewDMD | F29: Mm2 | G29: 0 | H29: 0.19149629 | I29: 1.1489778 | J29: 2.1064592 | K29: 3.0639407 | L29: 4.0214222 | M29: 4.9789036 | N29: 5.9363851 | O29: 6.8938665 | P29: 7.851348 | Q29: 8.8088295 | R29: 9.7663109 | S29: 10.723792 | T29: 11.681274 | U29: 12.638755 | V29: 13.596237 | W29: 14.553718 | X29: 15.5112
... A33: Residential | B33: House | C33: High Income | D33: New | E33: RESHOUHINewDMD | F33: Mm2 | G33: 0 | H33: 0.48276025 | I33: 2.8965615 | J33: 5.3103628 | K33: 7.7241641 | L33: 10.137965 | M33: 12.551767 | N33: 14.965568 | O33: 17.379369 | P33: 19.79317 | Q33: 22.206972 | R33: 24.620773 | S33: 27.034574 | T33: 29.448376 | U33: 31.862177 | V33: 34.275978 | W33: 36.689779 | X33: 39.103581
A34: Industrial | B34: All Industries | E34: INDAINDMD | F34: TJ | G34: 66716.461 | H34: 68050.79 | I34: 74855.869 | J34: 82341.456 | K34: 90575.602 | L34: 99633.162 | M34: 109596.48 | N34: 120556.13 | O34: 132611.74 | P34: 145872.91 | Q34: 160460.2 | R34: 176506.22 | S34: 194156.85 | T34: 213572.53 | U34: 234929.78 | V34: 258422.76 | W34: 284265.04 | X34: 312691.54
A35: Transportation | B35: Passenger | C35: Passenger Car | E35: TRAPASCARDMD | F35: M Vkm | G35: 68921.251 | H35: 69265.857 | I35: 70997.504 | J35: 72772.441 | K35: 74591.752 | L35: 76456.546 | M35: 78367.96 | N35: 80327.159 | O35: 82335.338 | P35: 84393.721 | Q35: 86503.564 | R35: 88666.153 | S35: 90882.807 | T35: 93154.877 | U35: 95483.749 | V35: 97870.843 | W35: 100317.61 | X35: 102825.55
A36: Transportation | B36: Passenger | C36: Passenger Truck | E36: TRAPASLDTDMD | F36: M Vkm | G36: 0 | H36: 0 | I36: 0 | J36: 0 | K36: 0 | L36: 0 | M36: 0 | N36: 0 | O36: 0 | P36: 0 | Q36: 0 | R36: 0 | S36: 0 | T36: 0 | U36: 0 | V36: 0 | W36: 0 | X36: 0
A37: Transportation | B37: Passenger | C37: Motorcycle | E37: TRAPASMOTDMD | F37: M Vkm | G37: 0 | H37: 0 | I37: 0 | J37: 0 | K37: 0 | L37: 0 | M37: 0 | N37: 0 | O37: 0 | P37: 0 | Q37: 0 | R37: 0 | S37: 0 | T37: 0 | U37: 0 | V37: 0 | W37: 0 | X37: 0
A38: Transportation | B38: Freight | C38: Light Commercial Truck | E38: TRAFRECLTDMD | F38: M Vkm | G38: 1578.5179 | H38: 1586.4105 | I38: 1626.0707 | J38: 1666.7225 | K38: 1708.3906 | L38: 1751.1003 | M38: 1794.8778 | N38: 1839.7498 | O38: 1885.7435 | P38: 1932.8871 | Q38: 1981.2093 | R38: 2030.7395 | S38: 2081.508 | T38: 2133.5457 | U38: 2186.8844 | V38: 2241.5565 | W38: 2297.5954 | X38: 2355.0353
A39: Transportation | B39: Freight | C39: Refuse Truck | E39: TRAFRERFTDMD | F39: M Vkm | G39: 70.026308 | H39: 70.37644 | I39: 72.135851 | J39: 73.939247 | K39: 75.787728 | L39: 77.682421 | M39: 79.624482 | N39: 81.615094 | O39: 83.655471 | P39: 85.746858 | Q39: 87.89053 | R39: 90.087793 | S39: 92.339988 | T39: 94.648487 | U39: 97.0147 | V39: 99.440067 | W39: 101.92607 | X39: 104.47422
A40: Transportation | B40: Freight | C40: Single Unit Long-haul Truck | E40: TRAFRESLHDMD | F40: M Vkm | G40: 0 | H40: 0 | I40: 0 | J40: 0 | K40: 0 | L40: 0 | M40: 0 | N40: 0 | O40: 0 | P40: 0 | Q40: 0 | R40: 0 | S40: 0 | T40: 0 | U40: 0 | V40: 0 | W40: 0 | X40: 0
A41: Transportation | B41: Freight | C41: Single Unit Short-haul Truck | E41: TRAFRESSHDMD | F41: M Vkm | G41: 0 | H41: 0 | I41: 0 | J41: 0 | K41: 0 | L41: 0 | M41: 0 | N41: 0 | O41: 0 | P41: 0 | Q41: 0 | R41: 0 | S41: 0 | T41: 0 | U41: 0 | V41: 0 | W41: 0 | X41: 0
A42: Transportation | B42: Freight | C42: Combination Long-haul Truck | E42: TRAFRECLHDMD | F42: M Vkm | G42: 1367.6202 | H42: 1374.4583 | I42: 1408.8197 | J42: 1444.0402 | K42: 1480.1412 | L42: 1517.1447 | M42: 1555.0734 | N42: 1593.9502 | O42: 1633.7989 | P42: 1674.6439 | Q42: 1716.51 | R42: 1759.4228 | S42: 1803.4083 | T42: 1848.4935 | U42: 1894.7059 | V42: 1942.0735 | W42: 1990.6254 | X42: 2040.391
A43: Transportation | B43: Freight | C43: Combination Short-haul Truck | E43: TRAFRECSHDMD | F43: M Vkm | G43: 0 | H43: 0 | I43: 0 | J43: 0 | K43: 0 | L43: 0 | M43: 0 | N43: 0 | O43: 0 | P43: 0 | Q43: 0 | R43: 0 | S43: 0 | T43: 0 | U43: 0 | V43: 0 | W43: 0 | X43: 0
A44: Transportation | B44: Passenger | C44: Transit Bus | E44: TRAPASTBUDMD | F44: M Vkm | G44: 498.20419 | H44: 500.69521 | I44: 513.21259 | J44: 526.0429 | K44: 539.19397 | L44: 552.67382 | M44: 566.49067 | N44: 580.65294 | O44: 595.16926 | P44: 610.04849 | Q44: 625.2997 | R44: 640.93219 | S44: 656.9555 | T44: 673.37939 | U44: 690.21387 | V44: 707.46922 | W44: 725.15595 | X44: 743.28485
A45: Transportation | B45: Passenger | C45: School Bus | E45: TRAPASSBUDMD | F45: M Vkm | G45: 86.053217 | H45: 86.483483 | I45: 88.645571 | J45: 90.86171 | K45: 93.133253 | L45: 95.461584 | M45: 97.848123 | N45: 100.29433 | O45: 102.80168 | P45: 105.37173 | Q45: 108.00602 | R45: 110.70617 | S45: 113.47382 | T45: 116.31067 | U45: 119.21844 | V45: 122.1989 | W45: 125.25387 | X45: 128.38522
A46: Transportation | B46: Passenger | C46: Other Buses | E46: TRAPASOBUDMD | F46: M Vkm | G46: 0 | H46: 0 | I46: 0 | J46: 0 | K46: 0 | L46: 0 | M46: 0 | N46: 0 | O46: 0 | P46: 0 | Q46: 0 | R46: 0 | S46: 0 | T46: 0 | U46: 0 | V46: 0 | W46: 0 | X46: 0
...

Sheet Trans_Demand
A1: Demand Label | B1: Unit | C1: Attribute | D1: Value
A2: COMHOTOldDMD | B2: Mm2 | C2: 2019 | D2: {=_xlfn._xlws.FILTER(_xlfn._xlws.FILTER(Demand!$G$2:$X$66,(Demand!$E$2:$E$66=$A2),""),Demand!$G$1:$X$1=$C2,"")} -> 11.978701
A3: COMHOTOldDMD | B3: Mm2 | C3: 2020 | D3: {=_xlfn._xlws.FILTER(_xlfn._xlws.FILTER(Demand!$G$2:$X$66,(Demand!$E$2:$E$66=$A3),""),Demand!$G$1:$X$1=$C3,"")} -> 11.978701
A4: COMHOTOldDMD | B4: Mm2 | C4: 2025 | D4: {=_xlfn._xlws.FILTER(_xlfn._xlws.FILTER(Demand!$G$2:$X$66,(Demand!$E$2:$E$66=$A4),""),Demand!$G$1:$X$1=$C4,"")} -> 11.978701
A5: COMHOTOldDMD | B5: Mm2 | C5: 2030 | D5: {=_xlfn._xlws.FILTER(_xlfn._xlws.FILTER(Demand!$G$2:$X$66,(Demand!$E$2:$E$66=$A5),""),Demand!$G$1:$X$1=$C5,"")} -> 11.978701
A6: COMHOTOldDMD | B6: Mm2 | C6: 2035 | D6: {=_xlfn._xlws.FILTER(_xlfn._xlws.FILTER(Demand!$G$2:$X$66,(Demand!$E$2:$E$66=$A6),""),Demand!$G$1:$X$1=$C6,"")} -> 11.978701
A7: COMHOTOldDMD | B7: Mm2 | C7: 2040 | D7: {=_xlfn._xlws.FILTER(_xlfn._xlws.FILTER(Demand!$G$2:$X$66,(Demand!$E$2:$E$66=$A7),""),Demand!$G$1:$X$1=$C7,"")} -> 11.978701
A8: COMHOTOldDMD | B8: Mm2 | C8: 2045 | D8: {=_xlfn._xlws.FILTER(_xlfn._xlws.FILTER(Demand!$G$2:$X$66,(Demand!$E$2:$E$66=$A8),""),Demand!$G$1:$X$1=$C8,"")} -> 11.978701
A9: COMHOTOldDMD | B9: Mm2 | C9: 2050 | D9: {=_xlfn._xlws.FILTER(_xlfn._xlws.FILTER(Demand!$G$2:$X$66,(Demand!$E$2:$E$66=$A9),""),Demand!$G$1:$X$1=$C9,"")} -> 11.978701
A10: COMHOTOldDMD | B10: Mm2 | C10: 2055 | D10: {=_xlfn._xlws.FILTER(_xlfn._xlws.FILTER(Demand!$G$2:$X$66,(Demand!$E$2:$E$66=$A10),""),Demand!$G$1:$X$1=$C10,"")} -> 11.978701
A11: COMHOTOldDMD | B11: Mm2 | C11: 2060 | D11: {=_xlfn._xlws.FILTER(_xlfn._xlws.FILTER(Demand!$G$2:$X$66,(Demand!$E$2:$E$66=$A11),""),Demand!$G$1:$X$1=$C11,"")} -> 11.978701
A12: COMHOTOldDMD | B12: Mm2 | C12: 2065 | D12: {=_xlfn._xlws.FILTER(_xlfn._xlws.FILTER(Demand!$G$2:$X$66,(Demand!$E$2:$E$66=$A12),""),Demand!$G$1:$X$1=$C12,"")} -> 11.978701
A13: COMHOTOldDMD | B13: Mm2 | C13: 2070 | D13: {=_xlfn._xlws.FILTER(_xlfn._xlws.FILTER(Demand!$G$2:$X$66,(Demand!$E$2:$E$66=$A13),""),Demand!$G$1:$X$1=$C13,"")} -> 11.978701
... A1171: WASWATTRTDMD | B1171: Mm3 | C1171: 2100 | D1171: {=_xlfn._xlws.FILTER(_xlfn._xlws.FILTER(Demand!$G$2:$X$66,(Demand!$E$2:$E$66=$A1171),""),Demand!$G$1:$X$1=$C1171,"")} -> 2564.3647

Sheet >> TIMES

Sheet DMD_ELC
B4: ~TFM_INS | J4: ~TFM_INS
B5: CommName | C5: *Description | D5: *Unit | E5: Attribute | F5: Year | G5: EGRID | J5: CommName | K5: *Description | L5: Attribute | M5: TimeSlice | N5: Year | O5: EGRID
B6: * | C6: * | D6: * | E6: * | F6: * | G6: * | J6: * | K6: * | L6: * | M6: * | N6: * | O6: *
B7: =Demand!$E$65 -> ELCMISEGRIDDMD | C7: ="DEMAND - "&Demand!$A$65&" "&Demand!$B$65&" "&Demand!$C$65&" "&Demand!$D$65 -> DEMAND - Electricity Miscellanous EGRID electricity demand | D7: =_xlfn.XLOOKUP(B7,Trans_Demand!A:A,Trans_Demand!B:B) -> TJ | E7: COM_PROJ | F7: {=_xlfn._xlws.FILTER(_xlfn.UNIQUE(Trans_Demand!C2:C10000),_xlfn.UNIQUE(Trans_Demand!C2:C10000)<>0,"")} -> 2019 | G7: =SUMIFS(Trans_Demand!D:D,Trans_Demand!A:A,DMD_ELC!B7,Trans_Demand!C:C,DMD_ELC!F7,Trans_Demand!D:D,">0") -> 0 | J7: =Demand!$E$65 -> ELCMISEGRIDDMD | K7: ="DEMAND - "&Demand!$A$65&" "&Demand!$B$65&" "&Demand!$C$65&" "&Demand!$D$65 -> DEMAND - Electricity Miscellanous EGRID electricity demand | L7: COM_FR | M7: IDAM | N7: =Demand!$G$1 -> 2019 | O7: 0.0822
B8: =Demand!$E$65 -> ELCMISEGRIDDMD | C8: ="DEMAND - "&Demand!$A$65&" "&Demand!$B$65&" "&Demand!$C$65&" "&Demand!$D$65 -> DEMAND - Electricity Miscellanous EGRID electricity demand | D8: =_xlfn.XLOOKUP(B8,Trans_Demand!A:A,Trans_Demand!B:B) -> TJ | E8: COM_PROJ | F8: 2020 | G8: =SUMIFS(Trans_Demand!D:D,Trans_Demand!A:A,DMD_ELC!B8,Trans_Demand!C:C,DMD_ELC!F8,Trans_Demand!D:D,">0") -> 0 | J8: =Demand!$E$65 -> ELCMISEGRIDDMD | K8: ="DEMAND - "&Demand!$A$65&" "&Demand!$B$65&" "&Demand!$C$65&" "&Demand!$D$65 -> DEMAND - Electricity Miscellanous EGRID electricity demand | L8: COM_FR | M8: IDPM | N8: =Demand!$G$1 -> 2019 | O8: 0.0957
B9: =Demand!$E$65 -> ELCMISEGRIDDMD | C9: ="DEMAND - "&Demand!$A$65&" "&Demand!$B$65&" "&Demand!$C$65&" "&Demand!$D$65 -> DEMAND - Electricity Miscellanous EGRID electricity demand | D9: =_xlfn.XLOOKUP(B9,Trans_Demand!A:A,Trans_Demand!B:B) -> TJ | E9: COM_PROJ | F9: 2025 | G9: =SUMIFS(Trans_Demand!D:D,Trans_Demand!A:A,DMD_ELC!B9,Trans_Demand!C:C,DMD_ELC!F9,Trans_Demand!D:D,">0") -> 0 | J9: =Demand!$E$65 -> ELCMISEGRIDDMD | K9: ="DEMAND - "&Demand!$A$65&" "&Demand!$B$65&" "&Demand!$C$65&" "&Demand!$D$65 -> DEMAND - Electricity Miscellanous EGRID electricity demand | L9: COM_FR | M9: IN | N9: =Demand!$G$1 -> 2019 | O9: 0.1532
B10: =Demand!$E$65 -> ELCMISEGRIDDMD | C10: ="DEMAND - "&Demand!$A$65&" "&Demand!$B$65&" "&Demand!$C$65&" "&Demand!$D$65 -> DEMAND - Electricity Miscellanous EGRID electricity demand | D10: =_xlfn.XLOOKUP(B10,Trans_Demand!A:A,Trans_Demand!B:B) -> TJ | E10: COM_PROJ | F10: 2030 | G10: =SUMIFS(Trans_Demand!D:D,Trans_Demand!A:A,DMD_ELC!B10,Trans_Demand!C:C,DMD_ELC!F10,Trans_Demand!D:D,">0") -> 0 | J10: =Demand!$E$65 -> ELCMISEGRIDDMD | K10: ="DEMAND - "&Demand!$A$65&" "&Demand!$B$65&" "&Demand!$C$65&" "&Demand!$D$65 -> DEMAND - Electricity Miscellanous EGRID electricity demand | L10: COM_FR | M10: IP | N10: =Demand!$G$1 -> 2019 | O10: 0.0032
B11: =Demand!$E$65 -> ELCMISEGRIDDMD | C11: ="DEMAND - "&Demand!$A$65&" "&Demand!$B$65&" "&Demand!$C$65&" "&Demand!$D$65 -> DEMAND - Electricity Miscellanous EGRID electricity demand | D11: =_xlfn.XLOOKUP(B11,Trans_Demand!A:A,Trans_Demand!B:B) -> TJ | E11: COM_PROJ | F11: 2035 | G11: =SUMIFS(Trans_Demand!D:D,Trans_Demand!A:A,DMD_ELC!B11,Trans_Demand!C:C,DMD_ELC!F11,Trans_Demand!D:D,">0") -> 0 | J11: =Demand!$E$65 -> ELCMISEGRIDDMD | K11: ="DEMAND - "&Demand!$A$65&" "&Demand!$B$65&" "&Demand!$C$65&" "&Demand!$D$65 -> DEMAND - Electricity Miscellanous EGRID electricity demand | L11: COM_FR | M11: WDAM | N11: =Demand!$G$1 -> 2019 | O11: 0.0815
B12: =Demand!$E$65 -> ELCMISEGRIDDMD | C12: ="DEMAND - "&Demand!$A$65&" "&Demand!$B$65&" "&Demand!$C$65&" "&Demand!$D$65 -> DEMAND - Electricity Miscellanous EGRID electricity demand | D12: =_xlfn.XLOOKUP(B12,Trans_Demand!A:A,Trans_Demand!B:B) -> TJ | E12: COM_PROJ | F12: 2040 | G12: =SUMIFS(Trans_Demand!D:D,Trans_Demand!A:A,DMD_ELC!B12,Trans_Demand!C:C,DMD_ELC!F12,Trans_Demand!D:D,">0") -> 0 | J12: =Demand!$E$65 -> ELCMISEGRIDDMD | K12: ="DEMAND - "&Demand!$A$65&" "&Demand!$B$65&" "&Demand!$C$65&" "&Demand!$D$65 -> DEMAND - Electricity Miscellanous EGRID electricity demand | L12: COM_FR | M12: WDPM | N12: =Demand!$G$1 -> 2019 | O12: 0.1087
B13: =Demand!$E$65 -> ELCMISEGRIDDMD | C13: ="DEMAND - "&Demand!$A$65&" "&Demand!$B$65&" "&Demand!$C$65&" "&Demand!$D$65 -> DEMAND - Electricity Miscellanous EGRID electricity demand | D13: =_xlfn.XLOOKUP(B13,Trans_Demand!A:A,Trans_Demand!B:B) -> TJ | E13: COM_PROJ | F13: 2045 | G13: =SUMIFS(Trans_Demand!D:D,Trans_Demand!A:A,DMD_ELC!B13,Trans_Demand!C:C,DMD_ELC!F13,Trans_Demand!D:D,">0") -> 0 | J13: =Demand!$E$65 -> ELCMISEGRIDDMD | K13: ="DEMAND - "&Demand!$A$65&" "&Demand!$B$65&" "&Demand!$C$65&" "&Demand!$D$65 -> DEMAND - Electricity Miscellanous EGRID electricity demand | L13: COM_FR | M13: WN | N13: =Demand!$G$1 -> 2019 | O13: 0.1381
B14: =Demand!$E$65 -> ELCMISEGRIDDMD | C14: ="DEMAND - "&Demand!$A$65&" "&Demand!$B$65&" "&Demand!$C$65&" "&Demand!$D$65 -> DEMAND - Electricity Miscellanous EGRID electricity demand | D14: =_xlfn.XLOOKUP(B14,Trans_Demand!A:A,Trans_Demand!B:B) -> TJ | E14: COM_PROJ | F14: 2050 | G14: =SUMIFS(Trans_Demand!D:D,Trans_Demand!A:A,DMD_ELC!B14,Trans_Demand!C:C,DMD_ELC!F14,Trans_Demand!D:D,">0") -> 0 | J14: =Demand!$E$65 -> ELCMISEGRIDDMD | K14: ="DEMAND - "&Demand!$A$65&" "&Demand!$B$65&" "&Demand!$C$65&" "&Demand!$D$65 -> DEMAND - Electricity Miscellanous EGRID electricity demand | L14: COM_FR | M14: WP | N14: =Demand!$G$1 -> 2019 | O14: 0.0032
B15: =Demand!$E$65 -> ELCMISEGRIDDMD | C15: ="DEMAND - "&Demand!$A$65&" "&Demand!$B$65&" "&Demand!$C$65&" "&Demand!$D$65 -> DEMAND - Electricity Miscellanous EGRID electricity demand | D15: =_xlfn.XLOOKUP(B15,Trans_Demand!A:A,Trans_Demand!B:B) -> TJ | E15: COM_PROJ | F15: 2055 | G15: =SUMIFS(Trans_Demand!D:D,Trans_Demand!A:A,DMD_ELC!B15,Trans_Demand!C:C,DMD_ELC!F15,Trans_Demand!D:D,">0") -> 0 | J15: =Demand!$E$65 -> ELCMISEGRIDDMD | K15: ="DEMAND - "&Demand!$A$65&" "&Demand!$B$65&" "&Demand!$C$65&" "&Demand!$D$65 -> DEMAND - Electricity Miscellanous EGRID electricity demand | L15: COM_FR | M15: SDAM | N15: =Demand!$G$1 -> 2019 | O15: 0.0975
B16: =Demand!$E$65 -> ELCMISEGRIDDMD | C16: ="DEMAND - "&Demand!$A$65&" "&Demand!$B$65&" "&Demand!$C$65&" "&Demand!$D$65 -> DEMAND - Electricity Miscellanous EGRID electricity demand | D16: =_xlfn.XLOOKUP(B16,Trans_Demand!A:A,Trans_Demand!B:B) -> TJ | E16: COM_PROJ | F16: 2060 | G16: =SUMIFS(Trans_Demand!D:D,Trans_Demand!A:A,DMD_ELC!B16,Trans_Demand!C:C,DMD_ELC!F16,Trans_Demand!D:D,">0") -> 0 | J16: =Demand!$E$65 -> ELCMISEGRIDDMD | K16: ="DEMAND - "&Demand!$A$65&" "&Demand!$B$65&" "&Demand!$C$65&" "&Demand!$D$65 -> DEMAND - Electricity Miscellanous EGRID electricity demand | L16: COM_FR | M16: SDPM | N16: =Demand!$G$1 -> 2019 | O16: 0.1087
B17: =Demand!$E$65 -> ELCMISEGRIDDMD | C17: ="DEMAND - "&Demand!$A$65&" "&Demand!$B$65&" "&Demand!$C$65&" "&Demand!$D$65 -> DEMAND - Electricity Miscellanous EGRID electricity demand | D17: =_xlfn.XLOOKUP(B17,Trans_Demand!A:A,Trans_Demand!B:B) -> TJ | E17: COM_PROJ | F17: 2065 | G17: =SUMIFS(Trans_Demand!D:D,Trans_Demand!A:A,DMD_ELC!B17,Trans_Demand!C:C,DMD_ELC!F17,Trans_Demand!D:D,">0") -> 0 | J17: =Demand!$E$65 -> ELCMISEGRIDDMD | K17: ="DEMAND - "&Demand!$A$65&" "&Demand!$B$65&" "&Demand!$C$65&" "&Demand!$D$65 -> DEMAND - Electricity Miscellanous EGRID electricity demand | L17: COM_FR | M17: SN | N17: =Demand!$G$1 -> 2019 | O17: 0.1253
B18: =Demand!$E$65 -> ELCMISEGRIDDMD | C18: ="DEMAND - "&Demand!$A$65&" "&Demand!$B$65&" "&Demand!$C$65&" "&Demand!$D$65 -> DEMAND - Electricity Miscellanous EGRID electricity demand | D18: =_xlfn.XLOOKUP(B18,Trans_Demand!A:A,Trans_Demand!B:B) -> TJ | E18: COM_PROJ | F18: 2070 | G18: =SUMIFS(Trans_Demand!D:D,Trans_Demand!A:A,DMD_ELC!B18,Trans_Demand!C:C,DMD_ELC!F18,Trans_Demand!D:D,">0") -> 0 | J18: =Demand!$E$65 -> ELCMISEGRIDDMD | K18: ="DEMAND - "&Demand!$A$65&" "&Demand!$B$65&" "&Demand!$C$65&" "&Demand!$D$65 -> DEMAND - Electricity Miscellanous EGRID electricity demand | L18: COM_FR | M18: SP | N18: =Demand!$G$1 -> 2019 | O18: 0.0027
B19: =Demand!$E$65 -> ELCMISEGRIDDMD | C19: ="DEMAND - "&Demand!$A$65&" "&Demand!$B$65&" "&Demand!$C$65&" "&Demand!$D$65 -> DEMAND - Electricity Miscellanous EGRID electricity demand | D19: =_xlfn.XLOOKUP(B19,Trans_Demand!A:A,Trans_Demand!B:B) -> TJ | E19: COM_PROJ | F19: 2075 | G19: =SUMIFS(Trans_Demand!D:D,Trans_Demand!A:A,DMD_ELC!B19,Trans_Demand!C:C,DMD_ELC!F19,Trans_Demand!D:D,">0") -> 0 | J19: =Demand!$E$65 -> ELCMISEGRIDDMD | K19: ="DEMAND - "&Demand!$A$65&" "&Demand!$B$65&" "&Demand!$C$65&" "&Demand!$D$65 -> DEMAND - Electricity Miscellanous EGRID electricity demand | L19: COM_FR | M19: IDAM | N19: 2100 | O19: 0.0822
B20: =Demand!$E$65 -> ELCMISEGRIDDMD | C20: ="DEMAND - "&Demand!$A$65&" "&Demand!$B$65&" "&Demand!$C$65&" "&Demand!$D$65 -> DEMAND - Electricity Miscellanous EGRID electricity demand | D20: =_xlfn.XLOOKUP(B20,Trans_Demand!A:A,Trans_Demand!B:B) -> TJ | E20: COM_PROJ | F20: 2080 | G20: =SUMIFS(Trans_Demand!D:D,Trans_Demand!A:A,DMD_ELC!B20,Trans_Demand!C:C,DMD_ELC!F20,Trans_Demand!D:D,">0") -> 0 | J20: =Demand!$E$65 -> ELCMISEGRIDDMD | K20: ="DEMAND - "&Demand!$A$65&" "&Demand!$B$65&" "&Demand!$C$65&" "&Demand!$D$65 -> DEMAND - Electricity Miscellanous EGRID electricity demand | L20: COM_FR | M20: IDPM | N20: 2100 | O20: 0.0957
B21: =Demand!$E$65 -> ELCMISEGRIDDMD | C21: ="DEMAND - "&Demand!$A$65&" "&Demand!$B$65&" "&Demand!$C$65&" "&Demand!$D$65 -> DEMAND - Electricity Miscellanous EGRID electricity demand | D21: =_xlfn.XLOOKUP(B21,Trans_Demand!A:A,Trans_Demand!B:B) -> TJ | E21: COM_PROJ | F21: 2085 | G21: =SUMIFS(Trans_Demand!D:D,Trans_Demand!A:A,DMD_ELC!B21,Trans_Demand!C:C,DMD_ELC!F21,Trans_Demand!D:D,">0") -> 0 | J21: =Demand!$E$65 -> ELCMISEGRIDDMD | K21: ="DEMAND - "&Demand!$A$65&" "&Demand!$B$65&" "&Demand!$C$65&" "&Demand!$D$65 -> DEMAND - Electricity Miscellanous EGRID electricity demand | L21: COM_FR | M21: IN | N21: 2100 | O21: 0.1532
B22: =Demand!$E$65 -> ELCMISEGRIDDMD | C22: ="DEMAND - "&Demand!$A$65&" "&Demand!$B$65&" "&Demand!$C$65&" "&Demand!$D$65 -> DEMAND - Electricity Miscellanous EGRID electricity demand | D22: =_xlfn.XLOOKUP(B22,Trans_Demand!A:A,Trans_Demand!B:B) -> TJ | E22: COM_PROJ | F22: 2090 | G22: =SUMIFS(Trans_Demand!D:D,Trans_Demand!A:A,DMD_ELC!B22,Trans_Demand!C:C,DMD_ELC!F22,Trans_Demand!D:D,">0") -> 0 | J22: =Demand!$E$65 -> ELCMISEGRIDDMD | K22: ="DEMAND - "&Demand!$A$65&" "&Demand!$B$65&" "&Demand!$C$65&" "&Demand!$D$65 -> DEMAND - Electricity Miscellanous EGRID electricity demand | L22: COM_FR | M22: IP | N22: 2100 | O22: 0.0032
B23: =Demand!$E$65 -> ELCMISEGRIDDMD | C23: ="DEMAND - "&Demand!$A$65&" "&Demand!$B$65&" "&Demand!$C$65&" "&Demand!$D$65 -> DEMAND - Electricity Miscellanous EGRID electricity demand | D23: =_xlfn.XLOOKUP(B23,Trans_Demand!A:A,Trans_Demand!B:B) -> TJ | E23: COM_PROJ | F23: 2095 | G23: =SUMIFS(Trans_Demand!D:D,Trans_Demand!A:A,DMD_ELC!B23,Trans_Demand!C:C,DMD_ELC!F23,Trans_Demand!D:D,">0") -> 0 | J23: =Demand!$E$65 -> ELCMISEGRIDDMD | K23: ="DEMAND - "&Demand!$A$65&" "&Demand!$B$65&" "&Demand!$C$65&" "&Demand!$D$65 -> DEMAND - Electricity Miscellanous EGRID electricity demand | L23: COM_FR | M23: WDAM | N23: 2100 | O23: 0.0815
B24: =Demand!$E$65 -> ELCMISEGRIDDMD | C24: ="DEMAND - "&Demand!$A$65&" "&Demand!$B$65&" "&Demand!$C$65&" "&Demand!$D$65 -> DEMAND - Electricity Miscellanous EGRID electricity demand | D24: =_xlfn.XLOOKUP(B24,Trans_Demand!A:A,Trans_Demand!B:B) -> TJ | E24: COM_PROJ | F24: 2100 | G24: =SUMIFS(Trans_Demand!D:D,Trans_Demand!A:A,DMD_ELC!B24,Trans_Demand!C:C,DMD_ELC!F24,Trans_Demand!D:D,">0") -> 0 | J24: =Demand!$E$65 -> ELCMISEGRIDDMD | K24: ="DEMAND - "&Demand!$A$65&" "&Demand!$B$65&" "&Demand!$C$65&" "&Demand!$D$65 -> DEMAND - Electricity Miscellanous EGRID electricity demand | L24: COM_FR | M24: WDPM | N24: 2100 | O24: 0.1087
B25: =Demand!$E$65 -> ELCMISEGRIDDMD | C25: ="DEMAND - "&Demand!$A$65&" "&Demand!$B$65&" "&Demand!$C$65&" "&Demand!$D$65 -> DEMAND - Electricity Miscellanous EGRID electricity demand | D25: =_xlfn.XLOOKUP(B25,Trans_Demand!A:A,Trans_Demand!B:B) -> TJ | E25: COM_PROJ | F25: 0 | G25: 5 | J25: =Demand!$E$65 -> ELCMISEGRIDDMD | K25: ="DEMAND - "&Demand!$A$65&" "&Demand!$B$65&" "&Demand!$C$65&" "&Demand!$D$65 -> DEMAND - Electricity Miscellanous EGRID electricity demand | L25: COM_FR | M25: WN | N25: 2100 | O25: 0.1381
J26: =Demand!$E$65 -> ELCMISEGRIDDMD | K26: ="DEMAND - "&Demand!$A$65&" "&Demand!$B$65&" "&Demand!$C$65&" "&Demand!$D$65 -> DEMAND - Electricity Miscellanous EGRID electricity demand | L26: COM_FR | M26: WP | N26: 2100 | O26: 0.0032
J27: =Demand!$E$65 -> ELCMISEGRIDDMD | K27: ="DEMAND - "&Demand!$A$65&" "&Demand!$B$65&" "&Demand!$C$65&" "&Demand!$D$65 -> DEMAND - Electricity Miscellanous EGRID electricity demand | L27: COM_FR | M27: SDAM | N27: 2100 | O27: 0.0975
J28: =Demand!$E$65 -> ELCMISEGRIDDMD | K28: ="DEMAND - "&Demand!$A$65&" "&Demand!$B$65&" "&Demand!$C$65&" "&Demand!$D$65 -> DEMAND - Electricity Miscellanous EGRID electricity demand | L28: COM_FR | M28: SDPM | N28: 2100 | O28: 0.1087
J29: =Demand!$E$65 -> ELCMISEGRIDDMD | K29: ="DEMAND - "&Demand!$A$65&" "&Demand!$B$65&" "&Demand!$C$65&" "&Demand!$D$65 -> DEMAND - Electricity Miscellanous EGRID electricity demand | L29: COM_FR | M29: SN | N29: 2100 | O29: 0.1253
J30: =Demand!$E$65 -> ELCMISEGRIDDMD | K30: ="DEMAND - "&Demand!$A$65&" "&Demand!$B$65&" "&Demand!$C$65&" "&Demand!$D$65 -> DEMAND - Electricity Miscellanous EGRID electricity demand | L30: COM_FR | M30: SP | N30: 2100 | O30: 0.0027
B57: ~TFM_INS
B58: CommName | C58: *Description | D58: *Unit | E58: Attribute | F58: Year | G58: CITY
B59: * | C59: * | D59: * | E59: * | F59: * | G59: *

Sheet DMD_WAS
B2: ~TFM_INS
B3: CommName | C3: *Description | D3: *Unit | E3: Attribute | F3: Year | G3: CITY
B4: * | C4: * | D4: * | E4: * | F4: * | G4: *
B5: =Trans_Demand!A956 -> WASSOLPAPDMD | C5: ="DEMAND - "&_xlfn.XLOOKUP(B5,Demand!E:E,Demand!A:A)&" "&_xlfn.XLOOKUP(B5,Demand!E:E,Demand!B:B)&" "&_xlfn.XLOOKUP(B5,Demand!E:E,Demand!C:C)&" "&_xlfn.XLOOKUP(B5,Demand!E:E,Demand!D:D) -> DEMAND - Waste Solid Paper | D5: =Trans_Demand!B956 -> k tonnes | E5: COM_PROJ | F5: =Trans_Demand!C956 -> 2019 | G5: =Trans_Demand!D956 -> 3375.0741
B6: =Trans_Demand!A957 -> WASSOLPAPDMD | C6: ="DEMAND - "&_xlfn.XLOOKUP(B6,Demand!E:E,Demand!A:A)&" "&_xlfn.XLOOKUP(B6,Demand!E:E,Demand!B:B)&" "&_xlfn.XLOOKUP(B6,Demand!E:E,Demand!C:C)&" "&_xlfn.XLOOKUP(B6,Demand!E:E,Demand!D:D) -> DEMAND - Waste Solid Paper | D6: =Trans_Demand!B957 -> k tonnes | E6: COM_PROJ | F6: =Trans_Demand!C957 -> 2020 | G6: =Trans_Demand!D957 -> 3391.9495
B7: =Trans_Demand!A958 -> WASSOLPAPDMD | C7: ="DEMAND - "&_xlfn.XLOOKUP(B7,Demand!E:E,Demand!A:A)&" "&_xlfn.XLOOKUP(B7,Demand!E:E,Demand!B:B)&" "&_xlfn.XLOOKUP(B7,Demand!E:E,Demand!C:C)&" "&_xlfn.XLOOKUP(B7,Demand!E:E,Demand!D:D) -> DEMAND - Waste Solid Paper | D7: =Trans_Demand!B958 -> k tonnes | E7: COM_PROJ | F7: =Trans_Demand!C958 -> 2025 | G7: =Trans_Demand!D958 -> 3476.7482
B8: =Trans_Demand!A959 -> WASSOLPAPDMD | C8: ="DEMAND - "&_xlfn.XLOOKUP(B8,Demand!E:E,Demand!A:A)&" "&_xlfn.XLOOKUP(B8,Demand!E:E,Demand!B:B)&" "&_xlfn.XLOOKUP(B8,Demand!E:E,Demand!C:C)&" "&_xlfn.XLOOKUP(B8,Demand!E:E,Demand!D:D) -> DEMAND - Waste Solid Paper | D8: =Trans_Demand!B959 -> k tonnes | E8: COM_PROJ | F8: =Trans_Demand!C959 -> 2030 | G8: =Trans_Demand!D959 -> 3563.6669
B9: =Trans_Demand!A960 -> WASSOLPAPDMD | C9: ="DEMAND - "&_xlfn.XLOOKUP(B9,Demand!E:E,Demand!A:A)&" "&_xlfn.XLOOKUP(B9,Demand!E:E,Demand!B:B)&" "&_xlfn.XLOOKUP(B9,Demand!E:E,Demand!C:C)&" "&_xlfn.XLOOKUP(B9,Demand!E:E,Demand!D:D) -> DEMAND - Waste Solid Paper | D9: =Trans_Demand!B960 -> k tonnes | E9: COM_PROJ | F9: =Trans_Demand!C960 -> 2035 | G9: =Trans_Demand!D960 -> 3652.7586
B10: =Trans_Demand!A961 -> WASSOLPAPDMD | C10: ="DEMAND - "&_xlfn.XLOOKUP(B10,Demand!E:E,Demand!A:A)&" "&_xlfn.XLOOKUP(B10,Demand!E:E,Demand!B:B)&" "&_xlfn.XLOOKUP(B10,Demand!E:E,Demand!C:C)&" "&_xlfn.XLOOKUP(B10,Demand!E:E,Demand!D:D) -> DEMAND - Waste Solid Paper | D10: =Trans_Demand!B961 -> k tonnes | E10: COM_PROJ | F10: =Trans_Demand!C961 -> 2040 | G10: =Trans_Demand!D961 -> 3744.0775
B11: =Trans_Demand!A962 -> WASSOLPAPDMD | C11: ="DEMAND - "&_xlfn.XLOOKUP(B11,Demand!E:E,Demand!A:A)&" "&_xlfn.XLOOKUP(B11,Demand!E:E,Demand!B:B)&" "&_xlfn.XLOOKUP(B11,Demand!E:E,Demand!C:C)&" "&_xlfn.XLOOKUP(B11,Demand!E:E,Demand!D:D) -> DEMAND - Waste Solid Paper | D11: =Trans_Demand!B962 -> k tonnes | E11: COM_PROJ | F11: =Trans_Demand!C962 -> 2045 | G11: =Trans_Demand!D962 -> 3837.6795
B12: =Trans_Demand!A963 -> WASSOLPAPDMD | C12: ="DEMAND - "&_xlfn.XLOOKUP(B12,Demand!E:E,Demand!A:A)&" "&_xlfn.XLOOKUP(B12,Demand!E:E,Demand!B:B)&" "&_xlfn.XLOOKUP(B12,Demand!E:E,Demand!C:C)&" "&_xlfn.XLOOKUP(B12,Demand!E:E,Demand!D:D) -> DEMAND - Waste Solid Paper | D12: =Trans_Demand!B963 -> k tonnes | E12: COM_PROJ | F12: =Trans_Demand!C963 -> 2050 | G12: =Trans_Demand!D963 -> 3933.6215
B13: =Trans_Demand!A964 -> WASSOLPAPDMD | C13: ="DEMAND - "&_xlfn.XLOOKUP(B13,Demand!E:E,Demand!A:A)&" "&_xlfn.XLOOKUP(B13,Demand!E:E,Demand!B:B)&" "&_xlfn.XLOOKUP(B13,Demand!E:E,Demand!C:C)&" "&_xlfn.XLOOKUP(B13,Demand!E:E,Demand!D:D) -> DEMAND - Waste Solid Paper | D13: =Trans_Demand!B964 -> k tonnes | E13: COM_PROJ | F13: =Trans_Demand!C964 -> 2055 | G13: =Trans_Demand!D964 -> 4031.962
B14: =Trans_Demand!A965 -> WASSOLPAPDMD | C14: ="DEMAND - "&_xlfn.XLOOKUP(B14,Demand!E:E,Demand!A:A)&" "&_xlfn.XLOOKUP(B14,Demand!E:E,Demand!B:B)&" "&_xlfn.XLOOKUP(B14,Demand!E:E,Demand!C:C)&" "&_xlfn.XLOOKUP(B14,Demand!E:E,Demand!D:D) -> DEMAND - Waste Solid Paper | D14: =Trans_Demand!B965 -> k tonnes | E14: COM_PROJ | F14: =Trans_Demand!C965 -> 2060 | G14: =Trans_Demand!D965 -> 4132.761
B15: =Trans_Demand!A966 -> WASSOLPAPDMD | C15: ="DEMAND - "&_xlfn.XLOOKUP(B15,Demand!E:E,Demand!A:A)&" "&_xlfn.XLOOKUP(B15,Demand!E:E,Demand!B:B)&" "&_xlfn.XLOOKUP(B15,Demand!E:E,Demand!C:C)&" "&_xlfn.XLOOKUP(B15,Demand!E:E,Demand!D:D) -> DEMAND - Waste Solid Paper | D15: =Trans_Demand!B966 -> k tonnes | E15: COM_PROJ | F15: =Trans_Demand!C966 -> 2065 | G15: =Trans_Demand!D966 -> 4236.0801
B16: =Trans_Demand!A967 -> WASSOLPAPDMD | C16: ="DEMAND - "&_xlfn.XLOOKUP(B16,Demand!E:E,Demand!A:A)&" "&_xlfn.XLOOKUP(B16,Demand!E:E,Demand!B:B)&" "&_xlfn.XLOOKUP(B16,Demand!E:E,Demand!C:C)&" "&_xlfn.XLOOKUP(B16,Demand!E:E,Demand!D:D) -> DEMAND - Waste Solid Paper | D16: =Trans_Demand!B967 -> k tonnes | E16: COM_PROJ | F16: =Trans_Demand!C967 -> 2070 | G16: =Trans_Demand!D967 -> 4341.9821
... B22: =Trans_Demand!A973 -> WASSOLPAPDMD | C22: ="DEMAND - "&_xlfn.XLOOKUP(B22,Demand!E:E,Demand!A:A)&" "&_xlfn.XLOOKUP(B22,Demand!E:E,Demand!B:B)&" "&_xlfn.XLOOKUP(B22,Demand!E:E,Demand!C:C)&" "&_xlfn.XLOOKUP(B22,Demand!E:E,Demand!D:D) -> DEMAND - Waste Solid Paper | D22: =Trans_Demand!B973 -> k tonnes | E22: COM_PROJ | F22: =Trans_Demand!C973 -> 2100 | G22: =Trans_Demand!D973 -> 5035.368
B23: =B22 -> WASSOLPAPDMD | C23: =C22 -> DEMAND - Waste Solid Paper | D23: =D22 -> k tonnes | E23: =E22 -> COM_PROJ | F23: 0 | G23: 5
B24: =Trans_Demand!A974 -> WASSOLGLADMD | C24: ="DEMAND - "&_xlfn.XLOOKUP(B24,Demand!E:E,Demand!A:A)&" "&_xlfn.XLOOKUP(B24,Demand!E:E,Demand!B:B)&" "&_xlfn.XLOOKUP(B24,Demand!E:E,Demand!C:C)&" "&_xlfn.XLOOKUP(B24,Demand!E:E,Demand!D:D) -> DEMAND - Waste Solid Glass | D24: =Trans_Demand!B974 -> k tonnes | E24: COM_PROJ | F24: =Trans_Demand!C974 -> 2019 | G24: =Trans_Demand!D974 -> 405.00889
B25: =Trans_Demand!A975 -> WASSOLGLADMD | C25: ="DEMAND - "&_xlfn.XLOOKUP(B25,Demand!E:E,Demand!A:A)&" "&_xlfn.XLOOKUP(B25,Demand!E:E,Demand!B:B)&" "&_xlfn.XLOOKUP(B25,Demand!E:E,Demand!C:C)&" "&_xlfn.XLOOKUP(B25,Demand!E:E,Demand!D:D) -> DEMAND - Waste Solid Glass | D25: =Trans_Demand!B975 -> k tonnes | E25: COM_PROJ | F25: =Trans_Demand!C975 -> 2020 | G25: =Trans_Demand!D975 -> 407.03393
B26: =Trans_Demand!A976 -> WASSOLGLADMD | C26: ="DEMAND - "&_xlfn.XLOOKUP(B26,Demand!E:E,Demand!A:A)&" "&_xlfn.XLOOKUP(B26,Demand!E:E,Demand!B:B)&" "&_xlfn.XLOOKUP(B26,Demand!E:E,Demand!C:C)&" "&_xlfn.XLOOKUP(B26,Demand!E:E,Demand!D:D) -> DEMAND - Waste Solid Glass | D26: =Trans_Demand!B976 -> k tonnes | E26: COM_PROJ | F26: =Trans_Demand!C976 -> 2025 | G26: =Trans_Demand!D976 -> 417.20978
B27: =Trans_Demand!A977 -> WASSOLGLADMD | C27: ="DEMAND - "&_xlfn.XLOOKUP(B27,Demand!E:E,Demand!A:A)&" "&_xlfn.XLOOKUP(B27,Demand!E:E,Demand!B:B)&" "&_xlfn.XLOOKUP(B27,Demand!E:E,Demand!C:C)&" "&_xlfn.XLOOKUP(B27,Demand!E:E,Demand!D:D) -> DEMAND - Waste Solid Glass | D27: =Trans_Demand!B977 -> k tonnes | E27: COM_PROJ | F27: =Trans_Demand!C977 -> 2030 | G27: =Trans_Demand!D977 -> 427.64003
B28: =Trans_Demand!A978 -> WASSOLGLADMD | C28: ="DEMAND - "&_xlfn.XLOOKUP(B28,Demand!E:E,Demand!A:A)&" "&_xlfn.XLOOKUP(B28,Demand!E:E,Demand!B:B)&" "&_xlfn.XLOOKUP(B28,Demand!E:E,Demand!C:C)&" "&_xlfn.XLOOKUP(B28,Demand!E:E,Demand!D:D) -> DEMAND - Waste Solid Glass | D28: =Trans_Demand!B978 -> k tonnes | E28: COM_PROJ | F28: =Trans_Demand!C978 -> 2035 | G28: =Trans_Demand!D978 -> 438.33103
B29: =Trans_Demand!A979 -> WASSOLGLADMD | C29: ="DEMAND - "&_xlfn.XLOOKUP(B29,Demand!E:E,Demand!A:A)&" "&_xlfn.XLOOKUP(B29,Demand!E:E,Demand!B:B)&" "&_xlfn.XLOOKUP(B29,Demand!E:E,Demand!C:C)&" "&_xlfn.XLOOKUP(B29,Demand!E:E,Demand!D:D) -> DEMAND - Waste Solid Glass | D29: =Trans_Demand!B979 -> k tonnes | E29: COM_PROJ | F29: =Trans_Demand!C979 -> 2040 | G29: =Trans_Demand!D979 -> 449.2893
B30: =Trans_Demand!A980 -> WASSOLGLADMD | C30: ="DEMAND - "&_xlfn.XLOOKUP(B30,Demand!E:E,Demand!A:A)&" "&_xlfn.XLOOKUP(B30,Demand!E:E,Demand!B:B)&" "&_xlfn.XLOOKUP(B30,Demand!E:E,Demand!C:C)&" "&_xlfn.XLOOKUP(B30,Demand!E:E,Demand!D:D) -> DEMAND - Waste Solid Glass | D30: =Trans_Demand!B980 -> k tonnes | E30: COM_PROJ | F30: =Trans_Demand!C980 -> 2045 | G30: =Trans_Demand!D980 -> 460.52154
B31: =Trans_Demand!A981 -> WASSOLGLADMD | C31: ="DEMAND - "&_xlfn.XLOOKUP(B31,Demand!E:E,Demand!A:A)&" "&_xlfn.XLOOKUP(B31,Demand!E:E,Demand!B:B)&" "&_xlfn.XLOOKUP(B31,Demand!E:E,Demand!C:C)&" "&_xlfn.XLOOKUP(B31,Demand!E:E,Demand!D:D) -> DEMAND - Waste Solid Glass | D31: =Trans_Demand!B981 -> k tonnes | E31: COM_PROJ | F31: =Trans_Demand!C981 -> 2050 | G31: =Trans_Demand!D981 -> 472.03457
B32: =Trans_Demand!A982 -> WASSOLGLADMD | C32: ="DEMAND - "&_xlfn.XLOOKUP(B32,Demand!E:E,Demand!A:A)&" "&_xlfn.XLOOKUP(B32,Demand!E:E,Demand!B:B)&" "&_xlfn.XLOOKUP(B32,Demand!E:E,Demand!C:C)&" "&_xlfn.XLOOKUP(B32,Demand!E:E,Demand!D:D) -> DEMAND - Waste Solid Glass | D32: =Trans_Demand!B982 -> k tonnes | E32: COM_PROJ | F32: =Trans_Demand!C982 -> 2055 | G32: =Trans_Demand!D982 -> 483.83544
B33: =Trans_Demand!A983 -> WASSOLGLADMD | C33: ="DEMAND - "&_xlfn.XLOOKUP(B33,Demand!E:E,Demand!A:A)&" "&_xlfn.XLOOKUP(B33,Demand!E:E,Demand!B:B)&" "&_xlfn.XLOOKUP(B33,Demand!E:E,Demand!C:C)&" "&_xlfn.XLOOKUP(B33,Demand!E:E,Demand!D:D) -> DEMAND - Waste Solid Glass | D33: =Trans_Demand!B983 -> k tonnes | E33: COM_PROJ | F33: =Trans_Demand!C983 -> 2060 | G33: =Trans_Demand!D983 -> 495.93133
B34: =Trans_Demand!A984 -> WASSOLGLADMD | C34: ="DEMAND - "&_xlfn.XLOOKUP(B34,Demand!E:E,Demand!A:A)&" "&_xlfn.XLOOKUP(B34,Demand!E:E,Demand!B:B)&" "&_xlfn.XLOOKUP(B34,Demand!E:E,Demand!C:C)&" "&_xlfn.XLOOKUP(B34,Demand!E:E,Demand!D:D) -> DEMAND - Waste Solid Glass | D34: =Trans_Demand!B984 -> k tonnes | E34: COM_PROJ | F34: =Trans_Demand!C984 -> 2065 | G34: =Trans_Demand!D984 -> 508.32961
B35: =Trans_Demand!A985 -> WASSOLGLADMD | C35: ="DEMAND - "&_xlfn.XLOOKUP(B35,Demand!E:E,Demand!A:A)&" "&_xlfn.XLOOKUP(B35,Demand!E:E,Demand!B:B)&" "&_xlfn.XLOOKUP(B35,Demand!E:E,Demand!C:C)&" "&_xlfn.XLOOKUP(B35,Demand!E:E,Demand!D:D) -> DEMAND - Waste Solid Glass | D35: =Trans_Demand!B985 -> k tonnes | E35: COM_PROJ | F35: =Trans_Demand!C985 -> 2070 | G35: =Trans_Demand!D985 -> 521.03785
... B41: =Trans_Demand!A991 -> WASSOLGLADMD | C41: ="DEMAND - "&_xlfn.XLOOKUP(B41,Demand!E:E,Demand!A:A)&" "&_xlfn.XLOOKUP(B41,Demand!E:E,Demand!B:B)&" "&_xlfn.XLOOKUP(B41,Demand!E:E,Demand!C:C)&" "&_xlfn.XLOOKUP(B41,Demand!E:E,Demand!D:D) -> DEMAND - Waste Solid Glass | D41: =Trans_Demand!B991 -> k tonnes | E41: COM_PROJ | F41: =Trans_Demand!C991 -> 2100 | G41: =Trans_Demand!D991 -> 604.24416
B42: =B41 -> WASSOLGLADMD | C42: =C41 -> DEMAND - Waste Solid Glass | D42: =D41 -> k tonnes | E42: =E41 -> COM_PROJ | F42: 0 | G42: 5
B43: =Trans_Demand!A992 -> WASSOLMETDMD | C43: ="DEMAND - "&_xlfn.XLOOKUP(B43,Demand!E:E,Demand!A:A)&" "&_xlfn.XLOOKUP(B43,Demand!E:E,Demand!B:B)&" "&_xlfn.XLOOKUP(B43,Demand!E:E,Demand!C:C)&" "&_xlfn.XLOOKUP(B43,Demand!E:E,Demand!D:D) -> DEMAND - Waste Solid Metals | D43: =Trans_Demand!B992 -> k tonnes | E43: COM_PROJ | F43: =Trans_Demand!C992 -> 2019 | G43: =Trans_Demand!D992 -> 540.01185
B44: =Trans_Demand!A993 -> WASSOLMETDMD | C44: ="DEMAND - "&_xlfn.XLOOKUP(B44,Demand!E:E,Demand!A:A)&" "&_xlfn.XLOOKUP(B44,Demand!E:E,Demand!B:B)&" "&_xlfn.XLOOKUP(B44,Demand!E:E,Demand!C:C)&" "&_xlfn.XLOOKUP(B44,Demand!E:E,Demand!D:D) -> DEMAND - Waste Solid Metals | D44: =Trans_Demand!B993 -> k tonnes | E44: COM_PROJ | F44: =Trans_Demand!C993 -> 2020 | G44: =Trans_Demand!D993 -> 542.71191
B45: =Trans_Demand!A994 -> WASSOLMETDMD | C45: ="DEMAND - "&_xlfn.XLOOKUP(B45,Demand!E:E,Demand!A:A)&" "&_xlfn.XLOOKUP(B45,Demand!E:E,Demand!B:B)&" "&_xlfn.XLOOKUP(B45,Demand!E:E,Demand!C:C)&" "&_xlfn.XLOOKUP(B45,Demand!E:E,Demand!D:D) -> DEMAND - Waste Solid Metals | D45: =Trans_Demand!B994 -> k tonnes | E45: COM_PROJ | F45: =Trans_Demand!C994 -> 2025 | G45: =Trans_Demand!D994 -> 556.27971
B46: =Trans_Demand!A995 -> WASSOLMETDMD | C46: ="DEMAND - "&_xlfn.XLOOKUP(B46,Demand!E:E,Demand!A:A)&" "&_xlfn.XLOOKUP(B46,Demand!E:E,Demand!B:B)&" "&_xlfn.XLOOKUP(B46,Demand!E:E,Demand!C:C)&" "&_xlfn.XLOOKUP(B46,Demand!E:E,Demand!D:D) -> DEMAND - Waste Solid Metals | D46: =Trans_Demand!B995 -> k tonnes | E46: COM_PROJ | F46: =Trans_Demand!C995 -> 2030 | G46: =Trans_Demand!D995 -> 570.1867
B47: =Trans_Demand!A996 -> WASSOLMETDMD | C47: ="DEMAND - "&_xlfn.XLOOKUP(B47,Demand!E:E,Demand!A:A)&" "&_xlfn.XLOOKUP(B47,Demand!E:E,Demand!B:B)&" "&_xlfn.XLOOKUP(B47,Demand!E:E,Demand!C:C)&" "&_xlfn.XLOOKUP(B47,Demand!E:E,Demand!D:D) -> DEMAND - Waste Solid Metals | D47: =Trans_Demand!B996 -> k tonnes | E47: COM_PROJ | F47: =Trans_Demand!C996 -> 2035 | G47: =Trans_Demand!D996 -> 584.44137
B48: =Trans_Demand!A997 -> WASSOLMETDMD | C48: ="DEMAND - "&_xlfn.XLOOKUP(B48,Demand!E:E,Demand!A:A)&" "&_xlfn.XLOOKUP(B48,Demand!E:E,Demand!B:B)&" "&_xlfn.XLOOKUP(B48,Demand!E:E,Demand!C:C)&" "&_xlfn.XLOOKUP(B48,Demand!E:E,Demand!D:D) -> DEMAND - Waste Solid Metals | D48: =Trans_Demand!B997 -> k tonnes | E48: COM_PROJ | F48: =Trans_Demand!C997 -> 2040 | G48: =Trans_Demand!D997 -> 599.05241
B49: =Trans_Demand!A998 -> WASSOLMETDMD | C49: ="DEMAND - "&_xlfn.XLOOKUP(B49,Demand!E:E,Demand!A:A)&" "&_xlfn.XLOOKUP(B49,Demand!E:E,Demand!B:B)&" "&_xlfn.XLOOKUP(B49,Demand!E:E,Demand!C:C)&" "&_xlfn.XLOOKUP(B49,Demand!E:E,Demand!D:D) -> DEMAND - Waste Solid Metals | D49: =Trans_Demand!B998 -> k tonnes | E49: COM_PROJ | F49: =Trans_Demand!C998 -> 2045 | G49: =Trans_Demand!D998 -> 614.02872
B50: =Trans_Demand!A999 -> WASSOLMETDMD | C50: ="DEMAND - "&_xlfn.XLOOKUP(B50,Demand!E:E,Demand!A:A)&" "&_xlfn.XLOOKUP(B50,Demand!E:E,Demand!B:B)&" "&_xlfn.XLOOKUP(B50,Demand!E:E,Demand!C:C)&" "&_xlfn.XLOOKUP(B50,Demand!E:E,Demand!D:D) -> DEMAND - Waste Solid Metals | D50: =Trans_Demand!B999 -> k tonnes | E50: COM_PROJ | F50: =Trans_Demand!C999 -> 2050 | G50: =Trans_Demand!D999 -> 629.37943
B51: =Trans_Demand!A1000 -> WASSOLMETDMD | C51: ="DEMAND - "&_xlfn.XLOOKUP(B51,Demand!E:E,Demand!A:A)&" "&_xlfn.XLOOKUP(B51,Demand!E:E,Demand!B:B)&" "&_xlfn.XLOOKUP(B51,Demand!E:E,Demand!C:C)&" "&_xlfn.XLOOKUP(B51,Demand!E:E,Demand!D:D) -> DEMAND - Waste Solid Metals | D51: =Trans_Demand!B1000 -> k tonnes | E51: COM_PROJ | F51: =Trans_Demand!C1000 -> 2055 | G51: =Trans_Demand!D1000 -> 645.11392
...

Sheet DMD_TRA
B3: ~TFM_INS
B4: CommName | C4: *Description | D4: *Unit | E4: Attribute | F4: Year | G4: CITY
B5: * | C5: * | D5: * | E5: * | F5: * | G5: *
B6: =Trans_Demand!A596 -> TRAPASCARDMD | C6: ="DEMAND - "&_xlfn.XLOOKUP(B6,Demand!E:E,Demand!A:A)&" "&_xlfn.XLOOKUP(B6,Demand!E:E,Demand!B:B)&" "&_xlfn.XLOOKUP(B6,Demand!E:E,Demand!C:C)&" "&_xlfn.XLOOKUP(B6,Demand!E:E,Demand!D:D) -> DEMAND - Transportation Passenger Passenger Car | D6: =_xlfn.XLOOKUP(B6,Trans_Demand!A:A,Trans_Demand!B:B) -> M Vkm | E6: COM_PROJ | F6: =Trans_Demand!C2 -> 2019 | G6: =SUMIFS(Trans_Demand!D:D,Trans_Demand!A:A,DMD_TRA!B6,Trans_Demand!C:C,DMD_TRA!F6) -> 68921.251
B7: =Trans_Demand!A597 -> TRAPASCARDMD | C7: ="DEMAND - "&_xlfn.XLOOKUP(B7,Demand!E:E,Demand!A:A)&" "&_xlfn.XLOOKUP(B7,Demand!E:E,Demand!B:B)&" "&_xlfn.XLOOKUP(B7,Demand!E:E,Demand!C:C)&" "&_xlfn.XLOOKUP(B7,Demand!E:E,Demand!D:D) -> DEMAND - Transportation Passenger Passenger Car | D7: =_xlfn.XLOOKUP(B7,Trans_Demand!A:A,Trans_Demand!B:B) -> M Vkm | E7: COM_PROJ | F7: =Trans_Demand!C3 -> 2020 | G7: =SUMIFS(Trans_Demand!D:D,Trans_Demand!A:A,DMD_TRA!B7,Trans_Demand!C:C,DMD_TRA!F7) -> 69265.857
B8: =Trans_Demand!A598 -> TRAPASCARDMD | C8: ="DEMAND - "&_xlfn.XLOOKUP(B8,Demand!E:E,Demand!A:A)&" "&_xlfn.XLOOKUP(B8,Demand!E:E,Demand!B:B)&" "&_xlfn.XLOOKUP(B8,Demand!E:E,Demand!C:C)&" "&_xlfn.XLOOKUP(B8,Demand!E:E,Demand!D:D) -> DEMAND - Transportation Passenger Passenger Car | D8: =_xlfn.XLOOKUP(B8,Trans_Demand!A:A,Trans_Demand!B:B) -> M Vkm | E8: COM_PROJ | F8: =Trans_Demand!C4 -> 2025 | G8: =SUMIFS(Trans_Demand!D:D,Trans_Demand!A:A,DMD_TRA!B8,Trans_Demand!C:C,DMD_TRA!F8) -> 70997.504
B9: =Trans_Demand!A599 -> TRAPASCARDMD | C9: ="DEMAND - "&_xlfn.XLOOKUP(B9,Demand!E:E,Demand!A:A)&" "&_xlfn.XLOOKUP(B9,Demand!E:E,Demand!B:B)&" "&_xlfn.XLOOKUP(B9,Demand!E:E,Demand!C:C)&" "&_xlfn.XLOOKUP(B9,Demand!E:E,Demand!D:D) -> DEMAND - Transportation Passenger Passenger Car | D9: =_xlfn.XLOOKUP(B9,Trans_Demand!A:A,Trans_Demand!B:B) -> M Vkm | E9: COM_PROJ | F9: =Trans_Demand!C5 -> 2030 | G9: =SUMIFS(Trans_Demand!D:D,Trans_Demand!A:A,DMD_TRA!B9,Trans_Demand!C:C,DMD_TRA!F9) -> 72772.441
B10: =Trans_Demand!A600 -> TRAPASCARDMD | C10: ="DEMAND - "&_xlfn.XLOOKUP(B10,Demand!E:E,Demand!A:A)&" "&_xlfn.XLOOKUP(B10,Demand!E:E,Demand!B:B)&" "&_xlfn.XLOOKUP(B10,Demand!E:E,Demand!C:C)&" "&_xlfn.XLOOKUP(B10,Demand!E:E,Demand!D:D) -> DEMAND - Transportation Passenger Passenger Car | D10: =_xlfn.XLOOKUP(B10,Trans_Demand!A:A,Trans_Demand!B:B) -> M Vkm | E10: COM_PROJ | F10: =Trans_Demand!C6 -> 2035 | G10: =SUMIFS(Trans_Demand!D:D,Trans_Demand!A:A,DMD_TRA!B10,Trans_Demand!C:C,DMD_TRA!F10) -> 74591.752
B11: =Trans_Demand!A601 -> TRAPASCARDMD | C11: ="DEMAND - "&_xlfn.XLOOKUP(B11,Demand!E:E,Demand!A:A)&" "&_xlfn.XLOOKUP(B11,Demand!E:E,Demand!B:B)&" "&_xlfn.XLOOKUP(B11,Demand!E:E,Demand!C:C)&" "&_xlfn.XLOOKUP(B11,Demand!E:E,Demand!D:D) -> DEMAND - Transportation Passenger Passenger Car | D11: =_xlfn.XLOOKUP(B11,Trans_Demand!A:A,Trans_Demand!B:B) -> M Vkm | E11: COM_PROJ | F11: =Trans_Demand!C7 -> 2040 | G11: =SUMIFS(Trans_Demand!D:D,Trans_Demand!A:A,DMD_TRA!B11,Trans_Demand!C:C,DMD_TRA!F11) -> 76456.546
B12: =Trans_Demand!A602 -> TRAPASCARDMD | C12: ="DEMAND - "&_xlfn.XLOOKUP(B12,Demand!E:E,Demand!A:A)&" "&_xlfn.XLOOKUP(B12,Demand!E:E,Demand!B:B)&" "&_xlfn.XLOOKUP(B12,Demand!E:E,Demand!C:C)&" "&_xlfn.XLOOKUP(B12,Demand!E:E,Demand!D:D) -> DEMAND - Transportation Passenger Passenger Car | D12: =_xlfn.XLOOKUP(B12,Trans_Demand!A:A,Trans_Demand!B:B) -> M Vkm | E12: COM_PROJ | F12: =Trans_Demand!C8 -> 2045 | G12: =SUMIFS(Trans_Demand!D:D,Trans_Demand!A:A,DMD_TRA!B12,Trans_Demand!C:C,DMD_TRA!F12) -> 78367.96
B13: =Trans_Demand!A603 -> TRAPASCARDMD | C13: ="DEMAND - "&_xlfn.XLOOKUP(B13,Demand!E:E,Demand!A:A)&" "&_xlfn.XLOOKUP(B13,Demand!E:E,Demand!B:B)&" "&_xlfn.XLOOKUP(B13,Demand!E:E,Demand!C:C)&" "&_xlfn.XLOOKUP(B13,Demand!E:E,Demand!D:D) -> DEMAND - Transportation Passenger Passenger Car | D13: =_xlfn.XLOOKUP(B13,Trans_Demand!A:A,Trans_Demand!B:B) -> M Vkm | E13: COM_PROJ | F13: =Trans_Demand!C9 -> 2050 | G13: =SUMIFS(Trans_Demand!D:D,Trans_Demand!A:A,DMD_TRA!B13,Trans_Demand!C:C,DMD_TRA!F13) -> 80327.159
B14: =Trans_Demand!A604 -> TRAPASCARDMD | C14: ="DEMAND - "&_xlfn.XLOOKUP(B14,Demand!E:E,Demand!A:A)&" "&_xlfn.XLOOKUP(B14,Demand!E:E,Demand!B:B)&" "&_xlfn.XLOOKUP(B14,Demand!E:E,Demand!C:C)&" "&_xlfn.XLOOKUP(B14,Demand!E:E,Demand!D:D) -> DEMAND - Transportation Passenger Passenger Car | D14: =_xlfn.XLOOKUP(B14,Trans_Demand!A:A,Trans_Demand!B:B) -> M Vkm | E14: COM_PROJ | F14: =Trans_Demand!C10 -> 2055 | G14: =SUMIFS(Trans_Demand!D:D,Trans_Demand!A:A,DMD_TRA!B14,Trans_Demand!C:C,DMD_TRA!F14) -> 82335.338
B15: =Trans_Demand!A605 -> TRAPASCARDMD | C15: ="DEMAND - "&_xlfn.XLOOKUP(B15,Demand!E:E,Demand!A:A)&" "&_xlfn.XLOOKUP(B15,Demand!E:E,Demand!B:B)&" "&_xlfn.XLOOKUP(B15,Demand!E:E,Demand!C:C)&" "&_xlfn.XLOOKUP(B15,Demand!E:E,Demand!D:D) -> DEMAND - Transportation Passenger Passenger Car | D15: =_xlfn.XLOOKUP(B15,Trans_Demand!A:A,Trans_Demand!B:B) -> M Vkm | E15: COM_PROJ | F15: =Trans_Demand!C11 -> 2060 | G15: =SUMIFS(Trans_Demand!D:D,Trans_Demand!A:A,DMD_TRA!B15,Trans_Demand!C:C,DMD_TRA!F15) -> 84393.721
B16: =Trans_Demand!A606 -> TRAPASCARDMD | C16: ="DEMAND - "&_xlfn.XLOOKUP(B16,Demand!E:E,Demand!A:A)&" "&_xlfn.XLOOKUP(B16,Demand!E:E,Demand!B:B)&" "&_xlfn.XLOOKUP(B16,Demand!E:E,Demand!C:C)&" "&_xlfn.XLOOKUP(B16,Demand!E:E,Demand!D:D) -> DEMAND - Transportation Passenger Passenger Car | D16: =_xlfn.XLOOKUP(B16,Trans_Demand!A:A,Trans_Demand!B:B) -> M Vkm | E16: COM_PROJ | F16: =Trans_Demand!C12 -> 2065 | G16: =SUMIFS(Trans_Demand!D:D,Trans_Demand!A:A,DMD_TRA!B16,Trans_Demand!C:C,DMD_TRA!F16) -> 86503.564
B17: =Trans_Demand!A607 -> TRAPASCARDMD | C17: ="DEMAND - "&_xlfn.XLOOKUP(B17,Demand!E:E,Demand!A:A)&" "&_xlfn.XLOOKUP(B17,Demand!E:E,Demand!B:B)&" "&_xlfn.XLOOKUP(B17,Demand!E:E,Demand!C:C)&" "&_xlfn.XLOOKUP(B17,Demand!E:E,Demand!D:D) -> DEMAND - Transportation Passenger Passenger Car | D17: =_xlfn.XLOOKUP(B17,Trans_Demand!A:A,Trans_Demand!B:B) -> M Vkm | E17: COM_PROJ | F17: =Trans_Demand!C13 -> 2070 | G17: =SUMIFS(Trans_Demand!D:D,Trans_Demand!A:A,DMD_TRA!B17,Trans_Demand!C:C,DMD_TRA!F17) -> 88666.153
... B365: =Trans_Demand!A955 -> TRAOTHAIRDMD | C365: ="DEMAND - "&_xlfn.XLOOKUP(B365,Demand!E:E,Demand!A:A)&" "&_xlfn.XLOOKUP(B365,Demand!E:E,Demand!B:B)&" "&_xlfn.XLOOKUP(B365,Demand!E:E,Demand!C:C)&" "&_xlfn.XLOOKUP(B365,Demand!E:E,Demand!D:D) -> DEMAND - Transportation Other Aviation | D365: =_xlfn.XLOOKUP(B365,Trans_Demand!A:A,Trans_Demand!B:B) -> M Vkm | E365: COM_PROJ | F365: =Trans_Demand!C361 -> 2100 | G365: =SUMIFS(Trans_Demand!D:D,Trans_Demand!A:A,DMD_TRA!B365,Trans_Demand!C:C,DMD_TRA!F365) -> 0.1875586

Sheet DMD_RES
B3: ~TFM_INS
B4: CommName | C4: *Description | D4: *Unit | E4: Attribute | F4: Year | G4: CITY
B5: * | C5: * | D5: * | E5: * | F5: * | G5: *
B6: =Trans_Demand!A290 -> RESAPALOOldDMD | C6: ="DEMAND - "&_xlfn.XLOOKUP(B6,Demand!E:E,Demand!A:A)&" "&_xlfn.XLOOKUP(B6,Demand!E:E,Demand!B:B)&" "&_xlfn.XLOOKUP(B6,Demand!E:E,Demand!C:C)&" "&_xlfn.XLOOKUP(B6,Demand!E:E,Demand!D:D) -> DEMAND - Residential Apartment Low Income Old | D6: =_xlfn.XLOOKUP(B6,Trans_Demand!A:A,Trans_Demand!B:B) -> Mm2 | E6: COM_PROJ | F6: =Trans_Demand!C290 -> 2019 | G6: =SUMIFS(Trans_Demand!D:D,Trans_Demand!A:A,B6,Trans_Demand!C:C,F6) -> 51.807877
B7: =Trans_Demand!A291 -> RESAPALOOldDMD | C7: ="DEMAND - "&_xlfn.XLOOKUP(B7,Demand!E:E,Demand!A:A)&" "&_xlfn.XLOOKUP(B7,Demand!E:E,Demand!B:B)&" "&_xlfn.XLOOKUP(B7,Demand!E:E,Demand!C:C)&" "&_xlfn.XLOOKUP(B7,Demand!E:E,Demand!D:D) -> DEMAND - Residential Apartment Low Income Old | D7: =_xlfn.XLOOKUP(B7,Trans_Demand!A:A,Trans_Demand!B:B) -> Mm2 | E7: COM_PROJ | F7: =Trans_Demand!C291 -> 2020 | G7: =SUMIFS(Trans_Demand!D:D,Trans_Demand!A:A,B7,Trans_Demand!C:C,F7) -> 51.807877
B8: =Trans_Demand!A292 -> RESAPALOOldDMD | C8: ="DEMAND - "&_xlfn.XLOOKUP(B8,Demand!E:E,Demand!A:A)&" "&_xlfn.XLOOKUP(B8,Demand!E:E,Demand!B:B)&" "&_xlfn.XLOOKUP(B8,Demand!E:E,Demand!C:C)&" "&_xlfn.XLOOKUP(B8,Demand!E:E,Demand!D:D) -> DEMAND - Residential Apartment Low Income Old | D8: =_xlfn.XLOOKUP(B8,Trans_Demand!A:A,Trans_Demand!B:B) -> Mm2 | E8: COM_PROJ | F8: =Trans_Demand!C292 -> 2025 | G8: =SUMIFS(Trans_Demand!D:D,Trans_Demand!A:A,B8,Trans_Demand!C:C,F8) -> 51.807877
B9: =Trans_Demand!A293 -> RESAPALOOldDMD | C9: ="DEMAND - "&_xlfn.XLOOKUP(B9,Demand!E:E,Demand!A:A)&" "&_xlfn.XLOOKUP(B9,Demand!E:E,Demand!B:B)&" "&_xlfn.XLOOKUP(B9,Demand!E:E,Demand!C:C)&" "&_xlfn.XLOOKUP(B9,Demand!E:E,Demand!D:D) -> DEMAND - Residential Apartment Low Income Old | D9: =_xlfn.XLOOKUP(B9,Trans_Demand!A:A,Trans_Demand!B:B) -> Mm2 | E9: COM_PROJ | F9: =Trans_Demand!C293 -> 2030 | G9: =SUMIFS(Trans_Demand!D:D,Trans_Demand!A:A,B9,Trans_Demand!C:C,F9) -> 51.807877
B10: =Trans_Demand!A294 -> RESAPALOOldDMD | C10: ="DEMAND - "&_xlfn.XLOOKUP(B10,Demand!E:E,Demand!A:A)&" "&_xlfn.XLOOKUP(B10,Demand!E:E,Demand!B:B)&" "&_xlfn.XLOOKUP(B10,Demand!E:E,Demand!C:C)&" "&_xlfn.XLOOKUP(B10,Demand!E:E,Demand!D:D) -> DEMAND - Residential Apartment Low Income Old | D10: =_xlfn.XLOOKUP(B10,Trans_Demand!A:A,Trans_Demand!B:B) -> Mm2 | E10: COM_PROJ | F10: =Trans_Demand!C294 -> 2035 | G10: =SUMIFS(Trans_Demand!D:D,Trans_Demand!A:A,B10,Trans_Demand!C:C,F10) -> 51.807877
B11: =Trans_Demand!A295 -> RESAPALOOldDMD | C11: ="DEMAND - "&_xlfn.XLOOKUP(B11,Demand!E:E,Demand!A:A)&" "&_xlfn.XLOOKUP(B11,Demand!E:E,Demand!B:B)&" "&_xlfn.XLOOKUP(B11,Demand!E:E,Demand!C:C)&" "&_xlfn.XLOOKUP(B11,Demand!E:E,Demand!D:D) -> DEMAND - Residential Apartment Low Income Old | D11: =_xlfn.XLOOKUP(B11,Trans_Demand!A:A,Trans_Demand!B:B) -> Mm2 | E11: COM_PROJ | F11: =Trans_Demand!C295 -> 2040 | G11: =SUMIFS(Trans_Demand!D:D,Trans_Demand!A:A,B11,Trans_Demand!C:C,F11) -> 51.807877
B12: =Trans_Demand!A296 -> RESAPALOOldDMD | C12: ="DEMAND - "&_xlfn.XLOOKUP(B12,Demand!E:E,Demand!A:A)&" "&_xlfn.XLOOKUP(B12,Demand!E:E,Demand!B:B)&" "&_xlfn.XLOOKUP(B12,Demand!E:E,Demand!C:C)&" "&_xlfn.XLOOKUP(B12,Demand!E:E,Demand!D:D) -> DEMAND - Residential Apartment Low Income Old | D12: =_xlfn.XLOOKUP(B12,Trans_Demand!A:A,Trans_Demand!B:B) -> Mm2 | E12: COM_PROJ | F12: =Trans_Demand!C296 -> 2045 | G12: =SUMIFS(Trans_Demand!D:D,Trans_Demand!A:A,B12,Trans_Demand!C:C,F12) -> 51.807877
B13: =Trans_Demand!A297 -> RESAPALOOldDMD | C13: ="DEMAND - "&_xlfn.XLOOKUP(B13,Demand!E:E,Demand!A:A)&" "&_xlfn.XLOOKUP(B13,Demand!E:E,Demand!B:B)&" "&_xlfn.XLOOKUP(B13,Demand!E:E,Demand!C:C)&" "&_xlfn.XLOOKUP(B13,Demand!E:E,Demand!D:D) -> DEMAND - Residential Apartment Low Income Old | D13: =_xlfn.XLOOKUP(B13,Trans_Demand!A:A,Trans_Demand!B:B) -> Mm2 | E13: COM_PROJ | F13: =Trans_Demand!C297 -> 2050 | G13: =SUMIFS(Trans_Demand!D:D,Trans_Demand!A:A,B13,Trans_Demand!C:C,F13) -> 51.807877
B14: =Trans_Demand!A298 -> RESAPALOOldDMD | C14: ="DEMAND - "&_xlfn.XLOOKUP(B14,Demand!E:E,Demand!A:A)&" "&_xlfn.XLOOKUP(B14,Demand!E:E,Demand!B:B)&" "&_xlfn.XLOOKUP(B14,Demand!E:E,Demand!C:C)&" "&_xlfn.XLOOKUP(B14,Demand!E:E,Demand!D:D) -> DEMAND - Residential Apartment Low Income Old | D14: =_xlfn.XLOOKUP(B14,Trans_Demand!A:A,Trans_Demand!B:B) -> Mm2 | E14: COM_PROJ | F14: =Trans_Demand!C298 -> 2055 | G14: =SUMIFS(Trans_Demand!D:D,Trans_Demand!A:A,B14,Trans_Demand!C:C,F14) -> 51.807877
B15: =Trans_Demand!A299 -> RESAPALOOldDMD | C15: ="DEMAND - "&_xlfn.XLOOKUP(B15,Demand!E:E,Demand!A:A)&" "&_xlfn.XLOOKUP(B15,Demand!E:E,Demand!B:B)&" "&_xlfn.XLOOKUP(B15,Demand!E:E,Demand!C:C)&" "&_xlfn.XLOOKUP(B15,Demand!E:E,Demand!D:D) -> DEMAND - Residential Apartment Low Income Old | D15: =_xlfn.XLOOKUP(B15,Trans_Demand!A:A,Trans_Demand!B:B) -> Mm2 | E15: COM_PROJ | F15: =Trans_Demand!C299 -> 2060 | G15: =SUMIFS(Trans_Demand!D:D,Trans_Demand!A:A,B15,Trans_Demand!C:C,F15) -> 51.807877
B16: =Trans_Demand!A300 -> RESAPALOOldDMD | C16: ="DEMAND - "&_xlfn.XLOOKUP(B16,Demand!E:E,Demand!A:A)&" "&_xlfn.XLOOKUP(B16,Demand!E:E,Demand!B:B)&" "&_xlfn.XLOOKUP(B16,Demand!E:E,Demand!C:C)&" "&_xlfn.XLOOKUP(B16,Demand!E:E,Demand!D:D) -> DEMAND - Residential Apartment Low Income Old | D16: =_xlfn.XLOOKUP(B16,Trans_Demand!A:A,Trans_Demand!B:B) -> Mm2 | E16: COM_PROJ | F16: =Trans_Demand!C300 -> 2065 | G16: =SUMIFS(Trans_Demand!D:D,Trans_Demand!A:A,B16,Trans_Demand!C:C,F16) -> 51.807877
B17: =Trans_Demand!A301 -> RESAPALOOldDMD | C17: ="DEMAND - "&_xlfn.XLOOKUP(B17,Demand!E:E,Demand!A:A)&" "&_xlfn.XLOOKUP(B17,Demand!E:E,Demand!B:B)&" "&_xlfn.XLOOKUP(B17,Demand!E:E,Demand!C:C)&" "&_xlfn.XLOOKUP(B17,Demand!E:E,Demand!D:D) -> DEMAND - Residential Apartment Low Income Old | D17: =_xlfn.XLOOKUP(B17,Trans_Demand!A:A,Trans_Demand!B:B) -> Mm2 | E17: COM_PROJ | F17: =Trans_Demand!C301 -> 2070 | G17: =SUMIFS(Trans_Demand!D:D,Trans_Demand!A:A,B17,Trans_Demand!C:C,F17) -> 51.807877
