Workbook

Sheet ReadMe
A1: Generic Comet (GC) TIMES Supply
B3: Sheet color
C4: Raw Data and Parameters
C6: City Specific Data
C8: Post processing for TIMES
C10: Table formatted for TIMES

Sheet >> City Data

Sheet City characteristics
B2: City Basic Data
B4: Calibration methodology | C4: GHG Inventory
B6: A. City Characteristics
B7: Data Item | C7: Value | D7: Units
B8: City Name | C8: New York
B9: Latitude | C9: 40.5
B10: Longitude | C10: -75
B11: County | C11: New York County
B12: State | C12: New York
B13: Census Division | C13: Middle Atlantic
B14: Climate Division | C14: Northeast
B15: Egrid Region | C15: NPCC NYC/Westchester
B16: Area of city (excluding water, natural and agricultural areas) | C16: 778 | D16: square kilometers
B17: * Division and Region Map can be found in the Maps sheet.
B18: B. Planning Base Year and Target Years
B19: Year | C19: Value | D19: Units
B20: Base Year | C20: 2019 | D20: Acceptable range [2018,2021]
B21: End Year | C21: 2050
B23: C. City Population and GDP
B24: Data Item | C24: Value | D24: Units
B25: Population in Base Year | C25: 8337 | D25: Thousand of people
B26: Annual population growth (Base Year - End Year) | C26: 0.5 | D26: % people
B27: GDP in Base Year | C27: 1206000 | D27: Million US$
B28: Annual GDP growth rate | C28: 2 | D28: % US$
B29: Share of manufacturing GDP | C29: 5 | D29: % US$
B30: Share of State population | C30: 0.42835123
B31: Share of State GDP | C31: 0.67251772
B32: Adjustment from state manufacturing GDP | C32: 1.0638298
B34: D. Climate Data
B35: Data Item | C35: 2000 | D35: 2050 | E35: 2100 | F35: Units
B36: Heating degree days (HDD) | C36: 4473.4625 | D36: 4066.4182 | E36: 3763.8582 | F36: F
B37: Cooling degree days (CDD) | C37: 1020.7333 | D37: 1224.2555 | E37: 1375.5355 | F37: F
B39: Data Item | C39: Value | D39: Units
B40: Correction from State HDD | C40: 0.72727402
B41: Correction from State CDD | C41: 1.5583715
B42: Annual precipitation | C42: 762 | D42: mm / year
B43: Climate change scenario | C43: RCP4.5
B44: Average temperature increase in 1980-2020 | C44: 1.4617857 | D44: F
B45: Forecasted average temperature increase in 2035-2065 | C45: 3.13 | D45: F
B46: Forecasted average temperature increase in 2070-2100 | C46: 4.37 | D46: F
...

Sheet >> GC_Existing

Sheet >> TIMES

Sheet TAX
C4: ~TFM_INS
C5: TimeSlice | D5: LimType | E5: Attribute | F5: Year | G5: CITY | H5: EGRID | I5: Cset_CN
C6: * | G6: k $/t CO2eq | H6: k $/t CO2eq
E7: COM_TAXNET | F7: 2019 | G7: =Data!$C4/10^3 -> 0 | H7: =Data!$C4/10^3 -> 0 | I7: CO2e
E8: COM_TAXNET | F8: 2020 | G8: =Data!$C5/10^3 -> 0 | H8: =Data!$C5/10^3 -> 0 | I8: CO2e
E9: COM_TAXNET | F9: 2021 | G9: =Data!$C6/10^3 -> 0 | H9: =Data!$C6/10^3 -> 0 | I9: CO2e
E10: COM_TAXNET | F10: 2022 | G10: =Data!$C7/10^3 -> 0 | H10: =Data!$C7/10^3 -> 0 | I10: CO2e
E11: COM_TAXNET | F11: 2023 | G11: =Data!$C8/10^3 -> 0.025 | H11: =Data!$C8/10^3 -> 0.025 | I11: CO2e
E12: COM_TAXNET | F12: 2024 | G12: =Data!$C9/10^3 -> 0.033492823 | H12: =Data!$C9/10^3 -> 0.033492823 | I12: CO2e
E13: COM_TAXNET | F13: 2025 | G13: =Data!$C10/10^3 -> 0.042011903 | H13: =Data!$C10/10^3 -> 0.042011903 | I13: CO2e
E14: COM_TAXNET | F14: 2026 | G14: =Data!$C11/10^3 -> 0.050095495 | H14: =Data!$C11/10^3 -> 0.050095495 | I14: CO2e
E15: COM_TAXNET | F15: 2027 | G15: =Data!$C12/10^3 -> 0.057759772 | H15: =Data!$C12/10^3 -> 0.057759772 | I15: CO2e
E16: COM_TAXNET | F16: 2030 | G16: =Data!$C13/10^3 -> 0.078390624 | H16: =Data!$C13/10^3 -> 0.078390624 | I16: CO2e
E17: COM_TAXNET | F17: 2032 | G17: =Data!$C14/10^3 -> 0.090321393 | H17: =Data!$C14/10^3 -> 0.090321393 | I17: CO2e
E18: COM_TAXNET | F18: 2035 | G18: =Data!$C15/10^3 -> 0.10575215 | H18: =Data!$C15/10^3 -> 0.10575215 | I18: CO2e
... E31: COM_TAXNET | F31: 2100 | G31: =Data!$C28/10^3 -> 0.11647617 | H31: =Data!$C28/10^3 -> 0.11647617 | I31: CO2e

Sheet >> Parameters

Sheet Data
B2: Carbon tax - Durbin proposal
B3: US$/t CO eq | C3: 2023 US$/t CO eq
A4: 2019 | B4: 0 | C4: =B4*SUMIFS(Inflation!$C:$C,Inflation!$A:$A,$A4) -> 0
A5: 2020 | B5: 0 | C5: =B5*SUMIFS(Inflation!$C:$C,Inflation!$A:$A,$A5) -> 0
A6: 2021 | B6: 0 | C6: =B6*SUMIFS(Inflation!$C:$C,Inflation!$A:$A,$A6) -> 0
A7: 2022 | B7: 0 | C7: =B7*SUMIFS(Inflation!$C:$C,Inflation!$A:$A,$A7) -> 0
A8: 2023 | B8: 25 | C8: =B8*SUMIFS(Inflation!$C:$C,Inflation!$A:$A,$A8) -> 25
A9: 2024 | B9: =B8+10*(A9-A8) -> 35 | C9: =B9*SUMIFS(Inflation!$C:$C,Inflation!$A:$A,$A9) -> 33.492823
A10: 2025 | B10: =B9+10*(A10-A9) -> 45 | C10: =B10*SUMIFS(Inflation!$C:$C,Inflation!$A:$A,$A10) -> 42.011903
A11: 2026 | B11: =B10+10*(A11-A10) -> 55 | C11: =B11*SUMIFS(Inflation!$C:$C,Inflation!$A:$A,$A11) -> 50.095495
A12: 2027 | B12: =B11+10*(A12-A11) -> 65 | C12: =B12*SUMIFS(Inflation!$C:$C,Inflation!$A:$A,$A12) -> 57.759772
A13: 2030 | B13: =B12+10*(A13-A12) -> 95 | C13: =B13*SUMIFS(Inflation!$C:$C,Inflation!$A:$A,$A13) -> 78.390624
A14: 2032 | B14: =B13+10*(A14-A13) -> 115 | C14: =B14*SUMIFS(Inflation!$C:$C,Inflation!$A:$A,$A14) -> 90.321393
A15: 2035 | B15: =B14+10*(A15-A14) -> 145 | C15: =B15*SUMIFS(Inflation!$C:$C,Inflation!$A:$A,$A15) -> 105.75215
A16: 2040 | B16: =B15+10*(A16-A15) -> 195 | C16: =B16*SUMIFS(Inflation!$C:$C,Inflation!$A:$A,$A16) -> 125.70035
A17: 2045 | B17: =B16+10*(A17-A16) -> 245 | C17: =B17*SUMIFS(Inflation!$C:$C,Inflation!$A:$A,$A17) -> 139.58817
A18: 2050 | B18: =B17+10*(A18-A17) -> 295 | C18: =B18*SUMIFS(Inflation!$C:$C,Inflation!$A:$A,$A18) -> 148.5543
A19: 2055 | B19: =B18+10*(A19-A18) -> 345 | C19: =B19*SUMIFS(Inflation!$C:$C,Inflation!$A:$A,$A19) -> 153.55465
A20: 2060 | B20: =B19+10*(A20-A19) -> 395 | C20: =B20*SUMIFS(Inflation!$C:$C,Inflation!$A:$A,$A20) -> 155.38949
... A28: 2100 | B28: =B27+10*(A28-A27) -> 795 | C28: =B28*SUMIFS(Inflation!$C:$C,Inflation!$A:$A,$A28) -> 116.47617

Sheet Inflation
A1: Data Source | B1: World Development Indicators
A3: Last Updated Date | B3: 45379
A6: Country Name | B6: Inflation (point) | C6: Current to 2023 US$
A7: 1960 | B7: 1.457976 | C7: =C8*(1+B7%) -> 10.03962
A8: 1961 | B8: 1.0707241 | C8: =C9*(1+B8%) -> 9.895348
A9: 1962 | B9: 1.1987733 | C9: =C10*(1+B9%) -> 9.7905185
A10: 1963 | B10: 1.2396694 | C10: =C11*(1+B10%) -> 9.6745427
A11: 1964 | B11: 1.2789116 | C11: =C12*(1+B11%) -> 9.5560789
A12: 1965 | B12: 1.5851693 | C12: =C13*(1+B12%) -> 9.4354084
A13: 1966 | B13: 3.0150754 | C13: =C14*(1+B13%) -> 9.2881751
A14: 1967 | B14: 2.7727856 | C14: =C15*(1+B14%) -> 9.0163261
A15: 1968 | B15: 4.2717962 | C15: =C16*(1+B15%) -> 8.7730677
A16: 1969 | B16: 5.4623862 | C16: =C17*(1+B16%) -> 8.4136536
A17: 1970 | B17: 5.8382553 | C17: =C18*(1+B17%) -> 7.9778714
A18: 1971 | B18: 4.2927667 | C18: =C19*(1+B18%) -> 7.5377957
... A69: 2022 | B69: 8.0027998 | C69: =C70*(1+B69%) -> 1.080028
A70: 2023 | B70: 4.5 | C70: =1 -> 1
A71: 2024 | B71: 2.5 | C71: =C70/(1+B70%) -> 0.9569378
A72: 2025 | B72: 2.5 | C72: =C71/(1+B71%) -> 0.93359785
A73: 2026 | B73: 2.5 | C73: =C72/(1+B72%) -> 0.91082717
A74: 2027 | B74: 2.5 | C74: =C73/(1+B73%) -> 0.88861188
A75: 2028 | B75: 2.5 | C75: =C74/(1+B74%) -> 0.86693842
A76: 2029 | B76: 2.5 | C76: =C75/(1+B75%) -> 0.84579358
A77: 2030 | B77: 2.5 | C77: =C76/(1+B76%) -> 0.82516447
A78: 2031 | B78: 2.5 | C78: =C77/(1+B77%) -> 0.8050385
A79: 2032 | B79: 2.5 | C79: =C78/(1+B78%) -> 0.78540342
A80: 2033 | B80: 2.5 | C80: =C79/(1+B79%) -> 0.76624724
A81: 2034 | B81: 2.5 | C81: =C80/(1+B80%) -> 0.74755828
A82: 2035 | B82: 2.5 | C82: =C81/(1+B81%) -> 0.72932515
... A147: 2100 | B147: 2.5 | C147: =C146/(1+B146%) -> 0.1465109
