Workbook

Sheet ReadMe
A1: Generic Comet (GC) TIMES Supply
B3: Sheet color
C4: Raw Data and Parameters
C6: City Specific Data
C8: Post processing for TIMES
C10: Table formatted for TIMES

Sheet >> City Data

Sheet City characteristics
B2: City Basic Data
B4: Calibration methodology | C4: GHG Inventory
B6: A. City Characteristics
B7: Data Item | C7: Value | D7: Units
B8: City Name | C8: New York
B9: Latitude | C9: 40.5
B10: Longitude | C10: -75
B11: County | C11: New York County
B12: State | C12: New York
B13: Census Division | C13: Middle Atlantic
B14: Climate Division | C14: Northeast
B15: Egrid Region | C15: NPCC NYC/Westchester
B16: Area of city (excluding water, natural and agricultural areas) | C16: 778 | D16: square kilometers
B17: * Division and Region Map can be found in the Maps sheet.
B18: B. Planning Base Year and Target Years
B19: Year | C19: Value | D19: Units
B20: Base Year | C20: 2019 | D20: Acceptable range [2018,2021]
B21: End Year | C21: 2050
B23: C. City Population and GDP
B24: Data Item | C24: Value | D24: Units
B25: Population in Base Year | C25: 8337 | D25: Thousand of people
B26: Annual population growth (Base Year - End Year) | C26: 0.5 | D26: % people
B27: GDP in Base Year | C27: 1206000 | D27: Million US$
B28: Annual GDP growth rate | C28: 2 | D28: % US$
B29: Share of manufacturing GDP | C29: 5 | D29: % US$
B30: Share of State population | C30: 0.42835123
B31: Share of State GDP | C31: 0.67251772
B32: Adjustment from state manufacturing GDP | C32: 1.0638298
B34: D. Climate Data
B35: Data Item | C35: 2000 | D35: 2050 | E35: 2100 | F35: Units
B36: Heating degree days (HDD) | C36: 4473.4625 | D36: 4066.4182 | E36: 3763.8582 | F36: F
B37: Cooling degree days (CDD) | C37: 1020.7333 | D37: 1224.2555 | E37: 1375.5355 | F37: F
B39: Data Item | C39: Value | D39: Units
B40: Correction from State HDD | C40: 0.72727402
B41: Correction from State CDD | C41: 1.5583715
B42: Annual precipitation | C42: 762 | D42: mm / year
B43: Climate change scenario | C43: RCP4.5
B44: Average temperature increase in 1980-2020 | C44: 1.4617857 | D44: F
B45: Forecasted average temperature increase in 2035-2065 | C45: 3.13 | D45: F
B46: Forecasted average temperature increase in 2070-2100 | C46: 4.37 | D46: F
...

Sheet >> GC_Existing

Sheet >> TIMES

Sheet UC
C4: ~UC_Sets: R_S: CITY
E6: ~UC_T: UC_RHST
C7: UC_N | D7: Cset_CN | E7: Year | F7: UC_COMNET | G7: UC_RHST~UP | H7: UC_RHST~UP~0
C8: UC_GHGCO2_CITY | D8: CO2 | E8: 2025 | F8: 1 | G8: ='Pre-processing'!$D$15 -> 13916464 | H8: 15
D9: CO2 | E9: 2030 | F9: 1 | G9: ='Pre-processing'!$D$17 -> 11303689
D10: CO2 | E10: 2035 | F10: 1 | G10: ='Pre-processing'!$D$18 -> 10258579
D11: CO2 | E11: 2040 | F11: 1 | G11: ='Pre-processing'!$D$19 -> 8690914.5
D12: CO2 | E12: 2045 | F12: 1 | G12: ='Pre-processing'!$D$20 -> 6078139.6
D13: CO2 | E13: 2050 | F13: 1 | G13: ='Pre-processing'!$D$21 -> 3465364.7
D14: CO2 | E14: 2055 | F14: 1 | G14: ='Pre-processing'!$D$22 -> 852589.72
D15: CO2 | E15: 2060 | F15: 1 | G15: ='Pre-processing'!$D$23 -> 852589.72
D16: CO2 | E16: 2065 | F16: 1 | G16: ='Pre-processing'!$D$24 -> 852589.72
D17: CO2 | E17: 2070 | F17: 1 | G17: ='Pre-processing'!$D$25 -> 852589.72
D18: CO2 | E18: 2075 | F18: 1 | G18: ='Pre-processing'!$D$26 -> 852589.72
D19: CO2 | E19: 2080 | F19: 1 | G19: ='Pre-processing'!$D$27 -> 852589.72
D20: CO2 | E20: 2085 | F20: 1 | G20: ='Pre-processing'!$D$28 -> 852589.72
D21: CO2 | E21: 2090 | F21: 1 | G21: ='Pre-processing'!$D$29 -> 852589.72
D22: CO2 | E22: 2095 | F22: 1 | G22: ='Pre-processing'!$D$30 -> 852589.72
D23: CO2 | E23: 2100 | F23: 1 | G23: ='Pre-processing'!$D$31 -> 852589.72
C28: ~UC_Sets: R_S: EGRID
E30: ~UC_T: UC_RHST
C31: UC_N | D31: Cset_CN | E31: Year | F31: UC_COMNET | G31: UC_RHST~UP | H31: UC_RHST~UP~0
C32: UC_GHGCO2_EGRID | D32: CO2 | E32: 2025 | F32: 1 | G32: ='Pre-processing'!$F$15 -> 1.1438441e+08 | H32: 15
D33: CO2 | E33: 2030 | F33: 1 | G33: ='Pre-processing'!$F$17 -> 92909077
D34: CO2 | E34: 2035 | F34: 1 | G34: ='Pre-processing'!$F$18 -> 84318943
D35: CO2 | E35: 2040 | F35: 1 | G35: ='Pre-processing'!$F$19 -> 71433743
D36: CO2 | E36: 2045 | F36: 1 | G36: ='Pre-processing'!$F$20 -> 49958409
D37: CO2 | E37: 2050 | F37: 1 | G37: ='Pre-processing'!$F$21 -> 28483075
D38: CO2 | E38: 2055 | F38: 1 | G38: ='Pre-processing'!$F$22 -> 7007740.6
D39: CO2 | E39: 2060 | F39: 1 | G39: ='Pre-processing'!$F$23 -> 7007740.6
D40: CO2 | E40: 2065 | F40: 1 | G40: ='Pre-processing'!$F$24 -> 7007740.6
D41: CO2 | E41: 2070 | F41: 1 | G41: ='Pre-processing'!$F$25 -> 7007740.6
D42: CO2 | E42: 2075 | F42: 1 | G42: ='Pre-processing'!$F$26 -> 7007740.6
D43: CO2 | E43: 2080 | F43: 1 | G43: ='Pre-processing'!$F$27 -> 7007740.6
D44: CO2 | E44: 2085 | F44: 1 | G44: ='Pre-processing'!$F$28 -> 7007740.6
D45: CO2 | E45: 2090 | F45: 1 | G45: ='Pre-processing'!$F$29 -> 7007740.6
D46: CO2 | E46: 2095 | F46: 1 | G46: ='Pre-processing'!$F$30 -> 7007740.6
D47: CO2 | E47: 2100 | F47: 1 | G47: ='Pre-processing'!$F$31 -> 7007740.6

Sheet >> Parameters

Sheet REF_data
A1: Table = _Emissions_for_GHG_constraint
A4: Sum of Pv | C4: Period
A5: Commodity | B5: Region | C5: 2019 | D5: 2020 | E5: 2021 | F5: 2022 | G5: 2023 | H5: 2024 | I5: 2025 | J5: 2027 | K5: 2030 | L5: 2032 | M5: 2035 | N5: 2040 | O5: 2045 | P5: 2050 | Q5: 2055 | R5: 2060 | S5: 2065 | T5: 2070 | U5: 2075 | V5: 2080 | W5: 2085 | X5: 2090 | Y5: 2095 | Z5: 2100
A6: CO2 | B6: CITY | C6: 17051794 | D6: 17411913 | E6: 17042314 | F6: 16738951 | G6: 16467807 | H6: 16169641 | I6: 15909010 | J6: 15481949 | K6: 14551152 | L6: 14083056 | M6: 13838793 | N6: 13330953 | O6: 13335442 | P6: 13363578 | Q6: 13122308 | R6: 13186984 | S6: 13434599 | T6: 13688958 | U6: 13945373 | V6: 14203176 | W6: 14462561 | X6: 14723407 | Y6: 14988271 | Z6: 15256424
A7: CO2 | B7: EGRID | C7: 1.4015481e+08 | D7: 1.1679105e+08 | E7: 1.1207702e+08 | F7: 1.0731871e+08 | G7: 1.0268916e+08 | H7: 98021451 | I7: 93480479 | J7: 86474338 | K7: 75821480 | L7: 71157764 | M7: 63660712 | N7: 65309850 | O7: 63123238 | P7: 59738128 | Q7: 61105985 | R7: 45114583 | S7: 24614500 | T7: 8473768.2 | U7: 8542059.4 | V7: 8555461.2 | W7: 8565567.3 | X7: 8677311.3 | Y7: 8714429.2 | Z7: 8727202.8
A8: GrandTotal | B8: GrandTotal | C8: 1.5720661e+08 | D8: 1.3420296e+08 | E8: 1.2911933e+08 | F8: 1.2405766e+08 | G8: 1.1915697e+08 | H8: 1.1419109e+08 | I8: 1.0938949e+08 | J8: 1.0195629e+08 | K8: 90372632 | L8: 85240820 | M8: 77499505 | N8: 78640803 | O8: 76458681 | P8: 73101707 | Q8: 74228293 | R8: 58301567 | S8: 38049099 | T8: 22162726 | U8: 22487432 | V8: 22758638 | W8: 23028128 | X8: 23400718 | Y8: 23702700 | Z8: 23983627
A15: New York
A16: Sum of Pv | C16: Period
A17: Commodity | B17: Region | C17: 2019 | D17: 2020 | E17: 2021 | F17: 2022 | G17: 2023 | H17: 2024 | I17: 2025 | J17: 2027 | K17: 2030 | L17: 2032 | M17: 2035 | N17: 2040 | O17: 2045 | P17: 2050 | Q17: 2055 | R17: 2060 | S17: 2065 | T17: 2070 | U17: 2075 | V17: 2080 | W17: 2085 | X17: 2090 | Y17: 2095 | Z17: 2100
A18: CO2 | B18: EGRID | C18: 38627279 | D18: 41546699 | E18: 40934895 | F18: 40417389 | G18: 39925914 | H18: 39497230 | I18: 39117291 | J18: 38194832 | K18: 36194520 | L18: 35380259 | M18: 34993775 | N18: 32349669 | O18: 28704114 | P18: 27324792 | Q18: 27456074 | R18: 27959420 | S18: 28476331 | T18: 28999490 | U18: 29491504 | V18: 30050874 | W18: 30579354 | X18: 31103124 | Y18: 31641981 | Z18: 32176545
A19: CO2 | B19: CITY | C19: 11434915 | D19: 7535855.8 | E19: 8027883.4 | F19: 7560538.3 | G19: 7013467.8 | H19: 6513435.7 | I19: 6440342.5 | J19: 5858894.5 | K19: 5633948 | L19: 5461669.4 | M19: 3888295.2 | N19: 6056346.1 | O19: 9277221.7 | P19: 8062247 | Q19: 7179450.9 | R19: 7322101.3 | S19: 7395879.5 | T19: 7710440.4 | U19: 7766026.4 | V19: 8082155.4 | W19: 8407882.6 | X19: 8737543.8 | Y19: 9070452.1 | Z19: 9414203.6
A20: CO2 | B20: CO2 Total | C20: 50062194 | D20: 49082555 | E20: 48962779 | F20: 47977928 | G20: 46939382 | H20: 46010666 | I20: 45557633 | J20: 44053726 | K20: 41828468 | L20: 40841928 | M20: 38882070 | N20: 38406015 | O20: 37981336 | P20: 35387039 | Q20: 34635524 | R20: 35281522 | S20: 35872210 | T20: 36709930 | U20: 37257530 | V20: 38133029 | W20: 38987236 | X20: 39840668 | Y20: 40712433 | Z20: 41590749

Sheet Pre-processing
C1: REF - CO2 | D1: NZ50 - CO2 | E1: REF - CO2 | F1: NZ50 - CO2
C2: CITY | D2: CITY | E2: EGRID | F2: EGRID
A3: Target | B3: 2030
A4: Target | B4: 2040
A5: Target | B5: 2050 | D5: 0.95 | F5: 0.95
A6: Target | B6: 2060
A7: Ref | B7: 1990
A8: Ref | B8: 2005
B9: 2019 | C9: =REF_data!$C6 -> 17051794 | D9: =C9 -> 17051794 | E9: =REF_data!$C7 -> 1.4015481e+08 | F9: =E9 -> 1.4015481e+08
B10: 2020 | C10: =REF_data!$D6 -> 17411913 | D10: =(D$22-D$9)/($B$22-$B$9)*($B10-$B$9)+D$9 -> 16529239 | E10: =REF_data!$D7 -> 1.1679105e+08 | F10: =(F$22-F$9)/($B$22-$B$9)*($B10-$B$9)+F$9 -> 1.3585975e+08
B11: 2021 | C11: =REF_data!$E6 -> 17042314 | D11: =(D$22-D$9)/($B$22-$B$9)*($B11-$B$9)+D$9 -> 16006684 | E11: =REF_data!$E7 -> 1.1207702e+08 | F11: =(F$22-F$9)/($B$22-$B$9)*($B11-$B$9)+F$9 -> 1.3156468e+08
B12: 2022 | C12: =REF_data!$F6 -> 16738951 | D12: =(D$22-D$9)/($B$22-$B$9)*($B12-$B$9)+D$9 -> 15484129 | E12: =REF_data!$F7 -> 1.0731871e+08 | F12: =(F$22-F$9)/($B$22-$B$9)*($B12-$B$9)+F$9 -> 1.2726961e+08
B13: 2023 | C13: =REF_data!$G6 -> 16467807 | D13: =(D$22-D$9)/($B$22-$B$9)*($B13-$B$9)+D$9 -> 14961574 | E13: =REF_data!$G7 -> 1.0268916e+08 | F13: =(F$22-F$9)/($B$22-$B$9)*($B13-$B$9)+F$9 -> 1.2297454e+08
B14: 2024 | C14: =REF_data!$H6 -> 16169641 | D14: =(D$22-D$9)/($B$22-$B$9)*($B14-$B$9)+D$9 -> 14439019 | E14: =REF_data!$H7 -> 98021451 | F14: =(F$22-F$9)/($B$22-$B$9)*($B14-$B$9)+F$9 -> 1.1867948e+08
B15: 2025 | C15: =REF_data!$I6 -> 15909010 | D15: =(D$22-D$9)/($B$22-$B$9)*($B15-$B$9)+D$9 -> 13916464 | E15: =REF_data!$I7 -> 93480479 | F15: =(F$22-F$9)/($B$22-$B$9)*($B15-$B$9)+F$9 -> 1.1438441e+08
B16: 2027 | C16: =REF_data!$J6 -> 15481949 | D16: =(D$22-D$9)/($B$22-$B$9)*($B16-$B$9)+D$9 -> 12871354 | E16: =REF_data!$J7 -> 86474338 | F16: =(F$22-F$9)/($B$22-$B$9)*($B16-$B$9)+F$9 -> 1.0579428e+08
B17: 2030 | C17: =REF_data!$K6 -> 14551152 | D17: =(D$22-D$9)/($B$22-$B$9)*($B17-$B$9)+D$9 -> 11303689 | E17: =REF_data!$K7 -> 75821480 | F17: =(F$22-F$9)/($B$22-$B$9)*($B17-$B$9)+F$9 -> 92909077
B18: 2032 | C18: =REF_data!$L6 -> 14083056 | D18: =(D$22-D$9)/($B$22-$B$9)*($B18-$B$9)+D$9 -> 10258579 | E18: =REF_data!$L7 -> 71157764 | F18: =(F$22-F$9)/($B$22-$B$9)*($B18-$B$9)+F$9 -> 84318943
B19: 2035 | C19: =REF_data!$M6 -> 13838793 | D19: =(D$22-D$9)/($B$22-$B$9)*($B19-$B$9)+D$9 -> 8690914.5 | E19: =REF_data!$M7 -> 63660712 | F19: =(F$22-F$9)/($B$22-$B$9)*($B19-$B$9)+F$9 -> 71433743
B20: 2040 | C20: =REF_data!$N6 -> 13330953 | D20: =(D$22-D$9)/($B$22-$B$9)*($B20-$B$9)+D$9 -> 6078139.6 | E20: =REF_data!$N7 -> 65309850 | F20: =(F$22-F$9)/($B$22-$B$9)*($B20-$B$9)+F$9 -> 49958409
B21: 2045 | C21: =REF_data!$O6 -> 13335442 | D21: =(D$22-D$9)/($B$22-$B$9)*($B21-$B$9)+D$9 -> 3465364.7 | E21: =REF_data!$O7 -> 63123238 | F21: =(F$22-F$9)/($B$22-$B$9)*($B21-$B$9)+F$9 -> 28483075
B22: 2050 | C22: =REF_data!$P6 -> 13363578 | D22: =D9*(1-D5) -> 852589.72 | E22: =REF_data!$P7 -> 59738128 | F22: =F9*(1-F5) -> 7007740.6
B23: 2055 | C23: =REF_data!$Q6 -> 13122308 | D23: =D22 -> 852589.72 | E23: =REF_data!$Q7 -> 61105985 | F23: =F22 -> 7007740.6
B24: 2060 | C24: =REF_data!$R6 -> 13186984 | D24: =D23 -> 852589.72 | E24: =REF_data!$R7 -> 45114583 | F24: =F23 -> 7007740.6
B25: 2065 | C25: =REF_data!$S6 -> 13434599 | D25: =D24 -> 852589.72 | E25: =REF_data!$S7 -> 24614500 | F25: =F24 -> 7007740.6
B26: 2070 | C26: =REF_data!$T6 -> 13688958 | D26: =D25 -> 852589.72 | E26: =REF_data!$T7 -> 8473768.2 | F26: =F25 -> 7007740.6
B27: 2075 | C27: =REF_data!$U6 -> 13945373 | D27: =D26 -> 852589.72 | E27: =REF_data!$U7 -> 8542059.4 | F27: =F26 -> 7007740.6
B28: 2080 | C28: =REF_data!$V6 -> 14203176 | D28: =D27 -> 852589.72 | E28: =REF_data!$V7 -> 8555461.2 | F28: =F27 -> 7007740.6
B29: 2085 | C29: =REF_data!$W6 -> 14462561 | D29: =D28 -> 852589.72 | E29: =REF_data!$W7 -> 8565567.3 | F29: =F28 -> 7007740.6
B30: 2090 | C30: =REF_data!$X6 -> 14723407 | D30: =D29 -> 852589.72 | E30: =REF_data!$X7 -> 8677311.3 | F30: =F29 -> 7007740.6
B31: 2095 | C31: =REF_data!$Y6 -> 14988271 | D31: =D30 -> 852589.72 | E31: =REF_data!$Y7 -> 8714429.2 | F31: =F30 -> 7007740.6
B32: 2100 | C32: =REF_data!$Z6 -> 15256424 | D32: =D31 -> 852589.72 | E32: =REF_data!$Z7 -> 8727202.8 | F32: =F31 -> 7007740.6
