Workbook

Sheet ReadMe
A1: Generic Comet (GC) TIMES Supply
B3: Sheet color
C4: Raw Data and Parameters
C6: City Specific Data
C8: Post processing for TIMES
C10: Table formatted for TIMES

Sheet >> City Data

Sheet City characteristics
B2: City Basic Data
B4: Calibration methodology | C4: GHG Inventory
B6: A. City Characteristics
B7: Data Item | C7: Value | D7: Units
B8: City Name | C8: New York
B9: Latitude | C9: 40.5
B10: Longitude | C10: -75
B11: County | C11: New York County
B12: State | C12: New York
B13: Census Division | C13: Middle Atlantic
B14: Climate Division | C14: Northeast
B15: Egrid Region | C15: NPCC NYC/Westchester
B16: Area of city (excluding water, natural and agricultural areas) | C16: 778 | D16: square kilometers
B17: * Division and Region Map can be found in the Maps sheet.
B18: B. Planning Base Year and Target Years
B19: Year | C19: Value | D19: Units
B20: Base Year | C20: 2019 | D20: Acceptable range [2018,2021]
B21: End Year | C21: 2050
B23: C. City Population and GDP
B24: Data Item | C24: Value | D24: Units
B25: Population in Base Year | C25: 8337 | D25: Thousand of people
B26: Annual population growth (Base Year - End Year) | C26: 0.5 | D26: % people
B27: GDP in Base Year | C27: 1206000 | D27: Million US$
B28: Annual GDP growth rate | C28: 2 | D28: % US$
B29: Share of manufacturing GDP | C29: 5 | D29: % US$
B30: Share of State population | C30: 0.42835123
B31: Share of State GDP | C31: 0.67251772
B32: Adjustment from state manufacturing GDP | C32: 1.0638298
B34: D. Climate Data
B35: Data Item | C35: 2000 | D35: 2050 | E35: 2100 | F35: Units
B36: Heating degree days (HDD) | C36: 4473.4625 | D36: 4066.4182 | E36: 3763.8582 | F36: F
B37: Cooling degree days (CDD) | C37: 1020.7333 | D37: 1224.2555 | E37: 1375.5355 | F37: F
B39: Data Item | C39: Value | D39: Units
B40: Correction from State HDD | C40: 0.72727402
B41: Correction from State CDD | C41: 1.5583715
B42: Annual precipitation | C42: 762 | D42: mm / year
B43: Climate change scenario | C43: RCP4.5
B44: Average temperature increase in 1980-2020 | C44: 1.4617857 | D44: F
B45: Forecasted average temperature increase in 2035-2065 | C45: 3.13 | D45: F
B46: Forecasted average temperature increase in 2070-2100 | C46: 4.37 | D46: F
...

Sheet >> GC_NewTech

Sheet TRA TECH
Q1: 2020 | R1: 2025 | S1: 2030 | T1: 2035 | U1: 2040 | V1: 2045 | W1: 2050 | X1: 2020 | Y1: 2025 | Z1: 2030 | AA1: 2035 | AB1: 2040 | AC1: 2045 | AD1: 2050 | AE1: 2020 | AF1: 2025 | AG1: 2030 | AH1: 2035 | AI1: 2040 | AJ1: 2045 | AK1: 2050
A2: Sector | B2: Sub-sector | C2: Archetype | D2: Vintage | E2: End Use | F2: Technology | G2: Energy | H2: Input Label | I2: Output Label | J2: Technology Label | K2: Capacity Unit | L2: Main fuel | M2: To include | N2: First year of availability | O2: Lifetime (yr) | P2: MAX FUEL SHARE (%) | Q2: EFF (Vkm/MJ) | X2: CAPEX (Thousands US$ 2023 / Mvkm) | AE2: Fixed OPEX (Thousands US$ 2023 / Mvkm)
A3: Transportation | B3: Passenger | C3: Passenger Car | F3: Gasoline ICE Vehicle (spark ignition) | G3: Gasoline | H3: TRAGSL | I3: TRAPASCARDMD | J3: TRAPASCARICEVGSL20 | K3: Mvkm | L3: 1 | M3: 1 | N3: 2020 | O3: 16.861274 | P3: 1 | Q3: 0.37474421 | R3: 0.3694381 | S3: 0.42979513 | T3: 0.46959098 | U3: 0.49413175 | V3: 0.51800926 | W3: 0.54255003 | X3: 149.37153 | Y3: 151.86106 | Z3: 152.21671 | AA3: 163.95304 | AB3: 162.17481 | AC3: 160.04093 | AD3: 157.90705 | AE3: 5.2309413 | AF3: 5.2309413 | AG3: 5.2309413 | AH3: 5.2309413 | AI3: 5.2309413 | AJ3: 5.2309413 | AK3: 5.2309413
A4: Transportation | B4: Passenger | C4: Passenger Car | F4: Gasoline ICE Vehicle (spark ignition) | G4: Ethanol | H4: TRAETH | I4: TRAPASCARDMD | J4: TRAPASCARICEVGSL20 | K4: Mvkm | L4: 0 | M4: 1 | N4: 2020 | O4: 16.861274 | P4: 0.1 | Q4: 0.37474421 | R4: 0.3694381 | S4: 0.42979513 | T4: 0.46959098 | U4: 0.49413175 | V4: 0.51800926 | W4: 0.54255003 | X4: 149.37153 | Y4: 151.86106 | Z4: 152.21671 | AA4: 163.95304 | AB4: 162.17481 | AC4: 160.04093 | AD4: 157.90705 | AE4: 5.2309413 | AF4: 5.2309413 | AG4: 5.2309413 | AH4: 5.2309413 | AI4: 5.2309413 | AJ4: 5.2309413 | AK4: 5.2309413
A5: Transportation | B5: Passenger | C5: Passenger Car | F5: Gasoline ICE Vehicle (spark ignition with turbo) | G5: Gasoline | H5: TRAGSL | I5: TRAPASCARDMD | J5: TRAPASCARICEVTGSL20 | K5: Mvkm | L5: 1 | M5: 1 | N5: 2020 | O5: 16.861274 | P5: 1 | Q5: 0.41785638 | R5: 0.41586659 | S5: 0.46627466 | T5: 0.50540724 | U5: 0.53326433 | V5: 0.56112142 | W5: 0.59030504 | X5: 157.19576 | Y5: 156.12882 | Z5: 159.32964 | AA5: 165.73127 | AB5: 165.37563 | AC5: 165.01998 | AD5: 164.66433 | AE5: 5.2309413 | AF5: 5.2309413 | AG5: 5.2309413 | AH5: 5.2309413 | AI5: 5.2309413 | AJ5: 5.2309413 | AK5: 5.2309413
A6: Transportation | B6: Passenger | C6: Passenger Car | F6: Gasoline ICE Vehicle (spark ignition with turbo) | G6: Ethanol | H6: TRAETH | I6: TRAPASCARDMD | J6: TRAPASCARICEVTGSL20 | K6: Mvkm | L6: 0 | M6: 1 | N6: 2020 | O6: 16.861274 | P6: 0.1 | Q6: 0.41785638 | R6: 0.41586659 | S6: 0.46627466 | T6: 0.50540724 | U6: 0.53326433 | V6: 0.56112142 | W6: 0.59030504 | X6: 157.19576 | Y6: 156.12882 | Z6: 159.32964 | AA6: 165.73127 | AB6: 165.37563 | AC6: 165.01998 | AD6: 164.66433 | AE6: 5.2309413 | AF6: 5.2309413 | AG6: 5.2309413 | AH6: 5.2309413 | AI6: 5.2309413 | AJ6: 5.2309413 | AK6: 5.2309413
A7: Transportation | B7: Passenger | C7: Passenger Car | F7: Gasoline Micro Hybrid Electric Vehicle (spark ignition) | G7: Gasoline | H7: TRAGSL | I7: TRAPASCARDMD | J7: TRAPASCARHEVGSL20 | K7: Mvkm | L7: 1 | M7: 1 | N7: 2020 | O7: 16.861274 | P7: 1 | Q7: 0.38469318 | R7: 0.37938706 | S7: 0.44173389 | T7: 0.48351953 | U7: 0.5080603 | V7: 0.53326433 | W7: 0.55846837 | X7: 150.79412 | Y7: 153.28364 | Z7: 153.63929 | AA7: 165.01998 | AB7: 162.8861 | AC7: 161.10787 | AD7: 158.97399 | AE7: 4.9356462 | AF7: 4.9356462 | AG7: 4.9356462 | AH7: 4.9356462 | AI7: 4.9356462 | AJ7: 4.9356462 | AK7: 4.9356462
A8: Transportation | B8: Passenger | C8: Passenger Car | F8: Gasoline Micro Hybrid Electric Vehicle (spark ignition) | G8: Ethanol | H8: TRAETH | I8: TRAPASCARDMD | J8: TRAPASCARHEVGSL20 | K8: Mvkm | L8: 0 | M8: 1 | N8: 2020 | O8: 16.861274 | P8: 0.1 | Q8: 0.38469318 | R8: 0.37938706 | S8: 0.44173389 | T8: 0.48351953 | U8: 0.5080603 | V8: 0.53326433 | W8: 0.55846837 | X8: 150.79412 | Y8: 153.28364 | Z8: 153.63929 | AA8: 165.01998 | AB8: 162.8861 | AC8: 161.10787 | AD8: 158.97399 | AE8: 4.9356462 | AF8: 4.9356462 | AG8: 4.9356462 | AH8: 4.9356462 | AI8: 4.9356462 | AJ8: 4.9356462 | AK8: 4.9356462
A9: Transportation | B9: Passenger | C9: Passenger Car | F9: Gasoline Micro Hybrid Electric Vehicle (spark ignition with turbo) | G9: Gasoline | H9: TRAGSL | I9: TRAPASCARDMD | J9: TRAPASCARHEVTGSL20 | K9: Mvkm | L9: 1 | M9: 1 | N9: 2020 | O9: 16.861274 | P9: 1 | Q9: 0.42515228 | R9: 0.42249923 | S9: 0.47489709 | T9: 0.51601947 | U9: 0.54453982 | V9: 0.57306018 | W9: 0.6022438 | X9: 158.97399 | Y9: 157.5514 | Z9: 160.39657 | AA9: 166.79821 | AB9: 166.44257 | AC9: 166.08692 | AD9: 165.73127 | AE9: 4.9356462 | AF9: 4.9356462 | AG9: 4.9356462 | AH9: 4.9356462 | AI9: 4.9356462 | AJ9: 4.9356462 | AK9: 4.9356462
A10: Transportation | B10: Passenger | C10: Passenger Car | F10: Gasoline Micro Hybrid Electric Vehicle (spark ignition with turbo) | G10: Ethanol | H10: TRAETH | I10: TRAPASCARDMD | J10: TRAPASCARHEVTGSL20 | K10: Mvkm | L10: 0 | M10: 1 | N10: 2020 | O10: 16.861274 | P10: 0.1 | Q10: 0.42515228 | R10: 0.42249923 | S10: 0.47489709 | T10: 0.51601947 | U10: 0.54453982 | V10: 0.57306018 | W10: 0.6022438 | X10: 158.97399 | Y10: 157.5514 | Z10: 160.39657 | AA10: 166.79821 | AB10: 166.44257 | AC10: 166.08692 | AD10: 165.73127 | AE10: 4.9356462 | AF10: 4.9356462 | AG10: 4.9356462 | AH10: 4.9356462 | AI10: 4.9356462 | AJ10: 4.9356462 | AK10: 4.9356462
A11: Transportation | B11: Passenger | C11: Passenger Car | F11: Gasoline Mild Hybrid Electric Vehicle (belt-driven integrated starter generator with spark ignition) | G11: Gasoline | H11: TRAGSL | I11: TRAPASCARDMD | J11: TRAPASCARHEVIGSL20 | K11: Mvkm | L11: 1 | M11: 1 | N11: 2020 | O11: 16.861274 | P11: 1 | Q11: 0.3953054 | R11: 0.38933602 | S11: 0.45433591 | T11: 0.49612154 | U11: 0.52397864 | V11: 0.55117246 | W11: 0.57969282 | X11: 155.06188 | Y11: 156.84011 | Z11: 156.48446 | AA11: 167.5095 | AB11: 165.01998 | AC11: 163.24175 | AD11: 160.75222 | AE11: 4.9356462 | AF11: 4.9356462 | AG11: 4.9356462 | AH11: 4.9356462 | AI11: 4.9356462 | AJ11: 4.9356462 | AK11: 4.9356462
A12: Transportation | B12: Passenger | C12: Passenger Car | F12: Gasoline Mild Hybrid Electric Vehicle (belt-driven integrated starter generator with spark ignition) | G12: Ethanol | H12: TRAETH | I12: TRAPASCARDMD | J12: TRAPASCARHEVIGSL20 | K12: Mvkm | L12: 0 | M12: 1 | N12: 2020 | O12: 16.861274 | P12: 0.1 | Q12: 0.3953054 | R12: 0.38933602 | S12: 0.45433591 | T12: 0.49612154 | U12: 0.52397864 | V12: 0.55117246 | W12: 0.57969282 | X12: 155.06188 | Y12: 156.84011 | Z12: 156.48446 | AA12: 167.5095 | AB12: 165.01998 | AC12: 163.24175 | AD12: 160.75222 | AE12: 4.9356462 | AF12: 4.9356462 | AG12: 4.9356462 | AH12: 4.9356462 | AI12: 4.9356462 | AJ12: 4.9356462 | AK12: 4.9356462
A13: Transportation | B13: Passenger | C13: Passenger Car | F13: Gasoline Mild Hybrid Electric Vehicle (belt-driven integrated starter generator with spark ignition and turbo) | G13: Gasoline | H13: TRAGSL | I13: TRAPASCARDMD | J13: TRAPASCARHEVIGSL20 | K13: Mvkm | L13: 0 | M13: 1 | N13: 2020 | O13: 16.861274 | P13: 1 | Q13: 0.44505021 | R13: 0.44040736 | S13: 0.49744807 | T13: 0.53989697 | U13: 0.57173365 | V13: 0.60423359 | W13: 0.63607027 | X13: 162.8861 | Y13: 160.75222 | Z13: 163.24175 | AA13: 169.28774 | AB13: 168.57644 | AC13: 167.86515 | AD13: 167.15386 | AE13: 4.9356462 | AF13: 4.9356462 | AG13: 4.9356462 | AH13: 4.9356462 | AI13: 4.9356462 | AJ13: 4.9356462 | AK13: 4.9356462
A14: Transportation | B14: Passenger | C14: Passenger Car | F14: Gasoline Mild Hybrid Electric Vehicle (belt-driven integrated starter generator with spark ignition and turbo) | G14: Ethanol | H14: TRAETH | I14: TRAPASCARDMD | J14: TRAPASCARHEVIGSL20 | K14: Mvkm | L14: 0 | M14: 1 | N14: 2020 | O14: 16.861274 | P14: 0.1 | Q14: 0.44505021 | R14: 0.44040736 | S14: 0.49744807 | T14: 0.53989697 | U14: 0.57173365 | V14: 0.60423359 | W14: 0.63607027 | X14: 162.8861 | Y14: 160.75222 | Z14: 163.24175 | AA14: 169.28774 | AB14: 168.57644 | AC14: 167.86515 | AD14: 167.15386 | AE14: 4.9356462 | AF14: 4.9356462 | AG14: 4.9356462 | AH14: 4.9356462 | AI14: 4.9356462 | AJ14: 4.9356462 | AK14: 4.9356462
... A279: Transportation | B279: Other | C279: Off-Road | F279: Battery Electric Vehicle | G279: Battery Freight | H279: TRABAF | I279: TRAOTHOFRDMD | J279: TRAOTHOFRBEV20 | K279: Mvkm | L279: 1 | M279: 1 | N279: 2020 | O279: 8 | P279: 1 | Q279: 0.36877484 | R279: 0.36877484 | S279: 0.40061151 | T279: 0.43510125 | U279: 0.44969306 | V279: 0.46428487 | W279: 0.48152973 | X279: 508.57451 | Y279: 508.57451 | Z279: 462.34046 | AA279: 437.4452 | AB279: 426.06452 | AC279: 414.68383 | AD279: 403.30314 | AE279: 6.7572836 | AF279: 6.7572836 | AG279: 6.7572836 | AH279: 6.7572836 | AI279: 6.7572836 | AJ279: 6.7572836 | AK279: 6.7572836
A280: Transportation | B280: Passenger | C280: Bicycle | F280: N/a | G280: N/a | H280: TRA | I280: TRAPASBICDMD | J280: TRAPASBIC20 | K280: Mvkm | L280: 1 | M280: 1 | N280: 2020 | P280: 0
A281: Transportation | B281: Passenger | C281: Walk | F281: N/a | G281: N/a | H281: TRA | I281: TRAPASWALDMD | J281: TRAPASWAL20 | K281: Mvkm | L281: 1 | M281: 1 | N281: 2020 | P281: 0
A282: Transportation | B282: Passenger | C282: Rail | F282: Diesel ICE Vehicle | G282: Diesel | H282: TRADSL | I282: TRAPASRAIDMD | J282: TRAPASRAIICEVDSL20 | K282: Mvkm | L282: 1 | M282: 1 | N282: 2020 | O282: 30 | P282: 1 | Q282: 0.040874687 | R282: 0.040874687 | S282: 0.040874687 | T282: 0.040874687 | U282: 0.040874687 | V282: 0.040874687 | W282: 0.040874687 | X282: 35064.744 | Y282: 35064.744 | Z282: 35064.744 | AA282: 35064.744 | AB282: 35064.744 | AC282: 35064.744 | AD282: 35064.744 | AE282: 3506.4744 | AF282: 3506.4744 | AG282: 3506.4744 | AH282: 3506.4744 | AI282: 3506.4744 | AJ282: 3506.4744 | AK282: 3506.4744
A283: Transportation | B283: Passenger | C283: Rail | F283: Diesel ICE Vehicle | G283: Renewable diesel | H283: TRARDS | I283: TRAPASRAIDMD | J283: TRAPASRAIICEVDSL20 | K283: Mvkm | L283: 0 | M283: 1 | N283: 2020 | O283: 30 | P283: 1 | Q283: 0.040874687 | R283: 0.040874687 | S283: 0.040874687 | T283: 0.040874687 | U283: 0.040874687 | V283: 0.040874687 | W283: 0.040874687 | X283: 35064.744 | Y283: 35064.744 | Z283: 35064.744 | AA283: 35064.744 | AB283: 35064.744 | AC283: 35064.744 | AD283: 35064.744 | AE283: 3506.4744 | AF283: 3506.4744 | AG283: 3506.4744 | AH283: 3506.4744 | AI283: 3506.4744 | AJ283: 3506.4744 | AK283: 3506.4744
A284: Transportation | B284: Passenger | C284: Rail | F284: Diesel ICE Vehicle | G284: Bio diesel | H284: TRABDS | I284: TRAPASRAIDMD | J284: TRAPASRAIICEVDSL20 | K284: Mvkm | L284: 0 | M284: 1 | N284: 2020 | O284: 30 | P284: 0.1 | Q284: 0.040874687 | R284: 0.040874687 | S284: 0.040874687 | T284: 0.040874687 | U284: 0.040874687 | V284: 0.040874687 | W284: 0.040874687 | X284: 35064.744 | Y284: 35064.744 | Z284: 35064.744 | AA284: 35064.744 | AB284: 35064.744 | AC284: 35064.744 | AD284: 35064.744 | AE284: 3506.4744 | AF284: 3506.4744 | AG284: 3506.4744 | AH284: 3506.4744 | AI284: 3506.4744 | AJ284: 3506.4744 | AK284: 3506.4744
A285: Transportation | B285: Passenger | C285: Rail | F285: Electric Propulsion Vehicle | G285: Electricity | H285: TRAELC | I285: TRAPASRAIDMD | J285: TRAPASRAIPROELC20 | K285: Mvkm | L285: 1 | M285: 1 | N285: 2020 | O285: 30 | P285: 1 | Q285: 0.040874687 | R285: 0.040874687 | S285: 0.040874687 | T285: 0.040874687 | U285: 0.040874687 | V285: 0.040874687 | W285: 0.040874687 | X285: 35064.744 | Y285: 35064.744 | Z285: 35064.744 | AA285: 35064.744 | AB285: 35064.744 | AC285: 35064.744 | AD285: 35064.744 | AE285: 3506.4744 | AF285: 3506.4744 | AG285: 3506.4744 | AH285: 3506.4744 | AI285: 3506.4744 | AJ285: 3506.4744 | AK285: 3506.4744
A286: Transportation | B286: Passenger | C286: Rail | F286: Hydrogen Fuel Cell Electric Vehicle | G286: Hydrogen | H286: TRAH2G | I286: TRAPASRAIDMD | J286: TRAPASRAIFCEV20 | K286: Mvkm | L286: 1 | M286: 1 | N286: 2020 | O286: 30 | P286: 1 | Q286: 0.040874687 | R286: 0.040874687 | S286: 0.040874687 | T286: 0.040874687 | U286: 0.040874687 | V286: 0.040874687 | W286: 0.040874687 | X286: 35064.744 | Y286: 35064.744 | Z286: 35064.744 | AA286: 35064.744 | AB286: 35064.744 | AC286: 35064.744 | AD286: 35064.744 | AE286: 3506.4744 | AF286: 3506.4744 | AG286: 3506.4744 | AH286: 3506.4744 | AI286: 3506.4744 | AJ286: 3506.4744 | AK286: 3506.4744
A287: Transportation | B287: Passenger | C287: Tram | F287: Electric Propulsion Vehicle | G287: Electricity | H287: TRAELC | I287: TRAPASTRMDMD | J287: TRAPASTRMPROELC20 | K287: Mvkm | L287: 1 | M287: 1 | N287: 2020 | O287: 30 | P287: 1 | Q287: 0.07814652 | R287: 0.07814652 | S287: 0.07814652 | T287: 0.07814652 | U287: 0.07814652 | V287: 0.07814652 | W287: 0.07814652 | X287: 1585.9239 | Y287: 1585.9239 | Z287: 1585.9239 | AA287: 1585.9239 | AB287: 1585.9239 | AC287: 1585.9239 | AD287: 1585.9239 | AE287: 158.59239 | AF287: 158.59239 | AG287: 158.59239 | AH287: 158.59239 | AI287: 158.59239 | AJ287: 158.59239 | AK287: 158.59239
A288: Transportation | B288: Passenger | C288: Subway | F288: Electric Propulsion Vehicle | G288: Electricity | H288: TRAELC | I288: TRAPASSUBDMD | J288: TRAPASSUBPROELC20 | K288: Mvkm | L288: 1 | M288: 1 | N288: 2020 | O288: 30 | P288: 1 | Q288: 0.07814652 | R288: 0.07814652 | S288: 0.07814652 | T288: 0.07814652 | U288: 0.07814652 | V288: 0.07814652 | W288: 0.07814652 | X288: 1585.9239 | Y288: 1585.9239 | Z288: 1585.9239 | AA288: 1585.9239 | AB288: 1585.9239 | AC288: 1585.9239 | AD288: 1585.9239 | AE288: 158.59239 | AF288: 158.59239 | AG288: 158.59239 | AH288: 158.59239 | AI288: 158.59239 | AJ288: 158.59239 | AK288: 158.59239
A289: Transportation | B289: Other | C289: Waterborne | F289: Diesel ICE Vehicle | G289: Diesel | H289: TRADSL | I289: TRAOTHWATDMD | J289: TRAOTHWATICEVDSL20 | K289: Mvkm | L289: 1 | M289: 1 | N289: 2020 | O289: 30 | P289: 1 | Q289: 0.0011427622 | R289: 0.0011427622 | S289: 0.0011427622 | T289: 0.0011427622 | U289: 0.0011427622 | V289: 0.0011427622 | W289: 0.0011427622 | X289: 59271.955 | Y289: 59271.955 | Z289: 59271.955 | AA289: 59271.955 | AB289: 59271.955 | AC289: 59271.955 | AD289: 59271.955 | AE289: 2963.5978 | AF289: 2963.5978 | AG289: 2963.5978 | AH289: 2963.5978 | AI289: 2963.5978 | AJ289: 2963.5978 | AK289: 2963.5978
A290: Transportation | B290: Other | C290: Waterborne | F290: Diesel ICE Vehicle | G290: Renewable diesel | H290: TRARDS | I290: TRAOTHWATDMD | J290: TRAOTHWATICEVDSL20 | K290: Mvkm | L290: 0 | M290: 1 | N290: 2020 | O290: 30 | P290: 1 | Q290: 0.0011427622 | R290: 0.0011427622 | S290: 0.0011427622 | T290: 0.0011427622 | U290: 0.0011427622 | V290: 0.0011427622 | W290: 0.0011427622 | X290: 59271.955 | Y290: 59271.955 | Z290: 59271.955 | AA290: 59271.955 | AB290: 59271.955 | AC290: 59271.955 | AD290: 59271.955 | AE290: 2963.5978 | AF290: 2963.5978 | AG290: 2963.5978 | AH290: 2963.5978 | AI290: 2963.5978 | AJ290: 2963.5978 | AK290: 2963.5978
A291: Transportation | B291: Other | C291: Waterborne | F291: Diesel ICE Vehicle | G291: Bio diesel | H291: TRABDS | I291: TRAOTHWATDMD | J291: TRAOTHWATICEVDSL20 | K291: Mvkm | L291: 0 | M291: 1 | N291: 2020 | O291: 30 | P291: 0.1 | Q291: 0.0011427622 | R291: 0.0011427622 | S291: 0.0011427622 | T291: 0.0011427622 | U291: 0.0011427622 | V291: 0.0011427622 | W291: 0.0011427622 | X291: 59271.955 | Y291: 59271.955 | Z291: 59271.955 | AA291: 59271.955 | AB291: 59271.955 | AC291: 59271.955 | AD291: 59271.955 | AE291: 2963.5978 | AF291: 2963.5978 | AG291: 2963.5978 | AH291: 2963.5978 | AI291: 2963.5978 | AJ291: 2963.5978 | AK291: 2963.5978
A292: Transportation | B292: Other | C292: Waterborne | F292: Diesel ICE Vehicle Direct Injection | G292: Diesel | H292: TRADSL | I292: TRAOTHWATDMD | J292: TRAOTHWATICEVDSL20 | K292: Mvkm | L292: 0 | M292: 1 | N292: 2020 | O292: 30 | P292: 1 | Q292: 0.0012985934 | R292: 0.0012985934 | S292: 0.0012985934 | T292: 0.0012985934 | U292: 0.0012985934 | V292: 0.0012985934 | W292: 0.0012985934 | X292: 61074.415 | Y292: 61074.415 | Z292: 61074.415 | AA292: 61074.415 | AB292: 61074.415 | AC292: 61074.415 | AD292: 61074.415 | AE292: 3029.7957 | AF292: 3029.7957 | AG292: 3029.7957 | AH292: 3029.7957 | AI292: 3029.7957 | AJ292: 3029.7957 | AK292: 3029.7957
A293: Transportation | B293: Other | C293: Waterborne | F293: Diesel ICE Vehicle Direct Injection | G293: Renewable diesel | H293: TRARDS | I293: TRAOTHWATDMD | J293: TRAOTHWATICEVDSL20 | K293: Mvkm | L293: 0 | M293: 1 | N293: 2020 | O293: 30 | P293: 1 | Q293: 0.0012985934 | R293: 0.0012985934 | S293: 0.0012985934 | T293: 0.0012985934 | U293: 0.0012985934 | V293: 0.0012985934 | W293: 0.0012985934 | X293: 61074.415 | Y293: 61074.415 | Z293: 61074.415 | AA293: 61074.415 | AB293: 61074.415 | AC293: 61074.415 | AD293: 61074.415 | AE293: 3029.7957 | AF293: 3029.7957 | AG293: 3029.7957 | AH293: 3029.7957 | AI293: 3029.7957 | AJ293: 3029.7957 | AK293: 3029.7957
... A319: Transportation | B319: Other | C319: Aviation | F319: Aviation Gasoline ICE Vehicle Improved | G319: Aviation gasoline | H319: TRAAGA | I319: TRAOTHAIRDMD | J319: TRAOTHAIRICEIAGA20 | K319: Mvkm | L319: 1 | M319: 1 | N319: 2020 | O319: 20 | P319: 1 | Q319: 0.0040699936 | R319: 0.0040699936 | S319: 0.0040699936 | T319: 0.0040699936 | U319: 0.0040699936 | V319: 0.0040699936 | W319: 0.0040699936 | X319: 3154.2202 | Y319: 3154.2202 | Z319: 3154.2202 | AA319: 3154.2202 | AB319: 3154.2202 | AC319: 3154.2202 | AD319: 3154.2202 | AE319: 315.42202 | AF319: 315.42202 | AG319: 315.42202 | AH319: 315.42202 | AI319: 315.42202 | AJ319: 315.42202 | AK319: 315.42202
A320: * | B320: https://theicct.org/sites/default/files/publications/ICCT_EV_HDVs_Infrastructure_20190809.pdf | J320: * | L320: 0 | M320: *
A321: Transportation | B321: Light-duty | E321: Battery | F321: Residential Charging Station | G321: Electricity | H321: TRAELC | I321: TRABAT | J321: TRALDTRESCHA19 | K321: MW | L321: 1 | M321: 1 | N321: 2019 | O321: 25 | Q321: 0.9 | R321: 0.91 | S321: 0.92 | T321: 0.93 | U321: 0.94 | V321: 0.95 | W321: 0.95 | X321: 1083.8776 | Y321: 757.54886 | Z321: 692.28311 | AA321: 627.01737 | AB321: 561.75162 | AC321: 496.48587 | AD321: 431.22012 | AE321: 29.136495 | AF321: 26.805575 | AG321: 24.474656 | AH321: 22.143736 | AI321: 19.812816 | AJ321: 17.481897 | AK321: 15.150977
A322: Transportation | B322: Light-duty | E322: Battery | F322: Commercial 120V Charging Station | G322: Electricity | H322: TRAELC | I322: TRABAT | J322: TRALDTCOM1CHA19 | K322: MW | L322: 1 | M322: 1 | N322: 2019 | O322: 25 | Q322: 0.9 | R322: 0.91 | S322: 0.92 | T322: 0.93 | U322: 0.94 | V322: 0.95 | W322: 0.95 | X322: 970.828 | Y322: 675.96668 | Z322: 617.69369 | AA322: 559.4207 | AB322: 501.14771 | AC322: 442.87472 | AD322: 384.60173 | AE322: 37.294713 | AF322: 34.18682 | AG322: 31.078928 | AH322: 27.971035 | AI322: 24.863142 | AJ322: 21.755249 | AK322: 18.647357
A323: Transportation | B323: Light-duty | E323: Battery | F323: Commercial 240V Charging Station | G323: Electricity | H323: TRAELC | I323: TRABAT | J323: TRALDTCOM2CHA19 | K323: MW | L323: 1 | M323: 1 | N323: 2019 | O323: 25 | Q323: 0.9 | R323: 0.91 | S323: 0.92 | T323: 0.93 | U323: 0.94 | V323: 0.95 | W323: 0.95 | X323: 1165.4598 | Y323: 815.82185 | Z323: 745.89426 | AA323: 675.96668 | AB323: 606.03909 | AC323: 536.1115 | AD323: 466.18392 | AE323: 44.287472 | AF323: 40.596849 | AG323: 36.906227 | AH323: 33.215604 | AI323: 29.524981 | AJ323: 25.834359 | AK323: 22.143736
A324: Transportation | B324: Light-duty | E324: Battery | F324: Public Charging Station | G324: Electricity | H324: TRAELC | I324: TRABAT | J324: TRALDTPUBCHA19 | K324: MW | L324: 1 | M324: 1 | N324: 2019 | O324: 25 | Q324: 0.9 | R324: 0.91 | S324: 0.92 | T324: 0.93 | U324: 0.94 | V324: 0.95 | W324: 0.95 | X324: 1748.1897 | Y324: 1223.7328 | Z324: 1118.8414 | AA324: 1118.8414 | AB324: 1118.8414 | AC324: 1118.8414 | AD324: 699.27587 | AE324: 60.603909 | AF324: 55.553583 | AG324: 50.503257 | AH324: 45.452932 | AI324: 40.402606 | AJ324: 35.35228 | AK324: 30.301954
A325: Transportation | B325: Heavy-duty | E325: Battery Freight | F325: Slow Charging Station | G325: Electricity | H325: TRAELC | I325: TRABAF | J325: TRAHDTSLWCHA19 | K325: MW | L325: 1 | M325: 1 | N325: 2019 | O325: 25 | Q325: 0.9 | R325: 0.91 | S325: 0.92 | T325: 0.93 | U325: 0.94 | V325: 0.95 | W325: 0.95 | X325: 582.72989 | Y325: 524.4569 | Z325: 466.18392 | AA325: 466.18392 | AB325: 466.18392 | AC325: 466.18392 | AD325: 466.18392 | AE325: 163.16437 | AF325: 143.93428 | AG325: 124.7042 | AH325: 105.47411 | AI325: 86.244024 | AJ325: 67.013938 | AK325: 47.783851
A326: Transportation | B326: Heavy-duty | E326: Battery Freight | F326: Fast Charging Station | G326: Electricity | H326: TRAELC | I326: TRABAF | J326: TRAHDTFASCHA19 | K326: MW | L326: 1 | M326: 1 | N326: 2019 | O326: 25 | Q326: 0.9 | R326: 0.91 | S326: 0.92 | T326: 0.93 | U326: 0.94 | V326: 0.95 | W326: 0.95 | X326: 874.09484 | Y326: 757.54886 | Z326: 641.00288 | AA326: 641.00288 | AB326: 641.00288 | AC326: 641.00288 | AD326: 641.00288 | AE326: 174.81897 | AF326: 156.36585 | AG326: 137.91274 | AH326: 119.45963 | AI326: 101.00651 | AJ326: 82.553402 | AK326: 64.100288

Sheet TRA RESID
A1: Sector | B1: Sub-sector | C1: Archetype | D1: Vintage | E1: End Use | F1: Technology | G1: Energy | H1: Input Label | I1: Output Label | J1: Technology Label | K1: Main fuel | L1: MODE DEMAND (MVkm) | M1: Demand SHARE (%) | N1: Minimum fuel share (%) | O1: Maximum fuel share (%) | P1: DEMAND (MVkm) | Q1: FINAL ENERGY (GJ) | R1: RESID (Mvkma) | S1: EFF (Vkm/MJ) | T1: Residual life (Yr) | U1: Fixed O&M (Thousands $/Mvkm/yr) | V1: Variable O&M (Thousands $/Mvkm) | W1: CFA | X1: C2A
A2: Transportation | B2: Passenger | C2: Passenger Car | F2: Gasoline ICE Vehicle (spark ignition) | G2: Gasoline | H2: TRAGSL | I2: TRAPASCARDMD | J2: TRAPASCARICEVGSL19 | K2: 1 | L2: 68921.251 | M2: 0.97948822 | N2: 0.9 | O2: 1 | P2: 67507.553 | Q2: 205180.58 | R2: 67507.553 | S2: 0.32901532 | T2: 12 | U2: 6.472949 | W2: 1 | X2: 1
A3: Transportation | B3: Passenger | C3: Passenger Car | F3: Gasoline ICE Vehicle (spark ignition) | G3: Ethanol | H3: TRAETH | I3: TRAPASCARDMD | J3: TRAPASCARICEVGSL19 | K3: 0 | L3: 68921.251 | M3: 0 | N3: 0 | O3: 0.1 | P3: 0 | Q3: 0 | R3: 0 | S3: 0.32901532 | T3: 12 | U3: 6.472949 | W3: 1 | X3: 1
A4: Transportation | B4: Passenger | C4: Passenger Car | F4: Diesel Conventional Compression Ignition Vehicle | G4: Diesel | H4: TRADSL | I4: TRAPASCARDMD | J4: TRAPASCARICEVDSL19 | K4: 1 | L4: 68921.251 | M4: 0.011074786 | N4: 0 | O4: 1 | P4: 763.2881 | Q4: 2284.357 | R4: 763.2881 | S4: 0.33413696 | T4: 12 | U4: 6.472949 | W4: 1 | X4: 1
A5: Transportation | B5: Passenger | C5: Passenger Car | F5: Diesel Conventional Compression Ignition Vehicle | G5: Renewable diesel | H5: TRARDS | I5: TRAPASCARDMD | J5: TRAPASCARICEVDSL19 | K5: 0 | L5: 68921.251 | M5: 0 | N5: 0 | O5: 1 | P5: 0 | Q5: 0 | R5: 0 | S5: 0.33413696 | T5: 12 | U5: 6.472949 | W5: 1 | X5: 1
A6: Transportation | B6: Passenger | C6: Passenger Car | F6: Diesel Conventional Compression Ignition Vehicle | G6: Bio diesel | H6: TRABDS | I6: TRAPASCARDMD | J6: TRAPASCARICEVDSL19 | K6: 0 | L6: 68921.251 | M6: 0 | N6: 0 | O6: 0.1 | P6: 0 | Q6: 0 | R6: 0 | S6: 0.33413696 | T6: 12 | U6: 6.472949 | W6: 1 | X6: 1
A7: Transportation | B7: Passenger | C7: Passenger Car | F7: Compressed Natural Gas Conventional Vehicle | G7: CNG | H7: TRACNG | I7: TRAPASCARDMD | J7: TRAPASCARICEVCNG19 | K7: 1 | L7: 68921.251 | M7: 0 | N7: 0 | O7: 1 | P7: 0 | Q7: 0 | R7: 0 | S7: 0.25976728 | T7: 12 | U7: 6.472949 | W7: 1 | X7: 1
A8: Transportation | B8: Passenger | C8: Passenger Car | F8: Compressed Natural Gas Conventional Vehicle | G8: RNG | H8: TRARNG | I8: TRAPASCARDMD | J8: TRAPASCARICEVCNG19 | K8: 0 | L8: 68921.251 | M8: 0 | N8: 0 | O8: 1 | P8: 0 | Q8: 0 | R8: 0 | S8: 0.25976728 | T8: 12 | U8: 6.472949 | W8: 1 | X8: 1
A9: Transportation | B9: Passenger | C9: Passenger Car | F9: Battery Electric Vehicle (300-mile range) | G9: Battery | H9: TRABAT | I9: TRAPASCARDMD | J9: TRAPASCAR300BEV19 | K9: 1 | L9: 68921.251 | M9: 0.0094369922 | N9: 1 | O9: 1 | P9: 650.4093 | Q9: 884.34672 | R9: 650.4093 | S9: 0.73546867 | T9: 12 | U9: 6.472949 | W9: 1 | X9: 1
A10: Transportation | B10: Passenger | C10: Passenger Car | F10: Hydrogen Fuel Cell Electric Vehicle (300-mile range) | G10: Hydrogen | H10: TRAH2G | I10: TRAPASCARDMD | J10: TRAPASCAR300FCEV19 | K10: 1 | L10: 68921.251 | M10: 0 | N10: 1 | O10: 1 | P10: 0 | Q10: 0 | R10: 0 | S10: 0.73546867 | T10: 12 | U10: 6.472949 | W10: 1 | X10: 1
A11: Transportation | B11: Passenger | C11: Passenger Truck | F11: Gasoline ICE Vehicle (spark ignition) | G11: Gasoline | H11: TRAGSL | I11: TRAPASLDTDMD | J11: TRAPASLDTICEVGSL19 | K11: 1 | L11: 0 | M11: 0 | N11: 0.9 | O11: 1 | P11: 0 | Q11: 0 | R11: 0 | S11: 0.24925979 | T11: 13 | U11: 5.8122532 | W11: 1 | X11: 1
A12: Transportation | B12: Passenger | C12: Passenger Truck | F12: Gasoline ICE Vehicle (spark ignition) | G12: Ethanol | H12: TRAETH | I12: TRAPASLDTDMD | J12: TRAPASLDTICEVGSL19 | K12: 0 | L12: 0 | M12: 0 | N12: 0 | O12: 0.1 | P12: 0 | Q12: 0 | R12: 0 | S12: 0.24925979 | T12: 13 | U12: 5.8122532 | W12: 1 | X12: 1
A13: Transportation | B13: Passenger | C13: Passenger Truck | F13: Diesel Conventional Compression Ignition Vehicle | G13: Diesel | H13: TRADSL | I13: TRAPASLDTDMD | J13: TRAPASLDTICEVDSL19 | K13: 1 | L13: 0 | M13: 0 | N13: 0 | O13: 1 | P13: 0 | Q13: 0 | R13: 0 | S13: 0.19756987 | T13: 13 | U13: 5.8122532 | W13: 1 | X13: 1
... A123: Transportation | B123: Passenger | C123: Subway | F123: Electric Propulsion Vehicle | G123: Electricity | H123: TRAELC | I123: TRAPASSUBDMD | J123: TRAPASSUBPROELC19 | K123: 1 | L123: 0 | M123: 0 | N123: 1 | O123: 1 | P123: 0 | Q123: 0 | R123: 0 | S123: 0.080703906 | T123: 30 | U123: 158.59239 | W123: 1 | X123: 1
A124: Transportation | B124: Passenger | C124: Bicycle | F124: N/a | G124: N/a | I124: TRAPASBICDMD | J124: TRAPASBIC19 | K124: 1 | L124: 783.71641 | M124: 1 | N124: 0 | O124: 0 | P124: 783.71641 | Q124: 0 | R124: 783.71641 | S124: 1 | T124: 50 | U124: 0 | W124: 1 | X124: 1
A125: Transportation | B125: Passenger | C125: Walk | F125: N/a | G125: N/a | I125: TRAPASWALDMD | J125: TRAPASWAL19 | K125: 1 | L125: 4185.0617 | M125: 1 | N125: 0 | O125: 0 | P125: 4185.0617 | Q125: 0 | R125: 4185.0617 | S125: 1 | T125: 100 | U125: 0 | W125: 1 | X125: 1
A126: Transportation | B126: Other | C126: Off-Road | F126: Gasoline ICE Vehicle | G126: Gasoline | H126: TRAGSL | I126: TRAOTHOFRDMD | J126: TRAOTHOFRICEVGSL19 | K126: 1 | L126: 0 | M126: 0 | N126: 0.9 | O126: 1 | P126: 0 | Q126: 0 | R126: 0 | S126: 0.10837963 | T126: 8 | U126: 10.491572 | W126: 1 | X126: 1
A127: Transportation | B127: Other | C127: Off-Road | F127: Gasoline ICE Vehicle | G127: Ethanol | H127: TRAETH | I127: TRAOTHOFRDMD | J127: TRAOTHOFRICEVGSL19 | K127: 0 | L127: 0 | M127: 0 | N127: 0 | O127: 0.1 | P127: 0 | Q127: 0 | R127: 0 | S127: 0.10837963 | T127: 8 | U127: 10.491572 | W127: 1 | X127: 1
A128: Transportation | B128: Other | C128: Off-Road | F128: Diesel ICE Vehicle | G128: Diesel | H128: TRADSL | I128: TRAOTHOFRDMD | J128: TRAOTHOFRICEVDSL19 | K128: 1 | L128: 0 | M128: 0 | N128: 0 | O128: 1 | P128: 0 | Q128: 0 | R128: 0 | S128: 0.1046149 | T128: 8 | U128: 10.491572 | W128: 1 | X128: 1
A129: Transportation | B129: Other | C129: Off-Road | F129: Diesel ICE Vehicle | G129: Renewable diesel | H129: TRARDS | I129: TRAOTHOFRDMD | J129: TRAOTHOFRICEVDSL19 | K129: 0 | L129: 0 | M129: 0 | N129: 0 | O129: 1 | P129: 0 | Q129: 0 | R129: 0 | S129: 0.1046149 | T129: 8 | U129: 10.491572 | W129: 1 | X129: 1
A130: Transportation | B130: Other | C130: Off-Road | F130: Diesel ICE Vehicle | G130: Bio diesel | H130: TRABDS | I130: TRAOTHOFRDMD | J130: TRAOTHOFRICEVDSL19 | K130: 0 | L130: 0 | M130: 0 | N130: 0 | O130: 0.1 | P130: 0 | Q130: 0 | R130: 0 | S130: 0.1046149 | T130: 8 | U130: 10.491572 | W130: 1 | X130: 1
A131: Transportation | B131: Other | C131: Off-Road | F131: Compressed Natural Gas Conventional Vehicle | G131: CNG | H131: TRACNG | I131: TRAOTHOFRDMD | J131: TRAOTHOFRICEVCNG19 | K131: 1 | L131: 0 | M131: 0 | N131: 0 | O131: 1 | P131: 0 | Q131: 0 | R131: 0 | S131: 0.10837963 | T131: 8 | U131: 10.491572 | W131: 1 | X131: 1
A132: Transportation | B132: Other | C132: Off-Road | F132: Compressed Natural Gas Conventional Vehicle | G132: RNG | H132: TRARNG | I132: TRAOTHOFRDMD | J132: TRAOTHOFRICEVCNG19 | K132: 0 | L132: 0 | M132: 0 | N132: 0 | O132: 1 | P132: 0 | Q132: 0 | R132: 0 | S132: 0.10837963 | T132: 8 | U132: 10.491572 | W132: 1 | X132: 1
A133: Transportation | B133: Other | C133: Off-Road | F133: Battery Electric Vehicle | G133: Battery Freight | H133: TRABAF | I133: TRAOTHOFRDMD | J133: TRAOTHOFRBEV19 | K133: 1 | L133: 0 | M133: 0 | N133: 1 | O133: 1 | P133: 0 | Q133: 0 | R133: 0 | S133: 0.21465702 | T133: 8 | U133: 10.491572 | W133: 1 | X133: 1
A134: Transportation | B134: Other | C134: Off-Road | F134: Hydrogen Fuel Cell Electric Vehicle | G134: Hydrogen | H134: TRAH2G | I134: TRAOTHOFRDMD | J134: TRAOTHOFRFCEV19 | K134: 1 | L134: 0 | M134: 0 | N134: 1 | O134: 1 | P134: 0 | Q134: 0 | R134: 0 | S134: 0.21465702 | T134: 8 | U134: 10.491572 | W134: 1 | X134: 1
A135: Transportation | B135: Other | C135: Waterborne | F135: Gasoline ICE Vehicle | G135: Gasoline | H135: TRAGSL | I135: TRAOTHWATDMD | J135: TRAOTHWATICEVGSL19 | K135: 1 | L135: 1.6054304 | M135: 0 | N135: 0.9 | O135: 1 | P135: 0 | Q135: 0 | R135: 0 | S135: 0.0012937722 | T135: 30 | U135: 6522.2354 | W135: 1 | X135: 1
A136: Transportation | B136: Other | C136: Waterborne | F136: Gasoline ICE Vehicle | G136: Ethanol | H136: TRAETH | I136: TRAOTHWATDMD | J136: TRAOTHWATICEVGSL19 | K136: 0 | L136: 1.6054304 | M136: 0 | N136: 0 | O136: 0.1 | P136: 0 | Q136: 0 | R136: 0 | S136: 0.0012937722 | T136: 30 | U136: 6522.2354 | W136: 1 | X136: 1
A137: Transportation | B137: Other | C137: Waterborne | F137: Diesel ICE Vehicle | G137: Diesel | H137: TRADSL | I137: TRAOTHWATDMD | J137: TRAOTHWATICEVDSL19 | K137: 1 | L137: 1.6054304 | M137: 1 | N137: 0 | O137: 1 | P137: 1.6054304 | Q137: 1400.5379 | R137: 1.6054304 | S137: 0.0011462956 | T137: 30 | U137: 6522.2354 | W137: 1 | X137: 1
... A143: Transportation | B143: Other | C143: Aviation | F143: Turbo-reactor | G143: Sustainable aviation fuel | H143: TRASAF | I143: TRAOTHAIRDMD | J143: TRAOTHAIRTURREA19 | K143: 0 | L143: 0.12571557 | M143: 0 | N143: 0 | O143: 1 | P143: 0 | Q143: 0 | R143: 0 | S143: 0.0043975374 | T143: 24 | U143: 1249.4626 | W143: 1 | X143: 1

Sheet >>> Data 

Sheet Selected_constraint
A1: Constraint number | B1: {=_xlfn.UNIQUE(_xlfn._xlws.FILTER('TRA RESID'!$H:$I,'TRA RESID'!$H:$H<>""))} -> Input Label | C1: Output Label | D1: Count | G1: Constraint number | H1: {=_xlfn.UNIQUE(_xlfn._xlws.FILTER('TRA RESID'!$I:$I,'TRA RESID'!$I:$I<>""))} -> Output Label
A2: =COUNTA($B$2:B2) -> 1 | B2: TRAGSL | C2: TRAPASCARDMD | D2: {=COUNTA(_xlfn.UNIQUE(_xlfn._xlws.FILTER('TRA TECH'!$H:$H,('TRA TECH'!$I:$I=C2)*('TRA TECH'!$M:$M=1))))} -> 9 | G2: =COUNTA($H$2:H2) -> 1 | H2: TRAPASCARDMD | I2: {=COUNTA(_xlfn.UNIQUE(_xlfn._xlws.FILTER('TRA RESID'!$F:$F,('TRA RESID'!$I:$I=$H2)*('TRA RESID'!$R:$R<>0))))} -> 3
A3: =COUNTA($B$2:B3) -> 2 | B3: TRAETH | C3: TRAPASCARDMD | D3: {=COUNTA(_xlfn.UNIQUE(_xlfn._xlws.FILTER('TRA TECH'!$H:$H,('TRA TECH'!$I:$I=C3)*('TRA TECH'!$M:$M=1))))} -> 9 | G3: =COUNTA($H$2:H3) -> 2 | H3: TRAPASLDTDMD | I3: {=COUNTA(_xlfn.UNIQUE(_xlfn._xlws.FILTER('TRA RESID'!$F:$F,('TRA RESID'!$I:$I=$H3)*('TRA RESID'!$R:$R<>0))))} -> 1
A4: =COUNTA($B$2:B4) -> 3 | B4: TRADSL | C4: TRAPASCARDMD | D4: {=COUNTA(_xlfn.UNIQUE(_xlfn._xlws.FILTER('TRA TECH'!$H:$H,('TRA TECH'!$I:$I=C4)*('TRA TECH'!$M:$M=1))))} -> 9 | G4: =COUNTA($H$2:H4) -> 3 | H4: TRAPASMOTDMD | I4: {=COUNTA(_xlfn.UNIQUE(_xlfn._xlws.FILTER('TRA RESID'!$F:$F,('TRA RESID'!$I:$I=$H4)*('TRA RESID'!$R:$R<>0))))} -> 1
A5: =COUNTA($B$2:B5) -> 4 | B5: TRARDS | C5: TRAPASCARDMD | D5: {=COUNTA(_xlfn.UNIQUE(_xlfn._xlws.FILTER('TRA TECH'!$H:$H,('TRA TECH'!$I:$I=C5)*('TRA TECH'!$M:$M=1))))} -> 9 | G5: =COUNTA($H$2:H5) -> 4 | H5: TRAFRECLTDMD | I5: {=COUNTA(_xlfn.UNIQUE(_xlfn._xlws.FILTER('TRA RESID'!$F:$F,('TRA RESID'!$I:$I=$H5)*('TRA RESID'!$R:$R<>0))))} -> 4
A6: =COUNTA($B$2:B6) -> 5 | B6: TRABDS | C6: TRAPASCARDMD | D6: {=COUNTA(_xlfn.UNIQUE(_xlfn._xlws.FILTER('TRA TECH'!$H:$H,('TRA TECH'!$I:$I=C6)*('TRA TECH'!$M:$M=1))))} -> 9 | G6: =COUNTA($H$2:H6) -> 5 | H6: TRAFRERFTDMD | I6: {=COUNTA(_xlfn.UNIQUE(_xlfn._xlws.FILTER('TRA RESID'!$F:$F,('TRA RESID'!$I:$I=$H6)*('TRA RESID'!$R:$R<>0))))} -> 3
A7: =COUNTA($B$2:B7) -> 6 | B7: TRACNG | C7: TRAPASCARDMD | D7: {=COUNTA(_xlfn.UNIQUE(_xlfn._xlws.FILTER('TRA TECH'!$H:$H,('TRA TECH'!$I:$I=C7)*('TRA TECH'!$M:$M=1))))} -> 9 | G7: =COUNTA($H$2:H7) -> 6 | H7: TRAFRESLHDMD | I7: {=COUNTA(_xlfn.UNIQUE(_xlfn._xlws.FILTER('TRA RESID'!$F:$F,('TRA RESID'!$I:$I=$H7)*('TRA RESID'!$R:$R<>0))))} -> 1
A8: =COUNTA($B$2:B8) -> 7 | B8: TRARNG | C8: TRAPASCARDMD | D8: {=COUNTA(_xlfn.UNIQUE(_xlfn._xlws.FILTER('TRA TECH'!$H:$H,('TRA TECH'!$I:$I=C8)*('TRA TECH'!$M:$M=1))))} -> 9 | G8: =COUNTA($H$2:H8) -> 7 | H8: TRAFRESSHDMD | I8: {=COUNTA(_xlfn.UNIQUE(_xlfn._xlws.FILTER('TRA RESID'!$F:$F,('TRA RESID'!$I:$I=$H8)*('TRA RESID'!$R:$R<>0))))} -> 1
A9: =COUNTA($B$2:B9) -> 8 | B9: TRABAT | C9: TRAPASCARDMD | D9: {=COUNTA(_xlfn.UNIQUE(_xlfn._xlws.FILTER('TRA TECH'!$H:$H,('TRA TECH'!$I:$I=C9)*('TRA TECH'!$M:$M=1))))} -> 9 | G9: =COUNTA($H$2:H9) -> 8 | H9: TRAFRECLHDMD | I9: {=COUNTA(_xlfn.UNIQUE(_xlfn._xlws.FILTER('TRA RESID'!$F:$F,('TRA RESID'!$I:$I=$H9)*('TRA RESID'!$R:$R<>0))))} -> 3
A10: =COUNTA($B$2:B10) -> 9 | B10: TRAH2G | C10: TRAPASCARDMD | D10: {=COUNTA(_xlfn.UNIQUE(_xlfn._xlws.FILTER('TRA TECH'!$H:$H,('TRA TECH'!$I:$I=C10)*('TRA TECH'!$M:$M=1))))} -> 9 | G10: =COUNTA($H$2:H10) -> 9 | H10: TRAFRECSHDMD | I10: {=COUNTA(_xlfn.UNIQUE(_xlfn._xlws.FILTER('TRA RESID'!$F:$F,('TRA RESID'!$I:$I=$H10)*('TRA RESID'!$R:$R<>0))))} -> 1
A11: =COUNTA($B$2:B11) -> 10 | B11: TRAGSL | C11: TRAPASLDTDMD | D11: {=COUNTA(_xlfn.UNIQUE(_xlfn._xlws.FILTER('TRA TECH'!$H:$H,('TRA TECH'!$I:$I=C11)*('TRA TECH'!$M:$M=1))))} -> 9 | G11: =COUNTA($H$2:H11) -> 10 | H11: TRAPASTBUDMD | I11: {=COUNTA(_xlfn.UNIQUE(_xlfn._xlws.FILTER('TRA RESID'!$F:$F,('TRA RESID'!$I:$I=$H11)*('TRA RESID'!$R:$R<>0))))} -> 2
A12: =COUNTA($B$2:B12) -> 11 | B12: TRAETH | C12: TRAPASLDTDMD | D12: {=COUNTA(_xlfn.UNIQUE(_xlfn._xlws.FILTER('TRA TECH'!$H:$H,('TRA TECH'!$I:$I=C12)*('TRA TECH'!$M:$M=1))))} -> 9 | G12: =COUNTA($H$2:H12) -> 11 | H12: TRAPASSBUDMD | I12: {=COUNTA(_xlfn.UNIQUE(_xlfn._xlws.FILTER('TRA RESID'!$F:$F,('TRA RESID'!$I:$I=$H12)*('TRA RESID'!$R:$R<>0))))} -> 2
A13: =COUNTA($B$2:B13) -> 12 | B13: TRADSL | C13: TRAPASLDTDMD | D13: {=COUNTA(_xlfn.UNIQUE(_xlfn._xlws.FILTER('TRA TECH'!$H:$H,('TRA TECH'!$I:$I=C13)*('TRA TECH'!$M:$M=1))))} -> 9 | G13: =COUNTA($H$2:H13) -> 12 | H13: TRAPASOBUDMD | I13: {=COUNTA(_xlfn.UNIQUE(_xlfn._xlws.FILTER('TRA RESID'!$F:$F,('TRA RESID'!$I:$I=$H13)*('TRA RESID'!$R:$R<>0))))} -> 1
... A21: =COUNTA($B$2:B21) -> 20 | B21: TRAETH | C21: TRAPASMOTDMD | D21: {=COUNTA(_xlfn.UNIQUE(_xlfn._xlws.FILTER('TRA TECH'!$H:$H,('TRA TECH'!$I:$I=C21)*('TRA TECH'!$M:$M=1))))} -> 9 | G21: =COUNTA($H$2:H21) -> 20 | H21: TRAOTHAIRDMD | I21: {=COUNTA(_xlfn.UNIQUE(_xlfn._xlws.FILTER('TRA RESID'!$F:$F,('TRA RESID'!$I:$I=$H21)*('TRA RESID'!$R:$R<>0))))} -> 1
A22: =COUNTA($B$2:B22) -> 21 | B22: TRADSL | C22: TRAPASMOTDMD | D22: {=COUNTA(_xlfn.UNIQUE(_xlfn._xlws.FILTER('TRA TECH'!$H:$H,('TRA TECH'!$I:$I=C22)*('TRA TECH'!$M:$M=1))))} -> 9
A23: =COUNTA($B$2:B23) -> 22 | B23: TRARDS | C23: TRAPASMOTDMD | D23: {=COUNTA(_xlfn.UNIQUE(_xlfn._xlws.FILTER('TRA TECH'!$H:$H,('TRA TECH'!$I:$I=C23)*('TRA TECH'!$M:$M=1))))} -> 9
A24: =COUNTA($B$2:B24) -> 23 | B24: TRABDS | C24: TRAPASMOTDMD | D24: {=COUNTA(_xlfn.UNIQUE(_xlfn._xlws.FILTER('TRA TECH'!$H:$H,('TRA TECH'!$I:$I=C24)*('TRA TECH'!$M:$M=1))))} -> 9
A25: =COUNTA($B$2:B25) -> 24 | B25: TRACNG | C25: TRAPASMOTDMD | D25: {=COUNTA(_xlfn.UNIQUE(_xlfn._xlws.FILTER('TRA TECH'!$H:$H,('TRA TECH'!$I:$I=C25)*('TRA TECH'!$M:$M=1))))} -> 9
A26: =COUNTA($B$2:B26) -> 25 | B26: TRARNG | C26: TRAPASMOTDMD | D26: {=COUNTA(_xlfn.UNIQUE(_xlfn._xlws.FILTER('TRA TECH'!$H:$H,('TRA TECH'!$I:$I=C26)*('TRA TECH'!$M:$M=1))))} -> 9
A27: =COUNTA($B$2:B27) -> 26 | B27: TRABAT | C27: TRAPASMOTDMD | D27: {=COUNTA(_xlfn.UNIQUE(_xlfn._xlws.FILTER('TRA TECH'!$H:$H,('TRA TECH'!$I:$I=C27)*('TRA TECH'!$M:$M=1))))} -> 9
A28: =COUNTA($B$2:B28) -> 27 | B28: TRAH2G | C28: TRAPASMOTDMD | D28: {=COUNTA(_xlfn.UNIQUE(_xlfn._xlws.FILTER('TRA TECH'!$H:$H,('TRA TECH'!$I:$I=C28)*('TRA TECH'!$M:$M=1))))} -> 9
A29: =COUNTA($B$2:B29) -> 28 | B29: TRAGSL | C29: TRAFRECLTDMD | D29: {=COUNTA(_xlfn.UNIQUE(_xlfn._xlws.FILTER('TRA TECH'!$H:$H,('TRA TECH'!$I:$I=C29)*('TRA TECH'!$M:$M=1))))} -> 9
A30: =COUNTA($B$2:B30) -> 29 | B30: TRAETH | C30: TRAFRECLTDMD | D30: {=COUNTA(_xlfn.UNIQUE(_xlfn._xlws.FILTER('TRA TECH'!$H:$H,('TRA TECH'!$I:$I=C30)*('TRA TECH'!$M:$M=1))))} -> 9
A31: =COUNTA($B$2:B31) -> 30 | B31: TRADSL | C31: TRAFRECLTDMD | D31: {=COUNTA(_xlfn.UNIQUE(_xlfn._xlws.FILTER('TRA TECH'!$H:$H,('TRA TECH'!$I:$I=C31)*('TRA TECH'!$M:$M=1))))} -> 9
A32: =COUNTA($B$2:B32) -> 31 | B32: TRARDS | C32: TRAFRECLTDMD | D32: {=COUNTA(_xlfn.UNIQUE(_xlfn._xlws.FILTER('TRA TECH'!$H:$H,('TRA TECH'!$I:$I=C32)*('TRA TECH'!$M:$M=1))))} -> 9
A33: =COUNTA($B$2:B33) -> 32 | B33: TRABDS | C33: TRAFRECLTDMD | D33: {=COUNTA(_xlfn.UNIQUE(_xlfn._xlws.FILTER('TRA TECH'!$H:$H,('TRA TECH'!$I:$I=C33)*('TRA TECH'!$M:$M=1))))} -> 9
... A141: =COUNTA($B$2:B141) -> 140 | B141: TRASAF | C141: TRAOTHAIRDMD | D141: {=COUNTA(_xlfn.UNIQUE(_xlfn._xlws.FILTER('TRA TECH'!$H:$H,('TRA TECH'!$I:$I=C141)*('TRA TECH'!$M:$M=1))))} -> 4

Sheet >> TIMES

Sheet UC
C2: ~UC_Sets: R_E: CITY | Q2: ~UC_Sets: R_E: CITY
H3: ~UC_T:UC_COMPRD | V3: ~UC_T:UC_COMPRD
C4: UC_N | D4: Pset_PN | E4: Pset: CI | F4: Pset: CO | G4: Cset: CN | H4: Year | I4: LimType | J4: UC_FLO | K4: CITY | L4: UC_RHSRTS | M4: UC_RHSRTS~0 | Q4: UC_N | R4: Pset_PN | S4: Pset: CI | T4: Pset: CO | U4: Cset: CN | V4: Year | W4: LimType | X4: UC_FLO | Y4: CITY | Z4: UC_RHSRTS | AA4: UC_RHSRTS~0
A5: 1 | C5: =IF(E5="","",IF(_xlfn.XLOOKUP($A5,Selected_constraint!$A:$A,Selected_constraint!$D:$D)=1,"*",IF(SUMIFS('TRA TECH'!$M:$M,'TRA TECH'!$H:$H,E5,'TRA TECH'!$I:$I,F5)=0,"*",IF(SUMIFS('TRA RESID'!$P:$P,'TRA RESID'!$H:$H,$E5,'TRA RESID'!$I:$I,$F5)=0,"*","UC_MarketShare_"&LEFT(F5,LEN(F5)-3)&"_"&RIGHT(E5,3)&"_MIN")))) -> UC_MarketShare_TRAPASCAR_GSL_MIN | E5: =_xlfn.XLOOKUP($A5,Selected_constraint!$A:$A,Selected_constraint!$B:$B) -> TRAGSL | F5: =_xlfn.XLOOKUP($A5,Selected_constraint!$A:$A,Selected_constraint!$C:$C) -> TRAPASCARDMD | G5: =F5 -> TRAPASCARDMD | H5: 2019 | I5: LO | J5: 1 | K5: =-SUMIFS('TRA RESID'!$P:$P,'TRA RESID'!$H:$H,$E5,'TRA RESID'!$I:$I,$F5)/SUMIFS('TRA RESID'!$P:$P,'TRA RESID'!$I:$I,$F5)*O5 -> -0.95989846 | L5: 0 | M5: 5 | O5: 0.98 | Q5: =SUBSTITUTE(C5,"MIN","MAX") -> UC_MarketShare_TRAPASCAR_GSL_MAX | S5: =E5 -> TRAGSL | T5: =F5 -> TRAPASCARDMD | U5: =G5 -> TRAPASCARDMD | V5: =H5 -> 2019 | W5: UP | X5: 1 | Y5: =-MIN(SUMIFS('TRA RESID'!$P:$P,'TRA RESID'!$H:$H,$E5,'TRA RESID'!$I:$I,$F5)/SUMIFS('TRA RESID'!$P:$P,'TRA RESID'!$I:$I,$F5)*AC5,1) -> -0.99907799 | Z5: 0 | AA5: 5 | AC5: 1.02
A6: =A5 -> 1 | C6: =IF(C5="*",C5,"") | E6: =E5 -> TRAGSL | F6: =F5 -> TRAPASCARDMD | G6: =G5 -> TRAPASCARDMD | H6: 2025 | I6: =I5 -> LO | K6: =-SUMIFS('TRA RESID'!$P:$P,'TRA RESID'!$H:$H,$E6,'TRA RESID'!$I:$I,$F6)/SUMIFS('TRA RESID'!$P:$P,'TRA RESID'!$I:$I,$F6)*O6 -> -0.78359058 | O6: 0.8 | Q6: =SUBSTITUTE(C6,"MIN","MAX") | S6: =E6 -> TRAGSL | T6: =F6 -> TRAPASCARDMD | U6: =G6 -> TRAPASCARDMD | V6: 2025 | W6: =W5 -> UP | Y6: =-MIN(SUMIFS('TRA RESID'!$P:$P,'TRA RESID'!$H:$H,$E6,'TRA RESID'!$I:$I,$F6)/SUMIFS('TRA RESID'!$P:$P,'TRA RESID'!$I:$I,$F6)*AC6,1) -> -1 | AC6: 1.2
A7: =A6 -> 1 | C7: =IF(C6="*",C6,"") | E7: =E6 -> TRAGSL | F7: =F6 -> TRAPASCARDMD | G7: =G6 -> TRAPASCARDMD | H7: 2030 | I7: =I6 -> LO | K7: =-SUMIFS('TRA RESID'!$P:$P,'TRA RESID'!$H:$H,$E7,'TRA RESID'!$I:$I,$F7)/SUMIFS('TRA RESID'!$P:$P,'TRA RESID'!$I:$I,$F7)*O7 -> -0.19589764 | O7: 0.2 | Q7: =SUBSTITUTE(C7,"MIN","MAX") | S7: =E7 -> TRAGSL | T7: =F7 -> TRAPASCARDMD | U7: =G7 -> TRAPASCARDMD | V7: 2030 | W7: =W6 -> UP | Y7: =-MIN(SUMIFS('TRA RESID'!$P:$P,'TRA RESID'!$H:$H,$E7,'TRA RESID'!$I:$I,$F7)/SUMIFS('TRA RESID'!$P:$P,'TRA RESID'!$I:$I,$F7)*AC7,1) -> -1 | AC7: 1.5
A8: =A7 -> 1 | C8: =IF(C7="*",C7,"") | E8: =E7 -> TRAGSL | F8: =F7 -> TRAPASCARDMD | G8: =G7 -> TRAPASCARDMD | H8: 2050 | I8: =I7 -> LO | K8: =-SUMIFS('TRA RESID'!$P:$P,'TRA RESID'!$H:$H,$E8,'TRA RESID'!$I:$I,$F8)/SUMIFS('TRA RESID'!$P:$P,'TRA RESID'!$I:$I,$F8)*O8 -> 0 | O8: 0 | Q8: =SUBSTITUTE(C8,"MIN","MAX") | S8: =E8 -> TRAGSL | T8: =F8 -> TRAPASCARDMD | U8: =G8 -> TRAPASCARDMD | V8: 2050 | W8: =W7 -> UP | Y8: =-MIN(SUMIFS('TRA RESID'!$P:$P,'TRA RESID'!$H:$H,$E8,'TRA RESID'!$I:$I,$F8)/SUMIFS('TRA RESID'!$P:$P,'TRA RESID'!$I:$I,$F8)*AC8,1) -> -1 | AC8: 3
A9: =A5+1 -> 2 | C9: =IF(E9="","",IF(_xlfn.XLOOKUP($A9,Selected_constraint!$A:$A,Selected_constraint!$D:$D)=1,"*",IF(SUMIFS('TRA TECH'!$M:$M,'TRA TECH'!$H:$H,E9,'TRA TECH'!$I:$I,F9)=0,"*",IF(SUMIFS('TRA RESID'!$P:$P,'TRA RESID'!$H:$H,$E9,'TRA RESID'!$I:$I,$F9)=0,"*","UC_MarketShare_"&LEFT(F9,LEN(F9)-3)&"_"&RIGHT(E9,3)&"_MIN")))) -> * | E9: =_xlfn.XLOOKUP($A9,Selected_constraint!$A:$A,Selected_constraint!$B:$B) -> TRAETH | F9: =_xlfn.XLOOKUP($A9,Selected_constraint!$A:$A,Selected_constraint!$C:$C) -> TRAPASCARDMD | G9: =F9 -> TRAPASCARDMD | H9: 2019 | I9: LO | J9: 1 | K9: =-SUMIFS('TRA RESID'!$P:$P,'TRA RESID'!$H:$H,$E9,'TRA RESID'!$I:$I,$F9)/SUMIFS('TRA RESID'!$P:$P,'TRA RESID'!$I:$I,$F9)*O9 -> 0 | L9: 0 | M9: 5 | O9: 0.98 | Q9: =SUBSTITUTE(C9,"MIN","MAX") -> * | S9: =E9 -> TRAETH | T9: =F9 -> TRAPASCARDMD | U9: =G9 -> TRAPASCARDMD | V9: 2019 | W9: UP | X9: 1 | Y9: =-MIN(SUMIFS('TRA RESID'!$P:$P,'TRA RESID'!$H:$H,$E9,'TRA RESID'!$I:$I,$F9)/SUMIFS('TRA RESID'!$P:$P,'TRA RESID'!$I:$I,$F9)*AC9,1) -> 0 | Z9: 0 | AA9: 5 | AC9: 1.02
A10: =A9 -> 2 | C10: =IF(C9="*",C9,"") -> * | E10: =E9 -> TRAETH | F10: =F9 -> TRAPASCARDMD | G10: =G9 -> TRAPASCARDMD | H10: 2025 | I10: =I9 -> LO | K10: =-SUMIFS('TRA RESID'!$P:$P,'TRA RESID'!$H:$H,$E10,'TRA RESID'!$I:$I,$F10)/SUMIFS('TRA RESID'!$P:$P,'TRA RESID'!$I:$I,$F10)*O10 -> 0 | O10: 0.8 | Q10: =SUBSTITUTE(C10,"MIN","MAX") -> * | S10: =E10 -> TRAETH | T10: =F10 -> TRAPASCARDMD | U10: =G10 -> TRAPASCARDMD | V10: 2025 | W10: =W9 -> UP | Y10: =-MIN(SUMIFS('TRA RESID'!$P:$P,'TRA RESID'!$H:$H,$E10,'TRA RESID'!$I:$I,$F10)/SUMIFS('TRA RESID'!$P:$P,'TRA RESID'!$I:$I,$F10)*AC10,1) -> 0 | AC10: 1.2
A11: =A10 -> 2 | C11: =IF(C10="*",C10,"") -> * | E11: =E10 -> TRAETH | F11: =F10 -> TRAPASCARDMD | G11: =G10 -> TRAPASCARDMD | H11: 2030 | I11: =I10 -> LO | K11: =-SUMIFS('TRA RESID'!$P:$P,'TRA RESID'!$H:$H,$E11,'TRA RESID'!$I:$I,$F11)/SUMIFS('TRA RESID'!$P:$P,'TRA RESID'!$I:$I,$F11)*O11 -> 0 | O11: 0.2 | Q11: =SUBSTITUTE(C11,"MIN","MAX") -> * | S11: =E11 -> TRAETH | T11: =F11 -> TRAPASCARDMD | U11: =G11 -> TRAPASCARDMD | V11: 2030 | W11: =W10 -> UP | Y11: =-MIN(SUMIFS('TRA RESID'!$P:$P,'TRA RESID'!$H:$H,$E11,'TRA RESID'!$I:$I,$F11)/SUMIFS('TRA RESID'!$P:$P,'TRA RESID'!$I:$I,$F11)*AC11,1) -> 0 | AC11: 1.5
A12: =A11 -> 2 | C12: =IF(C11="*",C11,"") -> * | E12: =E11 -> TRAETH | F12: =F11 -> TRAPASCARDMD | G12: =G11 -> TRAPASCARDMD | H12: 2050 | I12: =I11 -> LO | K12: =-SUMIFS('TRA RESID'!$P:$P,'TRA RESID'!$H:$H,$E12,'TRA RESID'!$I:$I,$F12)/SUMIFS('TRA RESID'!$P:$P,'TRA RESID'!$I:$I,$F12)*O12 -> 0 | O12: 0 | Q12: =SUBSTITUTE(C12,"MIN","MAX") -> * | S12: =E12 -> TRAETH | T12: =F12 -> TRAPASCARDMD | U12: =G12 -> TRAPASCARDMD | V12: 2050 | W12: =W11 -> UP | Y12: =-MIN(SUMIFS('TRA RESID'!$P:$P,'TRA RESID'!$H:$H,$E12,'TRA RESID'!$I:$I,$F12)/SUMIFS('TRA RESID'!$P:$P,'TRA RESID'!$I:$I,$F12)*AC12,1) -> 0 | AC12: 3
A13: =A9+1 -> 3 | C13: =IF(E13="","",IF(_xlfn.XLOOKUP($A13,Selected_constraint!$A:$A,Selected_constraint!$D:$D)=1,"*",IF(SUMIFS('TRA TECH'!$M:$M,'TRA TECH'!$H:$H,E13,'TRA TECH'!$I:$I,F13)=0,"*",IF(SUMIFS('TRA RESID'!$P:$P,'TRA RESID'!$H:$H,$E13,'TRA RESID'!$I:$I,$F13)=0,"*","UC_MarketShare_"&LEFT(F13,LEN(F13)-3)&"_"&RIGHT(E13,3)&"_MIN")))) -> UC_MarketShare_TRAPASCAR_DSL_MIN | E13: =_xlfn.XLOOKUP($A13,Selected_constraint!$A:$A,Selected_constraint!$B:$B) -> TRADSL | F13: =_xlfn.XLOOKUP($A13,Selected_constraint!$A:$A,Selected_constraint!$C:$C) -> TRAPASCARDMD | G13: =F13 -> TRAPASCARDMD | H13: 2019 | I13: LO | J13: 1 | K13: =-SUMIFS('TRA RESID'!$P:$P,'TRA RESID'!$H:$H,$E13,'TRA RESID'!$I:$I,$F13)/SUMIFS('TRA RESID'!$P:$P,'TRA RESID'!$I:$I,$F13)*O13 -> -0.01085329 | L13: 0 | M13: 5 | O13: 0.98 | Q13: =SUBSTITUTE(C13,"MIN","MAX") -> UC_MarketShare_TRAPASCAR_DSL_MAX | S13: =E13 -> TRADSL | T13: =F13 -> TRAPASCARDMD | U13: =G13 -> TRAPASCARDMD | V13: 2019 | W13: UP | X13: 1 | Y13: =-MIN(SUMIFS('TRA RESID'!$P:$P,'TRA RESID'!$H:$H,$E13,'TRA RESID'!$I:$I,$F13)/SUMIFS('TRA RESID'!$P:$P,'TRA RESID'!$I:$I,$F13)*AC13,1) -> -0.011296282 | Z13: 0 | AA13: 5 | AC13: 1.02
A14: =A13 -> 3 | C14: =IF(C13="*",C13,"") | E14: =E13 -> TRADSL | F14: =F13 -> TRAPASCARDMD | G14: =G13 -> TRAPASCARDMD | H14: 2025 | I14: =I13 -> LO | K14: =-SUMIFS('TRA RESID'!$P:$P,'TRA RESID'!$H:$H,$E14,'TRA RESID'!$I:$I,$F14)/SUMIFS('TRA RESID'!$P:$P,'TRA RESID'!$I:$I,$F14)*O14 -> -0.0088598287 | O14: 0.8 | Q14: =SUBSTITUTE(C14,"MIN","MAX") | S14: =E14 -> TRADSL | T14: =F14 -> TRAPASCARDMD | U14: =G14 -> TRAPASCARDMD | V14: 2025 | W14: =W13 -> UP | Y14: =-MIN(SUMIFS('TRA RESID'!$P:$P,'TRA RESID'!$H:$H,$E14,'TRA RESID'!$I:$I,$F14)/SUMIFS('TRA RESID'!$P:$P,'TRA RESID'!$I:$I,$F14)*AC14,1) -> -0.013289743 | AC14: 1.2
A15: =A14 -> 3 | C15: =IF(C14="*",C14,"") | E15: =E14 -> TRADSL | F15: =F14 -> TRAPASCARDMD | G15: =G14 -> TRAPASCARDMD | H15: 2030 | I15: =I14 -> LO | K15: =-SUMIFS('TRA RESID'!$P:$P,'TRA RESID'!$H:$H,$E15,'TRA RESID'!$I:$I,$F15)/SUMIFS('TRA RESID'!$P:$P,'TRA RESID'!$I:$I,$F15)*O15 -> -0.0022149572 | O15: 0.2 | Q15: =SUBSTITUTE(C15,"MIN","MAX") | S15: =E15 -> TRADSL | T15: =F15 -> TRAPASCARDMD | U15: =G15 -> TRAPASCARDMD | V15: 2030 | W15: =W14 -> UP | Y15: =-MIN(SUMIFS('TRA RESID'!$P:$P,'TRA RESID'!$H:$H,$E15,'TRA RESID'!$I:$I,$F15)/SUMIFS('TRA RESID'!$P:$P,'TRA RESID'!$I:$I,$F15)*AC15,1) -> -0.016612179 | AC15: 1.5
A16: =A15 -> 3 | C16: =IF(C15="*",C15,"") | E16: =E15 -> TRADSL | F16: =F15 -> TRAPASCARDMD | G16: =G15 -> TRAPASCARDMD | H16: 2050 | I16: =I15 -> LO | K16: =-SUMIFS('TRA RESID'!$P:$P,'TRA RESID'!$H:$H,$E16,'TRA RESID'!$I:$I,$F16)/SUMIFS('TRA RESID'!$P:$P,'TRA RESID'!$I:$I,$F16)*O16 -> 0 | O16: 0 | Q16: =SUBSTITUTE(C16,"MIN","MAX") | S16: =E16 -> TRADSL | T16: =F16 -> TRAPASCARDMD | U16: =G16 -> TRAPASCARDMD | V16: 2050 | W16: =W15 -> UP | Y16: =-MIN(SUMIFS('TRA RESID'!$P:$P,'TRA RESID'!$H:$H,$E16,'TRA RESID'!$I:$I,$F16)/SUMIFS('TRA RESID'!$P:$P,'TRA RESID'!$I:$I,$F16)*AC16,1) -> -0.033224358 | AC16: 3
A17: =A13+1 -> 4 | C17: =IF(E17="","",IF(_xlfn.XLOOKUP($A17,Selected_constraint!$A:$A,Selected_constraint!$D:$D)=1,"*",IF(SUMIFS('TRA TECH'!$M:$M,'TRA TECH'!$H:$H,E17,'TRA TECH'!$I:$I,F17)=0,"*",IF(SUMIFS('TRA RESID'!$P:$P,'TRA RESID'!$H:$H,$E17,'TRA RESID'!$I:$I,$F17)=0,"*","UC_MarketShare_"&LEFT(F17,LEN(F17)-3)&"_"&RIGHT(E17,3)&"_MIN")))) -> * | E17: =_xlfn.XLOOKUP($A17,Selected_constraint!$A:$A,Selected_constraint!$B:$B) -> TRARDS | F17: =_xlfn.XLOOKUP($A17,Selected_constraint!$A:$A,Selected_constraint!$C:$C) -> TRAPASCARDMD | G17: =F17 -> TRAPASCARDMD | H17: 2019 | I17: LO | J17: 1 | K17: =-SUMIFS('TRA RESID'!$P:$P,'TRA RESID'!$H:$H,$E17,'TRA RESID'!$I:$I,$F17)/SUMIFS('TRA RESID'!$P:$P,'TRA RESID'!$I:$I,$F17)*O17 -> 0 | L17: 0 | M17: 5 | O17: 0.98 | Q17: =SUBSTITUTE(C17,"MIN","MAX") -> * | S17: =E17 -> TRARDS | T17: =F17 -> TRAPASCARDMD | U17: =G17 -> TRAPASCARDMD | V17: 2019 | W17: UP | X17: 1 | Y17: =-MIN(SUMIFS('TRA RESID'!$P:$P,'TRA RESID'!$H:$H,$E17,'TRA RESID'!$I:$I,$F17)/SUMIFS('TRA RESID'!$P:$P,'TRA RESID'!$I:$I,$F17)*AC17,1) -> 0 | Z17: 0 | AA17: 5 | AC17: 1.02
A18: =A17 -> 4 | C18: =IF(C17="*",C17,"") -> * | E18: =E17 -> TRARDS | F18: =F17 -> TRAPASCARDMD | G18: =G17 -> TRAPASCARDMD | H18: 2025 | I18: =I17 -> LO | K18: =-SUMIFS('TRA RESID'!$P:$P,'TRA RESID'!$H:$H,$E18,'TRA RESID'!$I:$I,$F18)/SUMIFS('TRA RESID'!$P:$P,'TRA RESID'!$I:$I,$F18)*O18 -> 0 | O18: 0.8 | Q18: =SUBSTITUTE(C18,"MIN","MAX") -> * | S18: =E18 -> TRARDS | T18: =F18 -> TRAPASCARDMD | U18: =G18 -> TRAPASCARDMD | V18: 2025 | W18: =W17 -> UP | Y18: =-MIN(SUMIFS('TRA RESID'!$P:$P,'TRA RESID'!$H:$H,$E18,'TRA RESID'!$I:$I,$F18)/SUMIFS('TRA RESID'!$P:$P,'TRA RESID'!$I:$I,$F18)*AC18,1) -> 0 | AC18: 1.2
A19: =A18 -> 4 | C19: =IF(C18="*",C18,"") -> * | E19: =E18 -> TRARDS | F19: =F18 -> TRAPASCARDMD | G19: =G18 -> TRAPASCARDMD | H19: 2030 | I19: =I18 -> LO | K19: =-SUMIFS('TRA RESID'!$P:$P,'TRA RESID'!$H:$H,$E19,'TRA RESID'!$I:$I,$F19)/SUMIFS('TRA RESID'!$P:$P,'TRA RESID'!$I:$I,$F19)*O19 -> 0 | O19: 0.2 | Q19: =SUBSTITUTE(C19,"MIN","MAX") -> * | S19: =E19 -> TRARDS | T19: =F19 -> TRAPASCARDMD | U19: =G19 -> TRAPASCARDMD | V19: 2030 | W19: =W18 -> UP | Y19: =-MIN(SUMIFS('TRA RESID'!$P:$P,'TRA RESID'!$H:$H,$E19,'TRA RESID'!$I:$I,$F19)/SUMIFS('TRA RESID'!$P:$P,'TRA RESID'!$I:$I,$F19)*AC19,1) -> 0 | AC19: 1.5
A20: =A19 -> 4 | C20: =IF(C19="*",C19,"") -> * | E20: =E19 -> TRARDS | F20: =F19 -> TRAPASCARDMD | G20: =G19 -> TRAPASCARDMD | H20: 2050 | I20: =I19 -> LO | K20: =-SUMIFS('TRA RESID'!$P:$P,'TRA RESID'!$H:$H,$E20,'TRA RESID'!$I:$I,$F20)/SUMIFS('TRA RESID'!$P:$P,'TRA RESID'!$I:$I,$F20)*O20 -> 0 | O20: 0 | Q20: =SUBSTITUTE(C20,"MIN","MAX") -> * | S20: =E20 -> TRARDS | T20: =F20 -> TRAPASCARDMD | U20: =G20 -> TRAPASCARDMD | V20: 2050 | W20: =W19 -> UP | Y20: =-MIN(SUMIFS('TRA RESID'!$P:$P,'TRA RESID'!$H:$H,$E20,'TRA RESID'!$I:$I,$F20)/SUMIFS('TRA RESID'!$P:$P,'TRA RESID'!$I:$I,$F20)*AC20,1) -> 0 | AC20: 3
A21: =A17+1 -> 5 | C21: =IF(E21="","",IF(_xlfn.XLOOKUP($A21,Selected_constraint!$A:$A,Selected_constraint!$D:$D)=1,"*",IF(SUMIFS('TRA TECH'!$M:$M,'TRA TECH'!$H:$H,E21,'TRA TECH'!$I:$I,F21)=0,"*",IF(SUMIFS('TRA RESID'!$P:$P,'TRA RESID'!$H:$H,$E21,'TRA RESID'!$I:$I,$F21)=0,"*","UC_MarketShare_"&LEFT(F21,LEN(F21)-3)&"_"&RIGHT(E21,3)&"_MIN")))) -> * | E21: =_xlfn.XLOOKUP($A21,Selected_constraint!$A:$A,Selected_constraint!$B:$B) -> TRABDS | F21: =_xlfn.XLOOKUP($A21,Selected_constraint!$A:$A,Selected_constraint!$C:$C) -> TRAPASCARDMD | G21: =F21 -> TRAPASCARDMD | H21: 2019 | I21: LO | J21: 1 | K21: =-SUMIFS('TRA RESID'!$P:$P,'TRA RESID'!$H:$H,$E21,'TRA RESID'!$I:$I,$F21)/SUMIFS('TRA RESID'!$P:$P,'TRA RESID'!$I:$I,$F21)*O21 -> 0 | L21: 0 | M21: 5 | O21: 0.98 | Q21: =SUBSTITUTE(C21,"MIN","MAX") -> * | S21: =E21 -> TRABDS | T21: =F21 -> TRAPASCARDMD | U21: =G21 -> TRAPASCARDMD | V21: 2019 | W21: UP | X21: 1 | Y21: =-MIN(SUMIFS('TRA RESID'!$P:$P,'TRA RESID'!$H:$H,$E21,'TRA RESID'!$I:$I,$F21)/SUMIFS('TRA RESID'!$P:$P,'TRA RESID'!$I:$I,$F21)*AC21,1) -> 0 | Z21: 0 | AA21: 5 | AC21: 1.02
A22: =A21 -> 5 | C22: =IF(C21="*",C21,"") -> * | E22: =E21 -> TRABDS | F22: =F21 -> TRAPASCARDMD | G22: =G21 -> TRAPASCARDMD | H22: 2025 | I22: =I21 -> LO | K22: =-SUMIFS('TRA RESID'!$P:$P,'TRA RESID'!$H:$H,$E22,'TRA RESID'!$I:$I,$F22)/SUMIFS('TRA RESID'!$P:$P,'TRA RESID'!$I:$I,$F22)*O22 -> 0 | O22: 0.8 | Q22: =SUBSTITUTE(C22,"MIN","MAX") -> * | S22: =E22 -> TRABDS | T22: =F22 -> TRAPASCARDMD | U22: =G22 -> TRAPASCARDMD | V22: 2025 | W22: =W21 -> UP | Y22: =-MIN(SUMIFS('TRA RESID'!$P:$P,'TRA RESID'!$H:$H,$E22,'TRA RESID'!$I:$I,$F22)/SUMIFS('TRA RESID'!$P:$P,'TRA RESID'!$I:$I,$F22)*AC22,1) -> 0 | AC22: 1.2
A23: =A22 -> 5 | C23: =IF(C22="*",C22,"") -> * | E23: =E22 -> TRABDS | F23: =F22 -> TRAPASCARDMD | G23: =G22 -> TRAPASCARDMD | H23: 2030 | I23: =I22 -> LO | K23: =-SUMIFS('TRA RESID'!$P:$P,'TRA RESID'!$H:$H,$E23,'TRA RESID'!$I:$I,$F23)/SUMIFS('TRA RESID'!$P:$P,'TRA RESID'!$I:$I,$F23)*O23 -> 0 | O23: 0.2 | Q23: =SUBSTITUTE(C23,"MIN","MAX") -> * | S23: =E23 -> TRABDS | T23: =F23 -> TRAPASCARDMD | U23: =G23 -> TRAPASCARDMD | V23: 2030 | W23: =W22 -> UP | Y23: =-MIN(SUMIFS('TRA RESID'!$P:$P,'TRA RESID'!$H:$H,$E23,'TRA RESID'!$I:$I,$F23)/SUMIFS('TRA RESID'!$P:$P,'TRA RESID'!$I:$I,$F23)*AC23,1) -> 0 | AC23: 1.5
A24: =A23 -> 5 | C24: =IF(C23="*",C23,"") -> * | E24: =E23 -> TRABDS | F24: =F23 -> TRAPASCARDMD | G24: =G23 -> TRAPASCARDMD | H24: 2050 | I24: =I23 -> LO | K24: =-SUMIFS('TRA RESID'!$P:$P,'TRA RESID'!$H:$H,$E24,'TRA RESID'!$I:$I,$F24)/SUMIFS('TRA RESID'!$P:$P,'TRA RESID'!$I:$I,$F24)*O24 -> 0 | O24: 0 | Q24: =SUBSTITUTE(C24,"MIN","MAX") -> * | S24: =E24 -> TRABDS | T24: =F24 -> TRAPASCARDMD | U24: =G24 -> TRAPASCARDMD | V24: 2050 | W24: =W23 -> UP | Y24: =-MIN(SUMIFS('TRA RESID'!$P:$P,'TRA RESID'!$H:$H,$E24,'TRA RESID'!$I:$I,$F24)/SUMIFS('TRA RESID'!$P:$P,'TRA RESID'!$I:$I,$F24)*AC24,1) -> 0 | AC24: 3
A25: =A21+1 -> 6 | C25: =IF(E25="","",IF(_xlfn.XLOOKUP($A25,Selected_constraint!$A:$A,Selected_constraint!$D:$D)=1,"*",IF(SUMIFS('TRA TECH'!$M:$M,'TRA TECH'!$H:$H,E25,'TRA TECH'!$I:$I,F25)=0,"*",IF(SUMIFS('TRA RESID'!$P:$P,'TRA RESID'!$H:$H,$E25,'TRA RESID'!$I:$I,$F25)=0,"*","UC_MarketShare_"&LEFT(F25,LEN(F25)-3)&"_"&RIGHT(E25,3)&"_MIN")))) -> * | E25: =_xlfn.XLOOKUP($A25,Selected_constraint!$A:$A,Selected_constraint!$B:$B) -> TRACNG | F25: =_xlfn.XLOOKUP($A25,Selected_constraint!$A:$A,Selected_constraint!$C:$C) -> TRAPASCARDMD | G25: =F25 -> TRAPASCARDMD | H25: 2019 | I25: LO | J25: 1 | K25: =-SUMIFS('TRA RESID'!$P:$P,'TRA RESID'!$H:$H,$E25,'TRA RESID'!$I:$I,$F25)/SUMIFS('TRA RESID'!$P:$P,'TRA RESID'!$I:$I,$F25)*O25 -> 0 | L25: 0 | M25: 5 | O25: 0.98 | Q25: =SUBSTITUTE(C25,"MIN","MAX") -> * | S25: =E25 -> TRACNG | T25: =F25 -> TRAPASCARDMD | U25: =G25 -> TRAPASCARDMD | V25: 2019 | W25: UP | X25: 1 | Y25: =-MIN(SUMIFS('TRA RESID'!$P:$P,'TRA RESID'!$H:$H,$E25,'TRA RESID'!$I:$I,$F25)/SUMIFS('TRA RESID'!$P:$P,'TRA RESID'!$I:$I,$F25)*AC25,1) -> 0 | Z25: 0 | AA25: 5 | AC25: 1.02
A26: =A25 -> 6 | C26: =IF(C25="*",C25,"") -> * | E26: =E25 -> TRACNG | F26: =F25 -> TRAPASCARDMD | G26: =G25 -> TRAPASCARDMD | H26: 2025 | I26: =I25 -> LO | K26: =-SUMIFS('TRA RESID'!$P:$P,'TRA RESID'!$H:$H,$E26,'TRA RESID'!$I:$I,$F26)/SUMIFS('TRA RESID'!$P:$P,'TRA RESID'!$I:$I,$F26)*O26 -> 0 | O26: 0.8 | Q26: =SUBSTITUTE(C26,"MIN","MAX") -> * | S26: =E26 -> TRACNG | T26: =F26 -> TRAPASCARDMD | U26: =G26 -> TRAPASCARDMD | V26: 2025 | W26: =W25 -> UP | Y26: =-MIN(SUMIFS('TRA RESID'!$P:$P,'TRA RESID'!$H:$H,$E26,'TRA RESID'!$I:$I,$F26)/SUMIFS('TRA RESID'!$P:$P,'TRA RESID'!$I:$I,$F26)*AC26,1) -> 0 | AC26: 1.2
A27: =A26 -> 6 | C27: =IF(C26="*",C26,"") -> * | E27: =E26 -> TRACNG | F27: =F26 -> TRAPASCARDMD | G27: =G26 -> TRAPASCARDMD | H27: 2030 | I27: =I26 -> LO | K27: =-SUMIFS('TRA RESID'!$P:$P,'TRA RESID'!$H:$H,$E27,'TRA RESID'!$I:$I,$F27)/SUMIFS('TRA RESID'!$P:$P,'TRA RESID'!$I:$I,$F27)*O27 -> 0 | O27: 0.2 | Q27: =SUBSTITUTE(C27,"MIN","MAX") -> * | S27: =E27 -> TRACNG | T27: =F27 -> TRAPASCARDMD | U27: =G27 -> TRAPASCARDMD | V27: 2030 | W27: =W26 -> UP | Y27: =-MIN(SUMIFS('TRA RESID'!$P:$P,'TRA RESID'!$H:$H,$E27,'TRA RESID'!$I:$I,$F27)/SUMIFS('TRA RESID'!$P:$P,'TRA RESID'!$I:$I,$F27)*AC27,1) -> 0 | AC27: 1.5
A28: =A27 -> 6 | C28: =IF(C27="*",C27,"") -> * | E28: =E27 -> TRACNG | F28: =F27 -> TRAPASCARDMD | G28: =G27 -> TRAPASCARDMD | H28: 2050 | I28: =I27 -> LO | K28: =-SUMIFS('TRA RESID'!$P:$P,'TRA RESID'!$H:$H,$E28,'TRA RESID'!$I:$I,$F28)/SUMIFS('TRA RESID'!$P:$P,'TRA RESID'!$I:$I,$F28)*O28 -> 0 | O28: 0 | Q28: =SUBSTITUTE(C28,"MIN","MAX") -> * | S28: =E28 -> TRACNG | T28: =F28 -> TRAPASCARDMD | U28: =G28 -> TRAPASCARDMD | V28: 2050 | W28: =W27 -> UP | Y28: =-MIN(SUMIFS('TRA RESID'!$P:$P,'TRA RESID'!$H:$H,$E28,'TRA RESID'!$I:$I,$F28)/SUMIFS('TRA RESID'!$P:$P,'TRA RESID'!$I:$I,$F28)*AC28,1) -> 0 | AC28: 3
A29: =A25+1 -> 7 | C29: =IF(E29="","",IF(_xlfn.XLOOKUP($A29,Selected_constraint!$A:$A,Selected_constraint!$D:$D)=1,"*",IF(SUMIFS('TRA TECH'!$M:$M,'TRA TECH'!$H:$H,E29,'TRA TECH'!$I:$I,F29)=0,"*",IF(SUMIFS('TRA RESID'!$P:$P,'TRA RESID'!$H:$H,$E29,'TRA RESID'!$I:$I,$F29)=0,"*","UC_MarketShare_"&LEFT(F29,LEN(F29)-3)&"_"&RIGHT(E29,3)&"_MIN")))) -> * | E29: =_xlfn.XLOOKUP($A29,Selected_constraint!$A:$A,Selected_constraint!$B:$B) -> TRARNG | F29: =_xlfn.XLOOKUP($A29,Selected_constraint!$A:$A,Selected_constraint!$C:$C) -> TRAPASCARDMD | G29: =F29 -> TRAPASCARDMD | H29: 2019 | I29: LO | J29: 1 | K29: =-SUMIFS('TRA RESID'!$P:$P,'TRA RESID'!$H:$H,$E29,'TRA RESID'!$I:$I,$F29)/SUMIFS('TRA RESID'!$P:$P,'TRA RESID'!$I:$I,$F29)*O29 -> 0 | L29: 0 | M29: 5 | O29: 0.98 | Q29: =SUBSTITUTE(C29,"MIN","MAX") -> * | S29: =E29 -> TRARNG | T29: =F29 -> TRAPASCARDMD | U29: =G29 -> TRAPASCARDMD | V29: 2019 | W29: UP | X29: 1 | Y29: =-MIN(SUMIFS('TRA RESID'!$P:$P,'TRA RESID'!$H:$H,$E29,'TRA RESID'!$I:$I,$F29)/SUMIFS('TRA RESID'!$P:$P,'TRA RESID'!$I:$I,$F29)*AC29,1) -> 0 | Z29: 0 | AA29: 5 | AC29: 1.02
A30: =A29 -> 7 | C30: =IF(C29="*",C29,"") -> * | E30: =E29 -> TRARNG | F30: =F29 -> TRAPASCARDMD | G30: =G29 -> TRAPASCARDMD | H30: 2025 | I30: =I29 -> LO | K30: =-SUMIFS('TRA RESID'!$P:$P,'TRA RESID'!$H:$H,$E30,'TRA RESID'!$I:$I,$F30)/SUMIFS('TRA RESID'!$P:$P,'TRA RESID'!$I:$I,$F30)*O30 -> 0 | O30: 0.8 | Q30: =SUBSTITUTE(C30,"MIN","MAX") -> * | S30: =E30 -> TRARNG | T30: =F30 -> TRAPASCARDMD | U30: =G30 -> TRAPASCARDMD | V30: 2025 | W30: =W29 -> UP | Y30: =-MIN(SUMIFS('TRA RESID'!$P:$P,'TRA RESID'!$H:$H,$E30,'TRA RESID'!$I:$I,$F30)/SUMIFS('TRA RESID'!$P:$P,'TRA RESID'!$I:$I,$F30)*AC30,1) -> 0 | AC30: 1.2
