Workbook
Name __HDV50: #REF!
Name __LDV50: #REF!
Name _1995_Implicit_GDP_Deflator: #REF!
Name _2001_Implicit_GDP_Deflator: #REF!
Name _HDV50: #REF!
Name _LDV50: #REF!
Name Age_of_car: #REF!
Name AnswerData: #REF!
Name avg_water_heater_PJ: #REF!
Name bprint: #REF!
Name btu_per_watthr: #REF!
Name CAPCST: #REF!
Name CMM_SUPPLY_CRV_TABLE: #REF!
Name conv: #REF!
Name cprint: #REF!
Name CRI: #REF!
Name days_per_year: #REF!
Name Diesel_Car_CO: #REF!
Name Diesel_Car_Nox: #REF!
Name Diesel_Car_PM: #REF!
Name Diesel_Car_VOCs: #REF!
Name Diesel_HDT_CO: #REF!
Name Diesel_HDT_NOx: #REF!
Name Diesel_HDT_PM: #REF!
Name Diesel_HDT_SO2: #REF!
Name Diesel_HDT_VOCs: #REF!
Name Diesel_LDT_CO: #REF!
Name Diesel_LDT_Nox: #REF!
Name Diesel_LDT_PM: #REF!
Name Diesel_LDT_VOCs: #REF!
Name dollar____per__m: #REF!
Name EFFICIENCY: #REF!
Name exch_rate: #REF!
Name fitfile: #REF!
Name FUEL: #REF!
Name Gas_Car_CO: #REF!
Name Gas_Car_Nox: #REF!
Name Gas_Car_PM: #REF!
Name Gas_Car_VOC: #REF!
Name Gas_HDT_CO: #REF!
Name Gas_HDT_NOx: #REF!
Name Gas_HDT_PM: #REF!
Name Gas_HDT_SO2: #REF!
Name Gas_HDT_VOCs: #REF!
Name Gas_LDT_CO: #REF!
Name Gas_LDT_NOx: #REF!
Name Gas_LDT_PM: #REF!
Name Gas_LDT_VOCs: #REF!
Name hours_per_day: #REF!
Name INF: #REF!
Name j_per_btu: #REF!
Name j_per_pj: #REF!
Name joules_per_btu: #REF!
Name kwhr_per_j: #REF!
Name LIFE: #REF!
Name lumens_per_billion_lumens: #REF!
Name MAINTCST: #REF!
Name MAXREC: #REF!
Name million_short_tons_to_short_ton: #REF!
Name MMBTU_to_PJ: #REF!

Sheet ReadMe
A1: Generic Comet (GC) TIMES Supply
B3: Sheet color
C4: Raw Data and Parameters
C6: City Specific Data
C8: Post processing for TIMES
C10: Table formatted for TIMES

Sheet >> City Data

Sheet City characteristics
B2: City Basic Data
B4: Calibration methodology | C4: GHG Inventory
B6: A. City Characteristics
B7: Data Item | C7: Value | D7: Units
B8: City Name | C8: New York
B9: Latitude | C9: 40.5
B10: Longitude | C10: -75
B11: County | C11: New York County
B12: State | C12: New York
B13: Census Division | C13: Middle Atlantic
B14: Climate Division | C14: Northeast
B15: Egrid Region | C15: NPCC NYC/Westchester
B16: Area of city (excluding water, natural and agricultural areas) | C16: 778 | D16: square kilometers
B17: * Division and Region Map can be found in the Maps sheet.
B18: B. Planning Base Year and Target Years
B19: Year | C19: Value | D19: Units
B20: Base Year | C20: 2019 | D20: Acceptable range [2018,2021]
B21: End Year | C21: 2050
B23: C. City Population and GDP
B24: Data Item | C24: Value | D24: Units
B25: Population in Base Year | C25: 8337 | D25: Thousand of people
B26: Annual population growth (Base Year - End Year) | C26: 0.5 | D26: % people
B27: GDP in Base Year | C27: 1206000 | D27: Million US$
B28: Annual GDP growth rate | C28: 2 | D28: % US$
B29: Share of manufacturing GDP | C29: 5 | D29: % US$
B30: Share of State population | C30: 0.42835123
B31: Share of State GDP | C31: 0.67251772
B32: Adjustment from state manufacturing GDP | C32: 1.0638298
B34: D. Climate Data
B35: Data Item | C35: 2000 | D35: 2050 | E35: 2100 | F35: Units
B36: Heating degree days (HDD) | C36: 4473.4625 | D36: 4066.4182 | E36: 3763.8582 | F36: F
B37: Cooling degree days (CDD) | C37: 1020.7333 | D37: 1224.2555 | E37: 1375.5355 | F37: F
B39: Data Item | C39: Value | D39: Units
B40: Correction from State HDD | C40: 0.72727402
B41: Correction from State CDD | C41: 1.5583715
B42: Annual precipitation | C42: 762 | D42: mm / year
B43: Climate change scenario | C43: RCP4.5
B44: Average temperature increase in 1980-2020 | C44: 1.4617857 | D44: F
B45: Forecasted average temperature increase in 2035-2065 | C45: 3.13 | D45: F
B46: Forecasted average temperature increase in 2070-2100 | C46: 4.37 | D46: F
...

Sheet >> EPAUS9R

Sheet RES_Pollutants
B4: CommName | C4: RESDSL | D4: RESKER | E4: RESLPG | F4: RESNGA
B5: * Units | C5: Kt/PJ | D5: Kt/PJ | E5: Kt/PJ | F5: Kt/PJ
B6: RESSO2 | C6: 0.1320615 | D6: 0.13567165 | E6: 0.00028147728 | F6: 0.00025069701
B7: RESNOX | C7: 0.055800636 | D7: 0.05732605 | E7: 0.062863259 | F7: 0.039275865
B8: RESPM10 | C8: 0.077180565 | D8: 0.076294281 | E8: 0.065711628 | F8: 0.055983606
B9: RESPM25 | C9: 0.0066030752 | D9: 0.0065288001 | E9: 0.00018765152 | F9: 0.00017966619

Sheet IND_Pollutants
B4: CommName | C4: INDCOA | D4: INDDSL | E4: INDLPG | F4: INDMET | G4: INDNGA | H4: INDPTC | I4: INDRFL | J4: INDKER
B5: * Units | C5: Kt/PJ | D5: Kt/PJ | E5: Kt/PJ | F5: Kt/PJ | G5: Kt/PJ | H5: Kt/PJ | I5: Kt/PJ | J5: Kt/PJ
B6: INDNOX | C6: 0.24981209 | D6: 0.24815832 | E6: 0.38225412 | F6: 0.3219 | G6: 0.1302863 | H6: 0.7309 | I6: 0.18976807 | J6: 0.093778378
B7: INDSO2 | C7: 0.37430996 | D7: 0.029100705 | E7: 0.023822316 | F7: 0.85683708 | G7: 0.003376146 | H7: 0.7823043 | I7: 0.21970918 | J7: 0.093828105
B8: INDPM10 | C8: 0.062301616 | D8: 0.034232243 | E8: 0.028042914 | F8: 0.16470751 | G8: 0.0062704735 | H8: 0.16470751 | I8: 0.024921326 | J8: 0.093813563
B9: INDPM25 | C9: 0.029558468 | D9: 0.030723954 | E9: 0.028055577 | F9: 0.063126274 | G9: 0.0062893796 | H9: 0.063126274 | I9: 0.018765653 | J9: 0.093813132

Sheet COM_Pollutants
B4: CommName | C4: COMDSL | D4: COMKER | E4: COMLPG | F4: COMNGA | G4: COMRFL
B5: * Units | C5: Kt/PJ | D5: Kt/PJ | E5: Kt/PJ | F5: Kt/PJ | G5: Kt/PJ
B6: COMSO2 | C6: 0.13282188 | D6: 0.13567165 | E6: 0.0067703971 | F6: 0.00025069701 | G6: 1.014615
B7: COMNOX | C7: 0.047059231 | D7: 0.061466265 | E7: 0.066733568 | F7: 0.041782835 | G7: 0.15360397
B8: COMPM10 | C8: 0.0073780841 | D8: 0.0074523865 | E8: =D8 -> 0.0074523865 | F8: 0.0036351067 | G8: 0.018131316
B9: COMPM25 | C9: 0.0066030752 | D9: 0.0066880392 | E9: 0.00046605731 | F9: 0.0031754648 | G9: 0.0094449205

Sheet ELC_Pollutants
B2: TechName | C2: TechDesc | D2: Comm-IN | E2: Comm-OUT | F2: ENV_ACT~ELCNOX~2015 | G2: ENV_ACT~ELCNOX~2020 | H2: ENV_ACT~ELCNOX~2025 | I2: ENV_ACT~ELCNOX~2030 | J2: ENV_ACT~ELCNOX~2055 | K2: ENV_ACT~ELCPM10~2010 | L2: ENV_ACT~ELCPM10~2015 | M2: ENV_ACT~ELCPM10~2020 | N2: ENV_ACT~ELCPM10~2025 | O2: ENV_ACT~ELCPM10~2030 | P2: ENV_ACT~ELCPM10~2055 | Q2: ENV_ACT~ELCPM25~2015 | R2: ENV_ACT~ELCPM25~2020 | S2: ENV_ACT~ELCPM25~2025 | T2: ENV_ACT~ELCPM25~2030 | U2: ENV_ACT~ELCPM25~2055 | V2: ENV_ACT~ELCSO2~2015 | W2: ENV_ACT~ELCSO2~2020 | X2: ENV_ACT~ELCSO2~2025 | Y2: ENV_ACT~ELCSO2~2030 | Z2: ENV_ACT~ELCSO2~2055
B3: *Technology Name | C3: Technology Description | D3: Input Commodity | E3: Output Commodity | F3: Activity based emissions | G3: Activity based emissions | H3: Activity based emissions | I3: Activity based emissions | J3: Activity based emissions | K3: Activity based emissions | L3: Activity based emissions | M3: Activity based emissions | N3: Activity based emissions | O3: Activity based emissions | P3: Activity based emissions | Q3: Activity based emissions | R3: Activity based emissions | S3: Activity based emissions | T3: Activity based emissions | U3: Activity based emissions | V3: Activity based emissions | W3: Activity based emissions | X3: Activity based emissions | Y3: Activity based emissions | Z3: Activity based emissions
B4: *Units | C4: *Description | E4: \l:
B5: SEELCDSL | C5: Emissions: DSL to ELC | D5: ELCDSL | E5: ELCDSLEA | F5: 0.23 | G5: 0.199 | H5: 0.217 | I5: 0.196 | J5: 0.196 | K5: 0.034 | L5: 0.015 | M5: 0.014 | N5: 0.015 | O5: 0.014 | P5: 0.014 | Q5: 0.006 | R5: 0.005 | S5: 0.006 | T5: 0.005 | U5: 0.005 | V5: 0.044 | W5: 0.034 | X5: 0.032 | Y5: 0.025 | Z5: 0.025
B6: SEELCNGT | C6: Emissions: NGA to ELC (Turbine) | D6: ELCNGA | E6: ELCNGAEA | F6: 0.031 | G6: 0.031 | H6: 0.031 | I6: 0.031 | J6: 0.031 | K6: 0.003 | L6: 0.003 | M6: 0.003 | N6: 0.003 | O6: 0.003 | P6: 0.003 | Q6: 0.003 | R6: 0.003 | S6: 0.003 | T6: 0.003 | U6: 0.003 | V6: 0.001 | W6: 0.001 | X6: 0.001 | Y6: 0.001 | Z6: 0.001
B7: SEELCNGC | C7: Emissions: NGA to ELC (Combined Cycle) | D7: ELCNGA | E7: ELCNGCEA | F7: 0.009 | G7: 0.009 | H7: 0.009 | I7: 0.009 | J7: 0.009
B8: SEELCNGS | C8: Emissions: NGA to ELC (Steam) | D8: ELCNGA | E8: ELCNGSEA | F8: 0.067 | G8: 0.06 | H8: 0.054 | I8: 0.047 | J8: 0.047 | K8: 0.003 | L8: 0.003 | M8: 0.003 | N8: 0.003 | O8: 0.003 | P8: 0.003 | Q8: 0.003 | R8: 0.003 | S8: 0.003 | T8: 0.003 | U8: 0.003
B9: SEELCRFL | C9: Emissions: RFL to ELC | D9: ELCRFL | E9: ELCRFLEA
B10: SEELCRFH | C10: Emissions: RFH to ELC | D10: ELCRFH | E10: ELCRFHPS | F10: 0.112 | G10: 0.097 | H10: 0.087 | I10: 0.077 | J10: 0.077 | K10: 0.012 | L10: 0.012 | M10: 0.01 | N10: 0.009 | O10: 0.008 | P10: 0.008 | Q10: 0.01 | R10: 0.009 | S10: 0.008 | T10: 0.007 | U10: 0.007 | V10: 0.273 | W10: 0.232 | X10: 0.204 | Y10: 0.176 | Z10: 0.176
B11: SEELCRFL | C11: Emissions: RFL to ELC | D11: ELCRFL | E11: ELCRFLPS | F11: 0.112 | G11: 0.097 | H11: 0.087 | I11: 0.077 | J11: 0.077 | K11: 0.012 | L11: 0.012 | M11: 0.01 | N11: 0.009 | O11: 0.008 | P11: 0.008 | Q11: 0.01 | R11: 0.009 | S11: 0.008 | T11: 0.007 | U11: 0.007 | V11: 0.273 | W11: 0.232 | X11: 0.204 | Y11: 0.176 | Z11: 0.176
B12: SEELCBIGCC | C12: Emissions: Biomass to ELC (IGCC) | D12: ELCBIO | E12: ELCBIGCCEA | F12: 0.059 | G12: 0.059 | H12: 0.059 | I12: 0.059 | J12: 0.059 | K12: 0.008 | L12: 0.008 | M12: 0.008 | N12: 0.008 | O12: 0.008 | P12: 0.008 | Q12: 0.008 | R12: 0.008 | S12: 0.008 | T12: 0.008 | U12: 0.008 | V12: 0.01 | W12: 0.01 | X12: 0.01 | Y12: 0.01 | Z12: 0.01
B13: SEELCBIBHO | C13: Biomass cofiring | D13: ELCBSTMEA | E13: CSTMBHCCO | F13: 0.086 | G13: 0.086 | H13: 0.086 | I13: 0.086 | J13: 0.086 | K13: 0.151 | L13: 0.024 | M13: 0.01 | N13: 0.01 | O13: 0.01 | P13: 0.01 | Q13: 0.021 | R13: 0.009 | S13: 0.009 | T13: 0.008 | U13: 0.008 | V13: 0.01 | W13: 0.01 | X13: 0.01 | Y13: 0.01 | Z13: 0.01
B14: SEELCWTE | C14: Emissions: Waste to Energy to ELC | D14: ELCMSW | E14: ELCMSWEA | F14: 0.155 | G14: 0.155 | H14: 0.155 | I14: 0.155 | J14: 0.155 | K14: 0.012 | L14: 0.012 | M14: 0.012 | N14: 0.012 | O14: 0.012 | P14: 0.012 | Q14: 0.006 | R14: 0.006 | S14: 0.006 | T14: 0.006 | U14: 0.006 | V14: 0.15 | W14: 0.15 | X14: 0.15 | Y14: 0.15 | Z14: 0.15
B15: SELFGICE | C15: Emissions: Landfill gas to energy | D15: LFG | E15: LFGICEEA | F15: 0.039 | G15: 0.039 | H15: 0.039 | I15: 0.039 | J15: 0.039 | K15: 0.009 | L15: 0.009 | M15: 0.009 | N15: 0.009 | O15: 0.009 | P15: 0.009 | Q15: 0.009 | R15: 0.009 | S15: 0.009 | T15: 0.009 | U15: 0.009
B16: SECIGCCBH | C16: Emissions: Coal to IGCC | D16: ELCCOABH | E16: COALIGCC | F16: 0.011 | G16: 0.012 | H16: 0.012 | I16: 0.012 | J16: 0.012 | K16: 0.003 | L16: 0.002 | M16: 0.002 | N16: 0.002 | O16: 0.002 | P16: 0.002 | V16: 0.004 | W16: 0.004 | X16: 0.004 | Y16: 0.004 | Z16: 0.004
B17: SECSTMBH | C17: Emissions: Coal to New Steam Electric | D17: ELCCOABH | E17: COALSTMN | F17: 0.172 | G17: 0.172 | H17: 0.172 | I17: 0.172 | J17: 0.172 | K17: 0.013 | L17: 0.013 | M17: 0.013 | N17: 0.013 | O17: 0.013 | P17: 0.013 | Q17: 0.01 | R17: 0.01 | S17: 0.01 | T17: 0.01 | U17: 0.01 | V17: 0.051 | W17: 0.051 | X17: 0.051 | Y17: 0.051 | Z17: 0.051
B18: SECSTMRBH | C18: Emissions: Coal to Residual Steam Electric | D18: ELCCOABH | E18: CSTMBH | F18: 0.346 | G18: 0.346 | H18: 0.346 | I18: 0.346 | J18: 0.346 | K18: 0.013 | L18: 0.013 | M18: 0.013 | N18: 0.013 | O18: 0.013 | P18: 0.013 | Q18: 0.01 | R18: 0.01 | S18: 0.01 | T18: 0.01 | U18: 0.01 | V18: 1.186 | W18: 1.186 | X18: 1.186 | Y18: 1.186 | Z18: 1.186

Sheet TRA_Pollutants
B2: TechName | C2: TechDesc | D2: CEFF-I~2015 | E2: CEFF-I~2020 | F2: CEFF-I~2025 | G2: CEFF-I~2030 | H2: CEFF-I~2035 | I2: CEFF-I~2040 | J2: CEFF-I~2050 | K2: ENV_ACT~TRNNOX~2015 | L2: ENV_ACT~TRNNOX~2020 | M2: ENV_ACT~TRNNOX~2025 | N2: ENV_ACT~TRNNOX~2030 | O2: ENV_ACT~TRNNOX~2035 | P2: ENV_ACT~TRNNOX~2040 | Q2: ENV_ACT~TRNNOX~2045 | R2: ENV_ACT~TRNNOX~2050 | S2: ENV_ACT~TRNNOX~2055 | T2: ENV_ACT~TRNSO2~2015 | U2: ENV_ACT~TRNSO2~2020 | V2: ENV_ACT~TRNSO2~2025 | W2: ENV_ACT~TRNSO2~2030 | X2: ENV_ACT~TRNSO2~2035 | Y2: ENV_ACT~TRNSO2~2040 | Z2: ENV_ACT~TRNSO2~2045 | AA2: ENV_ACT~TRNSO2~2050 | AB2: ENV_ACT~TRNSO2~2055 | AC2: ENV_ACT~TRNPM10~2015 | AD2: ENV_ACT~TRNPM10~2020 | AE2: ENV_ACT~TRNPM10~2025 | AF2: ENV_ACT~TRNPM10~2030 | AG2: ENV_ACT~TRNPM10~2035 | AH2: ENV_ACT~TRNPM10~2040 | AI2: ENV_ACT~TRNPM10~2045 | AJ2: ENV_ACT~TRNPM10~2050 | AK2: ENV_ACT~TRNPM10~2055 | AL2: ENV_ACT~TRNPM25~2015 | AM2: ENV_ACT~TRNPM25~2020 | AN2: ENV_ACT~TRNPM25~2025 | AO2: ENV_ACT~TRNPM25~2030 | AP2: ENV_ACT~TRNPM25~2035 | AQ2: ENV_ACT~TRNPM25~2040 | AR2: ENV_ACT~TRNPM25~2045 | AS2: ENV_ACT~TRNPM25~2050 | AT2: ENV_ACT~TRNPM25~2055
B3: *Technology Name | C3: Technology Description | D3: Efficiency | E3: Efficiency | F3: Efficiency | G3: Efficiency | H3: Efficiency | I3: Efficiency | J3: Efficiency | K3: Activity based emissions | L3: Activity based emissions | M3: Activity based emissions | N3: Activity based emissions | O3: Activity based emissions | P3: Activity based emissions | Q3: Activity based emissions | R3: Activity based emissions | S3: Activity based emissions | T3: Activity based emissions | U3: Activity based emissions | V3: Activity based emissions | W3: Activity based emissions | X3: Activity based emissions | Y3: Activity based emissions | Z3: Activity based emissions | AA3: Activity based emissions | AB3: Activity based emissions | AC3: Activity based emissions | AD3: Activity based emissions | AE3: Activity based emissions | AF3: Activity based emissions | AG3: Activity based emissions | AH3: Activity based emissions | AI3: Activity based emissions | AJ3: Activity based emissions | AK3: Activity based emissions | AL3: Activity based emissions | AM3: Activity based emissions | AN3: Activity based emissions | AO3: Activity based emissions | AP3: Activity based emissions | AQ3: Activity based emissions | AR3: Activity based emissions | AS3: Activity based emissions | AT3: Activity based emissions
B4: *Units | C4: *Description | D4: bn-vmt/PJ | E4: bn-vmt/PJ | F4: bn-vmt/PJ | G4: bn-vmt/PJ | H4: bn-vmt/PJ | I4: bn-vmt/PJ | J4: bn-vmt/PJ
B5: TLEMCGSL | C5: TL.GSL.MC.Existing fleet | D5: 0.1477 | E5: 0.1477 | F5: 0.1477 | G5: 0.1477 | H5: 0.1477 | I5: 0.1477 | J5: 0.1477 | K5: 0.32208771 | L5: 0.14762243 | M5: 0.11012303 | N5: 0.079185885 | O5: 0.061480985 | P5: 0.056146365 | Q5: 0.055613052 | R5: 0.055587066 | S5: 0.055587066 | T5: 0.0065842526 | U5: 0.0021407767 | V5: 0.0018057388 | W5: 0.0015104916 | X5: 0.0013524278 | Y5: 0.0013087542 | Z5: 0.0013048051 | AA5: 0.0013041984 | AB5: 0.0013041984 | AC5: 0.038322364 | AD5: 0.036473825 | AE5: 0.035255419 | AF5: 0.033925553 | AG5: 0.033089959 | AH5: 0.032963258 | AI5: 0.032943129 | AJ5: 0.032948539 | AK5: 0.032948539 | AL5: 0.011356392 | AM5: 0.0097211379 | AN5: 0.0086433132 | AO5: 0.0074668917 | AP5: 0.0067277113 | AQ5: 0.0066156339 | AR5: 0.0065978296 | AS5: 0.0066026126 | AT5: 0.0066026126
B6: TLECGSL | C6: TL.GSL.C.Existing fleet | D6: 0.187 | E6: 0.187 | F6: 0.187 | G6: 0.187 | H6: 0.187 | I6: 0.187 | J6: 0.187 | K6: 0.32208771 | L6: 0.14762243 | M6: 0.11012303 | N6: 0.079185885 | O6: 0.061480985 | P6: 0.056146365 | Q6: 0.055613052 | R6: 0.055587066 | S6: 0.055587066 | T6: 0.0065842526 | U6: 0.0021407767 | V6: 0.0018057388 | W6: 0.0015104916 | X6: 0.0013524278 | Y6: 0.0013087542 | Z6: 0.0013048051 | AA6: 0.0013041984 | AB6: 0.0013041984 | AC6: 0.038322364 | AD6: 0.036473825 | AE6: 0.035255419 | AF6: 0.033925553 | AG6: 0.033089959 | AH6: 0.032963258 | AI6: 0.032943129 | AJ6: 0.032948539 | AK6: 0.032948539 | AL6: 0.011356392 | AM6: 0.0097211379 | AN6: 0.0086433132 | AO6: 0.0074668917 | AP6: 0.0067277113 | AQ6: 0.0066156339 | AR6: 0.0065978296 | AS6: 0.0066026126 | AT6: 0.0066026126
B7: TLEFDSL | C7: TL.DSL.F.Existing fleet | D7: 0.18 | E7: 0.18 | F7: 0.18 | G7: 0.18 | H7: 0.18 | I7: 0.18 | J7: 0.18 | K7: 0.33479805 | L7: 0.17279825 | M7: 0.12317848 | N7: 0.071764395 | O7: 0.04864317 | P7: 0.042515328 | Q7: 0.041768431 | R7: 0.041644852 | S7: 0.041644852 | T7: 0.0034397378 | U7: 0.002942135 | V7: 0.0023420273 | W7: 0.0019329267 | X7: 0.0017285728 | Y7: 0.0016724434 | Z7: 0.0016673504 | AA7: 0.0016665714 | AB7: 0.0016665714 | AC7: 0.035768981 | AD7: 0.035224302 | AE7: 0.034739303 | AF7: 0.033661351 | AG7: 0.03292756 | AH7: 0.032835659 | AI7: 0.032811813 | AJ7: 0.032808645 | AK7: 0.032808645 | AL7: 0.0093030959 | AM7: 0.0088020003 | AN7: 0.0083558183 | AO7: 0.0073641054 | AP7: 0.0066890192 | AQ7: 0.0066044725 | AR7: 0.0065825303 | AS7: 0.0065796177 | AT7: 0.0065796177
B8: TLEFGSL | C8: TL.GSL.F.Existing fleet | D8: 0.166 | E8: 0.166 | F8: 0.166 | G8: 0.166 | H8: 0.166 | I8: 0.166 | J8: 0.166 | K8: 0.32208771 | L8: 0.14762243 | M8: 0.11012303 | N8: 0.079185885 | O8: 0.061480985 | P8: 0.056146365 | Q8: 0.055613052 | R8: 0.055587066 | S8: 0.055587066 | T8: 0.0065842526 | U8: 0.0021407767 | V8: 0.0018057388 | W8: 0.0015104916 | X8: 0.0013524278 | Y8: 0.0013087542 | Z8: 0.0013048051 | AA8: 0.0013041984 | AB8: 0.0013041984 | AC8: 0.038322364 | AD8: 0.036473825 | AE8: 0.035255419 | AF8: 0.033925553 | AG8: 0.033089959 | AH8: 0.032963258 | AI8: 0.032943129 | AJ8: 0.032948539 | AK8: 0.032948539 | AL8: 0.011356392 | AM8: 0.0097211379 | AN8: 0.0086433132 | AO8: 0.0074668917 | AP8: 0.0067277113 | AQ8: 0.0066156339 | AR8: 0.0065978296 | AS8: 0.0066026126 | AT8: 0.0066026126
B9: TLESSGSL | C9: TL.GSL.SS.Existing fleet | D9: 0.158 | E9: 0.158 | F9: 0.158 | G9: 0.158 | H9: 0.158 | I9: 0.158 | J9: 0.158 | K9: 0.65533465 | L9: 0.23747314 | M9: 0.17135868 | N9: 0.11450547 | O9: 0.073896721 | P9: 0.063977663 | Q9: 0.062506206 | R9: 0.061988465 | S9: 0.061988465 | T9: 0.0088534928 | U9: 0.0028012255 | V9: 0.0023356257 | W9: 0.0020132364 | X9: 0.0018135501 | Y9: 0.0017535054 | Z9: 0.0017465986 | AA9: 0.0017442083 | AB9: 0.0017442083 | AC9: 0.054362379 | AD9: 0.052133188 | AE9: 0.050746207 | AF9: 0.049017581 | AG9: 0.047843144 | AH9: 0.047688453 | AI9: 0.047638518 | AJ9: 0.047629366 | AK9: 0.047629366 | AL9: 0.015433623 | AM9: 0.013462581 | AN9: 0.012236203 | AO9: 0.010706947 | AP9: 0.0096679405 | AQ9: 0.0095311126 | AR9: 0.0094869775 | AS9: 0.009478915 | AT9: 0.009478915
B10: TLELSGSL | C10: TL.GSL.LS.Existing fleet | D10: 0.129 | E10: 0.129 | F10: 0.129 | G10: 0.129 | H10: 0.129 | I10: 0.129 | J10: 0.129 | K10: 0.65533465 | L10: 0.23747314 | M10: 0.17135868 | N10: 0.11450547 | O10: 0.073896721 | P10: 0.063977663 | Q10: 0.062506206 | R10: 0.061988465 | S10: 0.061988465 | T10: 0.0088534928 | U10: 0.0028012255 | V10: 0.0023356257 | W10: 0.0020132364 | X10: 0.0018135501 | Y10: 0.0017535054 | Z10: 0.0017465986 | AA10: 0.0017442083 | AB10: 0.0017442083 | AC10: 0.054362379 | AD10: 0.052133188 | AE10: 0.050746207 | AF10: 0.049017581 | AG10: 0.047843144 | AH10: 0.047688453 | AI10: 0.047638518 | AJ10: 0.047629366 | AK10: 0.047629366 | AL10: 0.015433623 | AM10: 0.013462581 | AN10: 0.012236203 | AO10: 0.010706947 | AP10: 0.0096679405 | AQ10: 0.0095311126 | AR10: 0.0094869775 | AS10: 0.009478915 | AT10: 0.009478915
B11: TLEMGSL | C11: TL.GSL.M.Existing Fleet | D11: 0.16 | E11: 0.16 | F11: 0.16 | G11: 0.16 | H11: 0.16 | I11: 0.16 | J11: 0.16 | K11: 0.65533465 | L11: 0.23747314 | M11: 0.17135868 | N11: 0.11450547 | O11: 0.073896721 | P11: 0.063977663 | Q11: 0.062506206 | R11: 0.061988465 | S11: 0.061988465 | T11: 0.0088534928 | U11: 0.0028012255 | V11: 0.0023356257 | W11: 0.0020132364 | X11: 0.0018135501 | Y11: 0.0017535054 | Z11: 0.0017465986 | AA11: 0.0017442083 | AB11: 0.0017442083 | AC11: 0.054362379 | AD11: 0.052133188 | AE11: 0.050746207 | AF11: 0.049017581 | AG11: 0.047843144 | AH11: 0.047688453 | AI11: 0.047638518 | AJ11: 0.047629366 | AK11: 0.047629366 | AL11: 0.015433623 | AM11: 0.013462581 | AN11: 0.012236203 | AO11: 0.010706947 | AP11: 0.0096679405 | AQ11: 0.0095311126 | AR11: 0.0094869775 | AS11: 0.009478915 | AT11: 0.009478915
B12: TLEPGSL | C12: TL.GSL.P.Existing Fleet | D12: 0.132 | E12: 0.132 | F12: 0.132 | G12: 0.132 | H12: 0.132 | I12: 0.132 | J12: 0.132 | K12: 0.65533465 | L12: 0.23747314 | M12: 0.17135868 | N12: 0.11450547 | O12: 0.073896721 | P12: 0.063977663 | Q12: 0.062506206 | R12: 0.061988465 | S12: 0.061988465 | T12: 0.0088534928 | U12: 0.0028012255 | V12: 0.0023356257 | W12: 0.0020132364 | X12: 0.0018135501 | Y12: 0.0017535054 | Z12: 0.0017465986 | AA12: 0.0017442083 | AB12: 0.0017442083 | AC12: 0.054362379 | AD12: 0.052133188 | AE12: 0.050746207 | AF12: 0.049017581 | AG12: 0.047843144 | AH12: 0.047688453 | AI12: 0.047638518 | AJ12: 0.047629366 | AK12: 0.047629366 | AL12: 0.015433623 | AM12: 0.013462581 | AN12: 0.012236203 | AO12: 0.010706947 | AP12: 0.0096679405 | AQ12: 0.0095311126 | AR12: 0.0094869775 | AS12: 0.009478915 | AT12: 0.009478915
B13: TLEPDSL | C13: TL.DSL.P.Existing fleet | D13: 0.154 | E13: 0.154 | F13: 0.154 | G13: 0.154 | H13: 0.154 | I13: 0.154 | J13: 0.154 | K13: 1.986294 | L13: 1.0994421 | M13: 0.63113185 | N13: 0.43497463 | O13: 0.33067837 | P13: 0.31652765 | Q13: 0.31367857 | R13: 0.31264891 | S13: 0.31264891 | T13: 0.0060836625 | U13: 0.0054059153 | V13: 0.0047949015 | W13: 0.0044295223 | X13: 0.0042828785 | Y13: 0.004246944 | Z13: 0.0042418286 | AA13: 0.0042403248 | AB13: 0.0042403248 | AC13: 0.13747807 | AD13: 0.075855112 | AE13: 0.057063979 | AF13: 0.05405557 | AG13: 0.05302877 | AH13: 0.052861755 | AI13: 0.052841711 | AJ13: 0.052834709 | AK13: 0.052834709 | AL13: 0.092111167 | AM13: 0.035422378 | AN13: 0.018134386 | AO13: 0.015366521 | AP13: 0.014421802 | AQ13: 0.014268148 | AR13: 0.014249715 | AS13: 0.014243276 | AT13: 0.014243276
B14: TLEFETHX | C14: TL.E85X.F.Existing fleet | D14: 0.1596 | E14: 0.1596 | F14: 0.1596 | G14: 0.1596 | H14: 0.1596 | I14: 0.1596 | J14: 0.1596 | K14: 0.33115654 | L14: 0.14166503 | M14: 0.11043 | N14: 0.081508084 | O14: 0.06353378 | P14: 0.058075379 | Q14: 0.057430436 | R14: 0.057317909 | S14: 0.057317909 | T14: 0.010766176 | U14: 0.0032446468 | V14: 0.0027403184 | W14: 0.0022831641 | X14: 0.0020449586 | Y14: 0.0019783937 | Z14: 0.0019723148 | AA14: 0.0019713853 | AB14: 0.0019713853 | AC14: 0.038648196 | AD14: 0.036757622 | AE14: 0.035714587 | AF14: 0.034334014 | AG14: 0.033438917 | AH14: 0.033316304 | AI14: 0.033283145 | AJ14: 0.033278807 | AK14: 0.033278807 | AL14: 0.0116387 | AM14: 0.0099722046 | AN14: 0.0090495231 | AO14: 0.0078282459 | AP14: 0.0070364198 | AQ14: 0.006927961 | AR14: 0.0068986412 | AS14: 0.0068948155 | AT14: 0.0068948155
B15: TLEFCNG | C15: TL.CNG.F.Existing fleet | D15: 0.1712 | E15: 0.1712 | F15: 0.1712 | G15: 0.1712 | H15: 0.1712 | I15: 0.1712 | J15: 0.1712 | K15: 0.32208771 | L15: 0.14762243 | M15: 0.11012303 | N15: 0.079185885 | O15: 0.061480985 | P15: 0.056146365 | Q15: 0.055613052 | R15: 0.055587066 | S15: 0.055587066 | T15: 0.0065842526 | U15: 0.0021407767 | V15: 0.0018057388 | W15: 0.0015104916 | X15: 0.0013524278 | Y15: 0.0013087542 | Z15: 0.0013048051 | AA15: 0.0013041984 | AB15: 0.0013041984 | AC15: 0.038322364 | AD15: 0.036473825 | AE15: 0.035255419 | AF15: 0.033925553 | AG15: 0.033089959 | AH15: 0.032963258 | AI15: 0.032943129 | AJ15: 0.032948539 | AK15: 0.032948539 | AL15: 0.011356392 | AM15: 0.0097211379 | AN15: 0.0086433132 | AO15: 0.0074668917 | AP15: 0.0067277113 | AQ15: 0.0066156339 | AR15: 0.0065978296 | AS15: 0.0066026126 | AT15: 0.0066026126
B16: TLEFLPG | C16: TL.LPG.F.Existing fleet | D16: 0.1703 | E16: 0.1703 | F16: 0.1703 | G16: 0.1703 | H16: 0.1703 | I16: 0.1703 | J16: 0.1703 | K16: 0.32208771 | L16: 0.14762243 | M16: 0.11012303 | N16: 0.079185885 | O16: 0.061480985 | P16: 0.056146365 | Q16: 0.055613052 | R16: 0.055587066 | S16: 0.055587066 | T16: 0.0065842526 | U16: 0.0021407767 | V16: 0.0018057388 | W16: 0.0015104916 | X16: 0.0013524278 | Y16: 0.0013087542 | Z16: 0.0013048051 | AA16: 0.0013041984 | AB16: 0.0013041984 | AC16: 0.038322364 | AD16: 0.036473825 | AE16: 0.035255419 | AF16: 0.033925553 | AG16: 0.033089959 | AH16: 0.032963258 | AI16: 0.032943129 | AJ16: 0.032948539 | AK16: 0.032948539 | AL16: 0.011356392 | AM16: 0.0097211379 | AN16: 0.0086433132 | AO16: 0.0074668917 | AP16: 0.0067277113 | AQ16: 0.0066156339 | AR16: 0.0065978296 | AS16: 0.0066026126 | AT16: 0.0066026126
B17: TLEFELC | C17: TL.ELC.F.Existing fleet | D17: 0.7225 | E17: 0.7225 | F17: 0.7225 | G17: 0.7225 | H17: 0.7225 | I17: 0.7225 | J17: 0.7225 | AC17: 0.032574009 | AD17: 0.031002751 | AE17: 0.029967106 | AF17: 0.02883672 | AG17: 0.028126465 | AH17: 0.028018769 | AI17: 0.02800166 | AJ17: 0.028006258 | AK17: 0.028006258 | AL17: 0.0056781959 | AM17: 0.004860569 | AN17: 0.0043216566 | AO17: 0.0037334458 | AP17: 0.0033638556 | AQ17: 0.0033078169 | AR17: 0.0032989148 | AS17: 0.0033013063 | AT17: 0.0033013063
B18: TLMCCONV | C18: TL.GSL.MC.CONV | D18: 0.17026032 | E18: 0.20962535 | F18: 0.25470361 | G18: 0.25572741 | H18: 0.25571251 | I18: 0.25565792 | J18: 0.25565792 | K18: 0.32208771 | L18: 0.14762243 | M18: 0.11012303 | N18: 0.079185885 | O18: 0.061480985 | P18: 0.056146365 | Q18: 0.055613052 | R18: 0.055587066 | S18: 0.055587066 | T18: 0.0065842526 | U18: 0.0021407767 | V18: 0.0018057388 | W18: 0.0015104916 | X18: 0.0013524278 | Y18: 0.0013087542 | Z18: 0.0013048051 | AA18: 0.0013041984 | AB18: 0.0013041984 | AC18: 0.038322364 | AD18: 0.036473825 | AE18: 0.035255419 | AF18: 0.033925553 | AG18: 0.033089959 | AH18: 0.032963258 | AI18: 0.032943129 | AJ18: 0.032948539 | AK18: 0.032948539 | AL18: 0.011356392 | AM18: 0.0097211379 | AN18: 0.0086433132 | AO18: 0.0074668917 | AP18: 0.0067277113 | AQ18: 0.0066156339 | AR18: 0.0065978296 | AS18: 0.0066026126 | AT18: 0.0066026126
B19: TLCCONV | C19: TL.GSL.C.CONV | D19: 0.21859957 | E19: 0.27090368 | F19: 0.32797964 | G19: 0.33183968 | H19: 0.33121378 | I19: 0.33060645 | J19: 0.33060645 | K19: 0.32208771 | L19: 0.14762243 | M19: 0.11012303 | N19: 0.079185885 | O19: 0.061480985 | P19: 0.056146365 | Q19: 0.055613052 | R19: 0.055587066 | S19: 0.055587066 | T19: 0.0065842526 | U19: 0.0021407767 | V19: 0.0018057388 | W19: 0.0015104916 | X19: 0.0013524278 | Y19: 0.0013087542 | Z19: 0.0013048051 | AA19: 0.0013041984 | AB19: 0.0013041984 | AC19: 0.038322364 | AD19: 0.036473825 | AE19: 0.035255419 | AF19: 0.033925553 | AG19: 0.033089959 | AH19: 0.032963258 | AI19: 0.032943129 | AJ19: 0.032948539 | AK19: 0.032948539 | AL19: 0.011356392 | AM19: 0.0097211379 | AN19: 0.0086433132 | AO19: 0.0074668917 | AP19: 0.0067277113 | AQ19: 0.0066156339 | AR19: 0.0065978296 | AS19: 0.0066026126 | AT19: 0.0066026126
B20: TLCDSL | C20: TL.DSL.C.DSL | D20: 0.27327343 | E20: 0.31132764 | F20: 0.35134028 | G20: 0.35492746 | H20: 0.35430564 | I20: 0.35357546 | J20: 0.35357546 | K20: 0.33479805 | L20: 0.17279825 | M20: 0.12317848 | N20: 0.071764395 | O20: 0.04864317 | P20: 0.042515328 | Q20: 0.041768431 | R20: 0.041644852 | S20: 0.041644852 | T20: 0.0034397378 | U20: 0.002942135 | V20: 0.0023420273 | W20: 0.0019329267 | X20: 0.0017285728 | Y20: 0.0016724434 | Z20: 0.0016673504 | AA20: 0.0016665714 | AB20: 0.0016665714 | AC20: 0.035768981 | AD20: 0.035224302 | AE20: 0.034739303 | AF20: 0.033661351 | AG20: 0.03292756 | AH20: 0.032835659 | AI20: 0.032811813 | AJ20: 0.032808645 | AK20: 0.032808645 | AL20: 0.0093030959 | AM20: 0.0088020003 | AN20: 0.0083558183 | AO20: 0.0073641054 | AP20: 0.0066890192 | AQ20: 0.0066044725 | AR20: 0.0065825303 | AS20: 0.0065796177 | AT20: 0.0065796177
B21: TLCDHEV | C21: TL.DSL.C.DHEV | D21: 0.40570059 | E21: 0.40570059 | F21: 0.43935579 | G21: 0.44420424 | H21: 0.44341658 | I21: 0.44311741 | J21: 0.44311741 | K21: 0.33479805 | L21: 0.17279825 | M21: 0.12317848 | N21: 0.071764395 | O21: 0.04864317 | P21: 0.042515328 | Q21: 0.041768431 | R21: 0.041644852 | S21: 0.041644852 | T21: 0.0034397378 | U21: 0.002942135 | V21: 0.0023420273 | W21: 0.0019329267 | X21: 0.0017285728 | Y21: 0.0016724434 | Z21: 0.0016673504 | AA21: 0.0016665714 | AB21: 0.0016665714 | AC21: 0.035768981 | AD21: 0.035224302 | AE21: 0.034739303 | AF21: 0.033661351 | AG21: 0.03292756 | AH21: 0.032835659 | AI21: 0.032811813 | AJ21: 0.032808645 | AK21: 0.032808645 | AL21: 0.0093030959 | AM21: 0.0088020003 | AN21: 0.0083558183 | AO21: 0.0073641054 | AP21: 0.0066890192 | AQ21: 0.0066044725 | AR21: 0.0065825303 | AS21: 0.0065796177 | AT21: 0.0065796177
B22: TLCETHX | C22: TL.E85X.C.ETHX | D22: 0.21859957 | E22: 0.27090368 | F22: 0.32797964 | G22: 0.33183968 | H22: 0.33121378 | I22: 0.33060645 | J22: 0.33060645 | K22: 0.33115654 | L22: 0.14166503 | M22: 0.11043 | N22: 0.081508084 | O22: 0.06353378 | P22: 0.058075379 | Q22: 0.057430436 | R22: 0.057317909 | S22: 0.057317909 | T22: 0.010766176 | U22: 0.0032446468 | V22: 0.0027403184 | W22: 0.0022831641 | X22: 0.0020449586 | Y22: 0.0019783937 | Z22: 0.0019723148 | AA22: 0.0019713853 | AB22: 0.0019713853 | AC22: 0.038648196 | AD22: 0.036757622 | AE22: 0.035714587 | AF22: 0.034334014 | AG22: 0.033438917 | AH22: 0.033316304 | AI22: 0.033283145 | AJ22: 0.033278807 | AK22: 0.033278807 | AL22: 0.0116387 | AM22: 0.0099722046 | AN22: 0.0090495231 | AO22: 0.0078282459 | AP22: 0.0070364198 | AQ22: 0.006927961 | AR22: 0.0068986412 | AS22: 0.0068948155 | AT22: 0.0068948155
B23: TLCHEV | C23: TL.GSL.C.HEV | D23: 0.31526727 | E23: 0.37685368 | F23: 0.43786173 | G23: 0.44380134 | H23: 0.44317887 | I23: 0.44283487 | J23: 0.44283487 | K23: 0.32208771 | L23: 0.14762243 | M23: 0.11012303 | N23: 0.079185885 | O23: 0.061480985 | P23: 0.056146365 | Q23: 0.055613052 | R23: 0.055587066 | S23: 0.055587066 | T23: 0.0065842526 | U23: 0.0021407767 | V23: 0.0018057388 | W23: 0.0015104916 | X23: 0.0013524278 | Y23: 0.0013087542 | Z23: 0.0013048051 | AA23: 0.0013041984 | AB23: 0.0013041984 | AC23: 0.038322364 | AD23: 0.036473825 | AE23: 0.035255419 | AF23: 0.033925553 | AG23: 0.033089959 | AH23: 0.032963258 | AI23: 0.032943129 | AJ23: 0.032948539 | AK23: 0.032948539 | AL23: 0.011356392 | AM23: 0.0097211379 | AN23: 0.0086433132 | AO23: 0.0074668917 | AP23: 0.0067277113 | AQ23: 0.0066156339 | AR23: 0.0065978296 | AS23: 0.0066026126 | AT23: 0.0066026126
B24: TLFCONV | C24: TL.GSL.F.CONV | D24: 0.21371318 | E24: 0.26327044 | F24: 0.32311395 | G24: 0.3263575 | H24: 0.32637332 | I24: 0.32603926 | J24: 0.32603926 | K24: 0.32208771 | L24: 0.14762243 | M24: 0.11012303 | N24: 0.079185885 | O24: 0.061480985 | P24: 0.056146365 | Q24: 0.055613052 | R24: 0.055587066 | S24: 0.055587066 | T24: 0.0065842526 | U24: 0.0021407767 | V24: 0.0018057388 | W24: 0.0015104916 | X24: 0.0013524278 | Y24: 0.0013087542 | Z24: 0.0013048051 | AA24: 0.0013041984 | AB24: 0.0013041984 | AC24: 0.038322364 | AD24: 0.036473825 | AE24: 0.035255419 | AF24: 0.033925553 | AG24: 0.033089959 | AH24: 0.032963258 | AI24: 0.032943129 | AJ24: 0.032948539 | AK24: 0.032948539 | AL24: 0.011356392 | AM24: 0.0097211379 | AN24: 0.0086433132 | AO24: 0.0074668917 | AP24: 0.0067277113 | AQ24: 0.0066156339 | AR24: 0.0065978296 | AS24: 0.0066026126 | AT24: 0.0066026126
B25: TLFDHEV | C25: TL.DSL.F.DHEV | D25: 0.46429545 | E25: 0.46429545 | F25: 0.46429545 | G25: 0.46929576 | H25: 0.46863627 | I25: 0.46809402 | J25: 0.46809402 | K25: 0.33479805 | L25: 0.17279825 | M25: 0.12317848 | N25: 0.071764395 | O25: 0.04864317 | P25: 0.042515328 | Q25: 0.041768431 | R25: 0.041644852 | S25: 0.041644852 | T25: 0.0034397378 | U25: 0.002942135 | V25: 0.0023420273 | W25: 0.0019329267 | X25: 0.0017285728 | Y25: 0.0016724434 | Z25: 0.0016673504 | AA25: 0.0016665714 | AB25: 0.0016665714 | AC25: 0.035768981 | AD25: 0.035224302 | AE25: 0.034739303 | AF25: 0.033661351 | AG25: 0.03292756 | AH25: 0.032835659 | AI25: 0.032811813 | AJ25: 0.032808645 | AK25: 0.032808645 | AL25: 0.0093030959 | AM25: 0.0088020003 | AN25: 0.0083558183 | AO25: 0.0073641054 | AP25: 0.0066890192 | AQ25: 0.0066044725 | AR25: 0.0065825303 | AS25: 0.0065796177 | AT25: 0.0065796177
B26: TLFDSL | C26: TL.DSL.F.DSL | D26: 0.26685167 | E26: 0.2962221 | F26: 0.33631882 | G26: 0.33943833 | H26: 0.3394504 | I26: 0.33914415 | J26: 0.33914415 | K26: 0.33479805 | L26: 0.17279825 | M26: 0.12317848 | N26: 0.071764395 | O26: 0.04864317 | P26: 0.042515328 | Q26: 0.041768431 | R26: 0.041644852 | S26: 0.041644852 | T26: 0.0034397378 | U26: 0.002942135 | V26: 0.0023420273 | W26: 0.0019329267 | X26: 0.0017285728 | Y26: 0.0016724434 | Z26: 0.0016673504 | AA26: 0.0016665714 | AB26: 0.0016665714 | AC26: 0.035768981 | AD26: 0.035224302 | AE26: 0.034739303 | AF26: 0.033661351 | AG26: 0.03292756 | AH26: 0.032835659 | AI26: 0.032811813 | AJ26: 0.032808645 | AK26: 0.032808645 | AL26: 0.0093030959 | AM26: 0.0088020003 | AN26: 0.0083558183 | AO26: 0.0073641054 | AP26: 0.0066890192 | AQ26: 0.0066044725 | AR26: 0.0065825303 | AS26: 0.0065796177 | AT26: 0.0065796177
B27: TLFETHX | C27: TL.E85X.F.ETHX | D27: 0.21371318 | E27: 0.26327044 | F27: 0.32311395 | G27: 0.3263575 | H27: 0.32637332 | I27: 0.32603926 | J27: 0.32603926 | K27: 0.33115654 | L27: 0.14166503 | M27: 0.11043 | N27: 0.081508084 | O27: 0.06353378 | P27: 0.058075379 | Q27: 0.057430436 | R27: 0.057317909 | S27: 0.057317909 | T27: 0.010766176 | U27: 0.0032446468 | V27: 0.0027403184 | W27: 0.0022831641 | X27: 0.0020449586 | Y27: 0.0019783937 | Z27: 0.0019723148 | AA27: 0.0019713853 | AB27: 0.0019713853 | AC27: 0.038648196 | AD27: 0.036757622 | AE27: 0.035714587 | AF27: 0.034334014 | AG27: 0.033438917 | AH27: 0.033316304 | AI27: 0.033283145 | AJ27: 0.033278807 | AK27: 0.033278807 | AL27: 0.0116387 | AM27: 0.0099722046 | AN27: 0.0090495231 | AO27: 0.0078282459 | AP27: 0.0070364198 | AQ27: 0.006927961 | AR27: 0.0068986412 | AS27: 0.0068948155 | AT27: 0.0068948155
B28: TLFHEV | C28: TL.GSL.F.HEV | D28: 0.30408689 | E28: 0.36346079 | F28: 0.4294685 | G28: 0.43448027 | H28: 0.43403897 | I28: 0.433946 | J28: 0.433946 | K28: 0.32208771 | L28: 0.14762243 | M28: 0.11012303 | N28: 0.079185885 | O28: 0.061480985 | P28: 0.056146365 | Q28: 0.055613052 | R28: 0.055587066 | S28: 0.055587066 | T28: 0.0065842526 | U28: 0.0021407767 | V28: 0.0018057388 | W28: 0.0015104916 | X28: 0.0013524278 | Y28: 0.0013087542 | Z28: 0.0013048051 | AA28: 0.0013041984 | AB28: 0.0013041984 | AC28: 0.038322364 | AD28: 0.036473825 | AE28: 0.035255419 | AF28: 0.033925553 | AG28: 0.033089959 | AH28: 0.032963258 | AI28: 0.032943129 | AJ28: 0.032948539 | AK28: 0.032948539 | AL28: 0.011356392 | AM28: 0.0097211379 | AN28: 0.0086433132 | AO28: 0.0074668917 | AP28: 0.0067277113 | AQ28: 0.0066156339 | AR28: 0.0065978296 | AS28: 0.0066026126 | AT28: 0.0066026126
B29: TLMCONV | C29: TL.GSL.M.CONV | D29: 0.16516582 | E29: 0.19376696 | F29: 0.26130562 | G29: 0.26383883 | H29: 0.2650537 | I29: 0.26474318 | J29: 0.26474318 | K29: 0.65533465 | L29: 0.23747314 | M29: 0.17135868 | N29: 0.11450547 | O29: 0.073896721 | P29: 0.063977663 | Q29: 0.062506206 | R29: 0.061988465 | S29: 0.061988465 | T29: 0.0088534928 | U29: 0.0028012255 | V29: 0.0023356257 | W29: 0.0020132364 | X29: 0.0018135501 | Y29: 0.0017535054 | Z29: 0.0017465986 | AA29: 0.0017442083 | AB29: 0.0017442083 | AC29: 0.054362379 | AD29: 0.052133188 | AE29: 0.050746207 | AF29: 0.049017581 | AG29: 0.047843144 | AH29: 0.047688453 | AI29: 0.047638518 | AJ29: 0.047629366 | AK29: 0.047629366 | AL29: 0.015433623 | AM29: 0.013462581 | AN29: 0.012236203 | AO29: 0.010706947 | AP29: 0.0096679405 | AQ29: 0.0095311126 | AR29: 0.0094869775 | AS29: 0.009478915 | AT29: 0.009478915
... B70: TLCCNG | C70: TL.CNG.C.CNG | D70: 0.23710417 | E70: 0.29538801 | F70: 0.3621337 | G70: 0.36636751 | H70: 0.36572322 | I70: 0.36493225 | J70: 0.36493225 | K70: 0.32208771 | L70: 0.14762243 | M70: 0.11012303 | N70: 0.079185885 | O70: 0.061480985 | P70: 0.056146365 | Q70: 0.055613052 | R70: 0.055587066 | S70: 0.055587066 | T70: 0.0065842526 | U70: 0.0021407767 | V70: 0.0018057388 | W70: 0.0015104916 | X70: 0.0013524278 | Y70: 0.0013087542 | Z70: 0.0013048051 | AA70: 0.0013041984 | AB70: 0.0013041984 | AC70: 0.038322364 | AD70: 0.036473825 | AE70: 0.035255419 | AF70: 0.033925553 | AG70: 0.033089959 | AH70: 0.032963258 | AI70: 0.032943129 | AJ70: 0.032948539 | AK70: 0.032948539 | AL70: 0.011356392 | AM70: 0.0097211379 | AN70: 0.0086433132 | AO70: 0.0074668917 | AP70: 0.0067277113 | AQ70: 0.0066156339 | AR70: 0.0065978296 | AS70: 0.0066026126 | AT70: 0.0066026126
A71: * | B71: TLCCNGX | C71: TL.CNGX.C.CNGX | D71: 0.21959781 | E71: 0.27352499 | F71: 0.33518895 | G71: 0.33909317 | H71: 0.33833308 | I71: 0.33757918 | J71: 0.33757918 | K71: 0.32208771 | L71: 0.14762243 | M71: 0.11012303 | N71: 0.079185885 | O71: 0.061480985 | P71: 0.056146365 | Q71: 0.055613052 | R71: 0.055587066 | S71: 0.055587066 | T71: 0.0065842526 | U71: 0.0021407767 | V71: 0.0018057388 | W71: 0.0015104916 | X71: 0.0013524278 | Y71: 0.0013087542 | Z71: 0.0013048051 | AA71: 0.0013041984 | AB71: 0.0013041984 | AC71: 0.038322364 | AD71: 0.036473825 | AE71: 0.035255419 | AF71: 0.033925553 | AG71: 0.033089959 | AH71: 0.032963258 | AI71: 0.032943129 | AJ71: 0.032948539 | AK71: 0.032948539 | AL71: 0.011356392 | AM71: 0.0097211379 | AN71: 0.0086433132 | AO71: 0.0074668917 | AP71: 0.0067277113 | AQ71: 0.0066156339 | AR71: 0.0065978296 | AS71: 0.0066026126 | AT71: 0.0066026126
B72: TLFCNG | C72: TL.CNG.F.CNG | D72: 0.20585098 | E72: 0.26810122 | F72: 0.3342709 | G72: 0.33891059 | H72: 0.34007257 | I72: 0.34079271 | J72: 0.34079271 | K72: 0.32208771 | L72: 0.14762243 | M72: 0.11012303 | N72: 0.079185885 | O72: 0.061480985 | P72: 0.056146365 | Q72: 0.055613052 | R72: 0.055587066 | S72: 0.055587066 | T72: 0.0065842526 | U72: 0.0021407767 | V72: 0.0018057388 | W72: 0.0015104916 | X72: 0.0013524278 | Y72: 0.0013087542 | Z72: 0.0013048051 | AA72: 0.0013041984 | AB72: 0.0013041984 | AC72: 0.038322364 | AD72: 0.036473825 | AE72: 0.035255419 | AF72: 0.033925553 | AG72: 0.033089959 | AH72: 0.032963258 | AI72: 0.032943129 | AJ72: 0.032948539 | AK72: 0.032948539 | AL72: 0.011356392 | AM72: 0.0097211379 | AN72: 0.0086433132 | AO72: 0.0074668917 | AP72: 0.0067277113 | AQ72: 0.0066156339 | AR72: 0.0065978296 | AS72: 0.0066026126 | AT72: 0.0066026126
A73: * | B73: TLFCNGX | C73: TL.CNGX.F.CNGX | D73: 0.19074635 | E73: 0.2492436 | F73: 0.31124807 | G73: 0.31581276 | H73: 0.31724315 | I73: 0.31797114 | J73: 0.31797114 | K73: 0.32208771 | L73: 0.14762243 | M73: 0.11012303 | N73: 0.079185885 | O73: 0.061480985 | P73: 0.056146365 | Q73: 0.055613052 | R73: 0.055587066 | S73: 0.055587066 | T73: 0.0065842526 | U73: 0.0021407767 | V73: 0.0018057388 | W73: 0.0015104916 | X73: 0.0013524278 | Y73: 0.0013087542 | Z73: 0.0013048051 | AA73: 0.0013041984 | AB73: 0.0013041984 | AC73: 0.038322364 | AD73: 0.036473825 | AE73: 0.035255419 | AF73: 0.033925553 | AG73: 0.033089959 | AH73: 0.032963258 | AI73: 0.032943129 | AJ73: 0.032948539 | AK73: 0.032948539 | AL73: 0.011356392 | AM73: 0.0097211379 | AN73: 0.0086433132 | AO73: 0.0074668917 | AP73: 0.0067277113 | AQ73: 0.0066156339 | AR73: 0.0065978296 | AS73: 0.0066026126 | AT73: 0.0066026126
B74: TLMCNG | C74: TL.CNG.M.CNG | D74: 0.1784285 | E74: 0.20690191 | F74: 0.27683065 | G74: 0.27972055 | H74: 0.28122321 | I74: 0.28149304 | J74: 0.28149304 | K74: 0.65533465 | L74: 0.23747314 | M74: 0.17135868 | N74: 0.11450547 | O74: 0.073896721 | P74: 0.063977663 | Q74: 0.062506206 | R74: 0.061988465 | S74: 0.061988465 | T74: 0.0088534928 | U74: 0.0028012255 | V74: 0.0023356257 | W74: 0.0020132364 | X74: 0.0018135501 | Y74: 0.0017535054 | Z74: 0.0017465986 | AA74: 0.0017442083 | AB74: 0.0017442083 | AC74: 0.054362379 | AD74: 0.052133188 | AE74: 0.050746207 | AF74: 0.049017581 | AG74: 0.047843144 | AH74: 0.047688453 | AI74: 0.047638518 | AJ74: 0.047629366 | AK74: 0.047629366 | AL74: 0.015433623 | AM74: 0.013462581 | AN74: 0.012236203 | AO74: 0.010706947 | AP74: 0.0096679405 | AQ74: 0.0095311126 | AR74: 0.0094869775 | AS74: 0.009478915 | AT74: 0.009478915
A75: * | B75: TLMCNGX | C75: TL.CNGX.M.CNGX | D75: 0.16499091 | E75: 0.19343883 | F75: 0.25822098 | G75: 0.26114589 | H75: 0.26266237 | I75: 0.26253935 | J75: 0.26253935 | K75: 0.65533465 | L75: 0.23747314 | M75: 0.17135868 | N75: 0.11450547 | O75: 0.073896721 | P75: 0.063977663 | Q75: 0.062506206 | R75: 0.061988465 | S75: 0.061988465 | T75: 0.0088534928 | U75: 0.0028012255 | V75: 0.0023356257 | W75: 0.0020132364 | X75: 0.0018135501 | Y75: 0.0017535054 | Z75: 0.0017465986 | AA75: 0.0017442083 | AB75: 0.0017442083 | AC75: 0.054362379 | AD75: 0.052133188 | AE75: 0.050746207 | AF75: 0.049017581 | AG75: 0.047843144 | AH75: 0.047688453 | AI75: 0.047638518 | AJ75: 0.047629366 | AK75: 0.047629366 | AL75: 0.015433623 | AM75: 0.013462581 | AN75: 0.012236203 | AO75: 0.010706947 | AP75: 0.0096679405 | AQ75: 0.0095311126 | AR75: 0.0094869775 | AS75: 0.009478915 | AT75: 0.009478915
B76: TLPCNG | C76: TL.CNG.P.CNG | D76: 0.17714883 | E76: 0.19722086 | F76: 0.24250019 | G76: 0.24499686 | H76: 0.24675509 | I76: 0.24650936 | J76: 0.24650936 | K76: 0.65533465 | L76: 0.23747314 | M76: 0.17135868 | N76: 0.11450547 | O76: 0.073896721 | P76: 0.063977663 | Q76: 0.062506206 | R76: 0.061988465 | S76: 0.061988465 | T76: 0.0088534928 | U76: 0.0028012255 | V76: 0.0023356257 | W76: 0.0020132364 | X76: 0.0018135501 | Y76: 0.0017535054 | Z76: 0.0017465986 | AA76: 0.0017442083 | AB76: 0.0017442083 | AC76: 0.054362379 | AD76: 0.052133188 | AE76: 0.050746207 | AF76: 0.049017581 | AG76: 0.047843144 | AH76: 0.047688453 | AI76: 0.047638518 | AJ76: 0.047629366 | AK76: 0.047629366 | AL76: 0.015433623 | AM76: 0.013462581 | AN76: 0.012236203 | AO76: 0.010706947 | AP76: 0.0096679405 | AQ76: 0.0095311126 | AR76: 0.0094869775 | AS76: 0.009478915 | AT76: 0.009478915
A77: * | B77: TLPCNGX | C77: TL.CNGX.P.CNGX | D77: 0.16388628 | E77: 0.18398156 | F77: 0.22683177 | G77: 0.229359 | H77: 0.23090351 | I77: 0.23063886 | J77: 0.23063886 | K77: 0.65533465 | L77: 0.23747314 | M77: 0.17135868 | N77: 0.11450547 | O77: 0.073896721 | P77: 0.063977663 | Q77: 0.062506206 | R77: 0.061988465 | S77: 0.061988465 | T77: 0.0088534928 | U77: 0.0028012255 | V77: 0.0023356257 | W77: 0.0020132364 | X77: 0.0018135501 | Y77: 0.0017535054 | Z77: 0.0017465986 | AA77: 0.0017442083 | AB77: 0.0017442083 | AC77: 0.054362379 | AD77: 0.052133188 | AE77: 0.050746207 | AF77: 0.049017581 | AG77: 0.047843144 | AH77: 0.047688453 | AI77: 0.047638518 | AJ77: 0.047629366 | AK77: 0.047629366 | AL77: 0.015433623 | AM77: 0.013462581 | AN77: 0.012236203 | AO77: 0.010706947 | AP77: 0.0096679405 | AQ77: 0.0095311126 | AR77: 0.0094869775 | AS77: 0.009478915 | AT77: 0.009478915
B78: TLCLPG | C78: TL.LPG.C.LPG | D78: 0.21960157 | E78: 0.27353849 | F78: 0.33523297 | G78: 0.33920699 | H78: 0.33848529 | I78: 0.33777918 | J78: 0.33777918 | K78: 0.32208771 | L78: 0.14762243 | M78: 0.11012303 | N78: 0.079185885 | O78: 0.061480985 | P78: 0.056146365 | Q78: 0.055613052 | R78: 0.055587066 | S78: 0.055587066 | T78: 0.0065842526 | U78: 0.0021407767 | V78: 0.0018057388 | W78: 0.0015104916 | X78: 0.0013524278 | Y78: 0.0013087542 | Z78: 0.0013048051 | AA78: 0.0013041984 | AB78: 0.0013041984 | AC78: 0.038322364 | AD78: 0.036473825 | AE78: 0.035255419 | AF78: 0.033925553 | AG78: 0.033089959 | AH78: 0.032963258 | AI78: 0.032943129 | AJ78: 0.032948539 | AK78: 0.032948539 | AL78: 0.011356392 | AM78: 0.0097211379 | AN78: 0.0086433132 | AO78: 0.0074668917 | AP78: 0.0067277113 | AQ78: 0.0066156339 | AR78: 0.0065978296 | AS78: 0.0066026126 | AT78: 0.0066026126
B79: TLFLPG | C79: TL.LPG.F.LPG | D79: 0.2111553 | E79: 0.26138222 | F79: 0.32150523 | G79: 0.32490755 | H79: 0.32507252 | I79: 0.32482556 | J79: 0.32482556 | K79: 0.32208771 | L79: 0.14762243 | M79: 0.11012303 | N79: 0.079185885 | O79: 0.061480985 | P79: 0.056146365 | Q79: 0.055613052 | R79: 0.055587066 | S79: 0.055587066 | T79: 0.0065842526 | U79: 0.0021407767 | V79: 0.0018057388 | W79: 0.0015104916 | X79: 0.0013524278 | Y79: 0.0013087542 | Z79: 0.0013048051 | AA79: 0.0013041984 | AB79: 0.0013041984 | AC79: 0.038322364 | AD79: 0.036473825 | AE79: 0.035255419 | AF79: 0.033925553 | AG79: 0.033089959 | AH79: 0.032963258 | AI79: 0.032943129 | AJ79: 0.032948539 | AK79: 0.032948539 | AL79: 0.011356392 | AM79: 0.0097211379 | AN79: 0.0086433132 | AO79: 0.0074668917 | AP79: 0.0067277113 | AQ79: 0.0066156339 | AR79: 0.0065978296 | AS79: 0.0066026126 | AT79: 0.0066026126
A80: * | B80: TLMLPG | C80: TL.LPG.M.LPG | D80: 0.17174095 | E80: 0.20040423 | F80: 0.26814428 | G80: 0.27096807 | H80: 0.27235137 | I80: 0.27229866 | J80: 0.27229866 | K80: 0.65533465 | L80: 0.23747314 | M80: 0.17135868 | N80: 0.11450547 | O80: 0.073896721 | P80: 0.063977663 | Q80: 0.062506206 | R80: 0.061988465 | S80: 0.061988465 | T80: 0.0088534928 | U80: 0.0028012255 | V80: 0.0023356257 | W80: 0.0020132364 | X80: 0.0018135501 | Y80: 0.0017535054 | Z80: 0.0017465986 | AA80: 0.0017442083 | AB80: 0.0017442083 | AC80: 0.054362379 | AD80: 0.052133188 | AE80: 0.050746207 | AF80: 0.049017581 | AG80: 0.047843144 | AH80: 0.047688453 | AI80: 0.047638518 | AJ80: 0.047629366 | AK80: 0.047629366 | AL80: 0.015433623 | AM80: 0.013462581 | AN80: 0.012236203 | AO80: 0.010706947 | AP80: 0.0096679405 | AQ80: 0.0095311126 | AR80: 0.0094869775 | AS80: 0.009478915 | AT80: 0.009478915
B81: TLMLPG | C81: TL.LPG.M.LPG | D81: 0.17174095 | E81: 0.20040423 | F81: 0.26814428 | G81: 0.27096807 | H81: 0.27235137 | I81: 0.27229866 | J81: 0.27229866 | K81: 0.65533465 | L81: 0.23747314 | M81: 0.17135868 | N81: 0.11450547 | O81: 0.073896721 | P81: 0.063977663 | Q81: 0.062506206 | R81: 0.061988465 | S81: 0.061988465 | T81: 0.0088534928 | U81: 0.0028012255 | V81: 0.0023356257 | W81: 0.0020132364 | X81: 0.0018135501 | Y81: 0.0017535054 | Z81: 0.0017465986 | AA81: 0.0017442083 | AB81: 0.0017442083 | AC81: 0.054362379 | AD81: 0.052133188 | AE81: 0.050746207 | AF81: 0.049017581 | AG81: 0.047843144 | AH81: 0.047688453 | AI81: 0.047638518 | AJ81: 0.047629366 | AK81: 0.047629366 | AL81: 0.015433623 | AM81: 0.013462581 | AN81: 0.012236203 | AO81: 0.010706947 | AP81: 0.0096679405 | AQ81: 0.0095311126 | AR81: 0.0094869775 | AS81: 0.009478915 | AT81: 0.009478915
...

Sheet >> GC RESID

Sheet TRA RESID
A1: Sector | B1: Sub-sector | C1: Archetype | D1: Vintage | E1: End Use | F1: Technology | G1: Energy | H1: Input Label | I1: Output Label | J1: Technology Label | K1: Main fuel | L1: MODE DEMAND (MVkm) | M1: Demand SHARE (%) | N1: Minimum fuel share (%) | O1: Maximum fuel share (%) | P1: DEMAND (MVkm) | Q1: FINAL ENERGY (GJ) | R1: RESID (Mvkma) | S1: EFF (Vkm/MJ) | T1: Residual life (Yr) | U1: Fixed O&M (Thousands $/Mvkm/yr) | V1: Variable O&M (Thousands $/Mvkm) | W1: CFA | X1: C2A
A2: Transportation | B2: Passenger | C2: Passenger Car | F2: Gasoline ICE Vehicle (spark ignition) | G2: Gasoline | H2: TRAGSL | I2: TRAPASCARDMD | J2: TRAPASCARICEVGSL19 | K2: 1 | L2: 68921.251 | M2: 0.97948822 | N2: 0.9 | O2: 1 | P2: 67507.553 | Q2: 205180.58 | R2: 67507.553 | S2: 0.32901532 | T2: 12 | U2: 6.472949 | W2: 1 | X2: 1
A3: Transportation | B3: Passenger | C3: Passenger Car | F3: Gasoline ICE Vehicle (spark ignition) | G3: Ethanol | H3: TRAETH | I3: TRAPASCARDMD | J3: TRAPASCARICEVGSL19 | K3: 0 | L3: 68921.251 | M3: 0 | N3: 0 | O3: 0.1 | P3: 0 | Q3: 0 | R3: 0 | S3: 0.32901532 | T3: 12 | U3: 6.472949 | W3: 1 | X3: 1
A4: Transportation | B4: Passenger | C4: Passenger Car | F4: Diesel Conventional Compression Ignition Vehicle | G4: Diesel | H4: TRADSL | I4: TRAPASCARDMD | J4: TRAPASCARICEVDSL19 | K4: 1 | L4: 68921.251 | M4: 0.011074786 | N4: 0 | O4: 1 | P4: 763.2881 | Q4: 2284.357 | R4: 763.2881 | S4: 0.33413696 | T4: 12 | U4: 6.472949 | W4: 1 | X4: 1
A5: Transportation | B5: Passenger | C5: Passenger Car | F5: Diesel Conventional Compression Ignition Vehicle | G5: Renewable diesel | H5: TRARDS | I5: TRAPASCARDMD | J5: TRAPASCARICEVDSL19 | K5: 0 | L5: 68921.251 | M5: 0 | N5: 0 | O5: 1 | P5: 0 | Q5: 0 | R5: 0 | S5: 0.33413696 | T5: 12 | U5: 6.472949 | W5: 1 | X5: 1
A6: Transportation | B6: Passenger | C6: Passenger Car | F6: Diesel Conventional Compression Ignition Vehicle | G6: Bio diesel | H6: TRABDS | I6: TRAPASCARDMD | J6: TRAPASCARICEVDSL19 | K6: 0 | L6: 68921.251 | M6: 0 | N6: 0 | O6: 0.1 | P6: 0 | Q6: 0 | R6: 0 | S6: 0.33413696 | T6: 12 | U6: 6.472949 | W6: 1 | X6: 1
A7: Transportation | B7: Passenger | C7: Passenger Car | F7: Compressed Natural Gas Conventional Vehicle | G7: CNG | H7: TRACNG | I7: TRAPASCARDMD | J7: TRAPASCARICEVCNG19 | K7: 1 | L7: 68921.251 | M7: 0 | N7: 0 | O7: 1 | P7: 0 | Q7: 0 | R7: 0 | S7: 0.25976728 | T7: 12 | U7: 6.472949 | W7: 1 | X7: 1
A8: Transportation | B8: Passenger | C8: Passenger Car | F8: Compressed Natural Gas Conventional Vehicle | G8: RNG | H8: TRARNG | I8: TRAPASCARDMD | J8: TRAPASCARICEVCNG19 | K8: 0 | L8: 68921.251 | M8: 0 | N8: 0 | O8: 1 | P8: 0 | Q8: 0 | R8: 0 | S8: 0.25976728 | T8: 12 | U8: 6.472949 | W8: 1 | X8: 1
A9: Transportation | B9: Passenger | C9: Passenger Car | F9: Battery Electric Vehicle (300-mile range) | G9: Battery | H9: TRABAT | I9: TRAPASCARDMD | J9: TRAPASCAR300BEV19 | K9: 1 | L9: 68921.251 | M9: 0.0094369922 | N9: 1 | O9: 1 | P9: 650.4093 | Q9: 884.34672 | R9: 650.4093 | S9: 0.73546867 | T9: 12 | U9: 6.472949 | W9: 1 | X9: 1
A10: Transportation | B10: Passenger | C10: Passenger Car | F10: Hydrogen Fuel Cell Electric Vehicle (300-mile range) | G10: Hydrogen | H10: TRAH2G | I10: TRAPASCARDMD | J10: TRAPASCAR300FCEV19 | K10: 1 | L10: 68921.251 | M10: 0 | N10: 1 | O10: 1 | P10: 0 | Q10: 0 | R10: 0 | S10: 0.73546867 | T10: 12 | U10: 6.472949 | W10: 1 | X10: 1
A11: Transportation | B11: Passenger | C11: Passenger Truck | F11: Gasoline ICE Vehicle (spark ignition) | G11: Gasoline | H11: TRAGSL | I11: TRAPASLDTDMD | J11: TRAPASLDTICEVGSL19 | K11: 1 | L11: 0 | M11: 0 | N11: 0.9 | O11: 1 | P11: 0 | Q11: 0 | R11: 0 | S11: 0.24925979 | T11: 13 | U11: 5.8122532 | W11: 1 | X11: 1
A12: Transportation | B12: Passenger | C12: Passenger Truck | F12: Gasoline ICE Vehicle (spark ignition) | G12: Ethanol | H12: TRAETH | I12: TRAPASLDTDMD | J12: TRAPASLDTICEVGSL19 | K12: 0 | L12: 0 | M12: 0 | N12: 0 | O12: 0.1 | P12: 0 | Q12: 0 | R12: 0 | S12: 0.24925979 | T12: 13 | U12: 5.8122532 | W12: 1 | X12: 1
A13: Transportation | B13: Passenger | C13: Passenger Truck | F13: Diesel Conventional Compression Ignition Vehicle | G13: Diesel | H13: TRADSL | I13: TRAPASLDTDMD | J13: TRAPASLDTICEVDSL19 | K13: 1 | L13: 0 | M13: 0 | N13: 0 | O13: 1 | P13: 0 | Q13: 0 | R13: 0 | S13: 0.19756987 | T13: 13 | U13: 5.8122532 | W13: 1 | X13: 1
... A123: Transportation | B123: Passenger | C123: Subway | F123: Electric Propulsion Vehicle | G123: Electricity | H123: TRAELC | I123: TRAPASSUBDMD | J123: TRAPASSUBPROELC19 | K123: 1 | L123: 0 | M123: 0 | N123: 1 | O123: 1 | P123: 0 | Q123: 0 | R123: 0 | S123: 0.080703906 | T123: 30 | U123: 158.59239 | W123: 1 | X123: 1
A124: Transportation | B124: Passenger | C124: Bicycle | F124: N/a | G124: N/a | I124: TRAPASBICDMD | J124: TRAPASBIC19 | K124: 1 | L124: 783.71641 | M124: 1 | N124: 0 | O124: 0 | P124: 783.71641 | Q124: 0 | R124: 783.71641 | S124: 1 | T124: 50 | U124: 0 | W124: 1 | X124: 1
A125: Transportation | B125: Passenger | C125: Walk | F125: N/a | G125: N/a | I125: TRAPASWALDMD | J125: TRAPASWAL19 | K125: 1 | L125: 4185.0617 | M125: 1 | N125: 0 | O125: 0 | P125: 4185.0617 | Q125: 0 | R125: 4185.0617 | S125: 1 | T125: 100 | U125: 0 | W125: 1 | X125: 1
A126: Transportation | B126: Other | C126: Off-Road | F126: Gasoline ICE Vehicle | G126: Gasoline | H126: TRAGSL | I126: TRAOTHOFRDMD | J126: TRAOTHOFRICEVGSL19 | K126: 1 | L126: 0 | M126: 0 | N126: 0.9 | O126: 1 | P126: 0 | Q126: 0 | R126: 0 | S126: 0.10837963 | T126: 8 | U126: 10.491572 | W126: 1 | X126: 1
A127: Transportation | B127: Other | C127: Off-Road | F127: Gasoline ICE Vehicle | G127: Ethanol | H127: TRAETH | I127: TRAOTHOFRDMD | J127: TRAOTHOFRICEVGSL19 | K127: 0 | L127: 0 | M127: 0 | N127: 0 | O127: 0.1 | P127: 0 | Q127: 0 | R127: 0 | S127: 0.10837963 | T127: 8 | U127: 10.491572 | W127: 1 | X127: 1
A128: Transportation | B128: Other | C128: Off-Road | F128: Diesel ICE Vehicle | G128: Diesel | H128: TRADSL | I128: TRAOTHOFRDMD | J128: TRAOTHOFRICEVDSL19 | K128: 1 | L128: 0 | M128: 0 | N128: 0 | O128: 1 | P128: 0 | Q128: 0 | R128: 0 | S128: 0.1046149 | T128: 8 | U128: 10.491572 | W128: 1 | X128: 1
A129: Transportation | B129: Other | C129: Off-Road | F129: Diesel ICE Vehicle | G129: Renewable diesel | H129: TRARDS | I129: TRAOTHOFRDMD | J129: TRAOTHOFRICEVDSL19 | K129: 0 | L129: 0 | M129: 0 | N129: 0 | O129: 1 | P129: 0 | Q129: 0 | R129: 0 | S129: 0.1046149 | T129: 8 | U129: 10.491572 | W129: 1 | X129: 1
A130: Transportation | B130: Other | C130: Off-Road | F130: Diesel ICE Vehicle | G130: Bio diesel | H130: TRABDS | I130: TRAOTHOFRDMD | J130: TRAOTHOFRICEVDSL19 | K130: 0 | L130: 0 | M130: 0 | N130: 0 | O130: 0.1 | P130: 0 | Q130: 0 | R130: 0 | S130: 0.1046149 | T130: 8 | U130: 10.491572 | W130: 1 | X130: 1
A131: Transportation | B131: Other | C131: Off-Road | F131: Compressed Natural Gas Conventional Vehicle | G131: CNG | H131: TRACNG | I131: TRAOTHOFRDMD | J131: TRAOTHOFRICEVCNG19 | K131: 1 | L131: 0 | M131: 0 | N131: 0 | O131: 1 | P131: 0 | Q131: 0 | R131: 0 | S131: 0.10837963 | T131: 8 | U131: 10.491572 | W131: 1 | X131: 1
A132: Transportation | B132: Other | C132: Off-Road | F132: Compressed Natural Gas Conventional Vehicle | G132: RNG | H132: TRARNG | I132: TRAOTHOFRDMD | J132: TRAOTHOFRICEVCNG19 | K132: 0 | L132: 0 | M132: 0 | N132: 0 | O132: 1 | P132: 0 | Q132: 0 | R132: 0 | S132: 0.10837963 | T132: 8 | U132: 10.491572 | W132: 1 | X132: 1
A133: Transportation | B133: Other | C133: Off-Road | F133: Battery Electric Vehicle | G133: Battery Freight | H133: TRABAF | I133: TRAOTHOFRDMD | J133: TRAOTHOFRBEV19 | K133: 1 | L133: 0 | M133: 0 | N133: 1 | O133: 1 | P133: 0 | Q133: 0 | R133: 0 | S133: 0.21465702 | T133: 8 | U133: 10.491572 | W133: 1 | X133: 1
A134: Transportation | B134: Other | C134: Off-Road | F134: Hydrogen Fuel Cell Electric Vehicle | G134: Hydrogen | H134: TRAH2G | I134: TRAOTHOFRDMD | J134: TRAOTHOFRFCEV19 | K134: 1 | L134: 0 | M134: 0 | N134: 1 | O134: 1 | P134: 0 | Q134: 0 | R134: 0 | S134: 0.21465702 | T134: 8 | U134: 10.491572 | W134: 1 | X134: 1
A135: Transportation | B135: Other | C135: Waterborne | F135: Gasoline ICE Vehicle | G135: Gasoline | H135: TRAGSL | I135: TRAOTHWATDMD | J135: TRAOTHWATICEVGSL19 | K135: 1 | L135: 1.6054304 | M135: 0 | N135: 0.9 | O135: 1 | P135: 0 | Q135: 0 | R135: 0 | S135: 0.0012937722 | T135: 30 | U135: 6522.2354 | W135: 1 | X135: 1
A136: Transportation | B136: Other | C136: Waterborne | F136: Gasoline ICE Vehicle | G136: Ethanol | H136: TRAETH | I136: TRAOTHWATDMD | J136: TRAOTHWATICEVGSL19 | K136: 0 | L136: 1.6054304 | M136: 0 | N136: 0 | O136: 0.1 | P136: 0 | Q136: 0 | R136: 0 | S136: 0.0012937722 | T136: 30 | U136: 6522.2354 | W136: 1 | X136: 1
A137: Transportation | B137: Other | C137: Waterborne | F137: Diesel ICE Vehicle | G137: Diesel | H137: TRADSL | I137: TRAOTHWATDMD | J137: TRAOTHWATICEVDSL19 | K137: 1 | L137: 1.6054304 | M137: 1 | N137: 0 | O137: 1 | P137: 1.6054304 | Q137: 1400.5379 | R137: 1.6054304 | S137: 0.0011462956 | T137: 30 | U137: 6522.2354 | W137: 1 | X137: 1
... A143: Transportation | B143: Other | C143: Aviation | F143: Turbo-reactor | G143: Sustainable aviation fuel | H143: TRASAF | I143: TRAOTHAIRDMD | J143: TRAOTHAIRTURREA19 | K143: 0 | L143: 0.12571557 | M143: 0 | N143: 0 | O143: 1 | P143: 0 | Q143: 0 | R143: 0 | S143: 0.0043975374 | T143: 24 | U143: 1249.4626 | W143: 1 | X143: 1

Sheet ELC RESID
O1: 2019 | P1: 2020 | Q1: 2025 | R1: 2030 | S1: 2035 | T1: 2040 | U1: 2045 | V1: 2050 | W1: 2055 | X1: 2060 | Y1: 2065 | Z1: 2070 | AA1: 2075 | AB1: 2080 | AC1: 2085 | AD1: 2090 | AE1: 2095 | AF1: 2100 | AG1: 2019 | AH1: 2030 | AI1: 2050 | AJ1: 2100 | AK1: 2019 | AL1: 2030 | AM1: 2050 | AN1: 2100 | AO1: 2019 | AP1: 2030 | AQ1: 2050 | AR1: 2100
A2: Sector | B2: Sub-sector | C2: Archetype | D2: Vintage | E2: End Use | F2: Technology | G2: Energy | H2: Technology Label | I2: Generation (TJ) | J2: Fuel Input (MWh) | K2: Capacity Factor (%) | L2: Efficiency (%) | M2: Fixed OM 2023 US$ / kW . Yr | N2: Variable OM 2023 US$ / GJ | O2: Capacity base year (MW) | P2: Capacity 2020 (MW) | Q2: Capacity 2025 (MW) | R2: Capacity 2030 (MW) | S2: Capacity 2035 (MW) | T2: Capacity 2040 (MW) | U2: Capacity 2045 (MW) | V2: Capacity 2050 (MW) | W2: Capacity 2055 (MW) | X2: Capacity 2060 (MW) | Y2: Capacity 2065 (MW) | Z2: Capacity 2070 (MW) | AA2: Capacity 2075 (MW) | AB2: Capacity 2080 (MW) | AC2: Capacity 2085 (MW) | AD2: Capacity 2090 (MW) | AE2: Capacity 2095 (MW) | AF2: Capacity 2100 (MW) | AG2: Average CO2 emission factor ( t CO2 / TJ) | AH2: Average CO2 emission factor ( t CO2 / TJ) | AI2: Average CO2 emission factor ( t CO2 / TJ) | AJ2: Average CO2 emission factor ( t CO2 / TJ) | AK2: Average CH4 emission factor ( t CH4 / TJ) | AL2: Average CH4 emission factor ( t CH4 / TJ) | AM2: Average CH4 emission factor ( t CH4 / TJ) | AN2: Average CH4 emission factor ( t CH4 / TJ) | AO2: Average N2O emission factor ( t N2O / TJ) | AP2: Average N2O emission factor ( t N2O / TJ) | AQ2: Average N2O emission factor ( t N2O / TJ) | AR2: Average N2O emission factor ( t N2O / TJ)
A3: Electricity | B3: Grid | D3: 2019 | E3: Dispatchable | F3: Combustion turbine | G3: Natural gas | H3: ELCNGAGRDCTU19 | I3: 12173.114 | J3: 34569.709 | K3: 0.13746195 | L3: 0.35213238 | M3: 27.138389 | N3: 2.0228151 | O3: 2808.1 | P3: 1517.2 | Q3: 1517.2 | R3: 1517.2 | S3: 1517.2 | T3: 681.9 | U3: 677.3 | V3: 139.5 | W3: 0 | X3: 0 | Y3: 0 | Z3: 0 | AA3: 0 | AB3: 0 | AC3: 0 | AD3: 0 | AE3: 0 | AF3: 0
A4: Electricity | B4: Grid | D4: 2019 | E4: Dispatchable | F4: Steam turbine | G4: Natural gas | H4: ELCNGAGRDSTU19 | I4: 10774.678 | J4: 29246.467 | K4: 0.084997091 | L4: 0.36840957 | M4: 27.138389 | N4: 2.0228151 | O4: 4019.7 | P4: 16 | Q4: 16 | R4: 16 | S4: 16 | T4: 16 | U4: 16 | V4: 0 | W4: 0 | X4: 0 | Y4: 0 | Z4: 0 | AA4: 0 | AB4: 0 | AC4: 0 | AD4: 0 | AE4: 0 | AF4: 0
A5: Electricity | B5: Grid | D5: 2019 | E5: Dispatchable | F5: Combined cycle combustion turbine | G5: Natural gas | H5: ELCNGAGRDCCC19 | I5: 46780.596 | J5: 91771.957 | K5: 0.64588452 | L5: 0.50974827 | M5: 35.166828 | N5: 0.61563937 | O5: 2296.7 | P5: 2296.7 | Q5: 2296.7 | R5: 1726.5 | S5: 1484.5 | T5: 751 | U5: 400 | V5: 0 | W5: 0 | X5: 0 | Y5: 0 | Z5: 0 | AA5: 0 | AB5: 0 | AC5: 0 | AD5: 0 | AE5: 0 | AF5: 0
A6: Electricity | B6: Grid | D6: 2019 | E6: Dispatchable | F6: Combined cycle steam turbine | G6: Natural gas | H6: ELCNGAGRDCCS19 | I6: 17753.904 | J6: 34991.141 | K6: 0.47892182 | L6: 0.50738283 | M6: 35.166828 | N6: 0.61563937 | O6: 1175.5 | P6: 1173.1 | Q6: 1173.1 | R6: 860.5 | S6: 780.5 | T6: 505 | U6: 250 | V6: 0 | W6: 0 | X6: 0 | Y6: 0 | Z6: 0 | AA6: 0 | AB6: 0 | AC6: 0 | AD6: 0 | AE6: 0 | AF6: 0
A7: Electricity | B7: Grid | D7: 2019 | E7: Dispatchable | F7: Combined cycle - single shaft | G7: Natural gas | H7: ELCNGAGRDACC19 | I7: 0 | J7: 0 | M7: 34.827599 | N7: 0.61563937 | O7: 0 | P7: 0 | Q7: 0 | R7: 0 | S7: 0 | T7: 0 | U7: 0 | V7: 0 | W7: 0 | X7: 0 | Y7: 0 | Z7: 0 | AA7: 0 | AB7: 0 | AC7: 0 | AD7: 0 | AE7: 0 | AF7: 0
A8: Electricity | B8: Grid | D8: 2019 | E8: Dispatchable | F8: Other turbine | G8: Natural gas | H8: ELCNGAGRDOTT19 | I8: 0 | J8: 0 | M8: 34.827599 | N8: 0.61563937 | O8: 0 | P8: 0 | Q8: 0 | R8: 0 | S8: 0 | T8: 0 | U8: 0 | V8: 0 | W8: 0 | X8: 0 | Y8: 0 | Z8: 0 | AA8: 0 | AB8: 0 | AC8: 0 | AD8: 0 | AE8: 0 | AF8: 0
A9: Electricity | B9: Grid | D9: 2019 | E9: Dispatchable | F9: Internal combustion engine | G9: Natural gas | H9: ELCNGAGRDICE19 | I9: 234.73082 | J9: 538.0716 | K9: 0.23406495 | L9: 0.43624458 | M9: 27.138389 | N9: 2.0228151 | O9: 31.8 | P9: 31.8 | Q9: 31.8 | R9: 23.4 | S9: 22.5 | T9: 22.3 | U9: 2.4 | V9: 0 | W9: 0 | X9: 0 | Y9: 0 | Z9: 0 | AA9: 0 | AB9: 0 | AC9: 0 | AD9: 0 | AE9: 0 | AF9: 0
A10: Electricity | B10: Grid | D10: 2019 | E10: Dispatchable | F10: Fuel cell | G10: Natural gas | H10: ELCNGAGRDFCE19 | I10: 192.024 | J10: 392.5061 | K10: 0.92258198 | L10: 0.48922552 | M10: 34.827599 | N10: 0.61563937 | O10: 6.6 | P10: 6.6 | Q10: 6.6 | R10: 6.6 | S10: 6.6 | T10: 6.6 | U10: 6.6 | V10: 6.6 | W10: 0 | X10: 0 | Y10: 0 | Z10: 0 | AA10: 0 | AB10: 0 | AC10: 0 | AD10: 0 | AE10: 0 | AF10: 0
A11: Electricity | B11: Grid | D11: 2019 | E11: Dispatchable | F11: Combustion turbine | G11: RNG | H11: ELCRNGGRDCTU19 | I11: 0 | J11: 0 | M11: 27.138389 | N11: 2.0228151 | O11: 0 | P11: 0 | Q11: 0 | R11: 0 | S11: 0 | T11: 0 | U11: 0 | V11: 0 | W11: 0 | X11: 0 | Y11: 0 | Z11: 0 | AA11: 0 | AB11: 0 | AC11: 0 | AD11: 0 | AE11: 0 | AF11: 0
