Workbook

Sheet ReadMe
A1: Generic Comet (GC) TIMES Supply
B3: Sheet color
C4: Raw Data and Parameters
C6: City Specific Data
C8: Post processing for TIMES
C10: Table formatted for TIMES

Sheet >> City Data

Sheet City characteristics
B2: City Basic Data
B4: Calibration methodology | C4: GHG Inventory
B6: A. City Characteristics
B7: Data Item | C7: Value | D7: Units
B8: City Name | C8: New York
B9: Latitude | C9: 40.5
B10: Longitude | C10: -75
B11: County | C11: New York County
B12: State | C12: New York
B13: Census Division | C13: Middle Atlantic
B14: Climate Division | C14: Northeast
B15: Egrid Region | C15: NPCC NYC/Westchester
B16: Area of city (excluding water, natural and agricultural areas) | C16: 778 | D16: square kilometers
B17: * Division and Region Map can be found in the Maps sheet.
B18: B. Planning Base Year and Target Years
B19: Year | C19: Value | D19: Units
B20: Base Year | C20: 2019 | D20: Acceptable range [2018,2021]
B21: End Year | C21: 2050
B23: C. City Population and GDP
B24: Data Item | C24: Value | D24: Units
B25: Population in Base Year | C25: 8337 | D25: Thousand of people
B26: Annual population growth (Base Year - End Year) | C26: 0.5 | D26: % people
B27: GDP in Base Year | C27: 1206000 | D27: Million US$
B28: Annual GDP growth rate | C28: 2 | D28: % US$
B29: Share of manufacturing GDP | C29: 5 | D29: % US$
B30: Share of State population | C30: 0.42835123
B31: Share of State GDP | C31: 0.67251772
B32: Adjustment from state manufacturing GDP | C32: 1.0638298
B34: D. Climate Data
B35: Data Item | C35: 2000 | D35: 2050 | E35: 2100 | F35: Units
B36: Heating degree days (HDD) | C36: 4473.4625 | D36: 4066.4182 | E36: 3763.8582 | F36: F
B37: Cooling degree days (CDD) | C37: 1020.7333 | D37: 1224.2555 | E37: 1375.5355 | F37: F
B39: Data Item | C39: Value | D39: Units
B40: Correction from State HDD | C40: 0.72727402
B41: Correction from State CDD | C41: 1.5583715
B42: Annual precipitation | C42: 762 | D42: mm / year
B43: Climate change scenario | C43: RCP4.5
B44: Average temperature increase in 1980-2020 | C44: 1.4617857 | D44: F
B45: Forecasted average temperature increase in 2035-2065 | C45: 3.13 | D45: F
B46: Forecasted average temperature increase in 2070-2100 | C46: 4.37 | D46: F
...

Sheet >> GC_NewTech

Sheet IND TECH
A2: Sector | B2: Sub-sector | C2: Archetype | D2: Vintage | E2: End Use | F2: Technology | G2: Energy | H2: First Year | I2: Description | J2: Input Label | K2: Output Label | L2: Technology Label | M2: EFF | N2: CFA | O2: C2A | P2: CAPEX ($/kW) | Q2: To include
A3: Industrial | B3: All Industries | E3: All end use | G3: Coal | J3: INDCOA | K3: INDAINDMD | L3: INDAINAEUCOA20 | M3: 1 | N3: 0.9 | O3: 31.536 | P3: 1000 | Q3: 1
A4: Industrial | B4: All Industries | E4: All end use | G4: Petcoke | J4: INDPCK | K4: INDAINDMD | L4: INDAINAEUPCK20 | M4: 1 | N4: 0.9 | O4: 31.536 | P4: 1000 | Q4: 1
A5: Industrial | B5: All Industries | E5: All end use | G5: LPG | J5: INDLPG | K5: INDAINDMD | L5: INDAINAEULPG20 | M5: 1 | N5: 0.9 | O5: 31.536 | P5: 1000 | Q5: 1
A6: Industrial | B6: All Industries | E6: All end use | G6: Fuel oil | J6: INDFOI | K6: INDAINDMD | L6: INDAINAEUFOI20 | M6: 1 | N6: 0.9 | O6: 31.536 | P6: 1000 | Q6: 1
A7: Industrial | B7: All Industries | E7: All end use | G7: Natural gas | J7: INDNGA | K7: INDAINDMD | L7: INDAINAEUNGA20 | M7: 1 | N7: 0.9 | O7: 31.536 | P7: 1000 | Q7: 1
A8: Industrial | B8: All Industries | E8: All end use | G8: RNG | J8: INDRNG | K8: INDAINDMD | L8: INDAINAEURNG20 | M8: 1 | N8: 0.9 | O8: 31.536 | P8: 1000 | Q8: 1
A9: Industrial | B9: All Industries | E9: All end use | G9: Kerosene | J9: INDKER | K9: INDAINDMD | L9: INDAINAEUKER20 | M9: 1 | N9: 0.9 | O9: 31.536 | P9: 1000 | Q9: 1
A10: Industrial | B10: All Industries | E10: All end use | G10: Gasoline | J10: INDGSL | K10: INDAINDMD | L10: INDAINAEUGSL20 | M10: 1 | N10: 0.9 | O10: 31.536 | P10: 1000 | Q10: 1
A11: Industrial | B11: All Industries | E11: All end use | G11: Diesel | J11: INDDSL | K11: INDAINDMD | L11: INDAINAEUDSL20 | M11: 1 | N11: 0.9 | O11: 31.536 | P11: 1000 | Q11: 1
A12: Industrial | B12: All Industries | E12: All end use | G12: Electricity | J12: INDELC | K12: INDAINDMD | L12: INDAINAEUELC20 | M12: 1 | N12: 0.9 | O12: 31.536 | P12: 1000 | Q12: 1
A13: Industrial | B13: All Industries | E13: All end use | G13: Hydrogen | J13: INDH2G | K13: INDAINDMD | L13: INDAINAEUH2G20 | M13: 1 | N13: 0.9 | O13: 31.536 | P13: 1000 | Q13: 1
A14: * | L14: * | Q14: *
A15: Industrial | B15: All Industries | E15: All end use | G15: Retrofit | J15: INDRET | K15: INDAINDMD | L15: INDAINAEURET20 | M15: 1 | N15: 0.9 | O15: 31.536 | P15: 10000 | Q15: 1

Sheet IND RESID
A1: Sector | B1: Sub-sector | C1: Archetype | D1: Vintage | E1: End Use | F1: Technology | G1: Energy | H1: Input Label | I1: Output Label | J1: Technology Label | K1: DEMAND (TJ) | L1: SPLIT (%) | M1: DEMAND EUSE (TJ) | N1: RESID (MW) | O1: CFA | P1: C2A
A2: Industrial | B2: All Industries | E2: All end use | G2: Coal | H2: INDCOA | I2: INDAINDMD | J2: INDAINAEUCOA19 | K2: 66716.461 | L2: 0 | M2: 0 | N2: 0 | O2: 0.9 | P2: 31.536
A3: Industrial | B3: All Industries | E3: All end use | G3: Petcoke | H3: INDPCK | I3: INDAINDMD | J3: INDAINAEUPCK19 | K3: 66716.461 | L3: 0 | M3: 0 | N3: 0 | O3: 0.9 | P3: 31.536
A4: Industrial | B4: All Industries | E4: All end use | G4: LPG | H4: INDLPG | I4: INDAINDMD | J4: INDAINAEULPG19 | K4: 66716.461 | L4: 0 | M4: 0 | N4: 0 | O4: 0.9 | P4: 31.536
A5: Industrial | B5: All Industries | E5: All end use | G5: Fuel oil | H5: INDFOI | I5: INDAINDMD | J5: INDAINAEUFOI19 | K5: 66716.461 | L5: 0.044204541 | M5: 2949.1706 | N5: 103.90843 | O5: 0.9 | P5: 31.536
A6: Industrial | B6: All Industries | E6: All end use | G6: Natural gas | H6: INDNGA | I6: INDAINDMD | J6: INDAINAEUNGA19 | K6: 66716.461 | L6: 0.46029788 | M6: 30709.446 | N6: 1081.989 | O6: 0.9 | P6: 31.536
A7: Industrial | B7: All Industries | E7: All end use | G7: RNG | H7: INDRNG | I7: INDAINDMD | J7: INDAINAEURNG19 | K7: 66716.461 | L7: 0.001212344 | M7: 80.883298 | N7: 2.8497695 | O7: 0.9 | P7: 31.536
A8: Industrial | B8: All Industries | E8: All end use | G8: Kerosene | H8: INDKER | I8: INDAINDMD | J8: INDAINAEUKER19 | K8: 66716.461 | L8: 0 | M8: 0 | N8: 0 | O8: 0.9 | P8: 31.536
A9: Industrial | B9: All Industries | E9: All end use | G9: Waste | H9: INDWAS | I9: INDAINDMD | J9: INDAINAEUWAS19 | K9: 66716.461 | L9: 0 | M9: 0 | N9: 0 | O9: 0.9 | P9: 31.536
A10: Industrial | B10: All Industries | E10: All end use | G10: Wood biomass | H10: INDBIO | I10: INDAINDMD | J10: INDAINAEUBIO19 | K10: 66716.461 | L10: 0 | M10: 0 | N10: 0 | O10: 0.9 | P10: 31.536
A11: Industrial | B11: All Industries | E11: All end use | G11: Gasoline | H11: INDGSL | I11: INDAINDMD | J11: INDAINAEUGSL19 | K11: 66716.461 | L11: 0 | M11: 0 | N11: 0 | O11: 0.9 | P11: 31.536
A12: Industrial | B12: All Industries | E12: All end use | G12: Diesel | H12: INDDSL | I12: INDAINDMD | J12: INDAINAEUDSL19 | K12: 66716.461 | L12: 0 | M12: 0 | N12: 0 | O12: 0.9 | P12: 31.536
A13: Industrial | B13: All Industries | E13: All end use | G13: Steam | H13: INDSTM | I13: INDAINDMD | J13: INDAINAEUSTM19 | K13: 66716.461 | L13: 0.012291579 | M13: 820.05065 | N13: 28.892929 | O13: 0.9 | P13: 31.536
A14: Industrial | B14: All Industries | E14: All end use | G14: Electricity | H14: INDELC | I14: INDAINDMD | J14: INDAINAEUELC19 | K14: 66716.461 | L14: 0.48199365 | M14: 32156.911 | N14: 1132.9877 | O14: 0.9 | P14: 31.536

Sheet >>> Data

Sheet Selected_constraint
A1: Constraint number | B1: {=_xlfn.UNIQUE(_xlfn._xlws.FILTER('IND RESID'!$H:$I,'IND RESID'!$H:$H<>""))} -> Input Label | C1: Output Label | D1: Count
A2: =COUNTA($B$2:B2) -> 1 | B2: INDCOA | C2: INDAINDMD | D2: {=COUNTA(_xlfn.UNIQUE(_xlfn._xlws.FILTER('IND TECH'!$J:$J,('IND TECH'!$K:$K=C2)*('IND TECH'!$Q:$Q=1))))} -> 12
A3: =COUNTA($B$2:B3) -> 2 | B3: INDPCK | C3: INDAINDMD | D3: {=COUNTA(_xlfn.UNIQUE(_xlfn._xlws.FILTER('IND TECH'!$J:$J,('IND TECH'!$K:$K=C3)*('IND TECH'!$Q:$Q=1))))} -> 12
A4: =COUNTA($B$2:B4) -> 3 | B4: INDLPG | C4: INDAINDMD | D4: {=COUNTA(_xlfn.UNIQUE(_xlfn._xlws.FILTER('IND TECH'!$J:$J,('IND TECH'!$K:$K=C4)*('IND TECH'!$Q:$Q=1))))} -> 12
A5: =COUNTA($B$2:B5) -> 4 | B5: INDFOI | C5: INDAINDMD | D5: {=COUNTA(_xlfn.UNIQUE(_xlfn._xlws.FILTER('IND TECH'!$J:$J,('IND TECH'!$K:$K=C5)*('IND TECH'!$Q:$Q=1))))} -> 12
A6: =COUNTA($B$2:B6) -> 5 | B6: INDNGA | C6: INDAINDMD | D6: {=COUNTA(_xlfn.UNIQUE(_xlfn._xlws.FILTER('IND TECH'!$J:$J,('IND TECH'!$K:$K=C6)*('IND TECH'!$Q:$Q=1))))} -> 12
A7: =COUNTA($B$2:B7) -> 6 | B7: INDRNG | C7: INDAINDMD | D7: {=COUNTA(_xlfn.UNIQUE(_xlfn._xlws.FILTER('IND TECH'!$J:$J,('IND TECH'!$K:$K=C7)*('IND TECH'!$Q:$Q=1))))} -> 12
A8: =COUNTA($B$2:B8) -> 7 | B8: INDKER | C8: INDAINDMD | D8: {=COUNTA(_xlfn.UNIQUE(_xlfn._xlws.FILTER('IND TECH'!$J:$J,('IND TECH'!$K:$K=C8)*('IND TECH'!$Q:$Q=1))))} -> 12
A9: =COUNTA($B$2:B9) -> 8 | B9: INDWAS | C9: INDAINDMD | D9: {=COUNTA(_xlfn.UNIQUE(_xlfn._xlws.FILTER('IND TECH'!$J:$J,('IND TECH'!$K:$K=C9)*('IND TECH'!$Q:$Q=1))))} -> 12
A10: =COUNTA($B$2:B10) -> 9 | B10: INDBIO | C10: INDAINDMD | D10: {=COUNTA(_xlfn.UNIQUE(_xlfn._xlws.FILTER('IND TECH'!$J:$J,('IND TECH'!$K:$K=C10)*('IND TECH'!$Q:$Q=1))))} -> 12
A11: =COUNTA($B$2:B11) -> 10 | B11: INDGSL | C11: INDAINDMD | D11: {=COUNTA(_xlfn.UNIQUE(_xlfn._xlws.FILTER('IND TECH'!$J:$J,('IND TECH'!$K:$K=C11)*('IND TECH'!$Q:$Q=1))))} -> 12
A12: =COUNTA($B$2:B12) -> 11 | B12: INDDSL | C12: INDAINDMD | D12: {=COUNTA(_xlfn.UNIQUE(_xlfn._xlws.FILTER('IND TECH'!$J:$J,('IND TECH'!$K:$K=C12)*('IND TECH'!$Q:$Q=1))))} -> 12
A13: =COUNTA($B$2:B13) -> 12 | B13: INDSTM | C13: INDAINDMD | D13: {=COUNTA(_xlfn.UNIQUE(_xlfn._xlws.FILTER('IND TECH'!$J:$J,('IND TECH'!$K:$K=C13)*('IND TECH'!$Q:$Q=1))))} -> 12
A14: =COUNTA($B$2:B14) -> 13 | B14: INDELC | C14: INDAINDMD | D14: {=COUNTA(_xlfn.UNIQUE(_xlfn._xlws.FILTER('IND TECH'!$J:$J,('IND TECH'!$K:$K=C14)*('IND TECH'!$Q:$Q=1))))} -> 12

Sheet >> TIMES

Sheet UC
C2: ~UC_Sets: R_E: CITY | Q2: ~UC_Sets: R_E: CITY
H3: ~UC_T:UC_COMPRD | V3: ~UC_T:UC_COMPRD
C4: UC_N | D4: Pset_PN | E4: Pset: CI | F4: Pset: CO | G4: Cset: CN | H4: Year | I4: LimType | J4: UC_FLO | K4: CITY | L4: UC_RHSRTS | M4: UC_RHSRTS~0 | Q4: UC_N | R4: Pset_PN | S4: Pset: CI | T4: Pset: CO | U4: Cset: CN | V4: Year | W4: LimType | X4: UC_FLO | Y4: CITY | Z4: UC_RHSRTS | AA4: UC_RHSRTS~0
A5: 1 | C5: =IF(E5="","",IF(SUMIFS('IND TECH'!$Q:$Q,'IND TECH'!$J:$J,E5,'IND TECH'!$K:$K,F5)=0,"*","UC_MarketShare_"&LEFT(F5,LEN(F5)-3)&"_"&RIGHT(E5,3)&"_MIN")) -> UC_MarketShare_INDAIN_COA_MIN | E5: =_xlfn.XLOOKUP($A5,Selected_constraint!$A:$A,Selected_constraint!$B:$B) -> INDCOA | F5: =_xlfn.XLOOKUP($A5,Selected_constraint!$A:$A,Selected_constraint!$C:$C) -> INDAINDMD | G5: =F5 -> INDAINDMD | H5: 2019 | I5: LO | J5: 1 | K5: =-ROUNDDOWN(SUMIFS('IND RESID'!$M:$M,'IND RESID'!$H:$H,$E5,'IND RESID'!$I:$I,$F5)/SUMIFS('IND RESID'!$M:$M,'IND RESID'!$I:$I,$F5),3)*O5 -> 0 | L5: 0 | M5: 5 | O5: 0.98 | Q5: =SUBSTITUTE(C5,"MIN","MAX") -> UC_MarketShare_INDAIN_COA_MAX | S5: =E5 -> INDCOA | T5: =F5 -> INDAINDMD | U5: =G5 -> INDAINDMD | V5: =H5 -> 2019 | W5: UP | X5: 1 | Y5: =-ROUNDUP(MIN(SUMIFS('IND RESID'!$M:$M,'IND RESID'!$H:$H,$E5,'IND RESID'!$I:$I,$F5)/SUMIFS('IND RESID'!$M:$M,'IND RESID'!$I:$I,$F5)*AC5,1),3) -> 0 | Z5: 0 | AA5: 5 | AC5: 1.02
A6: =A5 -> 1 | C6: =IF(C5="*",C5,"") | E6: =E5 -> INDCOA | F6: =F5 -> INDAINDMD | G6: =G5 -> INDAINDMD | H6: 2025 | I6: =I5 -> LO | K6: =-ROUNDDOWN(SUMIFS('IND RESID'!$M:$M,'IND RESID'!$H:$H,$E6,'IND RESID'!$I:$I,$F6)/SUMIFS('IND RESID'!$M:$M,'IND RESID'!$I:$I,$F6),3)*O6 -> 0 | O6: 0.8 | Q6: =SUBSTITUTE(C6,"MIN","MAX") | S6: =E6 -> INDCOA | T6: =F6 -> INDAINDMD | U6: =G6 -> INDAINDMD | V6: 2025 | W6: =W5 -> UP | Y6: =-ROUNDUP(MIN(SUMIFS('IND RESID'!$M:$M,'IND RESID'!$H:$H,$E6,'IND RESID'!$I:$I,$F6)/SUMIFS('IND RESID'!$M:$M,'IND RESID'!$I:$I,$F6)*AC6,1),3) -> 0 | AC6: 1.2
A7: =A6 -> 1 | C7: =IF(C6="*",C6,"") | E7: =E6 -> INDCOA | F7: =F6 -> INDAINDMD | G7: =G6 -> INDAINDMD | H7: 2030 | I7: =I6 -> LO | K7: =-ROUNDDOWN(SUMIFS('IND RESID'!$M:$M,'IND RESID'!$H:$H,$E7,'IND RESID'!$I:$I,$F7)/SUMIFS('IND RESID'!$M:$M,'IND RESID'!$I:$I,$F7),3)*O7 -> 0 | O7: 0.2 | Q7: =SUBSTITUTE(C7,"MIN","MAX") | S7: =E7 -> INDCOA | T7: =F7 -> INDAINDMD | U7: =G7 -> INDAINDMD | V7: 2030 | W7: =W6 -> UP | Y7: =-ROUNDUP(MIN(SUMIFS('IND RESID'!$M:$M,'IND RESID'!$H:$H,$E7,'IND RESID'!$I:$I,$F7)/SUMIFS('IND RESID'!$M:$M,'IND RESID'!$I:$I,$F7)*AC7,1),3) -> 0 | AC7: 1.5
A8: =A7 -> 1 | C8: =IF(C7="*",C7,"") | E8: =E7 -> INDCOA | F8: =F7 -> INDAINDMD | G8: =G7 -> INDAINDMD | H8: 2050 | I8: =I7 -> LO | K8: =-ROUNDDOWN(SUMIFS('IND RESID'!$M:$M,'IND RESID'!$H:$H,$E8,'IND RESID'!$I:$I,$F8)/SUMIFS('IND RESID'!$M:$M,'IND RESID'!$I:$I,$F8),3)*O8 -> 0 | O8: 0 | Q8: =SUBSTITUTE(C8,"MIN","MAX") | S8: =E8 -> INDCOA | T8: =F8 -> INDAINDMD | U8: =G8 -> INDAINDMD | V8: 2050 | W8: =W7 -> UP | Y8: =-ROUNDUP(MIN(SUMIFS('IND RESID'!$M:$M,'IND RESID'!$H:$H,$E8,'IND RESID'!$I:$I,$F8)/SUMIFS('IND RESID'!$M:$M,'IND RESID'!$I:$I,$F8)*AC8,1),3) -> 0 | AC8: 3
A9: =A5+1 -> 2 | C9: =IF(E9="","",IF(SUMIFS('IND TECH'!$Q:$Q,'IND TECH'!$J:$J,E9,'IND TECH'!$K:$K,F9)=0,"*","UC_MarketShare_"&LEFT(F9,LEN(F9)-3)&"_"&RIGHT(E9,3)&"_MIN")) -> UC_MarketShare_INDAIN_PCK_MIN | E9: =_xlfn.XLOOKUP($A9,Selected_constraint!$A:$A,Selected_constraint!$B:$B) -> INDPCK | F9: =_xlfn.XLOOKUP($A9,Selected_constraint!$A:$A,Selected_constraint!$C:$C) -> INDAINDMD | G9: =F9 -> INDAINDMD | H9: 2019 | I9: LO | J9: 1 | K9: =-ROUNDDOWN(SUMIFS('IND RESID'!$M:$M,'IND RESID'!$H:$H,$E9,'IND RESID'!$I:$I,$F9)/SUMIFS('IND RESID'!$M:$M,'IND RESID'!$I:$I,$F9),3)*O9 -> 0 | L9: 0 | M9: 5 | O9: 0.98 | Q9: =SUBSTITUTE(C9,"MIN","MAX") -> UC_MarketShare_INDAIN_PCK_MAX | S9: =E9 -> INDPCK | T9: =F9 -> INDAINDMD | U9: =G9 -> INDAINDMD | V9: 2019 | W9: UP | X9: 1 | Y9: =-ROUNDUP(MIN(SUMIFS('IND RESID'!$M:$M,'IND RESID'!$H:$H,$E9,'IND RESID'!$I:$I,$F9)/SUMIFS('IND RESID'!$M:$M,'IND RESID'!$I:$I,$F9)*AC9,1),3) -> 0 | Z9: 0 | AA9: 5 | AC9: 1.02
A10: =A9 -> 2 | C10: =IF(C9="*",C9,"") | E10: =E9 -> INDPCK | F10: =F9 -> INDAINDMD | G10: =G9 -> INDAINDMD | H10: 2025 | I10: =I9 -> LO | K10: =-ROUNDDOWN(SUMIFS('IND RESID'!$M:$M,'IND RESID'!$H:$H,$E10,'IND RESID'!$I:$I,$F10)/SUMIFS('IND RESID'!$M:$M,'IND RESID'!$I:$I,$F10),3)*O10 -> 0 | O10: 0.8 | Q10: =SUBSTITUTE(C10,"MIN","MAX") | S10: =E10 -> INDPCK | T10: =F10 -> INDAINDMD | U10: =G10 -> INDAINDMD | V10: 2025 | W10: =W9 -> UP | Y10: =-ROUNDUP(MIN(SUMIFS('IND RESID'!$M:$M,'IND RESID'!$H:$H,$E10,'IND RESID'!$I:$I,$F10)/SUMIFS('IND RESID'!$M:$M,'IND RESID'!$I:$I,$F10)*AC10,1),3) -> 0 | AC10: 1.2
A11: =A10 -> 2 | C11: =IF(C10="*",C10,"") | E11: =E10 -> INDPCK | F11: =F10 -> INDAINDMD | G11: =G10 -> INDAINDMD | H11: 2030 | I11: =I10 -> LO | K11: =-ROUNDDOWN(SUMIFS('IND RESID'!$M:$M,'IND RESID'!$H:$H,$E11,'IND RESID'!$I:$I,$F11)/SUMIFS('IND RESID'!$M:$M,'IND RESID'!$I:$I,$F11),3)*O11 -> 0 | O11: 0.2 | Q11: =SUBSTITUTE(C11,"MIN","MAX") | S11: =E11 -> INDPCK | T11: =F11 -> INDAINDMD | U11: =G11 -> INDAINDMD | V11: 2030 | W11: =W10 -> UP | Y11: =-ROUNDUP(MIN(SUMIFS('IND RESID'!$M:$M,'IND RESID'!$H:$H,$E11,'IND RESID'!$I:$I,$F11)/SUMIFS('IND RESID'!$M:$M,'IND RESID'!$I:$I,$F11)*AC11,1),3) -> 0 | AC11: 1.5
A12: =A11 -> 2 | C12: =IF(C11="*",C11,"") | E12: =E11 -> INDPCK | F12: =F11 -> INDAINDMD | G12: =G11 -> INDAINDMD | H12: 2050 | I12: =I11 -> LO | K12: =-ROUNDDOWN(SUMIFS('IND RESID'!$M:$M,'IND RESID'!$H:$H,$E12,'IND RESID'!$I:$I,$F12)/SUMIFS('IND RESID'!$M:$M,'IND RESID'!$I:$I,$F12),3)*O12 -> 0 | O12: 0 | Q12: =SUBSTITUTE(C12,"MIN","MAX") | S12: =E12 -> INDPCK | T12: =F12 -> INDAINDMD | U12: =G12 -> INDAINDMD | V12: 2050 | W12: =W11 -> UP | Y12: =-ROUNDUP(MIN(SUMIFS('IND RESID'!$M:$M,'IND RESID'!$H:$H,$E12,'IND RESID'!$I:$I,$F12)/SUMIFS('IND RESID'!$M:$M,'IND RESID'!$I:$I,$F12)*AC12,1),3) -> 0 | AC12: 3
A13: =A9+1 -> 3 | C13: =IF(E13="","",IF(SUMIFS('IND TECH'!$Q:$Q,'IND TECH'!$J:$J,E13,'IND TECH'!$K:$K,F13)=0,"*","UC_MarketShare_"&LEFT(F13,LEN(F13)-3)&"_"&RIGHT(E13,3)&"_MIN")) -> UC_MarketShare_INDAIN_LPG_MIN | E13: =_xlfn.XLOOKUP($A13,Selected_constraint!$A:$A,Selected_constraint!$B:$B) -> INDLPG | F13: =_xlfn.XLOOKUP($A13,Selected_constraint!$A:$A,Selected_constraint!$C:$C) -> INDAINDMD | G13: =F13 -> INDAINDMD | H13: 2019 | I13: LO | J13: 1 | K13: =-ROUNDDOWN(SUMIFS('IND RESID'!$M:$M,'IND RESID'!$H:$H,$E13,'IND RESID'!$I:$I,$F13)/SUMIFS('IND RESID'!$M:$M,'IND RESID'!$I:$I,$F13),3)*O13 -> 0 | L13: 0 | M13: 5 | O13: 0.98 | Q13: =SUBSTITUTE(C13,"MIN","MAX") -> UC_MarketShare_INDAIN_LPG_MAX | S13: =E13 -> INDLPG | T13: =F13 -> INDAINDMD | U13: =G13 -> INDAINDMD | V13: 2019 | W13: UP | X13: 1 | Y13: =-ROUNDUP(MIN(SUMIFS('IND RESID'!$M:$M,'IND RESID'!$H:$H,$E13,'IND RESID'!$I:$I,$F13)/SUMIFS('IND RESID'!$M:$M,'IND RESID'!$I:$I,$F13)*AC13,1),3) -> 0 | Z13: 0 | AA13: 5 | AC13: 1.02
A14: =A13 -> 3 | C14: =IF(C13="*",C13,"") | E14: =E13 -> INDLPG | F14: =F13 -> INDAINDMD | G14: =G13 -> INDAINDMD | H14: 2025 | I14: =I13 -> LO | K14: =-ROUNDDOWN(SUMIFS('IND RESID'!$M:$M,'IND RESID'!$H:$H,$E14,'IND RESID'!$I:$I,$F14)/SUMIFS('IND RESID'!$M:$M,'IND RESID'!$I:$I,$F14),3)*O14 -> 0 | O14: 0.8 | Q14: =SUBSTITUTE(C14,"MIN","MAX") | S14: =E14 -> INDLPG | T14: =F14 -> INDAINDMD | U14: =G14 -> INDAINDMD | V14: 2025 | W14: =W13 -> UP | Y14: =-ROUNDUP(MIN(SUMIFS('IND RESID'!$M:$M,'IND RESID'!$H:$H,$E14,'IND RESID'!$I:$I,$F14)/SUMIFS('IND RESID'!$M:$M,'IND RESID'!$I:$I,$F14)*AC14,1),3) -> 0 | AC14: 1.2
A15: =A14 -> 3 | C15: =IF(C14="*",C14,"") | E15: =E14 -> INDLPG | F15: =F14 -> INDAINDMD | G15: =G14 -> INDAINDMD | H15: 2030 | I15: =I14 -> LO | K15: =-ROUNDDOWN(SUMIFS('IND RESID'!$M:$M,'IND RESID'!$H:$H,$E15,'IND RESID'!$I:$I,$F15)/SUMIFS('IND RESID'!$M:$M,'IND RESID'!$I:$I,$F15),3)*O15 -> 0 | O15: 0.2 | Q15: =SUBSTITUTE(C15,"MIN","MAX") | S15: =E15 -> INDLPG | T15: =F15 -> INDAINDMD | U15: =G15 -> INDAINDMD | V15: 2030 | W15: =W14 -> UP | Y15: =-ROUNDUP(MIN(SUMIFS('IND RESID'!$M:$M,'IND RESID'!$H:$H,$E15,'IND RESID'!$I:$I,$F15)/SUMIFS('IND RESID'!$M:$M,'IND RESID'!$I:$I,$F15)*AC15,1),3) -> 0 | AC15: 1.5
A16: =A15 -> 3 | C16: =IF(C15="*",C15,"") | E16: =E15 -> INDLPG | F16: =F15 -> INDAINDMD | G16: =G15 -> INDAINDMD | H16: 2050 | I16: =I15 -> LO | K16: =-ROUNDDOWN(SUMIFS('IND RESID'!$M:$M,'IND RESID'!$H:$H,$E16,'IND RESID'!$I:$I,$F16)/SUMIFS('IND RESID'!$M:$M,'IND RESID'!$I:$I,$F16),3)*O16 -> 0 | O16: 0 | Q16: =SUBSTITUTE(C16,"MIN","MAX") | S16: =E16 -> INDLPG | T16: =F16 -> INDAINDMD | U16: =G16 -> INDAINDMD | V16: 2050 | W16: =W15 -> UP | Y16: =-ROUNDUP(MIN(SUMIFS('IND RESID'!$M:$M,'IND RESID'!$H:$H,$E16,'IND RESID'!$I:$I,$F16)/SUMIFS('IND RESID'!$M:$M,'IND RESID'!$I:$I,$F16)*AC16,1),3) -> 0 | AC16: 3
A17: =A13+1 -> 4 | C17: =IF(E17="","",IF(SUMIFS('IND TECH'!$Q:$Q,'IND TECH'!$J:$J,E17,'IND TECH'!$K:$K,F17)=0,"*","UC_MarketShare_"&LEFT(F17,LEN(F17)-3)&"_"&RIGHT(E17,3)&"_MIN")) -> UC_MarketShare_INDAIN_FOI_MIN | E17: =_xlfn.XLOOKUP($A17,Selected_constraint!$A:$A,Selected_constraint!$B:$B) -> INDFOI | F17: =_xlfn.XLOOKUP($A17,Selected_constraint!$A:$A,Selected_constraint!$C:$C) -> INDAINDMD | G17: =F17 -> INDAINDMD | H17: 2019 | I17: LO | J17: 1 | K17: =-ROUNDDOWN(SUMIFS('IND RESID'!$M:$M,'IND RESID'!$H:$H,$E17,'IND RESID'!$I:$I,$F17)/SUMIFS('IND RESID'!$M:$M,'IND RESID'!$I:$I,$F17),3)*O17 -> -0.04312 | L17: 0 | M17: 5 | O17: 0.98 | Q17: =SUBSTITUTE(C17,"MIN","MAX") -> UC_MarketShare_INDAIN_FOI_MAX | S17: =E17 -> INDFOI | T17: =F17 -> INDAINDMD | U17: =G17 -> INDAINDMD | V17: 2019 | W17: UP | X17: 1 | Y17: =-ROUNDUP(MIN(SUMIFS('IND RESID'!$M:$M,'IND RESID'!$H:$H,$E17,'IND RESID'!$I:$I,$F17)/SUMIFS('IND RESID'!$M:$M,'IND RESID'!$I:$I,$F17)*AC17,1),3) -> -0.046 | Z17: 0 | AA17: 5 | AC17: 1.02
A18: =A17 -> 4 | C18: =IF(C17="*",C17,"") | E18: =E17 -> INDFOI | F18: =F17 -> INDAINDMD | G18: =G17 -> INDAINDMD | H18: 2025 | I18: =I17 -> LO | K18: =-ROUNDDOWN(SUMIFS('IND RESID'!$M:$M,'IND RESID'!$H:$H,$E18,'IND RESID'!$I:$I,$F18)/SUMIFS('IND RESID'!$M:$M,'IND RESID'!$I:$I,$F18),3)*O18 -> -0.0352 | O18: 0.8 | Q18: =SUBSTITUTE(C18,"MIN","MAX") | S18: =E18 -> INDFOI | T18: =F18 -> INDAINDMD | U18: =G18 -> INDAINDMD | V18: 2025 | W18: =W17 -> UP | Y18: =-ROUNDUP(MIN(SUMIFS('IND RESID'!$M:$M,'IND RESID'!$H:$H,$E18,'IND RESID'!$I:$I,$F18)/SUMIFS('IND RESID'!$M:$M,'IND RESID'!$I:$I,$F18)*AC18,1),3) -> -0.054 | AC18: 1.2
A19: =A18 -> 4 | C19: =IF(C18="*",C18,"") | E19: =E18 -> INDFOI | F19: =F18 -> INDAINDMD | G19: =G18 -> INDAINDMD | H19: 2030 | I19: =I18 -> LO | K19: =-ROUNDDOWN(SUMIFS('IND RESID'!$M:$M,'IND RESID'!$H:$H,$E19,'IND RESID'!$I:$I,$F19)/SUMIFS('IND RESID'!$M:$M,'IND RESID'!$I:$I,$F19),3)*O19 -> -0.0088 | O19: 0.2 | Q19: =SUBSTITUTE(C19,"MIN","MAX") | S19: =E19 -> INDFOI | T19: =F19 -> INDAINDMD | U19: =G19 -> INDAINDMD | V19: 2030 | W19: =W18 -> UP | Y19: =-ROUNDUP(MIN(SUMIFS('IND RESID'!$M:$M,'IND RESID'!$H:$H,$E19,'IND RESID'!$I:$I,$F19)/SUMIFS('IND RESID'!$M:$M,'IND RESID'!$I:$I,$F19)*AC19,1),3) -> -0.067 | AC19: 1.5
A20: =A19 -> 4 | C20: =IF(C19="*",C19,"") | E20: =E19 -> INDFOI | F20: =F19 -> INDAINDMD | G20: =G19 -> INDAINDMD | H20: 2050 | I20: =I19 -> LO | K20: =-ROUNDDOWN(SUMIFS('IND RESID'!$M:$M,'IND RESID'!$H:$H,$E20,'IND RESID'!$I:$I,$F20)/SUMIFS('IND RESID'!$M:$M,'IND RESID'!$I:$I,$F20),3)*O20 -> 0 | O20: 0 | Q20: =SUBSTITUTE(C20,"MIN","MAX") | S20: =E20 -> INDFOI | T20: =F20 -> INDAINDMD | U20: =G20 -> INDAINDMD | V20: 2050 | W20: =W19 -> UP | Y20: =-ROUNDUP(MIN(SUMIFS('IND RESID'!$M:$M,'IND RESID'!$H:$H,$E20,'IND RESID'!$I:$I,$F20)/SUMIFS('IND RESID'!$M:$M,'IND RESID'!$I:$I,$F20)*AC20,1),3) -> -0.133 | AC20: 3
A21: =A17+1 -> 5 | C21: =IF(E21="","",IF(SUMIFS('IND TECH'!$Q:$Q,'IND TECH'!$J:$J,E21,'IND TECH'!$K:$K,F21)=0,"*","UC_MarketShare_"&LEFT(F21,LEN(F21)-3)&"_"&RIGHT(E21,3)&"_MIN")) -> UC_MarketShare_INDAIN_NGA_MIN | E21: =_xlfn.XLOOKUP($A21,Selected_constraint!$A:$A,Selected_constraint!$B:$B) -> INDNGA | F21: =_xlfn.XLOOKUP($A21,Selected_constraint!$A:$A,Selected_constraint!$C:$C) -> INDAINDMD | G21: =F21 -> INDAINDMD | H21: 2019 | I21: LO | J21: 1 | K21: =-ROUNDDOWN(SUMIFS('IND RESID'!$M:$M,'IND RESID'!$H:$H,$E21,'IND RESID'!$I:$I,$F21)/SUMIFS('IND RESID'!$M:$M,'IND RESID'!$I:$I,$F21),3)*O21 -> -0.4508 | L21: 0 | M21: 5 | O21: 0.98 | Q21: =SUBSTITUTE(C21,"MIN","MAX") -> UC_MarketShare_INDAIN_NGA_MAX | S21: =E21 -> INDNGA | T21: =F21 -> INDAINDMD | U21: =G21 -> INDAINDMD | V21: 2019 | W21: UP | X21: 1 | Y21: =-ROUNDUP(MIN(SUMIFS('IND RESID'!$M:$M,'IND RESID'!$H:$H,$E21,'IND RESID'!$I:$I,$F21)/SUMIFS('IND RESID'!$M:$M,'IND RESID'!$I:$I,$F21)*AC21,1),3) -> -0.47 | Z21: 0 | AA21: 5 | AC21: 1.02
A22: =A21 -> 5 | C22: =IF(C21="*",C21,"") | E22: =E21 -> INDNGA | F22: =F21 -> INDAINDMD | G22: =G21 -> INDAINDMD | H22: 2025 | I22: =I21 -> LO | K22: =-ROUNDDOWN(SUMIFS('IND RESID'!$M:$M,'IND RESID'!$H:$H,$E22,'IND RESID'!$I:$I,$F22)/SUMIFS('IND RESID'!$M:$M,'IND RESID'!$I:$I,$F22),3)*O22 -> -0.368 | O22: 0.8 | Q22: =SUBSTITUTE(C22,"MIN","MAX") | S22: =E22 -> INDNGA | T22: =F22 -> INDAINDMD | U22: =G22 -> INDAINDMD | V22: 2025 | W22: =W21 -> UP | Y22: =-ROUNDUP(MIN(SUMIFS('IND RESID'!$M:$M,'IND RESID'!$H:$H,$E22,'IND RESID'!$I:$I,$F22)/SUMIFS('IND RESID'!$M:$M,'IND RESID'!$I:$I,$F22)*AC22,1),3) -> -0.553 | AC22: 1.2
A23: =A22 -> 5 | C23: =IF(C22="*",C22,"") | E23: =E22 -> INDNGA | F23: =F22 -> INDAINDMD | G23: =G22 -> INDAINDMD | H23: 2030 | I23: =I22 -> LO | K23: =-ROUNDDOWN(SUMIFS('IND RESID'!$M:$M,'IND RESID'!$H:$H,$E23,'IND RESID'!$I:$I,$F23)/SUMIFS('IND RESID'!$M:$M,'IND RESID'!$I:$I,$F23),3)*O23 -> -0.092 | O23: 0.2 | Q23: =SUBSTITUTE(C23,"MIN","MAX") | S23: =E23 -> INDNGA | T23: =F23 -> INDAINDMD | U23: =G23 -> INDAINDMD | V23: 2030 | W23: =W22 -> UP | Y23: =-ROUNDUP(MIN(SUMIFS('IND RESID'!$M:$M,'IND RESID'!$H:$H,$E23,'IND RESID'!$I:$I,$F23)/SUMIFS('IND RESID'!$M:$M,'IND RESID'!$I:$I,$F23)*AC23,1),3) -> -0.691 | AC23: 1.5
A24: =A23 -> 5 | C24: =IF(C23="*",C23,"") | E24: =E23 -> INDNGA | F24: =F23 -> INDAINDMD | G24: =G23 -> INDAINDMD | H24: 2050 | I24: =I23 -> LO | K24: =-ROUNDDOWN(SUMIFS('IND RESID'!$M:$M,'IND RESID'!$H:$H,$E24,'IND RESID'!$I:$I,$F24)/SUMIFS('IND RESID'!$M:$M,'IND RESID'!$I:$I,$F24),3)*O24 -> 0 | O24: 0 | Q24: =SUBSTITUTE(C24,"MIN","MAX") | S24: =E24 -> INDNGA | T24: =F24 -> INDAINDMD | U24: =G24 -> INDAINDMD | V24: 2050 | W24: =W23 -> UP | Y24: =-ROUNDUP(MIN(SUMIFS('IND RESID'!$M:$M,'IND RESID'!$H:$H,$E24,'IND RESID'!$I:$I,$F24)/SUMIFS('IND RESID'!$M:$M,'IND RESID'!$I:$I,$F24)*AC24,1),3) -> -1 | AC24: 3
A25: =A21+1 -> 6 | C25: =IF(E25="","",IF(SUMIFS('IND TECH'!$Q:$Q,'IND TECH'!$J:$J,E25,'IND TECH'!$K:$K,F25)=0,"*","UC_MarketShare_"&LEFT(F25,LEN(F25)-3)&"_"&RIGHT(E25,3)&"_MIN")) -> UC_MarketShare_INDAIN_RNG_MIN | E25: =_xlfn.XLOOKUP($A25,Selected_constraint!$A:$A,Selected_constraint!$B:$B) -> INDRNG | F25: =_xlfn.XLOOKUP($A25,Selected_constraint!$A:$A,Selected_constraint!$C:$C) -> INDAINDMD | G25: =F25 -> INDAINDMD | H25: 2019 | I25: LO | J25: 1 | K25: =-ROUNDDOWN(SUMIFS('IND RESID'!$M:$M,'IND RESID'!$H:$H,$E25,'IND RESID'!$I:$I,$F25)/SUMIFS('IND RESID'!$M:$M,'IND RESID'!$I:$I,$F25),3)*O25 -> -0.00098 | L25: 0 | M25: 5 | O25: 0.98 | Q25: =SUBSTITUTE(C25,"MIN","MAX") -> UC_MarketShare_INDAIN_RNG_MAX | S25: =E25 -> INDRNG | T25: =F25 -> INDAINDMD | U25: =G25 -> INDAINDMD | V25: 2019 | W25: UP | X25: 1 | Y25: =-ROUNDUP(MIN(SUMIFS('IND RESID'!$M:$M,'IND RESID'!$H:$H,$E25,'IND RESID'!$I:$I,$F25)/SUMIFS('IND RESID'!$M:$M,'IND RESID'!$I:$I,$F25)*AC25,1),3) -> -0.002 | Z25: 0 | AA25: 5 | AC25: 1.02
A26: =A25 -> 6 | C26: =IF(C25="*",C25,"") | E26: =E25 -> INDRNG | F26: =F25 -> INDAINDMD | G26: =G25 -> INDAINDMD | H26: 2025 | I26: =I25 -> LO | K26: =-ROUNDDOWN(SUMIFS('IND RESID'!$M:$M,'IND RESID'!$H:$H,$E26,'IND RESID'!$I:$I,$F26)/SUMIFS('IND RESID'!$M:$M,'IND RESID'!$I:$I,$F26),3)*O26 -> -0.0008 | O26: 0.8 | Q26: =SUBSTITUTE(C26,"MIN","MAX") | S26: =E26 -> INDRNG | T26: =F26 -> INDAINDMD | U26: =G26 -> INDAINDMD | V26: 2025 | W26: =W25 -> UP | Y26: =-ROUNDUP(MIN(SUMIFS('IND RESID'!$M:$M,'IND RESID'!$H:$H,$E26,'IND RESID'!$I:$I,$F26)/SUMIFS('IND RESID'!$M:$M,'IND RESID'!$I:$I,$F26)*AC26,1),3) -> -0.002 | AC26: 1.2
A27: =A26 -> 6 | C27: =IF(C26="*",C26,"") | E27: =E26 -> INDRNG | F27: =F26 -> INDAINDMD | G27: =G26 -> INDAINDMD | H27: 2030 | I27: =I26 -> LO | K27: =-ROUNDDOWN(SUMIFS('IND RESID'!$M:$M,'IND RESID'!$H:$H,$E27,'IND RESID'!$I:$I,$F27)/SUMIFS('IND RESID'!$M:$M,'IND RESID'!$I:$I,$F27),3)*O27 -> -0.0002 | O27: 0.2 | Q27: =SUBSTITUTE(C27,"MIN","MAX") | S27: =E27 -> INDRNG | T27: =F27 -> INDAINDMD | U27: =G27 -> INDAINDMD | V27: 2030 | W27: =W26 -> UP | Y27: =-ROUNDUP(MIN(SUMIFS('IND RESID'!$M:$M,'IND RESID'!$H:$H,$E27,'IND RESID'!$I:$I,$F27)/SUMIFS('IND RESID'!$M:$M,'IND RESID'!$I:$I,$F27)*AC27,1),3) -> -0.002 | AC27: 1.5
A28: =A27 -> 6 | C28: =IF(C27="*",C27,"") | E28: =E27 -> INDRNG | F28: =F27 -> INDAINDMD | G28: =G27 -> INDAINDMD | H28: 2050 | I28: =I27 -> LO | K28: =-ROUNDDOWN(SUMIFS('IND RESID'!$M:$M,'IND RESID'!$H:$H,$E28,'IND RESID'!$I:$I,$F28)/SUMIFS('IND RESID'!$M:$M,'IND RESID'!$I:$I,$F28),3)*O28 -> 0 | O28: 0 | Q28: =SUBSTITUTE(C28,"MIN","MAX") | S28: =E28 -> INDRNG | T28: =F28 -> INDAINDMD | U28: =G28 -> INDAINDMD | V28: 2050 | W28: =W27 -> UP | Y28: =-ROUNDUP(MIN(SUMIFS('IND RESID'!$M:$M,'IND RESID'!$H:$H,$E28,'IND RESID'!$I:$I,$F28)/SUMIFS('IND RESID'!$M:$M,'IND RESID'!$I:$I,$F28)*AC28,1),3) -> -0.004 | AC28: 3
A29: =A25+1 -> 7 | C29: =IF(E29="","",IF(SUMIFS('IND TECH'!$Q:$Q,'IND TECH'!$J:$J,E29,'IND TECH'!$K:$K,F29)=0,"*","UC_MarketShare_"&LEFT(F29,LEN(F29)-3)&"_"&RIGHT(E29,3)&"_MIN")) -> UC_MarketShare_INDAIN_KER_MIN | E29: =_xlfn.XLOOKUP($A29,Selected_constraint!$A:$A,Selected_constraint!$B:$B) -> INDKER | F29: =_xlfn.XLOOKUP($A29,Selected_constraint!$A:$A,Selected_constraint!$C:$C) -> INDAINDMD | G29: =F29 -> INDAINDMD | H29: 2019 | I29: LO | J29: 1 | K29: =-ROUNDDOWN(SUMIFS('IND RESID'!$M:$M,'IND RESID'!$H:$H,$E29,'IND RESID'!$I:$I,$F29)/SUMIFS('IND RESID'!$M:$M,'IND RESID'!$I:$I,$F29),3)*O29 -> 0 | L29: 0 | M29: 5 | O29: 0.98 | Q29: =SUBSTITUTE(C29,"MIN","MAX") -> UC_MarketShare_INDAIN_KER_MAX | S29: =E29 -> INDKER | T29: =F29 -> INDAINDMD | U29: =G29 -> INDAINDMD | V29: 2019 | W29: UP | X29: 1 | Y29: =-ROUNDUP(MIN(SUMIFS('IND RESID'!$M:$M,'IND RESID'!$H:$H,$E29,'IND RESID'!$I:$I,$F29)/SUMIFS('IND RESID'!$M:$M,'IND RESID'!$I:$I,$F29)*AC29,1),3) -> 0 | Z29: 0 | AA29: 5 | AC29: 1.02
A30: =A29 -> 7 | C30: =IF(C29="*",C29,"") | E30: =E29 -> INDKER | F30: =F29 -> INDAINDMD | G30: =G29 -> INDAINDMD | H30: 2025 | I30: =I29 -> LO | K30: =-ROUNDDOWN(SUMIFS('IND RESID'!$M:$M,'IND RESID'!$H:$H,$E30,'IND RESID'!$I:$I,$F30)/SUMIFS('IND RESID'!$M:$M,'IND RESID'!$I:$I,$F30),3)*O30 -> 0 | O30: 0.8 | Q30: =SUBSTITUTE(C30,"MIN","MAX") | S30: =E30 -> INDKER | T30: =F30 -> INDAINDMD | U30: =G30 -> INDAINDMD | V30: 2025 | W30: =W29 -> UP | Y30: =-ROUNDUP(MIN(SUMIFS('IND RESID'!$M:$M,'IND RESID'!$H:$H,$E30,'IND RESID'!$I:$I,$F30)/SUMIFS('IND RESID'!$M:$M,'IND RESID'!$I:$I,$F30)*AC30,1),3) -> 0 | AC30: 1.2
A31: =A30 -> 7 | C31: =IF(C30="*",C30,"") | E31: =E30 -> INDKER | F31: =F30 -> INDAINDMD | G31: =G30 -> INDAINDMD | H31: 2030 | I31: =I30 -> LO | K31: =-ROUNDDOWN(SUMIFS('IND RESID'!$M:$M,'IND RESID'!$H:$H,$E31,'IND RESID'!$I:$I,$F31)/SUMIFS('IND RESID'!$M:$M,'IND RESID'!$I:$I,$F31),3)*O31 -> 0 | O31: 0.2 | Q31: =SUBSTITUTE(C31,"MIN","MAX") | S31: =E31 -> INDKER | T31: =F31 -> INDAINDMD | U31: =G31 -> INDAINDMD | V31: 2030 | W31: =W30 -> UP | Y31: =-ROUNDUP(MIN(SUMIFS('IND RESID'!$M:$M,'IND RESID'!$H:$H,$E31,'IND RESID'!$I:$I,$F31)/SUMIFS('IND RESID'!$M:$M,'IND RESID'!$I:$I,$F31)*AC31,1),3) -> 0 | AC31: 1.5
A32: =A31 -> 7 | C32: =IF(C31="*",C31,"") | E32: =E31 -> INDKER | F32: =F31 -> INDAINDMD | G32: =G31 -> INDAINDMD | H32: 2050 | I32: =I31 -> LO | K32: =-ROUNDDOWN(SUMIFS('IND RESID'!$M:$M,'IND RESID'!$H:$H,$E32,'IND RESID'!$I:$I,$F32)/SUMIFS('IND RESID'!$M:$M,'IND RESID'!$I:$I,$F32),3)*O32 -> 0 | O32: 0 | Q32: =SUBSTITUTE(C32,"MIN","MAX") | S32: =E32 -> INDKER | T32: =F32 -> INDAINDMD | U32: =G32 -> INDAINDMD | V32: 2050 | W32: =W31 -> UP | Y32: =-ROUNDUP(MIN(SUMIFS('IND RESID'!$M:$M,'IND RESID'!$H:$H,$E32,'IND RESID'!$I:$I,$F32)/SUMIFS('IND RESID'!$M:$M,'IND RESID'!$I:$I,$F32)*AC32,1),3) -> 0 | AC32: 3
A33: =A29+1 -> 8 | C33: =IF(E33="","",IF(SUMIFS('IND TECH'!$Q:$Q,'IND TECH'!$J:$J,E33,'IND TECH'!$K:$K,F33)=0,"*","UC_MarketShare_"&LEFT(F33,LEN(F33)-3)&"_"&RIGHT(E33,3)&"_MIN")) -> * | E33: =_xlfn.XLOOKUP($A33,Selected_constraint!$A:$A,Selected_constraint!$B:$B) -> INDWAS | F33: =_xlfn.XLOOKUP($A33,Selected_constraint!$A:$A,Selected_constraint!$C:$C) -> INDAINDMD | G33: =F33 -> INDAINDMD | H33: 2019 | I33: LO | J33: 1 | K33: =-ROUNDDOWN(SUMIFS('IND RESID'!$M:$M,'IND RESID'!$H:$H,$E33,'IND RESID'!$I:$I,$F33)/SUMIFS('IND RESID'!$M:$M,'IND RESID'!$I:$I,$F33),3)*O33 -> 0 | L33: 0 | M33: 5 | O33: 0.98 | Q33: =SUBSTITUTE(C33,"MIN","MAX") -> * | S33: =E33 -> INDWAS | T33: =F33 -> INDAINDMD | U33: =G33 -> INDAINDMD | V33: 2019 | W33: UP | X33: 1 | Y33: =-ROUNDUP(MIN(SUMIFS('IND RESID'!$M:$M,'IND RESID'!$H:$H,$E33,'IND RESID'!$I:$I,$F33)/SUMIFS('IND RESID'!$M:$M,'IND RESID'!$I:$I,$F33)*AC33,1),3) -> 0 | Z33: 0 | AA33: 5 | AC33: 1.02
A34: =A33 -> 8 | C34: =IF(C33="*",C33,"") -> * | E34: =E33 -> INDWAS | F34: =F33 -> INDAINDMD | G34: =G33 -> INDAINDMD | H34: 2025 | I34: =I33 -> LO | K34: =-ROUNDDOWN(SUMIFS('IND RESID'!$M:$M,'IND RESID'!$H:$H,$E34,'IND RESID'!$I:$I,$F34)/SUMIFS('IND RESID'!$M:$M,'IND RESID'!$I:$I,$F34),3)*O34 -> 0 | O34: 0.8 | Q34: =SUBSTITUTE(C34,"MIN","MAX") -> * | S34: =E34 -> INDWAS | T34: =F34 -> INDAINDMD | U34: =G34 -> INDAINDMD | V34: 2025 | W34: =W33 -> UP | Y34: =-ROUNDUP(MIN(SUMIFS('IND RESID'!$M:$M,'IND RESID'!$H:$H,$E34,'IND RESID'!$I:$I,$F34)/SUMIFS('IND RESID'!$M:$M,'IND RESID'!$I:$I,$F34)*AC34,1),3) -> 0 | AC34: 1.2
A35: =A34 -> 8 | C35: =IF(C34="*",C34,"") -> * | E35: =E34 -> INDWAS | F35: =F34 -> INDAINDMD | G35: =G34 -> INDAINDMD | H35: 2030 | I35: =I34 -> LO | K35: =-ROUNDDOWN(SUMIFS('IND RESID'!$M:$M,'IND RESID'!$H:$H,$E35,'IND RESID'!$I:$I,$F35)/SUMIFS('IND RESID'!$M:$M,'IND RESID'!$I:$I,$F35),3)*O35 -> 0 | O35: 0.2 | Q35: =SUBSTITUTE(C35,"MIN","MAX") -> * | S35: =E35 -> INDWAS | T35: =F35 -> INDAINDMD | U35: =G35 -> INDAINDMD | V35: 2030 | W35: =W34 -> UP | Y35: =-ROUNDUP(MIN(SUMIFS('IND RESID'!$M:$M,'IND RESID'!$H:$H,$E35,'IND RESID'!$I:$I,$F35)/SUMIFS('IND RESID'!$M:$M,'IND RESID'!$I:$I,$F35)*AC35,1),3) -> 0 | AC35: 1.5
A36: =A35 -> 8 | C36: =IF(C35="*",C35,"") -> * | E36: =E35 -> INDWAS | F36: =F35 -> INDAINDMD | G36: =G35 -> INDAINDMD | H36: 2050 | I36: =I35 -> LO | K36: =-ROUNDDOWN(SUMIFS('IND RESID'!$M:$M,'IND RESID'!$H:$H,$E36,'IND RESID'!$I:$I,$F36)/SUMIFS('IND RESID'!$M:$M,'IND RESID'!$I:$I,$F36),3)*O36 -> 0 | O36: 0 | Q36: =SUBSTITUTE(C36,"MIN","MAX") -> * | S36: =E36 -> INDWAS | T36: =F36 -> INDAINDMD | U36: =G36 -> INDAINDMD | V36: 2050 | W36: =W35 -> UP | Y36: =-ROUNDUP(MIN(SUMIFS('IND RESID'!$M:$M,'IND RESID'!$H:$H,$E36,'IND RESID'!$I:$I,$F36)/SUMIFS('IND RESID'!$M:$M,'IND RESID'!$I:$I,$F36)*AC36,1),3) -> 0 | AC36: 3
A37: =A33+1 -> 9 | C37: =IF(E37="","",IF(SUMIFS('IND TECH'!$Q:$Q,'IND TECH'!$J:$J,E37,'IND TECH'!$K:$K,F37)=0,"*","UC_MarketShare_"&LEFT(F37,LEN(F37)-3)&"_"&RIGHT(E37,3)&"_MIN")) -> * | E37: =_xlfn.XLOOKUP($A37,Selected_constraint!$A:$A,Selected_constraint!$B:$B) -> INDBIO | F37: =_xlfn.XLOOKUP($A37,Selected_constraint!$A:$A,Selected_constraint!$C:$C) -> INDAINDMD | G37: =F37 -> INDAINDMD | H37: 2019 | I37: LO | J37: 1 | K37: =-ROUNDDOWN(SUMIFS('IND RESID'!$M:$M,'IND RESID'!$H:$H,$E37,'IND RESID'!$I:$I,$F37)/SUMIFS('IND RESID'!$M:$M,'IND RESID'!$I:$I,$F37),3)*O37 -> 0 | L37: 0 | M37: 5 | O37: 0.98 | Q37: =SUBSTITUTE(C37,"MIN","MAX") -> * | S37: =E37 -> INDBIO | T37: =F37 -> INDAINDMD | U37: =G37 -> INDAINDMD | V37: 2019 | W37: UP | X37: 1 | Y37: =-ROUNDUP(MIN(SUMIFS('IND RESID'!$M:$M,'IND RESID'!$H:$H,$E37,'IND RESID'!$I:$I,$F37)/SUMIFS('IND RESID'!$M:$M,'IND RESID'!$I:$I,$F37)*AC37,1),3) -> 0 | Z37: 0 | AA37: 5 | AC37: 1.02
A38: =A37 -> 9 | C38: =IF(C37="*",C37,"") -> * | E38: =E37 -> INDBIO | F38: =F37 -> INDAINDMD | G38: =G37 -> INDAINDMD | H38: 2025 | I38: =I37 -> LO | K38: =-ROUNDDOWN(SUMIFS('IND RESID'!$M:$M,'IND RESID'!$H:$H,$E38,'IND RESID'!$I:$I,$F38)/SUMIFS('IND RESID'!$M:$M,'IND RESID'!$I:$I,$F38),3)*O38 -> 0 | O38: 0.8 | Q38: =SUBSTITUTE(C38,"MIN","MAX") -> * | S38: =E38 -> INDBIO | T38: =F38 -> INDAINDMD | U38: =G38 -> INDAINDMD | V38: 2025 | W38: =W37 -> UP | Y38: =-ROUNDUP(MIN(SUMIFS('IND RESID'!$M:$M,'IND RESID'!$H:$H,$E38,'IND RESID'!$I:$I,$F38)/SUMIFS('IND RESID'!$M:$M,'IND RESID'!$I:$I,$F38)*AC38,1),3) -> 0 | AC38: 1.2
A39: =A38 -> 9 | C39: =IF(C38="*",C38,"") -> * | E39: =E38 -> INDBIO | F39: =F38 -> INDAINDMD | G39: =G38 -> INDAINDMD | H39: 2030 | I39: =I38 -> LO | K39: =-ROUNDDOWN(SUMIFS('IND RESID'!$M:$M,'IND RESID'!$H:$H,$E39,'IND RESID'!$I:$I,$F39)/SUMIFS('IND RESID'!$M:$M,'IND RESID'!$I:$I,$F39),3)*O39 -> 0 | O39: 0.2 | Q39: =SUBSTITUTE(C39,"MIN","MAX") -> * | S39: =E39 -> INDBIO | T39: =F39 -> INDAINDMD | U39: =G39 -> INDAINDMD | V39: 2030 | W39: =W38 -> UP | Y39: =-ROUNDUP(MIN(SUMIFS('IND RESID'!$M:$M,'IND RESID'!$H:$H,$E39,'IND RESID'!$I:$I,$F39)/SUMIFS('IND RESID'!$M:$M,'IND RESID'!$I:$I,$F39)*AC39,1),3) -> 0 | AC39: 1.5
A40: =A39 -> 9 | C40: =IF(C39="*",C39,"") -> * | E40: =E39 -> INDBIO | F40: =F39 -> INDAINDMD | G40: =G39 -> INDAINDMD | H40: 2050 | I40: =I39 -> LO | K40: =-ROUNDDOWN(SUMIFS('IND RESID'!$M:$M,'IND RESID'!$H:$H,$E40,'IND RESID'!$I:$I,$F40)/SUMIFS('IND RESID'!$M:$M,'IND RESID'!$I:$I,$F40),3)*O40 -> 0 | O40: 0 | Q40: =SUBSTITUTE(C40,"MIN","MAX") -> * | S40: =E40 -> INDBIO | T40: =F40 -> INDAINDMD | U40: =G40 -> INDAINDMD | V40: 2050 | W40: =W39 -> UP | Y40: =-ROUNDUP(MIN(SUMIFS('IND RESID'!$M:$M,'IND RESID'!$H:$H,$E40,'IND RESID'!$I:$I,$F40)/SUMIFS('IND RESID'!$M:$M,'IND RESID'!$I:$I,$F40)*AC40,1),3) -> 0 | AC40: 3
A41: =A37+1 -> 10 | C41: =IF(E41="","",IF(SUMIFS('IND TECH'!$Q:$Q,'IND TECH'!$J:$J,E41,'IND TECH'!$K:$K,F41)=0,"*","UC_MarketShare_"&LEFT(F41,LEN(F41)-3)&"_"&RIGHT(E41,3)&"_MIN")) -> UC_MarketShare_INDAIN_GSL_MIN | E41: =_xlfn.XLOOKUP($A41,Selected_constraint!$A:$A,Selected_constraint!$B:$B) -> INDGSL | F41: =_xlfn.XLOOKUP($A41,Selected_constraint!$A:$A,Selected_constraint!$C:$C) -> INDAINDMD | G41: =F41 -> INDAINDMD | H41: 2019 | I41: LO | J41: 1 | K41: =-ROUNDDOWN(SUMIFS('IND RESID'!$M:$M,'IND RESID'!$H:$H,$E41,'IND RESID'!$I:$I,$F41)/SUMIFS('IND RESID'!$M:$M,'IND RESID'!$I:$I,$F41),3)*O41 -> 0 | L41: 0 | M41: 5 | O41: 0.98 | Q41: =SUBSTITUTE(C41,"MIN","MAX") -> UC_MarketShare_INDAIN_GSL_MAX | S41: =E41 -> INDGSL | T41: =F41 -> INDAINDMD | U41: =G41 -> INDAINDMD | V41: 2019 | W41: UP | X41: 1 | Y41: =-ROUNDUP(MIN(SUMIFS('IND RESID'!$M:$M,'IND RESID'!$H:$H,$E41,'IND RESID'!$I:$I,$F41)/SUMIFS('IND RESID'!$M:$M,'IND RESID'!$I:$I,$F41)*AC41,1),3) -> 0 | Z41: 0 | AA41: 5 | AC41: 1.02
...
